
# Created by Ruins mod version 13.8 Ingame Parser
# authoring Player: OneWolfe

weight=1
embed_into_distance=10
biomesToSpawnIn=gravel beach,stone beach
acceptable_target_blocks=
unacceptable_target_blocks=flowing_water,water,flowing_lava,lava,terrafirmacraft:SaltWaterStationary-0,terrafirmacraft:SaltWaterStationary-8,terrafirmacraft:FreshWaterStationary-0,terrafirmacraft:FreshWaterStationary-8
dimensions=25,8,8
allowable_overhang=0
max_leveling=2
leveling_buffer=0
preserve_water=1
preserve_lava=0

rule1=0,100,terrafirmacraft:StoneIgEx-2
rule2=0,100,preserveBlock
rule3=0,100,air,air,air,terrafirmacraft:planks-5,terrafirmacraft:planks-4,terrafirmacraft:SaltWaterStationary-0

layer
2,2,1,1,1,1,2,2
2,1,1,1,1,1,1,2
1,1,1,1,1,1,1,1
1,1,1,1,1,1,1,1
1,1,1,1,1,1,1,1
1,1,1,1,1,1,1,1
2,1,1,1,1,1,1,2
2,2,1,1,1,1,2,2
endlayer

layer
2,2,1,1,1,1,2,2
2,1,1,1,1,1,1,2
1,1,1,1,1,1,1,1
1,1,1,1,1,1,1,1
1,1,1,1,1,1,1,1
1,1,1,1,1,1,1,1
2,1,1,1,1,1,1,2
2,2,1,1,1,1,2,2
endlayer

layer
2,2,1,1,1,1,2,2
2,1,1,1,1,1,1,2
1,1,1,1,1,1,1,1
1,1,1,1,1,1,1,1
1,1,1,1,1,1,1,1
1,1,1,1,1,1,1,1
2,1,1,1,1,1,1,2
2,2,1,1,1,1,2,2
endlayer

layer
2,2,1,1,1,1,2,2
2,1,1,1,1,1,1,2
1,1,1,1,1,1,1,1
1,1,1,1,1,1,1,1
1,1,1,1,1,1,1,1
1,1,1,1,1,1,1,1
2,1,1,1,1,1,1,2
2,2,1,1,1,1,2,2
endlayer

layer
2,2,1,1,1,1,2,2
2,1,1,1,1,1,1,2
1,1,1,1,1,1,1,1
1,1,1,1,1,1,1,1
1,1,1,1,1,1,1,1
1,1,1,1,1,1,1,1
2,1,1,1,1,1,1,2
2,2,1,1,1,1,2,2
endlayer

layer
2,2,1,1,1,1,2,2
2,1,1,1,1,1,1,2
1,1,1,1,1,1,1,1
1,1,1,1,1,1,1,1
1,1,1,1,1,1,1,1
1,1,1,1,1,1,1,1
2,1,1,1,1,1,1,2
2,2,1,1,1,1,2,2
endlayer

layer
2,2,1,1,1,1,2,2
2,1,1,1,1,1,1,2
1,1,1,1,1,1,1,1
1,1,1,1,1,1,1,1
1,1,1,1,1,1,1,1
1,1,1,1,1,1,1,1
2,1,1,1,1,1,1,2
2,2,1,1,1,1,2,2
endlayer

layer
2,2,1,1,1,1,2,2
2,1,1,1,1,1,1,2
1,1,1,1,1,1,1,1
1,1,1,1,1,1,1,1
1,1,1,1,1,1,1,1
1,1,1,1,1,1,1,1
2,1,1,1,1,1,1,2
2,2,1,1,1,1,2,2
endlayer

layer
2,2,1,1,1,1,2,2
2,1,1,1,1,1,1,2
1,1,1,1,1,1,1,1
1,1,1,1,1,1,1,1
1,1,1,1,1,1,1,1
1,1,1,1,1,1,1,1
2,1,1,1,1,1,1,2
2,2,1,1,1,1,2,2
endlayer

layer
2,2,1,1,1,1,2,2
2,1,1,1,1,1,1,2
1,1,1,1,1,1,1,1
1,1,1,1,1,1,1,1
1,1,1,1,1,1,1,1
1,1,1,1,1,1,1,1
2,1,1,1,1,1,1,2
2,2,1,1,1,1,2,2
endlayer

#Here is the Start of the Original Statue

layer
2,2,1,1,1,1,2,2
2,1,1,1,1,1,1,2
1,1,1,1,1,1,1,1
1,1,1,1,1,1,1,1
1,1,1,1,1,1,1,1
1,1,1,1,1,1,1,1
2,1,1,1,1,1,1,2
2,2,1,1,1,1,2,2
endlayer

layer
2,2,2,2,2,2,2,2
2,2,1,1,1,1,2,2
2,1,1,1,1,1,1,2
2,1,1,1,1,1,1,2
2,1,1,1,1,1,1,2
2,1,1,1,1,1,1,2
2,2,1,1,1,1,2,2
2,2,2,2,2,2,2,2
endlayer

layer
0,0,0,0,0,0,0,0
0,0,0,0,0,0,0,0
0,1,1,1,1,1,1,0
0,1,1,1,1,1,1,0
0,1,1,1,1,1,1,0
0,1,1,1,1,1,1,0
0,0,1,1,1,1,0,0
0,0,0,0,0,0,0,0
endlayer

layer
0,0,0,0,0,0,0,0
0,0,1,1,1,1,0,0
0,0,1,1,1,1,0,0
0,0,1,1,1,1,0,0
0,0,1,1,1,1,0,0
0,0,1,1,1,1,0,0
0,0,0,1,1,0,0,0
0,0,0,0,0,0,0,0
endlayer

layer
0,0,0,0,0,0,0,0
0,0,0,0,0,0,0,0
0,1,1,1,1,1,1,0
0,1,1,1,1,1,1,0
0,1,1,1,1,1,1,0
0,0,1,1,1,1,0,0
0,0,1,1,1,1,0,0
0,0,0,0,0,0,0,0
endlayer

layer
0,0,0,0,0,0,0,0
0,0,0,1,1,0,0,0
0,1,1,1,1,1,1,0
0,1,1,1,1,1,1,0
0,1,1,1,1,1,1,0
0,1,1,1,1,1,1,0
0,0,1,1,1,1,0,0
0,0,0,0,0,0,0,0
endlayer

layer
0,0,0,0,0,0,0,0
0,0,0,0,0,0,0,0
0,1,1,1,1,1,1,0
0,1,1,1,1,1,1,0
0,0,1,1,1,1,0,0
0,1,1,1,1,1,1,0
0,0,1,1,1,1,0,0
0,0,0,0,0,0,0,0
endlayer

layer
0,0,0,0,0,0,0,0
0,0,0,1,1,0,0,0
0,1,1,1,1,1,1,0
0,1,1,1,1,1,1,0
0,0,1,1,1,1,0,0
0,1,1,1,1,1,1,0
0,0,1,1,1,1,0,0
0,0,0,0,0,0,0,0
endlayer

layer
0,0,0,0,0,0,0,0
0,0,0,1,1,0,0,0
0,1,1,1,1,1,1,0
0,1,1,1,1,1,1,0
0,0,1,1,1,1,0,0
0,1,1,1,1,1,1,0
0,0,1,1,1,1,0,0
0,0,0,0,0,0,0,0
endlayer

layer
0,0,0,0,0,0,0,0
0,0,0,1,1,0,0,0
0,1,1,1,1,1,1,0
0,1,1,1,1,1,1,0
0,0,1,1,1,1,0,0
0,1,1,1,1,1,1,0
0,0,1,1,1,1,0,0
0,0,0,0,0,0,0,0
endlayer

layer
0,0,0,0,0,0,0,0
0,0,0,0,0,0,0,0
0,1,3,1,1,3,1,0
0,1,1,1,1,1,1,0
0,0,1,1,1,1,0,0
0,1,1,1,1,1,1,0
0,0,1,1,1,1,0,0
0,0,0,0,0,0,0,0
endlayer

layer
0,0,0,0,0,0,0,0
0,1,1,1,1,1,1,0
0,1,1,1,1,1,1,0
0,1,1,1,1,1,1,0
0,0,1,1,1,1,0,0
0,1,1,1,1,1,1,0
0,0,1,1,1,1,0,0
0,0,0,0,0,0,0,0
endlayer

layer
0,0,0,0,0,0,0,0
0,0,1,1,1,1,0,0
0,1,1,1,1,1,1,0
0,1,1,1,1,1,1,0
0,0,1,1,1,1,0,0
0,1,1,1,1,1,1,0
0,0,1,1,1,1,0,0
0,0,0,0,0,0,0,0
endlayer

layer
0,0,0,0,0,0,0,0
0,0,0,0,0,0,0,0
0,0,1,1,1,1,0,0
0,0,1,1,1,1,0,0
0,0,1,1,1,1,0,0
0,0,1,1,1,1,0,0
0,0,0,1,1,0,0,0
0,0,0,0,0,0,0,0
endlayer

layer
0,0,0,0,0,0,0,0
0,0,0,0,0,0,0,0
0,0,0,0,0,0,0,0
0,0,0,0,0,0,0,0
0,0,0,0,0,0,0,0
0,0,0,0,0,0,0,0
0,0,0,0,0,0,0,0
0,0,0,0,0,0,0,0
endlayer

