
# Created by Ruins mod version 13.8 Ingame Parser
# authoring Player: OneWolfe

weight=4
embed_into_distance=5
biomesToSpawnIn=river,lake
acceptable_target_blocks=
unacceptable_target_blocks=flowing_water,water,flowing_lava,lava
dimensions=14,5,10
allowable_overhang=2
max_leveling=2
leveling_buffer=0
preserve_water=1
preserve_lava=0

rule1=0,100,preserveBlock
rule2=0,100,air,terrafirmacraft:StoneIgInBrick-2,terrafirmacraft:StoneIgInBrick-2,terrafirmacraft:StoneIgInBrick-2,terrafirmacraft:StoneIgInSmooth-2,terrafirmacraft:StoneIgInCobble-2,
rule3=0,100,preserveBlock
rule4=0,100,air,terrafirmacraft:WallBrickIgIn-2,terrafirmacraft:WallBrickIgIn-2,terrafirmacraft:WallCobbleIgIn-2
rule5=0,100,terrafirmacraft:WallRawIgIn-2
rule6=0,100,Railcraft:track-0

layer
1,1,1,1,1,1,1,1,1,1
1,1,2,2,2,1,1,1,1,1
1,2,2,1,2,2,1,1,1,1
1,1,2,2,2,1,1,1,1,1
1,1,1,1,1,1,1,1,1,1
endlayer

layer
1,1,1,1,1,1,1,1,1,1
1,1,2,2,2,1,1,1,1,1
1,2,2,1,2,2,1,1,1,1
1,1,2,2,2,1,1,1,1,1
1,1,1,1,1,1,1,1,1,1
endlayer

layer
1,1,1,1,1,1,1,1,1,1
1,1,2,2,2,1,1,1,1,1
1,2,2,1,2,2,1,1,1,1
1,1,2,2,2,1,1,1,1,1
1,1,1,1,1,1,1,1,1,1
endlayer

layer
1,1,1,1,1,1,1,1,1,1
1,1,2,2,2,1,1,1,1,1
1,2,2,1,2,2,1,1,1,1
1,1,2,2,2,1,1,1,1,1
1,1,1,1,1,1,1,1,1,1
endlayer

layer
1,1,1,1,1,1,1,1,1,1
1,1,2,2,2,1,1,1,1,1
1,2,2,1,2,2,1,1,1,1
1,1,2,2,2,1,1,1,1,1
1,1,1,1,1,1,1,1,1,1
endlayer

layer
0,0,0,3,3,0,0,0,0,0
3,0,2,2,2,0,0,0,3,0
0,2,2,2,2,2,0,3,3,0
0,0,2,2,2,0,0,0,0,0
0,0,0,0,0,0,0,0,0,0
endlayer

layer
0,0,0,3,3,0,3,0,0,0
0,0,2,2,2,0,0,0,0,0
0,3,2,2,2,3,0,0,0,0
3,0,2,2,2,0,0,0,0,0
0,0,0,0,0,0,0,0,0,0
endlayer

layer
0,0,0,4,0,0,0,3,0,0
0,0,2,2,2,0,0,0,0,0
0,0,2,2,2,0,0,0,0,0
0,0,2,2,2,0,0,0,0,0
0,0,0,4,0,0,0,3,0,0
endlayer

layer
0,0,0,4,0,0,0,3,0,0
0,0,2,0,2,0,0,0,0,0
0,0,2,2,2,0,0,0,0,0
0,0,2,0,2,0,0,0,0,0
0,0,0,4,0,0,0,0,0,0
endlayer

layer
0,0,0,4,0,0,0,0,0,0
0,0,2,2,2,0,0,0,0,0
0,2,2,2,2,2,0,0,0,0
0,0,2,2,2,0,0,0,0,0
0,0,0,4,0,0,0,0,0,0
endlayer

layer
0,0,4,4,4,0,0,0,0,0
0,0,2,2,2,0,3,0,0,0
3,2,2,2,2,2,0,0,0,0
0,0,2,2,2,2,3,0,0,0
0,3,4,4,4,0,0,0,0,0
endlayer

layer
2,2,2,2,2,0,2,2,0,3
0,0,0,2,2,2,2,2,2,2
0,0,2,2,2,2,0,2,2,2
2,2,2,2,0,2,2,2,2,0
2,2,2,2,2,2,2,2,0,0
endlayer

layer
5,5,5,5,5,5,5,5,0,0
0,0,3,3,3,3,3,0,3,3
0,0,6,6,6,6,0,0,0,3
0,0,0,3,0,3,0,0,0,0
0,5,5,5,5,5,5,5,3,0
endlayer

layer
0,0,0,0,0,0,0,0,0,0
0,0,0,0,3,3,0,0,0,0
0,0,0,0,0,3,0,0,0,0
0,0,0,0,0,0,0,0,0,0
0,0,0,0,3,3,3,0,0,0
endlayer



