
# Created by Ruins mod version 14.7 Ingame Parser
# authoring Player: OneWolfe

weight=8
unique=1
embed_into_distance=3
acceptable_target_blocks=
unacceptable_target_blocks=flowing_water,water,flowing_lava,lava
dimensions=16,20,11
allowable_overhang=4
max_leveling=2
leveling_buffer=0
preserve_water=1
preserve_lava=0
preserve_plants=1

rule1=0,100,preserveBlock
rule2=0,100,terrafirmacraft:planks-14
rule3=0,100,terrafirmacraft:WoodVert-14
rule4=0,100,MobSpawner:skeletonTFC,MobSpawner:TwilightForest.Redcap Sapper,MobSpawner:TwilightForest.Lower Goblin Knight,MobSpawner:TwilightForest.Minotaur
rule5=0,100,ChestGenHook:dungeonChest:5-5
rule6=0,100,terrafirmacraft:Vine-1
rule7=0,100,terrafirmacraft:Vine-4
rule8=0,100,terrafirmacraft:Vine-8
rule9=0,100,minecraft:trapdoor-12
rule10=0,100,terrafirmacraft:StoneIgEx-1
rule11=0,100,minecraft:trapdoor-13
rule12=0,100,terrafirmacraft:Vine-2
rule13=0,100,terrafirmacraft:WoodHoriz2-14
rule14=0,100,terrafirmacraft:Vine-12
rule15=0,100,minecraft:trapdoor-10
rule16=0,100,terrafirmacraft:WoodHoriz2-6
rule17=0,100,terrafirmacraft:Fence-14

layer
1,1,1,1,1,1,1,1,1,1,1
1,1,1,1,1,1,1,1,1,1,1
1,1,1,1,1,1,1,1,1,1,1
1,1,1,1,1,1,1,1,1,1,1
1,1,1,1,1,1,1,1,1,1,1
1,1,1,1,1,1,1,1,1,1,1
1,1,1,1,1,1,1,1,1,1,1
1,1,1,1,1,2,1,1,1,1,1
1,1,1,1,1,2,1,1,1,1,1
1,1,1,1,1,2,1,1,1,1,1
1,1,1,1,1,2,1,1,1,1,1
1,1,1,1,1,2,1,1,1,1,1
1,1,1,1,1,2,1,1,1,1,1
1,1,1,1,1,2,1,1,1,1,1
1,1,1,1,1,2,1,1,1,1,1
1,1,1,1,1,2,1,1,1,1,1
1,1,1,1,1,2,1,1,1,1,1
1,1,1,1,1,2,1,1,1,1,1
1,1,1,1,1,1,1,1,1,1,1
1,1,1,1,1,1,1,1,1,1,1
endlayer

layer
1,1,1,1,1,1,1,1,1,1,1
1,1,1,1,1,1,1,1,1,1,1
1,1,1,1,1,1,1,1,1,1,1
1,1,1,1,1,1,1,1,1,1,1
1,1,1,1,1,1,1,1,1,1,1
1,1,1,1,1,1,1,1,1,1,1
1,1,1,1,1,2,1,1,1,1,1
1,1,1,1,2,2,2,1,1,1,1
1,1,1,2,2,0,2,2,1,1,1
1,1,1,2,2,0,2,2,1,1,1
1,1,1,2,2,0,2,2,1,1,1
1,1,1,2,2,0,2,2,1,1,1
1,1,1,2,2,3,2,2,1,1,1
1,1,1,2,2,0,2,2,1,1,1
1,1,1,2,2,0,2,2,1,1,1
1,1,1,2,2,0,2,2,1,1,1
1,1,1,2,2,0,2,2,1,1,1
1,1,1,2,2,0,2,2,1,1,1
1,1,1,1,2,2,2,1,1,1,1
1,1,1,1,1,1,1,1,1,1,1
endlayer

layer
1,1,1,1,1,1,1,1,1,1,1
1,1,1,1,1,1,1,1,1,1,1
1,1,1,1,1,1,1,1,1,1,1
1,1,1,1,1,1,1,1,1,1,1
1,1,1,1,1,1,1,1,1,1,1
1,1,1,1,1,2,1,1,1,1,1
1,1,1,1,2,4,2,1,1,1,1
1,1,1,2,2,2,2,2,1,1,1
1,1,2,2,0,0,0,2,2,1,1
1,1,2,0,0,0,0,0,2,1,1
1,1,2,0,0,0,0,0,2,1,1
1,1,2,0,0,0,0,0,2,1,1
1,1,2,0,0,3,0,0,2,1,1
1,1,2,0,0,0,0,0,2,1,1
1,1,2,0,0,0,0,0,2,1,1
1,1,2,0,0,0,0,0,2,1,1
1,1,2,0,0,0,0,0,2,1,1
1,1,2,2,0,0,0,2,2,1,1
1,1,1,1,2,2,2,2,1,1,1
1,1,1,1,1,1,1,1,1,1,1
endlayer

layer
0,0,0,0,0,0,0,0,0,0,0
0,0,0,0,0,0,0,0,0,0,0
0,0,0,0,0,0,0,0,0,0,0
0,0,0,0,0,0,0,0,0,0,0
0,0,0,0,0,2,0,0,0,0,0
0,0,0,0,2,5,2,0,0,0,0
0,0,0,2,2,2,2,2,0,0,0
0,0,2,2,0,0,0,2,2,0,0
0,2,2,0,0,0,0,0,2,2,6
0,2,0,0,0,0,0,0,0,2,0
0,2,0,0,0,0,0,0,0,2,6
7,2,0,0,0,0,0,0,0,2,0
7,2,0,0,0,3,0,0,0,2,0
0,2,0,0,0,0,0,0,0,2,0
7,2,0,0,0,0,0,0,0,2,0
0,2,0,0,0,0,0,0,0,2,0
0,2,0,0,0,0,0,0,0,2,0
0,2,2,2,0,0,0,0,2,2,0
0,0,2,2,2,2,2,2,2,0,0
0,0,0,0,2,2,2,0,0,0,0
endlayer

layer
0,0,0,0,0,0,0,0,0,0,0
0,0,0,0,0,0,0,0,0,0,0
0,0,0,0,0,2,0,0,0,0,0
0,0,0,0,0,2,0,0,0,0,0
0,0,0,0,0,2,8,0,0,0,0
0,0,0,8,2,0,2,0,0,0,0
0,0,0,2,0,0,0,2,0,0,0
0,0,2,0,0,0,0,0,2,6,0
0,2,0,0,0,0,0,0,0,2,6
0,11,10,0,0,0,0,0,10,9,0
0,2,0,0,0,0,0,0,0,2,0
0,11,10,0,0,0,0,0,10,9,0
7,2,0,0,0,3,0,0,0,2,0
0,2,0,0,0,0,0,0,0,2,0
0,11,10,0,0,0,0,0,10,9,0
0,2,0,0,0,0,0,0,0,2,0
0,11,10,0,0,0,0,0,10,9,0
7,2,0,0,0,0,0,0,0,2,6
0,0,2,2,2,2,2,2,2,0,0
0,0,0,2,2,2,2,2,12,0,0
endlayer

layer
0,0,0,0,0,13,0,0,0,0,0
0,0,0,0,0,13,0,0,0,0,0
0,0,0,0,0,13,0,0,0,0,0
0,0,0,0,0,13,0,0,0,0,0
0,0,0,7,2,13,2,0,0,0,0
0,0,0,2,2,13,2,2,0,0,0
0,0,2,2,2,13,2,2,2,0,0
0,14,2,2,2,13,2,2,2,0,0
0,2,2,2,2,13,2,2,2,2,0
0,2,2,2,2,13,2,2,2,2,0
7,2,2,2,2,13,2,2,2,2,0
0,2,2,2,2,13,2,2,2,2,0
0,2,2,2,2,3,2,2,2,2,6
0,2,2,2,2,13,2,2,2,2,0
0,2,2,2,2,13,2,2,2,2,0
0,2,2,2,2,13,2,2,2,2,0
0,2,2,2,2,13,2,2,2,2,0
0,2,2,2,2,15,2,2,2,2,0
0,7,2,2,2,13,2,2,2,0,0
0,0,12,16,16,16,16,16,0,0,0
endlayer

layer
0,0,0,0,0,0,0,0,0,0,0
0,0,0,0,0,0,0,0,0,0,0
0,0,0,0,0,0,0,0,0,0,0
0,0,0,0,0,0,0,0,0,0,0
0,0,0,7,2,17,2,0,0,0,0
0,0,0,2,0,0,0,2,0,0,0
0,0,2,0,0,0,0,0,2,0,0
0,0,2,0,0,0,0,0,2,0,0
0,2,0,0,0,0,0,0,0,2,0
0,17,0,0,0,0,0,0,0,17,0
0,17,0,0,0,0,0,0,0,17,0
0,17,0,0,0,0,0,0,0,17,0
0,17,0,0,0,3,0,0,0,17,0
0,17,0,0,0,0,0,0,0,17,0
0,17,0,0,0,0,0,0,0,17,0
0,17,0,0,0,0,0,0,0,17,0
0,17,0,0,0,0,0,0,0,17,0
0,2,0,0,0,0,0,0,0,2,0
0,0,2,0,0,0,0,0,2,0,0
0,0,0,2,17,17,17,2,0,0,0
endlayer

layer
0,0,0,0,0,0,0,0,0,0,0
0,0,0,0,0,0,0,0,0,0,0
0,0,0,0,0,0,0,0,0,0,0
0,0,0,0,0,0,0,0,0,0,0
0,0,0,0,0,0,0,0,0,0,0
0,0,0,0,0,0,0,0,0,0,0
0,0,0,0,0,0,0,0,0,0,0
0,0,0,0,0,0,0,0,0,0,0
0,0,0,0,0,0,0,0,0,0,0
0,0,0,0,0,0,0,0,0,0,0
0,8,0,0,0,0,0,0,0,0,0
0,0,0,0,0,0,0,0,0,0,0
0,0,0,0,0,3,0,0,0,0,0
0,0,0,0,0,0,0,0,0,0,0
0,0,0,0,0,0,0,0,0,0,0
0,0,0,0,0,0,0,0,0,0,0
0,0,0,0,0,0,0,0,0,0,0
0,0,0,0,0,0,0,0,0,0,0
0,0,0,0,0,0,0,0,0,0,0
0,0,0,0,0,0,0,0,0,0,0
endlayer

layer
0,0,0,0,0,0,0,0,0,0,0
0,0,0,0,0,0,0,0,0,0,0
0,0,0,0,0,0,0,0,0,0,0
0,0,0,0,0,0,0,0,0,0,0
0,0,0,0,0,0,0,0,0,0,0
0,0,0,0,0,0,0,0,0,0,0
0,0,0,0,0,0,0,0,0,0,0
0,0,0,0,0,0,0,0,0,0,0
0,0,0,0,0,0,0,0,0,0,0
0,0,0,0,0,0,0,0,0,0,0
0,8,0,0,0,0,0,8,0,0,0
0,0,0,0,0,0,0,0,0,0,0
0,0,0,0,0,3,0,0,0,0,0
0,0,0,0,0,0,0,0,0,0,0
0,0,0,0,0,0,0,0,0,0,0
0,0,0,0,0,0,0,0,0,0,0
0,0,0,0,0,0,0,0,0,0,0
0,0,0,0,0,0,0,0,0,0,0
0,0,0,0,0,0,0,0,0,0,0
0,0,0,0,0,0,0,0,0,0,0
endlayer

layer
0,0,0,0,0,0,0,0,0,0,0
0,0,0,0,0,0,0,0,0,0,0
0,0,0,0,0,0,0,0,0,0,0
0,0,0,0,0,0,0,0,0,0,0
0,0,0,0,0,0,0,0,0,0,0
0,0,0,0,0,0,0,0,0,0,0
0,0,0,0,0,0,0,0,0,0,0
0,0,0,0,0,0,0,0,0,0,0
0,0,0,0,0,0,0,0,0,0,0
0,0,0,0,0,0,0,0,0,0,0
0,8,0,8,0,0,0,8,0,0,0
0,0,0,0,0,0,0,0,0,0,0
0,0,0,0,0,3,0,0,0,0,0
0,0,0,0,0,0,0,0,0,0,0
0,0,0,0,0,0,0,0,0,0,0
0,0,0,0,0,0,0,0,0,0,0
0,0,0,0,0,0,0,0,0,0,0
0,0,0,0,0,0,0,0,0,0,0
0,0,0,0,0,0,0,0,0,0,0
0,0,0,0,0,0,0,0,0,0,0
endlayer

layer
0,0,0,0,0,0,0,0,0,0,0
0,0,0,0,0,0,0,0,0,0,0
0,0,0,0,0,0,0,0,0,0,0
0,0,0,0,0,0,0,0,0,0,0
0,0,0,0,0,0,0,0,0,0,0
0,0,0,0,0,0,0,0,0,0,0
0,0,0,0,0,0,0,0,0,0,0
0,0,0,0,0,0,0,0,0,0,0
0,0,0,0,0,0,0,0,0,0,0
0,0,0,0,0,0,0,0,0,0,0
0,8,0,8,0,0,8,8,0,8,0
0,0,0,0,0,0,0,0,0,0,0
0,0,0,0,0,3,0,0,0,0,0
0,0,0,0,0,0,0,0,0,0,0
0,0,0,0,0,0,0,0,0,0,0
0,0,0,0,0,0,0,0,0,0,0
0,0,0,0,0,0,0,0,0,0,0
0,0,0,0,0,0,0,0,0,0,0
0,0,0,0,0,0,0,0,0,0,0
0,0,0,0,0,0,0,0,0,0,0
endlayer

layer
0,0,0,0,0,0,0,0,0,0,0
0,0,0,0,0,0,0,0,0,0,0
0,0,0,0,0,0,0,0,0,0,0
0,0,0,0,0,0,0,0,0,0,0
0,0,0,0,0,0,0,0,0,0,0
0,0,0,0,0,0,0,0,0,0,0
0,0,0,0,0,0,0,0,0,0,0
0,0,0,0,0,0,0,0,0,0,0
0,0,0,0,0,0,0,0,0,0,0
0,0,0,0,0,0,0,0,0,0,0
0,8,0,8,8,0,8,8,0,8,8
0,0,0,0,0,0,0,0,0,0,0
0,0,0,0,0,3,0,0,0,0,0
0,0,0,0,0,0,0,0,0,0,0
0,0,0,0,0,0,0,0,0,0,0
0,0,0,0,0,0,0,0,0,0,0
0,0,0,0,0,0,0,0,0,0,0
0,0,0,0,0,0,0,0,0,0,0
0,0,0,0,0,0,0,0,0,0,0
0,0,0,0,0,0,0,0,0,0,0
endlayer

layer
0,0,0,0,0,0,0,0,0,0,0
0,0,0,0,0,0,0,0,0,0,0
0,0,0,0,0,0,0,0,0,0,0
0,0,0,0,0,0,0,0,0,0,0
0,0,0,0,0,0,0,0,0,0,0
0,0,0,0,0,0,0,0,0,0,0
0,0,0,0,0,0,0,0,0,0,0
0,0,0,0,0,0,0,0,0,0,0
0,0,0,0,0,0,0,0,0,0,0
0,0,0,0,0,0,0,0,0,0,0
0,8,0,8,8,0,8,8,0,8,8
16,16,16,16,16,16,16,16,16,16,16
0,0,0,0,0,3,0,0,0,0,0
0,0,0,0,0,0,0,0,0,0,0
0,0,0,0,0,0,0,0,0,0,0
0,0,0,0,0,0,0,0,0,0,0
0,0,0,0,0,0,0,0,0,0,0
0,0,0,0,0,0,0,0,0,0,0
0,0,0,0,0,0,0,0,0,0,0
0,0,0,0,0,0,0,0,0,0,0
endlayer

layer
0,0,0,0,0,0,0,0,0,0,0
0,0,0,0,0,0,0,0,0,0,0
0,0,0,0,0,0,0,0,0,0,0
0,0,0,0,0,0,0,0,0,0,0
0,0,0,0,0,0,0,0,0,0,0
0,0,0,0,0,0,0,0,0,0,0
0,0,0,0,0,0,0,0,0,0,0
0,0,0,0,0,0,0,0,0,0,0
0,0,0,0,0,0,0,0,0,0,0
0,0,0,0,0,0,0,0,0,0,0
0,0,0,0,0,0,0,0,0,0,0
0,0,0,0,0,0,0,0,0,0,0
0,0,0,0,0,3,0,0,0,0,0
0,0,0,0,0,0,0,0,0,0,0
0,0,0,0,0,0,0,0,0,0,0
0,0,0,0,0,0,0,0,0,0,0
0,0,0,0,0,0,0,0,0,0,0
0,0,0,0,0,0,0,0,0,0,0
0,0,0,0,0,0,0,0,0,0,0
0,0,0,0,0,0,0,0,0,0,0
endlayer

layer
0,0,0,0,0,0,0,0,0,0,0
0,0,0,0,0,0,0,0,0,0,0
0,0,0,0,0,0,0,0,0,0,0
0,0,0,0,0,0,0,0,0,0,0
0,0,0,0,0,0,0,0,0,0,0
0,0,0,0,0,0,0,0,0,0,0
0,0,0,0,0,0,0,0,0,0,0
0,0,0,0,0,0,0,0,0,0,0
0,0,0,0,0,0,0,0,0,0,0
0,0,0,0,0,0,0,0,0,0,0
0,0,0,0,0,0,0,0,0,0,0
0,0,0,0,0,0,0,0,0,0,0
0,0,0,0,0,3,0,0,0,0,0
0,0,0,0,0,0,0,0,0,0,0
0,0,0,0,0,0,0,0,0,0,0
0,0,0,0,0,0,0,0,0,0,0
0,0,0,0,0,0,0,0,0,0,0
0,0,0,0,0,0,0,0,0,0,0
0,0,0,0,0,0,0,0,0,0,0
0,0,0,0,0,0,0,0,0,0,0
endlayer

layer
0,0,0,0,0,0,0,0,0,0,0
0,0,0,0,0,0,0,0,0,0,0
0,0,0,0,0,0,0,0,0,0,0
0,0,0,0,0,0,0,0,0,0,0
0,0,0,0,0,0,0,0,0,0,0
0,0,0,0,0,0,0,0,0,0,0
0,0,0,0,0,0,0,0,0,0,0
0,0,0,0,0,0,0,0,0,0,0
0,0,0,0,0,0,0,0,0,0,0
0,0,0,0,0,0,0,0,0,0,0
0,0,0,0,0,0,0,0,0,0,0
0,0,0,0,0,0,0,0,0,0,0
0,0,0,0,0,3,0,0,0,0,0
0,0,0,0,0,0,0,0,0,0,0
0,0,0,0,0,0,0,0,0,0,0
0,0,0,0,0,0,0,0,0,0,0
0,0,0,0,0,0,0,0,0,0,0
0,0,0,0,0,0,0,0,0,0,0
0,0,0,0,0,0,0,0,0,0,0
0,0,0,0,0,0,0,0,0,0,0
endlayer

