
# Created by Ruins mod version 14.7 Ingame Parser
# authoring Player: OneWolfe

weight=4
unique=1
embed_into_distance=5
biomesToSpawnIn=lake,swamp
acceptable_target_blocks=
unacceptable_target_blocks=flowing_water,water,flowing_lava,lava
dimensions=25,21,21
allowable_overhang=4
max_leveling=2
leveling_buffer=0
preserve_water=1
preserve_lava=0
preserve_plants=1

rule1=0,100,preserveBlock
rule2=0,100,terrafirmacraft:WoodVert-0
rule3=0,100,terrafirmacraft:StoneIgIn-0
rule4=0,100,terrafirmacraft:planks-1
rule5=0,100,minecraft:ladder-3
rule6=0,100,ChestGenHook:dungeonChest:5-3,ChestGenHook:dungeonChest:5-3,ChestGenHook:dungeonChest:5-3,preserveBlock,preserveBlock
rule7=0,100,terrafirmacraft:planks-2
rule8=0,100,terrafirmacraft:Fence-7
rule9=0,100,terrafirmacraft:WoodVert-2
rule10=0,100,terrafirmacraft:planks-0
rule11=0,100,terrafirmacraft:Fence-1
rule12=0,100,terrafirmacraft:Fence-0
rule13=0,100,terrafirmacraft:DoorOak-1
rule14=0,100,terrafirmacraft:WoodHoriz-2
rule15=0,100,terrafirmacraft:StoneIgExSmooth-1
rule16=0,100,terrafirmacraft:DoorOak-8
rule17=0,100,terrafirmacraft:FreshWaterStationary-0
rule18=0,100,minecraft:ladder-5
rule19=0,100,terrafirmacraft:planks-4
rule20=0,100,terrafirmacraft:WoodHoriz-12
rule21=0,100,terrafirmacraft:WoodHoriz-4
rule22=0,100,terrafirmacraft:WoodHoriz-8
rule23=0,100,terrafirmacraft:StoneSed-0
rule24=0,100,minecraft:trapdoor-10
rule25=0,100,Cogs:tile.steamPipe-0
rule26=0,100,BiblioCraft:BiblioTable-1
rule27=0,100,minecraft:bookshelf-0,minecraft:bookshelf-0,minecraft:bookshelf-0,air,air
rule28=0,100,Steamcraft:pipe-0,Steamcraft:pipe-0,Steamcraft:pipe-0,Steamcraft:pipe-0,Steamcraft:pipe-0,air,air
rule29=0,100,TwilightForest:tile.TFBossSpawner-1,TwilightForest:tile.TFBossSpawner-1,MobSpawner:TwilightForest.Death Tome,MobSpawner:TwilightForest.Skeleton Druid
rule30=0,100,BiblioCraft:BiblioTypewriter-4,BiblioCraft:BiblioTypewriter-4,air
rule31=0,100,BiblioCraft:BiblioClock-5,BiblioCraft:BiblioClock-5,air
rule32=0,100,ChestGenHook:dungeonChest:5-4,ChestGenHook:dungeonChest:5-4,air,air,air
rule33=0,100,Railcraft:glass-0
rule34=0,100,ChestGenHook:dungeonChest:5-2

layer
1,1,1,1,1,1,1,1,1,1,1,1,1,1,1,1,1,1,1,1,1
1,1,1,1,1,1,1,1,1,1,1,1,1,1,1,1,1,1,2,1,1
1,1,1,1,1,1,1,1,1,1,1,1,1,1,1,1,1,1,1,1,1
1,1,1,1,1,1,1,1,1,1,1,1,1,1,1,1,1,1,1,1,1
1,1,1,1,3,4,4,4,4,4,4,4,4,4,4,4,3,1,1,1,1
1,1,1,1,4,1,1,1,1,1,1,1,1,1,1,1,4,1,1,1,1
1,1,1,1,4,1,1,1,1,1,1,1,1,1,1,1,4,1,1,1,1
1,2,1,3,4,1,1,1,1,1,1,1,1,1,1,1,4,3,1,2,1
1,1,1,1,4,1,1,1,1,1,1,1,1,1,1,5,4,1,1,1,1
1,1,1,1,4,1,1,1,1,1,1,1,1,1,1,1,4,1,1,1,1
1,2,1,3,4,1,1,1,1,1,2,1,1,1,1,1,4,3,1,1,1
1,1,1,1,4,1,1,1,1,1,1,1,1,1,1,1,4,1,1,1,1
1,1,1,1,4,1,1,1,1,1,1,1,1,1,1,1,4,1,1,1,1
1,2,1,3,4,1,1,1,1,1,1,1,1,1,1,1,4,3,1,2,1
1,1,1,1,4,1,1,1,1,1,1,1,1,1,1,1,4,1,1,1,1
1,1,1,1,4,1,1,1,1,1,1,1,1,1,1,6,4,1,1,1,1
1,1,1,1,3,4,4,4,4,4,4,4,4,4,4,4,3,1,1,1,1
1,1,1,1,1,1,1,3,1,1,3,1,1,3,1,1,1,1,1,1,1
1,1,1,1,1,1,1,1,1,1,1,1,1,1,1,1,1,1,1,1,1
1,2,1,1,1,1,1,2,1,1,2,1,1,2,1,1,1,1,2,1,1
1,1,1,1,1,1,1,1,1,1,1,1,1,1,1,1,1,1,1,1,1
endlayer

layer
1,1,1,1,1,1,1,1,1,1,1,1,1,1,1,1,1,1,1,1,1
1,1,1,1,1,1,1,1,7,7,7,7,7,1,1,1,1,1,2,1,1
1,1,1,1,1,1,1,1,1,1,1,1,1,1,1,1,1,1,1,1,1
1,1,1,1,1,1,1,1,7,7,7,7,7,1,1,1,1,1,1,1,1
1,1,1,1,3,4,4,4,4,4,4,4,4,4,4,4,3,1,1,1,1
1,1,1,1,4,1,1,1,1,1,1,1,1,1,1,1,4,1,1,1,1
1,1,1,1,4,1,1,1,1,1,1,1,1,1,1,1,4,1,1,1,1
1,2,1,3,4,1,1,1,1,1,1,1,1,1,1,1,4,3,1,2,1
1,1,1,1,4,1,1,1,1,1,1,1,1,1,1,5,4,1,1,1,1
1,1,1,1,4,1,1,1,1,1,1,1,1,1,1,1,4,1,1,1,1
1,2,1,3,4,1,1,1,1,1,2,1,1,1,1,1,4,3,1,1,1
1,1,1,1,4,1,1,1,1,1,1,1,1,1,1,1,4,1,1,1,1
1,1,1,1,4,1,1,1,1,1,1,1,1,1,1,1,4,1,1,1,1
1,2,1,3,4,1,1,1,1,1,1,1,1,1,1,1,4,3,1,2,1
1,1,1,1,4,1,1,1,1,1,1,1,1,1,1,1,4,1,1,1,1
1,1,1,1,4,1,1,1,1,1,1,1,1,1,1,1,4,1,1,1,1
1,1,1,1,3,4,4,4,4,4,4,4,4,4,4,4,3,1,1,1,1
1,1,1,1,1,1,1,3,1,1,3,1,1,3,1,1,1,1,1,1,1
1,1,1,1,1,1,1,1,1,1,1,1,1,1,1,1,1,1,1,1,1
1,2,1,1,1,1,1,2,1,1,2,1,1,2,1,1,1,1,2,1,1
1,1,1,1,1,1,1,1,1,1,1,1,1,1,1,1,1,1,1,1,1
endlayer

layer
1,1,1,1,1,1,1,1,1,1,1,1,1,1,1,1,1,1,1,1,1
1,1,1,1,1,1,1,7,8,8,9,8,8,7,1,1,1,1,2,1,1
1,1,1,1,1,1,1,1,10,10,10,10,10,1,1,1,1,1,1,1,1
1,1,1,1,1,1,1,7,8,8,9,8,8,7,1,1,1,1,1,1,1
1,1,1,1,3,4,4,4,4,4,4,4,4,4,4,4,3,1,1,1,1
1,1,1,1,4,1,1,1,1,1,1,1,1,1,1,1,4,1,1,1,1
1,1,1,1,4,1,1,1,1,1,1,1,1,1,1,1,4,1,1,1,1
1,2,1,3,4,1,1,1,1,1,1,1,1,1,1,1,4,3,1,2,1
1,1,1,1,4,1,1,1,1,1,1,1,1,1,1,5,4,1,1,1,1
1,1,1,1,4,1,1,1,1,1,1,1,1,1,1,1,4,1,1,1,1
1,2,1,3,4,1,1,1,1,1,2,1,1,1,1,1,4,3,1,1,1
1,1,1,1,4,1,1,1,1,1,1,1,1,1,1,1,4,1,1,1,1
1,1,1,1,4,1,1,1,1,1,1,1,1,1,1,1,4,1,1,1,1
1,2,1,3,4,1,1,1,1,1,1,1,1,1,1,1,4,3,1,2,1
1,1,1,1,4,1,1,1,1,1,1,1,1,1,1,1,4,1,1,1,1
1,1,1,1,4,1,1,1,1,1,1,1,1,1,1,1,4,1,1,1,1
1,1,1,1,3,4,4,4,4,4,4,4,4,4,4,4,3,1,1,1,1
1,1,1,1,1,1,1,3,1,1,3,1,1,3,1,1,1,1,1,1,1
1,1,1,1,1,1,1,1,1,1,1,1,1,1,1,1,1,1,1,1,1
1,2,1,1,1,1,1,2,1,1,2,1,1,2,1,1,1,1,2,1,1
1,1,1,1,1,1,1,1,1,1,1,1,1,1,1,1,1,1,1,1,1
endlayer

layer
1,1,1,1,1,1,1,1,1,1,1,1,1,1,1,1,1,1,1,1,1
1,1,1,1,1,1,7,8,8,8,9,8,8,8,7,1,1,1,2,1,1
1,1,1,1,1,1,1,10,1,1,1,1,1,10,1,1,1,1,1,1,1
1,1,1,1,1,1,7,8,8,8,9,8,8,8,7,1,1,1,1,1,1
1,1,1,1,3,4,4,4,4,4,4,4,4,4,4,4,3,1,1,1,1
1,1,1,1,4,1,1,1,1,1,1,1,1,1,1,1,4,1,1,1,1
1,1,1,1,4,1,1,1,1,1,1,1,1,1,1,1,4,1,1,1,1
1,2,1,3,4,1,1,1,1,1,1,1,1,1,1,1,4,3,1,2,1
1,1,1,1,4,1,1,1,1,1,1,1,1,1,1,5,4,1,1,1,1
1,1,1,1,4,1,1,1,1,1,1,1,1,1,1,1,4,1,1,1,1
1,1,1,3,4,1,1,1,1,1,2,1,1,1,1,1,4,3,1,1,1
1,1,1,1,4,1,1,1,1,1,1,1,1,1,1,1,4,1,1,1,1
1,1,1,1,4,1,1,1,1,1,1,1,1,1,1,1,4,1,1,1,1
1,2,1,3,4,1,1,1,1,1,1,1,1,1,1,1,4,3,1,2,1
1,1,1,1,4,1,1,1,1,1,1,1,1,1,1,1,4,1,1,1,1
1,1,1,1,4,1,1,1,1,1,1,1,1,1,1,1,4,1,1,1,1
1,1,1,1,3,4,4,4,4,4,4,4,4,4,4,4,3,1,1,1,1
1,1,1,1,1,1,1,3,1,1,3,1,1,3,1,1,1,1,1,1,1
1,1,1,1,1,1,1,1,1,1,1,1,1,1,1,1,1,1,1,1,1
1,1,1,1,1,1,1,1,1,1,2,1,1,2,1,1,1,1,2,1,1
1,1,1,1,1,1,1,1,1,1,1,1,1,1,1,1,1,1,1,1,1
endlayer

layer
1,1,1,1,1,1,1,1,1,1,1,1,1,1,1,1,1,1,1,1,1
1,1,1,1,1,7,8,8,8,8,9,8,8,8,8,7,1,10,2,10,1
1,1,1,1,1,1,10,1,1,1,1,1,1,1,10,1,1,10,10,10,1
1,1,1,1,1,7,8,8,8,8,9,8,8,8,8,7,1,10,10,10,1
1,1,1,1,3,4,4,4,4,4,4,4,4,4,4,4,3,10,10,10,1
1,1,1,1,4,1,1,1,1,1,1,1,1,1,1,1,4,10,10,10,1
1,1,1,1,4,1,1,1,1,1,1,1,1,1,1,1,4,10,10,10,1
1,2,10,3,4,1,1,1,1,1,1,1,1,1,1,1,4,3,10,2,1
1,1,10,10,4,1,1,1,1,7,7,7,1,1,1,5,4,10,10,10,1
1,10,10,10,4,1,1,1,1,7,7,7,1,10,10,10,4,10,10,10,10
1,1,1,3,4,1,1,1,1,1,2,1,1,10,10,10,4,10,10,10,10
1,1,1,10,4,1,1,1,1,1,1,1,1,10,10,10,4,10,10,10,10
1,1,1,10,4,1,1,1,1,1,1,1,1,10,10,10,4,10,10,10,1
1,2,1,3,4,1,1,1,1,1,1,1,1,10,10,10,4,3,10,2,1
1,1,1,10,4,1,1,1,1,1,1,1,1,10,10,10,4,10,10,10,1
1,1,10,10,4,1,1,1,1,1,1,1,1,10,10,10,4,10,10,10,1
1,1,10,10,3,4,4,4,4,4,4,4,4,4,4,4,3,10,10,10,1
1,1,1,10,10,10,10,3,1,1,3,10,10,3,10,10,10,10,10,10,1
1,1,1,1,10,10,10,1,1,10,10,10,10,10,10,10,10,10,10,10,1
1,1,1,1,1,1,1,1,1,10,2,10,10,2,10,10,10,10,2,10,1
1,1,1,1,1,1,1,1,1,1,1,1,1,1,1,1,1,1,1,1,1
endlayer

layer
0,0,0,0,0,0,0,0,0,0,0,0,0,0,0,0,0,0,0,0,0
0,0,0,0,0,7,8,8,8,8,9,8,8,8,8,7,0,11,2,11,0
0,0,0,0,0,12,10,0,0,0,0,0,0,0,10,0,0,0,0,11,0
0,0,0,0,0,7,8,8,8,8,9,8,8,8,8,7,0,0,0,11,0
0,0,0,0,3,4,4,4,4,4,4,4,4,4,4,4,3,0,0,11,0
0,0,0,0,4,0,0,0,0,0,0,0,0,0,0,0,4,0,0,11,0
0,11,0,0,4,0,0,0,0,0,0,0,0,0,0,0,4,0,0,11,0
0,2,0,3,4,0,0,0,0,0,0,0,0,0,0,0,4,3,0,2,0
0,11,0,0,4,0,0,0,7,13,9,13,7,0,0,0,4,0,0,11,0
0,0,0,0,4,0,0,0,7,13,9,13,7,11,11,0,4,3,0,0,0
0,0,0,3,4,0,0,0,0,0,2,0,0,11,0,0,14,0,0,0,0
0,0,0,0,4,0,0,0,0,0,0,0,0,11,0,0,4,3,0,0,0
0,0,0,0,4,0,0,0,0,0,0,0,0,11,0,0,4,0,0,11,0
0,2,0,3,4,0,0,0,0,0,0,0,10,11,0,0,4,3,0,2,0
0,0,0,0,4,0,0,0,0,0,0,0,10,0,0,0,4,0,0,11,0
0,0,0,0,4,0,0,0,0,0,0,0,10,0,0,0,4,0,0,11,0
0,0,0,0,3,4,4,4,4,4,4,4,4,4,4,4,3,0,0,11,0
0,0,0,0,0,0,0,3,0,0,3,0,0,3,0,0,0,0,0,11,0
0,0,0,0,0,0,0,0,0,0,0,0,0,0,0,0,0,0,0,11,0
0,0,0,0,0,0,0,0,11,11,2,11,11,2,11,11,11,11,2,11,0
0,0,0,0,0,0,0,0,0,0,0,0,0,0,0,0,0,0,0,0,0
endlayer

layer
0,0,0,0,0,0,0,0,0,0,0,0,0,0,0,0,0,0,0,0,0
0,0,0,0,0,7,15,15,15,15,16,15,15,15,15,7,0,0,0,0,0
0,0,0,0,0,12,10,0,0,0,16,0,0,0,10,0,0,0,0,0,0
0,0,0,0,0,7,15,15,15,15,16,15,15,15,15,7,0,0,0,0,0
0,0,0,0,3,4,4,4,4,4,16,4,4,4,4,4,3,0,0,0,0
0,0,0,0,4,0,0,0,0,0,16,0,0,0,0,0,4,0,0,0,0
0,0,0,0,4,0,0,0,0,0,16,0,0,0,0,0,4,0,0,0,0
0,2,0,3,4,0,0,0,0,0,16,0,0,0,0,0,4,3,0,2,0
0,0,0,0,11,0,0,0,7,15,16,15,7,0,0,0,11,0,0,0,0
0,0,0,0,11,0,0,0,7,15,16,15,7,0,0,0,4,3,0,0,0
0,0,0,3,4,0,0,0,0,0,2,0,0,0,0,0,17,0,0,0,0
0,0,0,0,11,0,0,0,0,0,0,0,0,0,0,0,4,3,0,0,0
0,0,0,0,11,0,0,0,0,0,0,0,0,0,0,0,11,0,0,0,0
0,0,0,3,4,0,0,0,10,10,10,10,11,0,0,0,4,3,0,0,0
0,0,0,0,4,0,0,0,10,10,10,10,0,0,0,0,4,0,0,0,0
0,0,0,0,4,0,0,0,10,10,10,10,0,0,0,0,4,0,0,0,0
0,0,0,0,3,4,4,4,11,11,4,11,11,4,4,4,3,0,0,0,0
0,0,0,0,0,0,0,3,0,0,3,0,0,3,0,0,0,0,0,0,0
0,0,0,0,0,0,0,0,0,0,0,0,0,0,0,0,0,0,0,0,0
0,0,0,0,0,0,0,0,0,0,2,0,0,0,0,0,0,0,2,0,0
0,0,0,0,0,0,0,0,0,0,0,0,0,0,0,0,0,0,0,0,0
endlayer

layer
0,0,0,0,0,0,0,0,0,0,0,0,0,0,0,0,0,0,0,0,0
0,0,0,0,0,7,8,8,8,8,9,8,8,8,8,7,0,0,0,0,0
0,0,0,0,0,12,10,0,0,0,0,0,0,0,10,0,0,0,0,0,0
0,0,0,0,0,7,8,8,8,8,9,8,8,8,8,7,0,0,0,0,0
0,0,0,0,3,4,4,4,4,4,4,4,4,4,4,4,3,0,0,0,0
0,0,0,0,4,0,0,0,0,0,0,0,0,0,0,0,4,0,0,0,0
0,0,0,0,4,0,0,0,0,0,0,0,0,0,0,0,4,0,0,0,0
0,0,0,3,4,0,0,0,0,0,0,0,0,0,0,0,4,3,0,0,0
0,0,0,0,11,10,10,0,7,13,9,13,7,0,0,0,11,0,0,0,0
0,0,0,0,11,10,10,0,7,13,9,13,7,0,0,0,4,3,0,0,0
0,0,0,3,4,10,10,0,0,0,2,0,0,0,0,0,4,3,0,0,0
0,0,0,0,11,10,10,0,0,0,0,0,0,0,0,0,4,3,0,0,0
0,0,0,0,11,10,10,0,0,0,0,0,0,0,0,0,11,0,0,0,0
0,0,0,3,4,10,10,10,11,11,11,11,0,0,0,0,4,3,0,0,0
0,0,0,0,4,10,10,10,0,0,0,0,0,0,0,0,4,0,0,0,0
0,0,0,0,4,10,10,10,0,0,0,0,0,0,0,0,4,0,0,0,0
0,0,0,0,3,4,4,4,11,11,4,11,11,4,4,4,3,0,0,0,0
0,0,0,0,0,0,0,3,0,0,3,0,0,3,0,0,0,0,0,0,0
0,0,0,0,0,0,0,0,0,0,0,0,0,0,0,0,0,0,0,0,0
0,0,0,0,0,0,0,0,0,0,0,0,0,0,0,0,0,0,0,0,0
0,0,0,0,0,0,0,0,0,0,0,0,0,0,0,0,0,0,0,0,0
endlayer

layer
0,0,0,0,0,0,0,0,0,0,0,0,0,0,0,0,0,0,0,0,0
0,0,0,0,0,7,8,8,8,8,9,8,8,8,8,7,0,0,0,0,0
0,0,0,0,0,12,10,0,0,0,0,0,0,0,10,0,0,0,0,0,0
0,0,0,0,0,7,8,8,8,8,9,8,8,8,8,7,0,0,0,0,0
0,0,0,0,3,4,4,4,4,4,4,4,4,4,4,4,3,0,0,0,0
0,0,0,0,4,10,10,10,10,10,10,10,10,10,10,10,4,0,0,0,0
0,0,0,0,4,10,10,10,10,10,10,10,10,10,10,10,4,0,0,0,0
0,0,0,3,4,10,10,0,0,0,0,0,0,10,10,10,4,3,0,0,0
0,0,0,0,4,0,11,0,0,7,7,7,0,0,10,10,4,0,0,0,0
0,0,0,0,4,0,11,0,0,7,7,7,0,0,10,10,4,0,0,0,0
0,0,0,3,4,0,11,0,0,0,2,0,0,0,0,0,4,3,0,0,0
0,0,0,0,4,0,11,0,0,0,0,0,0,0,0,0,4,0,0,0,0
0,0,0,0,4,0,11,0,0,0,0,0,0,0,0,0,4,0,0,0,0
0,0,0,3,4,0,11,11,0,0,0,0,0,0,0,0,4,3,0,0,0
0,0,0,0,4,0,0,0,0,0,0,0,0,0,0,0,4,0,0,0,0
0,0,0,0,4,0,0,0,0,0,0,0,0,0,0,0,4,0,0,0,0
0,0,0,0,3,4,4,4,4,4,4,4,4,4,4,4,3,0,0,0,0
0,0,0,0,0,0,0,3,0,0,3,0,0,3,0,0,0,0,0,0,0
0,0,0,0,0,0,0,0,0,0,0,0,0,0,0,0,0,0,0,0,0
0,0,0,0,0,0,0,0,0,0,0,0,0,0,0,0,0,0,0,0,0
0,0,0,0,0,0,0,0,0,0,0,0,0,0,0,0,0,0,0,0,0
endlayer

layer
0,0,0,0,0,0,0,0,0,0,0,0,0,0,0,0,0,0,0,0,0
0,0,0,0,0,0,7,8,8,8,9,8,8,8,7,0,0,0,0,0,0
0,0,0,0,0,0,12,10,0,0,0,0,0,10,0,0,10,0,0,0,0
0,0,0,0,0,0,7,8,8,8,9,8,8,8,7,0,10,0,0,0,0
0,0,0,0,3,4,4,4,4,4,4,4,4,4,4,4,3,0,0,0,0
0,0,0,0,4,0,0,0,0,0,0,0,0,0,0,0,4,0,0,0,0
0,0,0,0,4,0,11,11,11,11,11,11,11,4,11,0,4,0,0,0,0
0,0,0,3,4,0,11,0,0,19,19,19,0,18,0,0,4,3,0,0,0
0,0,0,0,4,0,0,0,19,11,20,11,19,0,11,0,4,0,0,0,0
0,0,0,0,4,0,0,19,11,11,20,11,11,19,11,11,4,0,0,0,0
0,0,0,3,4,0,0,19,21,21,2,21,21,19,0,0,4,3,0,0,0
0,0,0,0,4,0,0,19,11,11,20,11,11,19,0,0,4,0,0,0,0
0,0,0,0,4,0,0,0,19,11,20,11,19,0,0,0,4,0,0,0,0
0,0,0,3,4,0,0,0,0,19,19,19,0,0,0,0,4,3,0,0,0
0,0,0,0,4,0,0,0,0,0,0,0,0,0,0,0,4,0,0,0,0
0,0,0,0,4,0,0,0,0,0,0,0,0,0,0,0,4,0,0,0,0
0,0,0,0,3,4,4,4,4,4,4,4,4,4,4,4,3,0,0,0,0
0,0,0,0,0,0,0,3,0,0,3,0,0,3,0,0,0,0,0,0,0
0,0,0,0,0,0,0,0,0,0,0,0,0,0,0,0,0,0,0,0,0
0,0,0,0,0,0,0,0,0,0,0,0,0,0,0,0,0,0,0,0,0
0,0,0,0,0,0,0,0,0,0,0,0,0,0,0,0,0,0,0,0,0
endlayer

layer
0,0,0,0,0,0,0,0,0,0,0,0,0,0,0,0,0,0,0,0,0
0,0,0,0,0,0,0,7,8,8,9,8,8,7,0,0,0,0,0,0,0
0,0,0,0,0,0,0,12,10,10,10,10,10,0,0,10,13,10,0,0,0
0,0,0,0,0,0,0,7,8,8,9,8,8,7,0,10,13,10,0,0,0
0,0,0,0,3,4,4,4,4,4,4,4,4,4,4,4,3,0,0,0,0
0,0,0,0,4,0,0,0,0,0,0,0,0,0,0,0,4,0,0,0,0
0,0,0,0,4,0,0,0,0,0,0,0,0,4,11,0,4,0,0,0,0
0,0,0,3,4,0,0,0,0,19,19,19,0,18,0,0,4,3,0,0,0
0,0,0,0,4,0,0,0,19,11,20,11,19,0,0,0,4,0,0,0,0
0,0,0,0,4,0,0,19,11,11,20,11,11,19,0,0,4,0,0,0,0
0,0,0,3,4,0,0,19,21,21,2,21,21,19,0,0,4,3,0,0,0
0,0,0,0,4,0,0,19,11,11,20,11,11,19,0,0,4,0,0,0,0
0,0,0,0,4,0,0,0,19,11,20,11,19,0,0,0,4,0,0,0,0
0,0,0,3,4,0,0,0,0,19,19,19,0,0,0,0,4,3,0,0,0
0,0,0,0,4,0,0,0,0,0,0,0,0,0,0,0,4,0,0,0,0
0,0,0,0,4,0,0,0,0,0,0,0,0,0,0,0,4,0,0,0,0
0,0,0,0,3,4,4,4,4,4,4,4,4,4,4,4,3,0,0,0,0
0,0,0,0,0,0,0,3,0,0,3,0,0,3,0,0,0,0,0,0,0
0,0,0,0,0,0,0,0,0,0,0,0,0,0,0,0,0,0,0,0,0
0,0,0,0,0,0,0,0,0,0,0,0,0,0,0,0,0,0,0,0,0
0,0,0,0,0,0,0,0,0,0,0,0,0,0,0,0,0,0,0,0,0
endlayer

layer
0,0,0,0,0,0,0,0,0,0,0,0,0,0,0,0,0,0,0,0,0
0,0,0,0,0,0,0,0,7,7,7,7,7,0,0,0,0,0,0,0,0
0,0,0,0,0,0,0,0,12,12,7,0,0,0,10,13,22,13,10,0,0
0,0,0,0,0,0,0,0,7,7,7,7,7,0,10,13,22,13,10,0,0
0,0,0,0,3,3,3,3,3,3,3,3,3,3,3,3,3,0,0,0,0
0,0,0,0,3,0,0,0,0,0,0,0,0,0,0,0,3,0,0,0,0
0,0,0,0,3,0,0,0,0,0,0,0,0,4,11,0,3,0,0,0,0
0,0,0,0,3,0,0,0,0,0,0,0,0,18,0,0,3,0,0,0,0
0,0,0,0,3,0,0,0,0,0,0,0,0,0,0,0,3,0,0,0,0
0,0,0,0,3,0,0,0,0,0,0,0,0,0,0,0,3,0,0,0,0
0,0,0,0,3,0,0,0,0,0,2,0,0,0,0,0,3,0,0,0,0
0,0,0,0,3,0,0,0,0,0,0,0,0,0,0,0,3,0,0,0,0
0,0,0,0,3,0,0,0,0,0,0,0,0,0,0,0,3,0,0,0,0
0,0,0,0,3,0,0,0,0,0,0,0,0,0,0,0,3,0,0,0,0
0,0,0,0,3,0,0,0,0,0,0,0,0,0,0,0,3,0,0,0,0
0,0,0,0,3,0,0,0,0,0,0,0,0,0,0,4,3,0,0,0,0
0,0,0,0,3,3,3,3,3,3,3,3,3,3,3,3,3,0,0,0,0
0,0,0,0,0,0,0,0,0,0,0,0,0,0,0,0,0,0,0,0,0
0,0,0,0,0,0,0,0,0,0,0,0,0,0,0,0,0,0,0,0,0
0,0,0,0,0,0,0,0,0,0,0,0,0,0,0,0,0,0,0,0,0
0,0,0,0,0,0,0,0,0,0,0,0,0,0,0,0,0,0,0,0,0
endlayer

layer
0,0,0,0,0,0,0,0,0,0,0,0,0,0,0,0,0,0,0,0,0
0,0,0,0,0,0,0,0,0,0,0,0,0,0,0,0,0,0,0,0,0
0,0,0,0,0,0,0,0,0,0,0,0,0,0,0,10,13,10,0,0,0
0,0,0,0,0,0,0,0,0,0,0,0,0,0,0,10,13,10,0,0,0
0,0,0,0,0,0,0,0,0,0,0,0,0,0,0,0,0,0,0,0,0
0,0,0,0,0,4,4,4,4,4,4,4,4,4,4,4,0,0,0,0,0
0,0,0,0,0,4,0,0,0,0,0,0,0,4,11,4,0,0,0,0,0
0,0,0,0,0,4,0,0,0,0,0,0,0,18,0,4,0,0,0,0,0
0,0,0,0,0,4,0,0,0,0,0,0,0,0,0,4,0,0,0,0,0
0,0,0,0,0,4,0,0,0,0,0,0,0,0,0,4,0,0,0,0,0
0,0,0,0,0,4,0,0,0,0,2,0,0,0,0,4,0,0,0,0,0
0,0,0,0,0,4,0,0,0,0,0,0,0,0,0,4,0,0,0,0,0
0,0,0,0,0,4,0,0,0,0,0,0,0,0,0,4,0,0,0,0,0
0,0,0,0,0,4,0,0,0,0,0,0,0,0,0,4,0,0,0,0,0
0,0,0,0,0,4,0,0,0,0,0,0,0,0,0,4,0,0,0,0,0
0,0,0,0,0,4,4,4,4,4,4,4,4,4,4,4,0,0,0,0,0
0,0,0,0,0,0,0,0,0,0,0,0,0,0,0,0,0,0,0,0,0
0,0,0,0,0,0,0,0,0,0,0,0,0,0,0,0,0,0,0,0,0
0,0,0,0,0,0,0,0,0,0,0,0,0,0,0,0,0,0,0,0,0
0,0,0,0,0,0,0,0,0,0,0,0,0,0,0,0,0,0,0,0,0
0,0,0,0,0,0,0,0,0,0,0,0,0,0,0,0,0,0,0,0,0
endlayer

layer
0,0,0,0,0,0,0,0,0,0,0,0,0,0,0,0,0,0,0,0,0
0,0,0,0,0,0,0,0,0,0,0,0,0,0,0,0,0,0,0,0,0
0,0,0,0,0,0,0,0,23,23,23,23,23,0,0,0,10,0,0,0,0
0,0,0,0,0,0,23,23,23,23,4,23,23,23,23,0,10,0,0,0,0
0,0,0,0,0,23,23,23,23,23,4,23,23,23,23,23,0,0,0,0,0
0,0,0,0,23,23,23,23,23,23,4,23,23,23,23,23,23,0,0,0,0
0,0,0,23,23,23,4,23,23,23,4,23,23,4,4,23,23,23,0,0,0
0,0,0,23,23,23,23,23,23,23,4,23,23,18,23,23,23,23,0,0,0
0,0,23,23,23,23,23,23,23,23,4,23,23,23,23,23,23,23,23,0,0
0,0,23,23,23,23,23,23,23,23,4,23,23,23,23,23,23,23,23,0,0
0,0,23,4,4,4,4,4,4,4,2,4,4,4,4,4,4,4,23,0,0
0,0,23,23,23,23,23,23,23,23,4,23,23,23,23,23,23,23,23,0,0
0,0,23,23,23,23,23,23,23,23,4,23,23,23,23,23,23,23,23,0,0
0,0,0,23,23,23,23,23,23,23,4,23,23,23,23,23,23,23,0,0,0
0,0,0,23,23,23,4,23,23,23,4,23,23,23,4,23,23,23,0,0,0
0,0,0,0,23,23,23,23,23,23,4,23,23,23,23,23,23,0,0,0,0
0,0,0,0,0,23,23,23,23,23,4,23,23,23,23,23,0,0,0,0,0
0,0,0,0,0,0,23,23,23,23,4,23,23,23,23,0,0,0,0,0,0
0,0,0,0,0,0,0,0,23,23,23,23,23,0,0,0,0,0,0,0,0
0,0,0,0,0,0,0,0,0,0,0,0,0,0,0,0,0,0,0,0,0
0,0,0,0,0,0,0,0,0,0,0,0,0,0,0,0,0,0,0,0,0
endlayer

layer
0,0,0,0,0,0,0,0,0,0,0,0,0,0,0,0,0,0,0,0,0
0,0,0,0,0,0,0,0,0,0,0,0,0,0,0,0,0,0,0,0,0
0,0,0,0,0,0,0,0,0,0,0,0,0,0,0,0,0,0,0,0,0
0,0,0,0,0,0,0,0,4,4,4,4,4,0,0,0,0,0,0,0,0
0,0,0,0,0,0,4,4,0,0,4,0,0,4,4,0,0,0,0,0,0
0,0,0,0,0,4,0,0,0,0,4,0,0,0,0,4,0,0,0,0,0
0,0,0,0,4,0,4,0,0,0,4,0,0,4,4,0,4,0,0,0,0
0,0,0,0,4,0,0,0,0,0,4,0,4,18,4,0,4,0,0,0,0
0,0,0,4,0,0,0,0,0,0,4,0,0,4,0,0,0,4,0,0,0
0,0,0,4,0,0,0,0,0,0,4,0,0,0,0,0,0,4,0,0,0
0,0,0,4,4,4,4,4,4,4,4,4,4,4,4,4,4,4,0,0,0
0,0,0,4,0,0,0,0,0,0,4,0,0,0,0,0,0,4,0,0,0
0,0,0,4,0,0,0,0,0,0,4,0,0,0,0,0,0,4,0,0,0
0,0,0,0,4,0,0,0,0,0,4,0,0,0,0,0,4,0,0,0,0
0,0,0,0,4,0,4,0,0,0,4,0,0,0,4,0,4,0,0,0,0
0,0,0,0,0,4,0,0,0,0,4,0,0,0,0,4,0,0,0,0,0
0,0,0,0,0,0,4,4,0,0,4,0,0,4,4,0,0,0,0,0,0
0,0,0,0,0,0,0,0,4,4,4,4,4,0,0,0,0,0,0,0,0
0,0,0,0,0,0,0,0,0,0,0,0,0,0,0,0,0,0,0,0,0
0,0,0,0,0,0,0,0,0,0,0,0,0,0,0,0,0,0,0,0,0
0,0,0,0,0,0,0,0,0,0,0,0,0,0,0,0,0,0,0,0,0
endlayer

layer
0,0,0,0,0,0,0,0,0,0,0,0,0,0,0,0,0,0,0,0,0
0,0,0,0,0,0,0,0,0,0,0,0,0,0,0,0,0,0,0,0,0
0,0,0,0,0,0,0,0,23,23,23,23,23,0,0,0,0,0,0,0,0
0,0,0,0,0,0,23,23,23,23,4,23,23,23,23,0,0,0,0,0,0
0,0,0,0,0,23,23,23,23,23,4,23,23,23,23,23,0,0,0,0,0
0,0,0,0,23,23,23,23,23,23,4,23,23,23,23,23,23,0,0,0,0
0,0,0,23,23,23,4,23,23,23,4,23,23,4,4,23,23,23,0,0,0
0,0,0,23,23,23,23,23,23,23,4,23,4,24,4,23,23,23,0,0,0
0,0,23,23,23,23,23,23,23,23,4,23,23,4,23,23,23,23,23,0,0
0,0,23,23,23,23,23,23,23,23,4,23,23,23,23,23,23,23,23,0,0
0,0,23,4,4,4,4,4,4,4,25,4,4,4,4,4,4,4,23,0,0
0,0,23,23,23,23,23,23,23,23,4,23,23,23,23,23,23,23,23,0,0
0,0,23,23,23,23,23,23,23,23,4,23,23,23,23,23,23,23,23,0,0
0,0,0,23,23,23,23,23,23,23,4,23,23,23,23,23,23,23,0,0,0
0,0,0,23,23,23,4,23,23,23,4,23,23,23,4,23,23,23,0,0,0
0,0,0,0,23,23,23,23,23,23,4,23,23,23,23,23,23,0,0,0,0
0,0,0,0,0,23,23,23,23,23,4,23,23,23,23,23,0,0,0,0,0
0,0,0,0,0,0,23,23,23,23,4,23,23,23,23,0,0,0,0,0,0
0,0,0,0,0,0,0,0,23,23,23,23,23,0,0,0,0,0,0,0,0
0,0,0,0,0,0,0,0,0,0,0,0,0,0,0,0,0,0,0,0,0
0,0,0,0,0,0,0,0,0,0,0,0,0,0,0,0,0,0,0,0,0
endlayer

layer
0,0,0,0,0,0,0,0,0,0,0,0,0,0,0,0,0,0,0,0,0
0,0,0,0,0,0,0,0,0,0,0,0,0,0,0,0,0,0,0,0,0
0,0,0,0,0,0,0,0,11,11,11,11,11,0,0,0,0,0,0,0,0
0,0,0,0,0,0,11,11,11,0,0,0,11,11,11,0,0,0,0,0,0
0,0,0,0,0,11,11,0,0,0,0,0,0,0,11,11,0,0,0,0,0
0,0,0,0,11,11,0,0,0,7,7,7,0,0,0,11,11,0,0,0,0
0,0,0,11,11,0,0,7,7,26,26,26,7,7,0,0,11,11,0,0,0
0,0,0,11,0,0,7,27,0,0,0,0,0,0,7,0,0,11,0,0,0
0,0,11,11,0,0,7,0,0,0,0,0,0,0,7,0,0,11,11,0,0
0,0,11,0,0,7,0,0,28,0,28,0,0,0,0,7,0,0,11,0,0
0,0,11,0,0,7,0,0,0,0,25,29,0,0,0,14,0,0,11,0,0
0,0,11,0,0,7,0,0,28,0,28,0,0,0,0,7,0,0,11,0,0
0,0,11,11,0,0,7,0,0,0,0,0,0,0,7,0,0,11,11,0,0
0,0,0,11,0,0,7,27,0,0,0,0,0,27,7,0,0,11,0,0,0
0,0,0,11,11,0,0,7,7,26,26,26,7,7,0,0,11,11,0,0,0
0,0,0,0,11,11,0,0,0,7,7,7,0,0,0,11,11,0,0,0,0
0,0,0,0,0,11,11,0,0,0,0,0,0,0,11,11,0,0,0,0,0
0,0,0,0,0,0,11,11,11,0,0,0,11,11,11,0,0,0,0,0,0
0,0,0,0,0,0,0,0,11,11,11,11,11,0,0,0,0,0,0,0,0
0,0,0,0,0,0,0,0,0,0,0,0,0,0,0,0,0,0,0,0,0
0,0,0,0,0,0,0,0,0,0,0,0,0,0,0,0,0,0,0,0,0
endlayer

layer
0,0,0,0,0,0,0,0,0,0,0,0,0,0,0,0,0,0,0,0,0
0,0,0,0,0,0,0,0,0,0,0,0,0,0,0,0,0,0,0,0,0
0,0,0,0,0,0,0,0,0,0,0,0,0,0,0,0,0,0,0,0,0
0,0,0,0,0,0,0,0,0,0,0,0,0,0,0,0,0,0,0,0,0
0,0,0,0,0,0,0,0,0,0,0,0,0,0,0,0,0,0,0,0,0
0,0,0,0,0,0,0,0,0,7,7,7,0,0,0,0,0,0,0,0,0
0,0,0,0,0,0,0,7,7,31,0,30,7,7,0,0,0,0,0,0,0
0,0,0,0,0,7,7,27,0,0,0,0,0,0,7,0,0,0,0,0,0
0,0,0,0,0,7,7,0,0,0,0,0,0,0,7,0,0,0,0,0,0
0,0,0,0,0,0,0,0,28,0,28,0,0,0,0,7,0,0,0,0,0
0,0,0,0,0,0,0,0,0,0,25,0,0,0,0,17,0,0,0,0,0
0,0,0,0,0,0,0,0,28,0,28,0,0,0,0,7,0,0,0,0,0
0,0,0,0,0,7,7,0,0,0,0,0,0,0,7,0,0,0,0,0,0
0,0,0,0,0,7,7,27,0,0,0,0,0,27,7,0,0,0,0,0,0
0,0,0,0,0,0,0,7,7,0,32,0,7,7,0,0,0,0,0,0,0
0,0,0,0,0,0,0,0,0,7,7,7,0,0,0,0,0,0,0,0,0
0,0,0,0,0,0,0,0,0,0,0,0,0,0,0,0,0,0,0,0,0
0,0,0,0,0,0,0,0,0,0,0,0,0,0,0,0,0,0,0,0,0
0,0,0,0,0,0,0,0,0,0,0,0,0,0,0,0,0,0,0,0,0
0,0,0,0,0,0,0,0,0,0,0,0,0,0,0,0,0,0,0,0,0
0,0,0,0,0,0,0,0,0,0,0,0,0,0,0,0,0,0,0,0,0
endlayer

layer
0,0,0,0,0,0,0,0,0,0,0,0,0,0,0,0,0,0,0,0,0
0,0,0,0,0,0,0,0,0,0,0,0,0,0,0,0,0,0,0,0,0
0,0,0,0,0,0,0,0,0,0,0,0,0,0,0,0,0,0,0,0,0
0,0,0,0,0,0,0,0,0,0,0,0,0,0,0,0,0,0,0,0,0
0,0,0,0,0,0,0,0,0,0,0,0,0,0,0,0,0,0,0,0,0
0,0,0,0,0,0,0,0,0,7,7,7,0,0,0,0,0,0,0,0,0
0,0,0,0,0,0,0,7,7,0,0,0,7,7,0,0,0,0,0,0,0
0,0,0,0,0,7,7,27,0,0,0,0,0,0,7,0,0,0,0,0,0
0,0,0,0,0,7,7,0,0,0,0,0,0,0,7,0,0,0,0,0,0
0,0,0,0,0,0,0,0,28,0,28,0,0,0,0,7,0,0,0,0,0
0,0,0,0,0,0,0,25,25,25,25,0,0,0,0,7,0,0,0,0,0
0,0,0,0,0,0,0,0,28,0,28,0,0,0,0,7,0,0,0,0,0
0,0,0,0,0,7,7,0,0,0,0,0,0,0,7,0,0,0,0,0,0
0,0,0,0,0,7,7,27,0,0,0,0,0,27,7,0,0,0,0,0,0
0,0,0,0,0,0,0,7,7,0,0,0,7,7,0,0,0,0,0,0,0
0,0,0,0,0,0,0,0,0,7,7,7,0,0,0,0,0,0,0,0,0
0,0,0,0,0,0,0,0,0,0,0,0,0,0,0,0,0,0,0,0,0
0,0,0,0,0,0,0,0,0,0,0,0,0,0,0,0,0,0,0,0,0
0,0,0,0,0,0,0,0,0,0,0,0,0,0,0,0,0,0,0,0,0
0,0,0,0,0,0,0,0,0,0,0,0,0,0,0,0,0,0,0,0,0
0,0,0,0,0,0,0,0,0,0,0,0,0,0,0,0,0,0,0,0,0
endlayer

layer
0,0,0,0,0,0,0,0,0,0,0,0,0,0,0,0,0,0,0,0,0
0,0,0,0,0,0,0,0,0,0,0,0,0,0,0,0,0,0,0,0,0
0,0,0,0,0,0,0,0,0,0,0,0,0,0,0,0,0,0,0,0,0
0,0,0,0,0,0,0,0,0,0,0,0,0,0,0,0,0,0,0,0,0
0,0,0,0,0,0,0,0,0,0,0,0,0,0,0,0,0,0,0,0,0
0,0,0,0,0,0,0,0,0,0,0,0,0,0,0,0,0,0,0,0,0
0,0,0,0,0,0,0,0,0,7,7,7,0,0,0,0,0,0,0,0,0
0,0,0,0,0,0,7,7,7,0,0,0,7,7,0,0,0,0,0,0,0
0,0,0,0,0,0,7,7,0,0,0,0,0,7,0,0,0,0,0,0,0
0,0,0,0,0,0,0,0,28,28,28,0,0,0,7,0,0,0,0,0,0
0,0,0,0,0,0,25,25,33,33,28,0,0,0,7,0,0,0,0,0,0
0,0,0,0,0,0,0,0,28,28,28,0,0,0,7,0,0,0,0,0,0
0,0,0,0,0,0,7,7,0,0,0,0,0,7,0,0,0,0,0,0,0
0,0,0,0,0,0,7,7,7,0,0,0,7,7,0,0,0,0,0,0,0
0,0,0,0,0,0,0,0,0,7,7,7,0,0,0,0,0,0,0,0,0
0,0,0,0,0,0,0,0,0,0,0,0,0,0,0,0,0,0,0,0,0
0,0,0,0,0,0,0,0,0,0,0,0,0,0,0,0,0,0,0,0,0
0,0,0,0,0,0,0,0,0,0,0,0,0,0,0,0,0,0,0,0,0
0,0,0,0,0,0,0,0,0,0,0,0,0,0,0,0,0,0,0,0,0
0,0,0,0,0,0,0,0,0,0,0,0,0,0,0,0,0,0,0,0,0
0,0,0,0,0,0,0,0,0,0,0,0,0,0,0,0,0,0,0,0,0
endlayer

layer
0,0,0,0,0,0,0,0,0,0,0,0,0,0,0,0,0,0,0,0,0
0,0,0,0,0,0,0,0,0,0,0,0,0,0,0,0,0,0,0,0,0
0,0,0,0,0,0,0,0,0,0,0,0,0,0,0,0,0,0,0,0,0
0,0,0,0,0,0,0,0,0,0,0,0,0,0,0,0,0,0,0,0,0
0,0,0,0,0,0,0,0,0,0,0,0,0,0,0,0,0,0,0,0,0
0,0,0,0,0,0,0,0,0,0,0,0,0,0,0,0,0,0,0,0,0
0,0,0,0,0,0,0,0,0,7,7,7,0,0,0,0,0,0,0,0,0
0,0,0,0,0,0,7,0,7,0,0,0,7,0,0,0,0,0,0,0,0
0,0,0,0,0,0,7,7,7,0,0,0,0,7,0,0,0,0,0,0,0
0,0,0,0,0,0,0,28,28,0,0,0,0,0,7,0,0,0,0,0,0
0,0,0,0,0,25,25,33,28,0,0,0,0,0,7,0,0,0,0,0,0
0,0,0,0,0,0,0,28,28,0,0,0,0,0,7,0,0,0,0,0,0
0,0,0,0,0,0,7,7,0,0,0,0,0,7,0,0,0,0,0,0,0
0,0,0,0,0,0,7,0,7,0,0,0,7,0,0,0,0,0,0,0,0
0,0,0,0,0,0,0,0,0,7,7,7,0,0,0,0,0,0,0,0,0
0,0,0,0,0,0,0,0,0,0,0,0,0,0,0,0,0,0,0,0,0
0,0,0,0,0,0,0,0,0,0,0,0,0,0,0,0,0,0,0,0,0
0,0,0,0,0,0,0,0,0,0,0,0,0,0,0,0,0,0,0,0,0
0,0,0,0,0,0,0,0,0,0,0,0,0,0,0,0,0,0,0,0,0
0,0,0,0,0,0,0,0,0,0,0,0,0,0,0,0,0,0,0,0,0
0,0,0,0,0,0,0,0,0,0,0,0,0,0,0,0,0,0,0,0,0
endlayer

layer
0,0,0,0,0,0,0,0,0,0,0,0,0,0,0,0,0,0,0,0,0
0,0,0,0,0,0,0,0,0,0,0,0,0,0,0,0,0,0,0,0,0
0,0,0,0,0,0,0,0,0,0,0,0,0,0,0,0,0,0,0,0,0
0,0,0,0,0,0,0,0,0,0,0,0,0,0,0,0,0,0,0,0,0
0,0,0,0,0,0,0,0,0,0,0,0,0,0,0,0,0,0,0,0,0
0,0,0,0,0,0,0,0,0,0,0,0,0,0,0,0,0,0,0,0,0
0,0,0,0,0,0,0,0,0,0,0,0,0,0,0,0,0,0,0,0,0
0,0,0,0,0,0,0,7,0,7,7,7,0,0,0,0,0,0,0,0,0
0,0,0,0,0,0,0,7,7,0,0,0,7,0,0,0,0,0,0,0,0
0,0,0,0,0,0,28,28,0,0,0,0,0,7,0,0,0,0,0,0,0
0,0,0,0,25,25,33,28,28,0,0,0,0,7,0,0,0,0,0,0,0
0,0,0,0,0,0,28,28,0,0,0,0,0,7,0,0,0,0,0,0,0
0,0,0,0,0,0,0,7,7,0,0,0,7,0,0,0,0,0,0,0,0
0,0,0,0,0,0,0,7,0,7,7,7,0,0,0,0,0,0,0,0,0
0,0,0,0,0,0,0,0,0,0,0,0,0,0,0,0,0,0,0,0,0
0,0,0,0,0,0,0,0,0,0,0,0,0,0,0,0,0,0,0,0,0
0,0,0,0,0,0,0,0,0,0,0,0,0,0,0,0,0,0,0,0,0
0,0,0,0,0,0,0,0,0,0,0,0,0,0,0,0,0,0,0,0,0
0,0,0,0,0,0,0,0,0,0,0,0,0,0,0,0,0,0,0,0,0
0,0,0,0,0,0,0,0,0,0,0,0,0,0,0,0,0,0,0,0,0
0,0,0,0,0,0,0,0,0,0,0,0,0,0,0,0,0,0,0,0,0
endlayer

layer
0,0,0,0,0,0,0,0,0,0,0,0,0,0,0,0,0,0,0,0,0
0,0,0,0,0,0,0,0,0,0,0,0,0,0,0,0,0,0,0,0,0
0,0,0,0,0,0,0,0,0,0,0,0,0,0,0,0,0,0,0,0,0
0,0,0,0,0,0,0,0,0,0,0,0,0,0,0,0,0,0,0,0,0
0,0,0,0,0,0,0,0,0,0,0,0,0,0,0,0,0,0,0,0,0
0,0,0,0,0,0,0,0,0,0,0,0,0,0,0,0,0,0,0,0,0
0,0,0,0,0,0,0,0,0,0,0,0,0,0,0,0,0,0,0,0,0
0,0,0,0,0,0,0,0,7,7,0,0,0,0,0,0,0,0,0,0,0
0,0,0,0,0,0,0,0,7,7,7,7,0,0,0,0,0,0,0,0,0
0,0,0,25,0,28,28,0,0,7,7,7,7,0,0,0,0,0,0,0,0
0,0,0,25,25,33,28,28,0,7,34,7,7,0,0,0,0,0,0,0,0
0,0,0,25,0,28,28,0,0,7,7,7,7,0,0,0,0,0,0,0,0
0,0,0,0,0,0,0,0,7,7,7,7,0,0,0,0,0,0,0,0,0
0,0,0,0,0,0,0,0,7,7,0,0,0,0,0,0,0,0,0,0,0
0,0,0,0,0,0,0,0,0,0,0,0,0,0,0,0,0,0,0,0,0
0,0,0,0,0,0,0,0,0,0,0,0,0,0,0,0,0,0,0,0,0
0,0,0,0,0,0,0,0,0,0,0,0,0,0,0,0,0,0,0,0,0
0,0,0,0,0,0,0,0,0,0,0,0,0,0,0,0,0,0,0,0,0
0,0,0,0,0,0,0,0,0,0,0,0,0,0,0,0,0,0,0,0,0
0,0,0,0,0,0,0,0,0,0,0,0,0,0,0,0,0,0,0,0,0
0,0,0,0,0,0,0,0,0,0,0,0,0,0,0,0,0,0,0,0,0
endlayer

layer
0,0,0,0,0,0,0,0,0,0,0,0,0,0,0,0,0,0,0,0,0
0,0,0,0,0,0,0,0,0,0,0,0,0,0,0,0,0,0,0,0,0
0,0,0,0,0,0,0,0,0,0,0,0,0,0,0,0,0,0,0,0,0
0,0,0,0,0,0,0,0,0,0,0,0,0,0,0,0,0,0,0,0,0
0,0,0,0,0,0,0,0,0,0,0,0,0,0,0,0,0,0,0,0,0
0,0,0,0,0,0,0,0,0,0,0,0,0,0,0,0,0,0,0,0,0
0,0,0,0,0,0,0,0,0,0,0,0,0,0,0,0,0,0,0,0,0
0,0,0,0,0,0,0,0,0,0,0,0,0,0,0,0,0,0,0,0,0
0,0,0,0,0,0,0,0,0,0,0,0,0,0,0,0,0,0,0,0,0
0,0,0,25,28,28,0,0,0,0,0,0,0,0,0,0,0,0,0,0,0
0,0,33,33,33,28,28,0,0,0,7,0,0,0,0,0,0,0,0,0,0
0,0,0,25,28,28,0,0,0,0,0,0,0,0,0,0,0,0,0,0,0
0,0,0,0,0,0,0,0,0,0,0,0,0,0,0,0,0,0,0,0,0
0,0,0,0,0,0,0,0,0,0,0,0,0,0,0,0,0,0,0,0,0
0,0,0,0,0,0,0,0,0,0,0,0,0,0,0,0,0,0,0,0,0
0,0,0,0,0,0,0,0,0,0,0,0,0,0,0,0,0,0,0,0,0
0,0,0,0,0,0,0,0,0,0,0,0,0,0,0,0,0,0,0,0,0
0,0,0,0,0,0,0,0,0,0,0,0,0,0,0,0,0,0,0,0,0
0,0,0,0,0,0,0,0,0,0,0,0,0,0,0,0,0,0,0,0,0
0,0,0,0,0,0,0,0,0,0,0,0,0,0,0,0,0,0,0,0,0
0,0,0,0,0,0,0,0,0,0,0,0,0,0,0,0,0,0,0,0,0
endlayer

layer
0,0,0,0,0,0,0,0,0,0,0,0,0,0,0,0,0,0,0,0,0
0,0,0,0,0,0,0,0,0,0,0,0,0,0,0,0,0,0,0,0,0
0,0,0,0,0,0,0,0,0,0,0,0,0,0,0,0,0,0,0,0,0
0,0,0,0,0,0,0,0,0,0,0,0,0,0,0,0,0,0,0,0,0
0,0,0,0,0,0,0,0,0,0,0,0,0,0,0,0,0,0,0,0,0
0,0,0,0,0,0,0,0,0,0,0,0,0,0,0,0,0,0,0,0,0
0,0,0,0,0,0,0,0,0,0,0,0,0,0,0,0,0,0,0,0,0
0,0,0,0,0,0,0,0,0,0,0,0,0,0,0,0,0,0,0,0,0
0,0,0,0,0,0,0,0,0,0,0,0,0,0,0,0,0,0,0,0,0
0,0,0,25,0,0,0,0,0,0,0,0,0,0,0,0,0,0,0,0,0
0,0,0,25,28,28,0,0,0,0,0,0,0,0,0,0,0,0,0,0,0
0,0,0,25,0,0,0,0,0,0,0,0,0,0,0,0,0,0,0,0,0
0,0,0,0,0,0,0,0,0,0,0,0,0,0,0,0,0,0,0,0,0
0,0,0,0,0,0,0,0,0,0,0,0,0,0,0,0,0,0,0,0,0
0,0,0,0,0,0,0,0,0,0,0,0,0,0,0,0,0,0,0,0,0
0,0,0,0,0,0,0,0,0,0,0,0,0,0,0,0,0,0,0,0,0
0,0,0,0,0,0,0,0,0,0,0,0,0,0,0,0,0,0,0,0,0
0,0,0,0,0,0,0,0,0,0,0,0,0,0,0,0,0,0,0,0,0
0,0,0,0,0,0,0,0,0,0,0,0,0,0,0,0,0,0,0,0,0
0,0,0,0,0,0,0,0,0,0,0,0,0,0,0,0,0,0,0,0,0
0,0,0,0,0,0,0,0,0,0,0,0,0,0,0,0,0,0,0,0,0
endlayer

