
# Created by Ruins mod version 15.4 Ingame Parser
# authoring Player: OneWolfe

weight=1
embed_into_distance=0
acceptable_target_blocks=
unacceptable_target_blocks=flowing_water,water,flowing_lava,lava
dimensions=4,7,7
allowable_overhang=0
max_leveling=2
leveling_buffer=0
preserve_water=0
preserve_lava=0

rule1=0,100,Forestry:alveary-0
rule2=0,100,Forestry:alveary-1
rule3=0,100,Forestry:slabs-0

layer
0,0,0,0,0,0,0
0,0,0,0,0,0,0
0,0,1,1,1,0,0
0,0,1,1,1,0,0
0,0,1,1,1,0,0
0,0,0,0,0,0,0
0,0,0,0,0,0,0
endlayer

layer
0,0,0,0,0,0,0
0,0,0,0,0,0,0
0,0,1,1,1,0,0
0,0,1,1,1,0,0
0,0,1,1,1,0,0
0,0,0,0,0,0,0
0,0,0,0,0,0,0
endlayer

layer
0,0,0,0,0,0,0
0,0,0,0,0,0,0
0,0,1,2,1,0,0
0,0,2,2,2,0,0
0,0,1,2,1,0,0
0,0,0,0,0,0,0
0,0,0,0,0,0,0
endlayer

layer
0,0,0,0,0,0,0
0,0,0,0,0,0,0
0,0,3,3,3,0,0
0,0,3,3,3,0,0
0,0,3,3,3,0,0
0,0,0,0,0,0,0
0,0,0,0,0,0,0
endlayer

