
# Created by Ruins mod version 14.7 Ingame Parser
# authoring Player: OneWolfe

weight=10
unique=1
embed_into_distance=0
acceptable_target_blocks=
unacceptable_target_blocks=flowing_water,water,flowing_lava,lava
dimensions=19,20,20
allowable_overhang=8
max_leveling=6
leveling_buffer=0
preserve_water=1
preserve_lava=0
preserve_plants=1

rule1=0,100,terrafirmacraft:StoneIgExBrick-3,terrafirmacraft:StoneIgExBrick-3,terrafirmacraft:StoneIgExBrick-3,terrafirmacraft:StoneIgExBrick-3,air
rule2=0,100,terrafirmacraft:planks-0
rule3=0,100,terrafirmacraft:StoneSedBrick-6,terrafirmacraft:StoneSedBrick-6,terrafirmacraft:StoneSedBrick-6,terrafirmacraft:StoneSedBrick-6,air
rule4=0,100,MobSpawner:zombieTFC,terrafirmacraft:planks-0,terrafirmacraft:planks-0
rule5=0,100,terrafirmacraft:WoodSupportV-3
rule6=0,100,Railcraft:slab-0,Railcraft:slab-0,Railcraft:slab-0,air
rule7=0,100,terrafirmacraft:WoodSupportV-5
rule8=0,100,minecraft:stone_slab-7,minecraft:stone_slab-7,minecraft:stone_slab-7,air
rule9=0,100,terrafirmacraft:StoneMMSmooth-5
rule10=0,100,BiblioCraft:BiblioTable-5
rule11=0,100,terrafirmacraft:WallSmoothMM-5,terrafirmacraft:WallSmoothMM-5,terrafirmacraft:WallSmoothMM-5,terrafirmacraft:WallSmoothMM-5,air
rule12=0,100,ImmersiveEngineering:woodenStairs-2
rule13=0,100,BiblioCraft:BiblioDesk-5
rule14=0,100,terrafirmacraft:DoorChestnut-3
rule15=0,100,terrafirmacraft:Barrel-0
rule16=0,100,BiblioCraft:Armor Stand-0,air
rule17=0,100,BiblioCraft:BiblioSwordPedestal-4,air
rule18=0,100,minecraft:stained_glass-15,minecraft:stained_glass-15,minecraft:stained_glass-15,air
rule19=0,100,BiblioCraft:BiblioTypewriter-3
rule20=0,100,ChestGenHook:dungeonChest:5-5,air,air
rule21=0,100,terrafirmacraft:DoorChestnut-8
rule22=0,100,BiblioCraft:Armor Stand-4,air
rule23=0,100,BiblioCraft:BiblioRack-1,air
rule24=0,100,Steamcraft:steamTank-0,air
rule25=0,100,Cogs:blockMachine-0,air
rule26=0,100,BiblioCraft:BiblioFancyPainting-0,air,air
rule27=0,100,BiblioCraft:BiblioLamp-0,air,air,air
rule28=0,100,ImmersiveEngineering:woodenStairs-0,ImmersiveEngineering:woodenStairs-0,ImmersiveEngineering:woodenStairs-0,air
rule29=0,100,BiblioCraft:BiblioClock-5,air
rule30=0,100,ImmersiveEngineering:woodenStairs-3,ImmersiveEngineering:woodenStairs-3,ImmersiveEngineering:woodenStairs-3,air
rule31=0,100,ImmersiveEngineering:woodenStairs-5,ImmersiveEngineering:woodenStairs-5,ImmersiveEngineering:woodenStairs-5,air
rule32=0,100,ImmersiveEngineering:woodenStairs-1,ImmersiveEngineering:woodenStairs-1,ImmersiveEngineering:woodenStairs-1,air
rule33=0,100,BiblioCraft:BiblioIronLantern-3,air,air
rule34=0,100,terrafirmacraft:planks-5,terrafirmacraft:planks-5,terrafirmacraft:planks-5,terrafirmacraft:planks-5,terrafirmacraft:planks-5,air
rule35=0,100,ChestGenHook:dungeonChest:5-4,air,air
rule36=0,100,BiblioCraft:Bibliotheca-0
rule37=0,100,terrafirmacraft:WallRawMM-5,terrafirmacraft:WallRawMM-5,terrafirmacraft:WallRawMM-5,air
rule38=0,100,terrafirmacraft:Fence-4

layer
0,0,0,0,0,0,0,0,0,0,0,0,0,0,0,0,0,0,0,0
0,0,1,1,1,1,1,1,1,1,1,1,1,1,1,1,1,0,0,0
0,0,1,2,2,2,2,2,2,2,2,2,2,2,2,2,1,0,0,0
0,0,1,2,2,2,2,2,2,2,2,2,2,2,2,2,1,0,0,0
0,0,1,2,2,2,2,2,2,2,2,2,2,2,2,2,1,0,0,0
0,0,1,2,2,2,2,2,2,2,2,2,2,2,2,2,1,0,0,0
0,0,1,2,4,2,2,3,2,2,2,2,2,2,2,2,1,0,0,0
0,5,1,2,2,2,3,2,2,2,2,2,2,2,2,2,1,0,0,0
0,0,1,2,2,2,2,2,2,2,2,2,2,2,2,2,1,0,0,0
0,0,1,2,2,2,2,2,2,2,2,2,2,2,2,2,1,6,6,0
0,0,1,2,2,2,2,2,2,2,2,2,2,2,2,2,1,0,0,0
0,5,1,2,2,2,2,2,2,2,2,2,2,2,2,2,1,0,0,0
0,0,1,2,2,2,2,2,2,2,2,2,2,2,2,2,1,0,0,0
0,0,1,2,2,2,2,2,2,2,2,2,2,2,2,2,1,0,0,0
0,0,1,2,2,2,2,2,2,2,2,2,2,2,2,2,1,0,0,0
0,0,1,2,2,2,2,2,2,2,2,2,2,2,2,2,1,0,0,0
0,0,1,1,1,1,1,1,1,1,1,1,1,1,1,1,1,0,0,0
0,0,0,0,6,6,6,0,7,0,0,0,7,0,0,0,0,0,0,0
0,0,0,0,6,8,6,0,0,0,0,0,0,0,0,0,0,0,0,0
0,0,0,0,0,0,0,0,0,0,0,0,0,0,0,0,0,0,0,0
endlayer

layer
0,0,0,0,0,0,0,0,0,0,0,0,0,0,0,0,0,0,0,0
0,0,9,3,3,3,3,3,3,3,3,3,3,3,3,3,9,0,0,0
0,0,3,0,0,0,0,0,0,0,0,0,0,0,0,0,3,0,0,0
0,0,3,0,0,0,0,0,11,11,0,0,0,10,0,0,3,0,0,0
0,0,3,0,0,0,0,0,12,0,0,0,0,10,0,0,3,0,0,0
0,0,3,0,0,0,0,0,12,0,0,0,0,10,0,0,3,0,0,0
0,0,3,2,2,2,11,3,11,11,0,0,0,10,0,0,3,0,0,0
0,5,3,2,2,2,3,11,0,0,0,0,0,10,13,10,3,0,0,0
0,0,3,0,0,0,0,0,0,0,0,0,0,0,0,0,3,0,0,0
0,0,3,0,0,0,0,10,10,10,0,0,0,0,0,0,14,0,0,0
0,0,3,0,0,0,0,0,0,0,0,0,0,0,0,0,3,0,0,0
0,5,3,0,0,0,0,0,10,0,0,0,0,0,0,0,3,0,0,0
0,0,3,0,0,0,0,0,0,0,0,0,0,0,0,0,3,0,0,0
0,0,3,15,0,0,0,10,10,10,0,0,0,0,0,0,3,0,0,0
0,0,3,15,15,0,0,0,0,0,0,16,16,16,16,0,3,0,0,0
0,0,3,4,15,15,0,0,0,0,0,0,0,0,0,0,3,0,0,0
0,0,9,3,3,3,3,3,3,3,3,3,3,3,3,3,9,0,0,0
0,0,0,0,0,0,0,0,7,0,0,0,7,0,0,0,0,0,0,0
0,0,0,0,0,0,0,0,0,0,0,0,0,0,0,0,0,0,0,0
0,0,0,0,0,0,0,0,0,0,0,0,0,0,0,0,0,0,0,0
endlayer

layer
0,0,0,0,0,0,0,0,0,0,0,0,0,0,0,0,0,0,0,0
0,0,9,3,3,3,3,3,3,3,3,3,3,3,3,3,9,0,0,0
0,0,3,0,0,0,0,0,0,0,0,0,0,0,0,0,3,0,0,0
0,0,3,0,0,0,0,11,11,0,0,0,0,17,0,0,3,0,0,0
0,0,3,0,0,0,0,12,0,0,0,0,0,0,0,0,18,0,0,0
0,0,3,0,0,0,0,12,0,0,0,0,0,0,0,0,18,0,0,0
0,0,3,2,2,2,11,3,11,0,0,0,0,0,0,0,18,0,0,0
0,5,3,0,20,0,3,11,0,0,0,0,0,17,0,19,3,0,0,0
0,0,3,0,0,0,0,0,0,0,0,0,0,0,0,0,3,0,0,0
0,0,3,0,0,0,0,0,0,0,0,0,0,0,0,0,21,0,0,0
0,0,3,0,0,0,0,0,0,0,0,0,0,0,0,0,3,0,0,0
0,5,3,0,0,0,0,0,0,0,0,0,0,0,0,0,3,0,0,0
0,0,3,0,0,0,0,0,0,0,0,0,0,0,0,0,18,0,0,0
0,0,3,0,0,0,0,0,0,0,0,0,0,0,0,0,18,0,0,0
0,0,3,15,0,0,0,0,0,0,0,22,22,22,22,0,18,0,0,0
0,0,3,15,15,0,0,0,23,0,0,0,0,0,0,0,3,0,0,0
0,0,9,3,3,3,3,3,3,3,3,3,3,3,3,3,9,0,0,0
0,0,0,0,0,0,0,0,24,24,24,24,24,0,0,0,0,0,0,0
0,0,0,0,0,0,0,0,25,0,25,0,25,0,0,0,0,0,0,0
0,0,0,0,0,0,0,0,0,0,0,0,0,0,0,0,0,0,0,0
endlayer

layer
0,0,0,0,0,0,0,0,0,0,0,0,0,0,0,0,0,0,0,0
0,0,9,3,3,3,3,3,3,3,3,3,3,3,3,3,9,0,0,0
0,0,3,0,0,0,0,0,0,0,0,0,23,0,0,0,3,0,0,0
0,0,3,9,9,9,11,11,0,0,0,0,0,0,0,0,3,0,0,0
0,0,3,9,9,9,12,0,0,0,0,0,0,0,0,0,18,0,0,0
0,0,3,9,9,9,12,0,0,0,0,0,0,0,0,0,18,0,0,0
0,0,3,2,2,2,11,3,0,0,0,0,0,0,0,0,18,0,0,0
0,5,3,2,2,2,3,11,0,0,0,0,0,0,0,0,3,0,0,0
0,0,3,0,0,0,26,0,0,0,0,0,0,0,0,26,3,0,0,0
0,0,3,0,0,0,0,0,0,0,0,0,0,0,0,0,3,27,0,0
0,0,3,0,0,0,0,0,0,0,0,0,0,0,0,26,3,0,0,0
0,5,3,23,0,0,0,0,0,0,0,0,0,0,0,0,3,0,0,0
0,0,3,23,0,0,0,0,0,0,0,0,0,0,0,0,18,0,0,0
0,0,3,23,0,0,0,0,0,0,0,0,0,0,0,0,18,0,0,0
0,0,3,0,0,0,0,0,0,0,0,0,0,0,0,0,18,0,0,0
0,0,3,15,0,0,0,23,23,23,0,0,0,0,0,0,3,0,0,0
0,0,9,3,3,3,3,3,3,3,3,3,3,3,3,3,9,0,0,0
0,0,0,0,0,0,0,0,6,6,6,6,6,0,0,0,0,0,0,0
0,0,0,0,0,0,0,0,0,0,0,0,0,0,0,0,0,0,0,0
0,0,0,0,0,0,0,0,0,0,0,0,0,0,0,0,0,0,0,0
endlayer

layer
0,0,0,0,0,0,0,0,0,0,0,0,0,0,0,0,0,0,0,0
0,0,9,3,3,3,3,3,3,3,3,3,3,3,3,3,9,0,0,0
0,0,3,0,0,0,0,0,0,0,0,23,23,23,0,0,3,0,0,0
0,0,3,11,11,11,11,0,0,0,0,0,0,0,0,0,3,0,0,0
0,0,3,11,0,0,0,0,0,0,0,0,0,0,0,0,18,0,0,0
0,0,3,11,0,0,0,0,0,0,0,0,0,0,0,0,18,0,0,0
0,0,3,11,28,28,11,3,0,0,0,0,0,0,0,0,18,0,0,0
0,5,3,0,0,0,3,11,0,0,0,0,0,0,0,0,3,0,0,0
0,0,3,0,0,0,26,0,0,0,0,0,0,0,0,26,3,0,0,0
0,0,3,0,0,0,0,0,0,0,0,0,0,0,0,29,3,0,0,0
0,0,3,0,0,0,0,0,0,0,0,0,0,0,0,26,3,0,0,0
0,5,3,23,0,0,0,0,0,0,0,0,0,0,0,0,3,0,0,0
0,0,3,23,0,0,0,0,0,0,0,0,0,0,0,0,18,0,0,0
0,0,3,23,0,0,0,0,0,0,0,0,0,0,0,0,18,0,0,0
0,0,3,0,0,0,0,0,0,0,0,0,0,0,0,0,18,0,0,0
0,0,3,0,0,0,23,23,23,23,23,0,0,0,0,0,3,0,0,0
0,0,9,3,3,3,3,3,3,3,3,3,3,3,3,3,9,0,0,0
0,0,0,0,0,0,0,0,0,0,0,0,0,0,0,0,0,0,0,0
0,0,0,0,0,0,0,0,0,0,0,0,0,0,0,0,0,0,0,0
0,0,0,0,0,0,0,0,0,0,0,0,0,0,0,0,0,0,0,0
endlayer

layer
0,0,0,0,0,0,0,0,0,0,0,0,0,0,0,0,0,0,0,0
0,0,9,9,3,3,3,3,3,3,3,3,3,3,3,9,9,0,0,0
0,0,9,0,0,0,0,0,0,0,0,0,23,0,0,0,9,0,0,0
0,0,3,0,0,0,0,0,0,0,0,0,0,0,0,0,3,0,0,0
0,0,3,0,0,0,0,0,0,0,0,0,0,0,0,0,3,0,0,0
0,0,3,0,0,0,0,0,0,0,0,0,0,0,0,0,18,0,0,0
0,0,3,11,0,0,11,3,0,0,0,0,0,0,0,0,3,0,0,0
0,5,3,11,28,28,3,11,0,0,0,0,0,0,0,0,3,0,0,0
0,0,3,9,9,9,27,0,0,0,0,0,0,0,0,0,3,0,0,0
0,0,3,9,9,9,0,0,0,0,0,0,0,0,0,0,3,0,0,0
0,0,3,9,9,9,0,0,0,0,0,0,0,0,0,0,3,0,0,0
0,5,3,23,0,0,0,0,0,0,0,0,0,0,0,0,3,0,0,0
0,0,3,23,0,0,0,0,0,0,0,0,0,0,0,0,3,0,0,0
0,0,3,23,0,0,0,0,0,0,0,0,0,0,0,0,18,0,0,0
0,0,3,0,0,0,0,0,0,0,0,0,0,0,0,0,3,0,0,0
0,0,9,0,0,0,0,0,0,0,0,0,0,0,0,0,9,0,0,0
0,0,9,9,3,3,3,3,3,3,3,3,3,3,3,9,9,0,0,0
0,0,0,0,0,0,0,0,0,0,0,0,0,0,0,0,0,0,0,0
0,0,0,0,0,0,0,0,0,0,0,0,0,0,0,0,0,0,0,0
0,0,0,0,0,0,0,0,0,0,0,0,0,0,0,0,0,0,0,0
endlayer

layer
0,0,0,0,0,0,0,0,0,0,0,0,0,0,0,0,0,0,0,0
0,0,9,3,9,3,3,3,3,3,3,3,3,3,9,3,9,0,0,0
0,0,3,0,0,0,0,0,0,0,0,0,0,0,0,0,3,0,0,0
0,0,9,0,0,0,0,0,0,0,0,0,0,0,0,0,9,0,0,0
0,0,3,0,0,0,0,0,0,0,0,0,0,0,0,0,3,0,0,0
0,0,3,0,0,0,0,0,0,0,0,0,0,0,0,0,3,0,0,0
0,0,3,0,0,0,11,3,0,0,0,0,0,0,0,0,3,0,0,0
0,5,3,11,0,0,3,11,0,0,0,0,0,0,0,0,3,0,0,0
0,0,3,11,0,0,30,0,0,0,0,0,0,0,0,0,3,0,0,0
0,0,3,11,0,0,30,0,0,0,0,0,0,0,0,0,3,0,0,0
0,0,3,11,11,11,11,0,0,0,0,0,0,0,0,0,3,0,0,0
0,5,3,0,0,0,0,0,0,0,0,0,0,0,0,0,3,0,0,0
0,0,3,0,0,0,0,0,0,0,0,0,0,0,0,0,3,0,0,0
0,0,3,0,0,0,0,0,0,0,0,0,0,0,0,0,3,0,0,0
0,0,9,0,0,0,0,0,0,0,0,0,0,0,0,0,9,0,0,0
0,0,3,0,0,0,0,0,0,0,0,0,0,0,0,0,3,0,0,0
0,0,9,3,9,3,3,3,3,3,3,3,3,3,9,3,9,0,0,0
0,0,0,0,0,0,0,0,0,0,0,0,0,0,0,0,0,0,0,0
0,0,0,0,0,0,0,0,0,0,0,0,0,0,0,0,0,0,0,0
0,0,0,0,0,0,0,0,0,0,0,0,0,0,0,0,0,0,0,0
endlayer

layer
0,0,0,0,0,0,0,0,0,0,0,0,0,0,0,0,0,0,0,0
0,0,9,3,3,9,3,3,3,3,3,3,3,9,3,3,9,0,0,0
0,0,3,27,0,0,0,0,0,27,0,0,0,0,0,27,3,0,0,0
0,0,3,0,0,0,0,0,0,0,0,0,0,0,0,0,3,0,0,0
0,0,9,0,0,0,0,0,0,0,0,0,0,0,0,0,9,0,0,0
0,0,3,0,0,0,0,0,0,0,0,0,0,0,0,0,3,0,0,0
0,0,3,0,0,0,11,3,0,0,0,0,0,0,0,0,3,0,0,0
0,5,3,0,0,0,3,11,0,0,0,0,0,0,0,0,3,0,0,0
0,0,3,0,0,0,0,30,0,0,0,0,0,0,0,0,3,0,0,0
0,0,3,0,0,0,0,30,0,0,0,0,0,0,0,27,3,0,0,0
0,0,3,0,0,0,11,11,0,0,0,0,0,0,0,0,3,0,0,0
0,5,3,0,0,0,0,0,0,0,0,0,0,0,0,0,3,0,0,0
0,0,3,0,0,0,0,0,0,0,0,0,0,0,0,0,3,0,0,0
0,0,9,0,0,0,0,0,0,0,0,0,0,0,0,0,9,0,0,0
0,0,3,0,0,0,0,0,0,0,0,0,0,0,0,0,3,0,0,0
0,0,3,27,0,0,0,0,0,27,0,0,0,0,0,27,3,0,0,0
0,0,9,3,3,9,3,3,3,3,3,3,3,9,3,3,9,0,0,0
0,0,0,0,0,0,0,0,0,0,0,0,0,0,0,0,0,0,0,0
0,0,0,0,0,0,0,0,0,0,0,0,0,0,0,0,0,0,0,0
0,0,0,0,0,0,0,0,0,0,0,0,0,0,0,0,0,0,0,0
endlayer

layer
0,28,28,28,28,28,28,28,28,28,28,28,28,28,28,28,28,28,0,0
0,0,9,9,9,9,9,9,9,9,9,9,9,9,9,9,9,0,0,0
0,0,9,2,2,2,2,2,2,2,2,2,2,2,2,2,9,0,0,0
0,0,9,2,2,2,2,2,2,2,2,2,2,2,2,2,9,0,0,0
0,0,9,2,2,2,2,2,2,2,2,2,2,2,2,2,9,0,0,0
0,0,9,2,2,2,2,2,2,2,2,2,2,2,2,2,9,0,0,0
0,0,9,2,2,2,2,3,2,2,2,2,2,2,2,2,9,0,0,0
0,5,9,31,31,31,3,2,2,2,2,2,2,2,2,2,9,0,0,0
0,0,9,0,0,0,0,0,30,2,2,2,2,2,2,2,9,0,0,0
0,0,9,0,0,0,0,0,30,2,2,2,2,2,2,2,9,0,0,0
0,0,9,0,0,0,0,11,11,2,2,2,2,2,2,2,9,0,0,0
0,5,9,2,2,2,2,2,2,2,2,2,2,2,2,2,9,0,0,0
0,0,9,2,2,2,2,2,2,2,2,2,2,2,2,2,9,0,0,0
0,0,9,2,2,2,2,2,2,2,2,2,2,2,2,2,9,0,0,0
0,0,9,2,2,2,2,2,2,2,2,2,2,2,2,2,9,0,0,0
0,0,9,2,2,2,2,2,2,2,2,2,2,2,2,2,9,0,0,0
0,0,9,9,9,9,9,9,9,9,9,9,9,9,9,9,9,0,0,0
0,0,0,0,0,0,0,0,0,0,0,0,0,0,0,0,0,0,0,0
0,0,0,0,0,0,0,0,0,0,0,0,0,0,0,0,0,0,0,0
0,0,0,0,0,0,0,0,0,0,0,0,0,0,0,0,0,0,0,0
endlayer

layer
0,0,0,0,0,0,0,0,0,0,0,0,0,0,0,0,0,0,0,0
0,28,28,28,28,28,28,28,28,28,28,28,28,28,28,28,28,28,0,0
0,0,9,2,2,2,2,2,2,2,2,2,2,2,2,2,9,0,0,0
0,0,3,2,2,2,2,2,2,2,2,2,2,2,2,2,3,0,0,0
0,0,3,2,2,2,2,2,2,2,2,2,4,2,2,2,3,0,0,0
0,0,3,2,2,2,2,2,2,2,2,2,2,2,2,2,3,0,0,0
0,0,3,2,2,2,2,4,2,2,2,2,2,2,2,2,3,0,0,0
25,24,3,2,2,2,3,2,2,2,2,2,2,2,2,2,3,0,0,0
0,24,3,2,2,0,0,0,0,30,2,2,2,2,2,2,3,0,0,0
25,24,9,2,2,0,0,0,0,30,2,2,2,2,2,2,9,0,0,11
0,24,3,2,2,0,0,0,11,11,2,2,2,2,2,2,3,0,0,0
25,24,3,2,2,2,2,2,2,2,2,2,2,2,2,2,3,0,0,0
0,0,3,2,2,2,2,2,2,2,2,2,2,2,2,2,3,0,0,0
0,0,3,2,2,2,2,2,2,2,2,2,2,2,2,2,3,0,0,0
0,0,3,2,2,2,2,2,2,2,2,2,4,2,2,2,3,0,0,0
0,0,3,2,2,2,2,2,2,2,2,2,2,2,2,2,3,0,0,0
0,0,9,2,2,2,2,2,2,2,2,2,2,2,2,2,9,0,0,0
0,32,32,32,32,32,32,32,32,32,32,32,32,32,32,32,32,32,0,0
0,0,0,0,0,0,0,0,0,0,0,0,0,0,0,0,0,0,0,0
0,0,0,0,0,0,0,0,0,0,0,0,0,0,0,0,0,0,0,0
endlayer

layer
0,0,0,0,0,0,0,0,0,0,0,0,0,0,0,0,0,0,0,0
0,0,0,0,0,0,0,0,0,0,0,0,0,0,0,0,0,0,0,0
0,28,28,28,28,28,28,28,28,28,28,28,28,28,28,28,28,28,0,0
0,0,9,33,0,0,20,0,0,33,0,0,0,0,0,33,9,0,0,0
0,0,3,18,34,34,0,34,34,18,34,34,34,34,34,18,3,0,0,0
0,0,3,0,0,0,0,0,0,0,0,0,0,0,0,0,3,0,0,0
0,0,3,0,0,0,11,3,0,0,0,0,0,0,0,0,3,0,0,0
0,6,3,0,11,11,3,11,11,11,11,0,0,10,10,10,3,0,0,0
0,6,3,0,11,0,0,0,0,0,0,0,0,0,0,0,3,0,0,0
0,6,9,0,11,0,0,0,0,0,0,0,0,10,10,10,9,0,0,11
0,6,3,0,11,0,0,0,0,11,11,0,0,0,0,0,3,0,0,0
0,6,3,0,11,11,11,11,11,11,0,0,0,10,10,10,3,0,0,0
0,0,3,0,0,0,0,0,0,0,0,0,0,0,0,0,3,0,0,0
0,0,3,0,0,0,0,0,0,0,0,0,0,0,0,0,3,0,0,0
0,0,3,18,34,34,0,34,34,18,34,34,34,34,34,18,3,0,0,0
0,0,9,33,0,0,35,0,0,33,0,0,0,0,0,33,9,0,0,0
0,32,32,32,32,32,32,32,32,32,32,32,32,32,32,32,32,32,0,0
0,0,0,0,0,0,0,0,0,0,0,0,0,0,0,0,0,0,0,0
0,0,0,0,0,0,0,0,0,0,0,0,0,0,0,0,0,0,0,0
0,0,0,0,0,0,0,0,0,0,0,0,0,0,0,0,0,0,0,0
endlayer

layer
0,0,0,0,0,0,0,0,0,0,0,0,0,0,0,0,0,0,0,0
0,0,0,0,0,0,0,0,0,0,0,0,0,0,0,0,0,0,0,0
0,0,0,0,0,0,0,0,0,0,0,0,0,0,0,0,0,0,0,0
0,28,28,28,28,28,28,28,28,28,28,28,28,28,28,28,28,28,0,0
0,0,9,36,36,36,36,36,36,36,36,36,36,36,36,36,9,0,0,0
0,0,9,0,0,0,0,0,0,0,0,0,0,0,0,0,9,0,0,0
0,0,9,0,0,0,11,3,0,0,0,0,0,0,0,0,9,0,0,0
0,0,9,0,0,0,3,11,0,0,0,0,0,0,0,0,9,0,0,0
0,0,9,0,0,0,0,0,0,0,0,0,0,0,0,0,9,0,0,0
0,0,9,0,0,0,0,0,0,0,0,0,0,0,0,0,9,0,0,37
0,0,9,0,0,0,0,0,0,0,0,0,0,0,0,0,9,0,0,0
0,0,9,0,0,0,0,0,0,0,0,0,0,0,0,0,9,0,0,0
0,0,9,0,0,0,0,0,0,0,0,0,0,0,0,0,9,0,0,0
0,0,9,0,0,0,0,0,0,0,0,0,0,0,0,0,9,0,0,0
0,0,9,36,36,36,36,36,36,36,36,36,36,36,36,36,9,0,0,0
0,32,32,32,32,32,32,32,32,32,32,32,32,32,32,32,32,32,0,0
0,0,0,0,0,0,0,0,0,0,0,0,0,0,0,0,0,0,0,0
0,0,0,0,0,0,0,0,0,0,0,0,0,0,0,0,0,0,0,0
0,0,0,0,0,0,0,0,0,0,0,0,0,0,0,0,0,0,0,0
0,0,0,0,0,0,0,0,0,0,0,0,0,0,0,0,0,0,0,0
endlayer

layer
0,0,0,0,0,0,0,0,0,0,0,0,0,0,0,0,0,0,0,0
0,0,0,0,0,0,0,0,0,0,0,0,0,0,0,0,0,0,0,0
0,0,0,0,0,0,0,0,0,0,0,0,0,0,0,0,0,0,0,0
0,0,0,0,0,0,0,0,0,0,0,0,0,0,0,0,0,0,0,0
0,28,28,28,28,28,28,28,28,28,28,28,28,28,28,28,28,28,0,0
0,0,9,0,0,0,0,0,0,0,0,0,0,0,0,0,9,0,0,0
0,0,3,0,0,0,11,3,0,0,0,0,0,0,0,0,3,0,0,0
0,0,3,0,0,0,3,11,0,0,0,0,0,0,0,0,3,0,0,0
0,0,3,0,0,0,0,0,0,0,0,0,0,0,0,26,3,0,0,0
0,0,18,0,0,0,0,0,0,0,0,0,0,0,0,0,3,37,0,37
0,0,3,0,0,0,0,0,0,0,0,0,0,0,0,26,3,0,0,0
0,0,3,0,0,0,0,0,0,0,0,0,0,0,0,0,3,0,0,0
0,0,3,0,0,0,0,0,0,0,0,0,0,0,0,0,3,0,0,0
0,0,9,0,0,0,0,0,0,0,0,0,0,0,0,0,9,0,0,0
0,32,32,32,32,32,32,32,32,32,32,32,32,32,32,32,32,32,0,0
0,0,0,0,0,0,0,0,0,0,0,0,0,0,0,0,0,0,0,0
0,0,0,0,0,0,0,0,0,0,0,0,0,0,0,0,0,0,0,0
0,0,0,0,0,0,0,0,0,0,0,0,0,0,0,0,0,0,0,0
0,0,0,0,0,0,0,0,0,0,0,0,0,0,0,0,0,0,0,0
0,0,0,0,0,0,0,0,0,0,0,0,0,0,0,0,0,0,0,0
endlayer

layer
0,0,0,0,0,0,0,0,0,0,0,0,0,0,0,0,0,0,0,0
0,0,0,0,0,0,0,0,0,0,0,0,0,0,0,0,0,0,0,0
0,0,0,0,0,0,0,0,0,0,0,0,0,0,0,0,0,0,0,0
0,0,0,0,0,0,0,0,0,0,0,0,0,0,0,0,0,0,0,0
0,0,0,0,0,0,0,0,0,0,0,0,0,0,0,0,0,0,0,0
0,28,28,28,28,28,28,28,28,28,28,28,28,28,28,28,28,28,0,0
0,0,9,0,0,0,11,3,27,0,0,0,0,0,0,0,9,0,0,0
0,0,3,0,0,27,3,11,0,0,0,0,0,0,0,0,3,0,0,0
0,0,18,0,0,0,27,0,0,0,0,0,0,0,0,26,3,0,0,0
0,0,18,0,0,0,0,0,0,0,0,0,0,0,0,29,3,37,37,37
0,0,18,0,0,0,0,0,0,0,0,0,0,0,0,26,3,0,0,0
0,0,3,0,0,0,0,0,0,0,0,0,0,0,0,0,3,0,0,0
0,0,9,0,0,0,0,0,0,0,0,0,0,0,0,0,9,0,0,0
0,32,32,32,32,32,32,32,32,32,32,32,32,32,32,32,32,32,0,0
0,0,0,0,0,0,0,0,0,0,0,0,0,0,0,0,0,0,0,0
0,0,0,0,0,0,0,0,0,0,0,0,0,0,0,0,0,0,0,0
0,0,0,0,0,0,0,0,0,0,0,0,0,0,0,0,0,0,0,0
0,0,0,0,0,0,0,0,0,0,0,0,0,0,0,0,0,0,0,0
0,0,0,0,0,0,0,0,0,0,0,0,0,0,0,0,0,0,0,0
0,0,0,0,0,0,0,0,0,0,0,0,0,0,0,0,0,0,0,0
endlayer

layer
0,0,0,0,0,0,0,0,0,0,0,0,0,0,0,0,0,0,0,0
0,0,0,0,0,0,0,0,0,0,0,0,0,0,0,0,0,0,0,0
0,0,0,0,0,0,0,0,0,0,0,0,0,0,0,0,0,0,0,0
0,0,0,0,0,0,0,0,0,0,0,0,0,0,0,0,0,0,0,0
0,0,0,0,0,0,0,0,0,0,0,0,0,0,0,0,0,0,0,0
0,0,0,0,0,0,0,0,0,0,0,0,0,0,0,0,0,0,0,0
0,28,28,28,28,28,28,3,28,28,28,28,28,28,28,28,28,28,0,0
0,0,9,0,0,0,3,11,0,0,0,0,0,0,0,0,9,0,0,0
0,0,3,0,0,0,0,0,0,0,0,0,0,0,0,0,3,0,0,0
0,0,18,0,0,0,0,0,0,0,0,0,0,0,0,0,3,37,37,0
0,0,3,0,0,0,0,0,0,0,0,0,0,0,0,0,3,0,0,0
0,0,9,0,0,0,0,0,0,0,0,0,0,0,0,0,9,0,0,0
0,32,32,32,32,32,32,32,32,32,32,32,32,32,32,32,32,32,0,0
0,0,0,0,0,0,0,0,0,0,0,0,0,0,0,0,0,0,0,0
0,0,0,0,0,0,0,0,0,0,0,0,0,0,0,0,0,0,0,0
0,0,0,0,0,0,0,0,0,0,0,0,0,0,0,0,0,0,0,0
0,0,0,0,0,0,0,0,0,0,0,0,0,0,0,0,0,0,0,0
0,0,0,0,0,0,0,0,0,0,0,0,0,0,0,0,0,0,0,0
0,0,0,0,0,0,0,0,0,0,0,0,0,0,0,0,0,0,0,0
0,0,0,0,0,0,0,0,0,0,0,0,0,0,0,0,0,0,0,0
endlayer

layer
0,0,0,0,0,0,0,0,0,0,0,0,0,0,0,0,0,0,0,0
0,0,0,0,0,0,0,0,0,0,0,0,0,0,0,0,0,0,0,0
0,0,0,0,0,0,0,0,0,0,0,0,0,0,0,0,0,0,0,0
0,0,0,0,0,0,0,0,0,0,0,0,0,0,0,0,0,0,0,0
0,0,0,0,0,0,0,0,0,0,0,0,0,0,0,0,0,0,0,0
0,0,0,0,0,0,0,0,0,0,0,0,0,0,0,0,0,0,0,0
0,0,0,0,0,0,0,3,0,0,0,0,0,0,0,0,0,0,0,0
0,28,28,28,28,28,3,28,28,28,28,28,28,28,28,28,28,28,0,0
0,0,9,0,0,0,0,0,0,0,0,0,0,0,0,0,9,0,0,0
0,0,3,27,0,0,0,0,0,0,0,0,0,0,0,27,3,37,0,0
0,0,9,0,0,0,0,0,0,0,0,0,0,0,0,0,9,0,0,0
0,32,32,32,32,32,32,32,32,32,32,32,32,32,32,32,32,32,0,0
0,0,0,0,0,0,0,0,0,0,0,0,0,0,0,0,0,0,0,0
0,0,0,0,0,0,0,0,0,0,0,0,0,0,0,0,0,0,0,0
0,0,0,0,0,0,0,0,0,0,0,0,0,0,0,0,0,0,0,0
0,0,0,0,0,0,0,0,0,0,0,0,0,0,0,0,0,0,0,0
0,0,0,0,0,0,0,0,0,0,0,0,0,0,0,0,0,0,0,0
0,0,0,0,0,0,0,0,0,0,0,0,0,0,0,0,0,0,0,0
0,0,0,0,0,0,0,0,0,0,0,0,0,0,0,0,0,0,0,0
0,0,0,0,0,0,0,0,0,0,0,0,0,0,0,0,0,0,0,0
endlayer

layer
0,0,0,0,0,0,0,0,0,0,0,0,0,0,0,0,0,0,0,0
0,0,0,0,0,0,0,0,0,0,0,0,0,0,0,0,0,0,0,0
0,0,0,0,0,0,0,0,0,0,0,0,0,0,0,0,0,0,0,0
0,0,0,0,0,0,0,0,0,0,0,0,0,0,0,0,0,0,0,0
0,0,0,0,0,0,0,0,0,0,0,0,0,0,0,0,0,0,0,0
0,0,0,0,0,0,0,0,0,0,0,0,0,0,0,0,0,0,0,0
0,0,0,0,0,0,0,3,0,0,0,0,0,0,0,0,0,0,0,0
0,0,0,0,0,0,3,0,0,0,0,0,0,0,0,0,0,0,0,0
0,28,28,28,28,28,28,28,28,28,28,28,28,28,28,28,28,28,0,0
0,0,3,3,3,3,3,3,3,3,3,3,3,3,3,3,3,0,0,0
0,32,32,32,32,32,32,32,32,32,32,32,32,32,32,32,32,32,0,0
0,0,0,0,0,0,0,0,0,0,0,0,0,0,0,0,0,0,0,0
0,0,0,0,0,0,0,0,0,0,0,0,0,0,0,0,0,0,0,0
0,0,0,0,0,0,0,0,0,0,0,0,0,0,0,0,0,0,0,0
0,0,0,0,0,0,0,0,0,0,0,0,0,0,0,0,0,0,0,0
0,0,0,0,0,0,0,0,0,0,0,0,0,0,0,0,0,0,0,0
0,0,0,0,0,0,0,0,0,0,0,0,0,0,0,0,0,0,0,0
0,0,0,0,0,0,0,0,0,0,0,0,0,0,0,0,0,0,0,0
0,0,0,0,0,0,0,0,0,0,0,0,0,0,0,0,0,0,0,0
0,0,0,0,0,0,0,0,0,0,0,0,0,0,0,0,0,0,0,0
endlayer

layer
0,0,0,0,0,0,0,0,0,0,0,0,0,0,0,0,0,0,0,0
0,0,0,0,0,0,0,0,0,0,0,0,0,0,0,0,0,0,0,0
0,0,0,0,0,0,0,0,0,0,0,0,0,0,0,0,0,0,0,0
0,0,0,0,0,0,0,0,0,0,0,0,0,0,0,0,0,0,0,0
0,0,0,0,0,0,0,0,0,0,0,0,0,0,0,0,0,0,0,0
0,0,0,0,0,0,0,0,0,0,0,0,0,0,0,0,0,0,0,0
0,0,0,0,0,0,0,38,0,0,0,0,0,0,0,0,0,0,0,0
0,0,0,0,0,0,3,0,0,0,0,0,0,0,0,0,0,0,0,0
0,0,0,0,0,0,0,0,0,0,0,0,0,0,0,0,0,0,0,0
0,6,6,6,6,6,6,6,6,6,6,6,6,6,6,6,6,6,0,0
0,0,0,0,0,0,0,0,0,0,0,0,0,0,0,0,0,0,0,0
0,0,0,0,0,0,0,0,0,0,0,0,0,0,0,0,0,0,0,0
0,0,0,0,0,0,0,0,0,0,0,0,0,0,0,0,0,0,0,0
0,0,0,0,0,0,0,0,0,0,0,0,0,0,0,0,0,0,0,0
0,0,0,0,0,0,0,0,0,0,0,0,0,0,0,0,0,0,0,0
0,0,0,0,0,0,0,0,0,0,0,0,0,0,0,0,0,0,0,0
0,0,0,0,0,0,0,0,0,0,0,0,0,0,0,0,0,0,0,0
0,0,0,0,0,0,0,0,0,0,0,0,0,0,0,0,0,0,0,0
0,0,0,0,0,0,0,0,0,0,0,0,0,0,0,0,0,0,0,0
0,0,0,0,0,0,0,0,0,0,0,0,0,0,0,0,0,0,0,0
endlayer

layer
0,0,0,0,0,0,0,0,0,0,0,0,0,0,0,0,0,0,0,0
0,0,0,0,0,0,0,0,0,0,0,0,0,0,0,0,0,0,0,0
0,0,0,0,0,0,0,0,0,0,0,0,0,0,0,0,0,0,0,0
0,0,0,0,0,0,0,0,0,0,0,0,0,0,0,0,0,0,0,0
0,0,0,0,0,0,0,0,0,0,0,0,0,0,0,0,0,0,0,0
0,0,0,0,0,0,0,0,0,0,0,0,0,0,0,0,0,0,0,0
0,0,0,0,0,0,0,0,0,0,0,0,0,0,0,0,0,0,0,0
0,0,0,0,0,0,38,0,0,0,0,0,0,0,0,0,0,0,0,0
0,0,0,0,0,0,0,0,0,0,0,0,0,0,0,0,0,0,0,0
0,0,0,0,0,0,0,0,0,0,0,0,0,0,0,0,0,0,0,0
0,0,0,0,0,0,0,0,0,0,0,0,0,0,0,0,0,0,0,0
0,0,0,0,0,0,0,0,0,0,0,0,0,0,0,0,0,0,0,0
0,0,0,0,0,0,0,0,0,0,0,0,0,0,0,0,0,0,0,0
0,0,0,0,0,0,0,0,0,0,0,0,0,0,0,0,0,0,0,0
0,0,0,0,0,0,0,0,0,0,0,0,0,0,0,0,0,0,0,0
0,0,0,0,0,0,0,0,0,0,0,0,0,0,0,0,0,0,0,0
0,0,0,0,0,0,0,0,0,0,0,0,0,0,0,0,0,0,0,0
0,0,0,0,0,0,0,0,0,0,0,0,0,0,0,0,0,0,0,0
0,0,0,0,0,0,0,0,0,0,0,0,0,0,0,0,0,0,0,0
0,0,0,0,0,0,0,0,0,0,0,0,0,0,0,0,0,0,0,0
endlayer

