
# Created by Ruins mod version 14.7 Ingame Parser
# authoring Player: OneWolfe

weight=10
unique=1
embed_into_distance=2
acceptable_target_blocks=
unacceptable_target_blocks=flowing_water,water,flowing_lava,lava
dimensions=16,17,11
allowable_overhang=8
max_leveling=4
leveling_buffer=0
preserve_water=1
preserve_lava=1
preserve_plants=1

rule1=0,100,preserveBlock
rule2=0,100,terrafirmacraft:StoneMMBrick-4
rule3=0,100,MobSpawner:zombieTFC,MobSpawner:TwilightForest.Redcap,MobSpawner:TwilightForest.Redcap,MobSpawner:TwilightForest.Redcap Sapper,MobSpawner:TwilightForest.Twilight Kobold,MobSpawner:TwilightForest.Mosquito Swarm
rule4=0,100,BiblioCraft:Printing Press-0
rule5=0,100,ChestGenHook:dungeonChest:5-4
rule6=0,100,terrafirmacraft:WallSmoothSed-4,terrafirmacraft:WallSmoothSed-4,terrafirmacraft:WallSmoothSed-4,terrafirmacraft:WallSmoothSed-4,air
rule7=0,100,minecraft:wooden_pressure_plate-0
rule8=0,100,terrafirmacraft:WoodVert-4
rule9=0,100,terrafirmacraft:planks-8,terrafirmacraft:planks-8,terrafirmacraft:planks-8,terrafirmacraft:planks-4,terrafirmacraft:planks-4,air
rule10=0,100,terrafirmacraft:DoorWillow-2
rule11=0,100,minecraft:web-0,air,air
rule12=0,100,terrafirmacraft:DoorWillow-8
rule13=0,100,minecraft:stained_glass_pane-9,minecraft:stained_glass_pane-9,minecraft:stained_glass_pane-9,air
rule14=0,100,terrafirmacraft:WoodHoriz-4
rule15=0,100,terrafirmacraft:WoodHoriz-12
rule16=0,100,terrafirmacraft:planks-4
rule17=0,100,minecraft:anvil-8,air
rule18=0,100,Railcraft:machine.alpha-7,Railcraft:machine.alpha-7,Railcraft:machine.alpha-7,air,air
rule19=0,100,IInventory;terrafirmacraft:LogPile;terrafirmacraft:item.Log#1#4#3-2,air
rule20=0,100,terrafirmacraft:Charcoal-8,air
rule21=0,100,IInventory;terrafirmacraft:LogPile;terrafirmacraft:item.Log#1#4#2-2,air
rule22=0,100,minecraft:coal_block-0,air
rule23=0,100,Railcraft:cube-0,air
rule24=0,100,BiblioCraft:Armor Stand-0,air
rule25=0,100,BiblioCraft:BiblioTable-6,air
rule26=0,100,BiblioCraft:Armor Stand-4,air
rule27=0,100,minecraft:hopper-0,air
rule28=0,100,terrafirmacraft:planks-7,terrafirmacraft:planks-7,terrafirmacraft:planks-7,terrafirmacraft:planks-7,terrafirmacraft:planks-7,terrafirmacraft:planks-7,air
rule29=0,100,ChestGenHook:dungeonChest:5-2,air
rule30=0,100,ChestGenHook:dungeonChest:5-5,air
rule31=0,100,MobSpawner:spiderTFC,MobSpawner:TwilightForest.Pinch Beetle,MobSpawner:TwilightForest.Hedge Spider,MobSpawner:TwilightForest.Fire Beetle,MobSpawner:TwilightForest.Swarm Spider
rule32=0,100,ChestGenHook:dungeonChest:5-3,air

layer
1,1,1,1,1,1,1,1,1,1,1
1,1,1,1,1,1,1,1,1,1,1
1,1,1,1,1,1,1,1,1,1,1
1,1,1,2,2,2,2,2,1,1,1
1,1,1,2,2,2,2,2,1,1,1
1,1,1,2,2,2,2,2,1,1,1
1,1,1,2,2,2,2,2,1,1,1
1,1,1,2,2,2,2,2,1,1,1
1,1,1,2,2,2,2,2,1,1,1
1,1,1,2,2,2,2,2,1,1,1
1,1,1,2,2,2,2,2,1,1,1
1,1,1,2,2,3,2,2,1,1,1
1,1,1,2,2,2,2,2,1,1,1
1,1,1,2,2,2,2,2,1,1,1
1,1,1,1,1,1,1,1,1,1,1
1,1,1,1,1,1,1,1,1,1,1
1,1,1,1,1,1,1,1,1,1,1
endlayer

layer
1,1,1,1,1,1,1,1,1,1,1
1,1,1,1,1,1,1,1,1,1,1
1,1,1,1,1,1,1,1,1,1,1
1,1,1,2,2,2,2,2,1,1,1
1,1,1,2,0,0,0,2,1,1,1
1,1,1,2,0,0,0,2,1,1,1
1,1,1,2,0,0,0,2,1,1,1
1,1,1,2,0,0,0,2,1,1,1
1,1,1,2,0,0,0,2,1,1,1
1,1,1,2,0,0,4,2,1,1,1
1,1,1,2,2,2,2,2,1,1,1
1,1,1,2,2,2,2,2,1,1,1
1,1,1,2,2,5,2,2,1,1,1
1,1,1,2,2,2,2,2,1,1,1
1,1,1,1,1,1,1,1,1,1,1
1,1,1,1,1,1,1,1,1,1,1
1,1,1,1,1,1,1,1,1,1,1
endlayer

layer
6,6,6,6,0,0,6,6,6,6,6
6,0,0,0,0,0,0,0,0,0,6
6,0,0,0,0,7,0,0,0,0,6
6,0,0,8,9,10,9,8,0,0,6
6,0,0,9,0,0,0,9,0,0,6
6,0,0,9,0,0,0,9,0,0,6
6,0,0,8,0,0,0,8,11,0,6
6,0,0,9,0,0,0,9,0,0,6
6,0,0,9,0,0,0,9,0,0,6
6,0,0,9,0,0,0,9,0,0,6
6,0,0,8,11,0,0,8,0,0,6
6,0,0,9,0,0,0,9,0,0,6
6,0,0,9,0,2,0,9,0,0,6
6,0,0,8,9,9,9,8,0,0,6
6,0,0,0,0,0,0,0,0,0,6
6,0,0,0,0,0,0,0,0,0,6
6,6,6,6,6,6,6,6,6,6,6
endlayer

layer
6,0,0,6,0,0,6,0,0,0,6
0,0,0,0,0,0,0,0,0,0,0
0,0,0,0,0,0,0,0,0,0,0
0,0,0,8,9,12,9,8,0,0,0
0,0,0,13,0,0,0,13,0,0,0
0,0,0,13,0,0,0,13,11,0,0
6,0,0,8,0,0,0,8,0,0,6
0,0,0,9,0,0,0,9,0,0,0
0,0,0,13,0,0,0,13,0,0,0
0,0,0,9,0,0,0,9,11,0,0
6,0,0,8,0,0,0,8,0,0,6
0,0,0,13,0,0,11,13,0,0,0
0,0,0,13,0,11,2,13,0,0,0
0,0,0,8,9,9,9,8,11,0,0
0,0,0,0,0,0,11,0,0,0,0
0,0,0,0,0,0,0,0,0,0,0
6,0,0,0,6,0,6,0,0,0,6
endlayer

layer
0,0,0,0,0,0,0,0,0,0,0
0,0,0,0,0,0,0,0,0,0,0
0,11,0,0,0,0,11,0,0,0,0
0,0,0,8,9,9,9,8,0,0,0
0,0,0,13,0,0,0,13,11,0,0
0,0,0,13,0,0,0,13,0,0,0
0,0,11,8,0,0,11,8,0,0,0
0,0,0,9,11,0,0,9,0,0,0
0,0,0,13,0,11,11,13,0,0,0
0,0,0,9,0,0,0,9,11,0,0
0,11,0,8,0,0,0,8,0,0,0
0,0,0,13,0,0,2,13,0,0,0
0,0,0,13,11,0,0,13,0,11,0
0,0,11,8,9,9,9,8,0,0,0
0,0,0,11,0,0,0,11,0,0,0
0,0,0,0,0,0,0,11,0,0,0
0,0,0,0,0,0,0,0,0,0,0
endlayer

layer
0,0,0,0,0,0,0,0,0,0,0
14,8,14,14,14,14,14,14,14,8,14
0,15,16,15,16,16,16,15,16,15,0
14,14,14,8,14,14,14,8,14,14,14
0,15,16,15,16,16,16,15,16,15,0
0,15,16,15,16,16,16,15,16,15,0
14,14,14,8,14,14,14,8,14,14,14
0,15,16,15,16,16,16,15,16,15,0
0,15,16,15,16,16,16,15,16,15,0
0,15,16,15,16,16,16,15,16,15,0
14,14,14,8,14,14,14,8,14,14,14
0,15,16,15,16,16,0,15,16,15,0
0,15,16,15,16,0,11,15,16,15,0
14,14,14,8,14,14,14,8,14,14,14
0,15,16,15,16,16,16,15,16,15,0
14,8,14,14,14,14,14,14,14,8,14
0,0,0,0,0,0,0,0,0,0,0
endlayer

layer
0,0,0,0,0,0,0,0,0,0,0
0,8,9,8,9,9,9,8,9,8,0
0,9,11,11,11,17,11,11,0,9,0
0,8,11,11,0,0,0,0,0,8,0
0,9,11,0,18,18,18,0,0,9,0
0,9,11,0,18,18,18,0,0,9,0
0,8,0,0,18,18,18,0,0,8,0
0,9,20,0,11,0,0,0,19,9,0
0,9,22,0,0,11,11,11,21,9,0
0,9,23,11,11,11,11,0,21,9,0
0,8,0,0,0,0,0,0,11,8,0
0,9,0,0,0,0,0,0,0,9,0
0,9,0,0,0,0,0,0,11,9,0
11,8,0,0,0,0,0,0,0,8,0
0,9,24,0,25,25,25,0,24,9,11
0,8,9,8,9,9,9,8,9,8,0
0,0,0,0,0,0,0,0,0,0,0
endlayer

layer
0,0,0,0,0,0,0,0,0,0,0
0,8,9,8,9,13,9,8,9,8,11
11,9,0,11,11,0,0,11,11,9,0
0,8,11,0,0,0,0,11,11,8,0
0,13,11,0,18,18,18,11,0,13,0
0,13,11,11,18,0,18,0,11,13,0
0,8,0,0,18,18,18,0,0,8,0
0,9,0,0,0,0,0,0,11,9,0
0,13,11,0,0,0,11,0,0,13,0
11,9,0,0,0,0,11,0,21,9,0
0,8,0,0,0,0,11,0,0,8,0
0,13,0,0,0,11,0,0,0,13,0
0,13,0,0,0,0,0,0,0,13,0
0,8,0,0,0,0,0,0,0,8,0
0,9,26,0,0,0,0,11,26,9,0
0,8,9,8,9,13,9,8,9,8,0
0,0,0,0,0,0,0,0,0,0,0
endlayer

layer
0,0,0,0,0,0,0,0,0,0,0
0,8,9,8,9,13,9,8,9,8,11
11,9,11,11,11,0,0,11,11,9,0
0,8,0,0,0,0,0,0,11,8,0
0,13,0,0,18,18,18,0,0,13,0
0,13,0,0,18,18,18,0,0,13,0
0,8,0,11,18,18,18,0,0,8,0
11,9,0,0,0,0,0,0,11,9,0
0,13,0,0,0,0,11,0,0,13,0
0,9,0,0,0,0,11,0,0,9,0
0,8,0,0,0,11,11,0,0,8,11
0,13,0,0,0,11,0,11,11,13,0
0,13,0,0,0,0,0,11,11,13,0
0,8,0,0,0,11,0,0,0,8,0
0,9,0,0,11,0,0,0,0,9,0
0,8,9,8,9,13,9,8,9,8,0
0,0,0,0,0,0,0,0,0,0,0
endlayer

layer
0,0,0,0,0,0,0,0,0,0,0
14,8,14,8,14,14,14,8,14,8,14
11,15,11,0,0,0,0,0,11,15,11
14,8,14,14,14,14,14,14,14,8,14
0,15,11,0,0,0,0,11,11,15,0
11,15,0,0,0,27,0,0,11,15,0
14,8,14,14,14,14,14,14,14,8,14
0,15,0,0,11,0,11,0,11,15,11
0,15,0,0,0,0,11,0,0,15,0
0,15,11,11,0,0,0,0,11,15,0
14,8,14,14,14,14,14,14,14,8,14
0,15,0,0,0,0,0,0,11,15,0
11,15,11,11,0,11,0,11,0,15,0
14,8,14,14,14,14,14,14,14,8,14
11,15,11,0,11,0,11,0,0,15,0
14,8,14,8,14,14,14,8,14,8,14
0,0,0,0,0,0,0,11,0,0,11
endlayer

layer
28,0,0,0,0,0,0,0,0,0,28
28,8,9,8,9,9,9,8,9,8,28
28,29,11,0,0,0,0,0,0,0,28
28,8,0,0,11,11,11,0,11,8,28
28,0,0,0,11,11,11,0,0,0,28
28,0,0,0,11,30,11,0,0,0,28
28,8,0,11,11,11,0,0,0,8,28
28,0,0,0,0,0,0,0,0,0,28
28,0,0,0,0,0,0,0,0,0,28
28,0,0,0,0,0,0,0,0,0,28
28,8,0,0,11,31,11,11,0,8,28
28,0,0,0,0,11,0,0,0,0,28
28,0,0,0,0,0,0,0,0,0,28
28,8,0,0,0,0,0,0,0,8,28
28,0,0,0,0,0,0,0,11,32,28
28,8,9,8,9,9,9,8,9,8,28
28,11,0,0,0,0,0,0,0,0,28
endlayer

layer
0,28,11,0,0,0,0,0,11,28,0
0,28,9,8,9,13,9,8,9,28,0
0,28,11,0,0,0,0,0,0,28,0
0,28,0,0,0,0,0,0,0,28,0
0,28,0,0,0,11,0,0,0,28,0
0,28,0,0,0,0,0,0,0,28,0
0,28,0,0,0,0,0,0,0,28,0
0,28,0,0,0,0,0,0,0,28,0
0,28,0,0,0,0,0,0,0,28,0
0,28,0,0,0,0,0,0,0,28,0
0,28,0,0,0,0,0,0,0,28,0
0,28,0,0,0,0,0,0,0,28,0
0,28,0,0,0,0,0,0,0,28,0
0,28,0,0,0,0,0,0,0,28,0
0,28,0,0,0,0,0,0,0,28,0
0,28,9,8,9,13,9,8,9,28,0
0,28,0,11,0,0,11,0,0,28,0
endlayer

layer
0,0,28,11,0,0,0,0,28,0,0
0,0,28,8,9,9,9,14,28,0,0
0,0,28,0,11,0,0,11,28,0,0
0,0,28,0,0,0,0,0,28,0,0
0,0,28,0,0,0,0,0,28,0,0
0,0,28,0,0,0,0,0,28,0,0
0,0,28,0,0,0,0,0,28,0,0
0,0,28,0,0,0,0,0,28,0,0
0,0,28,0,0,0,0,0,28,0,0
0,0,28,0,0,0,0,0,28,0,0
0,0,28,11,0,0,0,0,28,0,0
0,0,28,0,0,0,0,0,28,0,0
0,0,28,0,0,0,0,0,28,0,0
0,0,28,0,0,0,0,0,28,0,0
0,0,28,0,0,0,0,0,28,0,0
0,0,28,8,9,9,9,8,28,0,0
0,0,28,0,11,0,11,0,28,0,0
endlayer

layer
0,0,0,28,0,0,11,28,0,0,0
0,0,0,28,14,14,14,28,0,0,0
0,0,0,28,0,0,0,28,0,0,0
0,0,0,28,0,0,0,28,0,0,0
0,0,0,28,0,0,0,28,0,0,0
0,0,0,28,0,0,0,28,0,0,0
0,0,0,28,0,0,0,28,0,0,0
0,0,0,28,0,0,0,28,0,0,0
0,0,0,28,0,0,0,28,0,0,0
0,0,0,28,0,0,0,28,0,0,0
0,0,0,28,0,0,11,28,0,0,0
0,0,0,28,11,0,0,28,0,0,0
0,0,0,28,0,0,0,28,0,0,0
0,0,0,28,0,0,0,28,0,0,0
0,0,0,28,0,0,0,28,0,0,0
0,0,0,28,14,14,14,28,0,0,0
0,0,0,28,0,0,0,28,0,0,0
endlayer

layer
0,0,0,0,28,0,28,0,0,0,0
0,0,0,0,28,9,28,0,0,0,0
0,0,0,0,28,0,28,0,0,0,0
0,0,0,0,28,0,28,0,0,0,0
0,0,0,0,28,0,28,0,0,0,0
0,0,0,0,28,0,28,0,0,0,0
0,0,0,0,28,0,28,0,0,0,0
0,0,0,0,28,0,28,0,0,0,0
0,0,0,0,28,0,28,0,0,0,0
0,0,0,0,28,0,28,0,0,0,0
0,0,0,0,28,0,28,0,0,0,0
0,0,0,0,28,0,28,0,0,0,0
0,0,0,0,28,0,28,0,0,0,0
0,0,0,0,28,0,28,0,0,0,0
0,0,0,0,28,0,28,0,0,0,0
0,0,0,0,28,9,28,0,0,0,0
0,0,0,0,28,0,28,0,0,0,0
endlayer

layer
0,0,0,0,0,28,0,0,0,0,0
0,0,0,0,0,28,0,0,0,0,0
0,0,0,0,0,28,0,0,0,0,0
0,0,0,0,0,28,0,0,0,0,0
0,0,0,0,0,28,0,0,0,0,0
0,0,0,0,0,28,0,0,0,0,0
0,0,0,0,0,28,0,0,0,0,0
0,0,0,0,0,28,0,0,0,0,0
0,0,0,0,0,28,0,0,0,0,0
0,0,0,0,0,28,0,0,0,0,0
0,0,0,0,0,28,0,0,0,0,0
0,0,0,0,0,28,0,0,0,0,0
0,0,0,0,0,28,0,0,0,0,0
0,0,0,0,0,28,0,0,0,0,0
0,0,0,0,0,28,0,0,0,0,0
0,0,0,0,0,28,0,0,0,0,0
0,0,0,0,0,28,0,0,0,0,0
endlayer

