
# Created by Ruins mod version 13.8 Ingame Parser
# authoring Player: OneWolfe

weight=8
embed_into_distance=4
biomesToSpawnIn=plains,jungle,swamp,forest,tiaga,high hills
unacceptable_target_blocks=flowing_water,water,flowing_lava,lava,terrafirmacraft:SaltWaterStationary-0,terrafirmacraft:SaltWaterStationary-8,terrafirmacraft:FreshWaterStationary-0,terrafirmacraft:FreshWaterStationary-8
dimensions=10,13,15
allowable_overhang=4
max_leveling=6
leveling_buffer=0
preserve_water=0
preserve_lava=0
preserve_plants=1

rule1=0,100,preserveBlock
rule2=0,100,preserveBlock
rule3=0,100,preserveBlock
rule4=0,100,TwilightForest:tile.TFRoots-0
rule5=0,100,terrafirmacraft:WoodVert-9
rule6=0,100,terrafirmacraft:WoodVert-9

layer
1,1,1,1,1,2,1,1,1,1,1,1,1,1,1
3,3,3,3,3,3,3,3,3,3,3,3,3,3,3
3,3,3,3,3,3,3,3,3,3,3,3,3,3,3
3,3,3,3,3,3,3,3,4,3,3,3,3,3,3
3,3,3,3,4,3,4,4,4,3,3,3,3,3,3
3,3,3,3,3,4,4,4,4,4,3,3,3,3,3
3,3,3,3,4,4,4,4,4,4,4,3,3,3,3
3,3,3,3,4,4,4,4,4,4,4,3,3,3,3
3,3,3,4,4,4,4,4,4,4,4,4,3,3,3
3,3,3,3,3,4,4,4,4,4,3,3,3,3,3
3,3,3,3,3,3,4,4,4,3,3,3,3,3,3
3,3,3,3,3,3,3,4,3,3,3,3,3,3,3
3,3,3,4,3,3,3,3,3,3,3,3,3,3,1
endlayer

layer
1,1,1,1,1,1,1,4,1,1,1,1,1,1,1
3,3,3,3,3,3,3,3,3,3,3,3,3,3,3
3,3,3,3,3,3,3,3,3,3,3,3,3,3,3
3,3,3,3,3,3,3,3,4,3,3,3,3,3,3
3,3,3,3,4,3,4,4,4,3,3,3,3,3,3
3,3,3,3,3,4,4,4,4,4,3,3,3,3,3
3,3,3,3,4,4,4,4,4,4,4,3,3,3,3
3,3,3,3,4,4,4,4,4,4,4,3,3,3,3
3,3,3,4,4,4,4,4,4,4,4,4,3,3,3
3,3,3,3,3,4,4,4,4,4,3,3,3,3,3
3,3,3,3,3,3,4,4,4,3,3,3,3,3,3
3,3,3,3,4,3,3,3,3,3,3,3,3,3,1
3,3,3,4,3,3,3,3,3,3,3,3,3,3,1
endlayer

layer
1,1,1,1,1,1,1,4,1,1,1,1,1,1,1
3,3,3,3,3,3,3,5,3,3,3,3,3,3,1
3,3,3,3,3,3,3,3,3,3,3,3,3,3,1
3,3,3,3,3,3,3,3,3,3,3,3,3,3,1
3,3,3,3,4,3,4,4,4,3,3,3,3,3,1
5,3,3,3,3,4,4,4,4,4,3,3,3,3,5
3,3,3,3,4,4,4,4,4,4,4,3,3,3,1
3,3,3,3,4,4,4,4,4,4,4,3,3,3,1
3,3,3,3,4,4,4,4,4,4,4,4,3,3,1
3,3,3,3,3,4,4,4,4,4,3,3,3,3,1
3,3,3,3,4,3,4,4,4,3,3,3,3,3,1
3,3,3,3,4,3,3,3,3,3,3,3,3,3,1
3,3,3,3,3,3,3,3,3,3,3,3,5,3,1
endlayer

layer
2,2,2,2,2,2,2,2,2,2,2,2,2,2,2
2,2,2,2,2,2,2,5,2,2,2,2,2,2,2
2,2,2,2,2,2,2,5,2,2,2,2,2,2,2
2,2,2,2,2,2,2,1,2,2,2,2,2,2,2
2,2,2,2,2,2,6,6,4,2,2,2,2,2,2
5,5,2,2,2,4,6,6,6,6,2,2,2,5,5
2,2,1,2,6,6,5,5,5,6,6,2,1,2,2
2,2,2,2,6,6,5,5,5,6,6,2,2,2,2
2,2,2,2,4,6,5,5,5,6,4,2,2,2,2
2,2,2,2,2,6,6,6,6,6,2,2,2,2,2
2,2,2,2,4,5,6,4,6,2,1,2,2,2,2
2,2,2,2,2,2,2,2,2,2,2,5,2,2,2
2,2,2,2,2,2,2,2,2,2,2,2,5,2,2
endlayer

layer
0,0,0,0,0,0,0,0,0,0,0,0,0,0,0
0,0,0,0,0,0,0,0,0,0,0,0,0,0,0
0,0,0,0,0,0,0,5,0,0,0,0,0,0,0
0,0,0,0,0,0,0,5,0,0,0,0,0,0,0
0,0,0,0,0,0,6,6,5,0,0,0,0,0,0
0,5,0,0,0,5,6,6,6,6,0,0,0,5,0
0,0,5,0,6,6,0,0,0,6,6,0,5,0,0
0,0,0,0,6,6,0,0,0,6,6,0,0,0,0
0,0,0,0,5,6,0,0,0,6,5,0,0,0,0
0,0,0,0,0,5,6,6,6,6,0,0,0,0,0
0,0,0,0,0,5,6,6,6,0,5,0,0,0,0
0,0,0,0,0,0,0,0,0,0,0,5,0,0,0
0,0,0,0,0,0,0,0,0,0,0,0,0,0,0
endlayer

layer
0,0,0,0,0,0,0,0,0,0,0,0,0,0,0
0,0,0,0,0,0,0,0,0,0,0,0,0,0,0
0,0,0,0,0,0,0,0,0,0,0,0,0,0,0
0,0,0,0,0,0,0,5,0,0,0,0,0,0,0
0,0,0,0,0,0,6,5,6,0,0,0,0,0,0
0,0,0,0,0,5,6,6,6,6,0,0,0,0,0
0,0,5,5,6,6,0,0,0,6,6,5,5,0,0
0,0,0,0,6,6,0,0,0,6,6,0,0,0,0
0,0,0,0,6,6,0,0,0,6,5,0,0,0,0
0,0,0,0,0,5,6,6,6,6,0,0,0,0,0
0,0,0,0,0,0,6,6,6,0,5,0,0,0,0
0,0,0,0,0,0,0,0,0,0,0,0,0,0,0
0,0,0,0,0,0,0,0,0,0,0,0,0,0,0
endlayer

layer
0,0,0,0,0,0,0,0,0,0,0,0,0,0,0
0,0,0,0,0,0,0,0,0,0,0,0,0,0,0
0,0,0,0,0,0,0,0,0,0,0,0,0,0,0
0,0,0,0,0,0,0,0,0,0,0,0,0,0,0
0,0,0,0,0,0,6,5,6,0,0,0,0,0,0
0,0,0,0,0,6,6,6,6,6,0,0,0,0,0
0,0,0,5,5,6,0,0,0,6,5,5,0,0,0
0,0,0,0,6,6,0,0,0,6,6,0,0,0,0
0,0,0,0,6,6,0,0,0,6,6,0,0,0,0
0,0,0,0,0,6,6,6,6,5,0,0,0,0,0
0,0,0,0,0,0,6,6,6,0,5,0,0,0,0
0,0,0,0,0,0,0,0,0,0,0,0,0,0,0
0,0,0,0,0,0,0,0,0,0,0,0,0,0,0
endlayer

layer
0,0,0,0,0,0,0,0,0,0,0,0,0,0,0
0,0,0,0,0,0,0,0,0,0,0,0,0,0,0
0,0,0,0,0,0,0,0,0,0,0,0,0,0,0
0,0,0,0,0,0,0,0,0,0,0,0,0,0,0
0,0,0,0,0,0,6,6,6,0,0,0,0,0,0
0,0,0,0,0,6,6,6,6,0,0,0,0,0,0
0,0,0,0,5,6,0,0,0,6,5,0,0,0,0
0,0,0,0,6,6,0,0,0,6,6,0,0,0,0
0,0,0,0,6,6,0,0,0,6,6,0,0,0,0
0,0,0,0,0,6,6,6,6,5,0,0,0,0,0
0,0,0,0,0,0,6,6,6,0,0,0,0,0,0
0,0,0,0,0,0,0,0,0,0,0,0,0,0,0
0,0,0,0,0,0,0,0,0,0,0,0,0,0,0
endlayer

layer
0,0,0,0,0,0,0,0,0,0,0,0,0,0,0
0,0,0,0,0,0,0,0,0,0,0,0,0,0,0
0,0,0,0,0,0,0,0,0,0,0,0,0,0,0
0,0,0,0,0,0,0,0,0,0,0,0,0,0,0
0,0,0,0,0,0,6,0,6,0,0,0,0,0,0
0,0,0,0,0,0,0,6,0,0,0,0,0,0,0
0,0,0,0,6,6,0,0,0,6,0,0,0,0,0
0,0,0,0,0,6,0,0,0,0,6,0,0,0,0
0,0,0,0,0,0,0,0,0,6,6,0,0,0,0
0,0,0,0,0,0,6,6,6,6,0,0,0,0,0
0,0,0,0,0,0,6,6,6,0,0,0,0,0,0
0,0,0,0,0,0,0,0,0,0,0,0,0,0,0
0,0,0,0,0,0,0,0,0,0,0,0,0,0,0
endlayer

layer
0,0,0,0,0,0,0,0,0,0,0,0,0,0,0
0,0,0,0,0,0,0,0,0,0,0,0,0,0,0
0,0,0,0,0,0,0,0,0,0,0,0,0,0,0
0,0,0,0,0,0,0,0,0,0,0,0,0,0,0
0,0,0,0,0,0,0,0,6,0,0,0,0,0,0
0,0,0,0,0,0,0,0,0,0,0,0,0,0,0
0,0,0,0,0,0,0,0,0,6,0,0,0,0,0
0,0,0,0,0,0,0,0,0,0,0,0,0,0,0
0,0,0,0,0,0,0,0,0,0,0,0,0,0,0
0,0,0,0,0,0,0,0,0,6,0,0,0,0,0
0,0,0,0,0,0,6,0,0,0,0,0,0,0,0
0,0,0,0,0,0,0,0,0,0,0,0,0,0,0
0,0,0,0,0,0,0,0,0,0,0,0,0,0,0
endlayer

