
# Created by Ruins mod version 13.8 Ingame Parser
# authoring Player: OneWolfe

weight=4
unique=1
embed_into_distance=0
acceptable_target_blocks=
unacceptable_target_blocks=flowing_water,water,flowing_lava,lava
dimensions=25,21,12
allowable_overhang=5
max_leveling=8
leveling_buffer=0
preserve_water=0
preserve_lava=0
preserve_plants=1

rule1=0,100,terrafirmacraft:StoneSedBrick-5,terrafirmacraft:StoneSedBrick-5,terrafirmacraft:StoneSedCobble-5
rule2=0,100,terrafirmacraft:WallBrickSed-5
rule3=0,100,terrafirmacraft:StoneMMBrick-2
rule4=0,100,terrafirmacraft:StoneMMCobble-2
rule5=0,100,terrafirmacraft:StoneSedBrick-5
rule6=0,100,terrafirmacraft:StoneSedCobble-5
rule7=0,100,terrafirmacraft:WallSmoothMM-2
rule8=0,100,air
rule9=0,100,air,BiblioCraft:Bibliotheca-0,minecraft:web-0,BiblioCraft:Bibliotheca-0,
rule10=0,100,air,terrafirmacraft:Bookshelf-0
rule11=0,100,BiblioCraft:BiblioLantern-3
rule12=0,100,terrafirmacraft:StoneMMSmooth-2
rule13=0,100,air,terrafirmacraft:StoneMMBrick-2,terrafirmacraft:StoneMMCobble-2,terrafirmacraft:StoneMMCobble-2
rule14=0,100,minecraft:iron_bars-0
rule15=0,100,air,BiblioCraft:BiblioShelf-0,minecraft:web-0,BiblioCraft:BiblioShelf-0,
rule16=0,100,air,air,MobSpawner:TwilightForest.Death Tome,MobSpawner:TwilightForest.Death Tome,MobSpawner:TwilightForest.Skeleton Druid
rule17=0,100,air,air,MobSpawner:TwilightForest.Death Tome,MobSpawner:TwilightForest.Death Tome,MobSpawner:TwilightForest.Skeleton Druid,MobSpawner:skeletonTFC,MobSpawner:spiderTFC
rule18=0,100,terrafirmacraft:StoneSedSmooth-5

layer
0,1,0,0,0,0,0,2,0,0,0,1
0,0,0,0,0,1,0,0,0,0,0,0
0,0,0,1,0,0,0,2,0,0,0,2
0,0,0,0,0,0,0,0,3,3,3,0
0,5,5,4,5,5,4,5,5,5,4,0
0,4,5,5,5,5,5,5,5,4,4,0
0,5,5,5,5,6,5,4,5,4,0,0
0,5,5,4,5,5,5,5,5,5,6,0
0,5,5,5,6,5,5,6,5,4,0,0
0,4,5,5,5,5,6,5,5,6,4,0
0,5,5,5,4,5,5,5,5,4,4,0
0,5,5,5,5,5,5,5,6,5,0,0
0,5,5,6,5,5,6,5,5,4,4,0
0,4,5,5,5,5,5,5,5,4,4,0
0,5,5,5,5,4,5,5,5,5,0,0
0,5,5,6,5,6,5,5,5,4,4,0
0,5,5,5,4,5,5,4,5,6,0,0
0,5,5,5,5,5,5,5,5,4,6,0
0,4,5,5,5,5,5,6,5,4,6,0
0,5,5,4,5,5,5,5,4,5,0,0
0,0,0,0,0,0,0,0,0,0,0,0
endlayer

layer
0,0,0,0,0,0,0,7,0,0,0,1
0,0,0,0,0,0,0,0,0,0,0,0
0,0,0,0,0,0,0,7,0,0,0,7
0,0,0,0,0,0,0,0,0,0,0,0
0,5,5,6,5,5,6,5,0,0,0,0
0,5,0,0,0,0,0,0,0,0,0,0
0,6,0,0,0,0,0,0,0,0,0,0
0,5,0,0,10,9,0,8,0,4,0,0
0,5,0,0,9,9,0,8,0,0,0,0
0,5,0,8,9,9,0,8,0,0,0,0
0,5,0,0,9,9,0,8,4,0,0,0
0,5,0,8,0,0,0,8,0,0,0,0
0,6,0,0,0,0,0,0,0,0,0,0
0,5,8,8,9,9,8,0,0,4,0,0
0,5,8,8,9,9,0,8,0,0,0,0
0,6,8,8,9,9,0,8,0,0,0,0
0,5,0,0,10,9,0,0,4,0,0,0
0,5,0,0,0,0,0,0,0,0,0,0
0,5,0,0,0,0,0,0,0,0,0,0
0,5,6,5,5,6,5,6,5,5,0,0
0,0,0,0,0,0,0,0,0,0,0,0
endlayer

layer
0,0,0,0,0,0,0,7,0,0,0,0
0,0,0,0,0,0,0,0,0,0,0,0
0,0,0,0,0,0,0,7,0,0,0,7
0,0,0,0,0,0,11,0,0,0,0,0
0,5,12,12,5,12,12,5,0,0,0,0
0,12,0,0,0,0,0,0,0,0,0,0
0,12,0,8,0,0,0,0,0,0,0,0
0,12,0,8,9,9,0,0,0,0,0,0
0,5,0,8,9,9,8,8,0,0,0,0
0,12,0,0,9,9,8,8,0,0,0,0
0,12,0,8,9,9,8,8,0,0,0,0
0,12,8,8,0,0,8,0,0,0,0,0
0,12,0,0,0,0,0,8,0,0,0,0
0,12,0,8,9,9,8,0,0,0,0,0
0,12,0,0,9,9,0,0,0,0,0,0
0,5,0,0,9,9,8,0,0,0,0,0
0,12,0,8,9,9,0,8,0,0,0,0
0,12,0,0,0,0,0,0,0,0,0,0
0,12,0,0,0,8,0,0,0,0,0,0
0,1,12,13,5,12,12,12,12,5,0,0
0,0,0,0,0,0,0,0,0,0,0,0
endlayer

layer
0,0,0,8,0,0,0,7,0,0,0,0
0,0,0,0,0,0,0,0,0,0,0,0
0,0,0,0,0,0,0,7,0,0,0,7
0,0,0,0,0,0,0,0,0,0,0,0
0,1,12,5,14,5,12,5,0,0,0,0
0,12,0,0,0,0,0,0,0,0,0,0
0,12,0,0,0,0,0,0,0,0,0,0
0,5,0,0,9,9,0,0,0,0,0,0
0,14,0,0,9,9,0,0,0,0,0,0
0,5,0,0,9,9,0,0,0,0,0,0
0,12,0,0,9,9,0,0,0,0,0,0
0,12,0,8,0,0,0,0,8,0,0,0
0,12,0,0,0,0,0,0,0,0,0,0
0,12,0,0,9,9,0,0,0,0,0,0
0,5,0,0,9,9,0,0,0,0,0,0
0,14,0,0,9,9,0,0,0,0,0,0
0,5,0,0,9,9,0,0,0,0,0,0
0,13,0,0,0,0,0,0,0,0,0,0
0,12,0,0,0,0,0,0,0,0,0,0
0,5,12,5,14,5,12,12,5,14,0,0
0,0,0,0,0,0,0,0,0,0,0,0
endlayer

layer
0,0,0,0,0,0,0,13,0,0,0,0
0,0,0,0,0,0,0,13,0,0,0,0
0,0,0,0,0,0,0,5,0,0,0,5
0,0,0,2,0,0,0,5,0,0,0,0
0,5,12,5,14,1,12,5,5,5,0,0
0,12,0,0,0,0,0,0,0,0,0,0
0,12,0,0,0,8,0,0,8,0,0,0
2,5,2,0,0,0,0,0,0,0,0,0
0,14,0,0,0,0,0,0,0,0,0,8
0,5,0,0,0,0,0,0,0,0,0,0
0,12,0,0,0,0,0,0,0,0,0,0
0,13,0,0,0,8,0,0,0,0,0,0
0,12,0,0,0,0,0,0,0,0,0,0
0,12,0,0,0,0,0,8,0,0,0,0
0,5,0,0,0,8,0,0,0,0,0,0
0,14,0,0,0,0,0,0,0,0,0,0
2,5,2,0,0,0,0,0,0,0,0,0
0,12,0,0,0,0,0,0,0,0,0,0
0,12,0,0,0,2,0,0,2,0,0,0
0,5,12,5,14,5,13,13,5,14,0,0
0,0,0,0,0,2,0,0,2,0,0,0
endlayer

layer
0,0,0,0,0,0,0,0,0,0,0,0
0,0,0,0,0,0,0,0,13,0,0,0
0,0,0,0,0,0,0,0,5,0,0,0
0,0,0,0,0,0,0,0,1,0,0,0
0,5,12,1,14,5,13,12,5,1,0,0
0,12,0,0,0,0,0,0,0,0,0,0
0,12,0,0,0,0,0,0,0,0,0,0
0,5,0,0,0,0,0,0,0,0,0,0
0,14,0,0,0,0,0,0,0,0,0,0
0,5,0,0,0,0,0,0,0,0,0,0
0,12,0,0,0,0,0,0,0,0,0,0
0,12,0,0,0,0,0,0,0,0,0,0
0,13,0,0,0,0,0,0,0,0,0,0
0,12,0,0,0,0,0,0,0,0,0,0
0,5,0,0,0,0,0,0,0,0,0,0
0,14,0,0,0,0,0,0,0,0,0,0
0,5,0,0,0,0,0,0,0,0,0,0
0,12,0,0,0,0,0,0,0,0,0,0
0,12,0,0,0,0,0,0,0,0,0,0
0,5,12,5,14,5,12,13,5,14,0,0
0,0,0,0,0,0,0,0,0,0,0,0
endlayer

layer
0,0,0,0,0,0,0,0,0,0,0,0
0,0,0,0,0,0,0,0,0,13,0,0
0,0,0,0,0,0,0,0,0,5,0,0
0,0,0,0,0,0,0,0,0,5,0,0
0,1,12,5,14,5,12,12,1,5,0,0
0,12,0,0,0,0,0,0,0,0,0,0
0,13,0,0,0,0,0,0,0,0,0,0
0,5,0,0,0,0,0,0,0,0,0,0
0,14,0,0,0,0,0,0,0,0,0,0
0,5,0,0,0,0,0,0,0,0,0,0
0,12,0,0,0,0,0,0,0,0,0,0
0,12,0,0,0,0,0,0,0,0,0,0
0,12,0,0,0,0,0,0,0,0,0,0
0,13,0,0,0,0,0,0,0,0,0,0
0,5,0,0,0,0,0,0,0,0,0,0
0,14,0,0,0,0,0,0,0,0,0,0
0,5,0,0,0,0,0,0,0,0,0,0
0,12,0,0,0,0,0,0,0,0,0,0
0,13,0,0,0,0,0,0,0,0,0,0
0,5,12,5,14,5,12,12,5,14,0,0
0,0,0,0,0,0,0,0,0,0,0,0
endlayer

layer
0,0,0,0,0,0,0,0,0,0,0,0
0,0,0,0,0,0,0,0,0,0,0,0
0,0,0,0,0,0,0,0,0,0,0,0
0,0,0,0,0,0,0,0,0,0,0,0
0,5,12,12,5,12,12,12,5,14,0,0
0,12,0,0,0,0,0,0,0,0,0,0
0,12,0,0,0,0,0,0,0,0,0,0
0,12,0,0,0,0,0,0,0,0,0,0
0,5,0,0,0,0,0,0,0,0,0,0
0,12,0,0,0,0,0,0,0,0,0,0
0,12,0,0,0,0,0,0,0,0,0,0
0,12,0,0,0,0,0,0,0,0,0,0
0,12,0,0,0,0,0,0,0,0,0,0
0,12,0,0,0,0,0,0,0,0,0,0
0,12,0,0,0,0,0,0,0,0,0,0
0,5,0,0,0,0,0,0,0,0,0,0
0,12,0,0,0,0,0,0,0,0,0,0
0,12,0,0,0,0,0,0,0,0,0,0
0,12,0,0,0,0,0,0,0,0,0,0
0,1,12,12,5,12,12,12,12,5,12,0
0,0,0,0,0,0,0,0,0,0,0,0
endlayer

layer
0,0,0,0,0,0,0,0,0,0,0,0
0,0,0,0,0,0,0,0,0,0,0,0
0,0,0,0,0,0,0,0,0,0,0,0
0,0,0,0,0,0,0,0,0,0,0,0
0,5,5,5,5,5,1,5,5,14,0,0
0,5,5,5,5,5,5,1,0,0,0,0
0,5,5,5,5,5,1,0,0,0,0,0
0,1,5,1,5,5,5,1,0,0,0,0
0,5,5,5,5,5,5,0,0,0,0,0
0,5,5,5,5,1,5,1,0,0,0,0
0,5,5,5,5,5,5,1,0,0,0,0
0,5,5,5,5,5,5,0,0,0,0,0
0,1,5,1,5,5,1,0,0,0,0,0
0,5,5,5,5,5,1,0,0,0,0,0
0,5,5,5,5,5,5,1,0,0,0,0
0,5,5,5,5,1,5,1,0,0,0,0
0,5,5,5,5,5,1,1,0,0,0,0
0,1,5,5,5,5,1,1,1,0,0,0
0,5,5,1,5,1,1,1,1,1,0,0
0,5,5,1,5,5,1,5,5,5,5,0
0,0,0,0,0,0,0,0,0,0,0,0
endlayer

layer
0,0,0,8,0,0,0,0,0,0,0,0
0,0,0,0,0,0,0,0,0,0,0,0
0,0,0,0,0,0,0,0,0,0,0,0
0,0,0,0,0,0,0,0,0,0,0,0
0,5,13,12,5,12,12,12,5,14,5,0
0,12,0,0,0,0,0,0,0,0,0,0
0,12,0,0,0,8,0,0,0,0,0,0
0,12,0,8,16,15,8,0,0,0,0,8
0,5,0,8,15,15,8,8,0,8,0,8
0,12,0,8,15,15,8,0,0,8,0,0
0,12,8,8,15,15,8,0,0,0,0,8
0,12,0,0,0,0,0,0,0,0,0,0
0,12,0,0,0,0,0,8,0,0,0,0
0,12,0,0,15,15,8,0,8,0,0,0
0,12,0,0,15,15,8,0,0,0,0,0
0,5,0,0,17,15,8,0,0,0,0,0
0,12,0,0,15,15,8,0,0,0,0,8
0,12,0,0,0,0,0,0,0,0,0,0
0,12,0,0,0,0,0,0,0,0,0,0
0,5,12,12,5,12,12,12,12,5,12,0
0,0,0,0,0,0,0,0,0,0,0,0
endlayer

layer
0,0,0,0,0,0,0,0,0,0,0,0
0,0,0,0,0,0,0,0,0,0,0,0
0,0,0,0,0,0,0,0,0,0,0,0
0,0,0,0,0,0,0,0,0,0,0,0
0,1,12,5,14,5,12,13,5,0,5,0
0,12,0,0,0,0,0,0,0,0,0,0
0,12,0,0,0,0,0,0,0,0,0,0
0,5,0,0,15,15,8,0,0,0,0,0
0,14,0,0,15,15,0,0,0,0,0,0
0,5,0,0,15,15,8,0,0,0,0,0
0,12,0,0,15,15,0,0,0,0,0,0
0,12,0,0,0,0,8,0,8,0,0,0
0,13,0,0,0,0,8,0,0,0,0,0
0,12,0,0,15,15,0,0,0,0,0,0
0,5,0,0,15,15,0,0,0,0,0,0
0,14,0,0,15,15,0,0,0,0,0,0
0,5,0,0,15,15,0,0,0,0,0,0
0,12,0,0,0,0,8,0,0,0,0,0
0,12,0,0,0,0,0,0,0,0,0,0
0,5,13,5,14,5,12,12,5,14,0,0
0,0,0,0,0,0,0,0,0,0,0,0
endlayer

layer
0,0,0,0,0,0,0,0,0,0,0,0
0,0,0,0,0,0,0,0,0,0,0,0
0,0,0,0,0,0,0,0,0,0,0,0
0,0,0,2,0,0,0,0,0,0,0,0
0,5,12,5,14,1,12,12,12,5,13,0
0,12,0,0,0,0,0,0,0,0,0,0
0,13,0,0,0,0,0,0,0,0,0,0
2,5,2,0,15,15,8,0,0,0,0,0
0,14,8,8,15,15,8,8,0,0,0,0
0,1,0,0,15,15,0,0,0,0,0,0
0,12,0,8,15,15,0,0,0,0,0,0
0,12,0,0,0,0,0,0,0,0,0,0
0,12,0,0,0,0,0,0,0,0,0,0
0,12,0,8,15,15,0,0,0,8,0,0
2,5,2,8,15,15,0,0,8,0,0,0
0,14,0,0,15,15,8,0,0,8,0,0
0,1,0,8,15,15,0,0,0,0,0,0
0,12,0,0,0,0,0,0,0,0,0,0
0,12,0,2,0,0,0,0,2,0,0,0
0,1,12,5,14,1,12,12,5,14,0,0
0,0,0,2,0,0,0,0,0,0,0,0
endlayer

layer
0,0,0,0,0,0,0,0,0,0,0,0
0,0,0,0,0,0,0,0,0,0,0,0
0,0,0,0,0,0,0,0,0,0,0,0
0,0,0,0,0,0,0,0,0,0,0,0
0,5,12,1,14,5,13,12,12,12,13,0
0,12,0,0,0,0,0,0,0,0,0,0
0,12,0,0,0,0,0,0,0,0,0,0
0,5,0,0,0,0,0,0,0,0,0,0
0,14,0,0,0,0,0,0,0,0,0,0
0,5,0,0,0,0,0,0,0,0,0,0
0,12,0,0,0,0,0,0,0,0,0,0
0,13,0,0,0,0,0,0,0,0,0,0
0,12,0,0,0,0,0,0,0,0,0,0
0,12,0,0,0,0,0,0,0,0,0,0
0,5,0,0,8,0,0,0,0,0,0,0
0,14,0,0,0,8,0,0,0,0,0,0
0,5,0,0,0,0,0,0,0,0,0,0
0,12,0,0,0,0,0,0,0,0,0,0
0,12,0,0,0,0,0,0,0,0,0,0
0,5,12,5,14,5,12,12,5,14,5,0
0,0,0,0,0,0,0,0,0,0,0,0
endlayer

layer
0,0,0,0,0,0,0,0,0,0,0,0
0,0,0,0,0,0,0,0,0,0,0,0
0,0,0,0,0,0,0,0,0,0,0,0
0,0,0,0,0,0,0,0,0,0,0,0
0,1,12,12,5,12,12,12,12,12,12,0
0,12,0,0,0,0,0,0,0,0,0,0
0,12,0,0,0,0,0,0,0,0,0,0
0,12,0,0,0,0,0,0,0,0,0,0
0,5,0,0,0,0,0,0,0,0,0,0
0,12,0,0,0,0,0,0,0,0,0,0
0,12,0,0,0,0,0,0,0,0,0,0
0,12,0,0,0,0,0,0,0,0,0,0
0,12,0,0,0,0,0,0,0,0,0,0
0,12,0,0,0,0,0,0,0,0,0,0
0,12,0,0,0,0,0,0,0,0,0,0
0,5,0,0,0,0,0,0,0,0,0,0
0,12,0,0,0,0,0,0,0,0,0,0
0,12,0,0,0,0,0,0,0,0,0,0
0,12,0,0,0,0,0,0,0,0,0,0
0,5,12,12,5,12,12,12,12,5,12,0
0,0,0,0,0,0,0,0,0,0,0,0
endlayer

layer
0,0,0,0,0,0,0,0,0,0,0,0
0,0,0,0,0,0,0,0,0,0,0,0
0,0,0,0,0,0,0,0,0,0,0,0
1,0,0,0,0,0,0,0,0,0,0,0
1,5,5,5,5,5,1,5,5,5,1,0
1,5,0,0,0,0,0,0,0,0,0,0
18,1,0,0,0,8,0,0,0,8,0,0
5,5,0,0,8,0,0,8,0,0,0,8
1,5,0,0,0,0,0,0,0,0,0,0
1,5,0,0,0,0,0,0,0,0,0,0
18,5,0,0,0,0,0,0,0,0,0,0
5,1,0,0,0,0,0,0,0,0,0,0
18,5,0,0,0,0,0,0,0,0,0,0
5,5,0,0,0,0,0,0,0,0,0,0
1,5,0,0,0,0,0,0,0,0,0,0
1,5,0,0,0,0,0,0,0,0,0,0
1,1,0,0,0,0,0,0,0,0,0,0
5,5,0,0,0,0,0,0,0,0,0,0
18,5,0,0,0,0,0,0,0,0,0,0
1,5,5,1,5,5,5,1,5,5,5,0
1,0,0,0,0,0,0,0,0,0,0,0
endlayer

layer
0,0,0,8,0,0,0,0,0,8,0,8
0,0,0,0,0,0,0,8,0,0,0,0
0,0,0,0,0,0,8,0,0,0,0,8
0,1,0,0,0,0,0,0,0,0,0,0
0,18,5,12,12,12,12,12,12,1,0,0
0,18,0,0,0,0,0,0,0,0,0,0
0,5,0,0,0,0,0,0,0,0,0,0
0,18,0,0,0,0,0,0,0,0,0,0
0,18,0,0,0,0,0,0,0,0,0,0
0,18,0,0,0,0,0,0,0,0,0,0
0,5,0,0,0,0,0,0,0,0,0,0
0,18,0,0,0,0,0,0,0,0,0,0
0,18,0,0,0,0,0,0,0,0,0,0
0,18,0,0,0,0,0,0,0,0,0,0
0,18,0,0,0,0,0,0,0,0,0,0
0,5,0,0,0,0,0,0,0,0,0,0
0,18,0,0,0,0,0,0,0,0,0,0
0,18,0,0,0,0,0,0,0,0,0,0
0,5,0,0,0,0,0,0,0,0,0,0
0,18,5,12,12,12,12,12,12,5,12,0
0,1,0,0,0,0,0,0,0,0,0,0
endlayer

layer
0,0,0,0,0,0,8,0,0,8,0,8
0,0,0,0,0,0,8,8,0,8,8,0
0,0,0,0,0,0,0,0,0,0,8,8
0,0,1,0,0,0,0,0,0,0,0,0
0,0,18,12,12,13,13,12,1,14,0,0
0,0,18,0,0,0,0,0,0,0,0,0
0,0,18,0,0,0,0,0,0,8,0,0
0,0,18,0,0,0,0,0,0,8,0,0
0,0,5,0,0,0,0,0,0,0,0,0
0,0,18,0,0,0,0,0,0,0,0,0
0,0,5,0,0,0,0,0,0,0,0,0
0,0,18,0,0,0,0,0,0,0,0,0
0,0,5,0,0,0,0,0,0,0,0,0
0,0,18,0,0,0,0,0,0,0,0,0
0,0,18,0,0,0,0,0,0,0,0,0
0,0,18,0,0,0,0,0,0,0,0,0
0,0,18,0,0,0,0,0,0,0,8,0
0,0,5,0,0,0,0,0,0,0,0,0
0,0,5,0,0,0,0,0,0,0,0,0
0,0,18,12,13,13,12,13,5,14,5,0
0,0,18,0,0,0,0,0,0,0,0,0
endlayer

layer
0,0,0,0,0,0,0,8,0,0,0,0
0,0,0,0,0,0,0,8,0,0,0,0
0,0,0,0,0,0,0,0,0,0,0,0
0,0,0,18,0,0,0,0,0,0,0,0
0,0,0,18,12,13,13,5,14,14,14,0
0,0,0,5,0,0,0,0,0,0,0,0
0,0,0,18,0,0,0,0,0,0,0,0
0,0,0,18,0,0,0,0,0,0,0,0
0,0,0,18,0,0,0,0,0,0,0,0
0,0,0,18,0,0,0,0,0,0,0,0
0,0,0,1,0,0,0,0,0,0,0,0
0,0,0,18,0,0,0,0,0,0,0,0
0,0,0,18,0,0,0,0,0,0,0,0
0,0,0,5,0,0,0,0,0,0,0,0
0,0,0,1,0,0,0,0,0,0,0,0
0,0,0,5,0,0,0,0,0,0,0,0
0,0,0,18,0,0,0,0,0,0,0,0
0,0,0,5,0,0,0,0,0,0,0,0
0,0,0,18,0,0,0,0,0,0,0,0
0,0,0,18,12,13,12,1,14,14,14,1
0,0,0,1,0,0,0,0,0,0,0,0
endlayer

layer
0,0,0,0,0,0,0,0,0,8,0,8
0,0,0,0,0,0,0,0,8,0,0,8
0,0,0,0,0,0,0,0,0,0,0,8
0,0,0,0,18,0,0,0,0,0,0,0
0,0,0,0,18,12,12,12,5,14,1,0
0,0,0,0,18,0,0,0,0,0,0,0
0,0,0,0,18,0,0,0,0,0,0,0
0,0,0,0,5,0,0,0,0,0,0,0
0,0,0,0,18,0,0,0,0,0,0,0
0,0,0,0,1,0,0,0,0,0,0,0
0,0,8,0,18,0,0,0,0,0,0,0
0,8,0,0,18,0,0,0,0,0,0,0
8,0,0,0,5,0,0,0,0,0,0,0
0,0,0,0,1,0,0,0,0,0,0,0
8,8,0,0,1,0,0,0,0,0,0,0
0,8,0,0,1,0,0,0,0,0,0,0
0,0,0,0,5,0,0,0,0,0,0,0
0,0,8,0,18,0,0,0,0,0,0,0
0,0,0,8,18,0,0,0,0,0,0,0
0,0,0,0,18,12,12,12,5,14,5,0
0,0,0,0,18,0,0,0,0,0,0,0
endlayer

layer
0,0,0,0,0,0,0,0,0,0,0,0
0,0,0,0,0,0,0,0,0,0,0,8
0,0,0,0,0,0,0,0,0,0,0,0
0,0,0,0,0,1,0,0,0,0,0,0
0,0,0,0,0,18,12,12,12,5,13,0
0,0,0,0,0,18,0,0,0,0,0,0
0,0,0,0,0,18,0,0,0,0,0,0
0,0,0,0,0,18,0,0,0,0,0,0
0,0,0,0,0,1,0,0,0,0,0,0
0,0,0,0,0,18,0,0,0,0,0,0
0,0,0,0,0,18,0,0,0,0,0,0
0,0,0,0,0,18,0,0,0,0,0,0
0,0,0,0,0,18,0,0,0,0,0,0
0,0,0,0,0,18,0,0,0,0,0,0
0,0,0,0,0,5,0,0,0,0,0,0
0,0,0,0,0,18,0,0,0,0,0,0
0,0,0,0,0,18,0,0,0,0,0,0
0,0,0,0,0,1,0,0,0,0,0,0
0,0,0,0,0,1,0,0,0,0,0,0
0,0,0,0,0,18,13,12,12,1,12,0
0,0,0,0,0,18,0,0,0,0,8,0
endlayer

layer
0,0,0,0,0,0,0,0,0,0,0,0
0,0,0,0,0,0,0,0,0,0,0,0
0,0,0,0,0,0,0,0,0,0,0,0
0,0,0,0,0,0,1,0,0,0,0,0
0,0,0,0,0,0,1,12,13,12,13,0
0,0,0,0,0,0,1,0,0,0,0,0
0,0,0,0,0,0,18,0,0,0,0,0
0,0,0,0,0,0,18,0,0,0,0,0
0,0,0,0,0,0,18,0,0,0,0,0
0,0,0,0,0,0,5,0,0,0,0,0
0,0,0,0,0,0,18,0,0,0,0,0
0,8,0,0,0,0,18,0,0,0,0,0
0,0,0,0,0,0,1,0,0,0,0,0
0,0,0,0,8,0,5,0,0,0,0,0
0,8,0,8,0,0,18,0,0,0,0,0
0,0,0,8,0,0,18,0,0,0,0,0
0,0,0,8,0,0,5,0,0,0,0,0
8,0,0,0,0,0,1,0,0,0,0,0
0,0,0,0,0,0,1,0,0,0,0,0
0,0,0,0,0,0,18,13,13,12,12,13
0,0,0,0,0,0,1,0,0,0,0,0
endlayer

layer
0,0,0,0,8,0,0,0,0,0,0,0
0,0,0,0,8,8,0,0,0,0,0,8
0,0,0,0,0,8,0,0,0,0,0,0
0,0,0,0,0,0,0,1,0,0,0,0
0,0,0,0,0,0,0,1,12,12,13,0
0,0,0,0,0,0,0,1,0,0,0,0
0,0,0,0,0,0,0,18,0,0,0,0
0,0,0,0,0,0,8,5,0,0,0,0
0,0,0,0,0,0,8,18,0,0,0,0
0,0,0,0,0,0,0,18,0,0,0,0
0,0,0,0,0,0,0,18,0,0,0,0
0,0,0,0,0,0,8,5,0,0,0,0
0,0,0,0,0,0,0,1,0,0,0,0
0,0,0,0,0,0,0,18,0,0,0,0
0,0,0,0,0,0,8,18,0,0,0,0
0,0,0,0,0,0,0,18,0,0,0,0
0,0,0,0,0,8,0,18,0,0,0,0
0,0,0,0,0,8,8,18,0,0,0,0
0,0,0,0,0,0,0,18,0,0,0,0
0,0,0,0,0,0,0,18,12,13,13,13
0,0,0,0,0,0,0,1,0,0,0,0
endlayer

layer
0,0,0,0,0,0,0,0,0,0,0,0
0,0,0,0,0,0,0,0,0,0,0,0
0,0,0,0,0,0,0,0,0,0,0,0
0,0,0,0,0,0,0,0,18,0,0,0
0,0,0,0,0,0,0,0,18,12,13,0
0,0,0,0,0,0,0,0,5,0,0,0
0,0,0,0,0,0,8,0,18,0,0,0
0,0,0,0,0,0,0,0,18,0,0,0
0,0,0,0,0,0,0,0,18,0,0,0
0,0,0,0,0,0,0,8,1,0,0,0
0,0,0,0,0,0,0,0,5,0,0,0
0,0,0,0,0,0,0,0,18,0,0,0
0,0,0,0,0,0,8,0,18,0,0,0
0,0,0,0,0,0,0,0,18,0,0,0
0,0,0,0,0,0,0,0,5,0,0,0
0,0,0,0,0,0,0,0,1,0,0,0
0,0,0,0,0,0,0,0,1,0,0,0
0,0,0,0,0,0,0,0,5,0,0,0
0,0,0,0,0,0,0,0,1,0,0,0
0,0,0,0,0,0,0,0,18,12,12,13
0,0,0,0,0,0,0,0,18,0,0,0
endlayer

layer
0,0,0,0,0,0,0,0,0,0,0,0
0,0,0,0,0,0,0,8,0,0,0,0
0,0,0,0,0,0,0,0,8,0,0,0
0,0,0,0,0,0,0,0,0,1,0,1
0,0,0,0,0,0,0,0,0,1,13,1
0,0,0,0,0,0,0,0,0,1,0,1
0,0,0,0,0,0,0,0,0,18,0,1
0,0,0,0,0,0,0,8,0,5,0,1
0,0,0,0,0,0,0,8,0,18,0,1
0,0,0,0,0,8,0,8,0,1,0,1
0,0,0,0,0,0,0,8,0,1,0,1
0,0,0,0,0,0,0,0,0,5,0,1
0,0,0,0,0,0,0,0,0,18,0,1
8,0,0,0,0,0,0,0,0,1,0,1
0,0,0,0,0,0,0,8,0,18,0,1
0,0,8,0,0,0,0,0,0,1,0,1
0,0,0,0,0,0,0,0,0,5,0,1
0,0,0,0,0,0,0,0,0,1,0,1
0,0,0,0,0,0,0,0,0,1,0,1
0,0,0,0,0,0,0,0,0,18,13,1
0,0,0,0,0,0,0,0,0,1,0,1
endlayer

layer
0,0,0,0,0,0,0,0,0,0,0,0
0,0,0,0,0,0,0,0,0,0,0,0
0,0,0,0,0,0,0,0,0,0,0,0
0,0,0,0,0,0,0,0,0,0,1,0
0,0,0,0,0,0,0,0,0,0,1,0
0,0,0,0,0,0,0,0,0,0,1,0
0,0,0,0,0,0,0,0,0,0,18,0
0,0,0,0,0,0,0,0,0,0,1,0
0,0,0,0,0,0,0,0,0,0,1,0
0,0,0,0,0,0,0,0,0,0,18,0
0,0,0,0,0,0,0,0,0,0,1,0
0,0,0,0,0,0,0,0,0,0,1,0
0,0,0,0,0,0,8,0,0,0,18,0
0,0,0,0,0,0,8,0,0,0,1,0
0,0,0,0,0,0,0,8,0,0,1,0
0,0,0,0,0,0,0,0,0,0,18,0
0,0,0,0,0,0,0,8,0,0,18,0
0,0,0,0,0,0,0,0,0,0,1,0
0,0,0,0,0,0,8,8,0,0,1,0
0,0,0,0,0,0,8,0,0,0,18,0
0,0,0,0,0,0,0,0,0,0,1,0
endlayer

