
# Created by Ruins mod version 13.8 Ingame Parser
# authoring Player: OneWolfe

weight=2
unique=1
embed_into_distance=3
biomesToSpawnIn=plains,forest
acceptable_target_blocks=
unacceptable_target_blocks=flowing_water,water,flowing_lava,lava,terrafirmacraft:SaltWaterStationary-0,terrafirmacraft:SaltWaterStationary-8,terrafirmacraft:FreshWaterStationary-0,terrafirmacraft:FreshWaterStationary-8
dimensions=6,22,25
allowable_overhang=6
max_leveling=6
leveling_buffer=0
preserve_water=0
preserve_lava=0
preserve_plants=1

rule1=0,100,TwilightForest:tile.TFMazestone-0
rule2=0,100,preserveBlock
rule3=0,100,preserveBlock
rule4=0,100,preserveBlock
rule5=0,100,TwilightForest:tile.TFHedge-0
rule6=0,100,MobSpawner:CaveSpider
rule7=0,100,ChestGenHook:dungeonChest:5-4
rule8=0,100,TwilightForest:tile.TFFirefly-2
rule9=0,100,TwilightForest:tile.TFFirefly-3
rule10=0,100,TwilightForest:tile.TFFirefly-1
rule11=0,100,TwilightForest:tile.TFFirefly-4

layer
1,1,1,1,2,2,1,1,1,1,1,1,1,1,1,1,1,1,1,1,1,1,1,1,1
1,2,2,1,2,2,2,2,2,1,2,2,2,2,2,2,2,2,1,2,2,1,2,2,1
1,2,2,1,2,2,2,2,2,1,2,2,2,2,2,2,2,2,1,2,2,1,2,2,1
1,2,2,1,2,2,1,2,2,1,1,1,1,1,1,1,2,2,1,2,2,1,2,2,1
1,2,2,1,2,2,1,2,2,2,2,2,2,2,2,1,2,2,2,2,2,2,2,2,1
1,2,2,1,2,2,1,2,2,2,2,2,2,2,2,1,2,2,2,2,2,2,2,2,1
1,1,1,1,2,2,1,1,1,1,1,1,1,2,2,1,1,1,1,1,1,1,2,2,1
1,2,2,2,2,2,1,2,2,2,2,2,1,2,2,2,2,2,2,2,2,1,2,2,1
1,2,2,2,2,2,1,2,2,2,2,2,1,2,2,2,2,2,2,2,2,1,2,2,1
1,2,2,1,1,1,1,1,1,1,2,2,1,1,1,1,1,1,1,2,2,1,2,2,1
1,2,2,2,2,2,2,2,2,1,2,2,2,2,2,2,2,2,1,2,2,1,2,2,1
1,2,2,2,2,2,2,2,2,1,2,2,2,2,2,2,2,2,1,2,2,1,2,2,1
1,1,1,1,1,1,1,2,2,1,1,1,1,2,2,1,1,1,1,2,2,1,2,2,1
1,2,2,2,2,2,1,2,2,2,2,2,1,2,2,1,2,2,2,2,2,1,2,2,1
1,2,2,2,2,2,1,2,2,2,2,2,1,2,2,1,2,2,2,2,2,1,2,2,1
1,1,1,1,2,2,1,1,1,1,2,2,1,2,2,1,2,2,1,1,1,1,2,2,1
1,2,2,1,2,2,2,2,2,1,2,2,2,2,2,1,2,2,1,2,2,2,2,2,1
1,2,2,1,2,2,2,2,2,1,2,2,2,2,2,1,2,2,1,2,2,2,2,2,1
1,1,1,1,1,1,1,2,2,1,1,1,1,1,1,1,2,2,1,2,2,1,1,1,1
1,2,2,2,2,2,2,2,2,2,2,2,2,2,2,2,2,2,1,2,2,2,2,2,1
1,2,2,2,2,2,2,2,2,2,2,2,2,2,2,2,2,2,1,2,2,2,2,2,1
1,1,1,1,1,1,1,1,1,1,1,1,1,1,1,1,1,1,1,1,1,1,1,1,1
endlayer

layer
1,1,1,1,2,2,1,1,1,1,1,1,1,1,1,1,1,1,1,1,1,1,1,1,1
1,2,2,1,2,2,2,2,2,1,2,2,2,2,2,2,2,2,1,2,2,1,2,2,1
1,2,2,1,2,2,2,2,2,1,2,2,2,2,2,2,2,2,1,2,2,1,2,2,1
1,2,2,1,2,2,1,2,2,1,1,1,1,1,1,1,2,2,1,2,2,1,2,2,1
1,2,2,1,2,2,1,2,2,2,2,2,2,2,2,1,2,2,2,2,2,2,2,2,1
1,2,2,1,2,2,1,2,2,2,2,2,2,2,2,1,2,2,2,2,2,2,2,2,1
1,1,1,1,2,2,1,1,1,1,1,1,1,2,2,1,1,1,1,1,1,1,2,2,1
1,3,3,2,2,2,1,2,2,2,2,2,1,2,2,2,2,2,2,2,2,1,2,2,1
1,3,3,3,2,2,1,2,2,2,2,2,1,2,2,2,2,2,2,2,2,1,2,2,1
1,3,3,1,1,1,1,1,1,1,2,2,1,1,1,1,1,1,1,2,2,1,2,2,1
1,3,3,3,2,2,2,2,2,1,2,2,2,2,2,2,2,2,1,2,2,1,2,2,1
1,3,3,2,2,2,2,2,2,1,2,2,2,2,2,2,2,2,1,2,2,1,2,2,1
1,1,1,1,1,1,1,2,2,1,1,1,1,2,2,1,1,1,1,2,2,1,2,2,1
1,3,2,2,2,2,1,2,2,2,2,2,1,2,2,1,2,2,2,2,2,1,2,2,1
1,3,2,2,2,2,1,2,2,2,2,2,1,2,2,1,2,2,2,2,2,1,2,2,1
1,1,1,1,2,2,1,1,1,1,2,2,1,2,2,1,2,2,1,1,1,1,2,2,1
1,2,2,1,2,2,2,2,2,1,2,2,2,2,2,1,2,2,1,2,2,2,2,2,1
1,2,2,1,2,2,2,2,2,1,2,2,2,2,2,1,2,2,1,2,2,2,2,2,1
1,1,1,1,1,1,1,2,2,1,1,1,1,1,1,1,2,2,1,2,2,1,1,1,1
1,2,2,3,3,3,2,2,2,2,2,2,2,2,2,2,2,2,1,2,2,2,2,2,1
1,2,3,3,3,3,3,2,2,2,2,2,2,2,2,2,2,2,1,2,2,2,2,2,1
1,1,1,1,1,1,1,1,1,1,1,1,1,1,1,1,1,1,1,1,1,1,1,1,1
endlayer

layer
1,1,1,1,4,4,1,1,1,1,1,1,1,1,1,1,1,1,1,1,1,1,1,1,1
1,4,4,1,4,4,4,4,4,1,4,4,4,4,4,4,4,4,1,4,4,1,4,4,1
1,4,4,1,4,4,4,4,4,1,4,4,4,4,4,4,4,4,1,4,4,1,4,4,1
1,4,4,1,4,4,1,4,4,1,1,1,1,1,1,1,4,4,1,4,4,1,4,4,1
1,4,4,1,4,4,1,4,4,4,4,4,4,4,4,1,4,4,4,4,4,4,4,4,1
1,4,4,1,4,4,1,4,4,4,4,4,4,4,4,1,4,4,4,4,4,4,4,4,1
1,4,4,1,1,1,1,1,1,1,1,1,1,4,4,1,1,1,1,1,1,1,4,4,1
1,4,4,4,4,4,4,4,4,4,4,4,1,4,4,4,4,4,4,4,4,1,4,4,1
1,4,4,4,4,4,3,4,4,4,4,4,1,4,4,4,4,4,4,4,4,1,4,4,1
1,4,4,1,1,1,1,1,1,1,4,4,1,1,1,1,1,1,1,4,4,1,4,4,1
1,4,4,4,4,4,1,4,4,4,4,4,4,4,4,4,4,4,1,4,4,4,4,4,1
1,4,4,4,4,4,1,4,4,3,4,4,4,4,4,4,4,4,1,4,4,4,4,4,1
1,1,1,1,3,3,1,4,4,4,3,4,4,4,4,1,1,1,1,4,4,1,4,4,1
1,4,4,4,4,4,1,4,4,4,4,4,4,4,4,1,4,4,4,4,4,1,4,4,1
1,4,4,4,4,4,1,4,4,4,4,4,4,4,4,1,4,4,4,4,4,1,4,4,1
1,3,4,1,4,4,1,1,1,1,4,4,4,4,4,1,4,4,1,1,1,1,4,4,1
1,3,4,1,4,4,4,4,4,1,4,4,4,4,4,1,4,4,1,4,4,4,4,4,1
1,4,4,1,4,4,4,4,4,1,4,4,4,4,4,1,4,4,1,4,4,4,4,4,1
1,3,4,1,1,1,1,1,1,1,1,1,1,1,1,1,4,4,1,4,4,1,1,1,1
1,4,4,4,4,4,4,4,4,4,4,4,4,4,4,4,4,4,1,4,4,4,4,4,1
1,4,4,4,4,4,4,4,4,4,4,4,4,4,4,4,4,4,1,4,4,4,4,4,1
1,1,1,1,1,1,1,1,1,1,1,1,1,1,1,1,1,1,1,1,1,1,1,1,1
endlayer

layer
5,5,5,5,0,0,5,5,5,5,5,5,5,5,5,5,5,5,5,5,5,5,5,5,5
5,0,0,5,0,0,0,0,0,5,0,0,0,0,0,0,0,0,5,0,0,5,0,0,5
5,0,0,5,0,0,0,0,0,5,0,0,0,0,0,0,0,0,5,0,0,5,0,0,5
5,0,0,5,0,0,5,0,0,5,5,5,5,5,5,5,0,0,5,0,0,5,0,0,5
5,0,0,5,0,0,5,0,0,0,0,0,0,0,0,5,0,0,0,0,0,0,0,0,5
5,0,0,5,0,0,5,0,0,0,0,0,0,0,0,5,0,0,0,0,0,0,0,0,5
5,0,0,5,5,5,5,5,5,5,5,5,5,0,0,5,5,5,5,5,5,5,0,0,5
5,0,0,0,0,0,0,0,0,0,0,0,5,0,0,0,0,0,0,0,0,5,0,0,5
5,0,0,0,0,0,0,0,0,0,0,0,5,0,0,0,0,0,0,0,0,5,0,0,5
5,0,0,5,5,5,5,5,5,5,0,0,5,5,5,5,5,5,5,0,0,5,0,0,5
5,0,0,0,0,0,5,0,0,0,0,0,0,0,0,0,0,0,5,0,0,0,0,0,5
5,0,0,0,0,0,5,0,0,0,0,0,0,0,0,0,0,0,5,0,0,0,0,0,5
5,5,5,5,0,0,5,0,6,0,0,0,0,0,0,5,5,5,5,0,0,5,0,0,5
5,0,0,0,0,0,5,0,0,0,0,0,0,0,0,5,0,0,0,0,0,5,0,0,5
5,0,0,0,0,0,5,0,0,0,0,0,0,0,6,5,0,0,0,0,0,5,0,0,5
5,0,0,5,0,0,5,5,5,5,0,0,0,0,0,5,0,0,5,5,5,5,0,0,5
5,0,0,5,0,0,0,0,0,5,0,0,7,0,0,5,0,0,5,0,0,0,0,0,5
5,0,0,5,0,0,0,0,0,5,0,0,0,0,0,5,0,0,5,0,0,0,0,0,5
5,0,0,5,5,5,5,5,5,5,5,5,5,5,5,5,0,0,5,0,0,5,5,5,5
5,0,0,0,0,0,0,0,0,0,0,0,0,0,0,0,0,0,5,0,0,0,0,0,5
5,0,0,0,0,0,0,0,0,0,0,0,0,0,0,0,0,0,5,0,0,0,0,0,5
5,5,5,5,5,5,5,5,5,5,5,5,5,5,5,5,5,5,5,5,5,5,5,5,5
endlayer

layer
5,5,5,5,0,0,9,5,5,5,5,5,5,5,5,5,5,5,8,5,5,5,5,5,5
5,0,0,5,0,0,0,0,0,5,0,0,0,0,0,0,0,0,5,0,0,5,0,0,5
5,0,0,5,0,0,0,0,0,5,0,0,0,0,0,0,0,0,5,0,0,5,0,0,5
5,0,0,5,0,0,8,0,0,10,5,5,5,5,5,8,0,0,10,0,0,10,0,0,5
5,0,0,5,0,0,5,0,0,0,0,0,0,0,0,5,0,0,0,0,0,0,0,0,5
5,0,0,5,0,0,5,0,0,0,0,0,0,0,0,5,0,0,0,0,0,0,0,0,5
5,0,0,5,5,5,5,5,5,5,5,5,8,0,0,10,5,5,5,5,5,8,0,0,5
5,0,0,0,0,0,0,0,0,0,0,0,5,0,0,0,0,0,0,0,0,5,0,0,5
5,0,0,0,0,0,0,0,0,0,0,0,5,0,0,0,0,0,0,0,0,5,0,0,5
5,0,0,9,5,5,5,5,5,11,0,0,5,5,5,5,5,5,8,0,0,10,0,0,5
5,0,0,0,0,0,5,0,0,0,0,0,0,0,10,0,0,0,5,0,0,0,0,0,5
5,0,0,0,0,0,5,0,0,0,0,0,0,0,0,0,0,0,5,0,0,0,0,0,5
5,5,5,11,0,0,5,0,0,0,0,0,0,0,0,5,5,5,10,0,0,8,0,0,5
5,0,0,0,0,0,5,0,0,0,0,0,0,0,0,5,0,0,0,0,0,5,0,0,5
5,0,0,0,0,0,5,0,0,0,0,0,0,0,0,5,0,0,0,0,0,5,0,0,5
5,0,0,8,0,0,10,5,5,8,0,0,0,0,0,5,0,0,8,5,5,10,0,0,5
5,0,0,5,0,0,0,0,0,5,0,0,0,0,0,5,0,0,5,0,0,0,0,0,5
5,0,0,5,0,0,0,0,0,5,0,0,8,0,0,5,0,0,5,0,0,0,0,0,5
5,0,0,5,5,5,5,5,5,5,5,5,5,5,5,10,0,0,5,0,0,9,5,5,5
5,0,0,0,0,0,0,0,0,0,0,0,0,0,0,0,0,0,5,0,0,0,0,0,5
5,0,0,0,0,0,0,0,0,0,0,0,0,0,0,0,0,0,5,0,0,0,0,0,5
5,5,5,5,5,5,5,5,5,5,5,5,5,5,5,5,5,5,5,5,5,5,5,5,5
endlayer

layer
5,5,5,5,0,0,5,5,5,5,5,5,5,5,5,5,5,5,5,5,5,5,5,5,5
5,0,0,5,0,0,0,0,0,5,0,0,0,0,0,0,0,0,5,0,0,5,0,0,5
5,0,0,5,0,0,0,0,0,5,0,0,0,0,0,0,0,0,5,0,0,5,0,0,5
5,0,0,5,0,0,5,0,0,5,5,5,5,5,5,5,0,0,5,0,0,5,0,0,5
5,0,0,5,0,0,5,0,0,0,0,0,0,0,0,5,0,0,0,0,0,0,0,0,5
5,0,0,5,0,0,5,0,0,0,0,0,0,0,0,5,0,0,0,0,0,0,0,0,5
5,0,0,5,5,5,5,5,5,5,5,5,5,0,0,5,5,5,5,5,5,5,0,0,5
5,0,0,0,0,0,0,0,0,0,0,0,5,0,0,0,0,0,0,0,0,5,0,0,5
5,0,0,0,0,0,0,0,0,0,0,0,5,0,0,0,0,0,0,0,0,5,0,0,5
5,0,0,5,5,5,5,5,5,5,0,0,5,5,5,5,5,5,5,0,0,5,0,0,5
5,0,0,0,0,0,5,0,0,0,0,0,0,0,0,0,0,0,5,0,0,0,0,0,5
5,0,0,0,0,0,5,0,0,0,0,0,0,0,0,0,0,0,5,0,0,0,0,0,5
5,5,5,5,0,0,5,0,0,0,0,0,0,0,0,5,5,5,5,0,0,5,0,0,5
5,0,0,0,0,0,5,0,0,0,0,0,0,0,0,5,0,0,0,0,0,5,0,0,5
5,0,0,0,0,0,5,0,0,0,0,0,0,0,0,5,0,0,0,0,0,5,0,0,5
5,0,0,5,0,0,5,5,5,5,0,0,0,0,0,5,0,0,5,5,5,5,0,0,5
5,0,0,5,0,0,0,0,0,5,0,0,0,0,0,5,0,0,5,0,0,0,0,0,5
5,0,0,5,0,0,0,0,0,5,0,0,0,0,0,5,0,0,5,0,0,0,0,0,5
5,0,0,5,5,5,5,5,5,5,5,5,5,5,5,5,0,0,5,0,0,5,5,5,5
5,0,0,0,0,0,0,0,0,0,0,0,0,0,0,0,0,0,5,0,0,0,0,0,5
5,0,0,0,0,0,0,0,0,0,0,0,0,0,0,0,0,0,5,0,0,0,0,0,5
5,5,5,5,5,5,5,5,5,5,5,5,5,5,5,5,5,5,5,5,5,5,5,5,5
endlayer


