
# Created by Ruins mod version 13.8 Ingame Parser
# authoring Player: OneWolfe

weight=4
embed_into_distance=1
biomesToSpawnIn=plains,swamp,forest,high hills
acceptable_target_blocks=
unacceptable_target_blocks=flowing_water,water,flowing_lava,lava,terrafirmacraft:SaltWaterStationary-0,terrafirmacraft:SaltWaterStationary-8,terrafirmacraft:FreshWaterStationary-0,terrafirmacraft:FreshWaterStationary-8
dimensions=8,7,9
allowable_overhang=8
max_leveling=6
leveling_buffer=0
preserve_water=0
preserve_lava=0
preserve_plants=1

rule1=0,100,preserveBlock
rule2=0,100,terrafirmacraft:StoneIgInSmooth-1
rule3=0,100,Railcraft:frame-0
rule4=0,100,air
rule5=0,100,air,air,Steamcraft:steamTank-0
rule6=0,100,air,air,Steamcraft:pipe-0
rule7=0,100,air,air,Steamcraft:valvePipe-4
rule8=0,100,air,air,MobSpawner:TwilightForest.Pinch Beetle
rule9=0,100,air,air,Steamcraft:valvePipe-2
rule10=0,100,air,air,Steamcraft:horn-4
rule11=0,100,air

layer
0,2,2,2,2,2,2,2,1
2,3,3,3,3,3,3,3,1
2,3,1,2,1,1,2,2,3
2,3,2,1,11,2,1,1,3
2,3,2,1,1,1,2,2,3
2,3,3,3,3,3,3,3,3
2,2,2,2,2,2,2,1,1
endlayer

layer
0,2,2,2,2,2,11,0,0
2,3,11,0,4,11,4,11,4
2,2,4,4,11,0,11,4,4
2,2,4,4,11,0,11,4,4
6,6,5,4,11,0,11,0,0
2,3,11,0,11,0,11,0,3
0,2,2,2,11,0,2,11,0
endlayer

layer
0,2,11,0,2,2,11,0,0
2,3,11,0,11,0,4,11,0
2,11,0,11,0,11,0,11,0
4,11,4,11,0,11,0,11,0
0,11,7,11,0,11,0,11,0
2,3,4,11,0,11,0,11,3
0,2,2,11,0,11,2,11,0
endlayer

layer
0,2,2,2,2,2,4,11,0
2,3,3,3,3,3,3,11,0
2,3,4,11,0,3,4,11,0
2,3,4,11,0,3,11,0,0
2,3,6,11,0,3,11,0,3
2,3,3,3,3,3,3,3,3
4,2,2,2,2,2,2,11,0
endlayer

layer
0,11,0,11,0,11,4,11,0
0,2,2,2,2,2,2,11,0
0,2,4,11,0,2,11,0,0
0,2,4,4,8,2,11,0,0
0,2,6,2,2,2,11,0,0
0,2,2,2,2,2,2,11,0
4,11,0,11,0,11,0,11,0
endlayer

layer
0,11,0,11,0,11,0,11,0
0,11,4,11,0,11,0,11,0
4,4,2,2,2,11,0,11,0
0,11,2,2,2,11,0,11,0
0,11,6,4,11,0,11,0,0
0,4,9,4,4,11,0,11,0
0,4,6,11,4,4,11,0,0
endlayer

layer
0,11,0,11,0,11,0,11,0
0,11,0,11,0,11,0,11,0
0,11,0,11,4,11,0,11,0
0,11,10,11,0,11,0,11,0
0,11,6,11,0,11,0,11,0
0,11,0,4,11,0,11,0,0
0,11,0,11,0,11,4,11,0
endlayer

layer
0,11,0,11,0,11,0,11,0
0,11,0,11,0,11,0,11,0
0,11,0,11,0,11,0,11,0
0,11,0,11,0,11,0,11,0
0,11,0,11,0,11,0,11,0
0,11,0,11,4,11,0,11,0
0,11,0,11,0,11,0,11,0
endlayer

