
# Created by Ruins mod version 13.8 Ingame Parser
# authoring Player: OneWolfe

weight=8
unique=1
embed_into_distance=43
biomesToSpawnIn=plains,rolling hills,swamp,forest,high hills
acceptable_target_blocks=
unacceptable_target_blocks=flowing_water,water,flowing_lava,lava,terrafirmacraft:SaltWaterStationary-0,terrafirmacraft:SaltWaterStationary-8,terrafirmacraft:FreshWaterStationary-0,terrafirmacraft:FreshWaterStationary-8
dimensions=49,15,15
allowable_overhang=8
max_leveling=6
leveling_buffer=-1
preserve_water=0
preserve_lava=0
preserve_plants=1

rule1=0,100,preserveBlock
rule2=0,100,Railcraft:frame-0
rule3=0,100,terrafirmacraft:StoneMM-4
rule4=0,100,Steamcraft:pipe-0
rule5=0,100,MobSpawner:TwilightForest.Mini Ghast
rule6=0,100,air
rule7=0,100,Steamcraft:valvePipe-5
rule8=0,100,Steamcraft:valvePipe-3
rule9=0,100,Steamcraft:valvePipe-2
rule10=0,100,Steamcraft:valvePipe-4
rule11=0,100,Steamcraft:vacuum-5
rule12=0,100,Steamcraft:vacuum-3
rule13=0,100,Steamcraft:vacuum-2
rule14=0,100,Steamcraft:vacuum-4
rule15=0,100,Steamcraft:blockBrass-0
rule16=0,100,air
rule17=0,100,Steamcraft:chargingPad-2
rule18=0,100,Steamcraft:steamTank-0
rule19=0,100,ChestGenHook:dungeonChest:5-2
rule20=0,100,terrafirmacraft:Vine-2
rule21=0,100,terrafirmacraft:Vine-8
rule22=0,100,terrafirmacraft:Vine-1
rule23=0,100,terrafirmacraft:Vine-3
rule24=0,100,terrafirmacraft:Vine-4
rule25=0,100,terrafirmacraft:Vine-12
rule26=0,100,terrafirmacraft:Vine-9
rule27=0,100,minecraft:redstone_wire-0
rule28=0,100,minecraft:unpowered_repeater-2
rule29=0,100,minecraft:unpowered_repeater-1
rule30=0,100,minecraft:unpowered_repeater-3
rule31=0,100,minecraft:unpowered_repeater-0
rule32=2,100,minecraft:redstone_torch-5
rule33=0,100,terrafirmacraft:planks-0
rule34=0,100,minecraft:sticky_piston-13
rule35=2,100,minecraft:piston_head-13
rule36=0,100,minecraft:sticky_piston-11
rule37=2,100,minecraft:piston_head-11
rule38=2,100,minecraft:piston_head-10
rule39=0,100,minecraft:sticky_piston-10
rule40=2,100,minecraft:piston_head-12
rule41=0,100,minecraft:sticky_piston-12
rule42=0,100,terrafirmacraft:StoneIgIn-0
rule43=0,100,terrafirmacraft:WoodVert-0
rule44=0,100,terrafirmacraft:WallBrickIgIn-0
rule45=0,100,minecraft:iron_door-2
rule46=0,100,minecraft:lever-2
rule47=0,100,minecraft:iron_door-8
rule48=0,100,minecraft:glass-0
rule49=0,100,BiblioCraft:BiblioIronLantern-10
rule50=0,100,terrafirmacraft:WoodHoriz-8
rule51=0,100,terrafirmacraft:WoodHoriz-0

layer
1,1,1,1,1,1,1,1,1,1,1,1,1,1,1
1,2,3,3,3,4,4,4,4,4,3,3,3,2,1
1,3,5,3,3,3,3,3,3,3,3,3,5,3,1
1,3,3,3,3,3,3,3,3,3,3,3,3,3,1
1,3,3,3,3,3,3,3,3,3,3,3,3,3,1
1,4,3,3,3,3,3,3,3,3,3,3,3,4,1
1,4,3,3,3,3,3,3,3,3,3,3,3,4,1
1,4,3,3,3,3,3,3,3,3,3,3,3,4,1
1,4,3,3,3,3,3,3,3,3,3,3,3,4,1
1,4,3,3,3,3,3,3,3,3,3,3,3,4,1
1,3,3,3,3,3,3,3,3,3,3,3,3,3,1
1,3,3,3,3,3,3,3,3,3,3,3,3,3,1
1,3,5,3,3,3,3,3,3,3,3,3,5,3,1
1,2,3,3,3,4,4,4,4,4,3,3,3,2,1
1,1,1,1,1,1,1,1,1,1,1,1,1,1,1
endlayer

layer
1,1,4,1,1,1,1,1,1,1,1,1,4,1,1
1,2,4,0,1,4,1,4,1,4,1,0,4,2,1
4,4,0,0,0,0,6,0,0,0,0,0,0,4,4
1,0,6,6,6,6,0,6,0,6,6,0,0,0,1
1,1,0,6,0,6,6,0,6,0,6,6,0,1,1
1,4,0,0,0,0,6,0,6,6,6,6,0,4,1
1,1,0,6,0,0,6,0,0,0,6,6,0,1,1
1,4,6,0,0,6,0,0,0,6,6,6,0,4,1
1,1,0,0,0,0,6,0,6,6,6,0,0,1,1
1,4,0,6,0,6,6,0,0,6,0,6,0,4,1
1,1,0,6,6,0,0,0,0,6,6,6,6,1,1
1,0,0,6,6,0,0,0,6,0,0,0,0,0,1
4,4,0,0,0,6,6,0,0,6,0,0,0,4,4
1,2,4,0,1,4,1,4,1,4,1,0,4,2,1
1,1,4,1,1,1,1,1,1,1,1,1,4,1,1
endlayer

layer
1,1,1,1,1,1,1,1,1,1,1,1,1,1,1
1,2,4,0,1,7,1,7,1,7,1,0,4,2,1
1,4,0,0,0,0,0,0,0,0,0,0,0,4,1
1,0,0,0,6,0,0,0,0,0,6,0,0,0,1
1,1,0,0,6,0,6,6,6,0,6,6,0,1,1
1,9,0,0,0,6,0,0,0,0,0,0,0,8,1
1,1,0,0,6,0,0,0,0,0,0,0,0,1,1
1,9,0,0,6,0,0,0,0,6,6,0,0,8,1
1,1,0,0,6,0,0,0,0,0,0,0,0,1,1
1,9,0,0,0,0,0,0,0,0,0,0,0,8,1
1,1,0,6,6,0,6,6,0,6,6,6,0,1,1
1,0,0,0,0,0,0,0,0,0,0,0,0,0,1
1,4,0,0,0,0,0,0,0,0,0,0,0,4,1
1,2,4,0,1,10,1,10,1,10,1,0,4,2,1
1,1,1,1,1,1,1,1,1,1,1,1,1,1,1
endlayer

layer
1,1,1,1,1,4,1,4,1,4,1,1,1,1,1
1,2,4,0,1,4,1,4,1,4,1,0,4,2,1
1,4,0,0,0,0,0,0,0,0,0,0,0,4,1
1,0,0,6,0,6,0,0,0,6,0,0,0,0,1
1,1,0,6,0,6,0,6,6,0,6,6,0,1,1
4,4,0,6,6,6,0,0,6,0,0,6,0,4,4
1,1,0,0,6,0,0,6,0,6,6,0,0,1,1
4,4,0,6,6,0,0,0,0,6,0,0,0,4,4
1,1,0,0,6,0,6,0,0,0,6,0,0,1,1
4,4,0,0,6,0,6,6,6,6,6,6,0,4,4
1,1,0,6,6,0,6,6,6,6,6,6,0,1,1
1,0,0,0,6,6,6,0,0,6,0,6,0,0,1
1,4,0,0,0,0,0,0,0,0,0,0,0,4,1
1,2,4,0,1,4,1,4,1,4,1,0,4,2,1
1,1,1,1,1,4,1,4,1,4,1,1,1,1,1
endlayer

layer
1,1,1,1,1,1,1,1,1,1,1,1,1,1,1
1,2,4,0,1,4,1,4,1,4,1,0,4,2,1
1,4,0,0,0,0,0,11,0,0,0,0,0,4,1
1,0,0,0,0,0,0,0,0,0,0,0,0,0,1
1,1,0,0,0,0,0,0,0,6,0,0,0,1,1
1,4,0,0,0,0,0,0,0,0,0,0,0,4,1
1,1,0,0,0,0,0,0,0,0,0,0,0,1,1
1,4,13,0,0,0,0,0,0,0,0,0,12,4,1
1,1,0,0,0,0,0,0,0,0,0,0,0,1,1
1,4,0,0,0,0,0,0,0,0,0,0,0,4,1
1,1,0,0,0,0,0,0,0,0,0,0,0,1,1
1,0,0,0,0,0,0,0,0,0,0,0,0,0,1
1,4,0,0,0,0,0,14,0,0,0,0,0,4,1
1,2,4,0,1,4,1,4,1,4,1,0,4,2,1
1,1,1,1,1,1,1,1,1,1,1,1,1,1,1
endlayer

layer
1,1,1,1,1,1,1,1,1,1,1,1,1,1,1
1,2,4,4,4,4,1,1,1,4,4,4,4,2,1
1,4,0,0,0,0,0,0,0,0,0,0,0,4,1
1,4,0,0,0,0,0,0,0,0,0,0,0,4,1
1,4,0,0,0,0,0,0,0,0,0,0,0,4,1
1,4,0,0,0,0,0,0,0,0,0,0,0,4,1
1,1,0,0,0,0,0,0,0,0,0,0,0,1,1
1,1,0,0,0,0,0,0,0,0,0,0,0,1,1
1,1,0,0,0,0,0,0,0,0,0,0,0,1,1
1,4,0,0,0,0,0,0,0,0,0,0,0,4,1
1,4,0,0,0,0,0,0,0,0,0,0,0,4,1
1,4,0,0,0,0,0,0,0,0,0,0,0,4,1
1,4,0,0,0,0,0,0,0,0,0,0,0,4,1
1,2,4,4,4,4,1,1,1,4,4,4,4,2,1
1,1,1,1,1,1,1,1,1,1,1,1,1,1,1
endlayer

layer
1,2,1,1,1,1,1,1,1,1,1,1,1,2,1
2,2,2,2,2,4,2,2,2,4,2,2,2,2,2
1,2,0,0,0,0,0,0,0,0,0,0,0,2,1
1,2,0,0,0,0,0,0,0,0,0,0,0,2,1
1,2,0,0,0,0,0,0,0,0,0,0,0,2,1
1,4,0,0,0,0,0,0,0,0,0,0,0,4,1
1,2,0,0,0,0,0,0,0,0,0,0,0,2,1
1,2,0,0,0,0,0,0,0,0,0,0,0,2,1
1,2,0,0,0,0,0,0,0,0,0,0,0,2,1
1,4,0,0,0,0,0,0,0,0,0,0,0,4,1
1,2,0,0,0,0,0,0,0,0,0,0,0,2,1
1,2,0,0,0,0,0,0,0,0,0,0,0,2,1
1,2,0,0,0,0,0,0,0,0,0,0,0,2,1
2,2,2,2,2,4,2,2,2,4,2,2,2,2,2
1,2,1,1,1,1,1,1,1,1,1,1,1,2,1
endlayer

layer
1,1,1,1,1,1,1,1,1,1,1,1,1,1,1
1,2,3,3,3,4,3,3,3,4,3,3,3,2,1
1,3,3,3,3,3,3,3,3,3,3,3,3,3,1
1,3,3,3,3,3,3,3,3,3,3,3,3,3,1
1,3,3,3,3,3,3,3,3,3,3,3,3,3,1
1,4,3,3,3,3,3,0,3,3,3,3,3,4,1
1,3,3,3,3,3,0,0,0,3,3,3,3,3,1
1,3,3,3,3,0,0,0,0,0,3,3,3,3,1
1,3,3,3,3,3,0,6,0,3,3,3,3,3,1
1,4,3,3,3,3,3,0,3,3,3,3,3,4,1
1,3,3,3,3,3,3,3,3,3,3,3,3,3,1
1,3,3,3,3,3,3,3,3,3,3,3,3,3,1
1,3,3,3,3,3,3,3,3,3,3,3,3,3,1
1,2,3,3,3,4,3,3,3,4,3,3,3,2,1
1,1,1,1,1,1,1,1,1,1,1,1,1,1,1
endlayer

layer
1,1,1,1,1,1,1,1,1,1,1,1,1,1,1
1,2,0,0,0,15,0,0,0,15,0,0,0,2,1
1,0,0,0,0,0,0,0,0,0,0,0,0,0,1
1,0,0,0,0,0,0,0,0,0,0,0,0,0,1
1,0,0,0,0,0,16,16,16,0,0,0,0,0,1
1,17,0,0,0,16,16,0,16,16,0,0,0,15,1
1,0,0,0,16,16,0,0,0,16,16,0,0,0,1
1,3,3,0,16,0,0,0,0,0,16,0,0,0,1
1,0,0,0,16,16,0,0,0,16,16,0,0,0,1
4,4,0,0,0,16,16,0,16,16,0,0,0,18,1
1,0,0,0,0,0,16,16,16,0,0,0,0,0,1
1,0,0,0,0,0,0,16,0,0,0,0,0,0,1
1,0,0,0,0,0,0,0,0,0,0,0,0,0,1
1,2,0,0,0,15,0,0,0,15,0,0,0,2,1
1,1,1,1,1,1,1,1,1,1,1,1,1,1,1
endlayer

layer
1,1,1,1,1,1,1,1,1,1,1,1,1,1,1
1,2,0,0,0,0,0,0,0,0,0,0,0,2,1
1,0,0,0,0,0,0,0,0,0,0,0,0,0,1
1,0,0,0,0,0,0,0,0,0,0,0,0,0,1
1,0,0,0,6,6,6,0,0,6,0,0,0,0,1
1,0,0,0,0,0,0,0,0,0,0,0,0,0,1
1,3,3,0,0,0,0,0,0,0,6,0,0,0,1
1,0,0,0,0,0,0,0,0,0,0,0,0,0,1
1,0,0,6,0,0,6,6,0,6,6,0,0,0,1
1,0,0,0,6,6,6,0,0,0,0,6,0,0,1
1,0,0,0,0,6,0,0,0,0,6,0,0,0,1
1,0,0,0,0,6,0,6,0,0,0,0,0,0,1
1,0,0,0,0,0,0,0,0,0,0,0,0,0,1
1,2,0,0,0,0,0,0,0,0,0,0,0,2,1
1,1,1,1,1,1,1,1,1,1,1,1,1,1,1
endlayer

layer
1,1,1,1,1,1,1,1,1,1,1,1,1,1,1
1,2,0,0,0,0,0,0,0,0,0,0,0,2,1
1,0,0,0,0,0,0,0,0,0,0,0,0,0,1
1,0,0,0,0,0,0,0,0,0,0,0,0,0,1
1,0,0,0,0,0,0,0,0,0,0,0,0,0,1
1,3,3,0,0,0,0,0,0,0,0,0,0,0,1
1,0,0,0,0,0,0,0,0,0,0,0,0,0,1
1,0,0,0,0,0,0,0,0,0,0,0,0,0,1
1,0,0,0,0,0,0,0,0,0,0,0,0,0,1
1,0,0,0,0,0,0,0,0,0,0,0,0,0,1
1,0,0,0,0,0,0,0,0,0,0,0,0,0,1
1,0,0,0,0,0,0,0,0,0,0,0,0,0,1
1,0,0,0,0,0,0,0,0,0,0,0,0,0,1
1,2,0,0,0,0,0,0,0,0,0,0,0,2,1
1,1,1,1,1,1,1,1,1,1,1,1,1,1,1
endlayer

layer
1,1,1,1,1,1,1,1,1,1,1,1,1,1,1
1,2,0,0,0,0,0,0,0,0,0,0,0,2,1
1,0,0,0,0,0,0,0,0,0,0,0,0,0,1
1,0,0,0,0,0,0,0,0,0,0,0,0,0,1
1,3,3,0,0,0,0,0,0,0,0,0,0,0,1
1,0,0,0,0,0,0,0,0,0,0,0,0,0,1
1,0,0,0,0,0,0,0,0,0,0,0,0,0,1
1,0,0,0,0,0,0,0,0,0,0,0,0,0,1
1,0,0,0,0,0,0,0,0,0,0,0,0,0,1
1,0,0,0,0,0,0,0,0,0,0,0,0,0,1
1,0,0,0,0,0,0,0,0,0,0,0,0,0,1
1,0,0,0,0,0,0,0,0,0,0,0,0,0,1
1,0,0,0,0,0,0,0,0,0,0,0,0,0,1
1,2,0,0,0,0,0,0,0,0,0,0,0,2,1
1,1,1,1,1,1,1,1,1,1,1,1,1,1,1
endlayer

layer
1,2,1,1,1,1,1,1,1,1,1,1,1,2,1
2,2,2,2,2,2,2,2,2,2,2,2,2,2,2
1,2,3,0,0,0,0,0,0,0,0,0,0,2,1
1,2,3,0,0,0,0,0,0,0,0,0,0,2,1
1,2,0,0,0,0,0,0,0,0,0,0,0,2,1
1,2,0,0,0,0,0,0,0,0,0,0,0,2,1
1,2,0,0,0,0,0,0,0,0,0,0,0,2,1
1,2,0,0,0,0,0,0,0,0,0,0,0,2,1
1,2,0,0,0,0,0,0,0,0,0,0,0,2,1
1,2,0,0,0,0,0,0,0,0,0,0,0,2,1
1,2,0,0,0,0,0,0,0,0,0,0,0,2,1
1,2,0,0,0,0,0,0,0,0,0,0,0,2,1
1,2,0,0,0,0,0,0,0,0,0,0,0,2,1
2,2,2,2,2,2,2,2,2,2,2,2,2,2,2
1,2,1,1,1,1,1,1,1,1,1,1,1,2,1
endlayer

layer
1,1,1,1,1,1,1,1,1,1,1,1,1,1,1
1,2,3,3,3,3,3,3,3,3,3,3,3,2,1
1,3,3,3,3,3,3,3,3,3,3,3,3,3,1
1,0,0,3,3,3,3,3,3,3,3,3,3,3,1
1,0,0,3,3,3,3,3,3,3,3,3,3,3,1
1,0,0,3,3,3,3,3,3,3,3,3,3,3,1
1,0,0,3,3,3,3,3,3,3,3,3,3,3,1
1,3,3,3,3,3,3,3,3,3,3,3,3,3,1
1,3,3,3,3,3,3,3,3,3,3,3,3,3,1
1,3,3,3,3,3,3,3,3,3,3,3,3,3,1
1,3,3,3,3,3,3,3,3,3,3,3,3,3,1
1,3,3,3,3,3,3,3,3,3,3,3,3,3,1
1,3,3,3,3,3,3,3,3,3,3,3,3,3,1
1,2,3,3,3,3,3,3,3,3,3,3,3,2,1
1,1,1,1,1,1,1,1,1,1,1,1,1,1,1
endlayer

layer
1,1,1,1,1,1,1,1,1,1,1,1,1,1,1
1,2,6,3,1,1,1,1,1,0,0,0,0,2,1
1,0,0,3,1,1,1,1,1,1,0,0,0,0,1
1,0,0,0,1,1,1,1,1,0,6,6,6,0,1
1,0,0,0,1,1,1,1,1,0,6,0,0,0,1
1,0,6,0,1,1,1,1,0,0,0,6,0,0,1
1,0,0,0,1,1,1,1,0,6,6,0,0,0,1
1,0,0,0,1,1,1,1,1,0,0,0,6,1,1
1,0,0,0,0,1,1,1,0,0,0,0,1,1,1
1,0,0,0,0,0,1,1,1,0,0,1,1,1,1
1,1,0,0,6,0,0,1,1,0,0,1,1,1,1
1,1,0,0,0,0,0,1,0,6,6,0,0,0,1
1,1,1,0,0,0,0,0,0,0,0,0,0,0,1
1,2,1,1,1,0,0,0,0,0,0,0,0,2,1
1,1,1,1,1,1,1,1,1,1,1,1,1,1,1
endlayer

layer
1,1,1,1,1,1,1,1,1,1,1,1,1,1,1
1,2,0,0,3,1,1,1,19,0,0,0,0,2,1
1,0,0,0,3,1,1,1,1,0,0,0,0,0,1
1,0,0,0,0,1,1,1,1,0,0,0,0,0,1
1,0,0,0,0,1,1,1,0,0,0,0,0,0,1
1,0,0,0,0,0,1,1,0,0,0,0,0,0,1
1,0,0,0,0,0,1,1,0,0,0,0,0,0,1
1,0,0,0,0,0,1,1,0,0,0,6,0,0,1
1,0,0,0,0,0,1,1,0,0,0,0,0,1,1
1,0,0,0,0,0,0,1,1,0,0,1,1,1,1
1,0,0,0,0,0,0,1,1,0,0,0,1,1,1
1,0,0,0,0,0,0,0,0,0,0,0,0,0,1
1,1,0,0,0,0,0,0,0,0,0,0,0,0,1
1,2,1,1,0,0,0,0,0,0,0,0,0,2,1
1,1,1,1,1,1,1,1,1,1,1,1,1,1,1
endlayer

layer
1,1,1,1,1,1,1,1,1,1,1,1,1,1,1
1,2,0,0,6,3,1,1,0,0,0,0,0,2,1
1,0,0,0,0,3,1,1,1,0,0,0,0,0,1
1,0,0,6,0,0,1,1,0,0,0,0,0,0,1
1,0,0,0,0,0,1,1,0,0,0,0,0,0,1
1,0,0,0,0,0,1,1,0,0,0,0,0,0,1
1,0,0,0,0,0,0,1,0,0,0,0,0,0,1
1,0,0,0,0,0,0,1,0,0,0,0,0,0,1
1,0,0,0,0,0,0,0,0,0,0,0,6,0,1
1,0,0,0,0,0,0,1,1,0,0,1,1,1,1
1,0,0,0,0,0,0,0,1,0,0,0,1,1,1
1,0,0,0,0,0,0,0,0,0,0,0,0,0,1
1,1,0,0,0,0,0,0,6,0,0,0,0,0,1
1,2,1,0,0,0,0,0,0,0,0,0,0,2,1
1,1,1,1,1,1,1,1,1,1,1,1,1,1,1
endlayer

layer
1,1,1,1,1,1,1,1,1,1,1,1,1,1,1
1,2,0,0,0,0,3,1,0,0,0,0,0,2,1
1,0,0,0,0,0,3,1,0,0,0,0,0,0,1
1,0,0,0,0,0,0,1,0,0,0,0,0,0,1
1,0,0,0,0,0,0,1,0,0,0,0,0,0,1
1,0,0,0,0,0,0,1,0,0,0,0,0,0,1
1,0,0,0,0,0,0,1,0,0,0,0,0,0,1
1,0,0,0,0,0,0,1,0,0,0,0,0,0,1
1,0,0,0,0,0,0,0,0,0,0,0,0,0,1
1,0,0,0,0,0,0,1,1,1,1,1,1,5,1
1,0,0,0,0,0,0,0,0,0,0,0,1,0,1
1,0,0,0,0,0,0,0,0,0,0,0,0,0,1
1,0,0,0,0,0,0,0,0,0,0,0,0,0,1
1,2,0,0,0,0,0,0,0,0,0,0,0,2,1
1,1,1,1,1,1,1,1,1,1,1,1,1,1,1
endlayer

layer
1,2,1,1,1,1,1,1,1,1,1,1,1,2,1
2,2,2,2,2,2,2,2,2,2,2,2,2,2,2
1,2,0,0,0,0,6,3,3,0,0,0,0,2,1
1,2,0,0,0,0,0,1,0,0,0,0,0,2,1
1,2,0,0,0,0,0,1,0,0,0,0,0,2,1
1,2,0,0,0,0,0,1,0,0,0,0,0,2,1
1,2,0,0,0,0,0,1,0,0,0,0,0,2,1
1,2,0,0,0,0,0,0,0,0,0,0,0,2,1
1,2,0,0,0,0,0,0,0,0,0,0,1,2,1
1,2,0,0,0,0,0,1,1,1,1,1,1,2,1
1,2,0,0,0,0,0,0,0,0,0,0,1,2,1
1,2,0,0,0,0,0,0,0,0,0,0,0,2,1
1,2,0,0,0,0,0,0,0,0,0,0,0,2,1
2,2,2,2,2,2,2,2,2,2,2,2,2,2,2
1,2,1,1,1,1,1,1,1,1,1,1,1,2,1
endlayer

layer
1,1,1,1,1,1,1,1,1,1,1,1,1,1,1
1,2,3,0,0,0,0,0,3,3,3,3,3,2,1
1,3,3,0,0,0,0,0,3,3,3,3,3,3,1
1,3,3,3,3,3,3,3,3,3,3,3,3,3,1
1,3,3,3,3,3,3,3,3,3,3,3,3,3,1
1,3,3,3,3,3,3,3,3,3,3,3,3,3,1
1,3,3,3,3,3,3,3,3,3,3,3,3,3,1
1,3,3,3,3,3,3,3,3,3,3,3,3,3,1
1,3,3,3,3,3,3,3,3,3,3,3,3,3,1
1,3,3,3,3,3,3,3,3,3,3,3,3,3,1
1,3,3,3,3,3,3,3,3,3,3,3,3,3,1
1,3,3,3,3,3,3,3,3,3,3,3,3,3,1
1,3,3,3,3,3,3,3,3,3,3,3,3,3,1
1,2,3,3,3,3,3,3,3,3,3,3,3,2,1
1,1,1,1,1,1,1,1,1,1,1,1,1,1,1
endlayer

layer
1,1,1,1,1,1,1,1,1,1,1,1,1,1,1
1,2,0,0,0,0,0,0,0,3,1,1,1,2,1
1,0,0,0,0,0,0,0,0,3,1,1,1,1,1
1,0,0,0,0,0,0,0,0,0,0,1,1,1,1
1,0,0,0,0,0,0,0,0,0,0,0,1,1,1
1,0,0,6,0,0,0,0,0,0,0,0,0,1,1
1,0,0,0,0,0,0,6,6,0,0,0,0,0,1
1,0,0,0,0,0,0,6,0,0,0,0,0,0,1
1,0,0,0,0,0,0,0,0,0,0,0,6,0,1
1,0,0,0,0,6,0,0,6,6,0,0,0,0,1
1,0,0,0,0,0,0,0,0,6,6,0,0,1,1
1,0,0,0,0,0,0,0,0,6,6,6,1,1,1
1,0,0,0,0,0,0,0,0,0,0,0,1,1,1
1,2,0,0,0,0,0,0,0,0,0,1,5,2,1
1,1,1,1,1,1,1,1,1,1,1,1,1,1,1
endlayer

layer
1,1,1,1,1,1,1,1,1,1,1,1,1,1,1
1,2,0,0,0,0,0,0,0,0,3,1,1,2,1
1,0,0,0,0,0,0,0,6,0,3,1,1,1,1
1,0,0,0,0,0,0,0,0,6,0,1,1,1,1
1,0,0,0,0,0,0,0,0,0,0,0,0,1,1
1,0,0,0,0,0,0,0,0,0,0,0,0,6,1
1,0,0,0,0,0,0,0,0,0,0,0,0,0,1
1,0,0,0,0,0,0,0,0,0,0,0,0,0,1
1,0,0,0,0,0,0,0,0,0,0,0,0,0,1
1,0,0,0,0,0,0,0,0,0,0,0,0,0,1
1,0,0,0,0,0,0,0,0,0,0,0,0,0,1
1,0,0,0,0,0,0,0,0,0,0,0,0,1,1
1,0,0,0,0,0,0,0,0,0,0,0,0,1,1
1,2,0,0,0,0,0,0,0,0,0,0,1,2,1
1,1,1,1,1,1,1,1,1,1,1,1,1,1,1
endlayer

layer
1,1,1,1,1,1,1,1,1,1,1,1,1,1,1
1,2,0,0,0,0,0,0,0,0,0,3,3,2,1
1,0,0,0,0,0,0,0,0,0,6,3,3,3,1
1,0,0,0,0,0,0,0,0,0,0,0,1,0,1
1,0,0,0,0,0,0,0,0,0,0,0,0,0,1
1,0,0,0,0,0,0,0,0,0,0,0,0,0,1
1,0,0,0,0,0,0,0,0,0,0,0,0,0,1
1,0,0,0,0,0,0,0,0,0,0,0,0,0,1
1,0,0,0,0,0,0,0,0,0,0,0,0,0,1
1,0,0,0,0,0,0,0,0,0,0,0,0,0,1
1,0,0,0,0,0,0,0,0,0,0,0,0,0,1
1,0,0,0,0,0,0,0,0,0,0,0,0,0,1
1,0,0,0,0,0,0,0,0,0,0,0,0,1,1
1,2,0,0,0,0,0,0,0,0,0,0,0,2,1
1,1,1,1,1,1,1,1,1,1,1,1,1,1,1
endlayer

layer
1,1,1,1,1,1,1,1,1,1,1,1,1,1,1
1,2,0,0,0,0,0,0,0,0,0,0,0,2,1
1,0,0,0,0,0,0,0,0,0,0,6,6,0,1
1,0,0,0,0,0,0,0,0,0,0,0,3,3,1
1,0,0,0,0,0,0,0,0,0,0,0,0,0,1
1,0,0,0,0,0,0,0,0,0,0,0,0,0,1
1,0,0,0,0,0,0,0,0,0,0,0,0,0,1
1,0,0,0,0,0,0,0,0,0,0,0,0,0,1
1,0,0,0,0,0,0,0,0,0,0,0,0,0,1
1,0,0,0,0,0,0,0,0,0,0,0,0,0,1
1,0,0,0,0,0,0,0,0,0,0,0,0,0,1
1,0,0,0,0,0,0,0,0,0,0,0,0,0,1
1,0,0,0,0,0,0,0,0,0,0,0,0,0,1
1,2,0,0,0,0,0,0,0,0,0,0,0,2,1
1,1,1,1,1,1,1,1,1,1,1,1,1,1,1
endlayer

layer
1,2,1,1,1,1,1,1,1,1,1,1,1,2,1
2,2,2,2,2,2,2,2,2,2,2,2,2,2,2
1,2,0,0,0,0,0,0,0,0,0,0,0,2,1
1,2,0,0,0,0,0,0,0,0,0,0,0,2,1
1,2,0,0,0,0,0,0,0,0,0,0,3,2,1
1,2,0,0,0,0,0,0,0,0,0,0,3,2,1
1,2,0,0,0,0,0,0,0,0,0,0,0,2,1
1,2,0,0,0,0,0,0,0,0,0,0,0,2,1
1,2,0,0,0,0,0,0,0,0,0,0,0,2,1
1,2,0,0,0,0,0,0,0,0,0,0,0,2,1
1,2,0,0,0,0,0,0,0,0,0,0,0,2,1
1,2,0,0,0,0,0,0,0,0,0,0,0,2,1
1,2,0,0,0,0,0,0,0,0,0,0,0,2,1
2,2,2,2,2,2,2,2,2,2,2,2,2,2,2
1,2,1,1,1,1,1,1,1,1,1,1,1,2,1
endlayer

layer
1,1,1,1,1,1,1,1,1,1,1,1,1,1,1
1,2,3,3,3,3,3,3,3,3,0,0,0,2,1
1,3,3,3,3,3,3,3,3,3,0,0,0,0,1
1,3,3,3,3,3,3,3,3,3,3,3,0,0,1
1,3,3,3,3,3,3,3,3,3,3,3,0,0,1
1,3,3,3,3,3,3,3,3,3,3,3,3,3,1
1,3,3,3,3,3,3,3,3,3,3,3,3,3,1
1,3,3,3,3,3,3,3,3,3,3,3,3,3,1
1,3,3,3,3,3,3,3,3,3,3,3,3,3,1
1,3,3,3,3,3,3,3,3,3,3,3,3,3,1
1,3,3,3,3,3,3,3,3,3,3,3,3,3,1
1,3,3,3,3,3,3,3,3,3,3,3,3,3,1
1,3,3,3,3,3,3,3,3,3,3,3,3,3,1
1,2,3,3,3,3,3,3,3,3,3,3,3,2,1
1,1,1,1,1,1,1,1,1,1,1,1,1,1,1
endlayer

layer
1,1,1,1,1,1,1,1,1,1,1,1,1,1,1
1,2,0,0,0,0,0,0,0,0,0,0,0,2,1
1,0,0,0,0,0,0,0,0,0,0,0,0,0,1
1,0,0,0,0,0,0,0,0,0,0,0,0,0,1
1,0,0,0,0,0,0,0,0,0,0,0,0,0,1
1,0,0,0,0,0,0,6,0,0,0,0,6,0,1
1,0,0,0,0,0,0,0,0,0,0,0,3,3,1
1,0,0,0,0,0,0,0,0,0,0,0,1,1,1
1,0,0,0,0,0,0,6,0,0,0,1,1,1,1
1,1,0,0,0,0,0,0,0,0,0,1,1,1,1
1,1,1,0,0,0,0,0,0,0,0,1,1,1,1
1,1,1,1,0,0,0,6,0,0,1,1,1,1,1
1,1,1,1,1,0,0,0,0,0,0,1,1,1,1
1,2,1,1,1,1,0,0,0,0,6,0,6,2,1
1,1,1,1,1,1,1,1,1,1,1,1,1,1,1
endlayer

layer
1,1,1,1,1,1,1,1,1,1,1,1,1,1,1
1,2,0,0,0,0,0,0,0,0,0,0,0,2,1
1,0,0,0,0,0,0,0,0,0,0,0,0,0,1
1,0,0,0,0,0,0,0,0,0,0,0,0,0,1
1,0,0,0,0,0,0,0,0,0,0,0,0,0,1
1,0,0,0,0,0,0,0,0,0,0,0,0,0,1
1,0,0,0,0,0,0,0,0,0,0,0,6,0,1
1,0,0,0,0,0,0,0,0,0,0,0,3,3,1
1,0,0,0,0,0,0,0,0,0,0,0,1,1,1
1,0,0,0,0,0,0,0,0,0,0,0,1,1,1
1,0,0,0,0,0,0,0,0,0,0,1,1,1,1
1,0,0,0,0,0,0,0,0,0,0,1,1,5,1
1,1,1,0,0,0,0,0,0,0,0,0,0,0,1
1,2,1,0,0,0,0,0,0,0,0,0,0,2,1
1,1,1,1,1,1,1,1,1,1,1,1,1,1,1
endlayer

layer
1,1,1,1,1,1,1,1,1,1,1,1,1,1,1
1,2,0,0,0,0,0,0,0,0,0,0,0,2,1
1,0,0,0,0,0,0,0,0,0,0,0,0,0,1
1,0,0,0,0,0,0,0,0,0,0,0,0,0,1
1,0,0,0,0,0,0,0,0,0,0,0,0,0,1
1,0,0,0,0,0,0,0,0,0,0,0,0,0,1
1,0,0,0,0,0,0,0,0,0,0,0,0,0,1
1,0,0,0,0,0,0,0,0,0,0,0,0,0,1
1,0,0,0,0,0,0,0,0,0,0,0,3,3,1
1,0,0,0,0,0,0,0,0,0,0,0,1,1,1
1,0,0,0,0,0,0,0,0,0,0,0,1,1,1
1,0,0,0,0,0,0,0,0,0,0,1,1,1,1
1,1,0,0,0,0,0,0,0,0,0,0,0,0,1
1,2,1,0,0,0,0,0,0,0,0,0,0,2,1
1,1,1,1,1,1,1,1,1,1,1,1,1,1,1
endlayer

layer
1,1,1,1,1,1,1,1,1,1,1,1,1,1,1
1,2,0,0,0,0,0,0,0,0,0,0,0,2,1
1,0,0,0,0,0,0,0,0,0,0,0,0,0,1
1,0,0,0,0,0,0,0,0,0,0,0,0,0,1
1,0,0,0,0,0,0,0,0,0,0,0,0,0,1
1,0,0,0,0,0,0,0,0,0,0,0,0,0,1
1,0,0,0,0,0,0,0,0,0,0,0,0,0,1
1,0,0,0,0,0,0,0,0,0,0,0,0,0,1
1,0,0,0,0,0,0,0,0,0,0,0,6,0,1
1,0,0,0,0,0,0,0,0,0,0,0,3,3,1
1,0,0,0,0,0,0,0,0,0,0,0,1,1,1
1,0,0,0,0,0,0,0,0,0,0,0,1,1,1
1,0,0,0,0,0,0,0,0,0,0,0,0,0,1
1,2,0,0,0,0,0,0,0,0,0,0,0,2,1
1,1,1,1,1,1,1,1,1,1,1,1,1,1,1
endlayer

layer
1,2,1,1,1,1,1,1,1,1,1,1,1,2,1
2,2,2,2,2,2,2,2,2,2,2,2,2,2,2
1,2,0,0,0,0,0,0,0,0,0,0,0,2,1
1,2,0,0,0,0,0,0,0,0,0,0,0,2,1
1,2,0,0,0,0,0,0,0,0,0,0,0,2,1
1,2,0,0,0,0,0,0,0,0,0,0,0,2,1
1,2,0,0,0,0,0,0,0,0,0,0,0,2,1
1,2,0,0,0,0,0,0,0,0,0,0,0,2,1
1,2,0,0,0,0,0,0,0,0,0,0,0,2,1
1,2,0,0,0,0,0,0,0,0,0,0,0,2,1
1,2,0,0,0,0,0,0,0,0,0,0,3,2,1
1,2,0,0,0,0,0,0,0,0,0,0,3,2,1
1,2,0,0,0,0,0,0,0,0,0,0,0,2,1
2,2,2,2,2,2,2,2,2,2,2,2,2,2,2
1,2,1,1,1,1,1,1,1,1,1,1,1,2,1
endlayer

layer
1,1,1,1,1,1,1,1,1,1,1,1,1,1,1
1,2,3,3,3,3,3,3,3,3,3,3,3,2,1
1,3,3,3,3,3,3,3,3,3,3,3,3,3,1
1,3,3,3,3,3,3,3,3,3,3,3,3,3,1
1,3,3,3,3,3,3,3,3,3,3,3,3,3,1
1,3,3,3,3,3,3,3,3,3,3,3,3,3,1
1,3,3,3,3,3,3,3,3,3,3,3,3,3,1
1,3,3,3,3,3,3,3,3,3,3,3,0,0,1
1,3,3,3,3,3,3,3,3,3,3,3,0,0,1
1,3,3,3,3,3,3,3,3,3,3,3,0,0,1
1,3,3,3,3,3,3,3,3,3,3,3,0,0,1
1,3,3,3,3,3,3,3,3,3,3,3,3,3,1
1,3,3,3,3,3,3,3,3,3,3,3,3,3,1
1,2,3,3,3,3,3,3,3,3,3,3,3,2,1
1,1,1,1,1,1,1,1,1,1,1,1,1,1,1
endlayer

layer
1,1,1,1,1,1,1,1,1,1,1,1,1,1,1
1,2,1,1,1,0,0,0,0,0,0,0,0,2,1
1,1,1,1,0,0,0,0,0,0,0,0,0,0,1
1,1,1,1,6,0,6,0,0,0,0,0,0,0,1
1,1,1,0,6,0,0,0,0,0,0,0,0,0,1
1,1,0,0,0,6,6,0,0,0,0,0,0,0,1
1,0,0,0,6,0,20,6,0,0,0,0,0,0,1
1,0,0,0,0,0,0,6,0,0,0,0,0,0,1
1,0,0,0,6,0,21,0,21,0,6,0,0,0,1
1,0,0,0,0,6,0,0,0,6,0,0,0,0,1
1,0,0,0,0,0,0,0,6,0,0,6,0,0,1
1,0,0,0,0,0,0,0,6,0,0,0,0,0,1
1,0,0,0,0,0,0,0,0,0,0,1,1,0,1
1,2,0,0,0,0,0,0,0,1,1,1,1,2,1
1,1,1,1,1,1,1,1,1,1,1,1,1,1,1
endlayer

layer
1,1,1,1,1,1,1,1,1,1,1,1,1,1,1
1,2,5,1,0,0,0,0,0,0,0,0,0,2,1
1,1,1,1,6,0,0,0,0,0,0,0,0,0,1
1,1,1,6,0,0,0,0,0,0,0,0,0,0,1
1,1,0,0,0,0,0,0,0,0,0,0,0,0,1
1,0,0,0,0,0,0,0,0,0,0,0,0,0,1
1,0,0,0,0,0,20,0,0,0,0,0,0,0,1
1,0,0,0,0,0,22,0,0,0,0,0,0,0,1
1,0,0,0,0,0,21,0,21,0,0,0,0,0,1
1,0,0,0,0,0,0,0,0,0,0,0,0,0,1
1,0,0,0,0,0,0,0,0,0,0,0,0,0,1
1,0,0,0,0,0,0,0,0,0,0,0,0,0,1
1,0,0,0,0,0,0,0,0,0,0,0,0,0,1
1,2,0,0,0,0,0,0,0,0,1,1,1,2,1
1,1,1,1,1,1,1,1,1,1,1,1,1,1,1
endlayer

layer
1,1,1,1,1,1,1,1,1,1,1,1,1,1,1
1,2,0,1,0,0,0,0,0,0,0,0,0,2,1
1,1,1,6,6,0,0,0,0,0,0,0,0,0,1
1,0,0,0,0,0,0,0,0,0,0,0,0,0,1
1,0,0,0,0,0,0,0,0,0,0,0,0,0,1
1,0,0,0,0,0,0,0,0,0,0,0,0,0,1
1,0,0,0,0,0,20,0,0,0,0,0,0,0,1
1,0,0,0,0,0,22,0,0,0,0,0,0,0,1
1,0,0,0,0,0,21,21,21,0,0,0,0,0,1
1,0,0,0,0,0,0,0,0,0,0,0,0,0,1
1,0,0,0,0,0,0,0,0,0,0,0,0,0,1
1,0,0,0,0,0,0,0,0,0,0,0,0,0,1
1,0,0,0,0,0,0,0,0,0,0,0,0,0,1
1,2,0,0,0,0,0,0,0,0,0,1,1,2,1
1,1,1,1,1,1,1,1,1,1,1,1,1,1,1
endlayer

layer
1,1,1,1,1,1,1,1,1,1,1,1,1,1,1
1,2,0,0,0,0,0,0,0,0,0,0,0,2,1
1,1,0,0,0,0,0,0,0,0,0,0,0,0,1
1,0,0,0,0,0,0,0,0,0,0,0,0,0,1
1,0,0,0,0,0,0,0,0,0,0,0,0,0,1
1,0,0,0,0,0,0,0,0,0,0,0,0,0,1
1,0,0,0,0,0,23,0,0,0,0,0,0,0,1
1,0,0,0,0,0,22,0,24,0,0,0,0,0,1
1,0,0,0,0,0,26,21,25,0,0,0,0,0,1
1,0,0,0,0,0,0,0,0,0,0,0,0,0,1
1,0,0,0,0,0,0,0,0,0,0,0,0,0,1
1,0,0,0,0,0,0,0,0,0,0,0,0,0,1
1,0,0,0,0,0,0,0,0,0,0,0,0,0,1
1,2,0,0,0,0,0,0,0,0,0,0,1,2,1
1,1,1,1,1,1,1,1,1,1,1,1,1,1,1
endlayer

layer
1,1,1,1,1,1,1,1,1,1,1,1,1,1,1
1,2,0,0,2,2,2,2,2,2,2,2,2,2,1
1,2,0,0,0,0,0,0,0,0,0,0,0,2,1
1,2,0,0,0,0,0,0,0,0,0,0,0,2,1
1,2,0,0,0,0,0,0,0,0,0,0,0,2,1
1,2,0,0,0,0,0,0,0,0,0,0,0,2,1
1,2,0,0,0,0,23,0,0,0,0,0,0,2,1
1,2,0,0,0,0,22,0,24,0,0,0,0,2,1
1,2,0,0,0,0,26,21,25,0,0,0,0,2,1
1,2,0,0,0,0,0,0,0,0,0,0,0,2,1
1,2,0,0,0,0,0,0,0,0,0,0,0,2,1
1,2,0,0,0,0,0,0,0,0,0,0,0,2,1
1,2,0,0,0,0,0,0,0,0,0,0,0,2,1
1,2,2,2,2,2,2,2,2,2,2,2,2,2,1
1,1,1,1,1,1,1,1,1,1,1,1,1,1,1
endlayer

layer
1,1,1,1,1,1,1,1,1,1,1,1,1,1,1
1,3,3,3,3,3,3,3,3,3,3,3,3,3,1
1,3,3,3,3,3,3,3,3,3,3,3,3,3,1
1,3,3,3,3,3,3,3,3,3,3,3,3,3,1
1,3,3,3,3,3,3,3,3,3,3,3,3,3,1
1,3,3,3,3,3,3,3,3,3,3,3,3,3,1
1,3,3,3,3,3,23,20,24,3,3,3,3,3,1
1,3,3,3,3,3,22,6,24,3,3,3,3,3,1
1,3,3,3,3,3,26,21,25,3,3,3,3,3,1
1,3,3,3,3,3,3,3,3,3,3,3,3,3,1
1,3,3,3,3,3,3,3,3,3,3,3,3,3,1
1,3,3,3,3,3,3,3,3,3,3,3,3,3,1
1,3,3,3,3,3,3,3,3,3,3,3,3,3,1
1,3,3,3,3,3,3,3,3,3,3,3,3,3,1
1,1,1,1,1,1,1,1,1,1,1,1,1,1,1
endlayer

layer
1,1,1,1,1,1,1,1,1,1,1,1,1,1,1
1,1,1,1,1,3,3,3,3,3,3,3,3,3,1
1,1,1,1,1,3,3,3,3,3,3,3,3,3,1
1,1,1,1,1,3,3,3,3,3,3,3,3,3,1
1,1,1,1,1,3,3,3,3,3,3,3,3,3,1
1,3,3,3,3,3,3,3,3,3,3,3,3,3,1
1,3,3,3,3,3,23,20,20,3,0,3,3,3,1
1,3,3,3,3,3,22,0,24,3,0,3,3,3,1
1,3,3,3,3,3,26,21,25,3,0,3,3,3,1
1,3,3,3,3,3,3,3,3,3,3,3,3,3,1
1,3,3,3,3,3,0,0,3,3,3,3,3,3,1
1,3,3,3,3,3,3,3,3,3,3,3,3,3,1
1,3,3,3,3,3,3,3,3,3,3,3,3,3,1
1,3,3,3,3,3,3,3,3,3,3,3,3,3,1
1,1,1,1,1,1,1,1,1,1,1,1,1,1,1
endlayer

layer
1,1,1,1,1,1,1,1,1,1,1,1,1,1,1
1,1,1,1,1,3,3,3,3,3,3,3,3,3,1
1,1,1,1,1,3,27,27,27,27,28,27,27,3,1
1,1,1,1,1,3,29,29,3,3,3,3,27,3,1
1,1,1,1,1,3,3,3,3,3,3,3,27,3,1
1,3,3,3,3,3,3,3,3,3,3,3,30,3,1
1,3,27,31,3,3,20,0,20,3,3,28,27,3,1
1,3,27,31,3,3,22,0,0,3,3,28,27,3,1
1,3,27,3,3,3,22,21,24,3,3,28,27,3,1
1,3,30,3,3,3,3,3,3,3,3,3,30,3,1
1,3,27,3,3,3,3,3,3,3,3,3,27,3,1
1,3,27,3,3,3,30,30,30,3,3,3,27,3,1
1,3,27,27,27,28,27,27,27,28,27,27,3,3,1
1,3,3,3,3,3,3,3,3,3,3,3,3,3,1
1,1,1,1,1,1,1,1,1,1,1,1,1,1,1
endlayer

layer
1,1,1,1,1,1,1,1,1,1,1,1,1,1,1
1,1,1,1,1,3,3,3,3,3,3,3,3,3,1
1,1,1,1,1,3,3,3,3,3,3,3,3,3,1
1,1,1,1,1,3,0,0,3,3,3,3,3,3,1
1,1,1,1,1,3,32,32,3,3,3,3,3,3,1
1,3,3,3,3,3,3,3,3,3,3,3,3,3,1
1,1,3,0,32,3,20,0,0,3,32,3,3,3,1
1,1,3,0,32,3,0,0,0,3,32,3,3,3,1
1,1,3,3,3,3,0,21,0,3,32,3,3,3,1
1,1,3,3,3,3,3,3,3,3,3,3,3,3,1
1,1,3,3,3,3,32,32,33,3,3,3,3,3,1
1,3,3,3,3,3,0,0,0,3,3,27,0,3,1
1,1,3,3,3,3,3,3,3,3,3,0,3,3,1
1,1,1,1,1,1,1,1,1,1,3,3,3,3,1
1,1,1,1,1,1,1,1,1,1,1,1,1,1,1
endlayer

layer
1,1,1,1,1,1,1,1,1,1,1,1,1,1,1
1,1,1,1,1,1,1,1,1,1,1,1,1,1,1
1,1,1,1,1,3,3,3,3,1,1,1,1,1,1
1,1,1,1,1,3,3,3,3,1,1,1,1,1,1
1,1,1,1,1,3,3,34,3,1,1,1,1,1,1
1,1,1,1,3,3,0,35,0,3,3,1,1,1,1
1,1,1,3,39,38,33,33,33,37,36,3,1,1,1
1,1,1,3,39,38,33,33,33,37,36,3,1,1,1
1,1,1,3,0,33,33,33,33,37,36,3,1,1,1
1,1,1,1,3,3,40,40,33,3,3,3,3,1,1
1,1,1,1,3,3,41,41,33,3,3,27,3,3,1
1,1,1,1,3,3,3,3,3,3,3,0,3,3,1
1,1,1,1,3,3,1,1,1,1,3,3,3,3,1
1,1,1,1,1,1,1,1,1,1,1,1,1,1,1
1,1,1,1,1,1,1,1,1,1,1,1,1,1,1
endlayer

layer
1,1,1,1,1,1,1,1,1,1,1,1,1,1,1
1,1,1,1,1,1,1,1,1,1,1,1,1,1,1
1,1,1,1,1,1,1,1,1,1,1,1,1,1,1
1,1,1,1,1,1,42,42,42,1,1,1,1,1,1
1,1,1,1,43,1,43,42,42,43,1,1,43,1,1
1,1,1,1,33,33,33,33,33,33,33,42,33,1,1
1,1,1,1,33,33,0,0,0,33,33,33,33,1,1
1,1,1,1,33,33,0,0,0,33,33,33,33,1,1
1,1,1,1,33,33,0,0,0,33,33,33,33,1,1
1,1,1,1,33,33,33,33,33,33,33,27,33,1,1
1,1,1,1,43,1,33,33,33,43,33,0,43,1,1
1,1,1,1,1,1,1,1,1,1,1,33,1,1,1
1,1,1,1,1,1,1,1,1,1,1,1,1,1,1
1,1,1,1,1,1,1,1,1,1,1,1,1,1,1
1,1,1,1,1,1,1,1,1,1,1,1,1,1,1
endlayer

layer
44,44,44,44,44,44,44,0,44,44,44,44,44,44,44
44,0,0,0,0,0,0,0,0,0,0,0,0,0,44
44,0,0,0,0,0,0,0,6,0,0,0,0,0,44
44,0,0,0,0,0,0,0,6,0,0,0,0,0,44
44,0,0,0,43,0,43,16,0,43,33,33,43,0,44
44,0,0,0,33,33,33,45,33,33,33,33,33,0,44
0,0,0,0,33,0,0,0,6,0,0,0,33,0,44
44,0,0,0,33,0,6,0,0,6,0,0,33,0,0
44,0,0,0,33,0,0,6,6,0,0,46,33,0,44
44,0,0,0,33,33,0,0,0,33,33,33,33,0,44
44,0,0,0,43,33,33,33,33,43,33,33,43,0,44
44,0,0,0,0,0,0,0,0,0,0,0,0,0,44
44,0,0,0,0,0,0,0,0,0,0,0,0,0,44
44,0,0,0,0,0,0,0,0,0,0,0,0,0,44
44,44,44,44,44,44,44,0,44,44,44,44,44,44,44
endlayer

layer
0,0,0,0,0,0,0,0,0,0,0,0,0,0,0
0,0,0,0,0,0,0,0,0,0,0,0,0,0,0
0,0,0,0,0,0,0,0,0,0,0,0,0,0,0
0,0,0,0,0,0,0,0,0,0,0,0,0,0,0
0,0,0,0,43,0,43,0,0,43,33,33,43,0,0
0,0,0,0,33,33,33,47,33,33,33,33,33,0,0
0,0,0,0,48,0,0,0,0,0,0,0,48,0,0
0,0,0,0,48,0,0,0,0,0,0,0,48,0,0
0,0,0,0,48,0,0,0,0,0,0,0,48,0,0
0,0,0,0,33,33,0,0,0,33,33,33,33,0,0
0,0,0,0,43,33,48,48,48,43,33,33,43,0,0
0,0,0,0,0,0,0,0,0,0,0,0,0,0,0
0,0,0,0,0,0,0,0,0,0,0,0,0,0,0
0,0,0,0,0,0,0,0,0,0,0,0,0,0,0
0,0,0,0,0,0,0,0,0,0,0,0,0,0,0
endlayer

layer
0,0,0,0,0,0,0,0,0,0,0,0,0,0,0
0,0,0,0,0,0,0,0,0,0,0,0,0,0,0
0,0,0,0,0,0,0,0,0,0,0,0,0,0,0
0,0,0,0,0,0,49,0,0,0,0,0,0,0,0
0,0,0,0,43,0,43,0,0,43,33,33,43,0,0
0,0,0,0,33,33,33,33,33,33,33,33,33,0,0
0,0,0,0,48,0,0,0,0,0,0,0,48,0,0
0,0,0,0,48,0,0,0,0,0,0,0,48,0,0
0,0,0,0,48,0,0,0,0,0,0,0,48,0,0
0,0,0,0,33,33,0,0,0,33,33,33,33,0,0
0,0,0,0,43,33,48,48,48,43,33,33,43,0,0
0,0,0,0,0,0,0,0,0,0,0,0,0,0,0
0,0,0,0,0,0,0,0,0,0,0,0,0,0,0
0,0,0,0,0,0,0,0,0,0,0,0,0,0,0
0,0,0,0,0,0,0,0,0,0,0,0,0,0,0
endlayer

layer
0,0,0,0,0,0,0,0,0,0,0,0,0,0,0
0,0,0,0,0,0,0,0,0,0,0,0,0,0,0
0,0,0,0,0,0,0,0,0,0,0,0,0,0,0
0,0,0,0,0,0,0,0,0,0,0,0,0,0,0
0,0,0,0,50,51,51,51,51,51,51,51,50,0,0
0,0,0,0,50,43,0,0,0,0,0,43,50,0,0
0,0,0,0,50,0,0,0,0,0,0,0,50,0,0
0,0,0,0,50,0,0,0,0,0,0,0,50,0,0
0,0,0,0,50,0,0,0,0,0,0,0,50,0,0
0,0,0,0,50,43,0,0,0,0,0,43,50,0,0
0,0,0,0,50,51,51,51,51,51,51,51,50,0,0
0,0,0,0,0,0,0,0,0,0,0,0,0,0,0
0,0,0,0,0,0,0,0,0,0,0,0,0,0,0
0,0,0,0,0,0,0,0,0,0,0,0,0,0,0
0,0,0,0,0,0,0,0,0,0,0,0,0,0,0
endlayer

layer
0,0,0,0,0,0,0,0,0,0,0,0,0,0,0
0,0,0,0,0,0,0,0,0,0,0,0,0,0,0
0,0,0,0,0,0,0,0,0,0,0,0,0,0,0
0,0,0,0,0,0,0,0,0,0,0,0,0,0,0
0,0,0,0,0,0,0,0,0,0,0,0,0,0,0
0,0,0,0,0,43,33,33,33,33,33,43,0,0,0
0,0,0,0,0,33,33,0,0,0,33,33,0,0,0
0,0,0,0,0,33,0,0,0,0,0,33,0,0,0
0,0,0,0,0,33,33,0,0,0,33,33,0,0,0
0,0,0,0,0,43,33,33,33,33,33,43,0,0,0
0,0,0,0,0,0,0,0,0,0,0,0,0,0,0
0,0,0,0,0,0,0,0,0,0,0,0,0,0,0
0,0,0,0,0,0,0,0,0,0,0,0,0,0,0
0,0,0,0,0,0,0,0,0,0,0,0,0,0,0
0,0,0,0,0,0,0,0,0,0,0,0,0,0,0
endlayer

layer
0,0,0,0,0,0,0,0,0,0,0,0,0,0,0
0,0,0,0,0,0,0,0,0,0,0,0,0,0,0
0,0,0,0,0,0,0,0,0,0,0,0,0,0,0
0,0,0,0,0,0,0,0,0,0,0,0,0,0,0
0,0,0,0,0,0,0,0,0,0,0,0,0,0,0
0,0,0,0,0,0,50,0,0,0,50,0,0,0,0
0,0,0,0,0,50,50,50,50,50,50,50,0,0,0
0,0,0,0,0,50,50,50,50,50,50,50,0,0,0
0,0,0,0,0,50,50,50,50,50,50,50,0,0,0
0,0,0,0,0,0,50,0,0,0,50,0,0,0,0
0,0,0,0,0,0,0,0,0,0,0,0,0,0,0
0,0,0,0,0,0,0,0,0,0,0,0,0,0,0
0,0,0,0,0,0,0,0,0,0,0,0,0,0,0
0,0,0,0,0,0,0,0,0,0,0,0,0,0,0
0,0,0,0,0,0,0,0,0,0,0,0,0,0,0
endlayer

