
# Created by Ruins mod version 14.7 Ingame Parser
# authoring Player: OneWolfe

weight=6
unique=1
embed_into_distance=2
biomesToSpawnIn=plains,forest,mountains,tiaga,high hills,rolling hills
acceptable_target_blocks=
unacceptable_target_blocks=flowing_water,water,flowing_lava,lava
dimensions=24,21,21
allowable_overhang=12
max_leveling=4
leveling_buffer=2
preserve_water=0
preserve_lava=0
preserve_plants=1

rule1=0,100,preserveBlock
rule2=0,100,TwilightForest:tile.TFThorns-1
rule3=0,100,TwilightForest:tile.TFThorns-8
rule4=0,100,TwilightForest:tile.TFThorns-4
rule5=0,100,terrafirmacraft:StoneIgExBrick-0,terrafirmacraft:StoneIgExBrick-0,terrafirmacraft:StoneIgExBrick-0,terrafirmacraft:StoneIgExBrick-0,air
rule6=0,100,TwilightForest:tile.TFLog-0
rule7=0,100,TwilightForest:tile.TFUnderBrick-0
rule8=0,100,TwilightForest:tile.TFTowerStone-1
rule9=0,100,TwilightForest:tile.TFUnderBrick-2
rule10=0,100,TwilightForest:tile.TFLog-8
rule11=0,100,TwilightForest:tile.TFUnderBrick-1
rule12=0,100,TwilightForest:tile.TFLog-4
rule13=0,100,air,BiblioWoodsTFC:BiblioBrassLantern-1
rule14=0,100,TwilightForest:tile.TFThorns-9
rule15=0,100,TwilightForest:tile.TFThorns-5
rule16=0,100,air,minecraft:iron_bars-0
rule17=0,100,ChestGenHook:dungeonChest:5-4
rule18=0,100,TwilightForest:tile.TFBossSpawner-4
rule19=0,100,terrafirmacraft:planks-11
rule20=0,100,terrafirmacraft:StoneIgExSmooth-0

layer
1,1,1,1,1,1,1,1,1,1,1,1,1,1,1,1,1,1,1,1,1
1,1,1,1,1,1,1,1,1,1,1,1,1,1,1,1,1,1,1,1,1
1,1,1,1,1,1,1,1,1,1,1,1,1,1,1,1,1,1,1,1,1
1,1,1,1,1,1,1,1,1,1,1,1,1,1,1,1,1,1,1,1,1
1,1,1,1,1,1,1,1,1,1,1,1,1,1,1,1,1,1,1,1,1
1,1,1,1,1,1,1,1,1,1,1,1,1,1,1,1,1,1,1,1,1
1,1,1,1,1,1,1,1,1,1,1,1,1,1,1,1,1,1,1,1,1
1,1,1,1,1,1,1,1,1,1,1,1,1,1,1,1,1,1,1,1,1
1,1,1,1,1,1,1,1,1,1,1,1,1,1,1,1,1,1,1,1,1
1,1,1,1,1,1,1,1,1,1,1,1,1,1,1,1,1,1,1,1,1
1,1,1,1,1,1,1,1,1,1,1,1,1,1,1,1,1,1,1,1,1
1,1,1,1,1,1,1,1,1,1,1,1,1,1,1,1,1,1,1,1,1
1,1,1,1,1,1,1,1,1,1,1,1,1,1,1,1,1,1,1,1,1
1,1,1,1,1,1,1,1,1,1,1,1,1,1,1,1,1,1,1,1,1
1,1,1,1,1,1,1,1,1,1,1,1,1,1,1,1,1,1,1,1,1
1,1,1,1,1,1,1,1,1,1,1,1,1,1,1,1,1,1,1,1,1
1,1,1,1,1,1,1,1,1,1,1,1,1,1,1,1,1,1,1,1,1
1,1,1,1,1,1,1,1,1,1,1,1,1,1,1,1,1,1,1,1,1
1,1,1,1,1,1,1,1,1,1,1,1,1,1,1,1,1,1,1,1,1
1,1,1,1,1,1,1,1,1,1,1,1,1,1,1,1,1,1,1,1,1
1,1,1,1,1,1,1,1,1,1,1,1,1,1,1,1,1,1,1,1,1
endlayer

layer
1,1,1,1,1,1,1,1,1,1,1,1,1,1,1,1,1,1,1,1,1
1,1,1,1,1,1,1,1,1,1,1,1,1,1,1,1,1,1,1,1,1
1,1,1,1,1,1,1,1,1,1,1,1,1,1,1,1,1,1,1,1,1
1,1,1,1,1,1,1,1,1,1,1,1,1,1,1,1,1,1,1,1,1
1,1,1,1,1,1,1,1,1,1,1,1,1,1,1,1,1,1,1,1,1
1,1,1,1,1,1,1,1,1,1,1,1,1,1,1,1,1,1,1,1,1
1,1,1,1,1,1,1,1,1,1,1,1,1,1,1,1,1,1,1,1,1
1,1,1,1,1,1,1,1,1,1,1,1,1,1,1,1,1,1,1,1,1
1,1,1,1,1,1,1,1,1,1,1,1,1,1,1,1,1,1,1,1,1
1,1,1,1,1,1,1,1,1,1,1,1,1,1,1,1,1,1,1,1,1
1,1,1,1,1,1,1,1,1,1,1,1,1,1,1,1,1,1,1,1,1
1,1,1,1,1,1,1,1,1,1,1,1,1,1,1,1,1,1,1,1,1
1,1,1,1,1,1,1,1,1,1,1,1,1,1,1,1,1,1,1,1,1
1,1,1,1,1,1,1,1,1,1,1,1,1,1,1,1,1,1,1,1,1
1,1,1,1,1,1,1,1,1,1,1,1,1,1,1,1,1,1,1,1,1
1,1,1,1,1,1,1,1,1,1,1,1,1,1,1,1,1,1,1,1,1
1,1,1,1,1,1,1,1,1,1,1,1,1,1,1,1,1,1,1,1,1
1,1,1,1,1,1,1,1,1,1,1,1,1,1,1,1,1,1,1,1,1
1,1,1,1,1,1,1,1,1,1,1,1,1,1,1,1,1,1,1,1,1
1,1,1,1,1,1,1,1,1,1,1,1,1,1,1,1,1,1,1,1,1
1,1,1,1,1,1,1,1,1,1,1,1,1,1,1,1,1,1,1,1,1
endlayer

layer
2,3,3,3,2,3,3,3,2,0,0,0,2,3,3,3,2,3,3,3,2
4,0,0,0,0,0,0,0,0,0,0,0,0,0,0,0,0,0,0,0,4
4,0,0,0,0,0,0,0,0,0,0,0,0,0,0,0,0,0,0,0,4
4,0,0,0,5,5,0,0,0,0,0,0,0,0,0,5,5,0,0,0,4
2,0,0,5,0,0,5,0,0,0,0,0,0,0,5,0,0,5,0,0,2
4,0,0,5,0,0,5,0,6,0,0,0,6,0,5,0,0,5,0,0,4
4,0,0,0,5,5,7,7,7,8,8,8,7,7,7,5,5,0,0,0,4
4,0,0,0,0,0,7,6,0,0,0,0,0,6,9,0,0,0,0,0,4
2,0,0,0,0,6,7,0,0,0,0,0,0,0,7,6,0,0,0,0,2
0,0,0,0,0,0,8,0,0,0,0,0,0,0,8,0,0,0,0,0,0
0,0,0,0,0,0,8,0,0,0,6,10,0,0,8,0,0,0,0,0,0
0,0,0,0,0,0,8,0,0,0,0,0,0,0,8,0,0,0,0,0,0
2,0,0,0,0,6,7,0,0,0,0,0,0,0,7,6,0,0,0,0,2
4,0,0,0,0,0,7,6,0,0,0,0,0,6,11,0,0,0,0,0,4
4,0,0,0,5,5,5,7,7,8,8,8,7,7,7,5,5,0,0,0,4
4,0,0,5,0,0,5,0,6,0,0,0,6,0,5,0,0,5,0,0,4
2,0,0,5,0,0,5,0,0,0,0,0,0,0,5,0,0,5,0,0,2
4,0,0,0,5,5,0,0,0,0,0,0,0,0,0,5,5,0,0,0,4
4,0,0,0,0,0,0,0,0,0,0,0,0,0,0,0,0,0,0,0,4
4,0,0,0,0,0,0,0,0,0,0,0,0,0,0,0,0,0,0,0,4
2,3,3,3,2,3,3,3,2,0,0,0,2,3,3,3,2,3,3,3,2
endlayer

layer
2,3,3,3,2,3,3,3,2,0,0,0,2,3,3,3,2,3,3,3,2
4,0,0,0,0,0,0,0,0,0,0,0,0,0,0,0,0,0,0,0,4
4,0,0,0,0,0,0,0,0,0,0,0,0,0,0,0,0,0,0,0,4
4,0,0,0,5,5,0,0,0,0,0,0,0,0,0,5,5,0,0,0,4
2,0,0,5,0,0,5,0,0,0,0,0,0,0,5,0,0,5,0,0,2
4,0,0,5,0,0,5,0,6,0,0,0,6,0,5,0,0,5,0,0,4
4,0,0,0,5,5,7,7,7,8,8,8,7,7,7,5,5,0,0,0,4
4,0,0,0,0,0,7,6,0,0,0,0,0,6,7,0,0,0,0,0,4
2,0,0,0,0,6,7,0,0,0,0,0,0,0,7,6,0,0,0,0,2
0,0,0,0,0,0,8,0,0,0,12,0,0,0,8,0,0,0,0,0,0
0,0,0,0,0,0,8,0,0,0,6,0,0,0,8,0,0,0,0,0,0
0,0,0,0,0,0,8,0,0,0,0,0,0,0,8,0,0,0,0,0,0
2,0,0,0,0,6,7,0,0,0,0,0,0,0,7,6,0,0,0,0,2
4,0,0,0,0,0,7,6,0,0,0,0,0,6,7,0,0,0,0,0,4
4,0,0,0,5,5,7,7,7,8,8,8,7,7,7,5,5,0,0,0,4
4,0,0,5,0,0,5,0,6,0,0,0,6,0,5,0,0,5,0,0,4
2,0,0,5,0,0,5,0,0,0,0,0,0,0,5,0,0,5,0,0,2
4,0,0,0,5,5,0,0,0,0,0,0,0,0,0,5,5,0,0,0,4
4,0,0,0,0,0,0,0,0,0,0,0,0,0,0,0,0,0,0,0,4
4,0,0,0,0,0,0,0,0,0,0,0,0,0,0,0,0,0,0,0,4
2,3,3,3,2,3,3,3,2,0,0,0,2,3,3,3,2,3,3,3,2
endlayer

layer
2,0,0,0,2,0,0,0,2,0,0,0,2,0,0,0,2,0,0,0,2
0,0,0,0,0,0,0,0,0,0,0,0,0,0,0,0,0,0,0,0,0
0,0,0,0,0,0,0,0,0,0,0,0,0,0,0,0,0,0,0,0,0
0,0,0,0,5,5,0,0,0,0,0,0,0,0,0,5,5,0,0,0,0
2,0,0,5,0,0,5,0,13,0,0,0,13,0,5,0,0,5,0,0,2
0,0,0,5,0,0,5,0,6,0,0,0,6,0,5,0,0,5,0,0,0
0,0,0,0,5,5,7,7,7,8,8,8,7,7,7,5,5,0,0,0,0
0,0,0,0,0,0,7,6,0,0,0,0,0,6,7,0,0,0,0,0,0
2,0,0,0,13,6,7,0,0,0,0,0,0,0,7,6,13,0,0,0,2
0,0,0,0,0,0,8,0,0,0,0,0,0,0,8,0,0,0,0,0,0
0,0,0,0,0,0,8,0,0,10,6,0,0,0,8,0,0,0,0,0,0
0,0,0,0,0,0,8,0,0,0,0,0,0,0,8,0,0,0,0,0,0
2,0,0,0,13,6,7,0,0,0,0,0,0,0,7,6,13,0,0,0,2
0,0,0,0,0,0,7,6,0,0,0,0,0,6,7,0,0,0,0,0,0
0,0,0,0,5,5,7,7,7,8,8,8,7,7,7,5,5,0,0,0,0
0,0,0,5,0,0,5,0,6,0,0,0,6,0,5,0,0,5,0,0,0
2,0,0,5,0,0,5,0,13,0,0,0,13,0,5,0,0,5,0,0,2
0,0,0,0,5,5,0,0,0,0,0,0,0,0,0,5,5,0,0,0,0
0,0,0,0,0,0,0,0,0,0,0,0,0,0,0,0,0,0,0,0,0
0,0,0,0,0,0,0,0,0,0,0,0,0,0,0,0,0,0,0,0,0
2,0,0,0,2,0,0,0,2,0,0,0,2,0,0,0,2,0,0,0,2
endlayer

layer
0,0,0,0,0,0,0,0,0,0,0,0,0,0,0,0,0,0,0,0,0
0,0,0,0,0,0,0,0,0,0,0,0,0,0,0,0,0,0,0,0,0
0,0,0,0,0,0,0,0,0,0,0,0,0,0,0,0,0,0,0,0,0
0,0,0,0,5,5,0,0,0,0,0,0,0,0,0,5,5,0,0,0,0
0,0,0,5,0,0,5,0,0,0,0,0,0,0,5,0,0,5,0,0,0
0,0,0,5,0,0,5,0,0,10,10,10,0,0,5,0,0,5,0,0,0
0,0,0,0,5,5,7,7,7,7,7,7,7,7,7,5,5,0,0,0,0
0,0,0,0,0,0,7,6,0,0,0,0,0,6,7,0,0,0,0,0,0
0,0,0,0,0,0,7,0,0,0,0,0,0,0,7,0,0,0,0,0,0
0,0,0,0,0,12,7,0,0,0,0,0,0,0,7,12,0,0,0,0,0
0,0,0,0,0,12,7,0,0,0,6,0,0,0,7,12,0,0,0,0,0
0,0,0,0,0,12,7,0,0,0,12,0,0,0,7,12,0,0,0,0,0
0,0,0,0,0,0,7,0,0,0,0,0,0,0,7,0,0,0,0,0,0
0,0,0,0,0,0,7,6,0,0,0,0,0,6,7,0,0,0,0,0,0
0,0,0,0,5,5,7,7,7,7,7,7,7,7,7,5,5,0,0,0,0
0,0,0,5,0,0,5,0,0,10,10,10,0,0,5,0,0,5,0,0,0
0,0,0,5,0,0,5,0,0,0,0,0,0,0,5,0,0,5,0,0,0
0,0,0,0,5,5,0,0,0,0,0,0,0,0,0,5,5,0,0,0,0
0,0,0,0,0,0,0,0,0,0,0,0,0,0,0,0,0,0,0,0,0
0,0,0,0,0,0,0,0,0,0,0,0,0,0,0,0,0,0,0,0,0
0,0,0,0,0,0,0,0,0,0,0,0,0,0,0,0,0,0,0,0,0
endlayer

layer
0,0,0,0,0,0,0,0,0,0,0,0,0,0,0,0,0,0,0,0,0
0,0,0,0,0,0,0,0,0,0,0,0,0,0,0,0,0,0,0,0,0
0,0,0,0,0,0,0,0,0,0,0,0,0,0,0,0,0,0,0,0,0
0,0,0,0,5,5,0,0,0,0,0,0,0,0,0,5,5,0,0,0,0
0,0,0,5,0,0,5,0,0,0,0,0,0,0,5,0,0,5,0,0,0
0,0,0,5,0,0,5,0,0,0,0,0,0,0,5,0,0,5,0,0,0
0,0,0,0,5,5,7,7,7,7,7,7,7,7,7,5,5,0,0,0,0
0,0,0,0,0,0,7,6,0,0,0,0,0,6,7,0,0,0,0,0,0
0,0,0,0,0,0,7,0,0,0,0,0,0,0,7,0,0,0,0,0,0
0,0,0,0,0,0,7,0,0,0,0,0,0,0,7,0,0,0,0,0,0
0,0,0,0,0,0,7,0,0,0,6,10,0,0,7,0,0,0,0,0,0
0,0,0,0,0,0,7,0,0,0,0,0,0,0,7,0,0,0,0,0,0
0,0,0,0,0,0,7,0,0,0,0,0,0,0,7,0,0,0,0,0,0
0,0,0,0,0,0,7,6,0,0,0,0,0,6,7,0,0,0,0,0,0
0,0,0,0,5,5,7,7,7,7,7,7,7,7,7,5,5,0,0,0,0
0,0,0,5,0,0,5,0,0,0,0,0,0,0,5,0,0,5,0,0,0
0,0,0,5,0,0,5,0,0,0,0,0,0,0,5,0,0,5,0,0,0
0,0,0,0,5,5,0,0,0,0,0,0,0,0,0,5,5,0,0,0,0
0,0,0,0,0,0,0,0,0,0,0,0,0,0,0,0,0,0,0,0,0
0,0,0,0,0,0,0,0,0,0,0,0,0,0,0,0,0,0,0,0,0
0,0,0,0,0,0,0,0,0,0,0,0,0,0,0,0,0,0,0,0,0
endlayer

layer
0,0,0,0,0,0,0,0,0,0,0,0,0,0,0,0,0,0,0,0,0
0,0,0,0,0,0,0,0,0,0,0,0,0,0,0,0,0,0,0,0,0
0,0,0,0,0,0,0,0,0,0,0,0,0,0,0,0,0,0,0,0,0
0,0,0,0,5,5,0,0,0,0,0,0,0,0,0,5,5,0,0,0,0
0,0,0,5,0,0,5,0,0,0,0,0,0,0,5,0,0,5,0,0,0
0,0,0,5,0,0,5,10,10,10,10,10,10,10,5,0,0,5,0,0,0
0,0,0,0,5,5,7,7,7,7,7,7,7,7,7,5,5,0,0,0,0
0,0,0,0,0,12,7,7,7,7,7,7,7,7,7,12,0,0,0,0,0
0,0,0,0,0,12,7,7,7,7,7,7,7,7,7,12,0,0,0,0,0
0,0,0,0,0,12,7,7,7,0,7,7,7,7,7,12,0,0,0,0,0
0,0,0,0,0,12,7,7,7,0,6,0,7,7,7,12,0,0,0,0,0
0,0,0,0,0,12,7,7,7,0,0,0,7,7,7,12,0,0,0,0,0
0,0,0,0,0,12,7,7,7,7,7,7,7,7,7,12,0,0,0,0,0
0,0,0,0,0,12,7,7,7,7,7,7,7,7,7,12,0,0,0,0,0
0,0,0,0,5,5,7,7,7,7,7,7,7,7,6,5,5,0,0,0,0
0,0,0,5,0,0,5,10,10,10,10,10,10,10,5,0,0,5,0,0,0
0,0,0,5,0,0,5,0,0,0,0,0,0,0,5,0,0,5,0,0,0
0,0,0,0,5,5,0,0,0,0,0,0,0,0,0,5,5,0,0,0,0
0,0,0,0,0,0,0,0,0,0,0,0,0,0,0,0,0,0,0,0,0
0,0,0,0,0,0,0,0,0,0,0,0,0,0,0,0,0,0,0,0,0
0,0,0,0,0,0,0,0,0,0,0,0,0,0,0,0,0,0,0,0,0
endlayer

layer
0,0,0,0,0,0,0,0,0,0,0,0,0,0,0,0,0,0,0,0,0
0,0,0,0,0,0,0,0,0,0,0,0,0,0,0,0,0,0,0,0,0
0,0,0,0,0,0,0,0,0,0,0,0,0,0,0,0,0,0,0,0,0
0,0,0,0,5,5,0,0,5,5,5,5,5,0,0,5,5,0,0,0,0
0,0,0,5,0,0,5,0,5,5,5,5,5,0,5,0,0,5,0,0,0
0,0,0,5,0,0,5,7,7,7,7,7,7,7,5,0,0,5,0,0,0
0,0,0,0,5,5,6,0,0,0,0,0,0,0,6,5,5,0,0,0,0
0,0,0,0,0,7,0,0,0,0,0,0,0,0,0,7,0,0,0,0,0
0,0,0,0,0,7,0,0,0,0,0,0,0,0,0,7,0,0,0,0,0
0,0,0,0,0,7,0,0,0,0,0,0,0,0,0,7,0,0,0,0,0
0,0,0,0,0,7,0,0,0,0,6,0,0,0,0,7,0,0,0,0,0
0,0,0,0,0,7,0,0,0,0,0,0,0,0,0,7,0,0,0,0,0
0,0,0,0,0,7,0,0,0,0,0,0,0,0,0,7,0,0,0,0,0
0,0,0,0,0,7,0,0,0,0,0,0,0,0,0,7,0,0,0,0,0
0,0,0,0,5,5,6,0,0,0,0,0,0,0,6,5,5,0,0,0,0
0,0,0,5,0,0,5,7,7,7,7,7,7,7,5,0,0,5,0,0,0
0,0,0,5,0,0,5,0,5,5,5,5,5,0,5,0,0,5,0,0,0
0,0,0,0,5,5,0,0,5,5,5,5,5,0,0,5,5,0,0,0,0
0,0,0,0,0,0,0,0,0,0,0,0,0,0,0,0,0,0,0,0,0
0,0,0,0,0,0,0,0,0,0,0,0,0,0,0,0,0,0,0,0,0
0,0,0,0,0,0,0,0,0,0,0,0,0,0,0,0,0,0,0,0,0
endlayer

layer
0,0,0,0,0,0,0,0,0,0,0,0,0,0,0,0,0,0,0,0,0
0,0,0,0,0,0,0,0,0,0,0,0,0,0,0,0,0,0,0,0,0
0,0,0,0,0,0,0,0,0,0,0,0,0,0,0,0,0,0,0,0,0
0,0,0,0,5,5,0,0,6,0,0,0,6,0,0,5,5,0,0,0,0
0,0,0,5,0,0,5,0,0,0,0,0,0,0,5,0,0,5,0,0,0
0,0,0,5,0,0,5,7,7,0,0,0,7,7,5,0,0,5,0,0,0
0,0,0,0,5,5,6,0,0,0,0,0,0,0,6,5,5,0,0,0,0
0,0,0,0,0,7,0,0,0,0,0,0,0,0,0,7,0,0,0,0,0
0,0,0,0,0,7,0,0,0,0,0,0,0,0,0,7,0,0,0,0,0
0,0,0,0,0,7,0,0,0,0,0,0,0,0,0,7,0,0,0,0,0
0,0,0,0,0,7,0,0,0,0,6,0,0,0,0,7,0,0,0,0,0
0,0,0,0,0,7,0,0,0,0,0,0,0,0,0,7,0,0,0,0,0
0,0,0,0,0,7,0,0,0,0,0,0,0,0,0,7,0,0,0,0,0
0,0,0,0,0,7,0,0,0,0,0,0,0,0,0,7,0,0,0,0,0
0,0,0,0,5,5,6,0,0,0,0,0,0,0,6,5,5,0,0,0,0
0,0,0,5,0,0,5,7,7,0,0,0,7,7,5,0,0,5,0,0,0
0,0,0,5,0,0,5,0,0,0,0,0,0,0,5,0,0,5,0,0,0
0,0,0,0,5,5,0,0,6,0,0,0,6,0,0,5,5,0,0,0,0
0,0,0,0,0,0,0,0,0,0,0,0,0,0,0,0,0,0,0,0,0
0,0,0,0,0,0,0,0,0,0,0,0,0,0,0,0,0,0,0,0,0
0,0,0,0,0,0,0,0,0,0,0,0,0,0,0,0,0,0,0,0,0
endlayer

layer
0,0,0,0,0,0,0,0,0,0,0,0,0,0,0,0,0,0,0,0,0
0,0,0,0,0,0,0,0,0,0,0,0,0,0,0,0,0,0,0,0,0
0,0,0,0,0,0,0,0,0,0,0,0,0,0,0,0,0,0,0,0,0
0,0,0,0,5,5,0,0,6,14,14,14,6,0,0,5,5,0,0,0,0
0,0,0,5,0,0,5,0,15,0,0,0,15,0,5,0,0,5,0,0,0
0,0,0,5,0,0,5,7,7,16,0,16,7,7,5,0,0,5,0,0,0
0,0,0,0,5,5,6,0,0,0,0,0,0,0,6,5,5,0,0,0,0
0,0,0,0,0,7,0,0,0,0,0,0,0,0,0,7,0,0,0,0,0
0,0,0,0,0,7,0,0,0,0,0,0,0,0,0,7,0,0,0,0,0
0,0,0,0,0,16,0,0,0,0,0,0,0,0,0,16,0,0,0,0,0
0,0,0,0,0,16,0,0,0,0,6,0,0,0,0,16,0,0,0,0,0
0,0,0,0,0,16,0,0,0,0,0,0,0,0,0,16,0,0,0,0,0
0,0,0,0,0,7,0,0,0,0,0,0,0,0,0,7,0,0,0,0,0
0,0,0,0,0,7,0,0,0,0,0,0,0,0,0,7,0,0,0,0,0
0,0,0,0,5,5,6,0,0,0,0,0,0,0,6,5,5,0,0,0,0
0,0,0,5,0,0,5,7,7,16,0,16,7,7,5,0,0,5,0,0,0
0,0,0,5,0,0,5,0,15,0,0,0,15,0,5,0,0,5,0,0,0
0,0,0,0,5,5,0,0,6,14,14,14,6,0,0,5,5,0,0,0,0
0,0,0,0,0,0,0,0,0,0,0,0,0,0,0,0,0,0,0,0,0
0,0,0,0,0,0,0,0,0,0,0,0,0,0,0,0,0,0,0,0,0
0,0,0,0,0,0,0,0,0,0,0,0,0,0,0,0,0,0,0,0,0
endlayer

layer
0,0,0,0,0,0,0,0,0,0,0,0,0,0,0,0,0,0,0,0,0
0,0,0,0,0,0,0,0,0,0,0,0,0,0,0,0,0,0,0,0,0
0,0,0,0,0,0,0,0,13,0,0,0,13,0,0,0,0,0,0,0,0
0,0,0,0,5,5,0,0,6,0,0,0,6,0,0,5,5,0,0,0,0
0,0,0,5,0,0,5,0,0,0,0,0,0,0,5,0,0,5,0,0,0
0,0,0,5,0,0,5,7,7,16,16,16,7,7,5,0,0,5,0,0,0
0,0,0,0,5,5,6,0,0,0,0,0,0,0,6,5,5,0,0,0,0
0,0,0,0,0,7,0,0,0,0,0,0,0,0,0,7,0,0,0,0,0
0,0,0,0,0,7,0,0,0,0,0,0,0,0,0,7,0,0,0,0,0
0,0,0,0,0,16,0,0,0,0,0,0,0,0,0,16,0,0,0,0,0
0,0,0,0,0,16,0,0,0,0,17,0,0,0,0,16,0,0,0,0,0
0,0,0,0,0,16,0,0,0,0,0,0,0,0,0,16,0,0,0,0,0
0,0,0,0,0,7,0,0,0,0,0,0,0,0,0,7,0,0,0,0,0
0,0,0,0,0,7,0,0,0,0,0,0,0,0,0,7,0,0,0,0,0
0,0,0,0,5,5,6,0,0,0,0,0,0,0,6,5,5,0,0,0,0
0,0,0,5,0,0,5,7,7,16,16,16,7,7,5,0,0,5,0,0,0
0,0,0,5,0,0,5,0,0,0,0,0,0,0,5,0,0,5,0,0,0
0,0,0,0,5,5,0,0,6,0,0,0,6,0,0,5,5,0,0,0,0
0,0,0,0,0,0,0,0,13,0,0,0,13,0,0,0,0,0,0,0,0
0,0,0,0,0,0,0,0,0,0,0,0,0,0,0,0,0,0,0,0,0
0,0,0,0,0,0,0,0,0,0,0,0,0,0,0,0,0,0,0,0,0
endlayer

layer
0,0,0,0,0,0,0,0,0,0,0,0,0,0,0,0,0,0,0,0,0
0,0,0,0,0,0,0,0,0,0,0,0,0,0,0,0,0,0,0,0,0
0,0,0,0,0,0,0,0,0,0,0,0,0,0,0,0,0,0,0,0,0
0,0,0,0,5,5,0,0,6,0,0,0,6,0,0,5,5,0,0,0,0
0,0,0,5,0,0,5,0,0,0,0,0,0,0,5,0,0,5,0,0,0
0,0,0,5,0,0,5,7,7,7,7,7,7,7,5,0,0,5,0,0,0
0,0,0,0,5,5,6,0,0,0,0,0,0,0,6,5,5,0,0,0,0
0,0,0,0,0,7,0,0,0,0,0,0,0,0,0,7,0,0,0,0,0
0,0,0,0,0,7,0,0,0,0,0,0,0,0,0,7,0,0,0,0,0
0,0,0,0,0,7,0,0,0,0,0,0,0,0,0,7,0,0,0,0,0
0,0,0,0,0,7,0,0,0,0,18,0,0,0,0,7,0,0,0,0,0
0,0,0,0,0,7,0,0,0,0,0,0,0,0,0,7,0,0,0,0,0
0,0,0,0,0,7,0,0,0,0,0,0,0,0,0,7,0,0,0,0,0
0,0,0,0,0,7,0,0,0,0,0,0,0,0,0,7,0,0,0,0,0
0,0,0,0,5,5,6,0,0,0,0,0,0,0,6,5,5,0,0,0,0
0,0,0,5,0,0,5,7,7,7,7,7,7,7,5,0,0,5,0,0,0
0,0,0,5,0,0,5,0,0,0,0,0,0,0,5,0,0,5,0,0,0
0,0,0,0,5,5,0,0,6,0,0,0,6,0,0,5,5,0,0,0,0
0,0,0,0,0,0,0,0,0,0,0,0,0,0,0,0,0,0,0,0,0
0,0,0,0,0,0,0,0,0,0,0,0,0,0,0,0,0,0,0,0,0
0,0,0,0,0,0,0,0,0,0,0,0,0,0,0,0,0,0,0,0,0
endlayer

layer
0,0,0,0,0,0,0,0,0,0,0,0,0,0,0,0,0,0,0,0,0
0,0,0,0,0,0,0,0,0,0,0,0,0,0,0,0,0,0,0,0,0
0,0,0,0,0,0,0,0,19,19,19,19,19,0,0,0,0,0,0,0,0
0,0,0,0,5,5,0,0,5,0,0,0,5,0,0,5,5,0,0,0,0
0,0,0,5,0,0,5,0,5,0,0,0,5,0,5,0,0,5,0,0,0
0,0,0,5,0,0,5,7,7,7,7,7,7,7,5,0,0,5,0,0,0
0,0,0,0,5,5,6,0,5,0,0,0,5,0,6,5,5,0,0,0,0
0,0,0,0,19,7,0,0,5,0,0,0,5,0,0,7,19,0,0,0,0
0,0,0,0,19,7,0,0,5,0,0,0,5,0,0,7,19,0,0,0,0
0,0,0,0,19,7,0,0,5,0,0,0,5,0,0,7,19,0,0,0,0
0,0,0,0,19,7,0,0,5,0,0,0,5,0,0,7,19,0,0,0,0
0,0,0,0,19,7,0,0,5,0,0,0,5,0,0,7,19,0,0,0,0
0,0,0,0,19,7,0,0,5,0,0,0,5,0,0,7,19,0,0,0,0
0,0,0,0,19,7,0,0,5,0,0,0,5,0,0,7,19,0,0,0,0
0,0,0,0,5,5,6,0,5,0,0,0,5,0,6,5,5,0,0,0,0
0,0,0,5,0,0,5,7,7,7,7,7,7,7,5,0,0,5,0,0,0
0,0,0,5,0,0,5,0,5,0,0,0,5,0,5,0,0,5,0,0,0
0,0,0,0,5,5,0,0,5,0,0,0,5,0,0,5,5,0,0,0,0
0,0,0,0,0,0,0,0,19,19,19,19,19,0,0,0,0,0,0,0,0
0,0,0,0,0,0,0,0,0,0,0,0,0,0,0,0,0,0,0,0,0
0,0,0,0,0,0,0,0,0,0,0,0,0,0,0,0,0,0,0,0,0
endlayer

layer
0,0,0,0,0,0,0,0,0,0,0,0,0,0,0,0,0,0,0,0,0
0,0,0,0,0,0,0,0,0,0,0,0,0,0,0,0,0,0,0,0,0
0,0,0,0,0,0,0,0,0,0,0,0,0,0,0,0,0,0,0,0,0
0,0,0,0,5,5,0,0,19,19,19,19,19,0,0,5,5,0,0,0,0
0,0,0,5,0,0,5,0,19,19,19,19,19,0,5,0,0,5,0,0,0
0,0,0,5,0,0,5,19,0,0,0,0,0,19,5,0,0,5,0,0,0
0,0,0,0,5,5,6,0,0,0,0,0,0,0,6,5,5,0,0,0,0
0,0,0,0,0,19,0,0,0,0,0,0,0,0,0,19,0,0,0,0,0
0,0,0,0,0,19,0,0,0,0,0,0,0,0,0,19,0,0,0,0,0
0,0,0,0,0,19,0,0,0,0,0,0,0,0,0,19,0,0,0,0,0
0,0,0,0,0,19,0,0,0,0,0,0,0,0,0,19,0,0,0,0,0
0,0,0,0,0,19,0,0,0,0,0,0,0,0,0,19,0,0,0,0,0
0,0,0,0,0,19,0,0,0,0,0,0,0,0,0,19,0,0,0,0,0
0,0,0,0,0,19,0,0,0,0,0,0,0,0,0,19,0,0,0,0,0
0,0,0,0,5,5,6,0,0,0,0,0,0,0,6,5,5,0,0,0,0
0,0,0,5,0,0,5,19,0,0,0,0,0,19,5,0,0,5,0,0,0
0,0,0,5,0,0,5,0,19,19,19,19,19,0,5,0,0,5,0,0,0
0,0,0,0,5,5,0,0,19,19,19,19,19,0,0,5,5,0,0,0,0
0,0,0,0,0,0,0,0,0,0,0,0,0,0,0,0,0,0,0,0,0
0,0,0,0,0,0,0,0,0,0,0,0,0,0,0,0,0,0,0,0,0
0,0,0,0,0,0,0,0,0,0,0,0,0,0,0,0,0,0,0,0,0
endlayer

layer
0,0,0,0,0,0,0,0,0,0,0,0,0,0,0,0,0,0,0,0,0
0,0,0,0,0,0,0,0,0,0,0,0,0,0,0,0,0,0,0,0,0
0,0,0,0,0,0,0,0,0,0,0,0,0,0,0,0,0,0,0,0,0
0,0,0,0,5,5,0,0,0,0,0,0,0,0,0,5,5,0,0,0,0
0,0,0,5,0,0,5,0,0,0,0,0,0,0,5,0,0,5,0,0,0
0,0,0,5,0,0,5,0,19,19,19,19,19,0,5,0,0,5,0,0,0
0,0,0,0,5,5,19,19,0,0,0,0,0,19,19,5,5,0,0,0,0
0,0,0,0,0,0,19,0,0,0,0,0,0,0,19,0,0,0,0,0,0
0,0,0,0,0,0,19,0,0,0,0,0,0,0,19,0,0,0,0,0,0
0,0,0,0,0,0,19,0,0,0,0,0,0,0,19,0,0,0,0,0,0
0,0,0,0,0,0,19,0,0,0,0,0,0,0,19,0,0,0,0,0,0
0,0,0,0,0,0,19,0,0,0,0,0,0,0,19,0,0,0,0,0,0
0,0,0,0,0,0,19,0,0,0,0,0,0,0,19,0,0,0,0,0,0
0,0,0,0,0,0,19,0,0,0,0,0,0,0,19,0,0,0,0,0,0
0,0,0,0,5,5,19,19,0,0,0,0,0,19,19,5,5,0,0,0,0
0,0,0,5,0,0,5,0,19,19,19,19,19,0,5,0,0,5,0,0,0
0,0,0,5,0,0,5,0,0,0,0,0,0,0,5,0,0,5,0,0,0
0,0,0,0,5,5,0,0,0,0,0,0,0,0,0,5,5,0,0,0,0
0,0,0,0,0,0,0,0,0,0,0,0,0,0,0,0,0,0,0,0,0
0,0,0,0,0,0,0,0,0,0,0,0,0,0,0,0,0,0,0,0,0
0,0,0,0,0,0,0,0,0,0,0,0,0,0,0,0,0,0,0,0,0
endlayer

layer
0,0,0,0,0,0,0,0,0,0,0,0,0,0,0,0,0,0,0,0,0
0,0,0,0,0,0,0,0,0,0,0,0,0,0,0,0,0,0,0,0,0
0,0,0,0,0,0,0,0,0,0,0,0,0,0,0,0,0,0,0,0,0
0,0,0,0,5,5,0,0,0,0,0,0,0,0,0,5,5,0,0,0,0
0,0,0,5,0,0,5,0,0,0,0,0,0,0,5,0,0,5,0,0,0
0,0,0,5,0,0,5,0,0,0,0,0,0,0,5,0,0,5,0,0,0
0,0,0,0,5,5,0,0,19,19,19,19,19,0,0,5,5,0,0,0,0
0,0,0,0,0,0,0,19,0,0,0,0,0,19,0,0,0,0,0,0,0
0,0,0,0,0,0,0,19,0,0,0,0,0,19,0,0,0,0,0,0,0
0,0,0,0,0,0,0,19,0,0,0,0,0,19,0,0,0,0,0,0,0
0,0,0,0,0,0,0,19,0,0,0,0,0,19,0,0,0,0,0,0,0
0,0,0,0,0,0,0,19,0,0,0,0,0,19,0,0,0,0,0,0,0
0,0,0,0,0,0,0,19,0,0,0,0,0,19,0,0,0,0,0,0,0
0,0,0,0,0,0,0,19,0,0,0,0,0,19,0,0,0,0,0,0,0
0,0,0,0,5,5,0,0,19,19,19,19,19,0,0,5,5,0,0,0,0
0,0,0,5,0,0,5,0,0,0,0,0,0,0,5,0,0,5,0,0,0
0,0,0,5,0,0,5,0,0,0,0,0,0,0,5,0,0,5,0,0,0
0,0,0,0,5,5,0,0,0,0,0,0,0,0,0,5,5,0,0,0,0
0,0,0,0,0,0,0,0,0,0,0,0,0,0,0,0,0,0,0,0,0
0,0,0,0,0,0,0,0,0,0,0,0,0,0,0,0,0,0,0,0,0
0,0,0,0,0,0,0,0,0,0,0,0,0,0,0,0,0,0,0,0,0
endlayer

layer
0,0,0,0,0,0,0,0,0,0,0,0,0,0,0,0,0,0,0,0,0
0,0,0,0,0,0,0,0,0,0,0,0,0,0,0,0,0,0,0,0,0
0,0,0,0,0,0,0,0,0,0,0,0,0,0,0,0,0,0,0,0,0
0,0,0,0,5,5,0,0,0,0,0,0,0,0,0,5,5,0,0,0,0
0,0,0,5,0,0,5,0,0,0,0,0,0,0,5,0,0,5,0,0,0
0,0,0,5,0,0,5,0,0,0,0,0,0,0,5,0,0,5,0,0,0
0,0,0,0,5,5,0,0,0,0,0,0,0,0,0,5,5,0,0,0,0
0,0,0,0,0,0,0,0,19,19,19,19,19,0,0,0,0,0,0,0,0
0,0,0,0,0,0,0,0,19,0,0,0,19,0,0,0,0,0,0,0,0
0,0,0,0,0,0,0,0,19,0,0,0,19,0,0,0,0,0,0,0,0
0,0,0,0,0,0,0,0,19,0,0,0,19,0,0,0,0,0,0,0,0
0,0,0,0,0,0,0,0,19,0,0,0,19,0,0,0,0,0,0,0,0
0,0,0,0,0,0,0,0,19,0,0,0,19,0,0,0,0,0,0,0,0
0,0,0,0,0,0,0,0,19,19,19,19,19,0,0,0,0,0,0,0,0
0,0,0,0,5,5,0,0,0,0,0,0,0,0,0,5,5,0,0,0,0
0,0,0,5,0,0,5,0,0,0,0,0,0,0,5,0,0,5,0,0,0
0,0,0,5,0,0,5,0,0,0,0,0,0,0,5,0,0,5,0,0,0
0,0,0,0,5,5,0,0,0,0,0,0,0,0,0,5,5,0,0,0,0
0,0,0,0,0,0,0,0,0,0,0,0,0,0,0,0,0,0,0,0,0
0,0,0,0,0,0,0,0,0,0,0,0,0,0,0,0,0,0,0,0,0
0,0,0,0,0,0,0,0,0,0,0,0,0,0,0,0,0,0,0,0,0
endlayer

layer
0,0,0,0,0,0,0,0,0,0,0,0,0,0,0,0,0,0,0,0,0
0,0,0,0,0,0,0,0,0,0,0,0,0,0,0,0,0,0,0,0,0
0,0,0,0,0,0,0,0,0,0,0,0,0,0,0,19,19,0,0,0,0
0,0,0,0,5,5,0,0,0,0,0,0,0,0,19,5,5,19,0,0,0
0,0,0,5,0,0,5,0,0,0,0,0,0,19,5,0,0,5,19,0,0
0,0,0,5,0,0,5,0,0,0,0,0,0,19,5,0,0,5,19,0,0
0,0,0,0,5,5,0,0,0,0,0,0,0,0,19,5,5,19,0,0,0
0,0,0,0,0,0,0,0,0,0,0,0,0,0,0,19,19,0,0,0,0
0,0,0,0,0,0,0,0,0,19,19,19,0,0,0,0,0,0,0,0,0
0,0,0,0,0,0,0,0,0,19,0,19,0,0,0,0,0,0,0,0,0
0,0,0,0,0,0,0,0,0,19,0,19,0,0,0,0,0,0,0,0,0
0,0,0,0,0,0,0,0,0,19,0,19,0,0,0,0,0,0,0,0,0
0,0,0,0,0,0,0,0,0,19,19,19,0,0,0,0,0,0,0,0,0
0,0,0,0,0,0,0,0,0,0,0,0,0,0,0,0,0,0,0,0,0
0,0,0,0,5,5,0,0,0,0,0,0,0,0,0,5,5,0,0,0,0
0,0,0,5,0,0,5,0,0,0,0,0,0,0,5,0,0,5,0,0,0
0,0,0,5,0,0,5,0,0,0,0,0,0,0,5,0,0,5,0,0,0
0,0,0,0,5,5,0,0,0,0,0,0,0,0,0,5,5,0,0,0,0
0,0,0,0,0,0,0,0,0,0,0,0,0,0,0,0,0,0,0,0,0
0,0,0,0,0,0,0,0,0,0,0,0,0,0,0,0,0,0,0,0,0
0,0,0,0,0,0,0,0,0,0,0,0,0,0,0,0,0,0,0,0,0
endlayer

layer
0,0,0,0,0,0,0,0,0,0,0,0,0,0,0,0,0,0,0,0,0
0,0,0,0,0,0,0,0,0,0,0,0,0,0,0,0,0,0,0,0,0
0,0,0,0,19,19,0,0,0,0,0,0,0,0,0,0,0,0,0,0,0
0,0,0,19,5,5,19,0,0,0,0,0,0,0,0,19,19,0,0,0,0
0,0,19,5,0,0,5,19,0,0,0,0,0,0,19,0,0,19,0,0,0
0,0,19,5,0,0,5,19,0,0,0,0,0,0,19,0,0,19,0,0,0
0,0,0,19,5,5,19,0,0,0,0,0,0,0,0,19,19,0,0,0,0
0,0,0,0,19,19,0,0,0,0,0,0,0,0,0,0,0,0,0,0,0
0,0,0,0,0,0,0,0,0,0,0,0,0,0,0,0,0,0,0,0,0
0,0,0,0,0,0,0,0,0,0,19,0,0,0,0,0,0,0,0,0,0
0,0,0,0,0,0,0,0,0,0,19,0,0,0,0,0,0,0,0,0,0
0,0,0,0,0,0,0,0,0,0,19,0,0,0,0,0,0,0,0,0,0
0,0,0,0,0,0,0,0,0,0,0,0,0,0,0,0,0,0,0,0,0
0,0,0,0,0,0,0,0,0,0,0,0,0,0,0,0,0,0,0,0,0
0,0,0,0,5,5,0,0,0,0,0,0,0,0,0,5,5,0,0,0,0
0,0,0,5,0,0,5,0,0,0,0,0,0,0,5,0,0,20,0,0,0
0,0,0,5,0,0,5,0,0,0,0,0,0,0,5,0,0,5,0,0,0
0,0,0,0,5,5,0,0,0,0,0,0,0,0,0,5,5,0,0,0,0
0,0,0,0,0,0,0,0,0,0,0,0,0,0,0,0,0,0,0,0,0
0,0,0,0,0,0,0,0,0,0,0,0,0,0,0,0,0,0,0,0,0
0,0,0,0,0,0,0,0,0,0,0,0,0,0,0,0,0,0,0,0,0
endlayer

layer
0,0,0,0,0,0,0,0,0,0,0,0,0,0,0,0,0,0,0,0,0
0,0,0,0,0,0,0,0,0,0,0,0,0,0,0,0,0,0,0,0,0
0,0,0,0,0,0,0,0,0,0,0,0,0,0,0,0,0,0,0,0,0
0,0,0,0,19,19,0,0,0,0,0,0,0,0,0,0,0,0,0,0,0
0,0,0,19,0,0,19,0,0,0,0,0,0,0,0,19,19,0,0,0,0
0,0,0,19,0,0,19,0,0,0,0,0,0,0,0,19,19,0,0,0,0
0,0,0,0,19,19,0,0,0,0,0,0,0,0,0,0,0,0,0,0,0
0,0,0,0,0,0,0,0,0,0,0,0,0,0,0,0,0,0,0,0,0
0,0,0,0,0,0,0,0,0,0,0,0,0,0,0,0,0,0,0,0,0
0,0,0,0,0,0,0,0,0,0,0,0,0,0,0,0,0,0,0,0,0
0,0,0,0,0,0,0,0,0,0,0,0,0,0,0,0,0,0,0,0,0
0,0,0,0,0,0,0,0,0,0,0,0,0,0,0,0,0,0,0,0,0
0,0,0,0,0,0,0,0,0,0,0,0,0,0,0,0,0,0,0,0,0
0,0,0,0,19,19,0,0,0,0,0,0,0,0,0,0,0,0,0,0,0
0,0,0,19,5,5,19,0,0,0,0,0,0,0,0,5,5,0,0,0,0
0,0,19,5,0,0,5,19,0,0,0,0,0,0,5,0,0,5,0,0,0
0,0,19,5,0,0,5,19,0,0,0,0,0,0,5,0,0,5,0,0,0
0,0,0,19,5,5,19,0,0,0,0,0,0,0,0,5,5,0,0,0,0
0,0,0,0,19,19,0,0,0,0,0,0,0,0,0,0,0,0,0,0,0
0,0,0,0,0,0,0,0,0,0,0,0,0,0,0,0,0,0,0,0,0
0,0,0,0,0,0,0,0,0,0,0,0,0,0,0,0,0,0,0,0,0
endlayer

layer
0,0,0,0,0,0,0,0,0,0,0,0,0,0,0,0,0,0,0,0,0
0,0,0,0,0,0,0,0,0,0,0,0,0,0,0,0,0,0,0,0,0
0,0,0,0,0,0,0,0,0,0,0,0,0,0,0,0,0,0,0,0,0
0,0,0,0,0,0,0,0,0,0,0,0,0,0,0,0,0,0,0,0,0
0,0,0,0,19,19,0,0,0,0,0,0,0,0,0,0,0,0,0,0,0
0,0,0,0,19,19,0,0,0,0,0,0,0,0,0,0,0,0,0,0,0
0,0,0,0,0,0,0,0,0,0,0,0,0,0,0,0,0,0,0,0,0
0,0,0,0,0,0,0,0,0,0,0,0,0,0,0,0,0,0,0,0,0
0,0,0,0,0,0,0,0,0,0,0,0,0,0,0,0,0,0,0,0,0
0,0,0,0,0,0,0,0,0,0,0,0,0,0,0,0,0,0,0,0,0
0,0,0,0,0,0,0,0,0,0,0,0,0,0,0,0,0,0,0,0,0
0,0,0,0,0,0,0,0,0,0,0,0,0,0,0,0,0,0,0,0,0
0,0,0,0,0,0,0,0,0,0,0,0,0,0,0,0,0,0,0,0,0
0,0,0,0,0,0,0,0,0,0,0,0,0,0,0,19,19,0,0,0,0
0,0,0,0,19,19,0,0,0,0,0,0,0,0,19,5,5,19,0,0,0
0,0,0,19,0,0,19,0,0,0,0,0,0,19,5,0,0,5,19,0,0
0,0,0,19,0,0,19,0,0,0,0,0,0,19,5,0,0,5,19,0,0
0,0,0,0,19,19,0,0,0,0,0,0,0,0,19,5,5,19,0,0,0
0,0,0,0,0,0,0,0,0,0,0,0,0,0,0,19,19,0,0,0,0
0,0,0,0,0,0,0,0,0,0,0,0,0,0,0,0,0,0,0,0,0
0,0,0,0,0,0,0,0,0,0,0,0,0,0,0,0,0,0,0,0,0
endlayer

layer
0,0,0,0,0,0,0,0,0,0,0,0,0,0,0,0,0,0,0,0,0
0,0,0,0,0,0,0,0,0,0,0,0,0,0,0,0,0,0,0,0,0
0,0,0,0,0,0,0,0,0,0,0,0,0,0,0,0,0,0,0,0,0
0,0,0,0,0,0,0,0,0,0,0,0,0,0,0,0,0,0,0,0,0
0,0,0,0,0,0,0,0,0,0,0,0,0,0,0,0,0,0,0,0,0
0,0,0,0,0,0,0,0,0,0,0,0,0,0,0,0,0,0,0,0,0
0,0,0,0,0,0,0,0,0,0,0,0,0,0,0,0,0,0,0,0,0
0,0,0,0,0,0,0,0,0,0,0,0,0,0,0,0,0,0,0,0,0
0,0,0,0,0,0,0,0,0,0,0,0,0,0,0,0,0,0,0,0,0
0,0,0,0,0,0,0,0,0,0,0,0,0,0,0,0,0,0,0,0,0
0,0,0,0,0,0,0,0,0,0,0,0,0,0,0,0,0,0,0,0,0
0,0,0,0,0,0,0,0,0,0,0,0,0,0,0,0,0,0,0,0,0
0,0,0,0,0,0,0,0,0,0,0,0,0,0,0,0,0,0,0,0,0
0,0,0,0,0,0,0,0,0,0,0,0,0,0,0,0,0,0,0,0,0
0,0,0,0,0,0,0,0,0,0,0,0,0,0,0,19,19,0,0,0,0
0,0,0,0,19,19,0,0,0,0,0,0,0,0,19,0,0,19,0,0,0
0,0,0,0,19,19,0,0,0,0,0,0,0,0,19,0,0,19,0,0,0
0,0,0,0,0,0,0,0,0,0,0,0,0,0,0,19,19,0,0,0,0
0,0,0,0,0,0,0,0,0,0,0,0,0,0,0,0,0,0,0,0,0
0,0,0,0,0,0,0,0,0,0,0,0,0,0,0,0,0,0,0,0,0
0,0,0,0,0,0,0,0,0,0,0,0,0,0,0,0,0,0,0,0,0
endlayer

layer
0,0,0,0,0,0,0,0,0,0,0,0,0,0,0,0,0,0,0,0,0
0,0,0,0,0,0,0,0,0,0,0,0,0,0,0,0,0,0,0,0,0
0,0,0,0,0,0,0,0,0,0,0,0,0,0,0,0,0,0,0,0,0
0,0,0,0,0,0,0,0,0,0,0,0,0,0,0,0,0,0,0,0,0
0,0,0,0,0,0,0,0,0,0,0,0,0,0,0,0,0,0,0,0,0
0,0,0,0,0,0,0,0,0,0,0,0,0,0,0,0,0,0,0,0,0
0,0,0,0,0,0,0,0,0,0,0,0,0,0,0,0,0,0,0,0,0
0,0,0,0,0,0,0,0,0,0,0,0,0,0,0,0,0,0,0,0,0
0,0,0,0,0,0,0,0,0,0,0,0,0,0,0,0,0,0,0,0,0
0,0,0,0,0,0,0,0,0,0,0,0,0,0,0,0,0,0,0,0,0
0,0,0,0,0,0,0,0,0,0,0,0,0,0,0,0,0,0,0,0,0
0,0,0,0,0,0,0,0,0,0,0,0,0,0,0,0,0,0,0,0,0
0,0,0,0,0,0,0,0,0,0,0,0,0,0,0,0,0,0,0,0,0
0,0,0,0,0,0,0,0,0,0,0,0,0,0,0,0,0,0,0,0,0
0,0,0,0,0,0,0,0,0,0,0,0,0,0,0,0,0,0,0,0,0
0,0,0,0,0,0,0,0,0,0,0,0,0,0,0,19,19,0,0,0,0
0,0,0,0,0,0,0,0,0,0,0,0,0,0,0,19,19,0,0,0,0
0,0,0,0,0,0,0,0,0,0,0,0,0,0,0,0,0,0,0,0,0
0,0,0,0,0,0,0,0,0,0,0,0,0,0,0,0,0,0,0,0,0
0,0,0,0,0,0,0,0,0,0,0,0,0,0,0,0,0,0,0,0,0
0,0,0,0,0,0,0,0,0,0,0,0,0,0,0,0,0,0,0,0,0
endlayer

