
# Created by Ruins mod version 14.7 Ingame Parser
# authoring Player: OneWolfe

weight=6
unique=1
embed_into_distance=1
biomesToSpawnIn=plains,rolling hills,forest,high hills,swamp
acceptable_target_blocks=
unacceptable_target_blocks=flowing_water,water,flowing_lava,lava
dimensions=50,21,11
allowable_overhang=12
max_leveling=8
leveling_buffer=0
preserve_water=0
preserve_lava=0

rule1=0,100,preserveBlock
rule2=0,100,terrafirmacraft:StoneIgExSmooth-3
rule3=0,100,air,terrafirmacraft:StoneIgExBrick-3,terrafirmacraft:StoneIgExBrick-3,terrafirmacraft:StoneIgExBrick-3,terrafirmacraft:StoneIgExSmooth-3,terrafirmacraft:StoneIgEx-3
rule4=0,100,terrafirmacraft:StoneSed-5,terrafirmacraft:StoneIgExSmooth-3
rule5=0,100,air,MobSpawner:skeletonTFC
rule6=0,100,terrafirmacraft:StoneSedBrick-5
rule7=0,100,terrafirmacraft:StoneMMSmooth-5
rule8=0,100,terrafirmacraft:StoneIgEx-3
rule9=0,100,terrafirmacraft:WoodSupportV-1
rule10=0,100,air,minecraft:iron_bars-0,minecraft:iron_bars-0,minecraft:iron_bars-0
rule11=0,100,air,Railcraft:lantern.stone-4,Railcraft:lantern.stone-1
rule12=0,100,terrafirmacraft:WoodSupportH-1
rule13=0,100,air,terrafirmacraft:planks-1,terrafirmacraft:planks-1,terrafirmacraft:planks-1
rule14=0,100,TwilightForest:tile.TFBossSpawner-1
rule15=0,100,air,ChestGenHook:dungeonChest:5-4,ChestGenHook:dungeonChest:5-4

layer
1,1,1,1,1,1,1,1,1,1,1
1,1,1,1,2,2,2,1,1,1,1
1,1,3,2,3,2,2,2,3,1,1
1,1,3,2,2,2,2,2,3,1,1
1,3,3,2,4,2,4,2,3,3,1
1,3,3,2,2,5,2,2,3,3,1
1,3,3,2,2,4,2,2,3,3,1
1,1,3,2,2,2,2,2,3,1,1
1,1,3,2,4,2,4,2,3,1,1
1,1,1,1,2,2,2,1,1,1,1
1,1,3,1,3,3,3,1,3,1,1
1,1,3,2,2,4,2,2,3,1,1
1,1,3,2,2,2,2,2,3,1,1
1,1,3,2,4,2,4,2,3,1,1
1,1,3,2,2,2,2,2,3,3,3
1,1,3,2,2,4,2,3,4,3,1
1,1,3,2,2,2,2,2,3,3,3
1,1,3,2,4,2,4,2,3,1,1
1,1,3,2,2,2,2,2,3,1,1
1,1,3,3,3,3,3,3,3,1,1
1,1,1,1,1,1,1,1,1,1,1
endlayer

layer
0,0,0,0,4,6,3,0,0,0,0
0,0,7,3,0,0,0,3,3,0,0
0,7,0,0,2,0,0,0,0,3,0
0,3,0,0,0,0,0,0,0,3,0
3,0,0,0,0,0,0,0,0,0,3
3,0,0,0,0,3,0,0,0,0,3
3,0,0,0,0,0,0,0,0,0,3
0,3,0,0,0,0,0,0,0,3,0
0,3,0,0,0,0,0,0,0,7,0
0,0,8,2,0,0,0,3,7,0,0
0,0,9,3,3,0,4,4,9,0,0
0,0,3,0,0,0,0,0,3,0,0
0,0,3,0,0,0,0,0,3,0,0
0,0,3,0,0,0,0,0,3,0,0
0,0,3,0,0,0,0,0,3,9,0
0,0,3,0,0,0,0,0,0,0,0
0,0,3,0,0,0,0,0,3,9,0
0,0,3,0,0,0,0,0,3,0,0
0,0,3,0,0,0,0,0,3,0,0
0,0,9,3,3,3,3,3,9,0,0
0,0,0,0,0,0,0,0,0,0,0
endlayer

layer
0,0,0,0,4,3,3,0,0,0,0
0,0,3,4,0,0,0,3,3,0,0
0,7,0,2,0,0,0,0,0,3,0
0,7,0,0,0,0,0,0,0,3,0
3,0,0,0,0,0,0,0,0,0,3
3,0,0,0,0,3,0,0,0,0,3
3,0,0,0,0,0,0,0,0,0,3
0,3,0,0,0,0,0,0,0,7,0
0,3,0,0,0,0,0,0,0,7,0
0,0,3,3,0,0,0,4,3,0,0
0,0,9,3,3,0,3,4,9,0,0
0,0,3,0,0,0,0,0,3,0,0
0,0,3,0,0,0,0,0,10,0,0
0,0,10,0,0,0,0,0,3,0,0
0,0,3,0,0,0,0,0,3,9,0
0,0,3,0,0,0,0,0,0,0,0
0,0,3,0,0,0,0,0,3,9,0
0,0,10,0,0,0,0,0,10,0,0
0,0,3,0,0,0,0,0,3,0,0
0,0,9,3,10,10,10,3,9,0,0
0,0,0,0,0,0,0,0,0,0,0
endlayer

layer
0,0,0,0,3,3,3,0,0,0,0
0,0,4,4,0,0,0,3,3,0,0
0,3,2,0,0,0,0,0,0,3,0
0,7,0,0,0,0,0,0,0,3,0
7,0,0,0,0,0,0,0,0,0,3
3,0,0,0,0,11,0,0,0,0,3
3,0,0,0,0,0,0,0,0,0,7
0,3,0,0,0,0,0,0,0,7,0
0,3,0,0,0,0,0,0,0,3,0
0,0,3,3,0,0,0,4,4,0,0
0,0,9,3,3,3,3,3,9,0,0
0,0,3,0,0,0,0,0,3,0,0
0,0,3,0,0,0,0,0,3,11,0
0,11,3,0,0,0,0,0,3,0,0
0,0,3,0,0,0,0,0,3,9,0
0,0,3,0,0,0,0,0,3,12,0
0,0,3,0,0,0,0,0,3,9,0
0,11,3,0,0,0,0,0,3,11,0
0,0,3,0,0,0,0,0,3,0,0
0,0,9,3,3,3,3,3,9,0,0
0,0,0,0,0,11,0,0,0,0,0
endlayer

layer
0,0,0,0,3,3,3,0,0,0,0
0,0,4,3,0,0,0,3,3,0,0
0,4,0,0,0,0,0,0,0,3,0
0,3,2,0,0,0,0,0,0,3,0
7,0,0,0,0,0,0,0,0,0,3
7,0,0,0,0,0,0,0,0,0,7
3,0,0,0,0,0,0,0,0,0,7
0,3,0,0,0,0,0,0,0,3,0
0,3,0,0,0,0,0,0,0,4,0
0,0,3,3,0,0,0,3,4,0,0
0,0,13,3,3,3,3,3,13,0,0
0,0,13,0,0,0,0,0,13,0,0
0,0,13,0,0,0,0,0,13,0,0
0,0,13,0,0,0,0,0,13,0,0
0,0,13,0,0,0,0,0,13,7,0
0,0,13,0,0,0,0,0,13,7,0
0,0,13,0,0,0,0,0,13,7,0
0,0,13,0,0,0,0,0,13,0,0
0,0,13,0,0,0,0,0,13,0,0
0,0,13,3,3,3,3,3,13,0,0
0,0,13,0,0,0,0,0,13,0,0
endlayer

layer
0,0,0,0,3,3,3,0,0,0,0
0,0,3,3,0,0,0,3,3,0,0
0,4,0,0,0,0,0,0,0,3,0
0,4,0,0,0,0,0,0,0,3,0
3,2,2,0,0,0,0,0,0,0,7
7,0,0,0,0,0,0,0,0,0,7
7,0,0,0,0,0,0,0,0,0,3
0,3,0,0,0,0,0,0,0,4,0
0,3,0,0,0,0,0,0,0,4,0
0,0,3,3,0,0,0,3,3,0,0
0,0,0,0,3,3,3,0,0,0,0
0,0,0,7,0,0,0,7,0,0,0
0,0,0,7,0,0,0,7,0,0,0
0,0,0,7,0,0,0,7,0,0,0
0,0,0,7,0,0,0,7,0,0,0
0,0,0,7,0,0,0,7,7,7,0
0,0,0,7,0,0,0,7,0,0,0
0,0,0,7,0,0,0,7,0,0,0
0,0,0,7,0,0,0,7,0,0,0
0,0,0,7,3,3,3,7,0,0,0
0,0,0,7,0,0,0,7,0,0,0
endlayer

layer
0,0,0,0,3,3,3,0,0,0,0
0,0,3,3,0,0,0,3,3,0,0
0,3,0,0,0,0,0,0,0,3,0
0,4,0,0,0,0,0,0,0,7,0
4,0,0,0,0,0,0,0,0,0,7
3,2,0,0,0,0,0,0,0,0,3
7,0,0,0,0,0,0,0,0,0,4
0,7,0,0,0,0,0,0,0,4,0
0,3,0,0,0,0,0,0,0,3,0
0,0,3,3,0,0,0,3,3,0,0
0,0,0,0,3,3,3,0,0,0,0
0,0,0,0,13,0,13,0,0,0,0
0,0,0,0,13,0,13,0,0,0,0
0,0,0,0,13,0,13,0,0,0,0
0,0,0,0,13,0,13,0,0,0,0
0,0,0,0,13,0,13,0,0,0,0
0,0,0,0,13,0,13,0,0,0,0
0,0,0,0,13,0,13,0,0,0,0
0,0,0,0,13,0,13,0,0,0,0
0,0,0,0,13,3,13,0,0,0,0
0,0,0,0,13,0,13,0,0,0,0
endlayer

layer
0,0,0,0,3,3,3,0,0,0,0
0,0,3,3,0,0,0,3,3,0,0
0,3,0,0,0,0,0,0,0,7,0
0,3,0,0,0,0,0,0,0,7,0
4,0,0,0,0,0,0,0,0,0,3
4,0,0,0,0,0,0,0,0,0,4
3,2,0,0,0,0,0,0,0,0,4
0,7,0,0,0,0,0,0,0,3,0
0,7,0,0,0,0,0,0,0,3,0
0,0,3,3,0,0,0,3,3,0,0
0,0,0,0,3,3,3,0,0,0,0
0,0,0,0,0,7,0,0,0,0,0
0,0,0,0,0,7,0,0,0,0,0
0,0,0,0,0,7,0,0,0,0,0
0,0,0,0,0,7,0,0,0,0,0
0,0,0,0,0,7,0,0,0,0,0
0,0,0,0,0,7,0,0,0,0,0
0,0,0,0,0,7,0,0,0,0,0
0,0,0,0,0,7,0,0,0,0,0
0,0,0,0,0,7,0,0,0,0,0
0,0,0,0,0,7,0,0,0,0,0
endlayer

layer
0,0,0,0,3,3,3,0,0,0,0
0,0,3,3,0,0,0,3,7,0,0
0,3,0,0,0,0,0,0,0,7,0
0,3,0,0,0,0,0,0,0,3,0
3,0,0,0,0,0,0,0,0,0,4
4,0,0,0,0,0,0,0,0,0,4
4,0,2,0,0,0,0,0,0,0,3
0,3,2,0,0,0,0,0,0,3,0
0,7,0,0,0,0,0,0,0,3,0
0,0,7,3,0,0,0,3,3,0,0
0,0,0,0,3,3,3,0,0,0,0
0,0,0,0,0,0,0,0,0,0,0
0,0,0,0,0,0,0,0,0,0,0
0,0,0,0,0,0,0,0,0,0,0
0,0,0,0,0,0,0,0,0,0,0
0,0,0,0,0,0,0,0,0,0,0
0,0,0,0,0,0,0,0,0,0,0
0,0,0,0,0,0,0,0,0,0,0
0,0,0,0,0,0,0,0,0,0,0
0,0,0,0,0,0,0,0,0,0,0
0,0,0,0,0,0,0,0,0,0,0
endlayer

layer
0,0,0,0,3,10,3,0,0,0,0
0,0,3,3,0,0,0,7,7,0,0
0,3,0,0,0,0,0,0,0,3,0
0,3,0,0,0,0,0,0,0,4,0
3,0,0,0,0,0,0,0,0,0,4
10,0,0,0,0,0,0,0,0,0,10
4,0,0,0,0,0,0,0,0,0,3
0,4,0,0,0,0,0,0,0,3,0
0,3,2,0,0,0,0,0,0,3,0
0,0,7,7,0,0,0,3,3,0,0
0,0,0,0,3,10,3,0,0,0,0
0,0,0,0,0,0,0,0,0,0,0
0,0,0,0,0,0,0,0,0,0,0
0,0,0,0,0,0,0,0,0,0,0
0,0,0,0,0,0,0,0,0,0,0
0,0,0,0,0,0,0,0,0,0,0
0,0,0,0,0,0,0,0,0,0,0
0,0,0,0,0,0,0,0,0,0,0
0,0,0,0,0,0,0,0,0,0,0
0,0,0,0,0,0,0,0,0,0,0
0,0,0,0,0,0,0,0,0,0,0
endlayer

layer
0,0,0,0,3,10,7,0,0,0,0
0,0,3,3,0,0,0,7,3,0,0
0,3,0,0,0,0,0,0,0,4,0
0,3,0,0,0,0,0,0,0,4,0
3,0,0,0,0,0,0,0,0,0,3
10,0,0,0,0,0,0,0,0,0,10
3,0,0,0,0,0,0,0,0,0,3
0,4,0,0,0,0,0,0,0,3,0
0,4,0,2,0,0,0,0,0,3,0
0,0,3,7,0,0,0,3,3,0,0
0,0,0,0,7,10,3,0,0,0,0
0,0,0,0,0,0,0,0,0,0,0
0,0,0,0,0,0,0,0,0,0,0
0,0,0,0,0,0,0,0,0,0,0
0,0,0,0,0,0,0,0,0,0,0
0,0,0,0,0,0,0,0,0,0,0
0,0,0,0,0,0,0,0,0,0,0
0,0,0,0,0,0,0,0,0,0,0
0,0,0,0,0,0,0,0,0,0,0
0,0,0,0,0,0,0,0,0,0,0
0,0,0,0,0,0,0,0,0,0,0
endlayer

layer
0,0,0,0,3,7,7,0,0,0,0
0,0,3,3,0,0,0,3,4,0,0
0,3,0,0,0,0,0,0,0,4,0
0,3,0,0,0,0,0,0,0,3,0
3,0,0,0,0,0,0,0,0,0,3
3,0,0,0,0,0,0,0,0,0,3
3,0,0,0,0,0,0,0,0,0,3
0,3,0,0,0,0,0,0,0,3,0
0,4,0,0,2,0,0,0,0,3,0
0,0,4,3,2,0,0,3,3,0,0
0,0,0,0,7,7,3,0,0,0,0
0,0,0,0,0,11,0,0,0,0,0
0,0,0,0,0,0,0,0,0,0,0
0,0,0,0,0,0,0,0,0,0,0
0,0,0,0,0,0,0,0,0,0,0
0,0,0,0,0,0,0,0,0,0,0
0,0,0,0,0,0,0,0,0,0,0
0,0,0,0,0,0,0,0,0,0,0
0,0,0,0,0,0,0,0,0,0,0
0,0,0,0,0,0,0,0,0,0,0
0,0,0,0,0,0,0,0,0,0,0
endlayer

layer
0,0,0,0,7,7,3,0,0,0,0
0,0,3,3,0,0,0,4,4,0,0
0,3,0,0,0,0,0,0,0,3,0
0,3,0,0,0,0,0,0,0,3,0
3,0,0,0,0,0,0,0,0,0,3
3,0,0,0,0,0,0,0,0,0,3
3,0,0,0,0,0,0,0,0,0,3
0,3,0,0,0,0,0,0,0,3,0
0,3,0,0,0,0,0,0,0,3,0
0,0,4,4,0,2,0,3,3,0,0
0,0,0,0,3,7,7,0,0,0,0
0,0,0,0,0,0,0,0,0,0,0
0,0,0,0,0,0,0,0,0,0,0
0,0,0,0,0,0,0,0,0,0,0
0,0,0,0,0,0,0,0,0,0,0
0,0,0,0,0,0,0,0,0,0,0
0,0,0,0,0,0,0,0,0,0,0
0,0,0,0,0,0,0,0,0,0,0
0,0,0,0,0,0,0,0,0,0,0
0,0,0,0,0,0,0,0,0,0,0
0,0,0,0,0,0,0,0,0,0,0
endlayer

layer
0,0,0,0,7,3,4,0,0,0,0
0,0,3,7,0,0,0,4,3,0,0
0,3,0,0,0,0,0,0,0,3,0
0,3,0,0,0,0,0,0,0,3,0
3,0,0,0,0,0,0,0,0,0,3
3,0,0,0,0,0,0,0,0,0,3
3,0,0,0,0,0,0,0,0,0,3
0,3,0,0,0,0,0,0,0,3,0
0,3,0,0,0,0,2,0,0,3,0
0,0,3,4,0,0,2,7,3,0,0
0,0,0,0,4,3,7,0,0,0,0
0,0,0,0,0,0,0,0,0,0,0
0,0,0,0,0,0,0,0,0,0,0
0,0,0,0,0,0,0,0,0,0,0
0,0,0,0,0,0,0,0,0,0,0
0,0,0,0,0,0,0,0,0,0,0
0,0,0,0,0,0,0,0,0,0,0
0,0,0,0,0,0,0,0,0,0,0
0,0,0,0,0,0,0,0,0,0,0
0,0,0,0,0,0,0,0,0,0,0
0,0,0,0,0,0,0,0,0,0,0
endlayer

layer
0,0,0,0,3,4,4,0,0,0,0
0,0,7,7,0,0,0,3,3,0,0
0,3,0,0,0,0,0,0,0,3,0
0,3,0,0,0,0,0,0,0,3,0
3,0,0,0,0,0,0,0,0,0,3
3,0,0,0,0,0,0,0,0,0,3
3,0,0,0,0,0,0,0,0,0,3
0,3,0,0,0,0,2,0,0,3,0
0,3,0,0,0,0,0,0,0,3,0
0,0,3,3,0,0,0,7,7,0,0
0,0,0,0,4,4,3,0,0,0,0
0,0,0,0,0,0,0,0,0,0,0
0,0,0,0,0,0,0,0,0,0,0
0,0,0,0,0,0,0,0,0,0,0
0,0,0,0,0,0,0,0,0,0,0
0,0,0,0,0,0,0,0,0,0,0
0,0,0,0,0,0,0,0,0,0,0
0,0,0,0,0,0,0,0,0,0,0
0,0,0,0,0,0,0,0,0,0,0
0,0,0,0,0,0,0,0,0,0,0
0,0,0,0,0,0,0,0,0,0,0
endlayer

layer
0,0,0,0,4,4,3,0,0,0,0
0,0,7,3,4,4,3,3,3,0,0
0,7,7,3,0,3,0,3,3,3,0
0,3,3,0,0,3,0,0,3,3,0
3,3,0,0,0,3,0,0,0,3,3
3,3,3,3,3,3,3,3,3,3,3
3,3,0,0,0,3,0,0,0,3,3
0,3,3,0,0,3,0,2,3,3,0
0,3,3,3,0,3,0,3,7,7,0
0,0,3,3,3,0,0,3,7,0,0
0,0,0,0,3,4,4,0,0,0,0
0,0,0,0,0,0,0,0,0,0,0
0,0,0,0,0,0,0,0,0,0,0
0,0,0,0,0,0,0,0,0,0,0
0,0,0,0,0,0,0,0,0,0,0
0,0,0,0,0,0,0,0,0,0,0
0,0,0,0,0,0,0,0,0,0,0
0,0,0,0,0,0,0,0,0,0,0
0,0,0,0,0,0,0,0,0,0,0
0,0,0,0,0,0,0,0,0,0,0
0,0,0,0,0,0,0,0,0,0,0
endlayer

layer
0,0,0,0,0,0,0,0,0,0,0
0,0,0,0,4,3,3,0,0,0,0
0,0,0,4,0,0,0,3,0,0,0
0,0,7,0,0,0,0,0,3,0,0
0,7,0,0,0,0,0,0,0,3,0
0,3,0,0,0,5,0,0,0,3,0
0,3,0,0,0,0,0,2,2,7,0
0,0,3,0,0,0,0,0,7,0,0
0,0,0,3,0,0,0,4,0,0,0
0,0,0,0,3,3,4,0,0,0,0
0,0,0,0,0,0,0,0,0,0,0
0,0,0,0,0,0,0,0,0,0,0
0,0,0,0,0,0,0,0,0,0,0
0,0,0,0,0,0,0,0,0,0,0
0,0,0,0,0,0,0,0,0,0,0
0,0,0,0,0,0,0,0,0,0,0
0,0,0,0,0,0,0,0,0,0,0
0,0,0,0,0,0,0,0,0,0,0
0,0,0,0,0,0,0,0,0,0,0
0,0,0,0,0,0,0,0,0,0,0
0,0,0,0,0,0,0,0,0,0,0
endlayer

layer
0,0,0,0,0,0,0,0,0,0,0
0,0,0,0,3,3,3,0,0,0,0
0,0,0,4,0,0,0,3,0,0,0
0,0,3,0,0,0,0,0,3,0,0
0,7,0,0,0,0,0,0,0,3,0
0,7,0,0,0,3,0,0,0,7,0
0,3,0,0,0,0,0,0,2,7,0
0,0,3,0,0,0,0,0,3,0,0
0,0,0,3,0,0,0,4,0,0,0
0,0,0,0,3,3,3,0,0,0,0
0,0,0,0,0,0,0,0,0,0,0
0,0,0,0,0,0,0,0,0,0,0
0,0,0,0,0,0,0,0,0,0,0
0,0,0,0,0,0,0,0,0,0,0
0,0,0,0,0,0,0,0,0,0,0
0,0,0,0,0,0,0,0,0,0,0
0,0,0,0,0,0,0,0,0,0,0
0,0,0,0,0,0,0,0,0,0,0
0,0,0,0,0,0,0,0,0,0,0
0,0,0,0,0,0,0,0,0,0,0
0,0,0,0,0,0,0,0,0,0,0
endlayer

layer
0,0,0,0,0,0,0,0,0,0,0
0,0,0,0,3,3,3,0,0,0,0
0,0,0,3,0,0,0,3,0,0,0
0,0,4,0,0,0,0,0,3,0,0
0,3,0,0,0,0,0,0,0,7,0
0,7,0,0,0,11,0,0,2,7,0
0,7,0,0,0,0,0,0,0,3,0
0,0,3,0,0,0,0,0,4,0,0
0,0,0,3,0,0,0,3,0,0,0
0,0,0,0,3,3,3,0,0,0,0
0,0,0,0,0,0,0,0,0,0,0
0,0,0,0,0,0,0,0,0,0,0
0,0,0,0,0,0,0,0,0,0,0
0,0,0,0,0,0,0,0,0,0,0
0,0,0,0,0,0,0,0,0,0,0
0,0,0,0,0,0,0,0,0,0,0
0,0,0,0,0,0,0,0,0,0,0
0,0,0,0,0,0,0,0,0,0,0
0,0,0,0,0,0,0,0,0,0,0
0,0,0,0,0,0,0,0,0,0,0
0,0,0,0,0,0,0,0,0,0,0
endlayer

layer
0,0,0,0,0,0,0,0,0,0,0
0,0,0,0,3,3,3,0,0,0,0
0,0,0,3,0,0,0,3,0,0,0
0,0,4,0,0,0,0,0,7,0,0
0,4,0,0,0,0,0,0,2,7,0
0,3,0,0,0,0,0,0,0,3,0
0,7,0,0,0,0,0,0,0,4,0
0,0,7,0,0,0,0,0,4,0,0
0,0,0,3,0,0,0,3,0,0,0
0,0,0,0,3,3,3,0,0,0,0
0,0,0,0,0,0,0,0,0,0,0
0,0,0,0,0,0,0,0,0,0,0
0,0,0,0,0,0,0,0,0,0,0
0,0,0,0,0,0,0,0,0,0,0
0,0,0,0,0,0,0,0,0,0,0
0,0,0,0,0,0,0,0,0,0,0
0,0,0,0,0,0,0,0,0,0,0
0,0,0,0,0,0,0,0,0,0,0
0,0,0,0,0,0,0,0,0,0,0
0,0,0,0,0,0,0,0,0,0,0
0,0,0,0,0,0,0,0,0,0,0
endlayer

layer
0,0,0,0,0,0,0,0,0,0,0
0,0,0,0,3,3,3,0,0,0,0
0,0,0,3,0,0,0,7,0,0,0
0,0,3,0,0,0,0,0,7,0,0
0,4,0,0,0,0,0,2,0,3,0
0,4,0,0,0,0,0,0,0,4,0
0,3,0,0,0,0,0,0,0,4,0
0,0,7,0,0,0,0,0,3,0,0
0,0,0,7,0,0,0,3,0,0,0
0,0,0,0,3,3,3,0,0,0,0
0,0,0,0,0,0,0,0,0,0,0
0,0,0,0,0,0,0,0,0,0,0
0,0,0,0,0,0,0,0,0,0,0
0,0,0,0,0,0,0,0,0,0,0
0,0,0,0,0,0,0,0,0,0,0
0,0,0,0,0,0,0,0,0,0,0
0,0,0,0,0,0,0,0,0,0,0
0,0,0,0,0,0,0,0,0,0,0
0,0,0,0,0,0,0,0,0,0,0
0,0,0,0,0,0,0,0,0,0,0
0,0,0,0,0,0,0,0,0,0,0
endlayer

layer
0,0,0,0,0,0,0,0,0,0,0
0,0,0,0,3,3,7,0,0,0,0
0,0,0,3,0,0,0,7,0,0,0
0,0,3,0,0,0,0,2,3,0,0
0,3,0,0,0,0,0,0,0,4,0
0,4,0,0,0,0,0,0,0,4,0
0,4,0,0,0,0,0,0,0,3,0
0,0,3,0,0,0,0,0,3,0,0
0,0,0,7,0,0,0,3,0,0,0
0,0,0,0,7,3,3,0,0,0,0
0,0,0,0,0,0,0,0,0,0,0
0,0,0,0,0,0,0,0,0,0,0
0,0,0,0,0,0,0,0,0,0,0
0,0,0,0,0,0,0,0,0,0,0
0,0,0,0,0,0,0,0,0,0,0
0,0,0,0,0,0,0,0,0,0,0
0,0,0,0,0,0,0,0,0,0,0
0,0,0,0,0,0,0,0,0,0,0
0,0,0,0,0,0,0,0,0,0,0
0,0,0,0,0,0,0,0,0,0,0
0,0,0,0,0,0,0,0,0,0,0
endlayer

layer
0,0,0,0,0,0,0,0,0,0,0
0,0,0,0,3,10,7,0,0,0,0
0,0,0,3,0,0,2,3,0,0,0
0,0,3,0,0,0,2,0,4,0,0
0,3,0,0,0,0,0,0,0,4,0
0,10,0,0,0,0,0,0,0,10,0
0,4,0,0,0,0,0,0,0,3,0
0,0,4,0,0,0,0,0,3,0,0
0,0,0,3,0,0,0,3,0,0,0
0,0,0,0,7,10,3,0,0,0,0
0,0,0,0,0,0,0,0,0,0,0
0,0,0,0,0,0,0,0,0,0,0
0,0,0,0,0,0,0,0,0,0,0
0,0,0,0,0,0,0,0,0,0,0
0,0,0,0,0,0,0,0,0,0,0
0,0,0,0,0,0,0,0,0,0,0
0,0,0,0,0,0,0,0,0,0,0
0,0,0,0,0,0,0,0,0,0,0
0,0,0,0,0,0,0,0,0,0,0
0,0,0,0,0,0,0,0,0,0,0
0,0,0,0,0,0,0,0,0,0,0
endlayer

layer
0,0,0,0,0,0,0,0,0,0,0
0,0,0,0,7,10,3,0,0,0,0
0,0,0,3,0,0,2,4,0,0,0
0,0,3,0,0,0,0,0,4,0,0
0,3,0,0,0,0,0,0,0,3,0
0,10,0,0,0,0,0,0,0,10,0
0,3,0,0,0,0,0,0,0,3,0
0,0,4,0,0,0,0,0,3,0,0
0,0,0,4,0,0,0,3,0,0,0
0,0,0,0,3,10,7,0,0,0,0
0,0,0,0,0,0,0,0,0,0,0
0,0,0,0,0,0,0,0,0,0,0
0,0,0,0,0,0,0,0,0,0,0
0,0,0,0,0,0,0,0,0,0,0
0,0,0,0,0,0,0,0,0,0,0
0,0,0,0,0,0,0,0,0,0,0
0,0,0,0,0,0,0,0,0,0,0
0,0,0,0,0,0,0,0,0,0,0
0,0,0,0,0,0,0,0,0,0,0
0,0,0,0,0,0,0,0,0,0,0
0,0,0,0,0,0,0,0,0,0,0
endlayer

layer
0,0,0,0,0,11,0,0,0,0,0
0,0,0,0,7,3,4,0,0,0,0
0,0,0,7,0,2,0,4,0,0,0
0,0,3,0,0,0,0,0,3,0,0
0,3,0,0,0,0,0,0,0,3,0
11,3,0,0,0,0,0,0,0,3,11
0,3,0,0,0,0,0,0,0,3,0
0,0,3,0,0,0,0,0,3,0,0
0,0,0,4,0,0,0,7,0,0,0
0,0,0,0,4,3,7,0,0,0,0
0,0,0,0,0,11,0,0,0,0,0
0,0,0,0,0,0,0,0,0,0,0
0,0,0,0,0,0,0,0,0,0,0
0,0,0,0,0,0,0,0,0,0,0
0,0,0,0,0,0,0,0,0,0,0
0,0,0,0,0,0,0,0,0,0,0
0,0,0,0,0,0,0,0,0,0,0
0,0,0,0,0,0,0,0,0,0,0
0,0,0,0,0,0,0,0,0,0,0
0,0,0,0,0,0,0,0,0,0,0
0,0,0,0,0,0,0,0,0,0,0
endlayer

layer
0,0,0,0,0,0,0,0,0,0,0
0,0,0,0,3,4,4,0,0,0,0
0,0,0,7,2,0,0,3,0,0,0
0,0,7,0,0,0,0,0,3,0,0
0,3,0,0,0,0,0,0,0,3,0
0,3,0,0,0,0,0,0,0,3,0
0,3,0,0,0,0,0,0,0,3,0
0,0,3,0,0,0,0,0,7,0,0
0,0,0,3,0,0,0,7,0,0,0
0,0,0,0,4,4,3,0,0,0,0
0,0,0,0,0,0,0,0,0,0,0
0,0,0,0,0,0,0,0,0,0,0
0,0,0,0,0,0,0,0,0,0,0
0,0,0,0,0,0,0,0,0,0,0
0,0,0,0,0,0,0,0,0,0,0
0,0,0,0,0,0,0,0,0,0,0
0,0,0,0,0,0,0,0,0,0,0
0,0,0,0,0,0,0,0,0,0,0
0,0,0,0,0,0,0,0,0,0,0
0,0,0,0,0,0,0,0,0,0,0
0,0,0,0,0,0,0,0,0,0,0
endlayer

layer
0,0,0,0,0,0,0,0,0,0,0
0,0,0,0,4,4,3,0,0,0,0
0,0,0,3,0,0,0,3,0,0,0
0,0,7,2,2,0,0,0,3,0,0
0,7,0,0,0,0,0,0,0,3,0
0,3,0,0,0,0,0,0,0,3,0
0,3,0,0,0,0,0,0,0,7,0
0,0,3,0,0,0,0,0,7,0,0
0,0,0,3,0,0,0,3,0,0,0
0,0,0,0,3,4,4,0,0,0,0
0,0,0,0,0,0,0,0,0,0,0
0,0,0,0,0,0,0,0,0,0,0
0,0,0,0,0,0,0,0,0,0,0
0,0,0,0,0,0,0,0,0,0,0
0,0,0,0,0,0,0,0,0,0,0
0,0,0,0,0,0,0,0,0,0,0
0,0,0,0,0,0,0,0,0,0,0
0,0,0,0,0,0,0,0,0,0,0
0,0,0,0,0,0,0,0,0,0,0
0,0,0,0,0,0,0,0,0,0,0
0,0,0,0,0,0,0,0,0,0,0
endlayer

layer
0,0,0,0,0,0,0,0,0,0,0
0,0,0,0,4,3,3,0,0,0,0
0,0,0,4,0,0,0,3,0,0,0
0,0,3,0,0,0,0,0,3,0,0
0,7,2,2,0,0,0,0,0,3,0
0,7,0,0,0,0,0,0,0,7,0
0,3,0,0,0,0,0,0,0,7,0
0,0,3,0,0,0,0,0,3,0,0
0,0,0,3,0,0,0,4,0,0,0
0,0,0,0,3,3,4,0,0,0,0
0,0,0,0,0,0,0,0,0,0,0
0,0,0,0,0,0,0,0,0,0,0
0,0,0,0,0,0,0,0,0,0,0
0,0,0,0,0,0,0,0,0,0,0
0,0,0,0,0,0,0,0,0,0,0
0,0,0,0,0,0,0,0,0,0,0
0,0,0,0,0,0,0,0,0,0,0
0,0,0,0,0,0,0,0,0,0,0
0,0,0,0,0,0,0,0,0,0,0
0,0,0,0,0,0,0,0,0,0,0
0,0,0,0,0,0,0,0,0,0,0
endlayer

layer
0,0,0,0,0,0,0,0,0,0,0
0,0,0,0,3,3,3,0,0,0,0
0,0,0,4,0,0,0,3,0,0,0
0,0,4,0,0,0,0,0,3,0,0
0,3,0,0,0,0,0,0,0,7,0
0,7,2,2,0,0,0,0,0,7,0
0,7,0,0,0,0,0,0,0,3,0
0,0,3,0,0,0,0,0,4,0,0
0,0,0,3,0,0,0,4,0,0,0
0,0,0,0,3,3,3,0,0,0,0
0,0,0,0,0,0,0,0,0,0,0
0,0,0,0,0,0,0,0,0,0,0
0,0,0,0,0,0,0,0,0,0,0
0,0,0,0,0,0,0,0,0,0,0
0,0,0,0,0,0,0,0,0,0,0
0,0,0,0,0,0,0,0,0,0,0
0,0,0,0,0,0,0,0,0,0,0
0,0,0,0,0,0,0,0,0,0,0
0,0,0,0,0,0,0,0,0,0,0
0,0,0,0,0,0,0,0,0,0,0
0,0,0,0,0,0,0,0,0,0,0
endlayer

layer
0,0,0,0,0,0,0,0,0,0,0
0,0,0,0,3,3,3,0,0,0,0
0,0,0,3,0,0,0,3,0,0,0
0,0,4,0,0,0,0,0,7,0,0
0,4,0,0,0,0,0,0,0,7,0
0,3,0,0,0,0,0,0,0,3,0
0,7,2,2,0,0,0,0,0,4,0
0,0,7,0,0,0,0,0,4,0,0
0,0,0,3,0,0,0,3,0,0,0
0,0,0,0,3,3,3,0,0,0,0
0,0,0,0,0,0,0,0,0,0,0
0,0,0,0,0,0,0,0,0,0,0
0,0,0,0,0,0,0,0,0,0,0
0,0,0,0,0,0,0,0,0,0,0
0,0,0,0,0,0,0,0,0,0,0
0,0,0,0,0,0,0,0,0,0,0
0,0,0,0,0,0,0,0,0,0,0
0,0,0,0,0,0,0,0,0,0,0
0,0,0,0,0,0,0,0,0,0,0
0,0,0,0,0,0,0,0,0,0,0
0,0,0,0,0,0,0,0,0,0,0
endlayer

layer
0,0,0,0,0,0,0,0,0,0,0
0,0,0,0,3,3,3,0,0,0,0
0,0,0,3,0,3,3,7,0,0,0
0,0,3,3,0,3,0,7,7,0,0
0,4,4,0,0,3,0,0,3,3,0
0,4,4,0,0,3,3,3,4,4,0
0,3,3,0,2,3,0,0,4,4,0
0,0,7,7,2,3,0,3,3,0,0
0,0,0,7,3,3,3,3,0,0,0
0,0,0,0,3,3,3,0,0,0,0
0,0,0,0,0,0,0,0,0,0,0
0,0,0,0,0,0,0,0,0,0,0
0,0,0,0,0,0,0,0,0,0,0
0,0,0,0,0,0,0,0,0,0,0
0,0,0,0,0,0,0,0,0,0,0
0,0,0,0,0,0,0,0,0,0,0
0,0,0,0,0,0,0,0,0,0,0
0,0,0,0,0,0,0,0,0,0,0
0,0,0,0,0,0,0,0,0,0,0
0,0,0,0,0,0,0,0,0,0,0
0,0,0,0,0,0,0,0,0,0,0
endlayer

layer
0,0,0,0,0,0,0,0,0,0,0
0,0,0,0,0,0,0,0,0,0,0
0,0,0,0,3,3,7,0,0,0,0
0,0,0,3,0,0,0,7,0,0,0
0,0,3,0,0,0,0,0,3,0,0
0,0,4,0,0,5,0,0,4,0,0
0,0,3,0,0,0,0,0,3,0,0
0,0,0,7,2,0,0,3,0,0,0
0,0,0,0,7,3,3,0,0,0,0
0,0,0,0,0,0,0,0,0,0,0
0,0,0,0,0,0,0,0,0,0,0
0,0,0,0,0,0,0,0,0,0,0
0,0,0,0,0,0,0,0,0,0,0
0,0,0,0,0,0,0,0,0,0,0
0,0,0,0,0,0,0,0,0,0,0
0,0,0,0,0,0,0,0,0,0,0
0,0,0,0,0,0,0,0,0,0,0
0,0,0,0,0,0,0,0,0,0,0
0,0,0,0,0,0,0,0,0,0,0
0,0,0,0,0,0,0,0,0,0,0
0,0,0,0,0,0,0,0,0,0,0
endlayer

layer
0,0,0,0,0,0,0,0,0,0,0
0,0,0,0,0,0,0,0,0,0,0
0,0,0,0,3,7,7,0,0,0,0
0,0,0,3,0,0,0,3,0,0,0
0,0,3,0,0,0,0,0,4,0,0
0,0,4,0,0,3,0,0,4,0,0
0,0,4,0,0,0,0,0,3,0,0
0,0,0,3,0,2,0,3,0,0,0
0,0,0,0,7,7,3,0,0,0,0
0,0,0,0,0,0,0,0,0,0,0
0,0,0,0,0,0,0,0,0,0,0
0,0,0,0,0,0,0,0,0,0,0
0,0,0,0,0,0,0,0,0,0,0
0,0,0,0,0,0,0,0,0,0,0
0,0,0,0,0,0,0,0,0,0,0
0,0,0,0,0,0,0,0,0,0,0
0,0,0,0,0,0,0,0,0,0,0
0,0,0,0,0,0,0,0,0,0,0
0,0,0,0,0,0,0,0,0,0,0
0,0,0,0,0,0,0,0,0,0,0
0,0,0,0,0,0,0,0,0,0,0
endlayer

layer
0,0,0,0,0,0,0,0,0,0,0
0,0,0,0,0,0,0,0,0,0,0
0,0,0,0,7,7,3,0,0,0,0
0,0,0,3,0,0,0,4,0,0,0
0,0,3,0,0,0,0,0,4,0,0
0,0,3,0,0,11,0,0,3,0,0
0,0,4,0,0,0,0,0,3,0,0
0,0,0,4,0,0,2,3,0,0,0
0,0,0,0,3,7,7,0,0,0,0
0,0,0,0,0,0,0,0,0,0,0
0,0,0,0,0,0,0,0,0,0,0
0,0,0,0,0,0,0,0,0,0,0
0,0,0,0,0,0,0,0,0,0,0
0,0,0,0,0,0,0,0,0,0,0
0,0,0,0,0,0,0,0,0,0,0
0,0,0,0,0,0,0,0,0,0,0
0,0,0,0,0,0,0,0,0,0,0
0,0,0,0,0,0,0,0,0,0,0
0,0,0,0,0,0,0,0,0,0,0
0,0,0,0,0,0,0,0,0,0,0
0,0,0,0,0,0,0,0,0,0,0
endlayer

layer
0,0,0,0,0,0,0,0,0,0,0
0,0,0,0,0,0,0,0,0,0,0
0,0,0,0,7,3,4,0,0,0,0
0,0,0,7,0,0,0,4,0,0,0
0,0,3,0,0,0,0,0,3,0,0
0,0,3,0,0,0,0,0,3,0,0
0,0,3,0,0,0,2,2,3,0,0
0,0,0,4,0,0,0,7,0,0,0
0,0,0,0,4,3,7,0,0,0,0
0,0,0,0,0,0,0,0,0,0,0
0,0,0,0,0,0,0,0,0,0,0
0,0,0,0,0,0,0,0,0,0,0
0,0,0,0,0,0,0,0,0,0,0
0,0,0,0,0,0,0,0,0,0,0
0,0,0,0,0,0,0,0,0,0,0
0,0,0,0,0,0,0,0,0,0,0
0,0,0,0,0,0,0,0,0,0,0
0,0,0,0,0,0,0,0,0,0,0
0,0,0,0,0,0,0,0,0,0,0
0,0,0,0,0,0,0,0,0,0,0
0,0,0,0,0,0,0,0,0,0,0
endlayer

layer
0,0,0,0,0,0,0,0,0,0,0
0,0,0,0,0,0,0,0,0,0,0
0,0,0,0,3,10,4,0,0,0,0
0,0,0,7,0,0,0,3,0,0,0
0,0,7,0,0,0,0,0,3,0,0
0,0,10,0,0,0,0,0,10,0,0
0,0,3,0,0,0,0,2,7,0,0
0,0,0,3,0,0,0,7,0,0,0
0,0,0,0,4,10,3,0,0,0,0
0,0,0,0,0,0,0,0,0,0,0
0,0,0,0,0,0,0,0,0,0,0
0,0,0,0,0,0,0,0,0,0,0
0,0,0,0,0,0,0,0,0,0,0
0,0,0,0,0,0,0,0,0,0,0
0,0,0,0,0,0,0,0,0,0,0
0,0,0,0,0,0,0,0,0,0,0
0,0,0,0,0,0,0,0,0,0,0
0,0,0,0,0,0,0,0,0,0,0
0,0,0,0,0,0,0,0,0,0,0
0,0,0,0,0,0,0,0,0,0,0
0,0,0,0,0,0,0,0,0,0,0
endlayer

layer
0,0,0,0,0,0,0,0,0,0,0
0,0,0,0,0,0,0,0,0,0,0
0,0,0,0,4,10,3,0,0,0,0
0,0,0,3,0,0,0,3,0,0,0
0,0,7,0,0,0,0,0,3,0,0
0,0,10,0,0,0,0,2,10,0,0
0,0,3,0,0,0,0,0,7,0,0
0,0,0,3,0,0,0,3,0,0,0
0,0,0,0,3,10,4,0,0,0,0
0,0,0,0,0,0,0,0,0,0,0
0,0,0,0,0,0,0,0,0,0,0
0,0,0,0,0,0,0,0,0,0,0
0,0,0,0,0,0,0,0,0,0,0
0,0,0,0,0,0,0,0,0,0,0
0,0,0,0,0,0,0,0,0,0,0
0,0,0,0,0,0,0,0,0,0,0
0,0,0,0,0,0,0,0,0,0,0
0,0,0,0,0,0,0,0,0,0,0
0,0,0,0,0,0,0,0,0,0,0
0,0,0,0,0,0,0,0,0,0,0
0,0,0,0,0,0,0,0,0,0,0
endlayer

layer
0,0,0,0,0,0,0,0,0,0,0
0,0,0,0,0,11,0,0,0,0,0
0,0,0,0,4,3,3,0,0,0,0
0,0,0,4,0,0,0,3,0,0,0
0,0,3,0,0,0,0,2,7,0,0
0,11,7,0,0,0,0,0,7,11,0
0,0,7,0,0,0,0,0,3,0,0
0,0,0,3,0,0,0,4,0,0,0
0,0,0,0,3,3,4,0,0,0,0
0,0,0,0,0,11,0,0,0,0,0
0,0,0,0,0,0,0,0,0,0,0
0,0,0,0,0,0,0,0,0,0,0
0,0,0,0,0,0,0,0,0,0,0
0,0,0,0,0,0,0,0,0,0,0
0,0,0,0,0,0,0,0,0,0,0
0,0,0,0,0,0,0,0,0,0,0
0,0,0,0,0,0,0,0,0,0,0
0,0,0,0,0,0,0,0,0,0,0
0,0,0,0,0,0,0,0,0,0,0
0,0,0,0,0,0,0,0,0,0,0
0,0,0,0,0,0,0,0,0,0,0
endlayer

layer
0,0,0,0,0,0,0,0,0,0,0
0,0,0,0,0,0,0,0,0,0,0
0,0,0,0,3,3,3,0,0,0,0
0,0,0,4,0,0,2,7,0,0,0
0,0,4,0,0,2,2,0,7,0,0
0,0,3,0,0,0,0,0,3,0,0
0,0,7,0,0,0,0,0,4,0,0
0,0,0,7,0,0,0,4,0,0,0
0,0,0,0,3,3,3,0,0,0,0
0,0,0,0,0,0,0,0,0,0,0
0,0,0,0,0,0,0,0,0,0,0
0,0,0,0,0,0,0,0,0,0,0
0,0,0,0,0,0,0,0,0,0,0
0,0,0,0,0,0,0,0,0,0,0
0,0,0,0,0,0,0,0,0,0,0
0,0,0,0,0,0,0,0,0,0,0
0,0,0,0,0,0,0,0,0,0,0
0,0,0,0,0,0,0,0,0,0,0
0,0,0,0,0,0,0,0,0,0,0
0,0,0,0,0,0,0,0,0,0,0
0,0,0,0,0,0,0,0,0,0,0
endlayer

layer
0,0,0,0,0,0,0,0,0,0,0
0,0,0,0,0,0,0,0,0,0,0
0,0,0,0,3,3,7,0,0,0,0
0,0,0,3,0,0,2,7,0,0,0
0,0,4,0,0,2,0,0,3,0,0
0,0,4,0,0,0,0,0,4,0,0
0,0,3,0,0,0,0,0,4,0,0
0,0,0,7,0,0,0,3,0,0,0
0,0,0,0,7,3,3,0,0,0,0
0,0,0,0,0,0,0,0,0,0,0
0,0,0,0,0,0,0,0,0,0,0
0,0,0,0,0,0,0,0,0,0,0
0,0,0,0,0,0,0,0,0,0,0
0,0,0,0,0,0,0,0,0,0,0
0,0,0,0,0,0,0,0,0,0,0
0,0,0,0,0,0,0,0,0,0,0
0,0,0,0,0,0,0,0,0,0,0
0,0,0,0,0,0,0,0,0,0,0
0,0,0,0,0,0,0,0,0,0,0
0,0,0,0,0,0,0,0,0,0,0
0,0,0,0,0,0,0,0,0,0,0
endlayer

layer
0,0,0,0,0,0,0,0,0,0,0
0,0,0,0,3,7,7,0,0,0,0
0,0,0,3,3,7,7,3,0,0,0
0,0,3,3,3,3,3,3,3,0,0
0,3,3,3,3,0,0,0,4,4,0
0,4,4,3,3,3,3,0,4,4,0
0,4,4,3,3,3,3,3,3,3,0
0,0,3,3,3,3,3,3,3,0,0
0,0,0,3,7,7,3,3,0,0,0
0,0,0,0,7,7,3,0,0,0,0
0,0,0,0,0,0,0,0,0,0,0
0,0,0,0,0,0,0,0,0,0,0
0,0,0,0,0,0,0,0,0,0,0
0,0,0,0,0,0,0,0,0,0,0
0,0,0,0,0,0,0,0,0,0,0
0,0,0,0,0,0,0,0,0,0,0
0,0,0,0,0,0,0,0,0,0,0
0,0,0,0,0,0,0,0,0,0,0
0,0,0,0,0,0,0,0,0,0,0
0,0,0,0,0,0,0,0,0,0,0
0,0,0,0,0,0,0,0,0,0,0
endlayer

layer
0,0,0,0,0,0,0,0,0,0,0
0,0,0,0,0,0,0,0,0,0,0
0,0,0,0,0,0,0,0,0,0,0
0,0,0,3,0,0,0,4,0,0,0
0,0,0,0,0,0,0,0,0,0,0
0,0,0,0,0,14,0,0,0,0,0
0,0,0,0,0,0,0,0,0,0,0
0,0,0,4,0,0,0,3,0,0,0
0,0,0,0,0,15,0,0,0,0,0
0,0,0,0,0,0,0,0,0,0,0
0,0,0,0,0,0,0,0,0,0,0
0,0,0,0,0,0,0,0,0,0,0
0,0,0,0,0,0,0,0,0,0,0
0,0,0,0,0,0,0,0,0,0,0
0,0,0,0,0,0,0,0,0,0,0
0,0,0,0,0,0,0,0,0,0,0
0,0,0,0,0,0,0,0,0,0,0
0,0,0,0,0,0,0,0,0,0,0
0,0,0,0,0,0,0,0,0,0,0
0,0,0,0,0,0,0,0,0,0,0
0,0,0,0,0,0,0,0,0,0,0
endlayer

layer
0,0,0,0,0,0,0,0,0,0,0
0,0,0,0,0,0,0,0,0,0,0
0,0,0,0,0,0,0,0,0,0,0
0,0,0,7,0,0,0,4,0,0,0
0,0,0,0,0,0,0,0,0,0,0
0,0,0,0,0,0,0,0,0,0,0
0,0,0,0,0,0,0,0,0,0,0
0,0,0,4,0,0,0,7,0,0,0
0,0,0,0,0,0,0,0,0,0,0
0,0,0,0,0,0,0,0,0,0,0
0,0,0,0,0,0,0,0,0,0,0
0,0,0,0,0,0,0,0,0,0,0
0,0,0,0,0,0,0,0,0,0,0
0,0,0,0,0,0,0,0,0,0,0
0,0,0,0,0,0,0,0,0,0,0
0,0,0,0,0,0,0,0,0,0,0
0,0,0,0,0,0,0,0,0,0,0
0,0,0,0,0,0,0,0,0,0,0
0,0,0,0,0,0,0,0,0,0,0
0,0,0,0,0,0,0,0,0,0,0
0,0,0,0,0,0,0,0,0,0,0
endlayer

layer
0,0,0,0,0,0,0,0,0,0,0
0,0,0,0,0,0,0,0,0,0,0
0,0,0,11,0,0,0,11,0,0,0
0,0,0,7,0,0,0,3,0,0,0
0,0,0,0,0,0,0,0,0,0,0
0,0,0,0,0,0,0,0,0,0,0
0,0,0,0,0,0,0,0,0,0,0
0,0,0,3,0,0,0,7,0,0,0
0,0,0,11,0,0,0,11,0,0,0
0,0,0,0,0,0,0,0,0,0,0
0,0,0,0,0,0,0,0,0,0,0
0,0,0,0,0,0,0,0,0,0,0
0,0,0,0,0,0,0,0,0,0,0
0,0,0,0,0,0,0,0,0,0,0
0,0,0,0,0,0,0,0,0,0,0
0,0,0,0,0,0,0,0,0,0,0
0,0,0,0,0,0,0,0,0,0,0
0,0,0,0,0,0,0,0,0,0,0
0,0,0,0,0,0,0,0,0,0,0
0,0,0,0,0,0,0,0,0,0,0
0,0,0,0,0,0,0,0,0,0,0
endlayer

layer
0,0,0,0,0,0,0,0,0,0,0
0,0,0,0,0,0,0,0,0,0,0
0,0,0,3,0,0,0,4,0,0,0
0,0,7,3,3,3,3,3,3,0,0
0,0,0,3,0,0,0,3,0,0,0
0,0,0,3,0,0,0,3,0,0,0
0,0,0,3,0,0,0,3,0,0,0
0,0,3,3,3,3,3,3,7,0,0
0,0,0,4,0,0,0,3,0,0,0
0,0,0,0,0,0,0,0,0,0,0
0,0,0,0,0,0,0,0,0,0,0
0,0,0,0,0,0,0,0,0,0,0
0,0,0,0,0,0,0,0,0,0,0
0,0,0,0,0,0,0,0,0,0,0
0,0,0,0,0,0,0,0,0,0,0
0,0,0,0,0,0,0,0,0,0,0
0,0,0,0,0,0,0,0,0,0,0
0,0,0,0,0,0,0,0,0,0,0
0,0,0,0,0,0,0,0,0,0,0
0,0,0,0,0,0,0,0,0,0,0
0,0,0,0,0,0,0,0,0,0,0
endlayer

layer
0,0,0,0,0,0,0,0,0,0,0
0,0,13,13,13,13,4,4,13,0,0
0,13,0,0,0,0,0,0,0,13,0
0,7,0,3,0,0,0,3,0,13,0
0,7,0,0,0,0,0,0,0,13,0
0,13,0,0,0,0,0,0,0,13,0
0,13,0,0,0,0,0,0,0,7,0
0,13,0,3,0,0,0,3,0,7,0
0,13,0,0,0,0,0,0,0,13,0
0,0,13,4,4,13,13,13,13,0,0
0,0,0,0,0,0,0,0,0,0,0
0,0,0,0,0,0,0,0,0,0,0
0,0,0,0,0,0,0,0,0,0,0
0,0,0,0,0,0,0,0,0,0,0
0,0,0,0,0,0,0,0,0,0,0
0,0,0,0,0,0,0,0,0,0,0
0,0,0,0,0,0,0,0,0,0,0
0,0,0,0,0,0,0,0,0,0,0
0,0,0,0,0,0,0,0,0,0,0
0,0,0,0,0,0,0,0,0,0,0
0,0,0,0,0,0,0,0,0,0,0
endlayer

layer
0,0,0,0,0,0,0,0,0,0,0
0,0,0,0,0,0,0,0,0,0,0
0,0,13,13,13,4,4,13,13,0,0
0,0,13,0,0,0,0,0,13,0,0
0,0,7,0,0,0,0,0,13,0,0
0,0,7,0,0,0,0,0,7,0,0
0,0,13,0,0,0,0,0,7,0,0
0,0,13,0,0,0,0,0,13,0,0
0,0,13,13,4,4,13,13,13,0,0
0,0,0,0,0,0,0,0,0,0,0
0,0,0,0,0,0,0,0,0,0,0
0,0,0,0,0,0,0,0,0,0,0
0,0,0,0,0,0,0,0,0,0,0
0,0,0,0,0,0,0,0,0,0,0
0,0,0,0,0,0,0,0,0,0,0
0,0,0,0,0,0,0,0,0,0,0
0,0,0,0,0,0,0,0,0,0,0
0,0,0,0,0,0,0,0,0,0,0
0,0,0,0,0,0,0,0,0,0,0
0,0,0,0,0,0,0,0,0,0,0
0,0,0,0,0,0,0,0,0,0,0
endlayer

layer
0,0,0,0,0,0,0,0,0,0,0
0,0,0,0,0,0,0,0,0,0,0
0,0,0,0,0,0,0,0,0,0,0
0,0,0,13,4,4,13,13,0,0,0
0,0,0,13,0,0,0,7,0,0,0
0,0,0,7,0,0,0,7,0,0,0
0,0,0,7,0,0,0,13,0,0,0
0,0,0,13,13,4,4,13,0,0,0
0,0,0,0,0,0,0,0,0,0,0
0,0,0,0,0,0,0,0,0,0,0
0,0,0,0,0,0,0,0,0,0,0
0,0,0,0,0,0,0,0,0,0,0
0,0,0,0,0,0,0,0,0,0,0
0,0,0,0,0,0,0,0,0,0,0
0,0,0,0,0,0,0,0,0,0,0
0,0,0,0,0,0,0,0,0,0,0
0,0,0,0,0,0,0,0,0,0,0
0,0,0,0,0,0,0,0,0,0,0
0,0,0,0,0,0,0,0,0,0,0
0,0,0,0,0,0,0,0,0,0,0
0,0,0,0,0,0,0,0,0,0,0
endlayer

layer
0,0,0,0,0,0,0,0,0,0,0
0,0,0,0,0,0,0,0,0,0,0
0,0,0,0,0,0,0,0,0,0,0
0,0,0,0,0,0,0,0,0,0,0
0,0,0,0,4,13,7,0,0,0,0
0,0,0,0,13,0,3,0,0,0,0
0,0,0,0,7,13,4,0,0,0,0
0,0,0,0,0,0,0,0,0,0,0
0,0,0,0,0,0,0,0,0,0,0
0,0,0,0,0,0,0,0,0,0,0
0,0,0,0,0,0,0,0,0,0,0
0,0,0,0,0,0,0,0,0,0,0
0,0,0,0,0,0,0,0,0,0,0
0,0,0,0,0,0,0,0,0,0,0
0,0,0,0,0,0,0,0,0,0,0
0,0,0,0,0,0,0,0,0,0,0
0,0,0,0,0,0,0,0,0,0,0
0,0,0,0,0,0,0,0,0,0,0
0,0,0,0,0,0,0,0,0,0,0
0,0,0,0,0,0,0,0,0,0,0
0,0,0,0,0,0,0,0,0,0,0
endlayer

layer
0,0,0,0,0,0,0,0,0,0,0
0,0,0,0,0,0,0,0,0,0,0
0,0,0,0,0,0,0,0,0,0,0
0,0,0,0,0,0,0,0,0,0,0
0,0,0,0,0,0,0,0,0,0,0
0,0,0,0,0,13,0,0,0,0,0
0,0,0,0,0,0,0,0,0,0,0
0,0,0,0,0,0,0,0,0,0,0
0,0,0,0,0,0,0,0,0,0,0
0,0,0,0,0,0,0,0,0,0,0
0,0,0,0,0,0,0,0,0,0,0
0,0,0,0,0,0,0,0,0,0,0
0,0,0,0,0,0,0,0,0,0,0
0,0,0,0,0,0,0,0,0,0,0
0,0,0,0,0,0,0,0,0,0,0
0,0,0,0,0,0,0,0,0,0,0
0,0,0,0,0,0,0,0,0,0,0
0,0,0,0,0,0,0,0,0,0,0
0,0,0,0,0,0,0,0,0,0,0
0,0,0,0,0,0,0,0,0,0,0
0,0,0,0,0,0,0,0,0,0,0
endlayer

