
# Created by Ruins mod version 14.7 Ingame Parser
# authoring Player: OneWolfe

weight=10
unique=1
embed_into_distance=21
biomesToSpawnIn=jungle,forest,plains
acceptable_target_blocks=
unacceptable_target_blocks=flowing_water,water,flowing_lava,lava
dimensions=27,25,25
allowable_overhang=4
max_leveling=4
leveling_buffer=0
preserve_water=0
preserve_lava=0
preserve_plants=1

rule1=0,100,TwilightForest:tile.TFMazestone-1
rule2=0,100,TwilightForest:tile.TFMazestone-7
rule3=0,100,MobSpawner:TwilightForest.Minotaur,MobSpawner:TwilightForest.Minotaur,MobSpawner:TwilightForest.Maze Slime,MobSpawner:TwilightForest.Mosquito Swarm,MobSpawner:caveSpiderTFC,air
rule4=0,100,TwilightForest:tile.TFMazestone-6
rule5=0,100,ChestGenHook:dungeonChest:5-3,ChestGenHook:dungeonChest:5-3,ChestGenHook:dungeonChest:5-3,air
rule6=0,100,ChestGenHook:dungeonChest:5-4,ChestGenHook:dungeonChest:5-4,ChestGenHook:dungeonChest:5-4,air
rule7=0,100,TwilightForest:tile.TFTrophyPedestal-1
rule8=0,100,TwilightForest:tile.TFTrophyPedestal-3
rule9=0,100,TwilightForest:tile.TFTowerDevice-0
rule10=0,100,TwilightForest:tile.TFTrophyPedestal-2
rule11=0,100,TwilightForest:tile.TFMazestone-3
rule12=0,100,MobSpawner:TwilightForest.Minoshroom
rule13=0,100,TwilightForest:tile.TFMazestone-2
rule14=0,100,BiblioWoodsTFC:BiblioBrassLantern-1
rule15=0,100,minecraft:bedrock-0
rule16=0,100,ChestGenHook:dungeonChest:5-2,ChestGenHook:dungeonChest:5-2,ChestGenHook:dungeonChest:5-2,air
rule17=0,100,terrafirmacraft:Fence-9
rule18=0,100,preserveBlock
rule19=0,100,TwilightForest:tile.TFHedge-0
rule20=0,100,terrafirmacraft:planks-9

layer
1,1,1,1,1,1,1,1,1,1,1,1,1,1,1,1,1,1,1,1,1,1,1,1,1
1,2,2,2,2,2,2,2,2,2,2,2,2,2,2,1,2,2,2,2,2,2,2,2,1
1,2,2,2,2,2,2,2,2,2,2,2,2,2,2,1,2,2,2,2,2,2,2,2,1
1,2,2,1,1,1,1,1,1,1,1,1,1,2,2,1,2,2,1,2,2,1,1,1,1
1,2,2,1,2,2,2,2,2,2,2,2,1,2,2,1,2,2,1,2,2,2,2,2,1
1,2,2,1,2,2,2,2,2,2,2,2,1,2,2,1,2,2,1,2,2,2,2,2,1
1,2,2,1,2,2,1,2,2,1,1,1,1,1,1,1,2,2,1,1,3,1,1,1,1
1,2,2,1,2,2,1,2,2,1,2,2,4,2,2,1,2,2,2,2,2,2,2,2,1
1,2,2,1,2,2,1,2,2,1,2,2,2,2,2,1,2,2,2,2,2,2,2,2,1
1,2,2,1,2,2,1,1,1,4,2,4,2,4,2,4,1,1,1,2,2,1,2,2,1
1,2,2,1,2,2,1,2,2,2,4,2,2,2,4,2,2,2,1,2,2,1,2,2,1
1,2,2,2,2,2,2,2,2,4,2,4,2,4,2,4,2,2,1,2,2,1,2,2,1
1,2,2,2,2,2,2,4,2,2,2,2,4,2,2,2,2,4,1,2,2,1,2,2,1
1,2,2,2,2,2,2,2,2,4,2,4,2,4,2,4,2,2,1,2,2,1,2,2,1
1,2,2,1,2,2,1,2,2,2,4,2,2,2,4,2,2,2,1,2,2,1,2,2,1
1,2,2,1,2,2,1,1,1,4,2,4,2,4,2,4,1,1,1,1,1,1,2,2,1
1,2,2,1,2,2,2,2,2,1,2,2,2,2,2,1,1,1,1,1,1,1,2,2,1
1,2,2,1,2,2,2,2,2,1,2,2,4,2,2,1,1,2,2,2,2,2,2,2,1
1,2,2,1,2,2,1,1,1,1,1,1,1,1,1,1,1,2,2,2,2,2,2,2,1
1,2,2,1,2,2,2,2,2,1,2,2,2,2,2,1,1,2,2,2,2,2,2,2,1
1,2,2,1,2,2,2,2,2,1,2,2,2,2,2,1,1,2,2,2,2,2,2,2,1
1,2,2,3,1,1,1,2,2,1,2,2,1,2,2,1,1,2,2,2,2,2,2,2,1
1,2,2,2,2,2,2,2,2,2,2,2,1,2,2,2,2,2,2,2,2,2,2,2,1
1,2,2,2,2,2,2,2,2,2,2,2,1,2,2,2,2,2,2,2,2,2,2,2,1
1,1,1,1,1,1,1,1,1,1,1,1,1,1,1,1,1,1,1,1,1,1,1,1,1
endlayer

layer
1,1,1,1,1,1,1,1,1,1,1,1,1,1,1,1,1,1,1,1,1,1,1,1,1
1,0,0,0,0,0,0,0,0,0,0,0,0,0,0,1,0,0,0,0,0,0,0,0,1
1,0,0,0,0,0,0,0,0,0,0,0,0,0,0,1,0,0,0,0,0,0,0,0,1
1,0,0,1,1,1,1,1,1,1,1,1,1,0,0,1,0,0,1,0,0,1,1,1,1
1,0,0,1,0,0,0,0,0,0,0,0,1,0,0,1,0,0,1,0,0,0,0,5,1
1,0,0,1,0,0,0,0,0,0,0,0,1,6,6,1,0,0,1,0,0,0,0,5,1
1,0,0,1,0,0,1,0,0,1,1,1,1,1,1,1,0,0,1,1,1,1,1,1,1
1,0,0,1,0,0,1,0,0,1,0,7,0,7,0,1,0,0,0,0,0,0,0,0,1
1,0,0,1,0,0,1,0,0,1,0,0,0,0,0,1,0,0,0,0,0,0,0,0,1
1,0,0,1,0,0,1,1,1,0,0,0,0,0,0,0,1,1,1,0,0,1,0,0,1
1,0,0,1,0,0,1,0,0,0,0,0,0,0,0,0,0,0,1,0,0,1,0,0,1
1,0,0,0,0,0,9,0,0,0,0,0,0,0,0,0,0,8,1,0,0,1,0,0,1
1,0,0,0,0,0,9,0,0,0,0,0,8,0,0,0,0,0,1,0,0,1,0,0,1
1,0,0,0,0,0,9,0,0,0,0,0,0,0,0,0,0,8,1,0,0,1,0,0,1
1,0,0,1,0,0,1,0,0,0,0,0,0,0,0,0,0,0,1,0,0,1,0,0,1
1,0,0,1,0,0,1,1,1,0,0,0,0,0,0,0,1,1,1,1,1,1,0,0,1
1,0,0,1,0,0,0,0,0,1,0,0,0,0,0,1,1,1,1,1,1,1,0,0,1
1,0,0,1,0,0,0,0,0,1,0,10,0,10,0,1,1,0,0,0,0,0,0,0,1
1,0,0,1,0,0,1,1,1,1,1,1,1,1,1,1,1,0,0,0,1,0,0,0,1
1,0,0,1,0,0,0,0,0,1,0,0,0,0,0,1,1,0,0,0,0,0,0,0,1
1,0,0,1,0,0,0,0,0,1,0,0,0,0,0,1,1,0,1,0,0,0,1,0,1
1,0,0,1,1,1,1,0,0,1,0,0,1,0,0,1,1,0,0,0,0,0,0,0,1
1,0,0,0,0,0,0,0,0,0,0,0,1,0,0,0,0,0,0,0,1,0,0,0,1
1,0,0,0,0,0,0,0,0,0,0,0,1,0,0,0,0,0,0,0,0,0,0,0,1
1,1,1,1,1,1,1,1,1,1,1,1,1,1,1,1,1,1,1,1,1,1,1,1,1
endlayer

layer
11,11,11,11,11,11,11,11,11,11,11,11,11,11,11,11,11,11,11,11,11,11,11,11,11
11,0,0,0,0,0,0,0,0,0,0,0,0,0,0,11,0,0,0,0,0,0,0,0,11
11,0,0,0,0,0,0,0,0,0,0,0,0,0,0,11,0,0,0,0,0,0,0,0,11
11,0,0,11,11,11,11,11,11,11,11,11,11,0,0,11,0,0,11,0,0,11,11,11,11
11,0,0,11,0,0,0,0,0,0,0,0,11,0,0,11,0,0,11,0,0,0,0,0,11
11,0,0,11,0,0,0,0,0,0,0,0,11,0,0,11,0,0,11,0,0,0,0,0,11
11,0,0,11,0,0,11,0,0,11,11,11,11,11,11,11,0,0,11,11,11,11,11,11,11
11,0,0,11,0,0,11,0,0,11,0,0,0,0,0,11,0,0,0,0,0,0,0,0,11
11,0,0,11,0,0,11,0,0,11,0,0,0,0,0,11,0,0,0,0,0,0,0,0,11
11,0,0,11,0,0,11,11,11,0,0,0,0,0,0,0,11,11,11,0,0,11,0,0,11
11,0,0,11,0,0,11,0,0,0,0,0,0,0,0,0,0,0,11,0,0,11,0,0,11
11,0,0,0,0,0,9,0,0,0,0,0,0,0,0,0,0,5,11,0,0,11,0,0,11
11,0,0,0,0,0,9,0,0,0,0,0,12,0,0,0,0,0,11,0,0,11,0,0,11
11,0,0,0,0,0,9,0,0,0,0,0,0,0,0,0,0,5,11,0,0,11,0,0,11
11,0,0,11,0,0,11,0,0,0,0,0,0,0,0,0,0,0,11,0,0,11,0,0,11
11,0,0,11,0,0,11,11,11,0,0,0,0,0,0,0,11,11,11,11,11,11,0,0,11
11,0,0,11,0,0,0,0,0,11,0,0,0,0,0,11,11,11,11,11,11,11,0,0,11
11,0,0,11,0,0,0,0,0,11,0,0,0,0,0,11,11,0,0,0,0,0,0,0,11
11,0,0,11,0,0,11,11,11,11,11,11,11,11,11,11,11,0,0,0,11,0,0,0,11
11,0,0,11,0,0,0,0,0,11,0,0,0,0,0,11,11,0,0,0,0,0,0,0,11
11,0,0,11,0,0,0,0,0,11,0,0,0,0,0,11,11,0,11,0,0,0,11,0,11
11,0,0,11,11,11,11,0,0,11,0,0,11,0,0,11,11,0,0,0,0,0,0,0,11
11,0,0,0,0,0,0,0,0,0,0,0,11,0,0,0,0,0,0,0,11,0,0,0,11
11,0,0,0,0,0,0,0,0,0,0,0,11,0,0,0,0,0,0,0,0,0,0,0,11
11,11,11,11,11,11,11,11,11,11,11,11,11,11,11,11,11,11,11,11,11,11,11,11,11
endlayer

layer
13,13,13,13,13,13,13,13,13,13,13,13,13,13,13,13,13,13,13,13,13,13,13,13,13
13,0,0,0,0,0,0,0,0,0,0,0,0,0,0,13,0,0,0,0,0,0,0,0,13
13,0,0,0,0,0,0,0,0,0,0,0,0,0,0,13,0,0,0,0,0,0,0,0,13
13,0,0,13,13,13,13,13,13,13,13,13,13,0,0,13,0,0,13,0,0,13,13,13,13
13,0,0,13,0,0,0,0,0,0,0,0,13,0,0,13,0,0,13,0,0,0,0,0,13
13,0,0,13,0,0,0,0,0,0,0,0,13,0,0,13,0,0,13,0,0,0,0,0,13
13,0,0,13,0,0,13,0,0,13,13,13,13,13,13,13,0,0,13,13,13,13,13,13,13
13,0,0,13,0,0,13,0,0,13,0,0,0,0,0,13,0,0,0,0,0,0,0,0,13
13,0,0,13,0,0,13,0,0,13,0,0,0,0,0,13,0,0,0,0,0,0,0,0,13
13,0,0,13,0,0,13,13,13,0,0,0,0,0,0,0,13,13,13,0,0,13,0,0,13
13,0,0,13,0,0,13,0,0,0,0,0,0,0,0,0,0,0,13,0,0,13,0,0,13
13,0,0,0,0,0,9,0,0,0,0,0,0,0,0,0,0,0,13,0,0,13,0,0,13
13,0,0,0,0,0,9,0,0,0,0,0,0,0,0,0,0,0,13,0,0,13,0,0,13
13,0,0,0,0,0,9,0,0,0,0,0,0,0,0,0,0,0,13,0,0,13,0,0,13
13,0,0,13,0,0,13,0,0,0,0,0,0,0,0,0,0,0,13,0,0,13,0,0,13
13,0,0,13,0,0,13,13,13,0,0,0,0,0,0,0,13,13,13,13,13,13,0,0,13
13,0,0,13,0,0,0,0,0,13,0,0,0,0,0,13,13,13,13,13,13,13,0,0,13
13,0,0,13,0,0,0,0,0,13,0,0,0,0,0,13,13,0,0,0,0,0,0,0,13
13,0,0,13,0,0,13,13,13,13,13,13,13,13,13,13,13,0,0,0,13,0,0,0,13
13,0,0,13,0,0,0,0,0,13,0,0,0,0,0,13,13,0,0,0,0,0,0,0,13
13,0,0,13,0,0,0,0,0,13,0,0,0,0,0,13,13,0,13,0,0,14,13,0,13
13,0,0,13,13,13,13,0,0,13,0,0,13,0,0,13,13,0,0,0,0,0,0,0,13
13,0,0,0,0,0,0,0,0,0,0,0,13,0,0,0,0,0,0,0,13,0,0,0,13
13,0,0,0,0,0,0,0,0,0,0,0,13,0,0,0,0,0,0,0,0,0,0,0,13
13,13,13,13,13,13,13,13,13,13,13,13,13,13,13,13,13,13,13,13,13,13,13,13,13
endlayer

layer
1,1,1,1,1,1,1,1,1,1,1,1,1,1,1,1,1,1,1,1,1,1,1,1,1
1,0,0,0,0,0,0,0,0,0,0,0,0,0,0,1,0,0,0,0,0,0,0,0,1
1,0,0,0,0,0,0,0,0,0,0,0,0,0,0,1,0,0,0,0,0,0,0,0,1
1,0,0,1,1,1,1,1,1,1,1,1,1,0,0,1,0,0,1,0,0,1,1,1,1
1,0,0,1,0,0,0,0,0,0,0,0,1,0,0,1,0,0,1,0,0,0,0,0,1
1,0,0,1,0,0,0,0,0,0,0,0,1,0,0,1,0,0,1,0,0,0,0,0,1
1,0,0,1,0,0,1,0,0,1,1,1,1,1,1,1,0,0,1,1,1,1,1,1,1
1,0,0,1,0,0,1,0,0,1,0,0,0,0,0,1,0,0,0,0,0,0,0,0,1
1,0,0,1,0,0,1,0,0,1,0,0,0,0,0,1,0,0,0,0,0,0,0,0,1
1,0,0,1,0,0,1,1,1,0,0,0,0,0,0,0,1,1,1,0,0,1,0,0,1
1,0,0,1,0,0,1,0,0,0,0,0,0,0,0,0,0,0,1,0,0,1,0,0,1
1,0,0,0,0,0,9,0,0,0,0,0,0,0,0,0,0,0,1,0,0,1,0,0,1
1,0,0,0,0,0,9,0,0,0,0,0,0,0,0,0,0,0,1,0,0,1,0,0,1
1,0,0,0,0,0,9,0,0,0,0,0,0,0,0,0,0,0,1,0,0,1,0,0,1
1,0,0,1,0,0,1,0,0,0,0,0,0,0,0,0,0,0,1,0,0,1,0,0,1
1,0,0,1,0,0,1,1,1,0,0,0,0,0,0,0,1,1,1,1,1,1,0,0,1
1,0,0,1,0,0,0,0,0,1,0,0,0,0,0,1,1,1,1,1,1,1,0,0,1
1,0,0,1,0,0,0,0,0,1,0,0,0,0,0,1,1,0,0,0,0,0,0,0,1
1,0,0,1,0,0,1,1,1,1,1,1,1,1,1,1,1,0,0,0,1,0,0,0,1
1,0,0,1,0,0,0,0,0,1,0,0,0,0,0,1,1,0,0,0,0,0,0,0,1
1,0,0,1,0,0,0,0,0,1,0,0,0,0,0,1,1,0,1,0,0,0,1,0,1
1,0,0,1,1,1,1,0,0,1,0,0,1,0,0,1,1,0,0,0,0,0,0,0,1
1,0,0,0,0,0,0,0,0,0,0,0,1,0,0,0,0,0,0,0,1,0,0,0,1
1,0,0,0,0,0,0,0,0,0,0,0,1,0,0,0,0,0,0,0,0,0,0,0,1
1,1,1,1,1,1,1,1,1,1,1,1,1,1,1,1,1,1,1,1,1,1,1,1,1
endlayer

layer
1,1,1,1,1,1,1,1,1,1,1,1,1,1,1,1,1,1,1,1,1,1,1,1,1
1,1,1,1,1,1,1,1,1,1,1,1,1,1,1,1,1,1,1,1,1,1,1,1,1
1,1,1,1,1,1,1,1,1,1,1,1,1,1,1,1,1,1,1,1,1,1,1,1,1
1,1,1,1,1,1,1,1,1,1,1,1,1,1,1,1,1,1,1,1,1,1,1,1,1
1,1,1,1,1,1,1,1,1,1,1,1,1,1,1,1,1,1,1,1,1,1,1,1,1
1,1,1,1,1,1,1,1,1,1,1,1,1,1,1,1,1,1,1,1,1,1,1,1,1
1,1,1,1,1,1,1,1,1,1,1,1,1,1,1,1,1,1,1,1,1,1,1,1,1
1,1,1,1,1,1,1,1,1,1,0,0,0,0,0,1,1,1,1,1,1,1,1,1,1
1,1,1,1,1,1,1,1,1,1,0,0,0,0,0,1,1,1,1,1,1,1,1,1,1
1,1,1,1,1,1,1,1,1,0,0,0,0,0,0,0,1,1,1,1,1,1,1,1,1
1,1,1,1,1,1,1,0,0,0,0,0,0,0,0,0,0,0,1,1,1,1,1,1,1
1,1,1,1,1,1,1,0,0,0,0,0,0,0,0,0,0,0,1,1,1,1,1,1,1
1,1,1,1,1,1,1,0,0,0,0,0,0,0,0,0,0,0,1,1,1,1,1,1,1
1,1,1,1,1,1,1,0,0,0,0,0,0,0,0,0,0,0,1,1,1,1,1,1,1
1,1,1,1,1,1,1,0,0,0,0,0,0,0,0,0,0,0,1,1,1,1,1,1,1
1,1,1,1,1,1,1,1,1,0,0,0,0,0,0,0,1,1,1,1,1,1,1,1,1
1,1,1,1,1,1,1,1,1,1,0,0,0,0,0,1,1,1,1,1,1,1,1,1,1
1,1,1,1,1,1,1,1,1,1,0,0,0,0,0,1,1,1,1,1,1,1,1,1,1
1,1,1,1,1,1,1,1,1,1,1,1,1,1,1,1,1,1,1,1,13,1,1,1,1
1,1,1,1,1,1,1,1,1,1,1,1,1,1,1,1,1,1,1,0,0,0,1,1,1
1,1,1,1,1,1,1,1,1,1,1,1,1,1,1,1,1,1,13,0,0,0,13,1,1
1,1,1,1,1,1,1,1,1,1,1,1,1,1,1,1,1,1,1,0,0,0,1,1,1
1,1,1,1,1,1,1,1,1,1,1,1,1,1,1,1,1,1,1,1,13,1,1,1,1
1,1,1,1,1,1,1,1,1,1,1,1,1,1,1,1,1,1,1,1,1,1,1,1,1
1,1,1,1,1,1,1,1,1,1,1,1,1,1,1,1,1,1,1,1,1,1,1,1,1
endlayer

layer
1,1,1,1,1,1,1,1,1,1,1,1,1,1,1,1,1,1,1,1,1,1,1,1,1
1,15,15,15,15,15,15,15,15,15,15,15,15,15,15,15,15,15,15,15,15,15,15,15,1
1,15,15,15,15,15,15,15,15,15,15,15,15,15,15,15,15,15,15,15,15,15,15,15,1
1,15,15,15,15,15,15,15,15,15,15,15,15,15,15,15,15,15,15,15,15,15,15,15,1
1,15,15,15,15,15,15,15,15,15,15,15,15,15,15,15,15,15,15,15,15,15,15,15,1
1,15,15,15,15,15,15,15,15,15,15,15,15,15,15,15,15,15,15,15,15,15,15,15,1
1,15,15,15,15,15,15,15,15,15,15,15,15,15,15,15,15,15,15,15,15,15,15,15,1
1,15,15,15,15,15,15,15,15,15,1,1,1,1,1,15,15,15,15,15,15,15,15,15,1
1,15,15,15,15,15,15,15,15,15,1,0,0,0,1,15,15,15,15,15,15,15,15,15,1
1,15,15,15,15,15,15,15,15,1,1,0,0,0,1,1,15,15,15,15,15,15,15,15,1
1,15,15,15,15,15,15,1,1,1,0,0,0,0,0,1,1,1,15,15,15,15,15,15,1
1,15,15,15,15,15,15,1,0,0,0,0,0,0,0,0,0,1,15,15,15,15,15,15,1
1,15,15,15,15,15,15,1,0,0,0,0,0,0,0,0,0,1,15,15,15,15,15,15,1
1,15,15,15,15,15,15,1,0,0,0,0,0,0,0,0,0,1,15,15,15,15,15,15,1
1,15,15,15,15,15,15,1,1,1,0,0,0,0,0,1,1,1,15,15,15,15,15,15,1
1,15,15,15,15,15,15,15,15,1,1,0,0,0,1,1,15,15,15,15,15,15,15,15,1
1,15,15,15,15,15,15,15,15,15,1,0,0,0,1,15,15,15,15,15,15,15,15,15,1
1,15,15,15,15,15,15,15,15,15,1,1,1,1,1,15,15,15,15,15,15,15,15,15,1
1,15,15,15,15,15,15,15,15,15,15,15,15,15,15,15,15,15,1,11,13,11,1,15,1
1,15,15,15,15,15,15,15,15,15,15,15,15,15,15,15,15,15,11,0,0,0,11,15,1
1,15,15,15,15,15,15,15,15,15,15,15,15,15,15,15,15,15,13,0,0,0,13,15,1
1,15,15,15,15,15,15,15,15,15,15,15,15,15,15,15,15,15,11,0,0,0,11,15,1
1,15,15,15,15,15,15,15,15,15,15,15,15,15,15,15,15,15,1,11,13,11,1,15,1
1,15,15,15,15,15,15,15,15,15,15,15,15,15,15,15,15,15,15,15,15,15,15,15,1
1,1,1,1,1,1,1,1,1,1,1,1,1,1,1,1,1,1,1,1,1,1,1,1,1
endlayer

layer
1,1,1,1,1,1,1,1,1,1,1,1,1,1,1,1,1,1,1,1,1,1,1,1,1
1,1,1,1,1,1,1,1,1,1,1,1,1,1,1,1,1,1,1,1,1,1,1,1,1
1,1,1,1,1,1,1,1,1,1,1,1,1,1,1,1,1,1,1,1,1,1,1,1,1
1,1,1,1,1,1,1,1,1,1,1,1,1,1,1,1,1,1,1,1,1,1,1,1,1
1,1,1,1,1,1,1,1,1,1,1,1,1,1,1,1,1,1,1,1,1,1,1,1,1
1,1,1,1,1,1,1,1,1,1,1,1,1,1,1,1,1,1,1,1,3,1,1,1,1
1,1,1,1,1,1,1,1,1,1,1,1,1,1,1,1,1,1,1,1,1,1,1,1,1
1,1,1,1,1,1,1,1,1,1,1,1,1,1,1,1,1,1,1,1,1,1,1,1,1
1,1,1,1,1,1,1,1,1,1,1,1,1,1,1,1,1,1,1,1,1,1,1,1,1
1,1,1,1,1,1,1,1,1,1,1,1,4,1,1,1,1,1,1,1,1,1,1,1,1
1,1,1,1,1,1,1,1,1,1,1,1,2,1,1,1,1,1,1,1,1,1,1,1,1
1,1,1,1,1,1,1,1,1,1,1,4,2,4,1,1,1,1,1,1,1,1,1,1,1
1,1,1,1,1,1,1,1,1,4,2,2,4,2,2,4,1,1,1,1,1,1,1,1,1
1,1,1,1,1,1,1,1,1,1,1,4,2,4,1,1,1,1,1,1,1,1,1,1,1
1,1,1,1,1,1,1,1,1,1,1,1,2,1,1,1,1,1,1,1,1,1,1,1,1
1,1,1,1,1,1,1,1,1,1,1,1,4,1,1,1,1,1,1,1,1,3,1,1,1
1,1,1,1,1,1,1,1,1,1,1,1,1,1,1,1,1,1,1,1,1,1,1,1,1
1,1,3,1,1,1,1,1,1,1,1,1,1,1,1,1,1,1,1,1,1,1,1,1,1
1,1,1,1,1,1,1,1,1,1,1,1,1,1,1,1,1,1,1,1,13,1,1,1,1
1,1,1,1,1,1,1,1,1,1,1,1,1,1,1,1,1,1,1,0,0,0,1,1,1
1,1,1,1,1,1,1,1,1,1,1,1,1,1,1,1,1,1,13,0,0,0,13,1,1
1,1,1,1,1,1,1,1,1,1,1,1,1,1,1,1,1,1,1,0,0,0,1,1,1
1,1,1,1,1,1,1,1,1,1,1,1,1,1,1,1,1,1,1,1,13,1,1,1,1
1,1,1,1,1,1,1,1,1,1,1,1,1,1,1,1,1,1,1,1,1,1,1,1,1
1,1,1,1,1,1,1,1,1,1,1,1,1,1,1,1,1,1,1,1,1,1,1,1,1
endlayer

layer
1,1,1,1,1,1,1,1,1,1,1,1,1,1,1,1,1,1,1,1,1,1,1,1,1
1,0,0,0,0,0,0,0,1,0,0,0,0,0,0,0,1,0,0,0,0,0,0,1,1
1,0,0,0,1,0,0,0,1,0,0,0,0,0,0,0,1,0,0,0,0,0,0,1,1
1,0,0,0,0,0,0,0,1,0,0,1,1,1,0,0,1,1,0,0,1,0,0,1,1
1,0,1,0,0,0,1,0,1,0,0,0,0,1,0,0,0,0,0,0,1,0,0,1,1
1,0,0,0,0,0,0,0,1,0,0,0,0,1,0,0,0,0,0,0,1,0,0,1,1
1,0,0,0,1,0,0,0,1,1,1,0,0,1,1,1,1,1,1,1,1,0,0,1,1
1,0,0,0,0,0,0,0,0,0,0,0,0,0,0,0,0,0,1,0,0,0,0,1,1
1,1,1,1,1,1,1,0,0,0,0,0,0,0,0,0,0,0,1,0,0,0,0,1,1
1,0,0,0,0,0,1,0,0,1,1,1,1,1,1,1,0,0,1,0,0,1,1,1,1
1,0,0,0,0,0,1,0,0,1,15,15,15,1,0,0,0,0,1,0,0,0,0,1,1
1,0,0,1,0,0,1,0,0,1,15,15,15,1,0,0,0,0,1,0,0,0,0,1,1
1,0,0,1,0,0,0,0,0,1,15,15,15,1,1,1,0,0,1,1,1,0,0,1,1
1,0,0,1,0,0,0,0,0,1,1,1,1,1,1,1,0,0,1,16,0,0,0,1,1
1,0,0,1,1,1,1,0,0,1,0,0,1,0,0,0,0,0,1,16,0,0,0,1,1
1,0,0,0,0,0,1,0,0,1,0,0,1,0,0,0,0,0,1,1,1,1,1,1,1
1,0,0,0,0,0,1,0,0,0,0,0,1,0,0,1,1,1,1,1,1,1,1,1,1
1,1,1,1,0,0,1,0,0,0,0,0,1,0,0,1,1,0,0,0,0,0,0,0,1
1,0,0,1,0,0,1,1,1,1,1,1,1,1,1,1,1,0,0,0,1,0,0,0,1
1,0,0,0,0,0,1,0,0,0,0,0,0,0,0,0,1,0,0,0,0,0,0,0,1
1,0,0,0,0,0,1,0,0,0,0,0,0,0,0,0,1,0,1,0,0,0,1,0,1
1,0,0,1,1,1,1,0,0,1,1,0,0,1,0,0,1,0,0,0,0,0,0,0,1
1,0,0,0,0,0,0,0,0,1,0,0,0,1,0,0,0,0,0,0,1,0,0,0,1
1,0,0,0,0,0,0,0,0,1,0,0,0,1,0,0,0,0,0,0,0,0,0,0,1
1,1,1,1,1,1,1,1,1,1,1,1,1,1,1,1,1,1,1,1,1,1,1,1,1
endlayer

layer
11,11,11,11,11,11,11,11,11,11,11,11,11,11,11,11,11,11,11,11,11,11,11,11,11
11,0,0,0,0,0,0,0,11,0,0,0,0,0,0,0,11,0,0,0,0,0,0,11,11
11,0,0,0,11,0,0,0,11,0,0,0,0,0,0,0,11,0,0,0,0,0,0,11,11
11,0,0,0,0,0,0,0,11,0,0,11,11,11,0,0,11,11,0,0,11,0,0,11,11
11,0,11,0,0,0,11,0,11,0,0,0,0,11,0,0,0,0,0,0,11,0,0,11,11
11,0,0,0,0,0,0,0,11,0,0,0,0,11,0,0,0,0,0,0,11,0,0,11,11
11,0,0,0,11,0,0,0,11,11,11,0,0,11,11,11,11,11,11,11,11,0,0,11,11
11,0,0,0,0,0,0,0,0,0,0,0,0,0,0,0,0,0,11,0,0,0,0,11,11
11,11,11,11,11,11,11,0,0,0,0,0,0,0,0,0,0,0,11,0,0,0,0,11,11
11,0,0,0,0,0,11,0,0,11,11,11,11,11,11,11,0,0,11,0,0,11,11,11,11
11,0,0,0,0,0,11,0,0,11,15,15,15,11,0,0,0,0,11,0,0,0,0,11,11
11,0,0,11,0,0,11,0,0,11,15,15,15,11,0,0,0,0,11,0,0,0,0,11,11
11,0,0,11,0,0,0,0,0,11,15,15,15,11,11,11,0,0,11,11,11,0,0,11,11
11,0,0,11,0,0,0,0,0,11,11,11,11,11,11,11,0,0,11,0,0,0,0,11,11
11,0,0,11,11,11,11,0,0,11,0,0,11,0,0,0,0,0,11,0,0,0,0,11,11
11,0,0,0,0,0,11,0,0,11,0,0,11,0,0,0,0,0,11,11,11,11,11,11,11
11,0,0,0,0,0,11,0,0,0,0,0,11,0,0,11,11,11,11,11,11,11,11,11,11
11,11,11,11,0,0,11,0,0,0,0,0,11,0,0,11,11,0,0,0,0,0,0,0,11
11,0,0,11,0,0,11,11,11,11,11,11,11,11,11,11,11,0,0,0,11,0,0,0,11
11,0,0,0,0,0,11,0,0,0,0,0,0,0,0,0,11,0,0,0,0,0,0,0,11
11,0,0,0,0,0,11,0,0,0,0,0,0,0,0,0,11,0,11,0,0,0,11,0,11
11,0,0,11,11,11,11,0,0,11,11,0,0,11,0,0,11,0,0,0,0,0,0,0,11
11,0,0,0,0,0,0,0,0,11,0,0,0,11,0,0,0,0,0,0,11,0,0,0,11
11,0,0,0,0,0,0,0,0,11,0,0,0,11,0,0,0,0,0,0,0,0,0,0,11
11,11,11,11,11,11,11,11,11,11,11,11,11,11,11,11,11,11,11,11,11,11,11,11,11
endlayer

layer
13,13,13,13,13,13,13,13,13,13,13,13,13,13,13,13,13,13,13,13,13,13,13,13,13
13,0,0,0,0,0,0,0,13,0,0,0,0,0,0,0,13,0,0,0,0,0,0,13,13
13,0,0,0,13,0,0,0,13,0,0,0,0,0,0,0,13,0,0,0,0,0,0,13,13
13,0,0,0,0,0,0,0,13,0,0,13,13,13,0,0,13,13,0,0,13,0,0,13,13
13,0,13,0,0,14,13,0,13,0,0,0,0,13,0,0,0,0,0,0,13,0,0,13,13
13,0,0,0,0,0,0,0,13,0,0,0,0,13,0,0,0,0,0,0,13,0,0,13,13
13,0,0,0,13,0,0,0,13,13,13,0,0,13,13,13,13,13,13,13,13,0,0,13,13
13,0,0,0,0,0,0,0,0,0,0,0,0,0,0,0,0,0,13,0,0,0,0,13,13
13,13,13,13,13,13,13,0,0,0,0,0,0,0,0,0,0,0,13,0,0,0,0,13,13
13,0,0,0,0,0,13,0,0,13,13,13,13,13,13,13,0,0,13,0,0,13,13,13,13
13,0,0,0,0,0,13,0,0,13,15,15,15,13,0,0,0,0,13,0,0,0,0,13,13
13,0,0,13,0,0,13,0,0,13,15,15,15,13,0,0,0,0,13,0,0,0,0,13,13
13,0,0,13,0,0,0,0,0,13,15,15,15,13,13,13,0,0,13,13,13,0,0,13,13
13,0,0,13,0,0,0,0,0,13,13,13,13,13,13,13,0,0,13,0,0,0,0,13,13
13,0,0,13,13,13,13,0,0,13,0,0,13,0,0,0,0,0,13,0,0,0,0,13,13
13,0,0,0,0,0,13,0,0,13,0,0,13,0,0,0,0,0,13,13,13,13,13,13,13
13,0,0,0,0,0,13,0,0,0,0,0,13,0,0,13,13,13,13,13,13,13,13,13,13
13,13,13,13,0,0,13,0,0,0,0,0,13,0,0,13,13,0,0,0,0,0,0,0,13
13,0,0,13,0,0,13,13,13,13,13,13,13,13,13,13,13,0,0,0,13,0,0,0,13
13,0,0,0,0,0,13,0,0,0,0,0,0,0,0,0,13,0,0,0,0,0,0,0,13
13,0,0,0,0,0,13,0,0,0,0,0,0,0,0,0,13,0,13,0,0,0,13,0,13
13,0,0,13,13,13,13,0,0,13,13,0,0,13,0,0,13,0,0,0,0,0,0,0,13
13,0,0,0,0,0,0,0,0,13,0,0,0,13,0,0,0,0,0,0,13,0,0,0,13
13,0,0,0,0,0,0,0,0,13,0,0,0,13,0,0,0,0,0,0,0,0,0,0,13
13,13,13,13,13,13,13,13,13,13,13,13,13,13,13,13,13,13,13,13,13,13,13,13,13
endlayer

layer
1,1,1,1,1,1,1,1,1,1,1,1,1,1,1,1,1,1,1,1,1,1,1,1,1
1,0,0,0,0,0,0,0,1,0,0,0,0,0,0,0,1,0,0,0,0,0,0,1,1
1,0,0,0,1,0,0,0,1,0,0,0,0,0,0,0,1,0,0,0,0,0,0,1,1
1,0,0,0,0,0,0,0,1,0,0,1,1,1,0,0,1,1,0,0,1,0,0,1,1
1,0,1,0,0,0,1,0,1,0,0,0,0,1,0,0,0,0,0,0,1,0,0,1,1
1,0,0,0,0,0,0,0,1,0,0,0,0,1,0,0,0,0,0,0,1,0,0,1,1
1,0,0,0,1,0,0,0,1,1,1,0,0,1,1,1,1,1,1,1,1,0,0,1,1
1,0,0,0,0,0,0,0,0,0,0,0,0,0,0,0,0,0,1,0,0,0,0,1,1
1,1,1,1,1,1,1,0,0,0,0,0,0,0,0,0,0,0,1,0,0,0,0,1,1
1,0,0,0,0,0,1,0,0,1,1,1,1,1,1,1,0,0,1,0,0,1,1,1,1
1,0,0,0,0,0,1,0,0,1,15,15,15,1,0,0,0,0,1,0,0,0,0,1,1
1,0,0,1,0,0,1,0,0,1,15,15,15,1,0,0,0,0,1,0,0,0,0,1,1
1,0,0,1,0,0,0,0,0,1,15,15,15,1,1,1,0,0,1,1,1,0,0,1,1
1,0,0,1,0,0,0,0,0,1,1,1,1,1,1,1,0,0,1,0,0,0,0,1,1
1,0,0,1,1,1,1,0,0,1,0,0,1,0,0,0,0,0,1,0,0,0,0,1,1
1,0,0,0,0,0,1,0,0,1,0,0,1,0,0,0,0,0,1,1,1,1,1,1,1
1,0,0,0,0,0,1,0,0,0,0,0,1,0,0,1,1,1,1,1,1,1,1,1,1
1,1,1,1,0,0,1,0,0,0,0,0,1,0,0,1,1,0,0,0,0,0,0,0,1
1,0,0,1,0,0,1,1,1,1,1,1,1,1,1,1,1,0,0,0,1,0,0,0,1
1,0,0,0,0,0,1,0,0,0,0,0,0,0,0,0,1,0,0,0,0,0,0,0,1
1,0,0,0,0,0,1,0,0,0,0,0,0,0,0,0,1,0,1,0,0,0,1,0,1
1,0,0,1,1,1,1,0,0,1,1,0,0,1,0,0,1,0,0,0,0,0,0,0,1
1,0,0,0,0,0,0,0,0,1,0,0,0,1,0,0,0,0,0,0,1,0,0,0,1
1,0,0,0,0,0,0,0,0,1,0,0,0,1,0,0,0,0,0,0,0,0,0,0,1
1,1,1,1,1,1,1,1,1,1,1,1,1,1,1,1,1,1,1,1,1,1,1,1,1
endlayer

layer
1,1,1,1,1,1,1,1,1,1,1,1,1,1,1,1,1,1,1,1,1,1,1,1,1
1,1,1,1,1,1,1,1,15,1,1,1,1,1,1,1,15,1,1,1,1,1,1,15,1
1,1,1,1,1,1,1,1,15,1,1,1,1,1,1,1,15,1,1,1,1,1,1,15,1
1,1,1,0,0,0,1,1,15,1,1,15,15,15,1,1,15,15,1,1,15,1,1,15,1
1,1,1,0,0,0,1,1,15,1,1,1,1,15,1,1,1,1,1,1,15,1,1,15,1
1,1,1,0,0,0,1,1,15,1,1,1,1,15,1,1,1,1,1,1,15,1,1,15,1
1,1,1,1,1,1,1,1,15,15,15,1,1,15,15,15,15,15,15,15,15,1,1,15,1
1,1,1,1,1,1,1,1,1,1,1,1,1,1,1,1,1,1,15,1,1,1,1,15,1
1,15,15,15,15,15,15,1,1,1,1,1,1,1,1,1,1,1,15,1,1,1,1,15,1
1,1,1,1,1,1,15,1,1,15,15,15,15,15,15,15,1,1,15,1,1,15,15,15,1
1,1,1,1,1,1,15,1,1,15,15,15,15,15,1,1,1,1,15,1,1,1,1,15,1
1,1,1,15,1,1,15,1,1,15,15,15,15,15,1,1,1,1,15,1,1,1,1,15,1
1,1,1,15,1,1,1,1,1,15,15,15,15,15,15,15,1,1,15,15,15,1,1,15,1
1,1,1,15,1,1,1,1,1,15,15,15,15,15,15,15,1,1,15,1,1,1,1,15,1
1,1,1,15,15,15,15,1,1,15,1,1,15,1,1,1,1,1,15,1,1,1,1,15,1
1,1,1,1,1,1,15,1,1,15,1,1,15,1,1,1,1,1,15,15,15,15,15,15,1
1,1,1,1,1,1,15,1,1,1,1,1,15,1,1,15,15,15,15,15,15,15,15,15,1
1,15,15,15,1,1,15,1,1,1,1,1,15,1,1,15,15,1,1,1,1,1,1,1,1
1,1,1,15,1,1,15,15,15,15,15,15,15,15,15,15,15,1,1,1,1,1,1,1,1
1,1,1,1,1,1,15,1,1,1,1,1,1,1,1,1,15,1,1,1,1,1,1,1,1
1,1,1,1,1,1,15,1,1,1,1,1,1,1,1,1,15,1,1,1,1,1,1,1,1
1,1,1,15,15,15,15,1,1,15,15,1,1,15,1,1,15,1,1,1,1,1,1,1,1
1,1,1,1,1,1,1,1,1,15,1,1,1,15,1,1,1,1,1,1,1,1,1,1,1
1,1,1,1,1,1,1,1,1,15,1,1,1,15,1,1,1,1,1,1,1,1,1,1,1
1,1,1,1,1,1,1,1,1,1,1,1,1,1,1,1,1,1,1,1,1,1,1,1,1
endlayer

layer
1,1,1,1,1,1,1,1,1,1,1,1,1,1,1,1,1,1,1,1,1,1,1,1,1
1,15,15,15,15,15,15,15,15,15,15,15,15,15,15,15,15,15,15,15,15,15,15,15,1
1,15,15,1,1,1,15,15,15,15,15,15,15,15,15,15,15,15,15,15,15,15,15,15,1
1,15,1,0,0,0,1,15,15,15,15,15,15,15,15,15,15,15,15,15,15,15,15,15,1
1,15,1,0,0,0,1,15,15,15,15,15,15,15,15,15,15,15,15,15,15,15,15,15,1
1,15,1,0,0,0,1,15,15,15,15,15,15,15,15,15,15,15,15,15,15,15,15,15,1
1,15,15,1,1,1,15,15,15,15,15,15,15,15,15,15,15,15,15,15,15,15,15,15,1
1,15,15,15,15,15,15,15,15,15,15,15,15,15,15,15,15,15,15,15,15,15,15,15,1
1,15,15,15,15,15,15,15,15,15,15,15,15,15,15,15,15,15,15,15,15,15,15,15,1
1,15,15,15,15,15,15,15,15,15,15,15,15,15,15,15,15,15,15,15,15,15,15,15,1
1,15,15,15,15,15,15,15,15,15,15,15,15,15,15,15,15,15,15,15,15,15,15,15,1
1,15,15,15,15,15,15,15,15,15,15,15,15,15,15,15,15,15,15,15,15,15,15,15,1
1,15,15,15,15,15,15,15,15,15,15,15,15,15,15,15,15,15,15,15,15,15,15,15,1
1,15,15,15,15,15,15,15,15,15,15,15,15,15,15,15,15,15,15,15,15,15,15,15,1
1,15,15,15,15,15,15,15,15,15,15,15,15,15,15,15,15,15,15,15,15,15,15,15,1
1,15,15,15,15,15,15,15,15,15,15,15,15,15,15,15,15,15,15,15,15,15,15,15,1
1,15,15,15,15,15,15,15,15,15,15,15,15,15,15,15,15,15,15,15,15,15,15,15,1
1,15,15,15,15,15,15,15,15,15,15,15,15,15,15,15,15,15,15,15,15,15,15,15,1
1,15,15,15,15,15,15,15,15,15,15,15,15,15,15,15,15,15,15,15,15,15,15,15,1
1,15,15,15,15,15,15,15,15,15,15,15,15,15,15,15,15,15,15,15,15,15,15,15,1
1,15,15,15,15,15,15,15,15,15,15,15,15,15,15,15,15,15,15,15,15,15,15,15,1
1,15,15,15,15,15,15,15,15,15,15,15,15,15,15,15,15,15,15,15,15,15,15,15,1
1,15,15,15,15,15,15,15,15,15,15,15,15,15,15,15,15,15,15,15,15,15,15,15,1
1,15,15,15,15,15,15,15,15,15,15,15,15,15,15,15,15,15,15,15,15,15,15,15,1
1,1,1,1,1,1,1,1,1,1,1,1,1,1,1,1,1,1,1,1,1,1,1,1,1
endlayer

layer
1,1,1,1,1,1,1,1,1,1,1,1,1,1,1,1,1,1,1,1,1,1,1,1,1
1,13,13,13,13,13,13,13,13,15,13,13,13,15,13,13,13,13,15,13,13,13,13,13,1
1,13,13,1,1,1,13,13,13,15,13,13,13,15,13,13,13,13,15,13,13,13,13,13,1
1,13,1,0,0,0,1,13,13,15,13,13,15,15,13,13,15,15,15,15,15,15,13,13,1
1,13,1,0,0,0,1,13,13,3,13,13,13,13,13,13,13,13,13,13,13,13,13,13,1
1,13,1,0,0,0,1,15,15,15,13,13,13,13,13,13,13,13,13,13,13,13,13,13,1
1,13,13,1,1,1,15,13,13,15,15,15,15,15,15,15,15,13,13,15,15,15,13,13,1
1,13,13,13,13,13,15,13,13,15,13,13,13,13,13,13,13,13,13,15,13,13,13,13,1
1,13,13,13,13,13,15,13,13,15,13,13,13,13,13,13,13,13,13,15,13,13,13,13,1
1,15,15,15,13,13,15,13,13,15,13,1,13,15,15,15,15,15,15,15,15,15,15,15,1
1,13,13,15,13,13,15,13,13,13,13,13,13,13,13,13,15,13,13,13,13,13,13,13,1
1,13,13,13,13,13,15,13,13,1,13,13,13,1,13,13,15,13,13,13,13,13,13,13,1
1,13,13,13,13,13,15,13,13,13,13,13,13,13,13,13,15,13,13,15,15,15,13,13,1
1,13,13,15,15,15,15,15,15,15,13,1,13,15,13,13,15,13,13,13,13,15,13,13,1
1,13,13,15,13,13,13,13,13,13,13,13,13,15,13,13,15,13,13,13,13,15,13,13,1
1,13,13,15,13,13,13,13,13,13,13,13,13,15,13,13,15,3,13,13,15,15,13,13,1
1,13,13,15,13,13,15,15,15,15,15,15,15,15,13,13,15,15,15,15,15,15,13,13,1
1,13,13,15,13,13,15,15,13,13,13,13,13,15,13,13,13,13,13,13,13,15,13,13,1
1,13,13,15,13,13,15,15,13,13,13,13,13,15,13,13,13,13,13,13,13,15,13,13,1
1,13,13,15,13,13,13,13,13,13,15,13,13,15,15,15,15,15,15,13,13,15,13,13,1
1,13,13,15,13,13,13,13,13,13,15,13,13,13,13,13,13,13,15,13,13,15,13,13,1
1,13,13,15,3,15,15,15,13,13,15,13,13,13,13,13,13,13,15,13,13,15,13,13,1
1,13,13,13,13,13,13,13,13,13,15,13,13,13,13,15,13,13,13,13,13,13,13,13,1
1,13,13,13,13,13,13,13,13,13,15,13,13,13,13,15,13,13,13,13,13,13,13,13,1
1,1,1,1,1,1,1,1,1,1,1,1,1,1,1,1,1,1,1,1,1,1,1,1,1
endlayer

layer
1,1,1,1,1,1,1,1,1,1,1,1,1,1,1,1,1,1,1,1,1,1,1,1,1
1,0,0,0,0,0,0,0,0,1,0,0,0,1,0,0,0,0,1,0,0,0,0,0,1
1,0,0,0,1,0,0,0,0,1,0,0,0,1,0,0,0,0,1,0,0,0,0,0,1
1,0,0,0,0,0,1,0,0,1,0,0,1,1,0,0,1,1,1,1,1,1,0,0,1
1,0,1,0,0,0,1,0,0,1,0,0,0,0,0,0,0,0,0,0,0,0,0,0,1
1,0,0,0,0,0,1,1,1,1,0,0,0,0,0,0,0,0,0,0,0,0,0,0,1
1,0,0,0,1,1,1,0,0,1,1,1,1,1,1,1,1,0,0,1,1,1,0,0,1
1,0,0,0,0,0,1,0,0,1,0,0,0,0,0,0,0,0,0,1,0,0,0,0,1
1,0,0,0,0,0,1,0,0,1,0,0,0,0,0,0,0,0,0,1,0,0,0,0,1
1,1,1,1,0,0,1,0,0,1,0,1,0,1,1,1,1,1,1,1,1,1,1,1,1
1,0,0,1,0,0,1,0,0,0,0,0,0,0,0,0,1,0,0,0,0,0,0,0,1
1,0,0,0,0,0,1,0,0,1,0,0,0,1,0,0,1,0,0,0,0,0,0,0,1
1,0,0,0,0,0,1,0,0,0,0,0,0,0,0,0,1,0,0,1,1,1,0,0,1
1,0,0,1,1,1,1,1,1,1,0,1,0,1,0,0,1,0,0,0,0,1,0,0,1
1,0,0,1,0,0,0,0,0,0,0,0,0,1,0,0,1,0,0,0,5,1,0,0,1
1,0,0,1,0,0,0,0,0,0,0,0,0,1,0,0,1,1,0,6,1,1,0,0,1
1,0,0,1,0,0,1,1,1,1,1,1,1,1,0,0,1,1,1,1,1,1,0,0,1
1,0,0,1,0,0,1,1,0,0,0,0,0,1,0,0,0,0,0,0,0,1,0,0,1
1,0,0,1,0,0,1,1,0,0,0,0,0,1,0,0,0,0,0,0,0,1,0,0,1
1,0,0,1,0,0,0,0,0,0,1,0,0,1,1,1,1,1,1,0,0,1,0,0,1
1,0,0,1,0,0,0,0,0,0,1,0,0,0,0,0,0,0,1,0,0,1,0,0,1
1,0,0,1,1,1,1,1,0,0,1,0,0,0,0,0,0,0,1,0,0,1,0,0,1
1,0,0,0,0,0,0,0,0,0,1,0,0,0,0,1,0,0,0,0,0,0,0,0,1
1,0,0,0,0,0,0,0,0,0,1,0,0,0,0,1,0,0,0,0,0,0,0,0,1
1,1,1,1,1,1,1,1,1,1,1,1,1,1,1,1,1,1,1,1,1,1,1,1,1
endlayer

layer
1,1,1,1,1,1,1,1,1,1,1,1,1,1,1,1,1,1,1,1,1,1,1,1,1
1,0,0,0,0,0,0,0,0,1,0,0,0,1,0,0,0,0,1,0,0,0,0,0,1
1,0,0,0,1,0,0,0,0,1,0,0,0,1,0,0,0,0,1,0,0,0,0,0,1
1,0,0,0,0,0,1,0,0,1,0,0,1,1,0,0,1,1,1,1,1,1,0,0,1
1,0,1,0,0,0,1,0,0,1,0,0,0,0,0,0,0,0,0,0,0,0,0,0,1
1,0,0,0,0,0,1,1,1,1,0,0,0,0,0,0,0,0,0,0,0,0,0,0,1
1,0,0,0,1,1,1,0,0,1,1,1,1,1,1,1,1,0,0,1,1,1,0,0,1
1,0,0,0,0,0,1,0,0,1,0,0,0,0,0,0,0,0,0,1,0,0,0,0,1
1,0,0,0,0,0,1,0,0,1,0,0,0,0,0,0,0,0,0,1,0,0,0,0,1
1,1,1,1,0,0,1,0,0,1,0,1,0,1,1,1,1,1,1,1,1,1,1,1,1
1,0,0,1,0,0,1,0,0,0,0,0,0,0,0,0,1,0,0,0,0,0,0,0,1
1,0,0,0,0,0,1,0,0,1,0,0,0,1,0,0,1,0,0,0,0,0,0,0,1
1,0,0,0,0,0,1,0,0,0,0,0,0,0,0,0,1,0,0,1,1,1,0,0,1
1,0,0,1,1,1,1,1,1,1,0,1,0,1,0,0,1,0,0,0,0,1,0,0,1
1,0,0,1,0,0,0,0,0,0,0,0,0,1,0,0,1,0,0,0,0,1,0,0,1
1,0,0,1,0,0,0,0,0,0,0,0,0,1,0,0,1,1,0,0,1,1,0,0,1
1,0,0,1,0,0,1,1,1,1,1,1,1,1,0,0,1,1,1,1,1,1,0,0,1
1,0,0,1,0,0,1,1,0,0,0,0,0,1,0,0,0,0,0,0,0,1,0,0,1
1,0,0,1,0,0,1,1,0,0,0,0,0,1,0,0,0,0,0,0,0,1,0,0,1
1,0,0,1,0,0,0,0,0,0,1,0,0,1,1,1,1,1,1,0,0,1,0,0,1
1,0,0,1,0,0,0,0,0,0,1,0,0,0,0,0,0,0,1,0,0,1,0,0,1
1,0,0,1,1,1,1,1,0,0,1,0,0,0,0,0,0,0,1,0,0,1,0,0,1
1,0,0,0,0,0,0,0,0,0,1,0,0,0,0,1,0,0,0,0,0,0,0,0,1
1,0,0,0,0,0,0,0,0,0,1,0,0,0,0,1,0,0,0,0,0,0,0,0,1
1,1,1,1,1,1,1,1,1,1,1,1,1,1,1,1,1,1,1,1,1,1,1,1,1
endlayer

layer
1,1,1,1,1,1,1,1,1,1,1,1,1,1,1,1,1,1,1,1,1,1,1,1,1
1,0,0,0,0,0,0,0,0,1,0,0,0,1,0,0,0,0,1,0,0,0,0,0,1
1,0,0,0,1,0,0,0,0,1,0,0,0,1,0,0,0,0,1,0,0,0,0,0,1
1,0,0,0,0,0,1,0,0,1,0,0,1,1,0,0,1,1,1,1,1,1,0,0,1
1,0,1,0,0,0,1,0,0,1,0,0,0,0,0,0,0,0,0,0,0,0,0,0,1
1,0,0,0,0,0,1,1,1,1,0,0,0,0,0,0,0,0,0,0,0,0,0,0,1
1,0,0,0,1,1,1,0,0,1,1,1,1,1,1,1,1,0,0,1,1,1,0,0,1
1,0,0,0,0,0,1,0,0,1,0,0,0,0,0,0,0,0,0,1,0,0,0,0,1
1,0,0,0,0,0,1,0,0,1,0,0,0,0,0,0,0,0,0,1,0,0,0,0,1
1,1,1,1,0,0,1,0,0,1,0,1,0,1,1,1,1,1,1,1,1,1,1,1,1
1,0,0,1,0,0,1,0,0,0,0,0,0,0,0,0,1,0,0,0,0,0,0,0,1
1,0,0,0,0,0,1,0,0,1,14,0,0,1,0,0,1,0,0,0,0,0,0,0,1
1,0,0,0,0,0,1,0,0,0,0,0,0,0,0,0,1,0,0,1,1,1,0,0,1
1,0,0,1,1,1,1,1,1,1,0,1,0,1,0,0,1,0,0,0,0,1,0,0,1
1,0,0,1,0,0,0,0,0,0,0,0,0,1,0,0,1,0,0,0,0,1,0,0,1
1,0,0,1,0,0,0,0,0,0,0,0,0,1,0,0,1,1,0,0,1,1,0,0,1
1,0,0,1,0,0,1,1,1,1,1,1,1,1,0,0,1,1,1,1,1,1,0,0,1
1,0,0,1,0,0,1,1,0,0,0,0,0,1,0,0,0,0,0,0,0,1,0,0,1
1,0,0,1,0,0,1,1,0,0,0,0,0,1,0,0,0,0,0,0,0,1,0,0,1
1,0,0,1,0,0,0,0,0,0,1,0,0,1,1,1,1,1,1,0,0,1,0,0,1
1,0,0,1,0,0,0,0,0,0,1,0,0,0,0,0,0,0,1,0,0,1,0,0,1
1,0,0,1,1,1,1,1,0,0,1,0,0,0,0,0,0,0,1,0,0,1,0,0,1
1,0,0,0,0,0,0,0,0,0,1,0,0,0,0,1,0,0,0,0,0,0,0,0,1
1,0,0,0,0,0,0,0,0,0,1,0,0,0,0,1,0,0,0,0,0,0,0,0,1
1,1,1,1,1,1,1,1,1,1,1,1,1,1,1,1,1,1,1,1,1,1,1,1,1
endlayer

layer
1,1,1,1,1,1,1,1,1,1,1,1,1,1,1,1,1,1,1,1,1,1,1,1,1
1,1,1,1,1,1,1,1,1,1,1,1,1,1,1,1,1,1,1,1,1,1,1,1,1
1,1,1,1,1,1,1,1,1,1,1,1,1,1,1,1,1,1,1,1,1,1,1,1,1
1,1,1,1,1,1,1,1,1,1,1,1,1,1,1,1,1,1,1,1,1,1,1,1,1
1,1,1,1,1,1,1,1,1,1,1,1,1,1,1,1,1,1,1,1,1,1,1,1,1
1,1,1,1,1,1,1,1,1,1,1,1,1,1,1,1,1,1,1,1,1,1,1,1,1
1,1,1,1,1,1,1,1,1,1,1,1,1,1,1,1,1,1,1,1,1,1,1,1,1
1,1,1,1,1,1,1,1,1,1,1,1,1,1,1,1,1,1,1,1,1,1,1,1,1
1,1,1,1,1,1,1,1,1,1,1,1,1,1,1,1,1,1,1,1,1,1,1,1,1
1,1,1,1,1,1,1,1,1,1,1,1,1,1,1,1,1,1,1,1,1,1,1,1,1
1,1,1,1,1,1,1,1,1,1,0,0,0,1,1,1,1,1,1,1,1,1,1,1,1
1,1,1,1,1,1,1,1,1,1,0,17,0,1,1,1,1,1,1,1,1,1,1,1,1
1,1,1,1,1,1,1,1,1,1,0,0,0,1,1,1,1,1,1,1,1,1,1,1,1
1,1,1,1,1,1,1,1,1,1,1,1,1,1,1,1,1,1,1,1,1,1,1,1,1
1,1,1,1,1,1,1,1,1,1,1,1,1,1,1,1,1,1,1,1,1,1,1,1,1
1,1,1,1,1,1,1,1,1,1,1,1,1,1,1,1,1,1,1,1,1,1,1,1,1
1,1,1,1,1,1,1,1,1,1,1,1,1,1,1,1,1,1,1,1,1,1,1,1,1
1,1,1,1,1,1,1,1,1,1,1,1,1,1,1,1,1,1,1,1,1,1,1,1,1
1,1,1,1,1,1,1,1,1,1,1,1,1,1,1,1,1,1,1,1,1,1,1,1,1
1,1,1,1,1,1,1,1,1,1,1,1,1,1,1,1,1,1,1,1,1,1,1,1,1
1,1,1,1,1,1,1,1,1,1,1,1,1,1,1,1,1,1,1,1,1,1,1,1,1
1,1,1,1,1,1,1,1,1,1,1,1,1,1,1,1,1,1,1,1,1,1,1,1,1
1,1,1,1,1,1,1,1,1,1,1,1,1,1,1,1,1,1,1,1,1,1,1,1,1
1,1,1,1,1,1,1,1,1,1,1,1,1,1,1,1,1,1,1,1,1,1,1,1,1
1,1,1,1,1,1,1,1,1,1,1,1,1,1,1,1,1,1,1,1,1,1,1,1,1
endlayer

layer
18,18,18,18,18,18,18,18,18,18,18,18,18,18,18,18,18,18,18,18,18,18,18,18,18
18,13,13,13,13,13,13,13,13,13,13,13,13,13,13,13,13,13,13,13,13,13,13,13,18
18,13,18,18,18,18,13,18,18,13,18,18,18,18,18,18,13,18,18,13,18,18,18,13,18
18,18,18,18,18,18,13,18,18,13,18,18,18,18,18,18,13,18,18,13,18,18,18,13,18
18,18,18,18,18,18,13,18,18,18,18,18,18,13,18,18,18,18,18,13,18,18,18,13,18
18,13,18,18,18,18,13,18,18,18,18,18,18,13,18,18,18,18,3,13,18,18,18,13,18
18,13,13,13,18,18,13,13,13,13,13,18,13,13,13,13,13,18,18,13,18,13,13,13,18
18,13,18,18,18,18,13,18,18,18,18,18,18,18,18,18,13,18,18,18,18,18,18,13,18
18,13,18,18,18,18,13,18,18,18,18,18,18,18,18,18,13,18,18,18,18,18,18,13,18
18,13,18,18,13,13,13,18,18,1,1,1,1,1,18,18,13,13,13,13,13,18,18,13,18
18,13,18,18,18,18,13,18,18,1,0,0,0,1,18,18,13,18,18,18,18,18,18,13,18
18,13,18,18,18,18,18,18,18,1,0,17,0,1,18,18,18,18,18,18,18,18,18,13,18
18,13,18,18,18,18,13,18,18,1,0,0,0,1,18,18,13,18,18,13,18,18,13,13,18
18,13,13,13,18,18,13,18,18,1,1,1,1,1,18,18,13,18,18,13,18,18,18,13,18
18,13,18,18,18,18,13,18,18,18,18,18,18,18,18,18,13,18,18,13,18,18,18,13,18
18,13,18,18,18,18,13,18,18,18,18,18,18,18,18,18,13,18,18,13,18,18,18,13,18
18,13,18,18,13,13,13,13,13,13,13,18,13,13,13,13,13,18,18,13,13,13,13,13,18
18,13,18,18,18,13,3,18,18,18,18,18,18,18,18,18,13,18,18,18,18,18,18,13,18
18,13,18,18,18,13,18,18,18,18,18,18,18,18,18,18,13,18,18,18,18,18,18,13,18
18,13,13,18,18,13,18,18,13,18,18,13,13,13,13,13,13,13,13,13,18,18,18,13,18
18,13,18,18,18,18,18,18,13,18,18,18,13,18,18,18,18,18,18,18,18,18,18,18,18
18,13,18,18,18,18,18,18,13,18,18,18,13,18,18,13,18,18,18,18,18,18,18,18,18
18,13,18,18,18,18,18,18,13,18,18,18,18,18,18,13,18,18,18,13,18,18,18,13,18
18,13,13,13,13,13,13,13,13,13,13,13,13,13,13,13,13,13,13,13,13,13,13,13,18
18,18,18,18,18,18,18,18,18,18,18,18,18,18,18,18,18,18,18,18,18,18,18,18,18
endlayer

layer
18,18,18,18,18,18,18,18,18,18,18,18,18,18,18,18,18,18,18,18,18,18,18,18,18
18,13,13,13,13,13,13,13,13,13,13,13,13,13,13,13,13,13,13,13,13,13,13,13,18
18,13,18,18,18,18,13,18,18,13,18,18,18,18,18,18,13,18,18,13,18,18,18,13,18
18,18,18,18,18,18,13,18,18,13,18,18,18,18,18,18,13,18,18,13,18,18,18,13,18
18,18,18,18,18,18,13,18,18,18,18,18,18,13,18,18,18,18,18,13,18,18,18,13,18
18,13,18,18,18,18,13,18,18,18,18,18,18,13,18,18,18,18,18,13,18,18,18,13,18
18,13,13,13,18,18,13,13,13,13,13,18,13,13,13,13,13,18,18,13,18,13,13,13,18
18,13,18,18,18,18,13,18,18,18,18,18,18,18,18,18,13,18,18,18,18,18,18,13,18
18,13,18,18,18,18,13,18,18,18,18,18,18,18,18,18,13,18,18,18,18,18,18,13,18
18,13,18,18,13,13,13,18,18,18,1,1,1,18,18,18,13,13,13,13,13,18,18,13,18
18,13,18,18,18,18,13,18,18,1,0,0,0,1,18,18,13,18,18,18,18,18,18,13,18
18,13,18,18,18,18,18,18,18,1,0,17,0,1,18,18,18,18,18,18,18,18,18,13,18
18,13,18,18,18,18,13,18,18,1,0,0,0,1,18,18,13,18,18,13,18,18,13,13,18
18,13,13,13,18,18,13,18,18,18,1,1,1,18,18,18,13,18,18,13,18,18,18,13,18
18,13,18,18,18,18,13,18,18,18,18,18,18,18,18,18,13,18,18,13,18,18,18,13,18
18,13,18,18,18,18,13,18,18,18,18,18,18,18,18,18,13,18,18,13,18,18,18,13,18
18,13,18,18,13,13,13,13,13,13,13,18,13,13,13,13,13,18,18,13,13,13,13,13,18
18,13,18,18,18,13,18,18,18,18,18,18,18,18,18,18,13,18,18,18,18,18,18,13,18
18,13,18,18,18,13,18,18,18,18,18,18,18,18,18,18,13,18,18,18,18,18,18,13,18
18,13,13,18,18,13,18,18,13,18,18,13,13,13,13,13,13,13,13,13,18,18,18,13,18
18,13,18,18,18,18,18,18,13,18,18,18,13,18,18,18,18,18,18,18,18,18,18,18,18
18,13,18,18,18,18,18,18,13,18,18,18,13,18,18,13,18,18,18,18,18,18,18,18,18
18,13,18,18,18,18,18,18,13,18,18,18,18,18,18,13,18,18,18,13,18,18,18,13,18
18,13,13,13,13,13,13,13,13,13,13,13,13,13,13,13,13,13,13,13,13,13,13,13,18
18,18,18,18,18,18,18,18,18,18,18,18,18,18,18,18,18,18,18,18,18,18,18,18,18
endlayer

layer
0,0,0,0,0,0,0,0,0,0,0,0,0,0,0,0,0,0,0,0,0,0,0,0,0
0,19,19,19,19,19,19,19,19,19,19,19,19,19,19,19,19,19,19,19,19,19,19,19,0
0,19,0,0,0,0,19,0,0,19,0,0,0,0,0,0,19,0,0,19,0,0,0,19,0
0,0,0,0,0,0,19,0,0,19,0,0,0,0,0,0,19,0,0,19,0,0,0,19,0
0,0,0,0,0,0,19,0,0,0,0,0,0,19,0,0,0,0,0,19,0,0,0,19,0
0,19,0,0,0,0,19,0,0,0,0,0,0,19,0,0,0,0,0,19,0,0,0,19,0
0,19,19,19,0,0,19,19,19,19,19,0,19,19,19,19,19,0,0,19,0,19,19,19,0
0,19,0,0,0,0,19,0,0,0,0,0,0,0,0,0,19,0,0,0,0,0,0,19,0
0,19,0,0,0,0,19,0,0,0,0,0,0,0,0,0,19,0,0,0,0,0,0,19,0
0,19,0,0,19,19,19,0,0,17,1,1,1,17,0,0,19,19,19,19,19,0,0,19,0
0,19,0,0,0,0,19,0,0,1,0,0,0,1,0,0,19,0,0,0,0,0,0,19,0
0,19,0,0,0,0,0,0,0,1,0,17,0,1,0,0,0,0,0,0,0,0,0,19,0
0,19,0,0,0,0,19,0,0,1,0,0,0,1,0,0,19,0,0,19,0,0,19,19,0
0,19,19,19,0,0,19,0,0,17,1,1,1,17,0,0,19,0,0,19,0,0,0,19,0
0,19,0,0,0,0,19,0,0,0,0,0,0,0,0,0,19,0,0,19,0,0,0,19,0
0,19,0,0,0,0,19,0,0,0,0,0,0,0,0,0,19,0,0,19,0,0,0,19,0
0,19,0,0,19,19,19,19,19,19,19,0,19,19,19,19,19,0,0,19,19,19,19,19,0
0,19,0,0,0,19,0,0,0,0,0,0,0,0,0,0,19,0,0,0,0,0,0,19,0
0,19,0,0,0,19,0,0,0,0,0,0,0,0,0,0,19,0,0,0,0,0,0,19,0
0,19,19,0,0,19,0,0,19,0,0,19,19,19,19,19,19,19,19,19,0,0,0,19,0
0,19,0,0,0,0,0,0,19,0,0,0,19,0,0,0,0,0,0,0,0,0,0,0,0
0,19,0,0,0,0,0,0,19,0,0,0,19,0,0,19,0,0,0,0,0,0,0,0,0
0,19,0,0,0,0,0,0,19,0,0,0,0,0,0,19,0,0,0,19,0,0,0,19,0
0,19,19,19,19,19,19,19,19,19,19,19,19,19,19,19,19,19,19,19,19,19,19,19,0
0,0,0,0,0,0,0,0,0,0,0,0,0,0,0,0,0,0,0,0,0,0,0,0,0
endlayer

layer
0,0,0,0,0,0,0,0,0,0,0,0,0,0,0,0,0,0,0,0,0,0,0,0,0
0,19,19,19,19,19,19,19,19,19,19,19,19,19,19,19,19,19,19,19,19,19,19,19,0
0,19,0,0,0,0,19,0,0,19,0,0,0,0,0,0,19,0,0,19,0,0,0,19,0
0,0,0,0,0,0,19,0,0,19,0,0,0,0,0,0,19,0,0,19,0,0,0,19,0
0,0,0,0,0,0,19,0,0,0,0,0,0,19,0,0,0,0,0,19,0,0,0,19,0
0,19,0,0,0,0,19,0,0,0,0,0,0,19,0,0,0,0,0,19,0,0,0,19,0
0,19,19,19,0,0,19,19,19,19,19,0,19,19,19,19,19,0,0,19,0,19,19,19,0
0,19,0,0,0,0,19,0,0,0,0,0,0,0,0,0,19,0,0,0,0,0,0,19,0
0,19,0,0,0,0,19,0,0,0,0,0,0,0,0,0,19,0,0,0,0,0,0,19,0
0,19,0,0,19,19,19,0,0,17,0,0,0,17,0,0,19,19,19,19,19,0,0,19,0
0,19,0,0,0,0,19,0,0,0,0,0,0,0,0,0,19,0,0,0,0,0,0,19,0
0,19,0,0,0,0,0,0,0,0,0,17,0,0,0,0,0,0,0,0,0,0,0,19,0
0,19,0,0,0,0,19,0,0,0,0,0,0,0,0,0,19,0,0,19,0,0,19,19,0
0,19,19,19,0,0,19,0,0,17,0,0,0,17,0,0,19,0,0,19,0,0,0,19,0
0,19,0,0,0,0,19,0,0,0,0,0,0,0,0,0,19,0,0,19,0,0,0,19,0
0,19,0,0,0,0,19,0,0,0,0,0,0,0,0,0,19,0,0,19,0,0,0,19,0
0,19,0,0,19,19,19,19,19,19,19,0,19,19,19,19,19,0,0,19,19,19,19,19,0
0,19,0,0,0,19,0,0,0,0,0,0,0,0,0,0,19,0,0,0,0,0,0,19,0
0,19,0,0,0,19,0,0,0,0,0,0,0,0,0,0,19,0,0,0,0,0,0,19,0
0,19,19,0,0,19,0,0,19,0,0,19,19,19,19,19,19,19,19,19,0,0,0,19,0
0,19,0,0,0,0,0,0,19,0,0,0,19,0,0,0,0,0,0,0,0,0,0,0,0
0,19,0,0,0,0,0,0,19,0,0,0,19,0,0,19,0,0,0,0,0,0,0,0,0
0,19,0,0,0,0,0,0,19,0,0,0,0,0,0,19,0,0,0,19,0,0,0,19,0
0,19,19,19,19,19,19,19,19,19,19,19,19,19,19,19,19,19,19,19,19,19,19,19,0
0,0,0,0,0,0,0,0,0,0,0,0,0,0,0,0,0,0,0,0,0,0,0,0,0
endlayer

layer
0,0,0,0,0,0,0,0,0,0,0,0,0,0,0,0,0,0,0,0,0,0,0,0,0
0,19,19,19,19,19,19,19,19,19,19,19,19,19,19,19,19,19,19,19,19,19,19,19,0
0,19,0,0,0,0,19,0,0,19,0,0,0,0,0,0,19,0,0,19,0,0,0,19,0
0,0,0,0,0,0,19,0,0,19,0,0,0,0,0,0,19,0,0,19,0,0,0,19,0
0,0,0,0,0,0,19,0,0,0,0,0,0,19,0,0,0,0,0,19,0,0,0,19,0
0,19,0,0,0,0,19,0,0,0,0,0,0,19,0,0,0,0,0,19,0,0,0,19,0
0,19,19,19,0,0,19,19,19,19,19,0,19,19,19,19,19,0,0,19,0,19,19,19,0
0,19,0,0,0,0,19,0,0,0,0,0,0,0,0,0,19,0,0,0,0,0,0,19,0
0,19,0,0,0,0,19,0,0,0,0,0,0,0,0,0,19,0,0,0,0,0,0,19,0
0,19,0,0,19,19,19,0,0,17,0,0,0,17,0,0,19,19,19,19,19,0,0,19,0
0,19,0,0,0,0,19,0,0,0,0,0,0,0,0,0,19,0,0,0,0,0,0,19,0
0,19,0,0,0,0,0,0,0,0,0,17,0,0,0,0,0,0,0,0,0,0,0,19,0
0,19,0,0,0,0,19,0,0,0,0,0,0,0,0,0,19,0,0,19,0,0,19,19,0
0,19,19,19,0,0,19,0,0,17,0,0,0,17,0,0,19,0,0,19,0,0,0,19,0
0,19,0,0,0,0,19,0,0,0,0,0,0,0,0,0,19,0,0,19,0,0,0,19,0
0,19,0,0,0,0,19,0,0,0,0,0,0,0,0,0,19,0,0,19,0,0,0,19,0
0,19,0,0,19,19,19,19,19,19,19,0,19,19,19,19,19,0,0,19,19,19,19,19,0
0,19,0,0,0,19,0,0,0,0,0,0,0,0,0,0,19,0,0,0,0,0,0,19,0
0,19,0,0,0,19,0,0,0,0,0,0,0,0,0,0,19,0,0,0,0,0,0,19,0
0,19,19,0,0,19,0,0,19,0,0,19,19,19,19,19,19,19,19,19,0,0,0,19,0
0,19,0,0,0,0,0,0,19,0,0,0,19,0,0,0,0,0,0,0,0,0,0,0,0
0,19,0,0,0,0,0,0,19,0,0,0,19,0,0,19,0,0,0,0,0,0,0,0,0
0,19,0,0,0,0,0,0,19,0,0,0,0,0,0,19,0,0,0,19,0,0,0,19,0
0,19,19,19,19,19,19,19,19,19,19,19,19,19,19,19,19,19,19,19,19,19,19,19,0
0,0,0,0,0,0,0,0,0,0,0,0,0,0,0,0,0,0,0,0,0,0,0,0,0
endlayer

layer
0,0,0,0,0,0,0,0,0,0,0,0,0,0,0,0,0,0,0,0,0,0,0,0,0
0,0,0,0,0,0,0,0,0,0,0,0,0,0,0,0,0,0,0,0,0,0,0,0,0
0,0,0,0,0,0,0,0,0,0,0,0,0,0,0,0,0,0,0,0,0,0,0,0,0
0,0,0,0,0,0,0,0,0,0,0,0,0,0,0,0,0,0,0,0,0,0,0,0,0
0,0,0,0,0,0,0,0,0,0,0,0,0,0,0,0,0,0,0,0,0,0,0,0,0
0,0,0,0,0,0,0,0,0,0,0,0,0,0,0,0,0,0,0,0,0,0,0,0,0
0,0,0,0,0,0,0,0,0,0,0,0,0,0,0,0,0,0,0,0,0,0,0,0,0
0,0,0,0,0,0,0,0,0,0,0,0,0,0,0,0,0,0,0,0,0,0,0,0,0
0,0,0,0,0,0,0,0,0,0,0,0,0,0,0,0,0,0,0,0,0,0,0,0,0
0,0,0,0,0,0,0,0,0,20,20,20,20,20,0,0,0,0,0,0,0,0,0,0,0
0,0,0,0,0,0,0,0,0,20,0,0,0,20,0,0,0,0,0,0,0,0,0,0,0
0,0,0,0,0,0,0,0,0,20,0,17,0,20,0,0,0,0,0,0,0,0,0,0,0
0,0,0,0,0,0,0,0,0,20,0,0,0,20,0,0,0,0,0,0,0,0,0,0,0
0,0,0,0,0,0,0,0,0,20,20,20,20,20,0,0,0,0,0,0,0,0,0,0,0
0,0,0,0,0,0,0,0,0,0,0,0,0,0,0,0,0,0,0,0,0,0,0,0,0
0,0,0,0,0,0,0,0,0,0,0,0,0,0,0,0,0,0,0,0,0,0,0,0,0
0,0,0,0,0,0,0,0,0,0,0,0,0,0,0,0,0,0,0,0,0,0,0,0,0
0,0,0,0,0,0,0,0,0,0,0,0,0,0,0,0,0,0,0,0,0,0,0,0,0
0,0,0,0,0,0,0,0,0,0,0,0,0,0,0,0,0,0,0,0,0,0,0,0,0
0,0,0,0,0,0,0,0,0,0,0,0,0,0,0,0,0,0,0,0,0,0,0,0,0
0,0,0,0,0,0,0,0,0,0,0,0,0,0,0,0,0,0,0,0,0,0,0,0,0
0,0,0,0,0,0,0,0,0,0,0,0,0,0,0,0,0,0,0,0,0,0,0,0,0
0,0,0,0,0,0,0,0,0,0,0,0,0,0,0,0,0,0,0,0,0,0,0,0,0
0,0,0,0,0,0,0,0,0,0,0,0,0,0,0,0,0,0,0,0,0,0,0,0,0
0,0,0,0,0,0,0,0,0,0,0,0,0,0,0,0,0,0,0,0,0,0,0,0,0
endlayer

layer
0,0,0,0,0,0,0,0,0,0,0,0,0,0,0,0,0,0,0,0,0,0,0,0,0
0,0,0,0,0,0,0,0,0,0,0,0,0,0,0,0,0,0,0,0,0,0,0,0,0
0,0,0,0,0,0,0,0,0,0,0,0,0,0,0,0,0,0,0,0,0,0,0,0,0
0,0,0,0,0,0,0,0,0,0,0,0,0,0,0,0,0,0,0,0,0,0,0,0,0
0,0,0,0,0,0,0,0,0,0,0,0,0,0,0,0,0,0,0,0,0,0,0,0,0
0,0,0,0,0,0,0,0,0,0,0,0,0,0,0,0,0,0,0,0,0,0,0,0,0
0,0,0,0,0,0,0,0,0,0,0,0,0,0,0,0,0,0,0,0,0,0,0,0,0
0,0,0,0,0,0,0,0,0,0,0,0,0,0,0,0,0,0,0,0,0,0,0,0,0
0,0,0,0,0,0,0,0,0,0,0,0,0,0,0,0,0,0,0,0,0,0,0,0,0
0,0,0,0,0,0,0,0,0,0,0,0,0,0,0,0,0,0,0,0,0,0,0,0,0
0,0,0,0,0,0,0,0,0,0,20,20,20,0,0,0,0,0,0,0,0,0,0,0,0
0,0,0,0,0,0,0,0,0,0,20,17,20,0,0,0,0,0,0,0,0,0,0,0,0
0,0,0,0,0,0,0,0,0,0,20,20,20,0,0,0,0,0,0,0,0,0,0,0,0
0,0,0,0,0,0,0,0,0,0,0,0,0,0,0,0,0,0,0,0,0,0,0,0,0
0,0,0,0,0,0,0,0,0,0,0,0,0,0,0,0,0,0,0,0,0,0,0,0,0
0,0,0,0,0,0,0,0,0,0,0,0,0,0,0,0,0,0,0,0,0,0,0,0,0
0,0,0,0,0,0,0,0,0,0,0,0,0,0,0,0,0,0,0,0,0,0,0,0,0
0,0,0,0,0,0,0,0,0,0,0,0,0,0,0,0,0,0,0,0,0,0,0,0,0
0,0,0,0,0,0,0,0,0,0,0,0,0,0,0,0,0,0,0,0,0,0,0,0,0
0,0,0,0,0,0,0,0,0,0,0,0,0,0,0,0,0,0,0,0,0,0,0,0,0
0,0,0,0,0,0,0,0,0,0,0,0,0,0,0,0,0,0,0,0,0,0,0,0,0
0,0,0,0,0,0,0,0,0,0,0,0,0,0,0,0,0,0,0,0,0,0,0,0,0
0,0,0,0,0,0,0,0,0,0,0,0,0,0,0,0,0,0,0,0,0,0,0,0,0
0,0,0,0,0,0,0,0,0,0,0,0,0,0,0,0,0,0,0,0,0,0,0,0,0
0,0,0,0,0,0,0,0,0,0,0,0,0,0,0,0,0,0,0,0,0,0,0,0,0
endlayer

layer
0,0,0,0,0,0,0,0,0,0,0,0,0,0,0,0,0,0,0,0,0,0,0,0,0
0,0,0,0,0,0,0,0,0,0,0,0,0,0,0,0,0,0,0,0,0,0,0,0,0
0,0,0,0,0,0,0,0,0,0,0,0,0,0,0,0,0,0,0,0,0,0,0,0,0
0,0,0,0,0,0,0,0,0,0,0,0,0,0,0,0,0,0,0,0,0,0,0,0,0
0,0,0,0,0,0,0,0,0,0,0,0,0,0,0,0,0,0,0,0,0,0,0,0,0
0,0,0,0,0,0,0,0,0,0,0,0,0,0,0,0,0,0,0,0,0,0,0,0,0
0,0,0,0,0,0,0,0,0,0,0,0,0,0,0,0,0,0,0,0,0,0,0,0,0
0,0,0,0,0,0,0,0,0,0,0,0,0,0,0,0,0,0,0,0,0,0,0,0,0
0,0,0,0,0,0,0,0,0,0,0,0,0,0,0,0,0,0,0,0,0,0,0,0,0
0,0,0,0,0,0,0,0,0,0,0,0,0,0,0,0,0,0,0,0,0,0,0,0,0
0,0,0,0,0,0,0,0,0,0,0,0,0,0,0,0,0,0,0,0,0,0,0,0,0
0,0,0,0,0,0,0,0,0,0,0,20,0,0,0,0,0,0,0,0,0,0,0,0,0
0,0,0,0,0,0,0,0,0,0,0,0,0,0,0,0,0,0,0,0,0,0,0,0,0
0,0,0,0,0,0,0,0,0,0,0,0,0,0,0,0,0,0,0,0,0,0,0,0,0
0,0,0,0,0,0,0,0,0,0,0,0,0,0,0,0,0,0,0,0,0,0,0,0,0
0,0,0,0,0,0,0,0,0,0,0,0,0,0,0,0,0,0,0,0,0,0,0,0,0
0,0,0,0,0,0,0,0,0,0,0,0,0,0,0,0,0,0,0,0,0,0,0,0,0
0,0,0,0,0,0,0,0,0,0,0,0,0,0,0,0,0,0,0,0,0,0,0,0,0
0,0,0,0,0,0,0,0,0,0,0,0,0,0,0,0,0,0,0,0,0,0,0,0,0
0,0,0,0,0,0,0,0,0,0,0,0,0,0,0,0,0,0,0,0,0,0,0,0,0
0,0,0,0,0,0,0,0,0,0,0,0,0,0,0,0,0,0,0,0,0,0,0,0,0
0,0,0,0,0,0,0,0,0,0,0,0,0,0,0,0,0,0,0,0,0,0,0,0,0
0,0,0,0,0,0,0,0,0,0,0,0,0,0,0,0,0,0,0,0,0,0,0,0,0
0,0,0,0,0,0,0,0,0,0,0,0,0,0,0,0,0,0,0,0,0,0,0,0,0
0,0,0,0,0,0,0,0,0,0,0,0,0,0,0,0,0,0,0,0,0,0,0,0,0
endlayer

