
# Created by Ruins mod version 14.7 Ingame Parser
# authoring Player: OneWolfe

weight=6
unique=1
embed_into_distance=16
acceptable_target_blocks=
unacceptable_target_blocks=flowing_water,water,flowing_lava,lava,terrafirmacraft:SaltWaterStationary-0,terrafirmacraft:SaltWaterStationary-8,terrafirmacraft:FreshWaterStationary-0,terrafirmacraft:FreshWaterStationary-8
dimensions=16,11,11
allowable_overhang=8
max_leveling=4
leveling_buffer=0
preserve_water=0
preserve_lava=0
preserve_plants=1

rule1=0,100,preserveBlock
rule2=0,100,minecraft:nether_brick-0,minecraft:nether_brick-0,minecraft:nether_brick-0,minecraft:nether_brick-0,minecraft:nether_brick-0,Railcraft:brick.nether-1,Railcraft:brick.nether-1,Railcraft:brick.nether-1,Railcraft:brick.nether-1,minecraft:netherrack-0,minecraft:netherrack-0,minecraft:netherrack-0
rule3=0,100,Railcraft:brick.nether-1
rule4=0,100,minecraft:soul_sand-0,minecraft:soul_sand-0,terrafirmacraft:LavaStationary-0,terrafirmacraft:LavaStationary-0,minecraft:netherrack-0,minecraft:netherrack-0,minecraft:netherrack-0,minecraft:quartz_ore-0,air,air
rule5=0,100,minecraft:nether_brick_stairs-2,minecraft:nether_brick_stairs-2,minecraft:nether_brick_stairs-2,air,air
rule6=0,100,minecraft:netherrack-0
rule7=0,100,terrafirmacraft:LavaStationary-8
rule8=0,100,minecraft:nether_wart-0,air,air,air
rule9=0,100,minecraft:nether_wart-1,air,air,air
rule10=0,100,minecraft:nether_wart-2,air,air
rule11=0,100,minecraft:quartz_ore-0,ChestGenHook:dungeonChest:5-4,air,air
rule12=0,100,minecraft:nether_wart-3
rule13=0,100,minecraft:glowstone-0,air,air
rule14=0,100,minecraft:nether_brick_stairs-0,minecraft:nether_brick_stairs-0,minecraft:nether_brick_stairs-0,air,air
rule15=0,100,MobSpawner:blazeTFC,air,air
rule16=0,100,minecraft:nether_brick_stairs-3,minecraft:nether_brick_stairs-3,minecraft:nether_brick_stairs-3,air,air
rule17=0,100,terrafirmacraft:LavaStationary-0
rule18=0,100,air

layer
1,2,2,2,2,2,2,2,2,2,1
2,2,2,2,2,2,2,2,2,2,2
2,2,2,2,2,2,2,2,2,2,2
2,2,2,2,2,2,2,2,2,2,2
2,2,2,2,2,2,2,2,2,2,2
2,2,2,2,2,2,2,2,2,2,2
2,2,2,2,2,2,2,2,2,2,2
2,2,2,2,2,2,2,2,2,2,2
2,2,2,2,2,2,2,2,2,2,2
2,2,2,2,2,2,2,2,2,2,2
1,2,2,2,2,2,2,2,2,2,1
endlayer

layer
3,2,2,2,2,2,2,2,2,2,3
2,4,4,4,6,2,5,4,4,4,2
2,4,4,4,6,2,5,4,4,4,2
2,4,4,4,6,2,5,4,4,4,2
2,4,4,4,2,2,2,4,4,4,2
2,4,4,4,2,7,2,4,4,4,2
2,4,4,4,2,2,2,4,4,4,2
2,4,4,4,4,4,4,4,4,4,2
2,4,4,4,4,4,4,4,4,4,2
2,4,4,4,4,4,4,4,4,4,2
3,2,2,2,2,2,2,2,2,2,2
endlayer

layer
3,2,2,2,2,2,2,2,2,2,3
2,8,8,10,2,5,0,10,9,8,2
2,8,8,10,11,5,0,9,8,9,2
2,9,9,8,2,5,0,8,10,8,2
2,8,9,9,2,2,2,8,12,8,2
2,9,8,8,2,7,2,9,8,9,2
2,8,9,8,2,2,2,8,9,9,2
2,8,9,8,8,8,9,9,8,8,2
2,8,8,8,12,8,9,10,9,10,2
2,9,8,8,9,9,9,9,8,10,2
3,2,2,2,2,2,2,2,2,2,2
endlayer

layer
3,2,2,2,2,2,2,2,2,2,3
2,2,2,2,5,0,0,0,0,0,2
2,2,2,2,5,0,0,0,0,0,2
2,2,2,2,5,0,0,0,0,0,2
2,0,0,0,2,2,2,0,0,0,2
2,0,0,0,2,7,2,0,0,0,2
2,0,0,0,2,2,2,0,0,0,2
2,0,0,0,0,0,0,0,0,0,2
2,0,0,0,0,0,0,0,0,0,2
2,0,0,0,0,0,0,0,0,0,2
3,2,2,2,2,2,2,2,2,2,2
endlayer

layer
3,2,2,2,2,2,2,2,2,2,3
2,2,2,5,0,0,0,0,0,0,2
2,2,2,5,0,0,0,0,0,0,2
2,2,2,5,0,0,0,0,0,0,2
2,2,2,2,2,0,2,0,0,0,2
2,0,0,0,0,7,0,0,0,0,2
2,0,0,0,2,0,2,0,0,0,2
2,0,0,0,0,0,0,0,0,0,2
2,0,0,0,0,0,0,0,0,0,2
2,0,0,0,0,0,0,0,0,0,2
3,2,2,2,2,2,2,2,2,2,2
endlayer

layer
3,2,2,2,2,13,2,2,2,2,3
2,0,0,0,0,0,0,0,0,0,2
2,0,0,0,0,0,0,0,0,0,2
2,0,0,0,0,0,0,0,0,0,2
2,14,14,14,2,2,2,0,0,0,2
2,2,15,2,2,7,2,0,15,0,13
2,0,0,0,2,2,2,0,0,0,2
2,0,0,0,0,0,0,0,0,0,2
2,0,0,0,0,15,0,0,0,0,2
2,0,0,0,0,0,0,0,0,0,2
3,2,2,2,2,13,2,2,2,2,2
endlayer

layer
3,2,2,2,2,2,2,2,2,2,3
2,0,0,0,0,0,0,0,0,0,2
2,0,0,0,0,0,0,0,0,0,2
2,0,0,0,0,0,0,0,0,0,2
2,0,0,0,2,2,2,0,0,0,2
2,14,14,14,2,7,2,0,0,0,2
2,2,2,2,2,2,2,0,0,0,2
2,0,0,0,0,0,0,0,0,0,2
2,0,0,0,0,0,0,0,0,0,2
2,0,0,0,0,0,0,0,0,0,2
3,2,2,2,2,2,2,2,2,2,2
endlayer

layer
3,2,2,2,2,2,2,2,2,2,3
2,0,0,0,0,0,0,0,0,0,2
2,0,0,0,0,0,0,0,0,0,2
2,0,0,0,0,0,0,0,0,0,2
2,0,0,0,2,2,2,0,0,0,2
2,0,0,0,2,7,2,0,0,0,2
2,14,14,14,2,2,2,0,0,0,2
2,2,2,2,0,0,0,0,0,0,2
2,0,0,0,0,0,0,0,0,0,2
2,0,0,0,0,0,0,0,0,0,2
3,2,2,2,2,2,2,2,2,2,2
endlayer

layer
3,2,2,2,2,2,2,2,2,2,3
2,0,0,0,0,0,0,0,0,0,2
2,0,0,0,0,0,0,0,0,0,2
2,0,0,0,0,0,0,0,0,0,2
2,0,0,0,2,0,2,0,0,0,2
2,0,0,0,0,7,0,0,0,0,2
2,0,0,0,2,0,2,0,0,0,2
2,14,14,14,2,0,0,0,0,0,2
2,2,2,2,2,0,0,0,0,0,2
2,2,2,2,2,0,0,0,0,0,2
3,2,2,2,2,2,2,2,2,2,2
endlayer

layer
3,2,2,2,2,2,2,2,2,2,3
2,0,0,0,0,0,0,0,0,0,2
2,0,0,0,0,0,0,0,0,0,2
2,0,0,0,0,0,0,0,0,0,2
2,0,0,0,2,2,2,0,0,0,2
2,0,0,0,2,7,2,0,0,0,2
2,0,0,0,2,2,2,0,0,0,2
2,0,0,0,16,2,0,0,0,0,2
2,0,0,0,16,2,0,0,0,0,2
2,0,0,0,16,2,0,0,0,0,2
3,2,2,2,2,2,2,2,2,2,2
endlayer

layer
3,2,2,2,2,2,2,2,2,2,3
2,0,0,0,0,0,0,0,0,0,2
2,0,0,0,0,0,0,0,0,0,2
2,0,0,0,0,0,0,0,0,0,2
2,0,0,0,2,2,2,0,0,0,2
2,0,0,0,2,7,2,0,0,0,2
2,0,0,0,2,2,2,0,0,0,2
2,0,0,0,0,16,2,0,0,0,2
2,0,0,0,0,16,2,0,0,0,2
2,0,0,0,0,16,2,0,0,0,2
3,2,2,2,2,2,2,2,2,2,2
endlayer

layer
3,2,2,2,2,2,2,2,2,2,3
2,2,2,2,2,2,2,2,2,2,2
2,2,2,2,2,2,2,2,2,2,2
2,2,2,2,2,2,2,2,2,2,2
2,2,2,2,2,2,2,2,2,2,2
2,2,2,2,2,17,2,2,2,2,2
2,2,2,2,2,2,2,2,2,2,2
2,0,0,0,0,0,16,2,2,2,2
2,0,0,0,0,0,16,2,2,2,2
2,0,0,0,0,0,16,2,2,2,2
3,2,2,2,2,2,2,2,2,2,2
endlayer

layer
3,2,2,2,2,2,2,2,2,2,3
2,1,1,1,1,1,1,1,1,1,2
2,1,1,1,1,1,1,1,1,1,2
2,1,1,1,1,1,1,1,1,1,2
2,1,1,1,3,3,3,1,1,1,2
2,1,1,1,3,3,3,1,1,1,2
2,2,2,2,2,2,2,2,2,2,2
2,2,2,2,0,0,0,16,2,2,2
2,2,2,2,0,0,0,16,2,2,2
2,2,2,2,0,0,0,16,2,2,2
3,2,2,2,2,2,2,2,2,2,2
endlayer

layer
1,1,1,1,1,1,1,1,1,1,1
1,1,1,1,1,1,1,1,1,1,1
1,1,1,1,1,1,1,1,1,1,1
1,1,1,1,1,1,1,1,1,1,1
1,1,1,1,1,1,1,1,1,1,1
1,1,1,1,1,1,1,1,1,1,1
1,1,1,1,2,2,2,2,2,2,2
1,1,1,2,2,0,0,0,16,2,2
1,1,1,2,2,0,0,0,16,2,2
1,1,1,2,2,0,0,0,16,2,2
1,1,1,2,2,2,2,2,2,2,2
endlayer

layer
1,1,1,1,1,1,1,1,1,1,1
1,1,1,1,1,1,1,1,1,1,1
1,1,1,1,1,1,1,1,1,1,1
1,1,1,1,1,1,1,1,1,1,1
1,1,1,1,1,1,1,1,1,1,1
1,1,1,1,1,1,1,1,1,1,1
1,1,1,1,2,2,2,2,2,2,2
1,1,1,1,2,2,0,0,0,16,2
1,1,1,1,2,2,0,0,0,16,2
1,1,1,1,2,2,0,0,0,16,2
1,1,1,1,2,2,2,2,2,2,2
endlayer

layer
1,1,1,1,1,1,1,1,1,1,1
1,1,1,1,1,1,1,1,1,1,1
1,1,1,1,1,1,1,1,1,1,1
1,1,1,1,1,1,1,1,1,1,1
1,1,1,1,1,1,1,1,1,1,1
1,1,1,1,1,1,1,1,1,1,1
1,1,1,1,1,2,2,2,2,2,2
1,1,1,1,1,2,2,0,0,0,16
1,1,1,1,1,2,2,0,0,0,16
1,1,1,1,1,2,2,0,0,0,16
1,1,1,1,1,2,2,2,2,2,2
endlayer

