
# Created by Ruins mod version 13.8 Ingame Parser
# authoring Player: OneWolfe

weight=4
embed_into_distance=0
acceptable_target_blocks=
unacceptable_target_blocks=flowing_water,water,flowing_lava,lava
dimensions=6,23,18
allowable_overhang=8
max_leveling=6
leveling_buffer=0
preserve_water=0
preserve_lava=0
preserve_plants=1

rule1=0,100,terrafirmacraft:StoneMMBrick-4
rule2=0,100,minecraft:rail-0
rule3=0,100,minecraft:rail-5
rule4=0,100,minecraft:rail-4
rule5=0,100,terrafirmacraft:StoneIgInSmooth-1
rule6=0,100,terrafirmacraft:StoneIgExSmooth-3
rule7=0,100,terrafirmacraft:StoneIgInCobble-1
rule8=0,100,minecraft:rail-1
rule9=0,100,minecraft:golden_rail-1
rule10=0,100,minecraft:lever-5
rule11=0,100,terrafirmacraft:WallSmoothIgEx-1
rule12=0,100,minecraft:lever-6
rule13=0,100,minecraft:golden_rail-0
rule14=0,100,minecraft:rail-9
rule15=0,100,terrafirmacraft:StoneSedBrick-0
rule16=0,100,terrafirmacraft:Vine-1
rule17=0,100,terrafirmacraft:StoneIgExSmooth-1
rule18=0,100,ChestGenHook:dungeonChest:5-4
rule19=0,100,minecraft:lever-9
rule20=0,100,minecraft:lever-1
rule21=0,100,minecraft:lever-12
rule22=0,100,minecraft:lever-4
rule23=0,100,terrafirmacraft:DoorAspen-6
rule24=0,100,terrafirmacraft:Vine-2
rule25=0,100,minecraft:rail-8
rule26=0,100,air
rule27=0,100,terrafirmacraft:Vine-8
rule28=0,100,minecraft:stained_glass_pane-3
rule29=0,100,minecraft:lever-14
rule30=0,100,terrafirmacraft:MetalTrapDoor-4
rule31=0,100,minecraft:lever-13
rule32=0,100,minecraft:lever-11
rule33=0,100,minecraft:lever-3
rule34=0,100,terrafirmacraft:Vine-4
rule35=0,100,terrafirmacraft:DoorAspen-8
rule36=0,100,terrafirmacraft:Torch-1
rule37=0,100,Railcraft:signal-1
rule38=0,100,terrafirmacraft:Torch-2

layer
0,0,0,0,0,1,0,0,0,0,0,0,0,0,0,0,0,0
0,0,0,0,1,1,1,0,0,0,0,0,0,0,0,0,0,0
0,0,0,0,1,1,1,0,0,0,0,0,0,0,0,0,0,0
0,0,0,0,1,1,1,1,0,0,0,0,0,0,0,0,0,0
0,0,0,1,1,1,1,1,1,0,0,0,0,0,0,0,0,0
2,4,1,1,1,1,1,1,1,1,1,1,1,1,1,3,2,0
0,1,1,1,1,1,1,1,1,1,1,1,1,1,1,1,0,0
0,1,1,1,1,1,1,1,1,1,1,1,1,1,1,1,1,0
0,0,1,1,1,1,1,5,5,5,5,5,5,5,5,5,0,0
0,0,0,1,1,1,1,5,5,5,5,5,5,5,5,5,0,0
0,0,0,0,1,1,1,5,5,6,5,5,5,6,5,5,0,0
0,0,0,0,1,1,1,5,5,5,6,5,6,7,5,5,0,0
0,0,0,0,1,1,1,5,5,5,7,5,6,5,5,5,0,0
0,0,0,0,1,1,1,5,5,6,5,6,7,5,5,5,0,0
0,0,0,0,1,1,1,5,5,5,6,5,6,5,5,5,0,0
0,0,0,0,1,1,1,5,5,5,7,5,5,6,5,5,0,0
0,0,0,0,1,1,1,5,5,5,5,5,5,5,5,5,0,0
0,0,0,0,1,1,1,5,5,5,5,5,5,5,5,5,0,0
0,0,0,0,1,1,1,0,0,0,0,0,0,0,0,0,0,0
0,0,0,0,1,1,1,0,0,0,0,0,0,0,0,0,0,0
0,0,0,0,1,1,1,3,2,0,0,0,0,0,0,0,0,0
0,0,0,0,1,1,1,0,0,0,0,0,0,0,0,0,0,0
0,0,0,0,0,0,0,0,0,0,0,0,0,0,0,0,0,0
endlayer

layer
0,0,0,0,0,0,0,0,0,0,0,0,0,0,0,0,0,0
0,0,0,0,8,0,0,0,0,0,0,0,0,0,0,0,0,0
0,0,0,0,8,0,8,0,0,0,0,0,0,0,0,0,0,0
0,0,0,0,9,0,9,0,0,0,0,0,0,0,0,0,0,0
0,0,0,12,8,0,8,11,10,0,0,0,0,0,0,0,0,0
0,0,2,2,14,2,8,2,2,13,2,0,2,2,2,0,0,0
0,0,0,0,8,0,8,0,0,0,0,0,0,0,0,0,0,0
0,2,2,2,8,2,14,2,13,2,0,2,2,0,13,2,2,0
0,0,0,11,8,0,8,15,15,15,15,15,15,15,15,0,0,0
0,0,0,10,9,0,8,15,18,17,17,17,17,17,15,16,0,0
0,0,0,0,0,0,8,15,17,0,19,20,19,0,15,0,0,0
0,0,0,0,8,0,0,15,17,21,0,0,0,0,15,0,0,0
0,0,0,0,9,0,8,15,17,22,0,0,0,0,15,16,0,0
0,0,0,0,8,0,9,15,17,21,0,0,0,0,15,0,0,0
0,0,0,0,8,0,8,15,17,0,0,0,0,0,15,0,0,0
0,0,0,0,0,0,8,15,17,21,0,0,0,0,15,16,0,0
0,0,0,0,8,0,8,15,15,15,15,23,15,15,15,0,0,0
0,0,0,0,8,0,0,24,24,0,0,0,0,0,0,0,0,0
0,0,0,0,0,0,9,0,0,0,0,0,0,0,0,0,0,0
0,0,0,0,8,0,8,0,0,0,0,0,0,0,0,0,0,0
0,26,0,0,9,26,25,0,0,0,0,0,0,0,0,0,0,0
0,0,0,0,8,0,0,0,0,0,0,0,0,0,0,0,0,0
0,0,0,0,26,0,0,0,0,0,0,0,0,0,0,0,0,0
endlayer

layer
0,0,0,0,0,0,0,0,0,0,0,0,0,0,0,0,0,0
0,0,0,0,0,0,0,0,0,0,0,0,0,0,0,0,0,0
0,0,0,0,0,0,0,0,0,0,0,0,0,0,0,0,0,0
0,0,0,0,0,0,0,0,0,0,0,0,0,0,0,0,0,0
0,0,0,0,0,0,0,11,0,0,0,0,0,0,0,0,0,0
0,0,0,0,0,0,0,0,0,0,0,0,0,0,0,0,0,0
0,0,0,0,0,0,0,0,0,0,0,0,0,0,0,0,0,0
0,0,0,0,0,0,0,0,0,0,0,0,27,0,0,0,0,0
0,0,0,11,0,0,0,0,15,15,28,28,15,15,15,0,0,0
0,0,0,0,0,0,0,15,30,29,12,0,29,12,15,16,0,0
0,0,0,0,0,0,0,15,31,0,0,0,0,0,15,0,0,0
0,0,0,0,0,0,0,28,31,0,0,0,0,32,15,16,0,0
0,0,0,0,0,0,0,28,0,0,0,0,0,33,15,16,0,0
0,26,26,0,0,0,0,28,31,0,0,0,0,32,15,0,0,0
0,0,0,0,0,0,34,15,31,0,0,0,0,0,15,0,0,0
0,0,0,0,0,0,0,15,10,0,0,0,0,0,15,16,0,0
0,0,0,0,0,0,34,15,15,15,15,35,15,15,0,0,0,0
0,0,0,0,0,0,0,24,24,0,36,0,36,24,0,0,0,0
0,0,0,0,0,0,0,0,0,0,0,0,0,0,0,0,0,0
0,0,0,0,0,0,0,0,0,0,0,0,0,0,0,0,0,0
0,0,0,0,0,0,0,0,0,0,0,0,0,0,0,0,0,0
0,0,0,0,0,0,0,0,0,0,0,0,0,0,0,0,0,0
0,26,0,0,0,0,0,0,0,0,0,0,0,0,0,0,0,0
endlayer

layer
0,0,0,0,0,0,0,0,0,0,0,0,0,0,0,0,0,0
0,0,0,0,0,0,0,0,0,0,0,0,0,0,0,0,0,0
0,0,0,0,0,0,0,0,0,0,0,0,0,0,0,0,0,0
0,0,0,0,0,0,0,0,0,0,0,0,0,0,0,0,0,0
0,0,0,0,0,0,37,17,0,26,0,0,0,0,0,0,0,0
0,0,0,0,0,0,0,37,0,0,0,0,0,0,0,0,0,0
0,0,0,0,0,0,0,0,0,0,0,0,0,0,0,0,0,0
0,0,0,37,0,26,0,26,0,0,0,0,27,0,0,0,0,0
0,0,0,17,37,0,0,0,0,15,28,28,15,15,0,0,0,0
0,0,0,0,0,0,0,15,0,0,0,0,0,0,15,16,0,0
0,0,0,0,0,0,0,0,0,0,0,0,0,16,15,0,0,0
0,0,0,0,0,0,0,0,0,0,0,0,0,0,28,0,0,0
0,0,0,0,0,0,0,28,0,0,0,0,0,0,28,0,0,0
0,0,0,0,0,0,34,28,0,0,0,0,0,0,28,0,0,0
0,0,0,0,0,0,34,15,0,0,0,0,0,0,15,0,0,0
0,0,0,0,0,0,0,15,0,0,0,0,0,0,0,0,0,0
0,0,0,0,0,0,34,15,15,0,15,15,15,15,0,0,0,0
0,0,0,0,0,0,0,0,24,0,0,24,24,24,0,0,0,0
0,0,0,0,0,0,0,0,0,0,0,0,0,0,0,0,0,0
0,0,0,0,0,0,0,0,0,0,0,0,0,0,0,0,0,0
0,0,0,0,0,0,0,0,0,0,0,0,0,0,0,0,0,0
0,0,0,0,0,0,0,0,0,0,0,0,0,0,0,0,0,0
0,0,0,0,0,0,0,0,0,0,0,0,0,0,0,0,0,0
endlayer

layer
0,0,0,0,0,0,0,0,0,0,0,0,0,0,0,0,0,0
0,0,0,0,0,0,0,0,0,0,0,0,0,0,0,0,0,0
0,26,0,0,0,0,0,0,0,0,0,0,0,0,0,0,0,0
26,0,0,0,0,0,0,0,0,0,0,0,0,0,0,0,0,0
0,0,0,0,0,0,0,0,0,0,0,0,0,0,0,0,0,0
0,0,0,0,0,0,0,0,0,0,0,0,0,0,0,0,0,0
0,0,0,0,0,0,0,0,0,0,0,0,0,0,0,0,0,0
0,0,0,0,0,0,0,0,0,0,27,0,27,0,0,0,0,0
0,0,0,0,0,0,0,0,0,0,15,15,15,0,0,0,0,0
0,0,0,0,0,0,0,26,0,0,0,0,0,0,15,16,0,0
0,0,0,0,0,26,0,0,0,0,0,0,0,16,0,0,0,0
0,0,0,0,0,0,0,0,0,0,0,0,0,0,16,0,0,0
0,0,0,0,0,0,0,15,0,0,0,0,0,0,15,0,0,0
0,0,0,0,0,0,34,15,0,0,0,0,0,0,15,0,0,0
0,0,0,0,0,0,34,15,0,0,0,0,0,0,16,0,0,0
0,0,0,0,0,0,0,0,0,0,0,38,0,0,0,0,0,0
0,0,0,0,0,0,0,0,0,0,0,15,15,0,0,0,0,0
0,0,0,0,0,0,0,0,0,0,24,24,24,0,0,0,0,0
0,0,0,0,0,0,0,0,0,0,0,0,0,0,0,0,0,0
0,0,0,0,0,0,0,0,0,0,0,0,0,0,0,0,0,0
0,0,0,0,0,0,0,0,0,0,0,0,0,0,0,0,0,0
0,0,0,0,0,0,0,0,0,0,0,0,0,0,0,0,0,0
0,0,0,0,0,0,0,0,0,0,0,0,0,0,0,0,0,0
endlayer

layer
0,0,0,0,0,0,0,0,0,0,0,0,0,0,0,0,0,0
0,0,0,0,0,0,0,0,0,0,0,0,0,0,0,0,0,0
0,0,0,0,0,0,0,0,0,0,0,0,0,0,0,0,0,0
0,0,0,0,0,0,0,0,0,0,0,0,0,0,0,0,0,0
0,0,0,0,0,0,0,0,0,0,0,0,0,0,0,0,0,0
0,0,0,0,0,0,0,0,0,0,0,0,0,0,0,0,0,0
0,0,0,0,0,0,0,0,0,0,0,0,0,0,0,0,0,0
0,0,0,0,0,0,0,0,0,0,0,0,0,0,0,0,0,0
0,0,0,0,0,0,0,0,0,0,27,15,0,0,0,0,0,0
0,0,0,0,0,0,0,0,0,0,15,15,15,0,0,0,0,0
0,0,0,0,0,0,0,0,0,15,15,15,15,16,0,0,0,0
0,0,0,0,0,0,0,0,15,15,15,15,0,15,16,0,0,0
0,0,0,0,0,0,0,15,15,15,0,15,15,15,0,0,0,0
0,0,0,0,0,0,34,15,15,15,15,15,15,0,0,0,0,0
0,0,0,0,0,0,0,24,15,15,15,0,15,15,16,0,0,0
0,0,0,0,0,0,0,0,0,15,15,15,15,0,0,0,0,0
0,0,0,0,0,0,0,0,0,0,15,15,0,0,0,0,0,0
0,0,0,0,0,0,0,0,0,0,24,24,0,0,0,0,0,0
0,0,0,0,0,0,0,0,0,0,0,0,0,0,0,0,0,0
0,0,0,0,0,0,0,0,0,0,0,0,0,0,0,0,0,0
0,0,0,0,0,0,0,0,0,0,0,0,0,0,0,0,0,0
0,0,0,0,0,0,0,0,0,0,0,0,0,0,0,0,0,0
0,0,0,0,0,0,0,0,0,0,0,0,0,0,0,0,0,0
endlayer

