
# Created by Ruins mod version 13.8 Ingame Parser
# authoring Player: OneWolfe

weight=8
unique=1
embed_into_distance=0
biomesToSpawnIn=plains,forest,desert,high hills,rolling hills,high plains,beach
acceptable_target_blocks=
unacceptable_target_blocks=flowing_water,water,flowing_lava,lava
dimensions=8,13,6
allowable_overhang=10
max_leveling=6
leveling_buffer=0
preserve_water=0
preserve_lava=0
preserve_plants=1

rule1=0,100,terrafirmacraft:WoodVert-12
rule2=0,100,terrafirmacraft:FenceGate-12
rule3=0,100,terrafirmacraft:Fence-12,terrafirmacraft:Fence-12,terrafirmacraft:Fence-12,air
rule4=0,100,terrafirmacraft:StoneMMBrick-4
rule5=0,100,terrafirmacraft:StoneMMBrick-4,terrafirmacraft:StoneMMBrick-4,terrafirmacraft:StoneMMBrick-4,MobSpawner:spiderTFC,MobSpawner:skeletonTFC,MobSpawner:silverfishTFC,MobSpawner:pigZombieTFC,MobSpawner:TwilightForest.Troll,MobSpawner:TwilightForest.Lower Goblin Knight,MobSpawner:TwilightForest.Redcap Sapper,air
rule6=0,100,air
rule7=0,100,air,air,air,air,air,minecraft:anvil-6,air
rule8=0,100,air,minecraft:anvil-10,minecraft:anvil-10
rule9=0,100,air,air,Steamcraft:steamTank-0,Steamcraft:steamTank-0,Steamcraft:steamTank-0,Steamcraft:steamTank-0,air
rule10=0,100,terrafirmacraft:Charcoal-8,terrafirmacraft:Charcoal-8,terrafirmacraft:Charcoal-8,air
rule11=0,100,Steamcraft:hammer-2,Steamcraft:hammer-2,air,air,air
rule12=0,100,Steamcraft:pipe-0,Steamcraft:pipe-0,Steamcraft:pipe-0,air
rule13=0,100,air,air,Steamcraft:valvePipe-2
rule14=0,100,air,air,Steamcraft:meter-2
rule15=0,100,air,air,Steamcraft:ruptureDisc-3
rule16=0,100,terrafirmacraft:WoodHoriz2-4
rule17=0,100,terrafirmacraft:WoodHoriz2-12
rule18=0,100,terrafirmacraft:planks-5,terrafirmacraft:planks-5,terrafirmacraft:planks-5,terrafirmacraft:planks-5,terrafirmacraft:planks-5,terrafirmacraft:planks-5,air
rule19=0,100,air,air,Steamcraft:horn-4

layer
1,3,3,3,2,1
3,0,0,0,0,3
4,4,4,4,0,3
4,4,4,4,0,3
4,4,4,4,0,1
4,4,5,4,0,3
4,4,4,4,0,3
4,4,4,4,0,3
4,4,4,4,0,1
4,4,4,4,0,3
4,4,4,4,0,3
3,0,0,0,6,3
1,3,3,3,2,1
endlayer

layer
1,0,0,0,0,1
0,0,6,0,6,0
4,0,7,0,6,6
4,0,7,6,6,6
4,0,8,6,6,1
4,0,6,6,6,6
4,9,6,6,6,0
4,9,0,6,6,0
4,4,4,6,6,1
4,10,4,6,6,6
4,4,4,0,6,6
0,0,0,0,6,6
1,0,0,0,0,1
endlayer

layer
1,0,0,0,0,1
6,0,0,0,0,0
4,12,11,0,0,0
4,12,11,0,0,0
4,12,11,0,6,1
4,13,6,0,6,6
4,9,0,6,6,0
15,9,14,0,0,0
4,4,0,0,0,1
4,0,6,6,6,0
4,4,0,0,0,0
0,0,0,0,0,6
1,0,0,0,0,1
endlayer

layer
1,16,16,16,16,1
17,0,0,0,0,17
4,0,0,0,0,17
4,0,0,0,0,17
4,0,0,0,0,1
4,0,0,0,6,17
4,9,6,6,6,17
4,9,0,0,0,17
4,4,6,6,0,1
4,0,0,0,0,17
4,4,0,0,6,17
17,0,0,0,0,17
1,16,16,16,16,1
endlayer

layer
18,18,18,18,18,18
18,0,0,0,0,18
18,0,0,0,0,18
18,0,0,0,0,18
18,0,0,0,0,18
18,0,0,0,0,18
18,12,0,6,0,18
18,0,0,0,0,18
18,4,4,0,0,18
4,0,4,0,0,18
18,4,4,0,0,18
18,0,0,0,0,18
18,18,18,18,18,18
endlayer

layer
0,0,0,0,0,0
0,18,18,18,18,0
0,18,0,0,18,0
0,18,0,0,18,0
0,18,0,0,18,0
0,18,0,0,18,0
0,12,0,0,18,0
0,18,0,0,18,0
0,4,0,6,18,0
4,0,4,0,18,0
0,4,0,0,18,0
0,18,18,18,18,0
0,0,0,0,0,0
endlayer

layer
0,0,0,0,0,0
0,0,0,0,0,0
6,0,18,18,0,0
0,6,18,18,6,0
0,6,18,18,0,0
0,0,18,18,0,0
0,12,18,18,0,0
0,0,18,18,6,0
0,4,18,18,6,0
4,0,4,18,6,0
6,4,18,18,0,0
6,6,0,6,0,0
0,6,6,0,0,0
endlayer

layer
0,0,0,0,0,0
0,0,0,0,0,0
0,0,0,0,0,0
6,0,6,0,0,0
0,0,0,0,0,0
6,19,0,0,0,0
0,12,0,0,0,0
0,0,0,0,0,0
0,4,0,0,0,0
4,0,4,0,0,0
6,4,0,0,0,0
0,0,0,0,0,0
0,0,0,0,0,0
endlayer

