
# Created by Ruins mod version 13.8 Ingame Parser
# authoring Player: Spud_Gunn

weight=5
embed_into_distance=0
acceptable_target_blocks=
unacceptable_target_blocks=flowing_water,water,flowing_lava,lava
dimensions=4,11,8
allowable_overhang=8
max_leveling=6
leveling_buffer=0
preserve_water=0
preserve_lava=0
preserve_plants=1

rule1=0,100,minecraft:rail-1
rule2=0,100,terrafirmacraft:WoodVert-6
rule3=0,100,terrafirmacraft:planks-2
rule4=0,100,minecraft:golden_rail-1
rule5=0,100,terrafirmacraft:StoneIgInSmooth-0
rule6=0,100,minecraft:lever-3
rule7=0,100,terrafirmacraft:Chest TFC-5
rule8=0,100,minecraft:lever-11
rule9=0,100,air
rule10=0,100,terrafirmacraft:DoorWhiteCedar-2
rule11=0,100,minecraft:rail-7
rule12=0,100,minecraft:rail-0
rule13=0,100,minecraft:lever-6
rule14=0,100,minecraft:golden_rail-0
rule15=0,100,minecraft:lever-13
rule16=0,100,minecraft:stained_glass_pane-15
rule17=0,100,minecraft:lever-5
rule18=0,100,terrafirmacraft:DoorWhiteCedar-8
rule19=0,100,terrafirmacraft:Thatch-0

layer
0,0,0,0,0,0,0,0
0,2,3,3,3,2,1,0
0,3,7,6,5,3,4,0
0,3,0,8,5,3,0,0
0,3,0,6,5,3,1,0
0,3,0,9,5,3,4,0
0,2,3,10,3,2,1,0
0,0,0,0,0,12,11,0
0,0,0,0,1,13,1,0
0,12,12,14,11,0,1,0
0,0,9,0,0,0,1,0
endlayer

layer
0,0,0,0,0,0,0,0
0,2,3,3,3,2,9,9
0,3,0,0,15,3,0,9
0,16,0,9,17,16,0,0
0,16,0,9,15,16,0,0
0,3,0,0,17,3,0,0
0,2,3,18,3,2,0,0
0,0,0,0,0,0,0,0
0,0,0,0,9,0,0,0
0,0,0,0,0,0,0,0
0,0,0,0,0,0,0,0
endlayer

layer
0,0,0,0,0,0,0,0
0,2,3,3,3,2,0,0
0,3,0,0,0,3,0,0
0,3,0,0,0,3,0,0
0,3,0,0,9,3,0,0
0,3,0,0,0,3,0,0
0,2,3,3,3,2,0,0
0,0,0,0,0,0,0,0
0,0,0,0,0,0,0,0
0,0,0,0,0,0,0,0
0,0,0,0,0,0,0,0
endlayer

layer
0,0,0,0,0,0,0,0
0,2,19,19,19,2,0,0
0,19,19,19,19,19,0,0
0,19,19,19,19,19,0,0
0,19,19,19,19,19,0,0
0,19,19,19,19,19,0,0
0,2,19,19,19,2,0,0
0,0,0,9,0,0,0,0
0,0,0,0,0,0,0,0
0,0,0,0,0,0,0,0
0,0,0,0,0,0,0,0
endlayer

