
# Created by Ruins mod version 13.8 Ingame Parser
# authoring Player: Spud_Gunn

weight=4
unique=1
biomesToSpawnIn=forest,swamp,high hills
embed_into_distance=0
acceptable_target_blocks=
unacceptable_target_blocks=flowing_water,water,flowing_lava,lava,terrafirmacraft:SaltWaterStationary-0,terrafirmacraft:SaltWaterStationary-8,terrafirmacraft:FreshWaterStationary-0,terrafirmacraft:FreshWaterStationary-8
dimensions=18,12,19
allowable_overhang=4
max_leveling=6
leveling_buffer=0
preserve_water=0
preserve_lava=0
preserve_plants=1

rule1=0,100,terrafirmacraft:Vine-8
rule2=0,100,terrafirmacraft:Vine-1
rule3=0,100,terrafirmacraft:WoodVert-4,terrafirmacraft:WoodVert-4,terrafirmacraft:WoodVert-4,terrafirmacraft:WoodVert-4,air
rule4=0,100,terrafirmacraft:Vine-2
rule5=0,100,air,terrafirmacraft:StoneIgInSmooth-1,terrafirmacraft:StoneIgInSmooth-1,terrafirmacraft:StoneIgInSmooth-1,terrafirmacraft:StoneIgInSmooth-1
rule6=0,100,terrafirmacraft:StoneIgInCobble-1
rule7=0,100,terrafirmacraft:StoneSedCobble-0
rule8=0,100,air,terrafirmacraft:StoneSedSmooth-0,terrafirmacraft:StoneSedSmooth-0,terrafirmacraft:StoneSedSmooth-0,terrafirmacraft:StoneSedSmooth-0,terrafirmacraft:StoneSedSmooth-0
rule9=0,100,air,terrafirmacraft:Vine-4
rule10=0,100,air,air,MobSpawner:TwilightForest.Redcap,MobSpawner:TwilightForest.Redcap,MobSpawner:TwilightForest.Redcap Sapper,MobSpawner:TwilightForest.Twilight Kobold
rule11=0,100,air
rule12=0,100,terrafirmacraft:DoorHickory-3
rule13=0,100,terrafirmacraft:WoodHoriz-4,terrafirmacraft:WoodHoriz-4,terrafirmacraft:WoodHoriz-4,air
rule14=0,100,terrafirmacraft:WallSmoothIgIn-2,terrafirmacraft:WallSmoothIgIn-2,terrafirmacraft:WallSmoothIgIn-2,air
rule15=0,100,minecraft:ladder-5
rule16=0,100,air,minecraft:stained_glass_pane-7
rule17=0,100,terrafirmacraft:DoorHickory-8
rule18=0,100,terrafirmacraft:Fence2-0,terrafirmacraft:Fence2-0,terrafirmacraft:Fence2-0,air
rule19=0,100,terrafirmacraft:Vine-0
rule20=0,100,terrafirmacraft:WoodHoriz-12,terrafirmacraft:WoodHoriz-12,terrafirmacraft:WoodHoriz-12,air
rule21=0,100,terrafirmacraft:StoneIgInBrick-1,terrafirmacraft:StoneIgInBrick-1,terrafirmacraft:StoneIgInBrick-1,air
rule22=0,100,terrafirmacraft:planks-1,terrafirmacraft:planks-1,terrafirmacraft:planks-1,terrafirmacraft:planks-1,air
rule23=0,100,terrafirmacraft:planks-2,terrafirmacraft:planks-2,terrafirmacraft:planks-2,air
rule24=0,100,air
rule25=0,100,Steamcraft:heater-0
rule26=0,100,air,minecraft:stained_glass_pane-4
rule27=0,100,air,minecraft:stained_glass_pane-5
rule28=0,100,air,air,ChestGenHook:dungeonChest:5-3
rule29=0,100,Steamcraft:steamTank-0,Steamcraft:steamTank-0,air
rule30=0,100,Steamcraft:pipe-0
rule31=0,100,Steamcraft:valvePipe-2,Steamcraft:valvePipe-2,air
rule32=2,100,minecraft:redstone_torch-1
rule33=0,100,minecraft:ladder-3
rule34=0,100,terrafirmacraft:StoneSedBrick-0,terrafirmacraft:StoneSedBrick-0,terrafirmacraft:StoneSedBrick-0,air
rule35=0,100,air,air,ChestGenHook:dungeonChest:5-2
rule36=2,100,minecraft:redstone_torch-4
rule37=0,100,terrafirmacraft:Vine-6
rule38=0,100,Steamcraft:valvePipe-4
rule39=0,100,ForgeMultipart:block-0
rule40=0,100,air,terrafirmacraft:Bookshelf-0
rule41=0,100,air,terrafirmacraft:Torch-11
rule42=0,100,air,terrafirmacraft:Torch-12
rule43=0,100,Steamcraft:fluidSteamConverter-4
rule44=0,100,air,air,Steamcraft:horn-4
rule45=0,100,air,air,Steamcraft:horn-2
rule46=0,100,air,air,air,Steamcraft:horn-3

layer
0,0,0,0,0,0,0,0,0,0,0,0,0,0,0,1,0,0,0
0,0,0,0,3,0,1,0,0,0,0,1,0,0,0,3,2,0,0
0,0,0,0,0,5,5,6,6,5,5,6,5,0,0,4,0,0,0
0,0,0,0,9,5,4,0,0,7,8,7,5,0,0,0,0,0,0
0,0,0,11,11,12,11,11,0,8,10,8,5,0,0,0,0,0,0
0,0,0,0,0,5,0,0,0,8,7,8,6,2,0,0,0,0,0
0,0,0,0,0,6,5,5,5,5,5,5,5,0,0,0,0,0,0
0,0,0,0,0,0,0,3,13,13,3,0,0,0,0,0,0,0,0
0,0,0,0,11,0,0,0,0,4,0,0,0,0,0,0,0,0,0
0,0,9,3,0,0,0,0,0,0,0,0,0,0,0,3,0,0,0
0,0,0,0,0,0,0,0,0,0,0,0,0,0,0,0,11,0,0
0,0,0,0,0,0,0,0,0,0,0,0,0,0,0,0,0,0,0
endlayer

layer
0,11,0,11,0,0,0,0,0,0,0,0,0,0,0,0,0,0,0
0,0,0,0,3,0,1,0,0,0,1,1,0,0,0,3,2,0,0
0,0,0,0,0,14,5,5,5,5,5,5,14,0,0,0,0,0,0
0,0,0,0,9,5,4,0,0,11,11,15,5,0,0,0,0,0,0
0,0,0,0,0,17,11,0,11,11,11,11,16,0,0,0,0,11,0
0,0,0,0,0,5,0,0,0,0,1,0,5,2,0,0,0,0,0
0,0,0,0,9,14,5,5,5,5,5,5,14,0,0,11,0,11,0
0,0,0,0,0,0,0,18,0,4,18,0,0,0,11,11,0,0,0
0,0,0,0,0,0,0,0,0,0,0,0,11,11,0,0,0,0,0
0,0,9,3,0,11,0,0,0,0,0,0,0,0,0,3,0,0,0
0,0,0,0,0,0,0,0,0,0,0,0,0,0,0,0,0,0,0
0,0,0,0,11,0,11,0,11,0,0,0,11,0,0,0,0,0,0
endlayer

layer
0,0,0,0,0,0,0,0,0,0,0,0,0,0,1,1,0,0,0
0,0,0,0,3,0,1,1,0,0,0,1,0,0,0,3,2,0,0
0,0,0,0,0,14,5,5,16,16,5,5,14,0,0,4,0,0,0
0,0,0,0,9,5,4,0,0,0,11,15,5,0,0,0,0,0,0
0,0,0,0,0,5,0,0,0,0,0,11,16,0,0,0,0,0,0
0,0,11,11,0,5,0,0,0,0,1,0,5,2,0,0,0,0,0
0,0,0,0,9,0,5,5,16,16,5,5,0,0,0,0,0,0,0
11,0,0,0,0,0,0,18,0,0,18,0,0,0,0,0,0,0,0
0,11,0,0,0,0,0,0,0,0,0,11,0,0,0,0,0,0,0
0,0,9,3,0,0,0,0,0,0,0,0,0,0,0,3,0,0,0
0,0,0,0,0,0,0,0,0,11,0,0,0,0,0,0,0,0,0
0,0,0,0,11,0,0,0,0,0,0,0,0,0,0,0,0,0,0
endlayer

layer
0,0,11,0,0,0,0,0,0,0,0,0,0,0,1,1,0,0,0
0,0,0,0,3,0,0,1,0,0,0,1,0,0,0,3,2,0,0
0,0,9,0,0,5,5,5,5,5,5,5,5,2,0,4,0,0,0
0,0,0,0,9,5,4,0,0,0,11,15,5,0,0,0,0,0,0
0,0,0,0,0,5,0,0,0,0,0,0,5,0,0,0,0,0,0
0,0,0,0,0,5,0,0,0,0,1,0,5,0,0,0,0,0,0
0,0,0,0,19,5,5,5,5,5,5,5,5,0,0,0,0,0,0
0,0,0,0,0,0,0,18,0,0,18,0,0,0,0,0,0,0,0
0,0,0,0,0,0,0,0,0,0,0,0,0,0,0,0,0,0,0
0,0,9,3,0,0,0,0,0,0,0,0,0,0,0,3,0,0,0
0,0,0,4,0,0,0,4,0,11,0,0,0,0,0,0,0,0,0
0,11,0,11,11,0,0,11,0,0,0,0,0,0,0,0,0,0,0
endlayer

layer
0,0,0,0,0,0,0,0,0,0,0,0,0,0,1,1,0,0,0
0,0,0,0,20,13,13,13,13,13,13,13,20,20,13,3,2,0,0
0,0,9,0,20,5,5,5,5,5,5,5,5,20,20,20,0,0,0
0,0,0,0,20,5,21,21,21,21,21,15,11,20,20,20,0,0,0
0,0,0,0,20,5,21,21,21,21,21,21,5,20,20,20,0,0,0
0,0,9,0,20,5,21,21,21,21,21,21,5,20,20,20,0,0,0
0,0,0,0,20,5,5,5,5,5,5,5,5,20,20,20,0,0,0
0,0,0,0,20,13,13,13,13,13,13,13,13,20,20,13,0,0,0
0,0,0,0,20,3,13,13,13,13,13,13,13,20,20,20,0,0,0
0,0,9,3,13,13,13,13,13,13,13,13,20,20,13,3,0,0,0
0,0,0,4,0,0,0,4,0,0,0,0,4,0,11,20,0,0,0
0,0,0,0,0,0,11,11,0,0,0,0,0,11,0,0,0,0,11
endlayer

layer
0,0,0,0,0,0,0,0,0,0,0,0,0,0,0,1,0,0,0
0,0,0,0,3,0,1,0,0,1,0,0,1,0,0,3,2,0,0
0,0,9,22,22,22,22,23,22,22,22,22,23,23,22,0,11,11,0
0,0,0,22,5,0,0,0,0,0,0,11,11,3,23,0,0,0,0
0,0,0,22,5,0,11,11,11,11,11,0,0,5,22,0,0,0,0
0,0,9,22,5,0,11,11,11,11,11,11,0,5,22,2,0,0,0
0,0,9,22,5,24,0,0,0,11,0,11,11,5,23,0,0,0,0
0,0,0,0,23,5,5,5,5,5,5,5,5,5,22,0,0,0,0
0,0,0,0,23,22,22,22,22,22,22,22,22,22,0,0,0,0,0
0,0,0,3,0,0,0,0,0,0,0,0,4,0,0,3,0,0,0
0,0,0,4,0,25,0,0,0,0,0,0,0,0,0,0,0,0,0
0,0,0,0,0,0,0,0,0,0,0,0,0,0,0,0,0,0,0
endlayer

layer
0,0,0,0,0,0,0,0,0,0,0,0,0,0,0,11,0,0,0
0,0,0,0,3,11,1,0,0,1,0,0,1,0,0,3,0,0,0
0,0,0,22,22,22,22,22,26,22,26,26,22,22,23,0,0,0,0
0,0,0,27,0,0,11,0,0,0,0,0,0,3,22,0,0,0,0
0,0,0,27,0,11,11,11,0,0,0,11,0,0,22,0,0,0,0
0,0,9,22,0,11,11,11,11,0,0,11,0,0,22,2,0,0,0
0,0,9,22,29,29,11,11,0,11,0,0,11,28,23,0,0,0,0
0,0,9,23,3,29,11,0,0,0,0,0,0,0,22,0,0,0,0
0,0,0,0,22,30,26,26,26,22,26,26,22,22,0,0,0,0,0
0,0,0,3,2,30,0,0,0,0,4,0,4,0,0,3,0,0,0
0,0,0,4,0,30,0,0,0,0,0,0,0,0,0,0,0,0,0
0,0,0,0,0,0,0,0,0,0,0,0,0,0,0,0,0,0,0
endlayer

layer
0,0,0,0,0,0,0,0,0,0,0,0,0,0,0,0,0,0,0
0,0,0,0,3,0,0,0,0,1,0,0,1,0,0,3,0,0,0
0,0,0,22,22,22,22,22,22,22,22,22,22,23,22,0,0,0,0
0,0,0,22,0,0,0,0,0,0,0,0,0,3,23,0,0,0,0
0,0,0,22,0,0,11,0,0,0,0,0,0,0,22,2,0,0,0
0,0,0,22,0,0,0,0,0,11,11,0,0,0,23,0,0,0,0
0,0,9,23,0,31,0,0,0,0,0,0,11,0,22,0,0,0,0
0,0,9,23,3,0,0,0,0,0,0,0,0,0,22,0,0,0,0
0,0,20,32,23,22,22,22,22,22,22,22,23,22,0,0,0,0,0
0,0,20,3,0,0,0,0,0,0,4,0,4,0,0,3,2,0,0
0,0,20,0,0,0,0,0,0,0,0,0,0,0,0,0,0,0,0
0,8,8,8,8,8,8,8,8,8,8,8,8,8,0,0,11,0,0
endlayer

layer
0,8,8,8,8,8,8,8,8,8,8,8,8,8,8,8,8,0,0
0,0,20,20,0,0,0,0,0,0,0,0,1,0,0,3,2,0,0
9,0,20,20,22,22,22,23,22,22,23,22,23,22,22,13,2,0,0
0,0,20,20,22,0,11,0,0,0,0,0,0,3,22,20,0,0,11
0,0,20,20,22,0,11,11,0,0,0,0,0,0,22,20,0,0,0
0,0,20,20,22,0,11,0,11,11,11,0,0,0,22,20,0,0,0
0,0,20,20,22,30,11,11,0,11,11,0,0,33,22,20,0,0,0
0,0,20,20,3,22,22,22,22,22,22,22,22,22,22,20,0,0,0
0,0,20,20,23,23,22,22,22,23,22,22,22,23,0,0,0,0,0
0,0,20,3,0,0,0,4,0,4,4,0,0,0,0,3,2,0,0
0,8,8,8,8,8,34,34,8,8,8,8,34,8,8,0,0,0,0
0,0,0,0,0,0,0,0,0,4,0,0,0,0,0,0,0,0,0
endlayer

layer
0,0,0,0,0,1,0,0,0,1,0,0,0,1,0,0,0,0,0
0,8,8,34,34,34,8,34,34,34,8,8,34,34,34,34,8,0,0
9,0,0,22,10,22,22,22,22,22,22,22,22,22,22,0,0,0,0
0,0,0,22,35,11,11,0,11,0,0,0,0,3,22,0,0,0,0
0,0,3,22,0,11,11,11,11,0,11,0,0,0,22,3,0,0,0
0,0,0,26,0,0,11,11,0,0,11,11,0,0,23,0,0,0,0
0,0,3,22,0,30,0,11,0,0,0,0,0,0,22,3,0,0,0
0,0,0,22,3,30,0,0,0,0,0,0,0,0,23,2,0,0,0
0,0,9,23,22,22,22,22,22,23,23,22,23,23,23,0,0,0,0
0,8,8,8,8,4,8,8,8,8,8,34,34,34,8,8,2,0,0
0,4,4,4,0,0,0,0,0,4,0,0,4,0,0,0,0,0,0
0,0,0,0,0,0,0,0,0,0,0,0,0,0,0,0,0,0,0
endlayer

layer
0,0,0,0,0,0,0,0,0,0,0,0,0,0,0,0,0,0,0
0,1,0,0,0,1,0,1,1,1,0,0,0,1,1,0,0,0,0
9,8,8,34,34,34,34,8,34,34,8,34,34,8,34,34,8,0,0
0,4,0,22,0,0,0,0,0,11,0,0,0,3,23,0,0,0,0
0,0,0,22,0,0,0,11,0,0,0,0,0,0,23,3,0,11,0
0,0,0,27,0,0,0,0,0,0,0,0,0,0,23,0,0,0,11
0,0,3,22,0,0,0,0,0,0,0,0,0,0,22,2,0,0,11
0,0,0,22,3,30,0,0,0,0,0,0,0,0,22,2,0,0,0
0,8,8,34,8,8,8,34,8,34,34,34,34,34,34,8,8,0,0
0,0,0,0,0,0,0,0,0,4,0,0,4,0,0,0,0,0,0
0,0,0,11,0,0,0,0,0,0,0,0,0,0,0,0,0,0,0
0,0,11,0,0,0,0,0,0,0,0,0,0,0,0,0,0,0,0
endlayer

layer
0,0,0,0,0,0,0,0,11,0,0,0,0,0,0,0,0,0,0
0,0,0,0,0,0,0,0,1,0,0,0,0,1,1,0,0,0,0
8,8,34,34,34,34,8,34,8,34,34,8,30,34,34,8,34,8,0
0,0,0,23,20,0,0,0,0,0,0,0,30,3,36,0,0,0,0
0,0,37,22,20,0,0,0,0,0,0,0,30,20,22,2,0,0,0
0,0,20,22,20,0,0,0,0,0,0,0,30,20,22,0,0,0,0
0,0,3,22,20,0,0,0,0,0,0,0,30,20,22,2,0,0,0
0,0,0,39,3,30,38,30,30,30,30,30,30,20,0,0,0,0,0
8,8,8,0,8,30,8,8,34,34,34,8,34,34,34,34,8,8,0
0,0,11,0,0,19,4,0,0,4,0,0,0,0,0,0,0,0,0
0,0,0,0,0,0,0,0,0,0,0,0,0,0,0,0,0,0,0
0,0,0,0,0,0,0,0,0,0,0,0,0,0,0,0,0,0,0
endlayer

layer
0,0,0,0,0,0,0,0,0,0,0,0,0,0,0,0,0,0,0
0,0,0,0,0,0,0,0,0,0,0,0,0,0,0,0,0,0,0
0,1,1,0,0,0,0,0,0,0,0,0,30,0,0,0,0,0,0
8,8,34,34,34,34,34,8,34,34,34,34,34,34,8,8,8,8,0
0,0,37,23,40,0,0,0,0,0,0,0,0,0,22,2,0,0,0
0,0,0,22,42,0,0,0,0,0,0,0,0,41,22,0,0,0,0
0,0,0,23,40,0,0,0,0,0,0,0,0,0,0,0,0,0,0
8,8,34,34,8,8,8,8,34,34,8,8,8,34,34,8,8,8,0
0,0,0,0,8,30,8,0,0,0,0,0,0,0,0,4,0,0,0
0,0,0,0,0,8,0,0,0,0,0,0,0,0,0,0,0,0,0
0,0,0,0,0,0,0,0,0,0,0,0,0,0,0,0,0,0,0
0,0,0,0,0,0,0,0,0,0,0,0,0,0,0,0,0,0,0
endlayer

layer
0,0,0,0,0,0,0,0,0,0,0,0,43,0,0,0,0,0,0
0,0,0,0,0,0,0,0,0,0,0,0,30,0,0,0,0,0,0
0,0,0,0,0,0,0,0,0,0,0,0,30,0,0,0,0,0,0
0,0,0,0,1,0,0,0,0,1,0,0,0,0,0,1,0,0,0
8,8,8,34,34,34,34,34,34,34,34,34,34,34,34,8,8,8,0
0,0,8,8,8,8,0,34,34,0,0,0,8,34,8,8,0,0,0
8,8,8,8,8,8,34,34,34,34,34,8,34,34,34,8,8,8,0
0,0,0,0,0,8,8,0,4,4,0,0,0,4,4,0,0,0,0
0,0,0,0,8,30,8,0,0,0,0,0,0,0,0,0,0,0,0
0,0,0,0,8,30,11,0,0,0,11,0,0,0,0,0,0,0,0
0,0,0,0,0,11,0,0,11,11,0,11,0,0,0,0,0,0,0
0,0,11,0,0,0,0,0,0,0,0,0,0,0,0,0,0,0,0
endlayer

layer
0,0,0,0,0,0,0,0,0,0,0,0,0,0,0,0,0,0,0
0,0,0,0,0,0,0,0,0,0,0,0,0,0,0,0,0,0,0
0,0,0,0,0,0,0,0,0,0,0,0,0,0,0,0,0,0,0
0,0,0,0,0,0,0,0,0,0,0,0,0,0,0,0,0,0,0
0,0,0,0,0,0,1,0,0,0,0,0,0,0,0,0,0,0,0
8,8,8,8,8,8,8,8,8,8,8,8,8,8,8,8,8,8,0
0,0,0,0,0,11,0,0,0,0,0,0,0,0,0,0,0,0,0
0,0,0,0,0,11,0,0,0,0,11,0,0,0,0,0,11,0,0
0,0,0,0,0,8,0,0,0,0,0,0,11,0,0,0,0,0,0
0,0,11,0,8,30,8,0,0,0,0,0,0,0,0,0,0,0,0
0,0,0,0,0,8,0,0,0,0,0,0,0,0,0,0,0,0,0
0,0,0,0,0,0,0,0,0,0,0,0,0,0,0,0,0,0,0
endlayer

layer
0,0,0,0,0,0,0,0,0,0,0,0,0,0,0,0,0,0,0
0,0,0,0,0,0,0,0,0,0,0,0,0,0,0,0,0,0,0
0,0,0,0,0,0,0,0,0,0,0,0,0,0,0,0,0,0,0
0,0,0,0,0,0,0,0,0,0,0,0,0,0,0,0,0,0,0
0,0,0,11,0,0,0,0,0,0,0,0,0,0,0,0,0,0,0
0,0,0,0,0,0,0,0,0,0,0,0,0,0,0,0,0,0,0
0,0,0,0,0,0,0,0,0,0,0,0,0,0,0,0,0,0,0
0,0,0,0,0,11,0,11,0,0,0,0,0,0,0,0,0,0,0
0,0,0,0,0,44,0,11,0,0,0,0,0,0,0,0,0,0,0
0,0,0,0,46,30,45,0,0,11,0,0,0,0,0,0,0,0,0
0,0,0,0,0,8,0,0,0,0,0,0,0,0,0,0,0,0,0
0,0,0,0,0,0,0,0,0,0,0,0,0,0,0,0,0,0,0
endlayer

layer
0,0,0,0,0,0,0,0,0,0,0,0,0,0,0,0,0,0,0
0,0,0,0,0,0,0,0,0,0,0,0,0,0,0,0,0,0,0
0,0,0,0,0,0,0,0,0,0,0,0,0,0,0,0,0,0,0
0,0,0,0,0,0,0,0,0,0,0,0,0,0,0,0,0,0,0
0,0,0,0,0,0,0,0,0,0,0,0,0,0,0,0,0,0,0
0,0,0,0,0,0,0,0,0,0,0,0,0,0,0,0,0,0,0
0,0,0,0,0,0,0,0,0,0,0,0,0,0,0,0,0,0,0
0,0,0,0,0,11,11,0,0,0,0,0,0,0,0,0,0,0,0
0,0,0,0,0,0,0,0,0,0,0,0,0,0,0,0,0,0,0
0,0,0,0,0,8,0,11,11,0,0,0,0,0,0,0,0,0,0
0,0,0,0,0,11,11,0,0,0,0,0,0,0,0,0,0,0,0
0,0,0,0,0,0,0,0,0,0,0,0,0,0,0,0,0,0,0
endlayer

layer
0,0,0,0,0,0,0,0,0,0,0,0,0,0,0,0,0,0,0
0,0,0,0,0,0,0,0,0,0,0,0,0,0,0,0,0,0,0
0,0,0,0,0,0,0,0,0,0,0,0,0,0,0,0,0,0,0
0,0,0,0,0,0,0,0,0,0,0,0,0,0,0,0,0,0,0
0,0,0,0,0,0,0,0,0,0,0,0,0,0,0,0,0,0,0
0,0,0,0,0,0,0,0,0,0,0,0,0,0,0,0,0,0,0
0,0,0,0,0,0,0,0,0,0,0,0,0,0,0,0,0,0,0
0,0,0,0,0,0,0,11,0,0,0,0,0,0,0,0,0,0,0
0,0,0,0,0,0,0,0,0,0,0,0,0,0,0,0,0,0,0
0,0,0,0,0,0,0,0,0,0,0,0,0,0,0,0,0,0,0
0,0,0,0,0,11,0,11,0,0,0,0,0,0,0,0,0,0,0
0,0,0,0,0,0,0,0,0,0,0,0,0,0,0,0,0,0,0
endlayer

