
# Created by Ruins mod version 13.8 Ingame Parser
# authoring Player: Spud_Gunn

weight=6
unique=1
embed_into_distance=1
acceptable_target_blocks=
unacceptable_target_blocks=flowing_water,water,flowing_lava,lava
dimensions=4,37,7
allowable_overhang=4
max_leveling=6
leveling_buffer=0
preserve_water=0
preserve_lava=0
preserve_plants=1

rule1=0,100,terrafirmacraft:StoneMMBrick-4
rule2=0,100,air,air,minecraft:rail-1
rule3=0,100,air,air,minecraft:golden_rail-1
rule4=0,100,terrafirmacraft:WallSmoothIgEx-1
rule5=0,100,air,air,minecraft:rail-7
rule6=0,100,air,air,minecraft:rail-0
rule7=0,100,air,air,minecraft:rail-9
rule8=0,100,air,air,minecraft:rail-6
rule9=0,100,air,air,minecraft:rail-8
rule10=0,100,air
rule11=0,100,air,air,Railcraft:signal-3
rule12=0,100,terrafirmacraft:StoneIgExSmooth-1
rule13=0,100,preserveBlock

layer
13,13,13,13,13,13,13
13,13,13,1,1,1,13
13,13,13,1,1,1,13
13,13,13,1,1,1,13
13,13,13,1,1,1,13
13,13,13,1,1,1,13
13,13,1,1,1,1,13
13,1,1,1,1,1,13
13,1,1,1,1,1,13
13,1,1,1,1,1,13
13,1,1,1,1,13,13
13,1,1,1,13,13,13
13,1,1,1,13,13,13
13,1,1,1,13,13,13
13,1,1,1,13,13,13
13,1,1,1,13,13,13
13,1,1,1,13,13,13
13,1,1,1,13,13,13
13,1,1,1,13,13,13
13,1,1,1,13,13,13
13,1,1,1,13,13,13
13,1,1,1,13,13,13
13,1,1,1,13,13,13
13,1,1,1,13,13,13
13,1,1,1,1,13,13
13,1,1,1,1,1,13
13,1,1,1,1,1,13
13,1,1,1,1,1,13
13,13,1,1,1,1,13
13,13,13,1,1,1,13
13,13,13,1,1,1,13
13,13,13,1,1,1,13
13,13,13,1,1,1,13
13,13,13,1,1,1,13
13,13,13,1,1,1,13
13,13,13,1,1,1,13
13,13,13,13,13,13,13
endlayer

layer
0,0,0,0,0,0,0
0,0,0,2,2,0,0
0,0,0,3,3,2,0
0,0,0,0,2,2,0
0,0,0,2,2,3,0
0,0,0,2,2,2,0
0,0,4,2,3,0,0
0,7,6,5,2,2,0
0,2,0,6,5,2,0
0,3,0,7,6,5,0
0,2,2,2,4,0,0
0,0,3,2,0,0,0
0,2,2,3,0,0,0
0,3,2,2,0,0,0
0,2,0,2,0,0,0
0,2,2,2,0,0,0
0,2,3,0,0,0,0
0,3,2,0,0,0,0
0,0,2,2,0,0,0
0,2,2,2,0,0,0
0,2,0,3,0,0,0
0,3,2,2,0,0,0
0,2,2,0,0,0,0
0,0,3,2,0,0,0
0,2,2,2,4,0,0
0,3,0,9,6,8,0
0,2,0,6,8,2,0
0,9,6,8,2,3,0
0,0,4,2,2,2,0
0,0,0,0,3,0,0
0,0,0,2,2,0,0
0,0,0,3,2,2,0
0,0,0,2,0,3,0
0,0,0,2,2,2,0
0,0,0,2,3,0,0
0,0,0,0,2,2,0
0,0,0,0,0,0,0
endlayer

layer
0,0,0,0,0,0,0
10,0,0,0,10,0,0
0,0,0,0,0,0,0
0,0,0,0,0,10,0
0,0,0,0,0,0,0
0,0,0,0,0,0,0
0,0,4,0,0,0,0
0,0,0,0,0,0,0
0,0,0,0,0,0,0
0,0,0,0,0,0,0
0,0,0,0,0,0,0
0,0,0,0,0,0,0
0,0,0,0,0,0,0
0,0,0,0,0,0,0
0,0,0,0,0,0,0
0,0,0,0,0,0,0
0,0,0,0,0,0,0
0,0,0,0,0,10,0
0,0,0,0,0,0,0
0,0,0,0,0,0,0
0,0,0,0,0,0,0
0,0,0,0,0,0,0
0,0,0,0,0,0,0
0,0,0,0,0,0,0
10,0,0,0,4,0,0
0,0,0,0,0,0,0
0,0,0,0,0,0,0
0,0,0,0,10,0,0
0,0,4,0,0,0,0
0,0,0,0,0,10,0
0,0,0,10,0,0,0
0,0,0,0,0,0,0
0,0,0,0,0,0,0
0,0,0,0,0,0,0
0,0,0,0,0,0,0
0,0,0,0,0,0,0
0,0,0,0,0,0,0
endlayer

layer
0,0,0,0,0,0,0
0,0,0,0,0,0,0
0,0,0,0,0,0,0
0,0,0,0,0,0,0
0,0,0,0,0,0,0
0,0,0,0,0,0,0
0,0,12,11,0,0,0
0,0,0,0,0,0,0
0,0,0,0,0,0,0
0,0,0,0,0,0,0
0,0,0,0,0,0,0
0,0,0,0,0,0,0
0,0,0,0,0,0,0
0,0,0,0,0,0,0
0,0,0,0,0,0,0
0,0,0,0,0,0,0
0,0,0,0,0,0,0
0,0,0,0,0,0,0
0,0,0,0,0,0,0
0,0,0,0,0,0,0
0,0,0,0,0,0,0
0,0,0,0,0,0,0
0,0,0,0,0,0,0
0,0,0,0,0,0,0
0,0,0,0,0,0,0
0,0,0,0,0,0,0
0,0,0,0,0,0,0
0,0,0,0,0,0,0
0,0,12,11,0,0,0
0,0,0,0,0,0,0
0,0,0,0,0,0,0
0,0,0,0,0,0,0
0,0,0,0,0,0,0
0,0,0,0,0,0,0
0,0,0,0,0,0,0
0,0,0,0,0,0,0
0,0,0,0,0,0,0
endlayer

