
# Created by Ruins mod version 13.8 Ingame Parser
# authoring Player: Spud_Gunn

weight=10
embed_into_distance=0
biomesToSpawnIn=plains,forest,swamp,rolling hills,high hills
acceptable_target_blocks=
unacceptable_target_blocks=flowing_water,water,flowing_lava,lava,terrafirmacraft:SaltWaterStationary-0,terrafirmacraft:SaltWaterStationary-8,terrafirmacraft:FreshWaterStationary-0,terrafirmacraft:FreshWaterStationary-8
dimensions=9,11,15
allowable_overhang=4
max_leveling=6
leveling_buffer=0
preserve_water=0
preserve_lava=0
preserve_plants=1

rule1=0,100,air,air,terrafirmacraft:WoodVert-4
rule2=0,100,terrafirmacraft:WallBrickSed-0terrafirmacraft:WallBrickSed-0,terrafirmacraft:WallBrickSed-0,air
rule3=0,100,terrafirmacraft:WallCobbleSed-0
rule4=0,100,terrafirmacraft:WoodVert-4
rule5=0,100,air,air,air,terrafirmacraft:StoneIgInBrick-2
rule6=0,100,air,terrafirmacraft:StoneIgInBrick-1,terrafirmacraft:StoneIgInBrick-1,terrafirmacraft:StoneIgInBrick-1
rule7=0,100,terrafirmacraft:StoneIgInBrick-2
rule8=0,100,terrafirmacraft:StoneIgInCobble-1
rule9=0,100,preserveBlock,preserveBlock,preserveBlock,ChestGenHook:dungeonChest:5-3,ChestGenHook:dungeonChest:5-3,ChestGenHook:dungeonChest:5-3,MobSpawner:silverfishTFC,MobSpawner:TwilightForest.Troll,MobSpawner:TwilightForest.Forest Raven,MobSpawner:TwilightForest.Lower Goblin Knight,MobSpawner:TwilightForest.Redscale Broodling,MobSpawner:TwilightForest.Redcap
rule10=0,100,air,terrafirmacraft:StoneIgInSmooth-1,terrafirmacraft:StoneIgInSmooth-1,terrafirmacraft:StoneIgInSmooth-1
rule11=0,100,terrafirmacraft:StoneIgInCobble-2
rule12=0,100,air,terrafirmacraft:StoneIgInSmooth-2,terrafirmacraft:StoneIgInSmooth-2,terrafirmacraft:StoneIgInSmooth-2
rule13=0,100,air
rule14=0,100,terrafirmacraft:Vine-8
rule15=0,100,terrafirmacraft:Vine-4
rule16=0,100,terrafirmacraft:Vine-1
rule17=0,100,air,terrafirmacraft:StoneIgExSmooth-1,terrafirmacraft:StoneIgExSmooth-1,terrafirmacraft:StoneIgExSmooth-1,terrafirmacraft:StoneIgExSmooth-1
rule18=0,100,air,minecraft:coal_block-0
rule19=0,100,terrafirmacraft:DoorHickory-1
rule20=0,100,ChestGenHook:dungeonChest:5-3
rule21=0,100,air,air,minecraft:stained_glass_pane-14
rule22=0,100,terrafirmacraft:DoorHickory-8
rule23=0,100,terrafirmacraft:Vine-6
rule24=0,100,terrafirmacraft:Vine-2
rule25=0,100,air,terrafirmacraft:Torch-9
rule26=0,100,terrafirmacraft:Vine-3
rule27=0,100,air,air,air,terrafirmacraft:StoneIgInSmooth-2

layer
0,0,4,2,3,0,3,2,2,0,0,0,1,0,0
0,0,0,6,6,6,6,6,6,6,6,5,0,0,0
0,0,3,6,7,7,6,6,6,7,7,5,0,0,0
0,0,2,6,7,7,6,6,6,7,8,6,0,0,0
0,0,10,6,7,8,6,6,9,7,7,6,3,0,0
0,0,10,6,7,7,7,7,7,7,11,6,2,0,0
0,0,10,6,7,7,7,7,11,7,7,6,3,0,0
0,0,2,6,7,8,7,7,12,11,7,6,3,0,0
0,13,2,6,7,7,7,7,7,7,7,6,0,0,0
0,0,3,6,6,6,6,6,6,6,6,0,14,0,0
0,0,4,2,3,0,2,2,2,3,0,15,4,0,0
endlayer

layer
0,0,4,0,0,0,0,14,0,0,0,0,1,0,0
0,0,0,6,6,6,6,6,6,6,5,5,16,0,0
13,0,0,6,0,0,17,17,17,0,0,6,16,0,0
0,13,0,6,0,0,17,18,17,0,0,6,16,13,0
0,0,0,6,0,0,17,17,17,0,0,6,0,0,13
0,13,13,19,0,13,0,0,0,0,0,6,0,0,13
0,0,0,6,0,0,13,0,0,0,0,6,0,0,0
0,0,0,6,0,0,0,0,0,0,0,6,0,0,13
0,13,0,6,0,0,0,0,0,0,20,6,0,0,0
13,0,0,6,6,6,6,6,5,6,6,6,0,0,0
0,0,4,0,0,0,0,0,0,0,0,15,4,0,0
endlayer

layer
0,0,4,0,0,0,14,14,0,0,0,15,1,0,0
0,0,0,6,6,6,6,6,6,10,6,6,0,0,0
13,0,0,21,0,0,17,17,17,0,0,21,16,0,0
0,0,0,21,0,0,0,0,0,0,0,21,0,0,0
0,0,0,6,0,0,0,13,0,0,0,6,0,0,0
0,0,0,22,0,0,0,0,0,0,0,6,0,0,0
0,0,0,6,0,0,0,0,0,0,0,5,0,0,13
0,0,0,21,0,0,0,0,0,0,0,21,0,0,0
0,0,0,21,0,0,0,0,0,0,0,21,0,0,13
0,0,0,6,6,6,21,21,6,6,6,6,0,0,0
0,0,4,0,0,0,0,0,0,0,0,23,4,0,0
endlayer

layer
0,0,1,0,0,0,0,14,0,0,0,15,4,0,0
0,0,0,6,6,5,6,6,6,6,6,6,0,0,0
0,0,0,5,0,0,0,17,0,0,0,6,16,0,0
0,0,15,6,0,0,0,0,0,0,0,6,0,0,0
0,0,15,6,0,0,0,0,0,0,0,6,0,0,0
0,0,0,6,0,0,0,0,0,0,0,5,0,0,0
0,0,0,6,0,0,0,0,0,0,0,6,0,0,0
0,0,0,6,0,0,0,0,0,0,0,6,0,0,0
0,0,0,6,0,0,0,0,0,0,0,5,0,0,0
0,0,0,6,6,6,6,5,6,6,5,6,0,0,0
0,0,4,0,0,24,24,0,0,0,0,0,1,0,0
endlayer

layer
0,13,1,0,0,0,0,0,14,0,0,15,4,0,0
0,0,0,14,6,6,6,6,6,5,6,6,0,0,0
0,0,0,6,0,0,25,0,25,0,0,6,0,0,0
0,0,15,6,0,0,0,0,0,0,0,6,16,0,0
0,0,15,6,0,0,0,0,0,0,0,6,0,0,0
0,0,0,6,0,0,0,0,0,0,0,6,0,0,0
0,0,0,6,0,0,0,0,0,0,0,6,0,0,0
0,0,0,6,0,0,0,0,0,0,0,6,0,0,0
0,0,0,6,0,0,0,0,0,0,0,6,0,0,0
0,0,0,0,6,6,6,6,6,6,6,26,0,0,0
0,0,4,0,24,0,0,0,0,0,0,0,1,13,0
endlayer

layer
0,0,27,27,10,10,10,10,27,27,27,10,10,0,0
0,0,27,27,10,10,10,10,10,27,27,10,10,0,0
0,0,27,10,10,10,10,10,10,10,10,10,27,0,13
0,0,10,10,10,10,10,0,10,10,10,10,10,0,0
0,0,10,10,10,10,10,10,10,10,10,10,10,0,0
0,0,10,10,10,10,10,10,10,10,10,10,10,16,0
0,0,10,10,10,10,10,10,10,10,10,10,10,0,0
0,15,10,10,10,10,10,10,10,10,10,10,10,0,0
0,0,10,27,10,10,10,10,10,10,10,27,27,0,0
0,0,10,10,10,10,10,10,10,10,26,27,27,0,0
0,0,10,10,24,10,10,10,10,10,27,27,27,0,0
endlayer

layer
0,0,0,0,0,0,0,0,0,0,0,0,0,0,0
0,0,0,0,0,0,0,14,0,0,0,0,0,0,0
0,0,0,0,0,10,10,10,10,0,0,0,0,0,0
0,0,0,0,10,10,10,0,10,10,0,0,0,0,0
0,0,0,0,10,10,10,10,10,16,10,16,0,0,0
0,0,0,15,10,27,10,10,10,10,10,0,0,0,0
13,0,0,15,10,10,10,27,10,10,0,0,0,0,0
0,0,0,0,0,10,10,10,10,0,0,0,0,0,0
0,0,0,0,0,0,10,10,0,0,0,0,0,0,0
0,0,0,0,0,0,0,0,0,0,0,0,13,0,0
0,0,0,0,0,0,0,0,0,0,0,0,13,13,0
endlayer

layer
0,0,0,0,0,0,0,0,0,0,0,0,0,0,0
0,0,0,0,0,0,0,14,0,0,13,0,0,0,0
0,0,0,0,0,0,0,10,0,0,0,0,0,0,0
0,0,0,0,0,0,10,0,10,0,0,0,0,0,0
0,0,0,0,0,0,0,10,0,0,0,0,0,0,0
0,0,0,0,0,0,0,0,13,0,13,0,0,0,0
0,0,0,0,0,0,0,0,13,0,0,0,0,0,13
0,0,0,0,0,0,0,0,0,0,0,0,0,0,0
0,0,0,0,0,0,0,0,0,0,0,0,0,0,0
0,0,0,0,0,0,0,0,0,0,0,0,0,13,0
0,0,0,0,0,0,0,0,0,0,0,0,0,0,13
endlayer

layer
0,0,0,0,0,0,0,0,0,0,0,0,0,0,0
0,0,0,0,0,0,0,0,0,0,0,0,0,0,0
0,0,0,0,0,0,0,10,0,0,0,0,0,0,0
0,0,0,0,0,0,10,0,10,0,0,0,0,0,0
0,0,0,0,0,0,24,10,0,0,0,0,0,0,0
0,0,0,0,0,0,0,0,0,0,0,0,0,0,0
0,0,0,0,0,0,0,0,0,0,0,0,0,0,0
0,0,0,0,0,0,0,0,0,0,0,0,0,0,0
0,0,0,0,0,0,0,0,0,0,0,0,0,0,0
0,0,0,0,0,0,0,0,0,0,0,0,0,0,0
0,0,0,0,0,0,0,0,0,0,0,0,0,0,0
endlayer

