
# Created by Ruins mod version 13.8 Ingame Parser
# authoring Player: OneWolfe

weight=8
embed_into_distance=0
acceptable_target_blocks=
unacceptable_target_blocks=flowing_water,water,flowing_lava,lava
dimensions=40,14,24
allowable_overhang=4
max_leveling=6
leveling_buffer=0
preserve_water=0
preserve_lava=0
preserve_plants=1

rule1=0,100,preserveBlock
rule2=0,100,terrafirmacraft:StoneMMBrick-1
rule3=0,100,air,air,ChestGenHook:dungeonChest:5-3,MobSpawner:spiderTFC,MobSpawner:skeletonTFC
rule4=0,100,air,Steamcraft:pipe-0
rule5=0,100,air
rule6=0,100,Railcraft:frame-0
rule7=0,100,air,air,Steamcraft:valvePipe-2
rule8=0,100,air,air,Steamcraft:steamTank-0
rule9=0,100,air,air,Steamcraft:valvePipe-1
rule10=0,100,preserveBlock,terrafirmacraft:FreshWaterStationary-0
rule11=0,100,terrafirmacraft:planks-2
rule12=0,100,air,minecraft:stained_glass-8
rule13=0,100,air,air,ChestGenHook:dungeonChest:5-3,MobSpawner:spiderTFC,MobSpawner:skeletonTFC
rule14=0,100,air,Steamcraft:valvePipe-5
rule15=0,100,air,air,ChestGenHook:dungeonChest:5-3,MobSpawner:spiderTFC,MobSpawner:skeletonTFC
rule16=0,100,air,ChestGenHook:dungeonChest:5-3,Steamcraft:horn-2

layer
2,2,2,2,2,2,1,1,1,1,1,1,1,1,1,1,1,1,1,1,1,1,1,1
2,2,2,2,2,2,2,2,2,2,1,1,1,1,1,1,1,1,1,1,1,1,1,1
2,2,2,2,2,2,2,2,2,2,2,2,2,1,1,1,1,1,1,1,1,1,1,1
2,2,2,2,2,2,2,2,2,2,2,2,2,2,2,1,1,1,1,1,1,1,1,1
2,2,2,2,2,2,2,2,3,2,2,2,2,2,2,2,2,1,1,1,1,1,1,1
2,2,2,2,2,2,2,2,2,2,2,2,2,2,2,2,2,2,1,1,1,1,1,1
2,2,2,2,2,2,2,2,2,2,2,2,2,2,2,2,2,2,2,1,1,1,1,1
2,2,2,2,2,2,2,2,2,2,2,2,2,2,2,2,2,2,2,2,1,1,1,1
1,1,1,1,1,2,2,2,2,2,2,2,2,2,2,2,2,2,2,2,2,1,1,1
1,1,1,1,1,1,1,1,1,2,2,2,2,2,2,2,2,2,2,2,2,2,1,1
1,1,1,1,1,1,1,1,1,1,1,1,2,2,2,2,2,2,2,2,2,2,1,1
1,1,1,1,1,1,1,1,1,1,1,1,1,2,2,2,2,2,2,2,2,2,2,1
1,1,1,1,1,1,1,1,1,1,1,1,1,1,2,2,2,2,2,2,2,2,2,1
1,1,1,1,1,1,1,1,1,1,1,1,1,1,1,2,2,2,2,2,2,2,2,2
endlayer

layer
2,2,2,4,2,2,1,1,1,1,1,1,1,1,1,1,1,1,1,1,1,1,1,1
2,6,0,4,0,5,2,2,2,2,1,1,1,1,1,1,1,1,1,1,1,1,1,1
2,0,0,7,5,5,0,0,0,0,2,2,2,1,1,1,1,1,1,1,1,1,1,1
2,0,8,8,0,5,0,0,0,0,0,0,0,2,2,1,1,1,1,1,1,1,1,1
2,0,8,8,5,5,0,5,5,5,5,5,0,0,6,2,2,1,1,1,1,1,1,1
2,0,0,4,4,4,4,4,0,5,5,0,0,0,0,0,0,2,1,1,1,1,1,1
2,6,0,0,0,0,0,9,5,0,0,0,0,0,0,0,0,0,2,1,1,1,1,1
2,2,2,2,2,0,0,4,0,0,0,0,0,0,0,0,5,0,0,2,1,1,1,1
1,1,1,1,1,2,2,4,2,0,0,0,0,0,5,0,0,0,0,0,2,1,1,1
1,1,1,1,1,1,1,1,1,2,2,2,6,0,0,0,0,0,0,0,0,2,1,1
1,1,1,1,1,1,1,1,1,1,1,1,2,0,0,0,0,0,0,0,0,2,1,1
1,1,10,10,10,10,10,10,10,1,1,1,1,2,0,0,0,0,0,0,0,6,2,1
1,1,10,10,10,10,10,10,10,1,1,1,1,1,2,0,0,0,0,0,0,0,2,1
1,1,0,0,0,0,0,0,0,1,1,1,1,1,1,2,6,2,2,2,2,2,2,2
endlayer

layer
2,2,2,2,2,2,1,1,1,1,1,1,1,1,1,1,1,1,1,1,1,1,1,1
2,6,0,5,0,0,2,2,2,2,1,1,1,1,1,1,1,1,1,1,1,1,1,1
2,0,0,0,0,5,0,0,0,0,2,2,2,1,1,1,1,1,1,1,1,1,1,1
2,0,8,8,0,5,5,0,0,0,0,0,0,2,2,1,1,1,1,1,1,1,1,1
2,0,8,8,0,0,0,0,0,0,0,0,0,0,6,2,2,1,1,1,1,1,1,1
2,0,0,0,0,0,0,0,0,0,0,0,0,0,0,0,0,2,1,1,1,1,1,1
2,6,0,0,0,0,0,0,0,0,0,0,0,0,0,0,0,0,2,1,1,1,1,1
2,2,2,2,2,0,0,0,0,0,0,0,0,0,0,0,0,0,0,2,1,1,1,1
1,1,1,1,1,2,2,2,2,0,0,0,0,0,0,0,0,0,0,0,2,1,1,1
1,1,1,1,1,1,1,1,1,2,2,2,6,0,0,0,0,0,0,0,0,2,1,1
1,1,1,1,1,1,1,1,1,1,1,1,2,0,0,0,0,0,0,0,0,2,1,1
1,1,10,10,10,10,10,10,10,1,1,1,1,2,0,0,0,0,0,0,0,6,2,1
1,1,0,0,0,0,0,0,0,1,1,1,1,1,2,0,0,0,0,0,0,0,2,1
1,1,0,0,0,0,0,0,0,1,1,1,1,1,1,2,6,0,0,0,0,2,2,2
endlayer

layer
2,2,2,2,2,2,1,1,1,1,1,1,1,1,1,1,1,1,1,1,1,1,1,1
2,6,0,0,0,0,2,2,2,2,1,1,1,1,1,1,1,1,1,1,1,1,1,1
2,0,0,0,0,0,0,0,0,0,2,2,2,1,1,1,1,1,1,1,1,1,1,1
2,0,8,8,0,5,0,0,0,0,0,0,0,2,2,1,1,1,1,1,1,1,1,1
2,0,8,8,0,0,0,0,0,0,0,0,0,0,6,2,2,1,1,1,1,1,1,1
2,0,0,0,0,0,0,0,0,5,0,0,0,0,0,0,0,2,1,1,1,1,1,1
2,6,0,0,0,0,0,0,5,0,0,0,0,0,0,0,0,0,2,1,1,1,1,1
2,2,2,2,2,0,0,0,0,0,0,0,0,0,0,0,0,0,0,2,1,1,1,1
1,1,1,1,1,2,2,2,2,0,0,0,0,0,0,0,0,0,0,0,2,1,1,1
1,1,1,1,1,1,1,1,1,2,2,2,6,0,0,0,5,0,0,0,0,2,1,1
1,1,1,1,1,1,1,1,1,1,1,1,2,0,0,0,0,0,0,0,0,2,1,1
1,1,0,0,0,0,0,0,0,1,1,1,1,2,0,0,0,0,0,0,0,6,2,1
1,1,0,0,0,0,0,0,0,1,1,1,1,1,2,0,0,0,5,0,0,0,2,1
1,1,0,0,0,0,0,0,0,1,1,1,1,1,1,2,6,0,0,5,0,2,2,2
endlayer

layer
2,2,2,2,2,2,0,0,0,0,0,0,0,0,0,0,0,0,0,0,0,0,0,0
2,6,0,0,0,0,2,2,2,2,0,0,0,0,0,0,0,0,0,0,0,0,0,0
2,0,0,0,0,0,0,0,0,0,2,2,2,0,0,0,0,0,0,0,0,0,0,0
2,0,0,7,0,0,0,0,0,0,0,0,0,2,2,0,0,0,0,0,0,0,0,0
2,0,0,0,0,0,0,0,0,0,0,0,0,0,6,2,2,0,0,0,0,0,0,0
2,0,0,0,0,0,0,0,0,0,0,0,0,0,0,0,0,2,0,0,0,0,0,0
2,6,0,0,0,0,0,0,0,0,0,0,0,0,0,0,0,0,2,0,0,0,0,0
2,2,2,2,2,0,0,0,0,0,0,0,0,0,0,0,0,0,0,2,0,0,0,0
0,0,0,0,0,2,2,2,2,0,0,0,0,0,0,0,0,0,0,0,2,0,0,0
0,0,0,0,0,0,0,0,0,2,2,2,6,0,0,0,0,0,0,0,0,2,0,0
0,0,0,0,0,0,0,0,0,0,0,0,2,0,0,0,0,0,0,0,0,2,0,0
0,0,0,0,0,0,0,0,0,0,0,0,0,2,0,0,0,0,0,0,0,6,2,0
0,0,0,0,0,0,0,0,0,0,0,0,0,0,2,0,0,0,0,0,0,0,2,0
0,0,0,0,0,0,0,0,0,0,0,0,0,0,0,2,6,0,0,0,0,2,2,2
endlayer

layer
2,2,2,2,2,2,0,0,0,0,0,0,0,0,0,0,0,0,0,0,0,0,0,0
2,6,11,11,11,11,2,2,2,2,0,0,0,0,0,0,0,0,0,0,0,0,0,0
2,11,11,11,11,11,11,11,11,11,2,2,2,0,0,0,0,0,0,0,0,0,0,0
2,11,11,4,11,11,11,11,11,11,11,11,11,2,2,0,0,0,0,0,0,0,0,0
2,11,11,11,11,11,11,11,11,11,11,11,11,11,6,2,2,0,0,0,0,0,0,0
2,11,11,11,11,11,11,11,11,11,11,11,11,11,11,11,11,2,0,0,0,0,0,0
2,6,11,11,11,11,11,11,11,11,11,11,11,11,11,11,11,11,0,0,0,0,0,0
2,2,2,2,2,11,11,11,11,11,11,11,11,11,11,11,11,11,11,0,0,0,0,0
0,0,0,0,0,2,2,2,2,11,11,11,11,11,11,11,11,11,11,11,0,0,0,0
0,0,0,0,0,0,0,0,0,2,2,2,6,11,11,11,11,11,11,11,11,2,0,0
0,0,0,0,0,0,0,0,0,0,0,0,2,11,11,11,11,11,11,11,11,2,0,0
0,0,0,0,0,0,0,0,0,0,0,0,0,2,11,11,11,11,11,11,11,6,2,0
0,0,0,0,0,0,0,0,0,0,0,0,0,0,2,11,11,11,11,11,11,11,2,0
0,0,0,0,5,0,0,0,0,0,0,0,0,0,5,2,6,11,11,11,11,11,11,2
endlayer

layer
2,2,2,2,2,2,0,0,0,0,0,0,0,0,0,0,0,0,0,0,0,0,0,0
2,6,0,0,0,0,2,2,2,2,0,0,0,0,0,0,0,0,0,0,0,0,0,0
2,4,0,5,5,0,0,0,0,0,2,2,2,0,0,0,0,0,0,0,0,0,0,0
2,4,4,4,0,5,0,0,5,0,0,0,0,2,2,0,0,0,0,0,0,0,0,0
2,0,0,0,0,0,0,0,0,0,0,0,0,0,6,2,2,0,0,0,0,0,0,0
2,0,0,0,0,0,0,0,0,0,0,0,0,0,0,0,0,0,0,0,5,5,0,0
2,6,0,0,0,0,0,0,0,0,0,0,0,0,0,0,0,0,0,0,0,0,0,0
2,2,2,2,2,0,0,0,0,0,0,0,0,0,0,0,0,0,0,0,0,0,0,0
0,0,0,0,0,2,2,2,2,0,0,0,0,0,0,0,0,0,0,0,0,0,0,0
0,0,0,0,0,0,0,0,0,2,2,2,6,0,0,0,5,0,0,0,0,2,0,0
0,0,0,0,0,0,0,0,0,0,0,0,2,0,0,0,0,0,0,0,0,2,0,0
0,0,0,0,0,0,0,0,0,0,0,0,0,2,0,0,0,0,0,0,0,6,2,0
0,0,0,0,0,0,0,0,0,0,0,0,0,0,2,0,0,0,0,0,0,0,2,0
0,0,0,0,0,0,0,0,0,0,0,0,0,0,0,2,6,0,0,0,0,0,0,2
endlayer

layer
2,12,12,12,12,2,0,0,0,0,0,0,0,0,0,0,0,0,0,0,0,0,0,0
2,6,0,0,0,0,12,12,12,12,0,0,0,0,0,0,0,0,0,0,0,0,0,0
2,4,0,5,0,0,0,0,0,0,12,12,12,0,0,0,0,0,0,0,0,0,0,0
2,0,0,0,0,0,0,0,0,0,0,0,0,12,12,0,0,0,0,0,0,0,0,0
2,0,0,0,0,0,0,0,0,0,0,0,0,0,6,12,12,0,0,0,5,5,0,0
2,0,0,0,0,0,0,0,5,0,0,0,0,0,0,0,0,0,0,0,0,0,0,5
2,6,0,0,0,0,0,0,0,0,0,0,0,0,0,0,0,0,0,0,0,0,0,0
2,12,12,12,12,0,0,0,0,0,0,0,0,0,0,0,0,0,0,0,0,0,0,0
0,0,0,0,0,2,12,12,12,0,0,0,0,0,0,0,0,0,0,0,0,0,0,0
0,0,0,0,0,0,0,0,0,12,12,12,6,0,0,0,0,0,0,0,0,12,0,0
0,0,0,0,0,0,0,0,0,0,0,0,12,0,0,0,0,0,0,0,0,12,0,0
0,0,0,0,0,0,0,0,0,0,0,0,0,2,0,0,0,0,0,0,0,6,12,0
0,0,0,0,0,0,0,0,0,0,0,0,0,0,2,0,0,0,0,0,0,0,0,0
0,0,0,0,0,0,0,0,0,0,0,0,0,0,0,12,6,0,0,0,0,0,0,0
endlayer

layer
2,12,12,12,12,2,0,0,0,0,0,0,0,0,0,0,0,0,0,0,0,0,0,0
2,6,0,0,0,0,12,12,12,12,0,0,0,0,0,0,0,0,0,0,0,0,0,0
2,4,0,0,0,0,0,0,0,0,12,12,12,0,0,0,0,0,0,0,0,0,0,0
2,0,0,0,0,0,0,0,0,0,0,0,0,12,12,0,0,0,0,0,5,0,0,0
2,0,0,0,0,0,0,0,0,0,0,0,0,0,6,12,12,0,0,0,0,0,0,0
2,0,0,0,0,0,0,0,0,0,0,0,0,0,0,0,0,0,0,0,0,0,0,0
2,6,0,0,0,0,0,0,0,0,0,0,0,0,0,0,0,0,0,0,0,0,0,0
2,12,12,12,12,0,0,0,0,0,0,0,0,0,0,0,0,0,0,0,0,0,0,0
0,0,0,0,0,2,12,12,12,0,0,0,0,0,0,0,0,0,0,0,0,0,0,0
0,0,0,0,0,0,0,0,0,12,12,12,6,0,0,0,0,0,0,0,0,12,0,0
0,0,0,0,0,0,0,0,0,0,0,0,12,0,0,0,0,0,0,0,0,12,0,0
0,0,0,0,0,0,0,0,0,0,0,0,0,2,0,0,0,0,0,0,0,6,12,0
0,0,0,0,0,0,0,0,0,0,0,0,0,0,2,0,0,0,0,0,0,0,0,0
0,0,0,0,0,0,0,0,0,0,0,0,0,0,0,12,6,0,0,0,0,0,0,0
endlayer

layer
2,12,12,12,12,2,0,0,0,0,0,0,0,0,0,0,0,0,0,0,0,0,0,0
2,6,0,0,0,0,12,12,12,12,0,0,0,0,0,0,0,0,0,0,0,0,0,0
2,4,0,0,0,0,0,0,0,0,12,12,12,0,0,0,0,0,0,0,0,0,0,0
2,0,0,0,0,0,0,0,0,0,0,0,0,12,12,0,0,0,0,0,0,0,0,0
2,0,0,0,0,0,0,0,0,0,0,0,0,0,6,12,0,0,0,0,0,0,0,0
2,0,0,0,0,0,0,0,0,0,0,0,0,0,0,0,0,0,0,0,0,5,0,0
2,6,0,0,0,0,0,0,0,0,0,0,0,0,0,0,0,0,0,0,5,0,0,0
2,12,12,12,12,0,0,0,0,0,0,0,0,0,0,0,0,0,0,0,0,0,0,0
0,0,0,0,0,2,12,12,12,0,0,0,0,0,0,0,0,0,0,0,0,0,0,0
0,0,0,0,0,0,0,0,0,12,12,12,6,0,0,0,0,0,0,0,0,12,0,0
0,0,0,0,0,0,0,0,0,0,0,0,0,0,0,0,0,0,0,0,0,12,0,0
0,0,0,0,0,0,0,0,0,0,0,0,0,0,0,0,0,0,0,0,0,6,12,0
0,0,0,0,0,0,0,0,0,0,0,0,0,0,2,0,0,0,0,0,0,0,0,0
0,0,0,0,0,0,0,0,0,0,0,0,0,0,0,12,6,0,0,0,0,0,0,0
endlayer

layer
2,2,2,2,2,2,0,0,0,0,0,0,0,0,0,0,0,0,0,0,0,0,0,0
2,6,11,11,11,11,2,2,2,2,0,0,0,0,0,0,0,0,0,0,0,0,0,0
2,4,11,11,11,11,11,11,11,11,2,2,2,0,0,0,0,0,0,0,0,0,0,0
2,11,11,11,11,11,11,11,11,11,11,11,11,2,2,0,0,0,0,0,0,0,0,0
2,11,11,11,11,11,11,11,11,11,11,11,11,11,6,0,0,0,0,0,5,0,0,0
2,11,11,11,11,11,11,11,11,11,11,11,11,11,11,11,11,0,0,0,0,5,5,0
2,6,11,11,11,11,11,11,11,11,11,11,11,11,11,11,11,0,0,0,0,0,0,0
2,2,2,2,2,11,11,11,11,11,11,11,11,11,11,11,11,0,0,0,0,0,0,5
0,0,0,0,0,2,2,2,2,11,11,11,11,11,11,11,11,11,0,0,0,0,0,0
0,0,0,0,0,0,0,0,0,2,2,2,6,0,0,11,11,11,11,11,11,2,0,0
0,0,0,0,0,0,0,0,0,0,0,0,0,0,0,0,0,0,0,0,5,2,0,0
0,0,0,0,0,0,0,0,0,0,0,0,0,0,0,0,0,0,0,5,5,6,2,0
0,0,0,0,0,0,0,0,0,0,0,5,5,0,0,0,0,0,0,0,0,0,0,0
0,0,0,0,0,0,0,0,0,0,0,0,0,0,0,0,6,0,0,0,0,0,0,5
endlayer

layer
2,2,2,2,2,2,0,0,0,0,0,0,0,0,0,0,0,0,0,0,0,0,0,0
2,6,4,0,0,0,2,2,2,2,0,0,0,0,0,0,0,0,0,0,0,0,0,0
2,4,4,0,0,0,0,0,0,0,2,2,2,0,0,0,0,0,0,0,0,0,0,0
2,0,0,0,0,0,0,0,0,0,0,0,0,2,2,0,0,0,0,0,0,0,0,0
2,0,0,0,0,0,0,0,0,0,0,0,0,0,6,0,0,0,0,0,0,0,0,0
2,0,0,0,0,0,0,0,0,0,0,0,0,0,0,0,0,0,0,0,0,0,0,0
2,6,0,0,0,0,0,0,0,0,0,0,0,0,0,0,0,0,0,0,0,0,0,0
2,2,2,2,2,0,0,0,0,0,0,0,0,0,0,0,0,0,0,0,0,0,0,0
0,0,0,0,0,2,2,2,2,0,0,0,0,0,0,0,0,0,0,0,0,0,0,0
0,0,0,0,0,0,0,0,0,2,2,2,6,0,0,0,0,0,0,0,0,0,0,0
0,0,0,0,0,0,0,0,0,0,0,0,0,0,0,0,0,0,0,0,0,0,0,0
0,0,0,0,0,0,0,0,0,0,0,0,0,0,0,0,0,0,0,0,0,6,2,0
0,0,0,0,0,0,0,0,0,0,0,5,0,0,5,0,0,0,0,0,0,0,0,0
0,0,0,0,0,0,0,0,0,0,5,0,5,5,0,0,6,0,0,0,0,0,0,0
endlayer

layer
2,12,12,12,12,2,0,0,0,0,0,0,0,0,0,0,0,0,0,0,0,0,0,0
2,6,4,0,0,0,12,12,12,12,0,0,0,0,0,0,0,0,0,0,0,0,0,0
2,0,0,0,0,0,0,0,0,0,12,12,12,0,0,0,0,0,0,0,0,0,0,0
2,0,5,5,5,0,0,0,0,0,0,0,0,12,12,0,0,0,0,0,0,0,0,0
2,0,5,5,5,0,0,0,0,0,0,0,0,0,6,12,12,0,0,0,0,0,0,0
2,0,0,0,0,0,0,0,0,0,0,0,0,0,0,0,0,0,0,0,0,0,0,0
2,6,0,0,0,0,0,0,0,0,0,0,0,0,0,0,0,0,0,0,0,0,0,0
2,12,12,12,12,0,0,0,0,0,0,0,0,0,5,0,0,0,5,0,0,0,0,0
0,0,0,0,0,2,12,12,12,0,0,0,0,0,0,0,0,0,0,0,0,0,0,0
0,0,0,0,0,0,0,0,0,12,12,12,6,0,0,0,0,0,0,0,0,0,0,0
0,0,0,0,0,0,0,0,0,0,0,0,0,0,0,0,0,0,0,0,0,0,0,0
0,0,0,0,0,0,0,0,0,0,0,0,0,0,0,0,0,0,0,0,0,6,12,0
0,0,0,0,0,0,0,0,0,0,0,0,0,5,0,0,0,0,0,0,0,0,0,0
0,0,0,0,0,0,0,0,0,0,0,0,5,0,0,0,6,0,0,0,0,0,0,0
endlayer

layer
2,12,12,12,12,2,0,0,0,0,0,0,0,0,0,0,0,0,0,0,0,0,0,0
2,6,4,0,0,0,12,12,12,12,0,0,0,0,0,0,0,0,0,0,0,0,0,0
0,0,0,0,0,0,0,0,0,0,12,12,12,0,0,0,0,0,0,0,0,0,0,0
0,0,0,0,0,0,0,0,0,0,0,0,0,12,12,0,0,0,0,0,0,0,0,0
2,0,0,0,0,0,0,0,0,0,0,0,0,0,6,12,12,0,0,0,0,0,0,0
2,0,0,0,0,0,0,0,0,0,0,0,0,0,0,0,0,12,0,0,0,0,0,0
2,6,0,0,0,0,0,0,0,0,0,0,0,0,0,0,0,0,0,0,0,0,0,0
2,12,12,12,12,0,0,0,0,0,0,0,0,0,0,0,0,0,0,0,0,0,0,0
0,0,0,0,0,2,12,12,12,0,0,0,0,0,0,0,0,0,0,0,0,0,0,0
0,0,0,0,0,0,0,0,0,12,12,12,6,0,0,0,0,0,0,0,0,0,0,0
0,0,0,0,0,0,0,0,0,0,0,0,0,0,0,0,0,0,0,0,0,0,0,0
0,0,0,0,0,0,0,0,0,0,0,0,0,0,0,0,0,0,0,0,0,6,12,0
0,0,0,0,0,0,0,0,0,0,0,5,0,0,0,0,0,0,0,0,0,0,0,0
0,0,0,0,0,0,0,0,0,0,5,5,5,0,0,0,6,0,0,0,0,0,0,0
endlayer

layer
2,12,12,12,12,2,0,0,0,0,0,0,0,0,0,0,0,0,0,0,0,0,0,0
2,6,4,0,0,0,12,12,12,12,0,0,0,0,0,0,0,0,0,0,0,0,0,0
0,0,0,0,0,0,0,0,0,0,12,12,12,0,0,0,0,0,0,0,0,0,0,0
0,0,0,0,0,0,0,0,0,0,0,0,0,12,12,0,0,0,0,0,0,0,0,0
0,0,0,0,0,0,0,0,0,0,0,0,0,0,6,12,12,0,0,0,0,0,0,0
0,0,0,0,0,0,0,0,0,0,0,0,0,0,0,0,0,12,0,0,0,0,0,0
2,6,0,0,0,0,0,0,0,0,0,0,0,0,0,0,0,0,2,0,0,0,0,0
2,12,12,12,12,0,0,0,0,0,0,0,0,0,0,0,0,0,0,2,0,0,0,0
0,0,0,0,0,2,12,12,12,0,0,0,0,0,0,0,0,0,0,0,0,0,0,0
0,0,0,0,0,0,0,0,0,12,12,12,6,0,0,0,0,0,0,0,0,0,0,0
0,0,0,0,0,0,0,0,0,0,0,0,0,0,0,0,0,0,0,0,0,12,0,0
0,0,0,0,0,0,0,0,0,0,0,0,0,0,0,0,0,0,0,0,0,6,12,0
0,0,0,0,0,0,0,0,0,0,0,0,5,0,0,0,0,0,0,0,0,0,0,0
0,0,0,0,0,0,0,0,0,0,0,0,0,0,0,0,6,0,0,0,0,0,0,0
endlayer

layer
2,2,2,2,2,2,0,0,0,0,0,0,0,0,0,0,0,0,0,0,0,0,0,0
2,6,4,11,11,11,2,2,2,2,0,0,0,0,0,0,0,0,0,0,0,0,0,0
0,0,0,0,0,11,11,11,11,11,2,2,2,0,0,0,0,0,0,0,0,0,0,0
0,0,0,5,0,11,11,11,11,11,11,11,11,2,2,0,0,0,0,0,0,0,0,0
5,0,0,0,11,11,11,11,11,11,11,11,11,11,6,2,2,0,0,0,0,0,0,0
0,0,0,0,11,11,11,11,11,11,11,11,11,11,11,11,11,2,0,0,0,0,0,0
2,6,0,11,0,11,11,11,11,11,11,11,11,11,11,11,11,11,2,0,0,0,0,0
2,2,2,2,2,11,11,11,11,11,11,11,11,11,11,11,11,11,11,2,0,0,0,0
0,0,0,0,0,2,2,2,2,11,11,11,11,11,0,11,11,11,11,11,2,0,0,0
0,0,0,0,0,0,0,0,0,2,2,2,6,0,0,0,11,11,11,11,11,2,0,0
0,0,0,0,0,0,0,0,0,0,0,0,0,0,0,0,11,11,11,11,11,2,0,0
0,0,0,0,0,0,0,0,0,0,0,0,0,0,0,0,11,11,11,11,11,6,2,0
0,0,0,0,0,0,0,0,0,0,0,0,0,0,0,0,11,11,11,11,11,11,0,0
0,0,0,0,0,0,0,0,0,0,0,0,0,0,0,0,0,11,11,11,11,11,0,0
endlayer

layer
2,2,2,2,2,2,0,0,0,0,0,0,0,0,0,0,0,0,0,0,0,0,0,0
2,6,4,0,0,0,2,2,2,2,0,0,0,0,0,0,0,0,0,0,0,0,0,0
0,0,0,0,0,0,0,0,0,0,2,2,2,0,0,0,0,0,0,0,0,0,0,0
0,0,0,0,0,0,0,0,0,0,0,0,0,2,2,0,0,0,0,0,0,0,0,0
0,0,0,0,0,0,0,0,0,0,0,0,0,0,6,2,2,0,0,0,0,0,0,0
0,0,0,0,0,0,0,0,0,0,0,0,0,0,0,0,0,2,0,0,0,0,0,0
0,6,0,0,0,0,0,0,0,0,0,0,0,0,0,0,0,0,2,0,0,0,0,0
2,2,2,2,2,0,0,0,0,0,0,0,0,0,0,0,0,0,0,2,0,0,0,0
0,0,0,0,0,2,2,2,2,0,0,0,0,0,0,0,0,0,0,0,2,0,0,0
0,0,0,0,0,0,0,0,0,2,2,2,6,0,0,0,0,0,0,0,0,2,0,0
0,0,0,0,0,0,0,0,0,0,0,0,0,0,0,0,0,0,0,0,0,2,0,0
0,0,0,0,0,0,0,0,0,0,0,0,0,0,0,0,0,0,0,0,0,6,2,0
0,0,0,0,0,0,0,0,0,0,0,0,0,0,0,0,0,0,0,0,0,0,0,0
0,0,0,0,0,0,0,0,0,0,0,0,0,0,0,2,6,0,0,0,0,0,0,0
endlayer

layer
0,0,0,0,0,2,0,0,0,0,0,0,0,0,0,0,0,0,0,0,0,0,0,0
0,6,4,0,0,0,0,12,12,12,0,0,0,0,0,0,0,0,0,0,0,0,0,0
0,5,0,0,0,0,0,0,0,0,12,12,12,0,0,0,0,0,0,0,0,0,0,0
0,0,5,5,5,0,0,0,0,0,0,0,0,12,12,0,0,0,0,0,0,0,0,0
0,0,5,5,0,0,0,0,0,0,0,0,0,0,6,12,12,0,0,0,0,0,0,0
0,0,0,0,0,0,0,0,0,0,0,0,0,0,0,0,0,12,0,0,0,0,0,0
0,6,0,0,0,0,0,0,0,0,0,0,0,0,0,0,0,0,2,0,0,0,0,0
0,0,0,0,0,0,0,0,0,0,0,0,0,0,0,0,0,0,0,2,0,0,0,0
0,0,0,0,0,2,12,12,12,0,0,0,0,0,0,0,0,0,0,0,12,0,0,0
0,0,0,0,0,0,0,0,0,12,12,12,6,0,0,0,0,0,0,0,0,12,0,0
0,0,0,0,0,0,0,0,0,0,0,0,12,0,0,0,0,0,0,0,0,12,0,0
0,0,0,0,0,0,0,0,0,0,0,0,0,0,0,0,0,0,0,0,0,6,12,0
0,0,0,0,0,0,0,0,0,0,0,0,0,0,0,0,0,0,0,0,0,0,0,0
0,0,0,0,0,0,0,0,0,0,0,0,0,0,0,12,6,0,0,0,0,0,0,0
endlayer

layer
0,0,0,0,0,2,0,0,0,0,0,0,0,0,0,0,0,0,0,0,0,0,0,0
0,6,4,0,0,0,0,12,12,12,0,0,0,0,0,0,0,0,0,0,0,0,0,0
0,0,0,0,0,0,0,0,0,0,12,12,12,0,0,0,0,0,0,0,0,0,0,0
0,0,5,0,0,0,0,0,0,0,0,0,0,12,12,0,0,0,0,0,0,0,0,0
0,0,0,0,0,0,0,0,0,0,0,0,0,0,6,12,12,0,0,0,0,0,0,0
0,0,0,0,0,0,0,0,0,0,0,0,0,0,0,0,0,12,0,0,0,0,0,0
0,6,0,0,0,0,0,0,0,0,0,0,0,0,0,0,0,0,2,0,0,0,0,0
0,0,0,0,0,0,0,0,0,0,0,0,0,0,0,0,0,0,0,2,0,0,0,0
0,0,0,0,0,2,12,12,12,0,0,0,0,0,0,0,0,0,0,0,12,0,0,0
0,0,0,0,0,0,0,0,0,12,12,12,6,0,0,0,0,0,0,0,0,12,0,0
0,0,0,0,0,0,0,0,0,0,0,0,12,0,0,0,0,0,0,0,0,12,0,0
0,0,5,0,0,0,0,0,0,0,0,0,0,2,0,0,0,0,0,0,0,6,12,0
0,0,0,0,0,0,0,0,0,0,0,0,0,0,2,0,0,0,0,0,0,0,0,0
0,0,0,0,0,0,0,0,0,0,0,0,0,0,0,12,6,0,0,0,0,0,0,0
endlayer

layer
0,0,0,0,0,2,0,0,0,0,0,0,0,0,0,0,0,0,0,0,0,0,0,0
0,6,4,0,0,0,0,12,12,12,0,0,0,0,0,0,0,0,0,0,0,0,0,0
0,0,0,0,0,0,0,0,0,0,12,12,12,0,0,0,0,0,0,0,0,0,0,0
0,0,0,0,0,0,0,0,0,0,0,0,0,12,12,0,0,0,0,0,0,0,0,0
0,0,0,0,0,0,0,0,0,0,0,0,0,0,6,12,12,0,0,0,0,0,0,0
0,0,0,0,0,0,0,0,0,0,0,0,0,0,0,0,0,12,0,0,0,0,0,0
0,6,0,0,0,0,0,0,0,0,0,0,0,0,0,0,0,0,2,0,0,0,0,0
0,0,0,0,0,0,0,0,0,0,0,0,0,0,0,0,0,0,0,2,0,0,0,0
0,0,0,0,0,2,12,12,12,0,0,0,0,0,0,0,0,0,0,0,12,0,0,0
0,0,0,0,0,0,0,0,0,12,12,12,6,0,0,0,0,0,0,0,0,12,0,0
0,0,0,0,0,0,0,0,0,0,0,0,12,0,0,0,0,0,0,0,0,12,0,0
0,0,0,0,0,0,0,0,0,0,0,0,0,2,0,0,0,0,0,0,0,6,12,0
0,0,0,0,0,0,0,0,0,0,0,0,0,0,2,0,0,0,0,0,0,0,0,0
0,0,0,0,0,0,0,0,0,0,0,0,0,0,0,12,6,0,0,0,0,0,0,0
endlayer

layer
0,2,2,2,2,2,0,0,0,0,0,0,0,0,0,0,0,0,0,0,0,0,0,0
0,6,4,0,0,11,2,2,2,2,0,0,0,0,0,0,0,0,0,0,0,0,0,0
0,0,0,0,0,11,11,11,11,11,2,2,2,0,0,0,0,0,0,0,0,0,0,0
0,0,0,0,0,11,11,11,11,11,11,11,11,2,2,0,0,0,0,0,0,0,0,0
0,0,0,0,0,11,11,11,11,11,11,11,11,11,6,2,2,0,0,0,0,0,0,0
0,0,0,0,0,11,11,11,11,11,11,11,11,11,11,11,11,2,0,0,0,0,0,0
0,6,0,0,0,11,11,11,11,11,11,11,11,11,11,11,11,11,2,0,0,0,0,0
0,0,0,0,0,11,11,11,11,11,11,11,11,11,11,11,11,11,11,2,0,0,0,0
0,0,0,0,0,2,2,2,2,11,11,11,11,11,11,11,13,11,11,11,2,0,0,0
0,0,5,0,0,0,0,0,0,2,2,2,6,11,11,11,11,11,11,11,11,2,0,0
0,5,0,0,0,0,0,0,0,0,0,0,2,11,11,11,11,11,11,11,0,2,0,0
5,0,0,0,0,0,0,0,0,0,0,0,0,2,11,11,11,11,11,11,11,6,2,0
0,0,0,0,0,0,0,0,0,0,0,0,0,0,2,11,11,0,0,0,0,0,0,0
0,0,0,0,0,0,0,0,0,0,0,0,0,0,0,2,6,0,0,0,0,0,5,0
endlayer

layer
2,2,2,2,2,2,0,0,0,0,0,0,0,0,0,0,0,0,0,0,0,0,0,0
0,6,4,0,0,0,2,2,2,2,0,0,0,0,0,0,0,0,0,0,0,0,0,0
0,0,0,0,0,0,0,0,0,0,2,2,2,0,0,0,0,0,0,0,0,0,0,0
0,0,0,0,5,0,0,0,0,0,0,0,0,2,2,0,0,0,0,0,0,0,0,0
0,0,0,0,0,0,0,0,0,0,0,0,0,0,6,0,0,0,0,0,0,0,0,0
0,0,0,0,0,0,0,0,0,0,0,0,0,0,0,0,0,0,0,0,0,0,0,0
0,6,0,0,0,0,0,0,0,0,0,0,0,0,0,0,0,0,2,0,0,0,0,0
0,0,0,0,0,0,0,0,0,0,0,0,5,0,0,0,0,0,0,2,0,0,0,0
0,0,0,0,0,2,2,2,2,0,0,0,0,0,0,0,0,0,0,0,0,0,0,0
0,0,0,0,0,0,0,0,0,2,2,2,6,0,0,5,0,0,0,0,0,0,0,0
0,0,0,0,0,0,0,0,0,0,0,0,2,0,5,5,0,0,0,0,0,0,0,0
0,0,0,0,0,0,0,0,0,0,0,0,0,0,0,0,0,0,0,0,0,6,0,0
0,0,0,0,0,0,0,0,0,0,0,0,0,0,0,0,0,0,0,0,0,0,0,0
0,0,0,0,0,0,0,0,0,0,0,0,0,0,0,0,6,0,0,0,0,0,0,0
endlayer

layer
2,0,0,0,0,2,0,0,0,0,0,0,0,0,0,0,0,0,0,0,0,0,0,0
2,6,4,0,0,0,12,12,12,12,0,0,0,0,0,0,0,0,0,0,0,0,0,0
0,0,0,0,0,0,0,0,0,0,12,12,12,0,0,0,0,0,0,0,0,0,0,0
0,0,0,0,0,0,0,0,0,0,0,0,0,12,12,0,0,0,0,0,0,0,0,0
0,0,0,0,0,0,0,0,0,0,0,0,0,0,6,0,5,0,0,0,0,0,0,0
0,0,0,0,0,0,0,0,0,0,0,0,0,0,0,0,0,0,0,0,0,0,0,0
0,6,0,0,0,0,0,0,0,0,0,0,0,0,0,5,0,0,2,0,0,0,0,0
0,12,0,0,0,0,0,0,0,0,0,0,0,0,0,0,0,0,0,2,0,0,0,0
0,0,0,0,0,2,12,12,12,0,0,0,0,0,0,5,0,0,0,0,0,0,0,0
0,0,0,0,0,0,0,0,0,12,12,12,6,0,0,0,0,0,0,0,0,0,0,0
0,0,0,0,0,0,0,0,0,0,0,0,12,0,0,0,0,0,0,0,0,0,0,0
0,0,0,0,0,0,0,0,0,0,0,0,0,0,0,0,0,0,5,0,0,6,0,0
0,0,0,0,0,0,0,0,0,0,0,0,0,0,0,0,0,0,5,0,0,0,0,0
0,0,0,0,0,0,0,0,0,0,0,0,0,0,0,0,6,0,0,0,5,5,0,0
endlayer

layer
2,12,0,0,0,2,0,0,0,0,0,0,0,0,0,0,0,0,0,0,0,0,0,0
2,6,4,0,0,0,12,12,12,12,0,0,0,0,0,0,0,0,0,0,0,0,0,0
0,0,0,0,0,0,0,0,0,0,12,12,12,0,0,0,0,0,0,0,0,0,0,0
0,0,0,0,0,0,0,0,0,0,0,0,0,12,12,0,0,0,0,0,0,0,0,0
0,0,0,0,0,0,0,0,0,0,0,0,0,0,6,0,0,0,0,0,0,0,0,0
0,0,0,0,0,0,0,0,0,0,0,0,0,0,0,0,0,0,0,0,0,0,0,0
0,6,0,0,0,0,0,0,0,0,0,0,0,0,0,0,0,0,2,0,0,0,0,0
0,12,0,0,0,0,0,0,0,0,0,0,0,0,0,0,0,0,0,2,0,0,0,0
0,0,0,0,0,2,12,12,12,0,0,0,0,0,0,0,0,0,0,0,0,0,0,0
0,0,0,0,0,0,0,0,0,12,12,12,6,0,0,0,0,0,0,0,0,0,0,0
0,0,0,0,0,0,0,0,0,0,0,0,12,0,0,0,0,0,5,0,0,0,0,0
0,0,0,0,0,0,0,0,0,0,0,0,0,0,5,0,5,0,5,0,0,6,0,0
0,0,0,0,0,0,0,0,0,0,5,5,5,5,0,5,0,0,0,0,0,0,0,0
0,0,0,0,0,0,0,0,0,0,0,0,0,0,0,0,6,0,0,0,0,0,0,0
endlayer

layer
2,12,12,0,12,2,0,0,0,0,0,0,0,0,0,0,0,0,0,0,0,0,0,0
2,6,4,0,0,0,12,12,12,12,0,0,0,0,0,0,0,0,0,0,0,0,0,0
2,0,0,0,0,0,0,0,0,0,12,12,12,0,0,0,0,0,0,0,0,0,0,0
2,0,0,0,0,0,0,0,0,0,0,0,0,12,12,0,0,0,0,0,0,0,0,0
2,0,0,0,0,0,0,0,0,0,0,0,0,0,6,0,0,0,0,0,0,5,0,0
2,0,0,0,0,0,0,0,0,0,0,0,0,0,0,0,0,0,0,0,0,0,0,0
2,6,0,0,0,0,0,0,0,0,0,0,0,0,0,0,0,0,2,0,0,0,0,0
2,12,12,12,12,0,0,0,0,0,0,0,0,0,0,5,0,0,0,2,0,0,0,0
0,0,0,0,0,2,12,12,12,0,0,0,0,0,0,0,5,0,0,0,0,0,0,0
0,0,0,0,0,0,0,0,0,12,12,12,6,0,0,0,5,0,0,0,0,0,0,0
0,0,0,0,0,0,0,0,0,0,0,0,12,0,0,0,5,0,0,0,0,0,0,0
0,0,0,0,0,0,0,0,0,0,0,0,0,0,0,0,0,0,0,0,0,6,0,0
0,0,0,0,0,0,0,0,0,0,0,0,0,0,0,0,0,0,0,0,0,0,0,0
0,0,0,0,0,0,0,0,0,0,0,0,0,0,0,0,6,0,0,0,0,5,0,0
endlayer

layer
2,2,2,2,2,2,0,0,0,0,0,0,0,0,0,0,0,0,0,0,0,0,0,0
2,6,4,11,11,11,2,2,2,2,0,0,0,0,0,0,0,0,0,0,0,0,0,0
2,11,11,11,11,11,11,11,11,11,2,2,2,0,0,0,0,0,0,0,0,0,0,0
2,11,11,11,11,11,11,11,11,11,11,11,11,2,2,0,0,0,0,0,0,0,0,0
2,11,11,11,11,11,11,11,11,11,11,11,11,11,6,0,0,0,0,0,0,0,0,0
2,11,11,11,11,11,11,11,11,11,11,11,11,11,11,0,0,0,0,0,0,0,0,0
2,6,11,11,11,11,11,11,11,11,11,11,11,11,11,0,0,0,2,0,0,0,0,0
2,2,2,2,2,11,11,11,11,11,11,11,11,11,11,0,0,0,0,2,0,0,0,0
0,0,0,0,0,2,2,2,2,11,11,11,11,11,0,0,0,0,0,0,0,0,0,0
0,0,0,0,0,0,0,0,0,2,2,2,6,11,0,0,0,0,0,0,0,0,0,0
0,0,0,0,0,0,0,0,0,0,0,0,2,0,0,0,0,0,0,0,0,0,0,0
0,0,0,0,0,0,0,0,0,0,0,0,0,0,0,0,0,0,0,0,0,6,0,0
0,0,0,0,0,0,0,0,0,0,0,0,0,0,0,0,0,0,0,5,0,0,0,0
0,0,0,0,0,0,0,0,0,0,0,0,0,0,0,0,6,0,0,0,0,0,0,0
endlayer

layer
2,2,2,2,2,2,0,0,0,0,0,0,0,0,0,0,0,0,0,0,0,0,0,0
2,6,4,0,0,0,2,2,2,2,0,0,0,0,0,0,0,0,0,0,0,0,0,0
2,0,0,0,5,0,0,0,0,0,2,2,2,0,0,0,0,0,0,0,0,0,0,0
2,0,0,5,5,5,0,0,0,0,0,0,0,2,2,0,0,0,0,0,0,0,0,0
2,0,0,0,0,0,0,0,0,0,0,0,0,0,6,0,0,0,0,0,0,0,0,0
2,0,0,0,0,0,0,0,0,0,0,0,0,0,0,0,0,0,0,0,0,0,0,0
2,6,0,0,0,0,0,0,0,0,0,0,0,0,0,0,0,0,2,0,0,0,0,0
2,2,2,2,2,0,0,0,0,0,0,0,5,0,0,0,0,0,0,2,0,0,0,0
0,0,0,0,0,2,2,2,2,0,0,0,0,0,0,0,0,0,0,0,0,0,0,0
0,0,0,0,0,0,0,0,0,2,2,2,6,0,0,0,0,0,0,0,0,0,0,0
0,0,0,0,0,0,0,0,0,0,0,0,2,0,0,0,0,0,0,0,0,0,0,0
0,0,0,0,0,0,0,0,0,0,0,0,0,0,0,0,0,0,0,0,0,6,0,0
0,0,0,0,0,0,0,0,0,0,0,0,0,0,0,0,0,0,0,0,0,0,0,0
0,0,0,0,0,0,0,0,0,0,0,0,0,0,0,0,6,0,0,0,0,0,0,0
endlayer

layer
2,12,12,12,12,2,0,0,0,0,0,0,0,0,0,0,0,0,0,0,0,0,0,0
2,6,14,0,0,0,12,12,12,12,0,0,0,0,0,0,0,0,0,0,0,0,0,0
2,0,0,0,0,0,0,0,0,0,12,12,12,0,0,0,0,0,0,0,0,0,0,0
2,0,0,5,5,0,0,0,0,0,0,0,0,12,12,0,0,0,0,0,0,0,0,0
2,0,0,0,0,0,0,0,0,0,0,0,0,0,6,0,0,0,0,0,0,0,0,0
2,0,0,0,0,0,0,0,0,0,0,0,0,0,0,0,0,0,0,0,0,0,0,0
2,6,0,0,0,0,0,0,0,0,0,0,0,0,0,0,0,0,2,0,0,0,0,0
2,12,12,12,12,0,0,0,0,0,0,0,0,0,0,0,0,0,0,2,0,0,0,0
0,0,0,0,0,2,12,12,12,0,0,0,0,0,0,5,0,0,0,0,12,0,0,0
0,0,0,0,0,0,0,0,0,12,12,12,6,0,0,0,0,0,0,0,0,0,0,0
0,0,0,0,0,0,0,0,0,0,0,0,12,0,0,0,0,0,0,0,0,12,0,0
0,0,0,0,0,0,0,0,0,0,0,0,0,0,0,0,0,0,0,0,0,6,0,0
0,0,0,0,0,0,0,0,0,0,0,0,0,0,0,0,0,0,0,0,0,0,0,0
0,0,0,0,0,0,0,0,0,0,0,0,0,0,0,0,6,0,0,0,0,0,0,0
endlayer

layer
2,12,12,12,12,2,0,0,0,0,0,0,0,0,0,0,0,0,0,0,0,0,0,0
2,6,4,0,0,0,12,12,12,12,0,0,0,0,0,0,0,0,0,0,0,0,0,0
2,0,0,0,0,0,0,0,0,0,12,12,12,0,0,0,0,0,0,0,0,0,0,0
2,0,0,0,0,0,0,0,0,0,0,0,0,12,12,0,0,0,0,0,0,0,0,0
2,0,0,0,0,0,0,0,0,0,0,0,0,0,6,12,0,0,0,0,0,0,0,0
2,0,0,0,0,0,0,0,0,0,0,0,0,0,0,0,0,0,0,0,0,0,0,0
2,6,0,0,0,0,0,0,0,0,0,0,0,0,0,0,0,0,2,0,0,0,0,0
2,12,12,12,12,0,0,0,0,0,0,0,0,0,0,0,0,0,0,2,0,0,0,0
0,0,0,0,0,2,12,12,12,0,0,0,0,0,0,0,0,0,0,0,12,0,0,0
0,0,0,0,0,0,0,0,0,12,12,12,6,0,0,0,0,0,0,0,0,12,0,0
0,0,0,0,0,0,0,0,0,0,0,0,12,0,0,0,0,0,0,0,0,12,0,0
0,0,0,0,0,0,0,0,0,0,0,0,0,0,0,0,0,0,0,0,0,6,0,0
0,0,0,0,0,0,0,0,0,0,0,0,0,0,0,0,0,0,0,0,0,0,0,0
0,0,0,0,0,0,0,0,0,0,0,0,0,0,0,0,6,0,0,0,0,0,0,0
endlayer

layer
2,12,12,12,12,2,0,0,0,0,0,0,0,0,0,0,0,0,0,0,0,0,0,0
2,6,4,0,0,0,12,12,12,12,0,0,0,0,0,0,0,0,0,0,0,0,0,0
2,0,0,0,0,0,0,0,0,0,12,12,12,0,0,0,0,0,0,0,0,0,0,0
2,0,0,0,0,0,0,0,0,0,0,0,0,12,12,0,0,0,0,0,0,0,0,0
2,0,0,0,0,0,0,0,0,0,0,0,0,0,6,12,0,0,0,0,0,0,0,0
2,0,0,0,0,0,0,0,0,0,0,0,0,0,0,0,0,0,0,0,0,0,0,0
2,6,0,0,0,0,0,0,0,0,0,0,0,0,0,0,0,0,2,0,0,0,0,0
2,12,12,12,12,0,0,0,0,0,0,0,0,0,0,0,0,0,0,2,0,0,0,0
0,0,0,0,0,2,12,12,12,0,0,0,0,0,0,0,0,0,0,0,12,0,0,0
0,0,0,0,0,0,0,0,0,12,12,12,6,0,0,0,0,0,0,0,0,12,0,0
0,0,0,0,0,0,0,0,0,0,0,0,12,0,0,0,0,0,0,0,0,12,0,0
0,0,0,0,0,0,0,0,0,0,0,0,0,0,0,0,0,0,0,0,0,6,0,0
0,0,0,0,0,0,0,0,0,0,0,0,0,0,0,0,0,0,0,0,0,0,0,0
0,0,0,0,0,0,0,0,0,0,0,0,0,0,0,0,6,0,0,0,0,0,0,0
endlayer

layer
2,2,2,2,2,2,0,0,0,0,0,0,0,0,0,0,0,0,0,0,0,0,0,0
2,6,4,11,11,11,2,2,2,2,0,0,0,0,0,0,0,0,0,0,0,0,0,0
2,11,11,11,11,11,11,11,11,11,2,2,2,0,0,0,0,0,0,0,0,0,0,0
2,11,11,11,11,11,11,11,11,11,11,11,11,2,2,0,0,0,0,0,0,0,0,0
2,11,11,11,11,11,11,11,11,11,11,11,11,11,6,2,2,0,0,0,0,0,0,0
2,11,11,11,11,11,11,11,11,11,11,11,11,11,11,11,11,2,0,0,0,0,0,0
2,6,11,11,11,11,11,11,11,11,11,11,11,11,11,11,11,11,2,0,0,0,0,0
2,2,2,2,2,11,11,11,11,11,11,11,11,11,11,11,11,11,11,2,0,0,0,0
0,0,0,0,0,2,2,2,2,11,11,11,11,11,11,11,11,11,11,11,2,0,0,0
0,0,0,0,0,0,0,0,0,2,2,2,6,11,11,11,11,11,11,11,11,2,0,0
0,0,0,0,0,0,0,0,0,0,0,0,2,11,11,11,11,11,11,11,11,2,0,0
0,0,0,0,0,0,0,0,0,0,0,0,0,0,11,11,11,11,11,11,11,6,2,0
0,0,0,0,0,0,0,0,0,0,0,0,0,0,0,11,11,11,11,11,11,11,2,0
0,0,0,0,0,0,0,0,0,0,0,0,0,0,0,0,6,11,11,11,11,11,11,2
endlayer

layer
2,12,12,12,12,2,0,0,0,0,0,0,0,0,0,0,0,0,0,0,0,0,0,0
2,6,4,0,0,0,12,12,12,12,0,0,0,0,0,0,0,0,0,0,0,0,0,0
2,0,0,0,5,0,0,0,0,0,12,12,12,0,0,0,0,0,0,0,0,0,0,0
2,0,0,0,0,5,0,0,0,0,0,0,0,12,12,0,0,0,0,0,0,0,0,0
2,0,0,0,0,15,0,0,0,0,0,0,0,0,6,12,12,0,0,0,0,0,0,0
2,0,0,0,0,0,0,0,0,0,0,0,0,0,0,0,0,12,0,0,0,0,0,0
2,6,0,0,0,0,0,0,0,0,0,0,0,0,5,0,0,0,2,0,0,0,0,0
2,12,12,12,12,0,0,0,0,0,0,0,0,0,0,0,0,0,0,2,0,0,0,0
0,0,0,0,0,2,12,12,12,0,0,0,0,0,0,0,0,0,0,0,12,0,0,0
0,0,0,0,0,0,0,0,0,12,12,12,6,0,0,0,0,0,0,0,0,12,0,0
0,0,0,0,0,0,0,0,0,0,0,0,12,0,0,0,0,0,0,0,0,12,0,0
0,0,0,0,0,0,0,0,0,0,0,0,0,2,0,0,0,0,0,0,0,6,12,0
0,0,0,0,0,0,0,0,0,0,0,0,0,0,2,0,0,0,0,0,0,0,12,0
0,0,0,0,0,0,0,0,0,0,0,0,0,0,0,0,6,2,2,2,2,2,2,12
endlayer

layer
2,12,12,12,12,2,0,0,0,0,0,0,0,0,0,0,0,0,0,0,0,0,0,0
2,6,4,0,0,0,12,12,12,12,0,0,0,0,0,0,0,0,0,0,0,0,0,0
2,0,0,0,0,0,0,0,0,0,12,12,12,0,0,0,0,0,0,0,0,0,0,0
2,0,0,0,0,0,0,0,0,0,0,0,0,12,12,0,0,0,0,0,0,0,0,0
2,0,0,0,0,0,0,5,5,0,0,0,0,0,6,12,12,0,0,0,0,0,0,0
2,0,0,0,0,0,0,0,5,0,5,0,0,0,0,0,0,12,0,0,0,0,0,0
2,6,0,0,0,0,0,0,0,0,0,5,0,0,0,0,0,0,2,0,0,0,0,0
2,12,12,12,12,0,0,0,0,0,0,0,0,0,0,0,0,0,0,2,0,0,0,0
0,0,0,0,0,2,12,12,12,0,0,0,5,0,0,0,0,0,0,0,12,0,0,0
0,0,0,0,0,0,0,0,0,12,12,12,6,0,0,5,0,0,0,0,0,12,0,0
0,0,0,0,0,0,0,0,0,0,0,0,12,0,0,0,0,5,5,0,0,12,0,0
0,0,0,0,0,0,0,0,0,0,0,0,0,2,0,0,0,0,0,0,0,6,12,0
0,0,0,0,0,0,0,0,0,0,0,0,0,0,2,0,0,0,0,5,5,0,12,0
0,0,0,0,0,0,0,0,0,0,0,0,0,0,0,12,6,2,2,2,2,2,2,12
endlayer

layer
2,12,12,12,12,2,0,0,0,0,0,0,0,0,0,0,0,0,0,0,0,0,0,0
2,6,4,0,0,0,12,12,12,12,0,0,0,0,0,0,0,0,0,0,0,0,0,0
2,0,0,5,0,0,0,0,0,0,12,12,12,0,0,0,0,0,0,0,0,0,0,0
2,0,0,0,0,0,0,0,0,0,0,0,0,12,12,0,0,0,0,0,0,0,0,0
2,0,0,0,0,0,0,0,0,0,0,0,0,0,6,12,12,0,0,0,0,0,0,0
2,0,0,0,0,0,0,0,0,0,0,0,0,0,0,0,0,12,0,0,0,0,0,0
2,6,0,0,0,0,0,0,0,0,0,5,0,0,0,0,0,0,2,0,0,0,0,0
2,12,12,12,12,0,0,0,0,0,0,0,0,0,0,0,0,0,0,2,0,0,0,0
0,0,0,0,0,2,12,12,12,0,0,0,0,0,0,0,0,0,0,0,12,0,0,0
0,0,0,0,0,0,0,0,0,12,12,12,6,0,0,0,0,0,0,0,0,12,0,0
0,0,0,0,0,0,0,0,0,0,0,0,12,0,0,0,0,0,0,0,0,12,0,0
0,0,0,0,0,0,0,0,0,0,0,0,0,2,0,0,0,0,0,0,0,6,12,0
0,0,0,0,0,0,0,0,0,0,0,0,0,0,2,0,0,0,0,0,0,0,12,0
0,0,0,0,0,0,0,0,0,0,0,0,0,0,0,12,6,2,2,2,2,2,2,12
endlayer

layer
2,12,12,12,12,2,0,0,0,0,0,0,0,0,0,0,0,0,0,0,0,0,0,0
2,6,4,0,0,0,12,12,12,12,0,0,0,0,0,0,0,0,0,0,0,0,0,0
2,0,0,0,0,0,0,0,0,0,12,12,12,0,0,0,0,0,0,0,0,0,0,0
2,0,0,0,0,0,0,0,0,0,0,0,0,12,12,0,0,0,0,0,0,0,0,0
2,0,0,0,0,0,0,0,0,0,0,0,0,0,6,12,12,0,0,0,0,0,0,0
2,0,0,0,0,0,0,0,0,0,0,0,0,0,0,0,0,12,0,0,0,0,0,0
2,6,0,0,0,0,0,0,0,0,0,0,0,0,0,0,0,0,2,0,0,0,0,0
2,12,12,12,12,0,0,0,0,0,0,0,0,0,0,0,0,0,0,2,0,0,0,0
0,0,0,0,0,2,12,12,12,0,0,0,0,0,0,0,0,0,0,0,12,0,0,0
0,0,0,0,0,0,0,0,0,12,12,12,6,0,0,0,0,0,0,0,0,12,0,0
0,0,0,0,0,0,0,0,0,0,0,0,12,0,0,0,0,0,0,0,0,12,0,0
0,0,0,0,0,0,0,0,0,0,0,0,0,2,0,0,0,0,0,0,0,6,12,0
0,0,0,0,0,0,0,0,0,0,0,0,0,0,2,0,0,0,0,0,0,0,12,0
0,0,0,0,0,0,0,0,0,0,0,0,0,0,0,12,6,2,2,2,2,2,2,12
endlayer

layer
2,12,12,12,12,2,0,0,0,0,0,0,0,0,0,0,0,0,0,0,0,0,0,0
2,6,4,0,0,0,12,12,12,12,0,0,0,0,0,0,0,0,0,0,0,0,0,0
2,0,0,0,0,0,0,0,0,0,12,12,12,0,0,0,0,0,0,0,0,0,0,0
2,0,0,0,0,0,0,0,0,0,0,0,0,12,12,0,0,0,0,0,0,0,0,0
2,0,0,0,0,0,0,0,0,0,0,0,0,0,6,12,12,0,0,0,0,0,0,0
2,0,0,0,0,0,0,0,0,0,0,0,0,0,0,0,0,12,0,0,0,0,0,0
2,6,0,0,0,0,0,0,0,0,0,0,0,0,0,0,0,0,2,0,0,0,0,0
2,12,12,12,12,0,0,0,0,0,0,0,0,0,0,0,0,0,0,2,0,0,0,0
0,0,0,0,0,2,12,12,12,0,0,0,0,0,0,0,0,0,0,0,12,0,0,0
0,0,0,0,0,0,0,0,0,12,12,12,6,0,0,0,0,0,0,0,0,12,0,0
0,0,0,0,0,0,0,0,0,0,0,0,12,0,0,0,0,0,0,0,0,12,0,0
0,0,0,0,0,0,0,0,0,0,0,0,0,2,0,0,0,0,0,0,0,6,12,0
0,0,0,0,0,0,0,0,0,0,0,0,0,0,2,0,0,0,0,0,0,0,12,0
0,0,0,0,0,0,0,0,0,0,0,0,0,0,0,12,6,2,2,2,2,2,2,12
endlayer

layer
2,2,2,2,2,2,0,0,0,0,0,0,0,0,0,0,0,0,0,0,0,0,0,0
2,2,4,2,2,2,2,2,2,2,0,0,0,0,0,0,0,0,0,0,0,0,0,0
2,2,2,2,2,2,2,2,2,2,2,2,2,0,0,0,5,0,0,0,0,0,0,0
2,2,2,2,2,2,2,2,2,2,2,2,2,2,2,0,0,0,0,0,0,0,0,0
2,2,2,2,2,2,2,2,2,2,2,2,2,2,2,2,2,0,0,0,0,0,0,0
2,2,2,2,2,2,2,2,2,2,2,2,2,2,2,2,2,2,0,0,0,0,0,0
2,2,2,2,2,2,2,2,2,2,2,2,2,2,2,2,2,2,2,0,0,0,0,0
2,2,2,2,2,2,2,2,2,2,2,2,2,2,2,2,2,2,2,2,0,0,0,0
0,0,0,0,0,2,2,2,2,2,2,2,2,2,2,2,2,2,2,2,2,0,0,0
0,0,0,0,0,0,0,0,0,2,2,2,2,2,2,2,2,2,2,2,2,2,0,0
0,0,0,0,0,0,0,0,0,0,0,0,2,2,2,2,2,2,2,2,2,2,0,0
0,0,0,0,0,0,0,0,0,0,0,0,0,2,2,2,2,2,2,2,2,2,2,0
0,0,0,0,0,0,0,0,0,0,0,0,0,0,2,2,2,2,2,2,2,2,2,0
0,0,0,0,0,0,0,0,0,0,0,0,0,0,0,2,2,2,2,2,2,2,2,2
endlayer

layer
0,0,0,0,0,0,0,0,0,0,0,0,0,0,0,0,0,0,0,0,0,0,0,0
0,0,4,16,0,0,0,0,0,0,0,0,0,0,0,0,0,0,0,0,0,0,0,0
0,0,0,0,0,0,0,0,0,0,0,0,0,0,0,0,0,0,0,0,0,0,0,0
0,0,0,0,0,0,0,0,0,0,0,0,0,0,0,0,0,0,0,0,0,0,0,0
0,0,0,0,0,0,0,0,0,0,0,0,0,0,0,0,0,0,0,0,0,0,0,0
0,0,0,0,0,0,0,0,0,0,0,0,0,0,0,0,0,0,0,0,0,0,0,0
0,0,0,0,0,0,0,0,0,0,0,0,0,0,0,0,0,0,0,0,0,0,0,0
0,0,0,0,0,0,0,0,0,0,0,0,0,0,0,0,0,0,0,0,0,0,0,0
0,0,0,0,0,0,0,0,0,0,0,0,0,0,0,0,0,0,0,0,0,0,0,0
0,0,0,0,0,0,0,0,0,0,0,0,0,0,0,0,0,0,0,0,0,0,0,0
0,0,0,0,0,0,0,0,0,0,0,0,0,0,0,0,0,0,0,0,0,0,0,0
0,0,0,0,0,0,0,0,0,0,0,0,0,0,0,0,0,0,0,0,0,0,0,0
0,0,0,0,0,0,0,0,0,0,0,0,0,0,0,0,0,0,0,0,0,0,0,0
0,0,0,0,0,0,0,0,0,0,0,0,0,0,0,0,0,0,0,0,0,0,0,0
endlayer

layer
0,0,0,0,0,0,0,0,0,0,0,0,0,0,0,0,0,0,0,0,0,0,0,0
0,0,8,0,0,5,0,0,0,0,0,0,0,0,0,0,0,0,0,0,0,0,0,0
0,0,0,0,0,0,0,0,0,0,0,0,0,0,0,0,0,0,0,0,0,0,0,0
0,0,0,5,0,0,0,0,0,0,0,0,0,0,0,0,0,0,0,0,0,0,0,0
0,0,0,0,5,0,0,0,0,0,0,0,0,0,0,0,0,0,0,0,0,0,0,0
0,0,0,0,0,0,0,0,0,0,0,0,0,0,0,0,0,0,0,0,0,0,0,0
0,0,0,0,0,0,0,0,0,0,0,0,0,0,0,0,0,0,0,0,0,0,0,0
0,0,0,0,0,0,0,0,0,0,0,0,0,0,0,0,0,0,0,0,0,0,0,0
0,0,0,0,0,0,0,0,0,0,0,0,0,0,0,0,0,0,0,0,0,0,0,0
0,0,0,0,0,0,0,0,0,0,0,0,0,0,0,0,0,0,0,0,0,0,0,0
0,0,0,0,0,0,0,0,0,0,0,0,0,0,0,0,0,0,0,0,0,0,0,0
0,0,0,0,0,0,0,0,0,0,0,0,0,0,0,0,0,0,0,0,0,0,0,0
0,0,0,0,0,0,0,0,0,0,0,0,0,0,0,0,0,0,0,0,0,0,0,0
0,0,0,0,0,0,0,0,0,0,0,0,0,0,0,0,0,0,0,0,0,0,0,0
endlayer

layer
0,0,0,0,0,0,0,0,0,0,0,0,0,0,0,0,0,0,0,0,0,0,0,0
0,0,0,0,0,0,0,0,0,0,0,0,0,0,0,0,0,0,0,0,0,0,0,0
0,0,0,0,0,0,0,0,0,0,0,0,0,0,0,0,0,0,0,0,0,0,0,0
0,0,0,0,0,0,0,0,0,0,0,0,0,0,0,0,0,0,0,0,0,0,0,0
0,0,0,0,0,0,0,0,0,0,0,0,0,0,0,0,0,0,0,0,0,0,0,0
0,0,0,0,0,0,0,0,0,0,0,0,0,0,0,0,0,0,0,0,0,0,0,0
0,0,0,0,0,0,0,0,0,0,0,0,0,0,0,0,0,0,0,0,0,0,0,0
0,0,0,0,0,0,0,0,0,0,0,0,0,0,0,0,0,0,0,0,0,0,0,0
0,0,0,0,0,0,0,5,0,0,0,0,0,0,0,0,0,0,0,0,0,0,0,0
0,0,0,0,0,0,0,0,0,0,0,0,0,0,0,0,0,0,0,0,0,0,0,0
0,0,0,0,0,0,0,5,5,0,0,0,0,0,0,0,0,0,0,0,0,0,0,0
0,0,0,0,0,0,0,0,0,0,0,0,0,0,0,0,0,0,0,0,0,0,0,0
0,0,0,0,0,0,0,0,0,0,0,0,0,0,0,0,0,0,0,0,0,0,0,0
0,0,0,0,0,0,0,0,0,0,0,0,0,0,0,0,0,0,0,0,0,0,0,0
endlayer

