
# Created by Ruins mod version 13.8 Ingame Parser
# authoring Player: Spud_Gunn

weight=5
unique=1
biomesToSpawnIn=plains,forest,swamp,rolling hills,high hills
embed_into_distance=0
acceptable_target_blocks=
unacceptable_target_blocks=flowing_water,water,flowing_lava,lava,terrafirmacraft:SaltWaterStationary-0,terrafirmacraft:SaltWaterStationary-8,terrafirmacraft:FreshWaterStationary-0,terrafirmacraft:FreshWaterStationary-8
dimensions=11,14,13
allowable_overhang=8
max_leveling=6
leveling_buffer=0
preserve_water=0
preserve_lava=0

rule1=0,100,terrafirmacraft:WoodVert-5
rule2=0,100,terrafirmacraft:Vine-8
rule3=0,100,terrafirmacraft:StoneIgInCobble-0
rule4=0,100,terrafirmacraft:StoneIgInSmooth-0
rule5=0,100,terrafirmacraft:StoneIgInBrick-0
rule6=0,100,terrafirmacraft:Vine-4
rule7=0,100,terrafirmacraft:Vine-1
rule8=0,100,air,MobSpawner:TwilightForest.Redcap,MobSpawner:TwilightForest.Forest Raven
rule9=0,100,terrafirmacraft:planks-8
rule10=0,100,terrafirmacraft:planks-12
rule11=0,100,terrafirmacraft:DoorBirch-0
rule12=0,100,terrafirmacraft:Vine-2
rule13=0,100,terrafirmacraft:DoorBirch-8
rule14=0,100,terrafirmacraft:StoneSedSmooth-6
rule15=0,100,terrafirmacraft:Vine-12
rule16=2,100,minecraft:redstone_torch-2
rule17=0,100,terrafirmacraft:WoodHoriz-5
rule18=0,100,terrafirmacraft:WoodHoriz-13
rule19=0,100,air,air,MobSpawner:TwilightForest.Hedge Spider,MobSpawner:caveSpiderTFC
rule20=0,100,terrafirmacraft:Vine-3
rule21=2,100,minecraft:redstone_torch-3
rule22=2,100,minecraft:redstone_torch-4
rule23=0,100,air,air,air,minecraft:furnace-5
rule24=0,100,air,ChestGenHook:dungeonChest:5-3
rule25=2,100,minecraft:redstone_torch-1

layer
0,0,0,0,0,0,0,0,0,0,0,0,0
0,0,0,0,0,0,0,0,0,0,0,0,0
0,0,1,0,0,0,0,0,0,2,1,0,0
0,0,0,4,4,4,4,3,0,0,0,0,0
0,0,6,3,5,5,5,5,5,3,0,0,0
0,0,0,4,5,5,5,5,5,4,7,0,0
0,0,0,4,5,5,5,5,8,4,7,0,0
0,0,6,4,5,5,5,5,5,4,7,0,0
0,0,0,3,5,5,5,5,5,3,0,0,0
0,0,0,3,5,5,5,5,5,4,0,0,0
0,0,0,4,5,5,5,5,5,4,0,0,0
0,0,0,4,4,4,4,4,3,0,0,0,0
0,0,1,0,4,3,4,4,0,0,1,0,0
0,0,0,0,0,0,0,0,0,0,0,0,0
endlayer

layer
0,0,0,0,0,0,0,0,0,0,0,0,0
0,0,0,0,0,0,0,0,0,0,0,0,0
0,0,1,0,0,0,0,0,0,2,1,0,0
0,0,0,9,10,10,10,9,9,0,0,0,0
0,0,6,9,0,0,0,0,0,10,0,0,0
0,0,6,9,0,0,0,0,0,9,0,0,0
0,0,6,9,0,0,0,0,10,10,7,0,0
0,0,6,10,0,0,0,0,0,10,7,0,0
0,0,0,10,0,0,0,0,0,9,0,0,0
0,0,0,10,0,0,0,0,0,10,0,0,0
0,0,0,10,0,0,0,0,0,9,0,0,0
0,0,0,10,10,4,11,4,10,0,0,0,0
0,0,1,0,0,0,0,0,12,0,1,0,0
0,0,0,0,0,0,0,0,0,0,0,0,0
endlayer

layer
0,0,0,0,0,0,0,0,0,0,0,0,0
0,0,0,0,0,0,0,0,0,0,0,0,0
0,0,1,0,0,0,2,0,2,2,1,0,0
0,0,0,10,10,10,9,10,10,9,0,0,0
0,0,6,9,0,0,10,0,0,10,0,0,0
0,0,6,9,0,0,0,0,0,10,0,0,0
0,0,6,10,0,0,0,0,0,9,7,0,0
0,0,6,10,0,0,0,0,0,10,7,0,0
0,0,0,0,0,0,0,0,0,10,0,0,0
0,0,0,9,0,0,0,0,0,0,7,0,0
0,0,0,10,0,0,0,0,0,10,0,0,0
0,0,0,9,10,4,13,4,10,9,0,0,0
0,0,1,0,0,0,0,12,12,0,1,0,0
0,0,0,0,0,0,0,0,0,0,0,0,0
endlayer

layer
0,0,0,0,0,0,0,0,0,0,0,0,0
0,0,0,0,0,0,0,0,0,0,0,0,0
0,0,0,0,0,0,2,2,0,0,1,0,0
0,0,0,0,9,0,10,10,9,0,0,0,0
0,0,6,10,0,0,0,0,0,9,0,0,0
0,0,0,10,10,0,0,0,0,10,0,0,0
0,0,0,0,0,0,0,0,0,10,0,0,0
0,0,0,9,0,0,0,0,0,10,0,0,0
0,0,0,10,0,0,0,0,0,0,0,0,0
0,0,0,10,0,0,0,0,0,10,7,0,0
0,0,0,9,0,0,0,0,0,9,0,0,0
0,0,0,12,9,4,4,4,10,9,0,0,0
0,0,1,0,0,0,0,12,12,0,1,0,0
0,0,0,0,0,0,0,0,0,0,0,0,0
endlayer

layer
0,0,0,0,0,0,0,0,0,0,0,0,0
0,14,0,0,0,0,0,0,0,0,0,14,0
0,14,0,0,0,0,0,2,0,0,1,14,0
0,14,0,0,10,9,10,9,7,0,0,14,0
0,0,0,0,0,0,0,0,0,9,0,0,0
0,0,0,10,0,0,0,0,0,9,0,0,0
0,0,0,10,0,0,0,0,0,0,0,0,0
0,0,0,15,10,10,0,0,0,9,0,0,0
0,0,0,10,0,0,0,0,0,9,0,0,0
0,0,0,9,0,0,0,0,0,9,7,0,0
0,0,0,9,0,0,16,0,0,9,0,0,0
0,14,0,0,0,9,10,10,9,0,0,14,0
0,14,1,0,0,0,0,12,0,0,1,14,0
0,14,0,0,0,0,0,0,0,0,0,14,0
endlayer

layer
0,0,0,0,0,0,0,0,0,0,0,0,0
0,0,14,0,0,0,0,0,0,0,14,14,0
0,14,1,17,17,17,17,15,18,17,1,14,0
0,14,18,10,10,10,10,10,10,10,18,14,0
0,14,18,10,0,0,0,0,0,10,18,14,0
0,14,18,10,0,0,0,0,0,10,18,14,0
0,14,18,10,0,0,0,0,0,10,18,14,0
0,14,18,10,0,0,0,0,0,0,18,14,0
0,14,18,19,10,10,0,0,0,10,18,14,0
0,14,18,10,0,0,0,0,0,10,18,14,0
0,14,18,10,0,0,0,0,0,10,18,14,0
0,14,18,10,10,10,10,0,10,10,18,14,0
0,14,1,17,17,17,17,17,17,17,1,14,0
0,0,14,0,0,0,0,0,0,0,14,20,0
endlayer

layer
0,0,0,2,0,0,0,0,0,0,0,0,0
0,0,0,14,0,0,0,0,2,14,0,0,0
0,0,14,14,0,0,0,15,0,14,14,0,0
0,0,14,22,0,1,0,1,0,21,14,0,0
0,0,14,14,10,10,10,10,10,14,14,0,0
0,0,14,10,0,0,10,10,10,14,7,0,0
0,0,14,0,0,0,10,10,10,14,14,0,0
0,6,14,10,0,0,10,10,10,14,14,0,0
0,0,14,10,0,0,10,10,10,14,14,0,0
0,0,14,14,10,10,10,10,10,14,14,0,0
0,0,14,14,10,10,10,10,10,14,14,0,0
0,0,14,22,0,1,0,1,0,21,14,0,0
0,0,0,14,0,12,0,0,0,14,14,0,0
0,0,0,0,0,0,0,0,0,0,14,0,0
endlayer

layer
0,0,0,2,0,0,0,0,0,0,0,0,0
0,0,0,14,14,0,0,0,2,14,0,0,0
0,0,0,14,14,0,0,6,14,14,0,0,0
0,0,0,14,14,2,0,1,14,14,0,0,0
0,0,0,0,10,10,10,10,10,14,0,0,0
0,0,6,14,0,0,0,23,10,14,7,0,0
0,0,6,14,10,0,0,0,10,14,0,0,0
0,0,0,14,10,0,0,0,10,14,0,0,0
0,0,0,14,10,0,0,0,10,14,0,0,0
0,0,0,0,10,0,0,24,10,0,0,0,0
0,0,0,14,10,10,10,10,10,14,7,0,0
0,0,0,14,14,1,17,1,14,14,7,0,0
0,0,0,14,14,12,0,0,14,14,0,0,0
0,0,0,0,14,0,0,0,14,14,0,0,0
endlayer

layer
0,0,0,0,0,0,0,0,0,0,0,0,0
0,0,0,0,14,14,0,0,14,0,0,0,0
0,0,0,0,14,14,0,0,14,0,0,0,0
0,0,0,0,14,2,0,0,14,0,0,0,0
0,0,0,0,14,10,10,10,0,0,0,0,0
0,0,0,0,0,0,0,0,14,0,0,0,0
0,0,0,0,14,0,0,0,14,0,0,0,0
0,0,0,0,14,0,0,0,14,7,0,0,0
0,0,0,0,14,0,0,0,14,0,0,0,0
0,0,0,0,14,0,0,0,14,0,0,0,0
0,0,0,0,14,10,10,10,7,0,0,0,0
0,0,0,6,14,14,0,14,14,0,0,0,0
0,0,0,6,14,14,0,14,14,0,0,0,0
0,0,0,0,0,14,0,0,14,0,0,0,0
endlayer

layer
0,0,0,0,0,0,0,0,0,0,0,0,0
0,0,0,0,0,0,14,14,0,0,0,0,0
0,0,0,0,0,14,14,14,0,0,0,0,0
0,0,0,0,6,14,14,14,7,0,0,0,0
0,0,0,0,0,14,10,14,0,0,0,0,0
0,0,0,0,0,14,25,14,0,0,0,0,0
0,0,0,0,0,14,0,14,0,0,0,0,0
0,0,0,0,0,14,0,14,0,0,0,0,0
0,0,0,0,0,14,0,14,0,0,0,0,0
0,0,0,0,6,14,16,14,0,0,0,0,0
0,0,0,0,6,14,10,14,0,0,0,0,0
0,0,0,0,0,14,14,14,0,0,0,0,0
0,0,0,0,0,14,14,14,0,0,0,0,0
0,0,0,0,0,14,14,14,7,0,0,0,0
endlayer

layer
0,0,0,0,0,0,0,0,0,0,0,0,0
0,0,0,0,0,0,0,0,0,0,0,0,0
0,0,0,0,0,0,14,0,0,0,0,0,0
0,0,0,0,0,6,14,0,0,0,0,0,0
0,0,0,0,0,6,14,0,0,0,0,0,0
0,0,0,0,0,0,0,0,0,0,0,0,0
0,0,0,0,0,0,14,0,0,0,0,0,0
0,0,0,0,0,0,14,7,0,0,0,0,0
0,0,0,0,0,0,14,0,0,0,0,0,0
0,0,0,0,0,0,0,0,0,0,0,0,0
0,0,0,0,0,0,0,0,0,0,0,0,0
0,0,0,0,0,6,14,0,0,0,0,0,0
0,0,0,0,0,6,14,0,0,0,0,0,0
0,0,0,0,0,0,0,0,0,0,0,0,0
endlayer

