
# Created by Ruins mod version 13.8 Ingame Parser
# authoring Player: OneWolfe

weight=4
embed_into_distance=50
#random_height_offset=30
acceptable_target_blocks=
unacceptable_target_blocks=
dimensions=18,31,13
allowable_overhang=4
max_leveling=8
leveling_buffer=0
preserve_water=0
preserve_lava=0

rule1=0,100,preserveBlock
rule2=0,100,terrafirmacraft:StoneMMSmooth-4
rule3=0,100,MobSpawner:skeletonTFC,MobSpawner:blazeTFC,MobSpawner:pigZombieTFC,MobSpawner:zombieTFC,MobSpawner:TwilightForest.Helmet Crab,MobSpawner:TwilightForest.Ice Crystal,MobSpawner:TwilightForest.Twilight Wraith
rule4=0,100,air,air,Steamcraft:engineering-0
rule5=0,100,air,Steamcraft:steamTank-0,Steamcraft:steamTank-0,Steamcraft:pipe-0
rule6=0,100,Steamcraft:valvePipe-1
rule7=0,100,Steamcraft:pipe-0
rule8=0,100,minecraft:ladder-5,air
rule9=0,100,BiblioCraft:BiblioDesk-1,BiblioCraft:BiblioDesk-1,air
rule10=2,100,air
rule11=0,100,ArchimedesShips:seat-1,ArchimedesShips:seat-1,air
rule12=0,100,air,BiblioCraft:Printing Press-0,BiblioCraft:Printing Press-0
rule13=0,100,air,air,air,minecraft:glass-0
rule14=0,100,Steamcraft:valvePipe-3,Steamcraft:valvePipe-3,air
rule15=0,100,Steamcraft:valvePipe-2,Steamcraft:valvePipe-2,air
rule16=0,100,minecraft:iron_door-2,minecraft:iron_door-2,minecraft:iron_door-2,minecraft:iron_door-2,air
rule17=0,100,minecraft:bed-9,minecraft:bed-9,minecraft:bed-9,air
rule18=0,100,minecraft:bed-1,minecraft:bed-1,air
rule19=0,100,terrafirmacraft:WoodSupportV-12
rule20=0,100,minecraft:bed-3,minecraft:bed-3,air
rule21=0,100,minecraft:bed-11,minecraft:bed-11,minecraft:bed-11,air
rule22=0,100,minecraft:iron_door-0,minecraft:iron_door-0,minecraft:iron_door-0,minecraft:iron_door-0,air
rule23=0,100,air
rule24=0,100,BiblioCraft:BiblioTypewriter-4,BiblioCraft:BiblioTypewriter-2,BiblioCraft:BiblioTypewriter-3,air
rule25=0,100,BiblioCraft:BiblioShelf-1,BiblioCraft:BiblioShelf-1,air
rule26=0,100,BiblioCraft:BiblioCase-1,BiblioCraft:BiblioCase-1,BiblioCraft:BiblioCase-1,air
rule27=2,100,minecraft:stone_button-2,minecraft:stone_button-2,minecraft:stone_button-2,air
rule28=0,100,minecraft:iron_door-8,minecraft:iron_door-8,minecraft:iron_door-8,air
rule29=2,100,minecraft:stone_button-1,minecraft:stone_button-1,minecraft:stone_button-1,air
rule30=0,100,BiblioCraft:BiblioClock-1,BiblioCraft:BiblioClock-2,BiblioCraft:BiblioClock-3,BiblioCraft:BiblioClock-4,air
rule31=0,100,Steamcraft:valvePipe-0,Steamcraft:valvePipe-0,Steamcraft:valvePipe-0,Steamcraft:valvePipe-0,air
rule32=0,100,minecraft:trapdoor-3,air,air,air
rule33=0,100,air

layer
1,1,1,1,1,1,1,1,1,1,1,1,1
1,1,1,1,1,1,1,1,1,1,1,1,1
1,1,1,1,1,1,2,1,1,1,1,1,1
1,1,1,1,1,1,2,1,1,1,1,1,1
1,1,1,1,1,1,2,1,1,1,1,1,1
1,1,1,1,1,1,1,1,1,1,1,1,1
1,1,1,1,1,1,1,1,1,1,1,1,1
1,1,1,1,1,1,1,1,1,1,1,1,1
1,1,1,1,1,1,1,1,1,1,1,1,1
1,1,1,1,1,1,1,1,1,1,1,1,1
1,1,1,1,1,1,1,1,1,1,1,1,1
1,1,1,1,1,1,1,1,1,1,1,1,1
1,1,1,1,1,1,1,1,1,1,1,1,1
1,1,1,1,1,1,1,1,1,1,1,1,1
1,1,1,1,1,1,1,1,1,1,1,1,1
1,1,1,1,1,1,1,1,1,1,1,1,1
1,1,1,1,1,1,1,1,1,1,1,1,1
1,1,1,1,1,1,1,1,1,1,1,1,1
1,1,1,1,1,1,1,1,1,1,1,1,1
1,1,1,1,1,1,1,1,1,1,1,1,1
1,1,1,1,1,1,1,1,1,1,1,1,1
1,1,1,1,1,1,1,1,1,1,1,1,1
1,1,1,1,1,1,1,1,1,1,1,1,1
1,1,1,1,1,1,1,1,1,1,1,1,1
1,1,1,1,1,1,1,1,1,1,1,1,1
1,1,1,1,1,1,1,1,1,1,1,1,1
1,1,1,1,1,1,1,1,1,1,1,1,1
1,1,1,1,1,1,1,1,1,1,1,1,1
1,1,1,1,1,1,1,1,1,1,1,1,1
1,1,1,1,1,1,1,1,1,1,1,1,1
1,1,1,1,1,1,1,1,1,1,1,1,1
endlayer

layer
1,1,1,1,1,1,1,1,1,1,1,1,1
1,1,1,1,1,1,1,1,1,1,1,1,1
1,1,1,1,1,1,1,1,1,1,1,1,1
1,1,1,1,1,1,1,1,1,1,1,1,1
1,1,1,1,1,1,2,1,1,1,1,1,1
1,1,1,1,1,1,2,1,1,1,1,1,1
1,1,1,1,1,1,1,1,1,1,1,1,1
1,1,1,1,1,1,1,1,1,1,1,1,1
1,1,1,1,1,1,1,1,1,1,1,1,1
1,1,1,1,1,1,1,1,1,1,1,1,1
1,1,1,1,1,1,1,1,1,1,1,1,1
1,1,1,1,1,1,1,1,1,1,1,1,1
1,1,1,1,1,1,1,1,1,1,1,1,1
1,1,1,1,1,1,1,1,1,1,1,1,1
1,1,1,1,1,1,1,1,1,1,1,1,1
1,1,1,1,1,1,1,1,1,1,1,1,1
1,1,1,1,1,1,1,1,1,1,1,1,1
1,1,1,1,1,1,1,1,1,1,1,1,1
1,1,1,1,1,1,1,1,1,1,1,1,1
1,1,1,1,1,1,1,1,1,1,1,1,1
1,1,1,1,1,1,1,1,1,1,1,1,1
1,1,1,1,1,1,1,1,1,1,1,1,1
1,1,1,1,1,1,1,1,1,1,1,1,1
1,1,1,1,1,1,1,1,1,1,1,1,1
1,1,1,1,1,1,1,1,1,1,1,1,1
1,1,1,1,1,1,1,1,1,1,1,1,1
1,1,1,1,1,1,1,1,1,1,1,1,1
1,1,1,1,1,1,1,1,1,1,1,1,1
1,1,1,1,1,1,1,1,1,1,1,1,1
1,1,1,1,1,1,1,1,1,1,1,1,1
1,1,1,1,1,1,1,1,1,1,1,1,1
endlayer

layer
1,1,1,1,1,1,1,1,1,1,1,1,1
1,1,1,1,1,1,1,1,1,1,1,1,1
1,1,1,1,1,1,1,1,1,1,1,1,1
1,1,1,1,1,1,1,1,1,1,1,1,1
1,1,1,1,1,1,2,1,1,1,1,1,1
1,1,1,1,1,1,2,1,1,1,1,1,1
1,1,1,1,1,1,2,1,1,1,1,1,1
1,1,1,1,1,1,2,1,1,1,1,1,1
1,1,1,1,1,1,2,1,1,1,1,1,1
1,1,1,1,1,1,1,1,1,1,1,1,1
1,1,1,1,1,1,1,1,1,1,1,1,1
1,1,1,1,1,1,1,1,1,1,1,1,1
1,1,1,1,1,1,1,1,1,1,1,1,1
1,1,1,1,1,1,1,1,1,1,1,1,1
1,1,1,1,1,1,1,1,1,1,1,1,1
1,1,1,1,1,1,1,1,1,1,1,1,1
1,1,1,1,1,1,1,1,1,1,1,1,1
1,1,1,1,1,1,1,1,1,1,1,1,1
1,1,1,1,1,1,1,1,1,1,1,1,1
1,1,1,1,1,1,1,1,1,1,1,1,1
1,1,1,1,1,1,1,1,1,1,1,1,1
1,1,1,1,1,1,1,1,1,1,1,1,1
1,1,1,1,1,1,1,1,1,1,1,1,1
1,1,1,1,1,1,1,1,1,1,1,1,1
1,1,1,1,1,1,1,1,1,1,1,1,1
1,1,1,1,1,1,1,1,1,1,1,1,1
1,1,1,1,1,1,1,1,1,1,1,1,1
1,1,1,1,1,1,1,1,1,1,1,1,1
1,1,1,1,1,1,1,1,1,1,1,1,1
1,1,1,1,1,1,1,1,1,1,1,1,1
1,1,1,1,1,1,1,1,1,1,1,1,1
endlayer

layer
1,1,1,1,1,1,1,1,1,1,1,1,1
1,1,1,1,1,1,1,1,1,1,1,1,1
1,1,1,1,1,1,1,1,1,1,1,1,1
1,1,1,1,1,2,2,2,1,1,1,1,1
1,1,1,1,1,2,33,2,1,1,1,1,1
1,1,1,1,1,2,3,2,1,1,1,1,1
1,1,1,1,1,2,33,2,1,1,1,1,1
1,1,1,1,1,2,2,2,1,1,1,1,1
1,1,1,1,1,2,2,2,1,1,1,1,1
1,1,1,1,1,2,2,2,1,1,1,1,1
1,1,1,1,1,2,2,2,1,1,1,1,1
1,1,1,1,1,2,2,2,1,1,1,1,1
1,1,1,1,1,2,2,2,1,1,1,1,1
1,1,1,1,1,2,2,2,1,1,1,1,1
1,1,1,1,1,2,2,2,1,1,1,1,1
1,1,1,1,1,2,2,2,1,1,1,1,1
1,1,1,1,1,2,2,2,1,1,1,1,1
1,1,1,1,1,2,2,2,1,1,1,1,1
1,1,1,1,1,2,2,2,1,1,1,1,1
1,1,1,1,1,2,2,2,1,1,1,1,1
1,1,1,1,1,2,2,2,1,1,1,1,1
1,1,1,1,1,2,2,2,1,1,1,1,1
1,1,1,1,1,2,2,2,1,1,1,1,1
1,1,1,1,1,2,2,2,1,1,1,1,1
1,1,1,1,1,2,2,2,1,1,1,1,1
1,1,1,1,1,2,2,2,1,1,1,1,1
1,1,1,1,1,2,2,2,1,1,1,1,1
1,1,1,1,1,1,2,1,1,1,1,1,1
1,1,1,1,1,1,1,1,1,1,1,1,1
1,1,1,1,1,1,1,1,1,1,1,1,1
1,1,1,1,1,1,1,1,1,1,1,1,1
endlayer

layer
1,1,1,1,1,1,1,1,1,1,1,1,1
1,1,1,1,1,1,1,1,1,1,1,1,1
1,1,1,1,1,1,2,1,1,1,1,1,1
1,1,1,1,2,2,4,2,2,1,1,1,1
1,1,1,1,2,33,33,33,2,1,1,1,1
1,1,1,1,2,5,33,5,2,1,1,1,1
1,1,1,1,2,33,33,33,2,1,1,1,1
1,1,1,1,2,5,33,5,2,1,1,1,1
1,1,1,1,2,6,33,6,2,1,1,1,1
1,1,1,1,2,7,2,7,2,1,1,1,1
1,1,1,1,2,7,33,7,2,1,1,1,1
1,1,1,1,2,7,33,7,2,1,1,1,1
1,1,1,1,2,7,33,7,2,1,1,1,1
1,1,1,1,2,7,33,7,2,1,1,1,1
1,1,1,1,2,7,33,7,2,1,1,1,1
1,1,1,1,2,7,2,7,2,1,1,1,1
1,1,1,1,2,7,8,7,2,1,1,1,1
1,1,1,1,2,7,3,7,2,1,1,1,1
1,1,1,1,2,7,33,7,2,1,1,1,1
1,1,1,1,2,7,33,7,2,1,1,1,1
1,1,1,1,2,7,33,7,2,1,1,1,1
1,1,1,1,2,2,2,2,2,1,1,1,1
1,1,1,1,2,33,33,9,2,1,1,1,1
1,1,1,1,2,33,10,33,2,1,1,1,1
1,1,1,1,2,33,3,33,2,1,1,1,1
1,1,1,1,2,33,11,33,2,1,1,1,1
1,1,1,1,2,33,12,33,2,1,1,1,1
1,1,1,1,1,13,13,13,1,1,1,1,1
1,1,1,1,1,1,1,1,1,1,1,1,1
1,1,1,1,1,1,1,1,1,1,1,1,1
1,1,1,1,1,1,1,1,1,1,1,1,1
endlayer

layer
1,1,1,1,7,1,1,1,7,1,1,1,1
1,1,1,1,7,1,2,1,7,1,1,1,1
1,1,1,1,7,2,2,2,7,1,1,1,1
1,1,1,2,7,33,33,33,7,2,1,1,1
1,1,1,2,7,33,33,33,7,2,1,1,1
1,1,1,2,7,5,33,5,7,2,1,1,1
1,1,1,2,15,33,33,33,14,2,1,1,1
1,1,1,2,7,5,33,5,7,2,1,1,1
1,1,1,2,33,33,33,33,33,2,1,1,1
1,1,1,2,2,2,16,2,2,2,1,1,1
1,1,1,2,17,33,33,33,17,2,1,1,1
1,1,1,13,18,33,33,33,18,13,1,1,1
1,1,1,2,2,33,33,33,2,2,1,1,1
1,1,1,2,19,33,33,33,19,2,1,1,1
1,1,1,2,33,33,33,33,33,2,1,1,1
1,1,1,13,33,33,2,33,33,13,1,1,1
1,1,1,2,33,33,8,33,33,2,1,1,1
1,1,1,2,19,33,33,33,19,2,1,1,1
1,1,1,2,2,33,33,33,2,2,1,1,1
1,1,1,13,20,33,33,33,20,13,1,1,1
1,1,1,2,21,33,33,33,21,2,1,1,1
1,1,1,2,2,2,22,2,2,2,1,1,1
1,1,1,2,17,33,33,24,23,2,1,1,1
1,1,1,13,18,33,33,33,33,13,1,1,1
1,1,1,2,33,33,33,33,25,2,1,1,1
1,1,1,2,19,33,33,33,19,2,1,1,1
1,1,1,2,25,33,33,33,26,2,1,1,1
1,1,1,1,2,33,33,33,2,1,1,1,1
1,1,1,1,1,13,13,13,1,1,1,1,1
1,1,1,1,1,1,1,1,1,1,1,1,1
1,1,1,1,1,1,1,1,1,1,1,1,1
endlayer

layer
1,1,1,1,1,1,2,1,1,1,1,1,1
1,1,1,1,1,2,2,2,1,1,1,1,1
2,1,1,1,2,33,33,33,2,1,1,1,2
2,1,1,2,33,33,33,33,33,2,1,1,2
2,2,2,33,33,33,33,33,33,33,2,2,2
1,2,2,33,33,5,33,5,33,33,2,2,1
1,1,2,33,33,33,33,33,33,33,2,1,1
1,1,2,33,33,5,33,5,33,33,2,1,1
1,1,2,33,33,33,33,27,33,33,2,1,1
1,1,1,2,2,2,28,2,2,2,1,1,1
1,1,1,2,33,33,33,29,33,2,1,1,1
1,1,1,2,33,33,33,33,33,2,1,1,1
1,1,1,2,2,33,33,33,2,2,1,1,1
1,1,1,2,19,33,33,33,19,2,1,1,1
1,1,1,2,33,33,33,33,33,2,1,1,1
1,1,1,2,33,33,2,33,33,2,1,1,1
1,1,1,2,33,33,8,33,33,2,1,1,1
1,1,1,2,19,33,33,33,19,2,1,1,1
1,1,1,2,2,33,33,33,2,2,1,1,1
1,1,1,2,33,33,33,33,33,2,1,1,1
1,1,1,2,33,33,33,27,33,2,1,1,1
1,1,1,2,2,2,28,2,2,2,1,1,1
1,1,1,2,33,33,33,33,33,2,1,1,1
1,1,1,2,33,33,33,33,33,2,1,1,1
1,1,1,2,33,33,33,33,25,2,1,1,1
1,1,1,2,19,33,33,33,19,2,1,1,1
1,1,1,2,25,33,33,33,30,2,1,1,1
1,1,1,2,2,33,33,33,2,2,1,1,1
1,1,1,1,2,13,33,13,2,1,1,1,1
1,1,1,1,1,1,13,1,1,1,1,1,1
1,1,1,1,1,1,1,1,1,1,1,1,1
endlayer

layer
1,1,1,1,7,1,1,1,7,1,1,1,1
1,1,1,1,7,1,2,1,7,1,1,1,1
1,1,1,1,7,2,2,2,7,1,1,1,1
1,1,1,2,7,33,33,33,7,2,1,1,1
1,1,1,2,7,33,33,33,7,2,1,1,1
1,1,1,2,7,5,33,5,7,2,1,1,1
1,1,1,2,15,33,33,33,14,2,1,1,1
1,1,1,2,7,5,33,5,7,2,1,1,1
1,1,1,2,33,33,33,33,33,2,1,1,1
1,1,1,2,2,2,2,2,2,2,1,1,1
1,1,1,2,17,33,33,33,17,2,1,1,1
1,1,1,13,18,33,33,33,18,13,1,1,1
1,1,1,2,2,33,33,33,2,2,1,1,1
1,1,1,2,19,33,33,33,19,2,1,1,1
1,1,1,2,33,33,33,33,33,2,1,1,1
1,1,1,13,33,33,2,33,33,13,1,1,1
1,1,1,2,33,33,8,33,33,2,1,1,1
1,1,1,2,19,33,33,33,19,2,1,1,1
1,1,1,2,2,33,33,33,2,2,1,1,1
1,1,1,13,20,33,33,33,20,13,1,1,1
1,1,1,2,21,33,33,33,21,2,1,1,1
1,1,1,2,2,2,2,2,2,2,1,1,1
1,1,1,2,33,33,33,33,33,2,1,1,1
1,1,1,13,33,33,33,33,33,13,1,1,1
1,1,1,2,33,33,33,33,25,2,1,1,1
1,1,1,2,19,33,33,33,19,2,1,1,1
1,1,1,2,25,33,33,33,33,2,1,1,1
1,1,1,1,2,33,33,33,2,1,1,1,1
1,1,1,1,1,13,13,13,1,1,1,1,1
1,1,1,1,1,1,1,1,1,1,1,1,1
1,1,1,1,1,1,1,1,1,1,1,1,1
endlayer

layer
1,1,1,1,1,1,1,1,1,1,1,1,1
1,1,1,1,1,1,1,1,1,1,1,1,1
1,1,1,1,1,1,2,1,1,1,1,1,1
1,1,1,1,2,2,33,2,2,1,1,1,1
1,1,1,1,2,33,33,33,2,1,1,1,1
1,1,1,1,2,5,33,5,2,1,1,1,1
1,1,1,1,2,33,33,33,2,1,1,1,1
1,1,1,1,2,5,33,5,2,1,1,1,1
1,1,1,1,2,31,33,31,2,1,1,1,1
1,1,1,1,2,7,2,7,2,1,1,1,1
1,1,1,1,2,33,33,33,2,1,1,1,1
1,1,1,1,2,33,33,33,2,1,1,1,1
1,1,1,1,2,33,33,33,2,1,1,1,1
1,1,1,1,2,33,33,33,2,1,1,1,1
1,1,1,1,2,33,33,33,2,1,1,1,1
1,1,1,1,2,33,2,33,2,1,1,1,1
1,1,1,1,2,33,8,33,2,1,1,1,1
1,1,1,1,2,33,33,33,2,1,1,1,1
1,1,1,1,2,33,33,33,2,1,1,1,1
1,1,1,1,2,33,33,33,2,1,1,1,1
1,1,1,1,2,33,33,33,2,1,1,1,1
1,1,1,1,2,2,2,2,2,1,1,1,1
1,1,1,1,2,33,33,33,2,1,1,1,1
1,1,1,1,2,33,33,33,2,1,1,1,1
1,1,1,1,2,33,33,33,2,1,1,1,1
1,1,1,1,2,33,33,33,2,1,1,1,1
1,1,1,1,2,33,33,33,2,1,1,1,1
1,1,1,1,1,13,13,13,1,1,1,1,1
1,1,1,1,1,1,1,1,1,1,1,1,1
1,1,1,1,1,1,1,1,1,1,1,1,1
1,1,1,1,1,1,1,1,1,1,1,1,1
endlayer

layer
1,1,1,1,1,1,1,1,1,1,1,1,1
1,1,1,1,1,1,1,1,1,1,1,1,1
1,1,1,1,1,1,1,1,1,1,1,1,1
1,1,1,1,1,2,2,2,1,1,1,1,1
1,1,1,1,1,2,2,2,1,1,1,1,1
1,1,1,1,1,2,2,2,1,1,1,1,1
1,1,1,1,1,2,2,2,1,1,1,1,1
1,1,1,1,1,2,2,2,1,1,1,1,1
1,1,1,1,1,2,2,2,1,1,1,1,1
1,1,1,1,1,2,2,2,1,1,1,1,1
1,1,1,1,1,2,2,2,1,1,1,1,1
1,1,1,1,1,2,2,2,1,1,1,1,1
1,1,1,1,1,2,2,2,1,1,1,1,1
1,1,1,1,1,2,2,2,1,1,1,1,1
1,1,1,1,1,2,2,2,1,1,1,1,1
1,1,1,1,1,2,2,2,1,1,1,1,1
1,1,1,1,1,2,8,2,1,1,1,1,1
1,1,1,1,1,2,2,2,1,1,1,1,1
1,1,1,1,1,2,2,2,1,1,1,1,1
1,1,1,1,1,2,2,2,1,1,1,1,1
1,1,1,1,1,2,2,2,1,1,1,1,1
1,1,1,1,1,2,2,2,1,1,1,1,1
1,1,1,1,1,2,2,2,1,1,1,1,1
1,1,1,1,1,2,2,2,1,1,1,1,1
1,1,1,1,1,2,2,2,1,1,1,1,1
1,1,1,1,1,2,2,2,1,1,1,1,1
1,1,1,1,1,2,2,2,1,1,1,1,1
1,1,1,1,1,1,2,1,1,1,1,1,1
1,1,1,1,1,1,1,1,1,1,1,1,1
1,1,1,1,1,1,1,1,1,1,1,1,1
1,1,1,1,1,1,1,1,1,1,1,1,1
endlayer

layer
1,1,1,1,1,1,1,1,1,1,1,1,1
1,1,1,1,1,1,1,1,1,1,1,1,1
1,1,1,1,1,1,1,1,1,1,1,1,1
1,1,1,1,1,1,1,1,1,1,1,1,1
1,1,1,1,1,1,2,1,1,1,1,1,1
1,1,1,1,1,1,2,1,1,1,1,1,1
1,1,1,1,1,1,2,1,1,1,1,1,1
1,1,1,1,1,1,2,1,1,1,1,1,1
1,1,1,1,1,1,2,1,1,1,1,1,1
1,1,1,1,1,1,1,1,1,1,1,1,1
1,1,1,1,1,1,1,1,1,1,1,1,1
1,1,1,1,1,1,1,1,1,1,1,1,1
1,1,1,1,1,1,1,1,1,1,1,1,1
1,1,1,1,1,1,1,1,1,1,1,1,1
1,1,1,1,1,2,1,2,1,1,1,1,1
1,1,1,1,1,2,2,2,1,1,1,1,1
1,1,1,1,1,2,8,2,1,1,1,1,1
1,1,1,1,1,2,2,2,1,1,1,1,1
1,1,1,1,1,2,2,2,1,1,1,1,1
1,1,1,1,1,1,2,1,1,1,1,1,1
1,1,1,1,1,1,1,1,1,1,1,1,1
1,1,1,1,1,1,1,1,1,1,1,1,1
1,1,1,1,1,1,1,1,1,1,1,1,1
1,1,1,1,1,1,1,1,1,1,1,1,1
1,1,1,1,1,1,1,1,1,1,1,1,1
1,1,1,1,1,1,1,1,1,1,1,1,1
1,1,1,1,1,1,1,1,1,1,1,1,1
1,1,1,1,1,1,1,1,1,1,1,1,1
1,1,1,1,1,1,1,1,1,1,1,1,1
1,1,1,1,1,1,1,1,1,1,1,1,1
1,1,1,1,1,1,1,1,1,1,1,1,1
endlayer

layer
1,1,1,1,1,1,1,1,1,1,1,1,1
1,1,1,1,1,1,1,1,1,1,1,1,1
1,1,1,1,1,1,1,1,1,1,1,1,1
1,1,1,1,1,1,1,1,1,1,1,1,1
1,1,1,1,1,1,2,1,1,1,1,1,1
1,1,1,1,1,1,2,1,1,1,1,1,1
1,1,1,1,1,1,1,1,1,1,1,1,1
1,1,1,1,1,1,1,1,1,1,1,1,1
1,1,1,1,1,1,1,1,1,1,1,1,1
1,1,1,1,1,1,1,1,1,1,1,1,1
1,1,1,1,1,1,1,1,1,1,1,1,1
1,1,1,1,1,1,1,1,1,1,1,1,1
1,1,1,1,1,1,1,1,1,1,1,1,1
1,1,1,1,1,1,1,1,1,1,1,1,1
1,1,1,1,1,1,1,1,1,1,1,1,1
1,1,1,1,1,2,2,2,1,1,1,1,1
1,1,1,1,1,2,8,2,1,1,1,1,1
1,1,1,1,1,2,2,2,1,1,1,1,1
1,1,1,1,1,1,2,1,1,1,1,1,1
1,1,1,1,1,1,1,1,1,1,1,1,1
1,1,1,1,1,1,1,1,1,1,1,1,1
1,1,1,1,1,1,1,1,1,1,1,1,1
1,1,1,1,1,1,1,1,1,1,1,1,1
1,1,1,1,1,1,1,1,1,1,1,1,1
1,1,1,1,1,1,1,1,1,1,1,1,1
1,1,1,1,1,1,1,1,1,1,1,1,1
1,1,1,1,1,1,1,1,1,1,1,1,1
1,1,1,1,1,1,1,1,1,1,1,1,1
1,1,1,1,1,1,1,1,1,1,1,1,1
1,1,1,1,1,1,1,1,1,1,1,1,1
1,1,1,1,1,1,1,1,1,1,1,1,1
endlayer

layer
1,1,1,1,1,1,1,1,1,1,1,1,1
1,1,1,1,1,1,1,1,1,1,1,1,1
1,1,1,1,1,1,2,1,1,1,1,1,1
1,1,1,1,1,1,2,1,1,1,1,1,1
1,1,1,1,1,1,2,1,1,1,1,1,1
1,1,1,1,1,1,1,1,1,1,1,1,1
1,1,1,1,1,1,1,1,1,1,1,1,1
1,1,1,1,1,1,1,1,1,1,1,1,1
1,1,1,1,1,1,1,1,1,1,1,1,1
1,1,1,1,1,1,1,1,1,1,1,1,1
1,1,1,1,1,1,1,1,1,1,1,1,1
1,1,1,1,1,1,1,1,1,1,1,1,1
1,1,1,1,1,1,1,1,1,1,1,1,1
1,1,1,1,1,1,1,1,1,1,1,1,1
1,1,1,1,1,1,1,1,1,1,1,1,1
1,1,1,1,1,1,2,1,1,1,1,1,1
1,1,1,1,1,2,8,2,1,1,1,1,1
1,1,1,1,1,1,2,1,1,1,1,1,1
1,1,1,1,1,1,1,1,1,1,1,1,1
1,1,1,1,1,1,1,1,1,1,1,1,1
1,1,1,1,1,1,1,1,1,1,1,1,1
1,1,1,1,1,1,1,1,1,1,1,1,1
1,1,1,1,1,1,1,1,1,1,1,1,1
1,1,1,1,1,1,1,1,1,1,1,1,1
1,1,1,1,1,1,1,1,1,1,1,1,1
1,1,1,1,1,1,1,1,1,1,1,1,1
1,1,1,1,1,1,1,1,1,1,1,1,1
1,1,1,1,1,1,1,1,1,1,1,1,1
1,1,1,1,1,1,1,1,1,1,1,1,1
1,1,1,1,1,1,1,1,1,1,1,1,1
1,1,1,1,1,1,1,1,1,1,1,1,1
endlayer

layer
1,1,1,1,1,1,1,1,1,1,1,1,1
1,1,1,1,1,1,1,1,1,1,1,1,1
1,1,1,1,1,1,1,1,1,1,1,1,1
1,1,1,1,1,1,1,1,1,1,1,1,1
1,1,1,1,1,1,1,1,1,1,1,1,1
1,1,1,1,1,1,1,1,1,1,1,1,1
1,1,1,1,1,1,1,1,1,1,1,1,1
1,1,1,1,1,1,1,1,1,1,1,1,1
1,1,1,1,1,1,1,1,1,1,1,1,1
1,1,1,1,1,1,1,1,1,1,1,1,1
1,1,1,1,1,1,1,1,1,1,1,1,1
1,1,1,1,1,1,1,1,1,1,1,1,1
1,1,1,1,1,1,1,1,1,1,1,1,1
1,1,1,1,1,1,1,1,1,1,1,1,1
1,1,1,1,1,1,1,1,1,1,1,1,1
1,1,1,1,1,1,2,1,1,1,1,1,1
1,1,1,1,1,2,8,2,1,1,1,1,1
1,1,1,1,1,1,2,1,1,1,1,1,1
1,1,1,1,1,1,1,1,1,1,1,1,1
1,1,1,1,1,1,1,1,1,1,1,1,1
1,1,1,1,1,1,1,1,1,1,1,1,1
1,1,1,1,1,1,1,1,1,1,1,1,1
1,1,1,1,1,1,1,1,1,1,1,1,1
1,1,1,1,1,1,1,1,1,1,1,1,1
1,1,1,1,1,1,1,1,1,1,1,1,1
1,1,1,1,1,1,1,1,1,1,1,1,1
1,1,1,1,1,1,1,1,1,1,1,1,1
1,1,1,1,1,1,1,1,1,1,1,1,1
1,1,1,1,1,1,1,1,1,1,1,1,1
1,1,1,1,1,1,1,1,1,1,1,1,1
1,1,1,1,1,1,1,1,1,1,1,1,1
endlayer

layer
1,1,1,1,1,1,1,1,1,1,1,1,1
1,1,1,1,1,1,1,1,1,1,1,1,1
1,1,1,1,1,1,1,1,1,1,1,1,1
1,1,1,1,1,1,1,1,1,1,1,1,1
1,1,1,1,1,1,1,1,1,1,1,1,1
1,1,1,1,1,1,1,1,1,1,1,1,1
1,1,1,1,1,1,1,1,1,1,1,1,1
1,1,1,1,1,1,1,1,1,1,1,1,1
1,1,1,1,1,1,1,1,1,1,1,1,1
1,1,1,1,1,1,1,1,1,1,1,1,1
1,1,1,1,1,1,1,1,1,1,1,1,1
1,1,1,1,1,1,1,1,1,1,1,1,1
1,1,1,1,1,1,1,1,1,1,1,1,1
1,1,1,1,1,1,1,1,1,1,1,1,1
1,1,1,1,1,1,1,1,1,1,1,1,1
1,1,1,1,1,1,2,1,1,1,1,1,1
1,1,1,1,1,1,32,1,1,1,1,1,1
1,1,1,1,1,1,1,1,1,1,1,1,1
1,1,1,1,1,1,1,1,1,1,1,1,1
1,1,1,1,1,1,1,1,1,1,1,1,1
1,1,1,1,1,1,1,1,1,1,1,1,1
1,1,1,1,1,1,1,1,1,1,1,1,1
1,1,1,1,1,1,1,1,1,1,1,1,1
1,1,1,1,1,1,1,1,1,1,1,1,1
1,1,1,1,1,1,1,1,1,1,1,1,1
1,1,1,1,1,1,1,1,1,1,1,1,1
1,1,1,1,1,1,1,1,1,1,1,1,1
1,1,1,1,1,1,1,1,1,1,1,1,1
1,1,1,1,1,1,1,1,1,1,1,1,1
1,1,1,1,1,1,1,1,1,1,1,1,1
1,1,1,1,1,1,1,1,1,1,1,1,1
endlayer

layer
1,1,1,1,1,1,1,1,1,1,1,1,1
1,1,1,1,1,1,1,1,1,1,1,1,1
1,1,1,1,1,1,1,1,1,1,1,1,1
1,1,1,1,1,1,1,1,1,1,1,1,1
1,1,1,1,1,1,1,1,1,1,1,1,1
1,1,1,1,1,1,1,1,1,1,1,1,1
1,1,1,1,1,1,1,1,1,1,1,1,1
1,1,1,1,1,1,1,1,1,1,1,1,1
1,1,1,1,1,1,1,1,1,1,1,1,1
1,1,1,1,1,1,1,1,1,1,1,1,1
1,1,1,1,1,1,1,1,1,1,1,1,1
1,1,1,1,1,1,1,1,1,1,1,1,1
1,1,1,1,1,1,1,1,1,1,1,1,1
1,1,1,1,1,1,1,1,1,1,1,1,1
1,1,1,1,1,1,1,1,1,1,1,1,1
1,1,1,1,1,1,2,1,1,1,1,1,1
1,1,1,1,1,1,1,1,1,1,1,1,1
1,1,1,1,1,1,1,1,1,1,1,1,1
1,1,1,1,1,1,1,1,1,1,1,1,1
1,1,1,1,1,1,1,1,1,1,1,1,1
1,1,1,1,1,1,1,1,1,1,1,1,1
1,1,1,1,1,1,1,1,1,1,1,1,1
1,1,1,1,1,1,1,1,1,1,1,1,1
1,1,1,1,1,1,1,1,1,1,1,1,1
1,1,1,1,1,1,1,1,1,1,1,1,1
1,1,1,1,1,1,1,1,1,1,1,1,1
1,1,1,1,1,1,1,1,1,1,1,1,1
1,1,1,1,1,1,1,1,1,1,1,1,1
1,1,1,1,1,1,1,1,1,1,1,1,1
1,1,1,1,1,1,1,1,1,1,1,1,1
1,1,1,1,1,1,1,1,1,1,1,1,1
endlayer





