
# Created by Ruins mod version 13.8 Ingame Parser
# authoring Player: OneWolfe

weight=1
unique=1
embed_into_distance=3
biomesToSpawnIn=rolling hills,forest,high hills
acceptable_target_blocks=
unacceptable_target_blocks=flowing_water,water,flowing_lava,lava,terrafirmacraft:SaltWaterStationary-0,terrafirmacraft:SaltWaterStationary-8,terrafirmacraft:FreshWaterStationary-0,terrafirmacraft:FreshWaterStationary-8
dimensions=34,15,15
allowable_overhang=4
max_leveling=6
leveling_buffer=2
preserve_water=0
preserve_lava=0

rule1=0,100,air,terrafirmacraft:StoneIgEx-2
rule2=0,100,Railcraft:frame-0
rule3=0,100,air,Steamcraft:steamTank-0
rule4=0,100,Steamcraft:pipe-0
rule5=0,100,air,terrafirmacraft:planks-1,terrafirmacraft:planks-1,terrafirmacraft:planks-1
rule6=0,100,minecraft:stone_pressure_plate-0
rule7=0,100,air
rule8=0,100,minecraft:stone_brick_stairs-2
rule9=0,100,air,minecraft:stone_brick_stairs-1
rule10=0,100,air,air,MobSpawner:spiderTFC
rule11=0,100,Steamcraft:fan-3
rule12=0,100,air,air,MobSpawner:caveSpiderTFC
rule13=0,100,air,air,air,ChestGenHook:dungeonChest:5-2,ChestGenHook:dungeonChest:5-2,MobSpawner:TwilightForest.King Spider
rule14=0,100,air,Steamcraft:boilerOn-5
rule15=0,100,air,air,Steamcraft:fan-5
rule16=0,100,air,Steamcraft:valvePipe-5

layer
1,1,1,1,1,1,1,1,1,1,1,1,1,1,1
1,2,2,2,2,2,2,2,2,2,2,2,2,2,1
1,2,1,1,1,1,1,1,1,1,1,1,1,2,0
1,2,1,3,4,3,3,0,0,0,0,0,1,2,1
1,2,1,0,0,3,3,0,0,0,0,0,1,2,1
1,2,1,0,0,0,0,0,0,0,0,0,1,2,1
1,2,1,0,0,0,0,0,0,0,0,0,1,2,1
1,2,1,0,0,0,0,0,0,0,0,0,1,2,1
1,2,1,0,0,0,0,0,0,0,0,0,1,2,1
1,2,1,0,0,0,0,0,0,0,0,0,1,2,1
1,2,1,0,0,0,0,0,0,0,0,0,1,2,1
1,2,1,0,0,0,0,0,0,0,0,0,1,2,1
1,2,1,1,1,1,1,1,1,1,1,1,1,2,1
1,2,2,2,2,2,2,2,2,2,2,2,2,2,1
1,1,1,1,1,1,1,1,1,1,1,1,1,0,1
endlayer

layer
1,1,1,1,1,1,1,1,1,1,1,1,1,1,1
1,2,1,1,1,1,1,1,1,1,1,1,1,2,1
1,1,1,1,1,1,1,1,1,1,1,1,1,1,0
1,1,1,4,5,5,5,5,5,5,5,5,1,1,1
1,1,1,5,5,5,5,5,5,5,5,5,1,1,1
1,1,1,5,5,5,5,5,5,5,5,5,1,1,1
1,1,1,5,5,5,5,5,5,5,5,5,1,1,1
1,1,1,5,5,5,5,5,5,5,5,5,1,1,1
1,1,1,5,5,5,5,5,5,5,5,5,1,1,1
1,1,1,5,5,5,5,5,5,5,5,5,1,1,1
1,1,1,5,5,5,5,5,5,5,5,5,1,1,1
1,1,1,5,5,5,5,5,5,5,5,5,1,1,1
1,1,1,1,1,1,1,1,1,1,1,1,1,1,1
0,2,1,1,1,1,1,1,1,1,1,1,1,2,1
1,1,1,1,1,1,1,1,1,1,1,1,1,0,1
endlayer

layer
1,1,1,0,0,0,6,6,6,0,0,0,1,0,1
1,2,1,0,0,0,0,0,0,0,0,0,1,2,1
1,1,1,0,0,0,6,6,6,0,0,0,1,0,0
0,0,0,4,0,0,7,0,0,7,7,0,0,0,0
0,0,0,0,0,0,0,0,0,0,0,0,0,0,0
0,7,0,0,0,0,0,0,0,0,0,0,0,0,0
6,0,6,7,0,0,0,0,0,0,7,0,6,0,6
6,7,6,0,7,7,0,0,0,0,0,0,6,0,6
6,0,6,0,7,7,0,0,7,0,0,0,6,0,6
7,0,0,0,0,0,0,0,0,0,0,0,7,0,0
7,0,0,0,0,0,0,8,0,0,0,0,0,0,0
0,0,0,0,0,0,0,8,0,0,0,0,0,0,0
1,1,1,0,0,0,6,6,6,7,0,0,1,1,1
0,2,1,0,0,0,0,7,0,0,7,0,1,2,1
1,1,1,0,0,0,6,6,6,0,0,0,1,0,1
endlayer

layer
1,1,1,0,0,0,0,0,0,0,0,0,1,0,1
1,2,1,0,0,0,0,0,0,0,0,0,1,2,0
1,1,1,0,0,0,7,0,0,0,0,0,1,0,0
0,0,0,4,0,0,0,0,0,0,0,0,0,0,0
0,0,0,0,0,0,0,0,0,0,0,0,0,0,0
0,0,0,0,0,0,0,0,0,0,0,0,0,0,0
0,0,0,0,0,0,0,0,0,0,0,0,0,0,0
7,0,0,0,0,0,0,0,0,7,0,0,7,0,0
0,0,0,0,0,0,0,0,0,0,0,0,0,0,0
0,0,0,0,0,0,0,0,0,0,0,0,0,0,0
0,0,0,0,0,0,8,7,7,0,0,0,0,0,0
0,0,0,0,0,0,8,0,0,0,0,0,0,0,0
1,1,1,0,0,0,0,0,0,0,0,0,1,1,1
0,2,1,0,0,0,0,0,0,0,0,0,1,2,0
0,1,1,0,0,0,0,0,0,0,0,0,1,0,1
endlayer

layer
1,1,1,0,0,0,0,0,0,0,0,0,1,0,1
1,2,1,0,0,0,0,0,0,0,0,0,1,2,0
1,1,0,0,0,0,0,0,0,0,0,0,0,0,0
0,0,0,4,0,0,0,0,0,0,0,0,0,0,0
0,0,0,0,0,0,0,0,0,0,0,0,0,0,0
0,0,0,0,0,0,0,0,0,0,0,0,0,0,0
0,0,0,0,0,0,0,0,0,0,0,0,0,0,0
0,0,0,0,0,0,0,0,0,0,0,0,0,0,0
0,0,0,0,0,0,0,0,0,0,0,0,0,0,0
0,0,0,0,0,0,0,0,0,0,0,0,0,0,0
0,0,0,5,5,8,7,0,0,0,0,0,0,0,0
0,0,0,5,5,8,0,0,0,0,0,0,0,0,0
1,1,0,0,0,0,0,0,0,0,0,0,0,1,1
0,2,0,0,0,0,0,0,0,0,0,0,1,2,0
0,1,1,0,0,0,0,0,0,0,0,0,1,0,1
endlayer

layer
1,1,1,0,0,0,0,0,0,0,0,0,1,1,1
1,2,1,0,0,0,0,0,0,0,0,0,1,2,0
1,1,1,0,0,0,0,0,0,0,0,0,1,1,0
0,0,0,4,4,4,4,4,4,4,4,4,0,0,0
0,0,0,0,0,0,0,0,0,0,0,0,0,0,0
0,0,0,0,0,0,0,0,0,0,0,0,0,0,0
0,0,0,0,0,0,0,0,0,0,0,0,0,0,0
0,0,0,0,0,0,0,0,0,0,0,0,0,0,0
0,0,0,0,0,0,0,0,0,0,0,0,0,0,0
0,0,0,9,9,0,0,0,0,0,0,0,0,0,0
0,0,0,0,0,0,0,0,0,0,0,0,0,0,0
0,0,0,0,0,0,7,0,0,0,0,0,0,0,0
1,1,1,0,0,0,0,0,0,0,0,0,1,1,1
0,2,1,0,0,0,0,0,0,0,0,0,1,2,0
0,1,0,0,0,0,0,0,0,0,0,0,1,0,1
endlayer

layer
1,1,1,1,1,1,1,1,1,1,1,1,1,0,1
1,2,2,2,2,2,2,2,2,2,2,2,2,2,0
1,2,1,1,1,1,1,1,1,1,1,1,1,2,1
1,2,1,5,5,5,5,5,5,5,5,4,1,2,1
1,2,1,5,5,5,5,5,5,5,5,5,1,2,1
1,2,1,5,5,5,5,5,5,5,5,5,1,2,1
1,2,1,5,5,5,5,5,5,5,5,5,1,2,1
1,2,1,5,5,5,5,10,5,5,5,5,1,2,1
1,2,1,9,9,5,5,5,5,5,5,5,1,2,1
1,2,1,0,0,5,5,5,5,5,5,5,1,2,1
1,2,1,0,0,0,0,5,5,5,5,5,1,2,1
1,2,1,0,0,7,0,5,5,5,5,5,1,2,1
1,2,1,1,1,1,1,1,1,1,1,1,1,2,1
0,2,2,2,2,2,2,2,2,2,2,2,2,2,0
0,1,1,1,1,1,0,0,0,1,1,1,1,0,1
endlayer

layer
1,1,1,0,0,0,0,0,0,0,0,0,1,1,1
1,2,1,0,0,0,0,0,0,0,0,0,0,2,0
0,0,1,0,0,0,0,7,7,0,0,0,1,1,1
0,0,0,0,0,7,0,0,0,0,0,4,0,0,0
0,0,0,0,0,7,0,0,0,0,0,0,0,0,0
0,0,0,0,0,0,0,7,7,0,7,0,0,0,0
0,0,0,0,7,0,0,0,0,7,7,0,0,0,0
0,7,0,0,7,7,0,0,0,0,0,0,0,0,0
0,0,7,0,0,0,0,0,0,7,0,0,0,0,0
0,0,7,0,0,0,0,0,0,0,7,0,0,0,0
0,0,0,0,0,0,0,0,8,0,0,0,0,0,0
0,0,0,0,0,0,0,0,8,0,7,0,0,0,0
0,1,1,0,7,7,0,0,0,0,0,0,1,1,1
0,2,1,0,0,7,0,7,7,0,0,0,1,2,0
0,0,1,0,0,0,0,0,0,0,0,0,1,1,1
endlayer

layer
1,0,1,0,0,0,0,0,0,0,0,0,1,0,1
0,2,1,0,0,0,0,0,0,0,0,0,1,2,0
0,0,0,0,0,0,0,0,0,0,0,0,1,1,1
0,0,0,0,0,0,0,0,0,0,0,4,0,0,0
0,0,0,0,0,0,0,0,0,0,0,0,0,0,0
0,0,0,0,0,0,0,0,0,0,0,0,0,0,0
0,0,0,0,0,7,0,0,0,0,0,0,0,0,0
0,7,0,0,0,0,0,0,0,0,0,0,0,0,0
0,0,0,0,0,0,0,0,0,0,0,0,0,0,0
0,0,0,0,0,0,0,0,0,0,0,0,0,0,0
0,0,0,0,0,0,0,8,0,0,0,0,0,0,0
0,0,0,0,0,0,0,8,0,0,0,0,0,0,0
0,1,1,0,0,0,0,0,0,0,0,0,1,1,1
0,2,1,0,0,0,0,0,0,0,0,0,1,2,0
0,0,1,0,0,0,0,0,0,0,0,0,1,1,0
endlayer

layer
1,0,1,0,0,0,0,0,0,0,0,0,1,0,1
0,2,1,0,0,0,0,0,0,0,0,0,1,2,0
0,0,0,0,0,0,0,0,0,0,0,0,0,1,1
0,0,0,0,0,0,0,0,0,0,0,4,0,0,0
0,0,0,0,0,0,0,0,0,0,0,0,0,0,0
0,0,0,0,0,0,0,0,0,0,0,0,0,0,0
0,7,0,0,0,0,0,0,0,0,0,0,0,0,0
0,0,0,0,0,0,0,0,0,0,0,0,0,0,0
0,0,0,0,0,0,0,0,0,0,0,0,0,0,0
0,0,7,0,0,0,0,7,0,7,0,0,0,0,0
0,0,0,0,0,0,8,0,0,0,0,0,0,0,0
0,0,0,0,0,0,8,0,0,0,0,0,0,0,0
0,1,0,0,0,0,0,0,0,0,0,0,0,1,1
0,2,1,0,0,0,0,0,0,0,0,0,1,2,0
0,0,1,0,0,0,0,0,0,0,0,0,1,1,0
endlayer

layer
1,0,1,0,0,0,0,0,0,0,0,0,1,0,1
0,2,1,0,0,0,0,0,0,0,0,0,0,2,0
0,0,0,0,0,0,0,0,0,0,0,0,1,1,0
0,0,0,0,0,0,0,0,0,0,0,4,0,0,0
0,0,0,0,0,0,0,0,0,0,0,0,0,0,0
0,7,0,0,0,7,0,0,0,0,0,0,0,0,0
0,0,0,0,0,0,7,0,0,0,0,0,0,0,0
0,0,0,0,0,0,7,0,0,0,0,0,0,0,0
0,0,0,0,0,0,0,0,0,0,0,0,0,0,0
0,0,0,0,0,0,0,0,0,0,0,0,0,0,0
0,0,0,5,5,8,0,0,0,0,0,0,0,0,0
0,0,0,5,5,8,0,0,0,0,0,0,0,0,0
0,1,1,0,0,0,0,0,0,0,0,0,1,1,1
0,2,1,0,0,0,0,0,0,0,0,0,1,2,0
0,0,1,0,0,0,0,0,0,0,0,0,1,1,0
endlayer

layer
1,0,1,0,0,0,0,0,0,0,0,0,1,0,1
0,2,1,0,0,0,0,0,0,0,0,0,1,2,0
0,0,1,0,0,0,0,0,0,0,0,0,1,1,1
0,0,0,0,0,0,0,0,0,0,0,4,0,0,0
0,0,0,0,0,0,0,0,0,0,0,0,0,0,0
0,0,0,0,0,0,0,0,0,0,0,0,0,0,0
0,0,0,0,0,0,0,0,0,0,0,0,0,0,0
0,0,0,0,0,0,0,0,0,0,0,0,0,0,0
0,0,0,0,0,0,0,0,0,0,0,0,0,0,0
0,0,0,9,9,0,0,0,0,0,0,0,0,0,0
0,0,0,0,0,0,7,0,0,0,0,0,0,0,0
0,0,0,0,0,0,0,0,0,0,0,0,0,0,0
0,1,1,0,0,0,0,0,0,0,0,0,1,1,0
0,2,1,0,0,0,0,0,0,0,0,0,1,2,0
0,0,1,0,0,0,0,0,0,0,0,0,1,1,0
endlayer

layer
1,0,1,0,0,0,0,0,0,0,0,0,1,0,1
1,2,1,0,0,0,0,0,0,0,0,0,1,2,0
1,1,1,0,0,0,0,0,0,0,0,0,1,1,1
0,0,0,0,0,0,0,0,0,0,11,4,0,0,0
0,0,0,0,0,0,0,0,0,0,0,4,0,0,0
0,0,0,0,0,0,0,0,0,0,0,4,0,0,0
0,0,0,0,0,0,0,0,0,0,0,4,0,0,0
0,0,0,0,0,0,0,0,0,0,0,4,0,0,0
0,0,0,9,9,0,0,0,0,0,0,4,0,0,0
0,0,0,0,0,0,0,0,0,0,0,4,0,0,0
0,0,0,0,0,0,0,0,0,0,0,4,0,0,0
0,0,0,0,0,0,0,0,0,0,0,4,0,0,0
0,1,1,0,0,0,0,0,0,0,0,0,1,0,0
0,2,1,0,0,0,0,0,0,0,0,0,1,2,0
0,0,1,0,0,0,0,0,0,0,0,0,1,0,0
endlayer

layer
1,1,1,1,1,1,1,1,1,1,1,1,1,1,1
1,2,2,2,2,2,2,2,2,2,2,2,2,2,0
1,2,1,1,1,1,1,1,1,1,1,1,1,2,1
1,2,1,5,5,5,5,5,5,5,5,5,1,2,1
1,2,1,5,5,5,5,5,5,5,5,5,1,2,1
1,2,1,5,5,5,5,5,5,5,5,5,1,2,1
1,2,1,5,5,5,5,5,5,5,5,5,1,2,0
1,2,1,9,9,5,5,12,5,5,5,5,0,7,0
1,2,1,0,0,5,5,5,5,5,5,5,0,0,0
1,2,1,0,0,5,5,5,5,5,5,5,0,0,0
1,2,1,0,0,0,0,5,5,5,5,5,1,2,0
1,2,1,0,7,0,0,5,5,5,5,5,1,2,0
1,2,1,1,1,1,1,1,1,1,1,1,1,2,0
0,2,2,2,2,2,2,2,2,2,2,2,2,2,0
0,0,1,1,1,1,1,1,1,1,1,1,0,0,0
endlayer

layer
1,1,1,0,0,0,0,0,0,0,0,0,1,1,1
1,2,1,0,0,0,0,0,0,0,0,0,1,2,0
1,1,1,0,0,0,0,0,0,0,0,0,1,1,1
0,0,0,0,0,0,0,0,0,0,0,4,0,0,0
0,0,0,0,0,0,0,0,0,0,0,0,0,0,0
0,0,0,0,0,0,0,0,0,0,0,0,0,0,0
0,0,0,0,0,0,0,0,0,0,0,0,0,0,0
0,0,0,0,0,7,7,0,0,0,0,0,0,0,0
0,0,7,0,0,0,0,0,0,0,0,0,0,0,0
0,0,0,0,0,0,0,0,0,0,0,0,0,0,0
0,0,0,0,0,0,0,0,8,0,0,0,0,0,0
0,0,0,7,7,0,0,0,0,0,0,0,0,0,0
1,1,1,0,7,0,0,0,0,0,0,0,0,0,0
0,2,1,0,0,0,0,0,0,0,0,0,0,2,0
0,0,0,0,0,0,0,0,0,0,0,0,0,0,0
endlayer

layer
1,1,1,0,0,0,0,0,0,0,0,0,1,1,1
1,2,1,0,0,0,0,0,0,0,0,0,1,2,0
1,1,1,0,0,0,0,0,0,0,0,0,1,1,0
0,0,0,0,0,0,0,0,0,0,0,4,0,0,0
0,0,0,0,0,0,0,0,0,0,0,0,0,0,0
0,0,0,0,0,0,0,0,0,0,0,0,0,0,0
0,0,0,7,0,0,0,0,0,0,0,0,0,0,0
0,0,7,0,0,0,0,0,0,0,0,0,0,0,0
0,0,7,0,7,0,0,0,0,0,0,0,0,0,0
7,0,0,0,0,0,0,0,0,0,0,0,0,0,0
0,0,0,0,0,0,0,8,0,0,0,0,0,0,0
0,0,0,0,0,0,0,0,0,0,0,0,0,0,0
1,1,1,0,0,0,0,0,7,0,0,0,0,0,0
1,2,1,0,0,0,0,0,0,7,0,0,0,2,0
0,0,0,0,0,0,0,0,0,0,0,0,0,0,0
endlayer

layer
1,1,1,0,0,0,0,0,0,0,0,0,1,0,1
1,2,1,0,0,0,0,0,0,0,0,0,1,2,0
1,1,0,0,0,0,0,0,0,0,0,0,0,1,1
0,0,0,0,0,0,0,0,0,0,0,4,0,0,0
0,0,0,0,0,0,0,0,0,0,0,0,0,0,0
0,0,0,0,0,0,0,0,0,0,0,0,0,0,0
0,7,0,7,7,0,0,0,0,0,0,0,0,0,0
0,0,0,0,0,0,0,0,0,0,0,0,0,0,0
0,0,7,0,0,0,0,0,0,0,0,0,0,0,0
0,0,0,0,0,0,0,7,0,0,0,0,0,0,0
0,0,0,0,0,0,0,0,0,0,0,0,0,0,0
0,0,0,0,0,0,7,0,0,0,0,0,0,0,0
1,1,0,0,0,0,0,0,0,0,0,0,0,0,0
1,2,1,0,7,7,0,0,7,0,0,0,0,2,0
0,0,0,0,0,7,0,0,0,0,0,0,0,0,0
endlayer

layer
1,1,1,0,0,0,0,0,0,0,0,0,1,1,1
1,2,0,0,0,0,0,0,0,0,0,0,1,2,0
1,1,1,0,0,0,0,0,0,0,0,0,1,1,1
0,0,0,0,0,0,0,0,0,0,0,4,0,0,0
0,0,0,0,0,0,0,0,0,0,0,0,0,0,0
0,0,0,0,0,0,0,0,0,0,0,0,0,0,0
0,0,0,0,0,0,0,0,0,0,0,0,0,0,0
0,0,0,0,0,0,0,0,0,0,0,0,0,0,0
0,0,0,0,0,0,0,0,0,0,0,0,0,0,0
0,0,0,0,0,0,0,0,0,0,0,0,0,0,0
0,0,0,5,5,8,0,0,0,0,0,0,0,0,0
0,0,0,5,5,8,0,0,0,0,0,0,0,0,0
1,1,1,7,0,0,0,0,0,0,0,0,0,0,0
1,2,1,7,0,0,0,0,0,0,0,0,0,0,0
0,0,0,0,0,0,0,0,0,0,0,0,0,0,0
endlayer

layer
1,1,1,0,0,0,0,0,0,0,0,0,1,0,1
1,2,1,0,0,0,0,0,0,0,0,0,1,2,0
1,1,1,0,0,0,0,0,0,0,0,0,1,0,1
0,0,0,0,0,0,0,0,0,0,0,4,0,0,0
0,0,0,0,0,0,0,0,0,0,0,0,0,0,0
0,0,0,0,0,0,0,0,0,0,0,0,0,0,0
0,0,0,0,0,0,0,0,0,0,0,0,0,0,0
0,0,0,0,0,0,0,0,0,0,0,0,0,0,0
0,0,0,0,0,0,0,0,0,0,0,0,0,0,0
0,0,0,9,9,0,0,0,0,0,0,0,0,0,0
0,0,0,7,0,0,0,0,0,0,0,0,0,0,0
0,0,0,0,0,0,0,0,0,0,0,0,0,0,0
1,1,1,0,0,0,0,0,0,0,0,0,0,0,0
1,2,1,0,0,0,0,0,0,0,0,0,0,0,0
0,0,0,0,0,0,0,0,0,0,0,0,0,0,0
endlayer

layer
1,1,1,0,0,0,0,0,0,0,0,0,1,1,1
1,2,1,0,0,0,0,0,0,0,0,0,1,2,0
1,1,1,0,0,0,0,0,0,0,0,0,1,1,1
0,0,0,0,0,0,0,0,0,0,0,4,0,0,0
0,0,0,0,0,0,0,0,0,0,0,0,0,0,0
0,0,0,0,0,0,0,0,0,0,0,0,0,0,0
0,0,0,0,0,0,0,0,0,0,0,0,0,0,0
0,0,0,0,0,0,0,0,0,0,0,0,0,0,0
0,0,0,9,0,0,0,0,0,0,0,0,0,0,0
0,0,0,0,0,0,0,0,0,0,0,0,0,0,7
0,0,0,7,0,0,0,0,0,0,0,0,0,0,0
0,0,0,0,0,0,0,0,0,0,0,0,0,7,0
0,1,1,0,0,0,0,0,0,0,0,0,0,0,0
0,2,0,0,0,0,0,0,0,0,0,0,0,0,0
0,0,0,0,0,0,0,0,0,0,0,0,0,0,0
endlayer

layer
1,1,1,0,0,0,0,0,0,0,0,0,0,0,0
1,2,2,0,0,0,0,0,0,0,2,2,2,2,0
1,2,1,0,0,0,0,0,0,0,1,1,1,2,0
1,2,1,5,5,5,5,5,5,5,5,4,1,2,0
1,2,1,5,5,5,5,5,5,5,5,5,1,2,0
1,2,1,5,5,5,5,5,5,5,5,5,1,2,0
1,2,1,5,5,5,5,5,5,5,5,5,0,2,0
1,2,1,9,0,5,5,5,5,5,5,5,0,0,0
0,2,1,0,0,5,5,5,5,5,5,5,0,0,0
0,2,1,0,0,5,5,5,5,5,5,0,0,0,0
0,2,1,0,0,5,5,5,5,5,0,0,0,0,0
0,2,1,0,0,5,5,5,5,5,0,0,0,0,0
0,2,1,1,1,1,1,1,1,1,0,0,0,0,0
0,2,2,2,2,2,2,2,2,2,0,0,0,0,0
0,0,7,0,0,0,0,0,0,0,0,0,0,0,0
endlayer

layer
1,1,1,0,0,0,0,0,0,0,7,0,0,0,0
1,2,0,0,0,0,0,0,0,0,0,0,0,2,0
1,1,0,0,0,0,0,0,0,0,0,0,0,7,0
0,0,14,4,4,4,4,13,0,0,4,4,0,0,0
0,0,0,0,15,0,7,0,0,0,0,0,0,0,0
0,0,0,0,7,7,0,0,0,0,7,0,0,0,0
0,0,0,0,0,0,0,0,0,0,0,0,0,0,0
0,0,0,0,0,0,0,0,0,0,0,0,0,0,0
0,0,0,0,0,0,0,0,0,0,0,0,0,0,0
0,0,0,0,0,0,0,0,0,0,0,0,0,0,0
0,0,0,0,0,0,0,0,0,0,0,0,0,0,0
0,0,0,0,0,0,0,0,8,0,0,0,7,0,0
0,0,0,0,0,0,0,0,0,0,0,0,0,0,0
0,2,7,0,0,0,7,0,0,0,0,0,0,0,0
0,0,0,0,0,0,0,7,0,0,0,0,0,0,0
endlayer

layer
0,0,0,0,0,0,0,0,0,0,0,0,0,0,7
0,2,0,0,0,0,0,0,0,0,0,0,0,2,0
0,0,0,0,0,7,0,0,0,0,0,0,0,0,0
0,0,16,4,0,0,7,0,0,0,0,0,0,7,0
0,0,0,0,7,0,0,7,7,7,7,0,0,7,0
0,0,7,0,7,0,0,0,0,7,0,0,0,0,0
7,0,0,7,0,0,0,0,0,7,0,0,0,0,0
0,7,0,0,7,0,0,0,0,0,0,0,0,0,0
0,0,0,0,0,0,0,0,0,7,7,0,0,0,0
0,0,0,0,0,0,0,0,0,0,7,0,0,0,0
0,0,0,0,0,0,0,8,0,0,7,0,0,7,0
0,0,7,0,0,0,0,0,7,0,0,7,0,7,0
0,0,7,0,0,0,0,0,0,0,0,0,0,0,0
0,2,0,7,0,0,0,0,7,0,0,0,0,0,0
0,0,0,0,0,0,0,0,0,0,0,0,0,0,0
endlayer

layer
0,0,0,0,0,0,0,0,0,0,0,0,0,0,0
0,2,0,0,0,0,0,0,0,0,0,0,0,2,0
0,0,0,0,0,0,0,0,0,0,0,0,0,0,0
0,0,0,4,0,0,0,0,7,0,0,0,0,0,0
0,0,0,0,0,0,0,0,0,0,0,0,0,0,0
0,0,0,0,0,0,0,0,0,7,0,0,0,0,0
0,0,0,0,0,0,0,0,0,0,0,0,0,0,0
0,7,0,0,0,0,7,0,0,0,0,0,0,0,0
0,0,0,0,0,0,0,0,0,0,0,0,0,0,0
0,0,0,0,0,0,0,0,0,7,0,0,0,0,0
0,7,0,0,0,0,8,0,0,0,7,0,0,0,0
0,0,0,0,0,0,0,0,0,0,0,0,0,0,0
0,0,7,0,0,0,0,0,0,0,0,0,0,0,0
0,2,0,0,0,0,0,0,0,0,0,0,0,0,0
0,0,0,0,0,0,0,0,0,0,0,0,0,0,0
endlayer

layer
0,0,0,0,0,0,0,0,0,0,0,0,0,0,0
0,2,0,0,0,0,0,0,0,0,0,0,0,0,0
0,0,0,0,0,0,0,0,0,0,0,0,0,0,0
0,0,0,4,0,0,0,0,0,0,0,0,0,0,0
0,0,7,7,0,0,0,0,0,0,0,0,0,0,0
0,7,7,0,0,0,0,0,0,0,0,0,0,0,0
0,7,0,0,0,0,0,0,0,0,0,0,0,0,0
7,0,0,0,0,0,0,0,0,0,0,0,0,0,0
0,0,0,0,0,0,0,0,0,0,0,0,0,0,0
0,0,0,0,0,0,0,0,0,0,0,0,0,0,0
0,7,0,0,5,8,0,0,0,0,7,0,0,0,0
0,0,0,0,0,0,0,0,7,0,0,0,0,0,0
0,0,0,0,0,0,0,0,0,0,0,0,0,0,0
0,0,0,0,0,0,0,0,0,0,0,0,0,0,0
0,0,0,0,0,0,0,0,0,0,0,0,0,0,0
endlayer

layer
0,0,0,0,0,0,0,0,0,0,0,0,0,0,0
0,2,0,0,0,0,0,0,0,0,0,0,0,0,0
0,0,0,0,0,0,0,0,0,0,0,0,0,0,0
0,0,0,4,0,0,7,0,0,0,0,0,0,0,0
7,0,0,0,0,0,0,0,0,0,0,0,0,0,0
0,0,0,0,0,0,0,0,0,0,0,0,0,0,0
0,7,0,0,0,0,0,0,0,0,0,0,0,0,0
0,0,0,0,0,0,0,0,0,0,0,0,0,0,0
0,0,0,0,0,0,0,0,0,0,0,0,0,0,0
7,0,0,9,9,0,0,7,0,0,0,0,0,0,0
0,0,0,0,0,0,0,0,0,0,0,0,0,0,0
0,0,0,0,0,0,0,0,0,0,0,0,0,7,0
0,0,0,0,7,0,0,0,0,0,0,0,0,0,0
0,0,0,0,0,0,7,0,0,0,0,0,0,0,0
0,0,0,0,0,0,0,7,0,0,0,0,0,0,0
endlayer

layer
0,0,0,0,0,0,0,0,0,0,0,0,0,0,0
0,2,0,0,0,0,0,0,0,0,0,0,0,0,0
0,0,0,0,0,0,0,0,0,0,0,0,0,0,0
0,0,0,0,0,0,0,0,0,0,0,0,0,0,0
0,0,0,0,0,0,0,0,0,0,0,0,0,0,0
0,7,0,0,0,0,0,0,0,0,0,0,0,0,0
0,0,0,0,0,0,0,0,0,0,0,0,0,0,0
0,7,0,0,0,0,0,0,0,0,0,0,0,0,0
0,0,0,9,0,0,0,0,0,0,0,0,0,0,0
0,0,0,0,0,0,0,0,0,0,0,0,0,0,0
0,0,0,0,7,0,0,0,0,0,0,0,0,0,0
0,0,0,0,0,0,0,0,0,0,0,0,0,0,0
0,0,0,0,0,0,0,7,0,0,0,0,7,0,0
0,0,0,0,0,0,0,0,0,0,0,0,0,0,0
0,0,0,0,0,0,0,0,0,0,0,0,0,0,0
endlayer

layer
0,0,0,7,0,0,0,7,0,0,0,0,0,0,0
7,2,2,2,2,2,0,0,0,0,0,0,0,0,0
0,0,0,0,0,0,0,0,0,0,0,0,0,0,0
0,0,0,0,0,0,0,0,0,0,0,0,0,0,0
0,0,0,0,0,0,0,0,0,0,0,0,0,0,0
0,0,0,0,0,0,0,0,0,0,0,0,0,0,0
0,7,0,0,0,0,0,0,0,0,0,0,0,0,0
0,0,0,9,0,0,0,0,0,0,0,0,0,0,0
0,7,0,0,0,0,0,0,0,0,0,0,0,0,0
0,0,0,0,0,0,0,0,0,0,0,0,0,0,0
0,0,7,0,0,0,0,0,0,0,0,0,0,0,0
0,0,0,0,0,0,0,0,7,0,0,0,0,0,0
0,0,0,0,0,0,0,0,0,0,0,0,0,0,0
0,0,0,0,0,0,7,0,0,0,0,0,0,0,0
0,0,0,0,0,0,7,0,0,0,0,0,0,0,0
endlayer

layer
0,7,0,0,0,7,0,0,0,0,0,0,0,0,0
0,0,0,0,0,0,0,0,0,0,0,0,0,0,0
0,0,0,0,0,0,0,0,0,0,0,0,0,0,0
0,0,0,0,0,7,0,0,0,0,0,0,0,0,0
7,0,0,0,0,0,0,0,0,0,0,0,0,0,0
0,0,7,7,7,0,0,7,0,0,7,0,0,0,0
0,0,0,7,0,0,0,0,0,0,0,0,0,0,0
0,0,0,0,0,0,0,0,0,0,0,0,0,0,0
0,0,0,0,0,0,0,0,0,0,0,7,0,0,0
0,0,7,0,0,0,0,0,0,0,0,0,0,0,0
0,0,0,0,0,0,0,0,0,0,0,0,0,0,0
0,0,0,0,0,0,0,0,0,0,0,0,0,0,0
0,0,0,0,0,0,0,0,0,0,0,0,0,0,0
0,0,0,0,0,0,0,0,0,0,0,0,0,0,0
0,0,0,0,0,0,0,0,0,0,0,0,0,0,0
endlayer

layer
0,0,0,0,7,0,0,0,0,0,0,0,0,0,0
0,0,0,0,0,0,7,0,0,0,0,0,0,0,0
0,0,0,0,0,0,0,0,0,0,0,0,0,0,0
0,0,0,0,0,0,0,0,0,0,0,0,0,0,7
0,0,0,0,0,0,0,0,0,0,0,0,0,0,0
0,0,0,0,0,0,7,7,0,0,0,0,0,0,0
0,0,0,0,0,0,0,0,0,0,0,0,0,0,0
0,0,0,0,0,0,0,0,0,0,0,0,0,0,0
0,0,0,0,0,0,0,0,0,0,0,0,0,0,0
0,0,0,0,0,0,0,0,0,0,0,0,0,0,0
0,0,0,0,0,0,0,0,0,0,0,0,0,0,0
0,0,0,0,0,0,0,0,0,0,0,0,0,0,0
0,0,0,0,0,0,0,0,0,0,0,0,0,0,0
0,0,0,0,0,0,0,0,0,0,0,0,0,0,0
0,0,0,0,0,0,0,0,0,0,0,0,0,0,0
endlayer

layer
0,0,0,0,0,0,0,0,0,0,0,0,0,0,0
0,0,0,0,0,0,0,0,0,0,0,0,0,0,0
0,0,0,0,0,0,0,0,0,0,0,0,0,0,0
0,0,0,0,0,0,0,0,0,0,0,0,0,0,0
0,0,0,0,0,0,0,0,0,0,0,0,0,0,0
0,0,0,0,0,0,0,0,0,0,7,0,0,0,0
0,0,0,0,0,0,0,0,0,0,0,0,0,0,0
0,0,0,0,0,7,0,0,0,0,0,0,0,0,0
0,0,0,0,0,0,0,0,0,0,0,0,0,0,0
0,0,0,0,0,0,0,7,0,0,0,0,0,0,0
0,0,0,0,0,0,0,0,0,0,0,0,0,0,0
0,0,0,0,0,0,0,0,0,0,0,0,0,0,0
0,0,0,0,0,0,0,0,0,0,0,0,0,0,0
0,0,0,0,0,0,0,0,0,0,0,0,0,0,0
0,0,0,0,0,0,0,0,0,0,0,0,0,0,0
endlayer

layer
0,0,0,0,0,0,0,0,0,0,0,0,0,0,0
0,0,0,0,0,0,0,0,0,0,0,0,0,0,0
0,0,0,0,0,0,0,0,0,0,0,0,0,0,0
0,0,0,0,0,0,0,0,0,0,0,0,0,0,0
0,0,0,0,0,0,0,0,0,0,0,0,0,0,0
0,0,0,0,0,0,0,0,0,0,0,0,0,0,0
0,0,0,0,0,0,0,0,0,0,0,0,0,0,0
0,0,0,0,0,0,0,0,0,0,0,0,0,0,0
0,0,0,0,0,0,0,0,0,0,0,0,0,0,0
0,0,0,0,0,0,0,0,0,0,0,0,0,0,0
0,0,0,0,0,0,0,0,0,0,0,0,0,0,0
0,0,0,0,0,0,0,0,0,0,0,0,0,0,0
0,0,0,0,0,0,0,0,0,0,0,0,0,0,0
0,0,0,0,0,0,0,0,0,0,0,0,0,0,0
0,0,0,0,0,0,0,0,0,0,0,0,0,0,0
endlayer

layer
0,0,0,0,0,0,0,0,0,0,0,0,0,0,0
0,0,0,0,0,0,0,0,0,0,0,0,0,0,0
0,0,0,0,0,0,0,0,0,0,0,0,0,0,0
0,0,7,0,0,7,0,0,0,0,0,0,0,0,0
0,0,0,0,0,0,0,0,0,0,0,0,0,0,0
0,0,0,0,0,0,0,0,0,0,0,0,0,0,0
0,0,0,0,0,0,0,0,0,0,0,0,0,0,0
0,0,0,0,0,0,0,0,0,0,0,0,0,0,0
0,0,0,0,0,0,0,0,0,0,0,0,0,0,0
0,0,0,0,0,0,0,0,0,0,0,0,0,0,0
0,0,0,0,0,0,0,0,0,0,0,0,0,0,0
0,0,0,0,0,0,0,0,0,0,0,0,0,0,0
0,0,0,0,0,0,0,0,0,0,0,0,0,0,0
0,0,0,0,0,0,0,0,0,0,0,0,0,0,0
0,0,0,0,0,0,0,0,0,0,0,0,0,0,0
endlayer

layer
0,0,0,0,0,0,0,0,0,0,0,0,0,0,0
0,0,0,0,0,0,0,0,0,0,0,0,0,0,0
0,0,0,0,0,0,0,0,0,0,0,0,0,0,0
0,0,0,0,0,7,0,0,0,0,0,0,0,0,0
0,0,0,0,7,0,0,0,0,0,0,0,0,0,0
0,0,0,7,0,0,0,0,0,0,0,0,0,0,0
0,0,0,0,0,0,0,0,0,0,0,0,0,0,0
0,0,0,0,0,0,0,0,0,0,0,0,0,0,0
0,0,0,0,0,0,0,0,0,0,0,0,0,0,0
0,0,0,0,0,0,0,0,0,0,0,0,0,0,0
0,0,0,0,0,0,7,0,0,0,0,0,0,0,0
0,0,0,0,0,0,0,7,0,0,0,0,0,0,0
0,0,0,0,0,0,0,0,0,0,0,0,0,0,0
0,0,0,0,0,0,0,0,0,0,0,0,0,0,0
0,0,0,0,0,0,0,0,0,0,0,0,0,0,0
endlayer

