
# Created by Ruins mod version 13.8 Ingame Parser
# authoring Player: OneWolfe

weight=1
unique=1
embed_into_distance=3
biomesToSpawnIn=rolling hills,forest,high hills
acceptable_target_blocks=
unacceptable_target_blocks=flowing_water,water,flowing_lava,lava,terrafirmacraft:SaltWaterStationary-0,terrafirmacraft:SaltWaterStationary-8,terrafirmacraft:FreshWaterStationary-0,terrafirmacraft:FreshWaterStationary-8
dimensions=40,15,15
allowable_overhang=4
max_leveling=6
leveling_buffer=2
preserve_water=0
preserve_lava=0
preserve_plants=1

rule1=0,100,terrafirmacraft:StoneIgEx-2
rule2=0,100,Railcraft:frame-0
rule3=0,100,Steamcraft:steamTank-0
rule4=0,100,Steamcraft:pipe-0
rule5=0,100,air
rule6=0,100,terrafirmacraft:planks-1
rule7=0,100,minecraft:stone_pressure_plate-0
rule8=0,100,minecraft:stained_glass-11
rule9=0,100,minecraft:stone_brick_stairs-2
rule10=0,100,BiblioCraft:BiblioIronLantern-10
rule11=0,100,minecraft:stone_brick_stairs-1
rule12=0,100,Steamcraft:fan-3
rule13=0,100,Steamcraft:fan-5
rule14=0,100,Steamcraft:fan-1
rule15=0,100,air
layer
1,1,1,1,1,1,1,1,1,1,1,1,1,1,1
1,2,2,2,2,2,2,2,2,2,2,2,2,2,1
1,2,1,1,1,1,1,1,1,1,1,1,1,2,1
1,2,1,3,4,3,3,0,0,0,0,0,1,2,1
1,2,1,0,5,3,3,0,0,0,0,0,1,2,1
1,2,1,0,0,0,0,0,0,0,0,0,1,2,1
1,2,1,0,0,0,0,0,0,0,0,0,1,2,1
1,2,1,0,0,0,0,0,0,0,0,0,1,2,1
1,2,1,0,0,0,0,0,0,0,0,0,1,2,1
1,2,1,0,0,0,0,0,0,0,0,0,1,2,1
1,2,1,0,0,0,0,0,0,0,0,0,1,2,1
1,2,1,0,0,0,0,0,0,0,0,0,1,2,1
1,2,1,1,1,1,1,1,1,1,1,1,1,2,1
1,2,2,2,2,2,2,2,2,2,2,2,2,2,1
1,1,1,1,1,1,1,1,1,1,1,1,1,1,1
endlayer

layer
1,1,1,1,1,1,1,1,1,1,1,1,1,1,1
1,2,1,1,1,1,1,1,1,1,1,1,1,2,1
1,1,1,1,1,1,1,1,1,1,1,1,1,1,1
1,1,1,4,6,6,6,6,6,6,6,6,1,1,1
1,1,1,6,6,6,6,6,6,6,6,6,1,1,1
1,1,1,6,6,6,6,6,6,6,6,6,1,1,1
1,1,1,6,6,6,6,6,6,6,6,6,1,1,1
1,1,1,6,6,6,6,6,6,6,6,6,1,1,1
1,1,1,6,6,6,6,6,6,6,6,6,1,1,1
1,1,1,6,6,6,6,6,6,6,6,6,1,1,1
1,1,1,6,6,6,6,6,6,6,6,6,1,1,1
1,1,1,6,6,6,6,6,6,6,6,6,1,1,1
1,1,1,1,1,1,1,1,1,1,1,1,1,1,1
1,2,1,1,1,1,1,1,1,1,1,1,1,2,1
1,1,1,1,1,1,1,1,1,1,1,1,1,1,1
endlayer

layer
1,1,1,0,0,0,7,7,7,0,0,0,1,1,1
1,2,1,8,8,8,0,0,5,8,8,8,1,2,1
1,1,1,0,0,0,7,7,7,0,0,0,1,1,1
0,8,0,4,0,0,0,0,0,0,0,0,0,8,0
0,8,0,0,5,0,0,0,0,0,0,0,0,8,0
0,8,5,5,0,0,0,0,0,0,0,0,0,8,0
7,0,7,0,0,0,0,0,0,0,0,0,7,0,7
7,0,7,0,0,0,0,0,0,0,0,0,7,0,7
7,0,7,0,0,0,0,0,0,0,0,0,7,5,7
0,8,0,0,0,0,0,0,0,0,0,0,0,8,0
0,8,0,0,0,0,0,9,0,0,0,0,0,8,0
0,8,0,0,0,0,0,9,0,0,0,0,0,8,0
1,1,1,0,0,0,7,7,7,0,0,0,1,1,1
1,2,1,8,8,8,0,0,0,8,8,8,1,2,1
1,1,1,0,0,0,7,7,7,0,0,0,1,1,1
endlayer

layer
1,1,1,0,0,0,0,0,0,0,0,0,1,1,1
1,2,1,8,8,8,0,0,0,8,8,8,1,2,1
1,1,1,0,0,5,0,5,5,0,0,0,1,1,1
0,8,0,4,0,5,5,5,0,5,5,0,0,8,0
0,8,0,0,0,0,5,0,5,5,0,0,0,8,0
0,8,0,0,5,5,0,0,5,0,0,5,5,8,0
5,0,0,0,0,0,0,5,0,0,0,0,0,0,0
0,5,0,0,0,0,0,0,0,0,0,0,0,0,0
0,5,0,0,0,0,0,0,0,0,0,0,0,0,0
0,8,0,0,0,0,0,0,0,0,0,0,0,8,0
0,8,0,0,0,0,9,0,0,0,0,0,0,8,0
0,8,0,0,0,0,9,0,0,0,0,0,0,8,0
1,1,1,0,0,0,0,0,0,0,0,0,1,1,1
1,2,1,8,8,8,0,0,0,8,8,8,1,2,1
1,1,1,0,0,0,0,0,0,0,0,0,1,1,1
endlayer

layer
1,1,1,0,0,0,0,0,0,0,0,0,1,1,1
1,2,1,8,8,8,0,0,0,8,8,8,1,2,1
1,1,10,0,0,0,0,0,0,0,0,0,10,1,1
0,8,0,4,0,0,0,0,0,0,0,0,0,8,0
0,8,0,0,0,0,0,0,0,0,0,0,0,8,0
0,8,0,0,0,0,0,0,0,0,0,0,0,8,0
0,0,0,0,0,0,0,0,0,0,0,0,0,0,0
0,0,0,0,0,0,0,0,0,0,0,0,0,0,0
0,0,0,0,0,0,0,0,0,0,0,0,0,0,0
0,8,0,0,0,0,0,0,0,0,0,0,0,8,0
0,8,0,6,6,9,0,0,0,0,0,0,0,8,0
0,8,0,6,6,9,0,0,0,0,0,0,0,8,0
1,1,10,0,0,0,0,0,0,0,0,0,10,1,1
1,2,1,8,8,8,0,0,0,8,8,8,1,2,1
1,1,1,0,0,0,0,0,0,0,0,0,1,1,1
endlayer

layer
1,1,1,0,0,0,0,0,0,0,0,0,1,1,1
1,2,1,8,8,8,8,8,8,8,8,8,1,2,1
1,1,1,0,0,0,0,0,0,0,0,0,1,1,1
0,8,0,4,4,4,4,4,4,4,4,4,0,8,0
0,8,0,0,0,0,0,0,0,0,0,0,0,8,0
0,8,0,0,0,0,0,0,0,0,0,0,0,8,0
0,8,0,0,0,0,0,0,0,0,0,0,0,8,0
0,8,0,0,0,0,0,0,0,0,0,0,0,8,0
0,8,0,0,0,0,0,0,0,0,0,0,0,8,0
0,8,0,11,11,0,0,0,0,0,0,0,0,8,0
0,8,0,0,0,0,0,0,0,0,0,0,0,8,0
0,8,0,0,0,0,0,0,0,0,0,0,0,8,0
1,1,1,0,0,0,0,0,0,0,0,0,1,1,1
1,2,1,8,8,8,8,8,8,8,8,8,1,2,1
1,1,1,0,0,0,0,0,0,0,0,0,1,1,1
endlayer

layer
1,1,1,1,1,1,1,1,1,1,1,1,1,1,1
1,2,2,2,2,2,2,2,2,2,2,2,2,2,1
1,2,1,1,1,1,1,1,1,1,1,1,1,2,1
1,2,1,6,6,6,6,6,6,6,6,4,1,2,1
1,2,1,6,6,6,6,6,6,6,6,6,1,2,1
1,2,1,6,6,6,6,6,6,6,6,6,1,2,1
1,2,1,6,6,6,6,6,6,6,6,6,1,2,1
1,2,1,6,6,6,6,6,6,6,6,6,1,2,1
1,2,1,11,11,6,6,6,6,6,6,6,1,2,1
1,2,1,0,0,6,6,6,6,6,6,6,1,2,1
1,2,1,0,0,0,0,6,6,6,6,6,1,2,1
1,2,1,0,0,0,0,6,6,6,6,6,1,2,1
1,2,1,1,1,1,1,1,1,1,1,1,1,2,1
1,2,2,2,2,2,2,2,2,2,2,2,2,2,1
1,1,1,1,1,1,1,1,1,1,1,1,1,1,1
endlayer

layer
1,1,1,0,0,0,0,0,0,0,0,0,1,1,1
1,2,1,8,8,8,8,8,8,8,8,8,1,2,1
1,1,1,0,0,0,0,0,0,0,0,0,1,1,1
0,8,0,0,0,0,0,0,0,0,0,4,0,8,0
0,8,0,0,0,0,0,0,0,0,0,0,0,8,0
0,8,0,0,0,0,0,0,0,0,0,0,0,8,0
0,8,0,0,0,0,0,0,0,0,0,0,0,8,0
0,8,0,0,0,0,0,0,0,0,0,0,0,8,0
0,8,0,0,0,0,0,0,0,0,0,0,0,8,0
0,8,0,0,0,0,0,0,0,0,0,0,0,8,0
0,8,0,0,0,0,0,0,9,0,0,0,0,8,0
0,8,0,0,0,0,0,0,9,0,0,0,0,8,0
1,1,1,0,0,0,0,0,0,0,0,0,1,1,1
1,2,1,8,8,8,8,8,8,8,8,8,1,2,1
1,1,1,0,0,0,0,0,0,0,0,0,1,1,1
endlayer

layer
1,1,1,0,0,0,0,0,0,0,0,0,1,1,1
1,2,1,8,8,8,8,8,8,8,8,8,1,2,1
1,1,1,0,0,0,0,0,0,0,0,0,1,1,1
0,8,0,0,0,0,0,0,0,0,0,4,0,8,0
0,8,5,0,0,0,0,0,0,0,0,0,0,8,0
0,8,0,0,0,0,0,0,0,0,0,0,0,8,5
0,8,0,0,0,0,0,0,0,0,0,5,0,8,0
0,8,0,0,0,0,0,0,0,0,0,0,0,8,0
0,8,0,0,0,0,0,0,0,0,0,0,0,8,0
0,8,0,0,0,0,0,0,0,0,0,0,0,8,0
0,8,0,0,0,0,0,9,0,0,0,0,0,8,0
0,8,0,0,0,0,0,9,0,0,0,0,0,8,0
1,1,1,0,0,0,0,0,0,0,0,0,1,1,1
1,2,1,8,8,8,8,8,8,8,8,8,1,2,1
1,1,1,0,0,0,0,0,0,0,0,0,1,1,1
endlayer

layer
1,1,1,0,0,0,0,0,0,0,0,0,1,1,1
1,2,1,8,8,8,8,8,8,8,8,8,1,2,1
1,1,0,0,0,0,0,0,0,0,0,0,0,1,1
0,8,0,0,0,0,0,0,0,0,0,4,0,8,0
0,8,0,0,0,0,0,0,0,0,0,0,0,8,0
0,8,0,0,0,0,0,0,0,0,0,0,0,8,0
0,8,0,0,0,0,0,0,0,5,0,5,0,8,0
0,8,0,0,0,0,0,0,0,0,0,0,0,8,0
0,8,0,0,0,0,0,0,0,5,0,0,0,8,0
0,8,0,0,0,0,0,0,0,0,0,0,0,8,0
0,8,0,0,0,0,9,0,0,0,0,0,0,8,0
0,8,0,0,0,0,9,0,5,0,0,0,0,8,0
1,1,0,0,0,0,0,0,0,0,0,0,10,1,1
1,2,1,8,8,8,8,8,8,8,8,8,1,2,1
1,1,1,0,0,0,0,0,0,0,0,0,1,1,1
endlayer

layer
1,1,1,0,0,0,0,0,0,0,0,0,1,1,1
1,2,1,8,8,8,8,8,8,8,8,8,1,2,1
1,1,1,0,0,0,0,0,0,0,0,0,1,1,1
0,8,0,0,0,0,0,0,0,0,0,4,0,8,0
0,8,0,0,0,0,0,0,0,0,0,0,0,8,0
0,8,0,0,0,0,0,0,0,0,0,0,0,8,0
0,8,0,0,0,0,0,0,0,0,0,0,0,8,0
0,8,0,0,0,0,0,0,0,0,0,0,0,8,0
0,8,0,0,0,0,0,0,0,0,0,0,0,8,0
0,8,0,0,0,0,0,0,0,0,0,0,0,8,0
0,8,0,6,6,9,0,0,0,0,0,0,0,8,0
0,8,0,6,6,9,0,0,0,0,0,0,0,8,0
1,1,1,0,0,0,0,0,0,0,0,0,1,1,1
1,2,1,8,8,8,8,8,8,8,8,8,1,2,1
1,1,1,0,0,0,0,0,0,0,0,0,1,1,1
endlayer

layer
1,1,1,0,0,0,0,0,0,0,0,0,1,1,1
1,2,1,8,8,8,8,8,8,8,8,8,1,2,1
1,1,1,0,0,0,0,0,0,0,0,0,1,1,1
0,8,0,0,0,0,5,5,0,0,0,4,0,8,0
0,8,0,0,0,0,0,0,0,0,0,0,0,8,0
0,8,0,0,0,0,0,0,0,0,0,0,0,8,0
0,8,0,0,0,0,0,0,0,0,0,0,0,8,0
0,8,0,0,0,0,0,0,0,0,0,0,0,8,0
0,8,0,0,0,0,0,0,0,0,0,0,0,8,0
0,8,0,11,11,0,0,0,0,0,0,0,0,8,0
0,8,0,0,0,0,0,0,0,0,0,0,0,8,0
0,8,0,0,0,0,0,0,0,0,0,0,0,8,0
1,1,1,0,0,0,0,0,0,0,0,0,1,1,1
1,2,1,8,8,8,8,8,8,8,8,8,1,2,1
1,1,1,0,0,0,0,0,0,0,0,0,1,1,1
endlayer

layer
1,1,1,0,0,0,0,0,0,0,0,0,1,1,1
1,2,1,8,8,8,8,8,8,8,8,8,1,2,1
1,1,1,0,0,0,0,0,0,0,0,0,1,1,1
0,8,0,0,0,0,0,0,0,0,12,4,0,8,0
0,8,0,0,0,0,0,0,0,0,0,4,0,8,0
0,8,0,0,0,0,0,0,0,0,0,4,0,8,0
0,8,0,0,0,0,0,0,0,0,0,4,0,8,0
0,8,0,0,0,0,0,0,0,0,0,4,0,8,0
0,8,0,11,11,0,0,0,0,0,0,4,0,8,0
0,8,0,0,0,0,0,0,0,0,0,4,0,8,0
0,8,0,0,0,0,0,0,0,0,0,4,0,8,0
0,8,0,0,0,0,0,0,0,0,0,4,0,8,0
1,1,1,0,0,0,0,0,0,0,0,0,1,1,1
1,2,1,8,8,8,8,8,8,8,8,8,1,2,1
1,1,1,0,0,0,0,0,0,0,0,0,1,1,1
endlayer

layer
1,1,1,1,1,1,1,1,1,1,1,1,1,1,1
1,2,2,2,2,2,2,2,2,2,2,2,2,2,1
1,2,1,1,1,1,1,1,1,1,1,1,1,2,1
1,2,1,6,6,6,6,6,6,6,6,6,1,2,1
1,2,1,6,6,6,6,6,6,6,6,6,1,2,1
1,2,1,6,6,6,6,6,6,6,6,6,1,2,1
1,2,1,6,6,6,6,6,6,6,6,6,1,2,1
1,2,1,11,11,6,6,6,6,6,6,6,1,2,1
1,2,1,0,0,6,6,6,6,6,6,6,1,2,1
1,2,1,0,0,6,6,6,6,6,6,6,1,2,1
1,2,1,0,0,0,0,6,6,6,6,6,1,2,1
1,2,1,0,0,0,0,6,6,6,6,4,1,2,1
1,2,1,1,1,1,1,1,1,1,1,1,1,2,1
1,2,2,2,2,2,2,2,2,2,2,2,2,2,1
1,1,1,1,1,1,1,1,1,1,1,1,1,1,1
endlayer

layer
1,1,1,0,0,0,0,0,0,0,0,0,1,1,1
1,2,1,8,8,8,8,8,8,8,8,8,1,2,1
1,1,1,0,0,0,0,0,0,0,0,0,1,1,1
0,8,0,0,0,5,0,5,5,0,0,4,0,8,0
0,8,0,0,0,0,0,0,0,5,0,4,0,8,0
0,8,0,0,0,0,0,0,5,0,0,4,0,8,0
0,8,0,0,5,0,0,0,5,0,0,4,0,8,0
0,8,0,0,0,5,0,0,5,5,12,4,0,8,0
0,8,0,0,0,0,0,0,0,0,0,4,0,8,0
0,8,0,0,0,0,0,0,0,5,0,4,0,8,0
0,8,0,0,0,0,0,0,9,0,5,4,0,8,0
0,8,0,0,0,0,0,0,9,0,0,4,0,8,0
1,1,1,0,0,0,0,0,0,5,0,0,1,1,1
1,2,1,8,8,8,8,8,8,8,8,8,1,2,1
1,1,1,0,0,0,0,0,5,0,0,0,1,1,1
endlayer

layer
1,1,1,0,0,0,0,0,0,0,0,0,1,1,1
1,2,1,8,8,8,8,8,8,8,8,8,1,2,1
1,1,1,0,0,0,0,0,0,0,0,0,1,1,1
0,8,0,0,0,0,0,0,0,0,0,4,0,8,0
0,8,0,0,0,0,0,0,0,5,0,0,0,8,0
0,8,0,0,0,0,0,0,0,0,0,0,0,8,0
0,8,0,0,0,0,0,0,0,0,0,0,0,8,0
0,8,0,0,0,0,0,0,0,0,0,0,0,8,0
0,8,0,0,0,0,0,0,0,0,0,0,0,8,0
0,8,0,0,0,0,0,0,0,0,0,0,0,8,0
0,8,0,0,0,0,0,9,0,0,0,0,0,8,0
0,8,0,0,0,0,0,9,0,0,0,0,0,8,0
1,1,1,0,0,0,0,0,0,0,0,0,1,1,1
1,2,1,8,8,8,8,8,8,8,8,8,1,2,1
1,1,1,0,0,0,0,0,0,0,0,0,1,1,1
endlayer

layer
1,1,1,0,0,0,0,0,0,0,0,0,1,1,1
1,2,1,8,8,8,8,8,8,8,8,8,1,2,1
1,1,0,0,0,0,0,0,0,0,0,0,0,1,1
0,8,0,0,0,0,0,0,0,0,0,4,0,8,0
0,8,0,0,0,0,0,0,0,0,0,0,0,8,0
0,8,0,0,0,0,0,0,0,0,0,0,0,8,0
0,8,0,0,0,0,0,0,0,0,0,0,0,8,0
0,8,0,0,0,0,0,0,0,0,0,0,0,8,0
0,8,0,0,0,0,0,0,0,0,0,0,0,8,0
0,8,0,0,0,0,0,0,0,0,0,0,0,8,0
0,8,0,0,0,0,9,0,0,0,0,0,0,8,0
0,8,0,0,0,0,9,0,0,0,0,0,0,8,0
1,1,0,0,0,0,0,0,0,0,0,0,0,1,1
1,2,1,8,8,8,8,8,8,8,8,8,1,2,1
1,1,1,0,0,0,0,0,0,0,0,0,1,1,1
endlayer

layer
1,1,1,0,0,0,0,0,0,0,0,0,1,1,1
1,2,1,8,8,8,8,8,8,8,8,8,1,2,1
1,1,1,0,0,0,0,0,0,0,0,0,1,1,1
0,8,0,0,0,0,0,0,0,0,0,4,0,8,0
0,8,0,0,0,0,0,0,0,0,0,0,0,8,0
0,8,0,0,0,0,0,0,0,0,0,0,0,8,0
0,8,0,0,0,0,0,0,0,0,0,0,0,8,0
0,8,0,0,0,0,0,0,0,0,0,0,0,8,0
0,8,0,0,0,0,0,0,0,0,0,0,0,8,0
0,8,0,0,0,0,0,0,0,0,0,0,0,8,0
0,8,0,6,6,9,0,0,0,0,0,0,0,8,0
0,8,0,6,6,9,0,0,0,0,0,0,0,8,0
1,1,1,0,0,0,0,0,0,0,0,0,1,1,1
1,2,1,8,8,8,8,8,8,8,8,8,1,2,1
1,1,1,0,0,0,0,0,0,0,0,0,1,1,1
endlayer

layer
1,1,1,0,0,0,0,0,0,0,0,0,1,1,1
1,2,1,8,8,8,8,8,8,8,8,8,1,2,1
1,1,1,0,0,0,0,0,0,0,0,0,1,1,1
0,8,0,0,0,0,0,0,0,0,0,4,0,8,0
0,8,0,0,0,0,0,0,0,5,0,0,0,8,0
0,8,0,0,0,0,0,0,0,0,0,5,0,8,0
0,8,0,0,0,0,0,0,0,0,0,0,0,8,0
0,8,0,0,0,0,0,0,0,0,0,0,0,8,0
0,8,0,0,0,0,0,0,0,0,0,0,0,8,0
0,8,0,11,11,0,0,0,0,0,0,0,0,8,0
0,8,0,0,0,0,0,0,0,0,0,0,0,8,0
0,8,0,0,0,0,0,0,0,0,0,0,0,8,0
1,1,1,0,0,0,0,0,0,0,0,0,1,1,1
1,2,1,8,8,8,8,8,8,8,8,8,1,2,1
1,1,1,0,0,0,0,0,0,0,0,0,1,1,1
endlayer

layer
1,1,1,0,0,0,0,0,0,0,0,0,1,1,1
1,2,1,8,8,8,8,8,8,8,8,8,1,2,1
1,1,1,0,0,0,0,0,0,0,0,0,1,1,1
0,8,0,0,0,0,0,0,0,0,0,4,0,8,0
0,8,0,0,0,0,0,0,0,0,0,0,0,8,0
0,8,0,0,0,0,0,0,0,0,0,0,0,8,0
0,8,0,0,0,0,0,0,0,0,0,0,0,8,0
0,8,0,0,0,0,0,0,0,0,0,0,0,8,0
0,8,0,11,11,0,0,0,0,0,0,0,0,8,0
0,8,0,0,0,0,0,0,0,0,0,0,0,8,0
0,8,0,0,0,0,0,0,0,0,0,0,0,8,0
0,8,0,0,0,0,0,0,0,0,0,0,0,8,0
1,1,1,0,0,0,0,0,0,0,0,0,1,1,1
1,2,1,8,8,8,8,8,8,8,8,8,1,2,1
1,1,1,0,0,0,0,0,0,0,0,0,1,1,1
endlayer

layer
1,1,1,1,1,1,1,1,1,1,1,1,1,1,1
1,2,2,2,2,2,2,2,2,2,2,2,2,2,1
1,2,1,1,1,1,1,1,1,1,1,1,1,2,1
1,2,1,6,6,6,6,6,6,6,6,4,1,2,1
1,2,1,6,6,6,6,6,6,6,6,6,1,2,1
1,2,1,6,6,6,6,6,6,6,6,6,1,2,1
1,2,1,6,6,6,6,6,6,6,6,6,1,2,1
1,2,1,11,11,6,6,6,6,6,6,6,1,2,1
1,2,1,0,0,6,6,6,6,6,6,6,1,2,1
1,2,1,0,0,6,6,6,6,6,6,6,1,2,1
1,2,1,0,0,6,6,6,6,6,6,6,1,2,1
1,2,1,0,0,6,6,6,6,6,6,6,1,2,1
1,2,1,1,1,1,1,1,1,1,1,1,1,2,1
1,2,2,2,2,2,2,2,2,2,2,2,2,2,1
1,1,1,1,1,1,1,1,1,1,1,1,1,1,1
endlayer

layer
1,1,1,0,0,0,0,0,0,0,0,0,1,1,1
1,2,1,8,8,8,8,8,0,0,0,0,1,2,1
1,1,1,0,0,0,0,0,0,0,0,0,1,1,1
0,8,0,4,4,4,4,4,4,4,4,4,1,1,1
0,8,0,0,13,0,0,0,0,0,0,0,0,0,0
0,0,0,0,0,0,0,0,0,0,0,0,0,0,0
0,8,0,0,0,0,0,0,0,0,0,0,0,0,0
5,8,0,0,0,0,0,0,0,0,0,0,0,0,0
0,8,0,0,0,0,0,0,0,0,0,5,0,0,0
0,8,0,0,0,0,0,0,0,0,0,0,0,8,0
0,8,0,0,0,0,0,0,9,0,0,0,0,8,0
0,8,0,0,0,0,0,0,9,0,0,0,0,8,0
1,1,1,0,0,0,0,0,0,0,0,0,1,1,0
1,2,1,8,8,8,8,8,0,0,0,0,1,2,1
1,1,1,0,0,0,0,0,0,0,1,1,1,1,1
endlayer

layer
1,1,1,0,0,0,0,0,0,0,0,0,1,1,1
1,2,1,8,8,8,8,8,0,0,0,0,1,2,1
1,1,1,0,0,0,0,0,0,0,0,0,1,1,1
0,8,0,4,0,0,0,0,0,0,0,0,0,0,0
0,0,0,0,0,0,0,0,0,0,0,0,0,0,0
0,0,0,0,0,5,0,0,0,0,5,0,0,0,0
0,0,0,0,0,5,0,5,0,0,0,0,0,0,0
0,8,0,0,5,0,0,0,0,0,0,0,0,0,0
0,8,0,0,0,0,0,0,0,0,0,0,0,0,0
0,8,0,0,0,0,0,0,0,0,0,0,0,0,0
0,8,0,0,0,0,0,9,0,0,0,0,0,0,0
0,8,0,0,0,0,0,9,0,0,0,0,0,8,0
1,1,1,0,0,0,0,0,0,0,0,0,1,1,0
1,2,1,8,8,8,8,0,0,0,0,0,1,2,0
1,1,1,0,0,0,0,0,0,0,0,1,1,1,1
endlayer

layer
1,1,1,0,0,0,0,0,0,0,0,0,1,1,1
1,2,1,8,8,8,8,0,0,0,0,0,1,2,1
1,1,0,0,0,0,0,0,0,0,0,0,0,0,0
0,0,0,4,0,0,0,0,0,0,0,0,0,0,0
0,0,0,0,0,0,0,0,0,0,0,0,0,0,0
0,0,0,0,0,0,0,0,0,0,5,0,0,0,0
0,0,0,0,0,0,0,0,0,0,0,0,5,5,0
0,0,0,0,0,0,0,0,0,5,0,0,0,0,0
0,0,0,0,0,0,0,0,0,0,0,0,0,0,0
0,0,0,0,0,0,0,0,0,0,0,0,0,0,0
0,8,0,0,0,0,9,0,0,0,0,0,0,0,0
0,8,0,0,0,0,9,0,0,0,0,0,0,0,0
1,1,0,0,0,0,0,0,0,0,0,0,0,0,0
1,2,1,8,8,0,0,0,0,0,0,0,1,2,0
1,1,1,0,0,0,0,0,0,0,0,0,1,1,1
endlayer

layer
1,1,1,0,0,0,0,0,0,0,0,0,0,1,1
1,2,1,8,8,8,0,0,0,0,0,0,0,2,0
1,1,1,0,0,0,0,0,0,0,0,0,0,0,0
0,0,0,4,0,0,0,0,0,0,0,0,0,0,0
0,0,0,0,5,0,0,0,0,0,0,0,0,0,0
0,0,0,0,5,5,0,0,0,0,0,0,0,0,0
0,0,0,0,0,0,0,0,0,0,0,0,0,0,0
0,0,0,0,0,0,0,0,0,0,0,0,0,0,0
0,0,0,0,0,0,0,0,0,0,0,0,0,0,0
0,0,0,0,0,0,0,0,0,0,0,0,0,0,0
0,8,0,6,6,9,0,0,0,0,0,0,0,0,0
0,8,0,6,6,9,0,0,0,0,0,0,0,0,0
1,1,1,0,0,0,0,0,0,0,0,0,0,0,0
1,2,1,8,0,0,0,0,0,0,0,8,1,2,0
1,1,1,0,0,0,0,0,0,0,0,0,1,1,0
endlayer

layer
1,1,1,0,0,0,0,0,0,0,0,0,0,1,1
1,2,1,8,8,8,8,0,0,0,0,0,0,2,0
1,1,1,0,0,0,0,0,0,0,0,0,0,0,0
0,8,0,4,0,0,0,0,0,0,0,0,0,8,0
0,0,0,0,0,0,0,0,0,0,0,0,0,8,0
0,0,0,0,0,0,0,0,0,0,0,0,0,0,0
0,0,0,0,0,0,0,0,0,0,0,0,0,0,0
0,0,0,0,0,0,0,0,0,0,0,0,0,0,0
0,0,0,0,0,0,0,0,0,0,0,0,0,0,0
0,0,0,11,11,0,0,0,0,0,0,0,0,0,0
0,0,0,0,0,0,0,0,0,0,0,0,0,0,0
0,8,0,0,0,0,0,0,0,0,0,0,0,0,0
1,1,1,0,0,0,0,0,0,0,0,0,0,0,0
1,2,1,8,0,0,0,0,0,0,8,8,0,2,0
1,1,1,0,0,0,0,0,0,0,0,0,1,1,0
endlayer

layer
1,1,1,0,0,0,0,0,0,0,0,0,0,1,1
1,2,1,8,8,8,8,8,0,0,0,0,0,2,0
1,1,1,0,0,0,0,0,0,0,0,0,0,8,0
0,8,0,4,0,0,0,0,0,0,0,0,0,8,0
0,8,0,0,0,0,0,0,0,0,0,0,0,8,0
0,0,0,0,0,0,0,0,0,0,0,0,0,8,0
0,0,0,0,0,0,0,0,0,0,0,0,0,0,0
0,0,0,0,0,0,0,0,0,0,0,0,0,0,0
0,8,0,11,11,0,0,0,0,0,0,0,0,0,0
0,8,0,0,0,0,0,0,0,0,0,0,0,0,0
0,8,0,0,0,0,0,0,0,0,0,0,0,0,0
0,8,0,0,0,0,0,0,0,0,0,0,0,0,0
1,1,1,0,0,0,0,0,0,0,0,0,0,0,0
1,2,1,0,0,0,0,0,8,8,8,8,0,2,0
1,1,1,0,0,0,0,0,0,0,0,0,1,0,0
endlayer

layer
1,1,1,1,1,1,1,1,1,1,1,1,1,1,0
1,2,2,2,2,2,2,2,2,2,2,2,2,2,0
1,2,1,1,1,1,1,1,1,1,1,1,1,2,0
1,2,1,4,6,6,6,6,6,6,6,6,1,2,0
1,2,1,6,6,6,6,6,6,6,6,6,1,2,0
1,2,1,6,6,6,6,6,6,6,6,0,0,2,0
1,2,1,6,6,6,6,6,6,6,0,0,0,2,0
1,2,1,11,11,6,6,6,6,6,0,0,0,2,0
1,2,1,0,0,6,6,6,6,0,0,0,0,2,0
1,2,1,0,0,6,6,6,6,0,0,0,0,2,0
1,2,1,0,0,6,6,6,0,0,0,0,0,2,0
1,2,1,0,0,6,6,6,0,0,0,0,0,2,0
1,2,1,1,1,1,1,1,0,0,0,0,0,2,0
1,2,2,2,2,2,2,2,2,2,2,2,2,2,0
1,1,1,1,1,1,1,1,1,1,1,1,1,0,0
endlayer

layer
1,1,1,0,0,0,0,0,0,0,0,0,0,0,0
1,2,1,8,8,8,8,0,0,0,0,0,0,2,0
1,1,1,0,0,0,0,0,0,0,0,0,0,0,0
0,0,0,4,0,0,0,0,0,0,0,0,0,0,0
0,0,0,0,0,0,0,0,0,0,0,0,0,0,0
0,0,0,0,0,0,0,0,0,0,0,0,0,0,0
0,0,0,0,0,0,0,0,0,0,0,0,0,0,0
0,0,0,0,0,0,0,0,0,0,0,0,0,0,0
0,0,0,0,0,0,0,0,0,0,0,0,0,0,0
0,0,0,0,0,0,0,0,0,0,0,0,0,0,0
0,0,0,0,0,0,0,0,0,0,0,0,0,0,0
0,0,0,0,0,0,0,0,0,0,0,0,0,0,0
0,0,0,0,0,0,0,0,0,0,0,0,0,0,0
0,2,0,0,0,0,0,0,0,0,0,0,0,2,0
0,0,0,0,0,0,0,0,0,0,0,0,0,0,0
endlayer

layer
1,1,1,0,0,0,0,0,5,0,0,0,0,0,0
1,2,1,8,8,8,5,0,0,0,0,0,0,2,0
1,1,1,0,0,0,0,0,0,0,0,0,0,0,0
0,0,0,4,0,0,0,0,0,0,0,0,0,0,0
0,0,0,0,0,0,0,0,0,0,0,0,0,0,0
0,0,0,0,0,0,0,0,0,0,0,0,0,0,0
0,0,0,0,0,0,0,0,0,0,0,0,0,0,0
0,0,0,0,0,0,0,0,0,0,0,0,0,0,0
0,0,0,0,0,0,0,0,0,0,0,0,0,0,0
0,0,0,0,0,0,0,0,0,0,0,0,0,0,0
0,0,0,0,0,0,0,0,0,0,0,0,0,0,0
0,0,0,0,0,0,0,0,0,0,0,0,0,0,0
0,0,0,0,0,0,0,0,0,0,0,0,0,0,0
0,2,0,0,0,0,0,0,0,0,0,0,0,2,0
0,0,0,0,0,0,0,0,0,0,0,0,0,0,0
endlayer

layer
1,1,1,0,0,0,0,0,0,0,0,0,0,0,0
1,2,1,8,8,5,0,8,0,0,0,0,0,2,0
1,1,0,0,0,0,0,0,0,0,0,0,0,0,0
0,0,0,4,0,0,0,0,0,0,0,0,0,0,0
0,0,0,0,0,0,5,0,0,0,0,0,0,0,0
0,0,0,0,0,0,0,0,0,0,0,0,0,0,0
0,0,0,0,0,0,0,0,0,0,0,0,0,0,0
0,0,0,0,0,0,0,0,0,0,0,0,0,0,0
0,0,0,0,0,0,0,0,0,0,0,0,0,0,0
0,0,0,0,0,0,0,0,0,0,0,0,0,0,0
0,0,0,0,0,0,0,0,0,0,0,0,0,0,0
0,0,0,0,0,0,0,0,0,0,0,0,0,0,0
0,0,0,0,0,0,0,0,0,0,0,0,0,0,0
0,2,0,0,0,0,0,0,0,0,0,0,0,2,0
0,0,0,0,0,0,0,0,0,0,0,0,0,0,0
endlayer

layer
1,1,1,0,0,0,0,0,0,0,0,0,0,0,0
1,2,0,0,0,5,8,8,0,0,0,0,0,2,0
1,1,0,0,0,0,0,0,0,0,0,0,0,0,0
0,0,0,4,0,0,0,0,0,0,0,0,0,0,0
0,0,0,0,0,0,0,0,0,0,0,0,0,0,0
0,0,0,0,0,0,0,0,0,0,0,0,0,0,0
0,0,0,0,0,0,0,0,0,0,0,0,0,0,0
0,0,0,0,0,0,0,0,0,0,0,0,0,0,0
0,0,0,0,0,0,0,0,0,0,0,0,0,0,0
0,0,0,0,0,0,0,0,0,0,0,0,0,0,0
0,0,0,0,0,0,0,0,0,0,0,0,0,0,0
0,0,0,0,0,0,0,0,0,0,0,0,0,0,0
0,0,0,0,0,0,0,0,0,0,0,0,0,0,0
0,0,0,0,0,0,0,0,0,0,0,0,0,2,0
0,0,0,0,0,0,0,0,0,0,0,0,0,0,0
endlayer

layer
1,1,0,0,0,0,0,0,0,0,0,0,0,0,0
1,2,0,0,5,8,8,8,8,0,0,0,0,2,0
1,1,1,0,0,0,0,0,0,0,0,0,0,0,0
0,0,0,4,0,0,0,0,0,0,0,0,0,0,0
0,0,0,0,0,0,0,0,0,0,0,0,0,0,0
0,0,0,0,0,0,0,0,0,0,0,0,0,0,0
0,0,0,0,0,0,0,0,0,0,0,0,0,0,0
0,0,0,0,0,0,0,0,0,0,0,0,0,0,0
0,0,0,0,0,0,0,0,0,0,0,0,0,0,0
0,0,0,0,0,0,0,0,0,0,0,0,0,0,0
0,0,0,0,0,0,0,0,0,0,0,0,0,0,0
0,0,0,0,0,0,0,0,0,0,0,0,0,0,0
0,0,0,0,0,0,0,0,0,0,0,0,0,0,0
0,0,0,0,0,0,0,0,0,0,0,0,0,2,0
0,0,0,0,0,0,0,0,0,0,0,0,0,0,0
endlayer

layer
1,1,0,0,0,0,0,0,0,0,0,0,0,0,0
1,2,0,8,8,8,8,8,8,8,0,0,0,2,0
0,1,1,0,0,0,0,0,0,0,0,0,0,0,0
0,0,0,4,0,0,0,0,0,0,0,0,0,0,0
0,0,0,0,0,0,0,0,0,0,0,0,0,0,0
0,0,0,0,0,0,0,0,0,0,0,0,0,0,0
0,0,0,0,0,0,0,0,0,0,0,0,0,0,0
0,0,0,0,0,0,0,0,0,0,0,0,0,0,0
0,0,0,0,0,0,0,0,0,0,0,0,0,0,0
0,0,0,0,0,0,0,0,0,0,0,0,0,0,0
0,0,0,0,0,0,0,0,0,0,0,0,0,0,0
0,0,0,0,0,0,0,0,0,0,0,0,0,0,0
0,0,0,0,0,0,0,0,0,0,0,0,0,0,0
0,0,0,0,0,0,0,0,0,0,0,0,0,2,0
0,0,0,0,0,0,0,0,0,0,0,0,0,0,0
endlayer

layer
1,1,1,1,1,1,1,1,1,1,1,1,0,0,0
0,2,2,2,2,2,2,2,2,2,2,2,2,2,0
0,2,1,1,1,1,1,1,1,1,1,1,1,2,0
0,2,1,4,6,6,6,6,6,6,6,6,1,2,0
0,2,1,6,6,6,6,6,6,6,0,0,0,2,0
0,2,1,6,6,6,6,0,0,0,0,0,0,2,0
0,0,1,0,0,0,0,0,0,0,0,0,0,2,0
0,0,0,0,0,0,0,0,0,0,0,0,0,2,0
0,0,0,0,0,0,0,0,0,0,0,0,0,2,0
0,0,0,0,0,0,0,0,0,0,0,0,0,2,0
0,0,0,0,0,0,0,0,0,0,0,0,0,2,0
0,0,0,0,0,0,0,0,0,0,0,0,0,2,0
0,0,0,0,0,0,0,0,0,0,0,0,0,2,0
0,0,0,0,0,0,0,0,2,2,2,2,2,2,0
0,0,0,0,0,0,0,0,0,0,0,0,0,0,0
endlayer

layer
0,0,0,0,0,0,0,0,0,0,0,0,0,0,0
0,0,0,0,0,0,0,0,0,0,0,0,0,0,0
0,0,0,0,0,0,0,0,0,0,0,0,0,0,0
0,0,0,4,0,0,0,0,0,0,0,0,0,0,0
0,0,0,0,0,0,0,0,0,0,0,0,0,0,0
0,0,0,0,0,0,0,0,0,0,0,0,0,0,0
0,0,0,0,0,0,0,0,0,5,0,0,0,0,0
0,0,0,0,0,0,0,0,0,0,0,0,0,0,0
0,0,0,0,0,0,0,0,5,0,0,0,0,0,0
0,0,0,0,0,0,0,0,0,0,0,0,0,0,0
0,0,0,0,0,0,0,0,0,0,0,0,0,0,0
0,0,0,0,0,0,0,0,0,0,0,0,0,0,0
0,0,0,0,0,0,0,0,0,0,0,0,0,0,0
0,0,0,0,0,0,0,0,0,0,0,0,0,2,0
0,0,0,0,0,0,0,0,0,0,0,0,0,0,0
endlayer

layer
0,0,0,0,0,0,0,0,0,0,0,0,0,0,0
0,0,0,0,0,0,0,0,0,0,0,0,0,0,0
0,0,0,0,0,0,0,0,0,0,0,0,0,0,0
0,0,0,14,0,5,0,0,0,0,0,0,0,0,0
0,0,0,0,0,5,0,0,0,0,0,0,0,0,0
0,0,0,0,0,0,0,0,0,0,0,0,0,0,0
0,0,0,0,0,0,0,0,0,0,0,0,0,0,0
0,0,0,0,0,0,0,5,0,0,0,0,0,0,0
0,0,0,0,0,0,0,0,0,0,0,0,0,0,0
0,0,0,0,0,0,0,0,0,0,0,0,0,0,0
0,0,0,0,0,0,0,0,0,0,0,0,0,0,0
0,0,0,0,0,0,0,0,0,0,0,0,0,0,0
0,0,0,0,0,0,0,0,0,0,0,0,0,0,0
0,0,0,0,0,0,0,0,0,0,0,0,0,2,0
0,0,0,0,0,0,0,0,0,0,0,0,0,0,0
endlayer

layer
0,0,0,0,0,0,0,0,0,0,0,0,0,0,0
0,0,0,0,0,0,0,0,0,0,0,0,0,0,0
0,0,0,0,5,0,0,0,0,0,0,0,0,0,0
0,0,0,0,0,5,0,0,0,0,0,0,0,0,0
0,0,0,0,0,0,0,0,0,0,0,0,0,0,0
0,0,0,0,0,0,0,0,0,0,0,0,0,0,0
0,0,0,0,0,0,0,0,0,0,0,0,0,0,0
0,0,0,0,0,0,0,0,0,0,0,0,0,0,0
0,0,0,0,0,0,0,0,0,0,0,0,0,0,0
0,0,0,0,0,0,0,0,0,0,0,0,0,0,0
0,0,0,0,0,0,0,0,0,0,0,0,0,0,0
0,0,0,0,0,0,0,0,0,0,0,0,0,0,0
0,0,0,0,0,0,0,0,0,0,0,0,0,0,0
0,0,0,0,0,0,0,0,0,0,0,0,0,2,0
0,0,0,0,0,0,0,0,0,0,0,0,0,0,0
endlayer

layer
0,0,0,0,0,0,0,0,0,0,0,0,0,0,0
0,0,0,0,0,0,0,0,0,0,0,0,0,0,0
0,0,0,0,0,0,0,0,0,0,0,0,0,0,0
0,0,0,0,0,0,0,0,0,0,0,0,0,0,0
0,0,0,0,0,0,0,0,0,0,0,0,0,0,0
0,0,0,0,0,0,0,0,0,0,0,0,0,0,0
0,0,0,0,0,0,0,0,0,0,0,0,0,0,0
0,0,0,0,0,0,0,0,0,0,0,0,0,0,0
0,0,0,0,0,0,0,0,0,0,0,0,0,0,0
0,0,0,0,0,0,0,0,0,0,0,0,0,0,0
0,0,0,0,0,0,0,0,0,0,0,0,0,0,0
0,0,0,0,0,0,0,0,0,0,0,0,0,0,0
0,0,0,0,0,0,0,0,0,0,0,0,0,0,0
0,0,0,0,0,0,0,0,0,0,0,0,0,2,0
0,0,0,0,0,0,0,0,0,0,0,0,0,0,0
endlayer

layer
0,0,0,0,0,0,0,0,0,0,0,0,0,0,0
0,0,0,0,0,0,0,0,0,0,0,0,0,0,0
0,0,0,0,0,0,0,0,0,0,0,0,0,0,0
0,0,0,0,0,0,0,0,0,0,0,0,0,0,0
0,0,0,0,0,0,0,0,0,0,0,0,0,0,0
0,0,0,0,0,0,0,0,0,0,0,0,0,0,0
0,0,0,0,0,0,0,0,0,0,0,0,0,0,0
0,0,0,0,0,0,0,0,0,0,0,0,0,0,0
0,0,0,0,0,0,0,0,0,0,0,0,0,0,0
0,0,0,0,0,0,0,0,0,0,0,0,0,0,0
0,0,0,0,0,0,0,0,0,0,0,0,0,0,0
0,0,0,0,0,0,0,0,0,0,0,0,0,0,0
0,0,0,0,0,0,0,0,0,0,0,0,0,0,0
0,0,0,0,0,0,0,0,0,0,0,0,0,15,0
0,0,0,0,0,0,0,0,0,0,0,0,0,0,0
endlayer

