
# Created by Ruins mod version 13.8 Ingame Parser
# authoring Player: OneWolfe

weight=4
unique=1
embed_into_distance=6
biomesToSpawnIn=mountains,swamp
acceptable_target_blocks=
unacceptable_target_blocks=flowing_water,water,flowing_lava,lava
dimensions=23,17,17
allowable_overhang=8
max_leveling=6
leveling_buffer=0
preserve_water=0
preserve_lava=0

rule1=0,100,preserveBlock
rule2=0,100,terrafirmacraft:StoneSed-0
rule3=0,100,air,air,terrafirmacraft:StoneIgExSmooth-2,terrafirmacraft:StoneSedSmooth-0,terrafirmacraft:StoneSedSmooth-0,terrafirmacraft:StoneIgExSmooth-2
rule4=0,100,air,terrafirmacraft:StoneSedSmooth-0,terrafirmacraft:StoneSedSmooth-0,terrafirmacraft:StoneSedSmooth-0,terrafirmacraft:StoneIgExSmooth-2
rule5=0,100,terrafirmacraft:Gravel-3
rule6=0,100,terrafirmacraft:StoneSedBrick-0,terrafirmacraft:StoneSedBrick-0,terrafirmacraft:StoneSedBrick-0,terrafirmacraft:StoneIgExBrick-2
rule7=0,100,air,terrafirmacraft:StoneIgExBrick-2,terrafirmacraft:StoneSedBrick-0
rule8=0,100,air,terrafirmacraft:WallBrickSed-0,terrafirmacraft:WallBrickIgEx-2,terrafirmacraft:WallBrickSed-0
rule9=0,100,air,ChestGenHook:dungeonChest:5-2,ChestGenHook:dungeonChest:5-2
rule10=0,100,air,ChestGenHook:dungeonChest:5-3,ChestGenHook:dungeonChest:5-3
rule11=0,100,terrafirmacraft:Dirt-3
rule12=0,100,air,terrafirmacraft:Torch-13
rule13=0,100,air,terrafirmacraft:Torch-10
rule14=0,100,air,terrafirmacraft:DryGrass-3
rule15=0,100,air,terrafirmacraft:Flowers2-7
rule16=0,100,air,terrafirmacraft:Flowers2-1
rule17=0,100,air,terrafirmacraft:Flowers-1
rule18=0,100,minecraft:iron_door-0
rule19=0,100,air
rule20=0,100,minecraft:iron_door-8
rule21=0,100,air,minecraft:iron_bars-0
rule22=0,100,air,terrafirmacraft:Flowers2-3
rule23=0,100,air,terrafirmacraft:Torch-5
#rule24=0,100,TwilightForest:tile.TFBossSpawner-2,TwilightForest:tile.TFBossSpawner-2,MobSpawner:TwilightForest.Troll,MobSpawner:TwilightForest.Skeleton Druid
rule24=0,100,TwilightForest:tile.TFBossSpawner-2
rule25=0,100,minecraft:ladder-4
rule26=0,100,terrafirmacraft:Torch-11
rule27=0,100,terrafirmacraft:WallBrickIgEx-2

layer
1,1,1,1,1,1,1,1,1,1,1,1,1,1,1,1,1
1,1,1,1,1,2,2,2,2,2,2,2,1,1,1,1,1
1,1,1,2,2,2,2,2,2,2,2,2,2,2,1,1,1
1,1,2,2,2,2,2,2,2,2,2,2,2,2,2,1,1
1,1,2,2,2,2,2,2,2,2,2,2,2,2,2,1,1
1,2,2,2,2,2,2,2,2,2,2,2,2,2,2,2,1
1,2,2,2,2,2,4,4,4,4,3,2,2,2,2,2,1
1,2,2,2,2,2,4,3,4,4,4,2,2,2,2,2,1
1,2,2,2,2,2,4,4,2,4,4,2,2,2,2,2,1
1,2,2,2,2,2,3,4,4,2,2,2,2,2,2,2,1
1,2,2,2,2,2,4,4,3,2,2,2,2,2,2,2,1
1,2,2,2,2,2,2,2,2,2,2,2,2,2,2,2,1
1,1,2,2,2,2,2,2,2,2,2,2,2,2,2,1,1
1,1,2,2,2,2,2,2,2,2,2,2,2,2,2,1,1
1,1,1,2,2,2,2,2,2,2,2,2,2,2,1,1,1
1,1,1,1,1,2,2,2,2,2,2,2,1,1,1,1,1
1,1,1,1,1,1,1,1,1,1,1,1,1,1,1,1,1
endlayer

layer
5,5,5,5,5,5,5,5,5,5,5,5,5,5,5,5,5
5,5,5,5,5,6,6,6,6,6,6,6,5,5,5,5,5
5,5,5,6,6,0,0,0,0,0,0,0,6,6,5,5,5
5,5,6,8,0,0,0,0,0,0,0,0,0,8,7,5,5
5,5,6,0,0,0,0,0,0,0,0,0,0,0,6,5,5
5,6,9,0,0,0,0,0,0,0,0,0,0,0,0,6,5
5,6,9,0,0,0,0,0,0,0,0,0,0,0,0,6,5
5,6,0,0,0,0,0,0,0,0,0,0,0,0,0,6,5
5,6,0,0,0,0,0,0,2,0,0,0,0,0,10,6,5
5,6,0,0,0,0,0,0,0,3,4,0,0,0,0,6,5
5,6,9,0,0,0,0,0,0,4,4,0,0,0,0,6,5
5,6,9,0,0,0,0,0,0,0,0,0,0,0,0,6,5
5,5,7,0,0,0,0,0,0,0,0,0,0,0,6,5,5
5,5,6,8,0,0,0,0,0,0,0,0,0,8,6,5,5
5,5,5,6,6,0,0,0,0,0,0,0,6,6,5,5,5
5,5,5,5,5,6,6,6,6,7,6,6,5,5,5,5,5
5,5,5,5,5,5,5,5,5,5,5,5,5,5,5,5,5
endlayer

layer
11,11,11,11,11,11,11,11,11,11,11,11,11,11,11,11,11
11,11,11,11,11,6,6,6,7,6,6,6,11,11,11,11,11
11,11,11,6,7,0,0,0,0,0,0,0,6,6,11,11,11
11,11,6,12,0,0,0,0,0,0,0,0,0,12,6,11,11
11,11,6,0,0,0,0,0,0,0,0,0,0,0,6,11,11
11,6,0,0,0,0,0,0,0,0,0,0,0,0,0,6,11
11,6,0,0,0,0,0,0,0,0,0,0,0,0,0,6,11
11,6,0,0,0,0,0,0,0,0,0,0,0,0,0,6,11
11,6,0,0,0,0,0,0,2,0,0,0,0,0,0,7,11
11,6,0,0,0,0,0,0,4,0,0,0,0,0,0,6,11
11,6,0,0,0,0,0,0,4,0,0,0,0,0,0,6,11
11,6,0,0,0,0,0,0,0,0,0,0,0,0,0,6,11
11,11,6,0,0,0,0,0,0,0,0,0,0,0,6,11,11
11,11,6,12,0,0,0,0,0,0,0,0,0,12,6,11,11
11,11,11,6,6,0,0,0,0,0,0,0,7,6,11,11,11
11,11,11,11,11,6,6,7,6,6,6,6,11,11,11,11,11
11,11,11,11,11,11,11,11,11,11,11,11,11,11,11,11,11
endlayer

layer
11,11,11,11,11,11,11,11,11,11,11,11,11,11,11,11,11
11,11,11,11,11,6,6,6,6,6,6,6,11,11,11,11,11
11,11,11,6,6,0,0,0,0,0,0,0,7,6,11,11,11
11,11,6,0,0,0,0,0,0,0,0,0,0,0,6,11,11
11,11,7,0,0,0,0,0,0,0,0,0,0,0,6,11,11
11,6,0,0,0,0,0,0,0,0,0,0,0,0,0,6,11
11,6,0,0,0,0,0,0,0,0,0,0,0,0,0,7,11
11,6,0,0,0,0,0,0,13,0,0,0,0,0,0,6,11
11,7,0,0,0,0,0,0,2,0,0,0,0,0,0,6,11
11,6,0,0,0,0,4,4,0,0,0,0,0,0,0,6,11
11,6,0,0,0,0,4,3,0,0,0,0,0,0,0,6,11
11,6,0,0,0,0,0,0,0,0,0,0,0,0,0,7,11
11,11,6,0,0,0,0,0,0,0,0,0,0,0,6,11,11
11,11,6,0,0,0,0,0,0,0,0,0,0,0,6,11,11
11,11,11,7,6,0,0,0,0,0,0,0,6,6,11,11,11
11,11,11,11,11,6,7,6,6,6,6,6,11,11,11,11,11
11,11,11,11,11,11,11,11,11,11,11,11,11,11,11,11,11
endlayer

layer
11,11,11,11,11,11,11,11,11,11,11,11,11,11,11,11,11
11,11,11,11,11,6,6,6,6,6,6,6,11,11,11,11,11
11,11,11,6,6,0,0,0,0,0,0,0,6,6,11,11,11
11,11,6,0,0,0,0,0,0,0,0,0,0,0,6,11,11
11,11,6,0,0,0,0,0,0,0,0,0,0,0,6,11,11
11,6,0,0,0,0,0,0,0,0,0,0,0,0,0,6,11
11,6,0,0,0,0,0,0,0,0,0,0,0,0,0,6,11
11,6,0,0,0,0,0,0,0,0,0,0,0,0,0,6,11
11,6,0,0,0,0,4,4,2,0,0,0,0,0,0,6,11
11,6,0,0,0,0,0,0,0,0,0,0,0,0,0,6,11
11,6,0,0,0,0,0,0,0,0,0,0,0,0,0,6,11
11,6,0,0,0,0,0,0,0,0,0,0,0,0,0,6,11
11,11,6,0,0,0,0,0,0,0,0,0,0,0,6,11,11
11,11,6,0,0,0,0,0,0,0,0,0,0,0,6,11,11
11,11,11,6,6,0,0,0,0,0,0,0,6,6,11,11,11
11,11,11,11,11,6,6,6,6,6,7,6,11,11,11,11,11
11,11,11,11,11,11,11,11,11,11,11,11,11,11,11,11,11
endlayer

layer
14,14,14,14,14,14,14,14,14,14,14,14,14,14,14,14,14
14,14,14,14,14,6,6,6,6,6,6,6,14,14,14,14,14
14,14,14,6,6,4,4,4,4,4,4,4,6,6,14,14,14
14,14,6,4,4,4,4,4,4,4,4,4,4,4,6,14,14
14,14,6,4,4,3,4,4,4,4,3,4,4,4,6,14,14
14,6,4,4,4,4,4,4,4,4,4,4,4,4,4,6,14
14,6,4,4,4,4,4,4,4,4,4,4,4,3,4,6,14
14,6,4,4,4,4,4,4,4,4,4,4,4,4,4,6,14
14,6,4,3,4,4,0,0,2,0,0,4,4,4,4,6,14
14,6,4,4,4,4,0,0,0,0,0,4,3,4,4,6,14
14,6,4,4,4,4,0,0,0,0,0,4,4,4,4,6,14
14,6,4,4,4,3,4,4,4,4,4,4,4,4,4,6,11
14,14,6,4,4,4,4,4,4,4,4,4,3,4,6,11,11
14,14,6,4,4,4,4,4,4,3,4,4,4,4,6,11,11
14,14,14,6,6,4,4,4,4,4,4,4,6,6,11,11,11
14,14,14,14,14,6,6,6,6,6,6,6,11,11,11,11,11
11,14,14,14,14,14,14,14,14,14,14,11,11,11,11,11,14
endlayer

layer
0,0,0,0,0,0,0,0,0,0,0,0,0,0,0,0,0
0,15,0,16,17,6,6,6,18,6,6,6,17,16,0,15,0
0,0,0,6,7,0,0,0,0,0,0,0,6,7,0,0,0
0,16,6,0,0,0,0,0,0,0,0,0,0,0,6,16,0
0,17,6,0,0,0,0,0,0,0,0,0,0,0,6,17,0
0,6,0,0,0,0,0,0,0,0,0,0,0,0,0,6,0
0,6,0,0,0,0,0,0,0,0,0,0,0,0,0,6,0
0,6,0,0,0,0,0,0,0,0,0,0,0,0,0,6,0
0,6,0,0,0,0,0,0,2,4,4,0,0,0,0,6,0
0,6,0,0,0,0,0,0,0,0,0,0,0,0,0,6,0
0,7,0,0,0,0,0,0,0,0,0,0,0,0,0,6,0
0,6,0,0,0,0,0,0,0,0,0,0,0,0,0,6,14
0,17,6,0,0,0,0,0,0,0,0,0,0,0,6,11,11
0,16,0,0,0,0,0,0,0,0,0,0,0,0,6,11,11
0,0,0,19,0,0,0,0,0,0,0,0,6,6,11,11,11
0,15,19,16,17,0,0,6,6,6,6,6,11,11,11,11,14
4,0,0,0,0,0,0,0,0,0,0,14,14,14,14,14,0
endlayer

layer
0,0,0,0,0,0,0,0,0,0,0,0,0,0,0,0,0
0,0,0,0,0,6,6,6,20,7,6,6,0,0,0,0,0
0,0,0,6,6,0,0,0,0,0,0,0,6,6,0,0,0
0,0,6,8,0,0,0,0,0,0,0,0,0,8,4,0,0
0,0,7,0,0,0,0,0,0,0,0,0,0,0,6,0,0
0,6,0,0,0,0,0,0,0,0,0,0,0,0,0,6,0
0,6,0,0,0,0,0,0,0,0,0,0,0,0,0,7,0
0,6,0,0,0,0,0,0,0,0,0,0,0,0,0,6,0
0,0,0,0,0,0,0,0,2,0,0,0,0,0,0,4,0
0,0,0,0,0,0,0,0,0,3,4,0,0,0,0,6,0
0,0,0,0,0,0,0,0,0,4,4,0,0,0,0,6,0
0,0,0,0,0,0,0,0,0,0,0,0,0,0,0,6,0
0,0,0,0,0,0,0,0,0,0,0,0,0,0,6,14,14
0,0,0,0,0,0,0,0,0,0,0,0,0,8,6,14,14
0,0,0,0,0,0,0,0,0,0,0,0,6,6,11,11,14
0,0,0,0,0,0,0,6,6,4,6,6,14,14,14,14,0
4,0,0,0,0,0,0,0,0,0,0,0,0,0,0,0,0
endlayer

layer
0,0,0,0,0,0,0,8,0,8,0,0,0,0,0,0,0
0,0,0,0,0,4,21,6,6,6,21,6,0,0,0,0,0
0,0,8,6,6,0,0,0,0,0,0,0,6,6,8,0,0
0,0,6,12,0,0,0,0,0,0,0,0,0,12,6,0,0
0,0,6,0,0,0,0,0,0,0,0,0,0,0,6,0,0
0,6,0,0,0,0,0,0,0,0,0,0,0,0,0,6,0
0,7,0,0,0,0,0,0,0,0,0,0,0,0,0,21,0
0,21,0,0,0,0,0,0,13,0,0,0,0,0,0,6,0
0,0,0,0,0,0,0,0,2,0,0,0,0,0,0,6,0
0,0,0,0,0,0,0,0,4,0,0,0,0,0,0,6,0
0,0,0,0,0,0,0,0,3,0,0,0,0,0,0,21,0
0,0,0,0,0,0,0,0,0,0,0,0,0,0,0,6,0
19,0,0,19,0,0,0,0,0,0,0,0,0,0,6,22,0
19,0,19,0,0,0,0,0,0,0,0,0,0,23,6,22,0
19,0,0,0,19,0,0,0,0,0,0,0,6,6,14,14,0
0,0,0,0,0,0,0,21,6,6,21,7,22,22,22,0,0
24,0,0,0,0,0,0,0,0,0,0,0,0,0,0,0,0
endlayer

layer
0,0,0,0,0,0,0,0,0,0,0,0,0,0,0,0,0
0,0,0,0,0,6,21,7,4,6,21,7,0,0,0,0,0
0,0,0,7,6,0,0,0,0,0,0,0,6,6,0,0,0
0,0,6,0,0,0,0,0,0,0,0,0,0,0,7,0,0
0,0,6,0,0,0,0,0,0,0,0,0,0,0,6,0,0
0,6,0,0,0,0,0,0,0,0,0,0,0,0,0,6,0
0,6,0,0,0,0,0,0,0,0,0,0,0,0,0,21,0
0,21,0,0,0,0,0,0,0,0,0,0,0,0,0,6,0
0,0,0,0,0,0,0,0,2,0,0,0,0,0,0,6,0
0,0,0,0,0,0,4,4,0,0,0,0,0,0,0,6,0
0,0,0,0,0,0,4,4,0,0,0,0,0,0,0,21,0
0,0,0,0,0,0,0,0,0,0,0,0,0,0,0,7,0
0,0,0,0,0,0,0,0,0,0,0,0,0,0,6,0,0
0,0,0,0,0,0,0,0,0,0,0,0,0,0,7,0,0
0,0,19,0,0,0,0,0,0,0,0,0,6,6,0,15,0
0,0,0,0,0,0,0,21,6,6,21,6,0,0,0,0,0
0,0,0,0,0,0,0,0,0,0,0,0,0,0,0,0,0
endlayer

layer
0,0,0,0,0,0,0,0,0,0,0,0,0,0,0,0,0
0,0,0,0,0,7,6,6,6,6,6,6,0,0,0,0,0
0,0,0,6,6,0,0,0,0,0,0,0,4,6,0,0,0
0,0,7,0,0,0,0,0,0,0,0,0,0,0,6,0,0
0,0,6,0,0,0,0,0,0,0,0,0,0,0,6,0,0
0,6,0,0,0,0,0,0,0,0,0,0,0,0,0,7,0
0,6,0,0,0,0,0,0,0,0,0,0,0,0,0,6,0
0,4,0,0,0,0,0,0,0,0,0,0,0,0,0,6,0
0,0,0,0,0,0,3,4,2,0,0,0,0,0,0,6,0
0,0,0,0,0,0,0,0,0,0,0,0,0,0,0,6,0
0,0,0,0,0,0,0,0,0,0,0,0,0,0,0,6,0
0,0,0,0,0,0,0,0,0,0,0,0,0,0,0,6,0
0,0,0,0,0,0,0,0,0,0,0,0,0,0,4,0,0
0,0,0,0,0,0,0,0,0,0,0,0,0,0,6,0,0
0,0,0,0,0,0,0,0,0,0,0,0,7,6,0,0,0
0,0,0,0,0,0,0,0,0,6,6,6,0,0,0,0,0
0,0,0,0,0,0,0,0,0,0,0,0,0,0,0,0,0
endlayer

layer
0,0,0,0,0,0,0,0,0,0,0,0,0,0,0,0,0
0,0,0,0,0,6,6,6,7,6,6,6,0,0,0,0,0
0,0,8,6,6,4,4,4,4,4,4,4,6,6,8,0,0
0,0,4,4,4,4,4,3,4,4,4,4,4,4,6,0,0
0,0,6,4,3,4,4,4,4,4,3,4,4,4,4,0,0
0,6,0,4,4,4,4,4,3,4,4,4,4,3,4,6,0
0,6,0,0,4,3,4,4,4,4,4,3,4,4,4,6,0
19,0,0,0,0,4,4,3,4,4,4,4,4,4,4,7,0
0,0,19,0,0,0,0,0,2,0,0,4,3,4,4,6,0
0,0,0,0,0,0,0,0,0,0,0,4,4,4,4,6,0
0,0,0,0,0,0,0,0,0,0,0,3,4,4,4,4,0
0,0,0,0,0,0,19,0,0,3,4,4,4,4,3,6,0
0,0,0,0,0,0,0,0,0,0,4,4,4,4,6,0,0
0,0,0,0,19,0,0,0,19,0,0,4,4,4,6,0,0
0,0,0,0,0,0,19,0,0,0,0,3,4,6,8,0,0
0,0,0,0,0,0,0,0,0,0,0,6,0,0,0,0,0
0,0,0,0,0,0,0,0,0,0,0,0,0,0,0,0,0
endlayer

layer
0,0,0,0,0,0,0,0,0,0,0,0,0,0,0,0,0
0,0,0,0,0,6,6,6,6,6,4,6,0,0,0,0,0
0,0,0,6,6,0,0,0,0,0,0,0,7,6,0,0,0
0,0,6,0,0,0,0,0,0,0,0,0,0,0,6,0,0
0,0,6,0,0,0,0,0,0,0,0,0,0,0,6,0,0
0,6,0,0,0,0,0,0,0,0,0,0,0,0,0,6,0
0,7,0,0,0,0,0,0,0,0,0,0,0,0,0,4,0
0,0,0,0,0,0,0,0,25,0,0,0,0,0,0,6,0
0,0,0,0,19,0,0,0,2,4,4,0,0,0,0,6,0
0,0,0,0,0,0,0,0,0,0,0,0,0,0,0,6,0
0,0,0,0,0,0,0,0,0,0,0,0,0,0,0,7,0
0,0,0,0,0,0,0,0,0,0,0,0,0,0,0,6,0
19,0,0,0,0,0,0,0,19,0,0,0,0,0,7,0,0
0,0,0,0,0,0,0,0,0,0,0,0,0,0,6,0,0
0,0,0,0,0,0,0,0,0,0,0,0,6,6,0,0,0
0,0,0,0,0,0,0,0,0,0,0,6,0,0,0,0,0
0,0,0,0,0,19,0,0,0,0,19,0,0,0,0,0,0
endlayer

layer
0,0,0,0,0,0,0,8,0,8,0,0,0,0,0,0,0
0,0,0,0,0,6,21,6,21,6,21,7,0,0,0,0,0
0,0,0,7,6,0,0,0,0,0,0,0,6,6,0,0,0
0,0,6,8,0,0,0,0,0,0,0,0,0,8,6,0,0
0,0,6,0,0,0,0,0,0,0,0,0,0,0,7,0,0
0,6,0,0,0,0,0,0,0,0,0,0,0,0,0,6,0
0,21,0,0,0,0,0,0,0,0,0,0,0,0,0,21,0
0,0,0,0,0,0,0,0,25,0,0,0,0,0,0,6,8
0,0,0,0,0,0,0,0,2,0,0,0,0,0,0,21,0
0,19,0,19,0,0,0,0,0,4,4,0,0,0,0,6,8
0,0,0,0,0,0,0,0,0,4,4,0,0,0,0,21,0
0,19,0,19,0,0,0,0,0,0,0,0,0,0,0,6,0
0,0,0,0,0,0,19,0,0,0,0,0,0,0,6,0,0
0,0,0,0,0,0,0,0,0,0,0,0,0,8,4,0,0
0,0,0,0,0,0,0,19,0,0,0,0,6,7,0,0,0
0,0,0,0,0,0,19,0,0,0,0,6,0,0,0,0,0
0,0,0,0,0,0,0,0,0,0,0,0,0,0,0,0,0
endlayer

layer
0,0,0,0,0,0,0,0,0,0,0,0,0,0,0,0,0
0,0,0,0,0,6,21,7,21,6,21,6,0,0,0,0,0
0,0,8,6,4,0,0,0,0,0,0,0,6,6,8,0,0
0,0,6,12,0,0,0,0,0,0,0,0,0,12,6,0,0
0,0,6,0,0,0,0,0,0,0,0,0,0,0,6,0,0
0,4,0,0,0,0,0,0,0,0,0,0,0,0,0,6,0
0,21,0,0,0,0,0,0,0,0,0,0,0,0,0,21,0
0,0,0,0,19,0,0,0,25,0,0,0,0,0,0,6,0
0,0,0,0,0,0,0,26,2,0,0,0,0,0,0,21,0
0,0,0,0,0,0,0,0,4,0,0,0,0,0,0,6,0
0,0,0,0,0,0,0,0,4,0,0,0,0,0,0,21,0
0,0,0,0,0,0,0,0,0,0,0,0,0,0,0,6,0
0,0,0,0,0,0,0,0,0,0,0,0,0,0,6,0,0
0,0,0,0,0,0,0,0,0,0,0,0,0,12,6,0,0
0,0,0,0,0,0,0,0,0,0,0,0,6,6,8,0,0
0,0,0,0,0,0,0,0,0,0,0,6,0,0,0,0,0
0,0,0,0,0,0,0,0,0,0,0,0,0,0,0,0,0
endlayer

layer
0,0,0,0,0,0,0,6,6,6,0,0,0,0,0,0,0
0,0,0,6,6,6,6,6,6,6,6,6,6,6,0,0,0
0,0,6,6,6,0,0,0,0,0,0,0,6,6,6,0,0
0,6,6,0,0,0,0,0,0,0,0,0,0,0,6,6,0
0,6,6,0,0,0,0,0,0,0,0,0,0,0,6,6,0
0,0,0,0,0,0,0,0,0,0,0,0,0,0,0,6,0
0,0,0,0,0,0,0,0,0,0,0,0,0,0,0,6,0
0,0,0,0,0,0,0,0,25,0,0,0,0,0,0,6,6
0,0,0,0,0,0,0,0,2,0,0,0,0,0,0,7,6
0,0,0,0,0,0,4,4,0,0,0,0,0,0,0,6,6
0,0,0,0,0,0,4,4,0,0,0,0,0,0,0,6,0
0,0,0,0,0,0,0,0,0,0,0,0,0,0,0,6,0
0,0,0,0,0,0,0,0,0,0,0,0,0,0,6,6,0
0,0,0,0,0,0,0,0,0,0,0,0,0,0,6,6,0
0,0,0,0,0,0,0,0,0,0,0,0,6,6,6,0,0
0,0,0,0,0,0,0,0,0,0,0,0,6,6,0,0,0
0,0,0,0,0,0,0,0,0,0,0,19,0,0,0,0,0
endlayer

layer
0,0,0,0,8,6,6,6,6,6,6,6,8,0,0,0,0
0,0,8,6,6,6,6,6,6,6,6,6,6,6,8,0,0
0,8,6,6,6,0,0,0,0,0,0,0,6,6,6,8,0
0,6,6,0,0,0,0,0,0,0,0,0,0,0,6,6,0
8,6,6,0,0,0,0,0,0,0,0,0,0,0,6,6,8
0,6,0,0,0,0,0,0,0,0,0,0,0,0,0,6,6
0,0,0,0,0,0,0,0,0,0,0,0,0,0,0,6,6
0,0,19,0,19,0,0,0,25,0,0,0,0,0,0,6,6
0,19,0,0,0,0,0,4,2,0,0,0,0,0,0,6,6
0,0,0,19,0,0,0,0,0,0,0,0,0,0,0,6,6
0,0,0,0,0,0,0,0,0,0,0,0,0,0,0,6,6
0,0,0,0,19,0,0,0,0,0,0,0,0,0,0,6,6
19,0,0,0,0,0,0,0,0,0,0,0,0,0,6,6,8
0,0,19,0,19,0,0,19,19,0,0,0,0,0,6,6,0
0,0,0,0,0,19,0,19,0,0,0,0,6,6,6,8,0
0,0,19,0,0,0,0,0,0,0,0,0,0,6,8,0,0
0,0,0,0,0,0,0,0,0,0,0,0,0,0,0,0,0
endlayer

layer
0,0,0,0,0,6,6,6,6,6,6,6,0,0,0,0,0
0,0,0,6,6,4,4,4,4,4,4,4,6,6,0,0,0
19,0,6,4,4,4,4,4,4,4,4,4,4,4,6,0,0
0,0,4,4,4,4,4,4,4,4,4,4,4,4,4,6,0
0,0,0,4,4,4,4,4,4,4,4,4,4,4,4,6,0
0,0,19,4,4,4,4,4,4,4,4,4,4,4,4,4,6
0,0,19,4,4,4,4,4,4,4,4,4,4,4,4,4,6
0,0,0,4,4,4,4,4,4,4,4,4,4,4,4,4,6
0,0,0,0,4,4,0,0,4,4,4,4,4,4,4,4,6
0,0,0,0,4,4,19,0,0,0,0,4,4,4,4,4,6
0,0,0,0,4,4,0,0,0,0,0,4,4,4,4,4,6
0,0,0,0,4,4,4,4,4,4,4,4,4,4,4,4,6
0,0,0,0,0,4,4,4,4,4,4,4,4,4,4,6,0
0,19,0,0,0,0,4,4,4,4,4,4,4,4,4,6,0
0,0,0,0,0,0,0,0,0,0,19,0,4,4,6,0,0
0,0,0,0,0,0,0,0,0,0,0,0,0,6,0,0,0
0,0,0,0,0,0,0,0,0,0,0,19,0,0,0,0,0
endlayer

layer
0,0,0,0,0,6,6,6,6,6,6,6,0,0,0,0,0
0,0,0,6,6,0,0,0,6,0,0,0,6,6,0,0,0
0,0,6,0,0,0,0,0,0,0,0,0,0,0,6,0,0
0,0,0,0,0,0,0,0,0,0,0,0,0,0,0,6,0
0,0,0,0,0,0,0,0,0,0,0,0,0,0,0,6,0
0,0,0,0,0,0,0,0,0,0,0,0,0,0,0,0,6
0,0,0,0,0,0,0,0,0,0,0,0,0,0,0,0,6
0,0,0,0,0,0,0,0,0,0,0,0,0,0,0,0,6
0,0,0,0,0,0,0,0,0,0,0,0,0,0,0,6,6
0,0,0,19,0,0,0,0,0,0,0,0,0,0,0,0,6
0,0,19,19,0,0,0,19,0,0,0,0,0,0,0,0,6
0,0,0,19,19,0,0,19,0,0,0,0,0,0,0,0,6
0,0,19,19,0,19,19,0,0,0,0,0,0,0,0,6,0
0,0,19,0,19,0,19,19,0,0,0,0,0,0,0,6,0
0,0,0,0,0,0,0,0,0,0,0,0,0,0,6,0,0
0,0,0,0,0,0,0,0,0,0,0,0,0,6,0,0,0
0,0,0,0,0,0,0,0,0,0,0,0,0,0,0,0,0
endlayer

layer
0,0,0,0,0,8,8,0,27,0,8,8,0,0,0,0,0
0,0,0,8,8,0,0,0,27,0,0,0,8,8,0,0,0
0,0,6,0,0,0,0,0,0,0,0,0,0,0,6,0,0
0,0,0,0,0,0,0,0,0,0,0,0,0,0,0,8,0
0,0,0,0,0,0,0,0,19,0,0,0,0,0,0,8,0
0,0,0,0,0,0,0,0,0,0,19,0,0,0,0,0,8
0,0,0,0,0,0,0,0,0,0,19,0,0,0,0,0,8
0,0,0,0,0,0,0,0,0,0,0,0,0,0,0,0,0
0,0,19,0,0,0,0,0,0,0,0,0,0,0,0,27,27
0,0,0,0,0,0,0,0,0,0,0,0,0,0,0,0,0
0,0,0,0,0,0,0,0,0,0,0,0,0,0,0,0,8
0,0,0,0,0,0,19,0,0,0,0,0,0,0,0,0,8
0,0,0,0,0,0,0,0,0,0,0,0,0,0,0,8,0
0,0,0,0,0,0,0,0,0,0,0,0,0,0,0,8,0
0,0,0,0,0,0,0,0,0,0,0,0,0,0,6,0,0
0,0,0,0,0,0,0,0,0,0,0,0,0,8,0,0,0
0,0,0,0,0,0,0,0,0,0,0,0,19,0,0,0,0
endlayer

layer
0,0,0,0,0,0,0,0,0,0,0,0,0,0,0,0,0
0,0,0,0,0,0,0,0,0,0,0,0,0,0,0,0,0
0,0,12,0,0,0,0,0,0,0,0,0,0,0,23,0,0
0,0,0,0,0,0,0,0,0,0,0,0,0,0,0,0,0
0,0,0,0,0,0,0,0,0,19,0,0,0,0,0,0,0
0,0,0,0,0,0,0,0,0,0,19,0,0,0,0,0,0
0,0,0,0,0,0,0,0,0,19,19,0,0,0,0,0,0
0,0,0,0,0,0,0,0,0,0,0,0,0,0,0,0,0
0,0,0,0,0,0,0,0,0,0,0,0,0,0,0,0,0
0,0,0,0,0,0,0,0,0,0,0,0,0,0,0,0,0
0,0,0,0,0,0,0,0,0,0,0,0,0,0,0,0,0
0,0,0,0,0,0,0,0,0,0,0,0,0,0,0,0,0
0,0,0,0,0,0,0,0,0,0,0,0,0,0,0,0,0
0,0,0,0,0,0,0,0,0,0,0,0,0,0,0,0,0
0,0,0,0,0,0,0,0,0,0,0,0,0,0,0,0,0
0,0,0,0,0,0,0,0,0,0,0,0,0,0,0,0,0
0,0,0,0,0,0,0,0,0,0,0,0,0,0,0,0,0
endlayer

layer
0,0,0,0,0,0,0,0,0,0,0,0,0,0,0,0,0
0,0,0,0,0,0,0,0,0,0,0,0,0,19,0,0,0
0,0,0,0,0,0,0,0,0,0,0,0,0,0,0,0,0
0,0,0,0,0,0,0,0,0,0,0,0,0,0,0,0,0
0,0,0,0,0,0,0,0,0,0,0,0,0,0,0,0,0
0,0,0,0,0,0,0,0,0,0,0,0,0,0,0,0,0
0,0,0,0,0,0,0,0,0,0,19,0,0,0,0,0,0
0,0,0,0,0,0,0,0,0,0,0,0,0,0,0,0,0
0,0,0,0,0,0,0,0,0,0,0,0,0,0,0,0,0
0,0,0,0,0,0,0,0,0,0,0,0,0,0,0,0,0
0,0,0,0,0,0,0,0,0,0,0,0,0,0,0,0,0
0,0,0,0,0,0,0,0,0,0,0,0,0,0,0,0,0
0,0,0,0,0,0,0,0,0,0,0,0,0,0,0,0,0
0,0,0,0,0,0,0,0,0,0,0,0,0,0,0,0,0
0,0,0,0,0,0,0,0,0,0,0,0,0,0,0,0,0
0,0,0,0,0,0,0,0,0,0,0,0,0,0,0,0,0
0,0,0,0,0,0,0,0,0,0,0,0,0,0,0,0,0
endlayer

layer
0,0,0,0,0,0,0,0,0,0,0,0,0,0,0,0,0
0,0,0,0,0,0,0,0,0,0,0,0,0,0,0,0,0
0,0,0,0,0,0,0,0,0,0,0,0,0,0,0,0,0
0,0,0,0,0,0,0,0,0,19,0,0,0,0,0,0,0
0,0,0,0,0,0,0,0,0,0,0,0,0,0,0,0,0
0,0,0,0,0,0,0,0,0,0,0,0,0,0,0,0,0
0,0,0,0,0,0,0,0,0,0,0,0,0,0,0,0,0
0,0,0,0,0,0,0,0,0,0,0,0,0,0,0,0,0
0,0,0,0,0,0,0,0,0,0,0,0,0,0,0,0,0
0,0,0,0,0,0,0,0,0,0,0,0,0,0,0,0,0
0,0,0,0,0,0,0,0,0,0,0,0,0,0,0,0,0
0,0,0,0,0,0,0,0,0,0,0,0,0,0,0,0,0
0,0,0,0,0,0,0,0,0,0,0,0,0,0,0,0,0
0,0,0,0,0,0,0,0,0,0,0,0,0,0,0,0,0
0,0,0,0,0,0,0,0,0,0,0,0,0,0,0,0,0
0,0,0,0,0,0,0,0,0,0,0,0,0,0,0,0,0
0,0,0,0,0,0,0,0,0,0,0,0,0,0,0,0,0
endlayer

