
# Created by Ruins mod version 13.8 Ingame Parser
# authoring Player: OneWolfe

weight=2
embed_into_distance=4
acceptable_target_blocks=
unacceptable_target_blocks=flowing_water,water,flowing_lava,lava
dimensions=40,14,24
allowable_overhang=8
max_leveling=6
leveling_buffer=0
preserve_water=0
preserve_lava=0
preserve_plants=1

rule1=0,100,preserveBlock
rule2=0,100,terrafirmacraft:StoneMMBrick-1,terrafirmacraft:StoneMMBrick-1,terrafirmacraft:StoneMMSmooth-1,terrafirmacraft:StoneMMSmooth-1
rule3=0,100,air,ChestGenHook:dungeonChest:5-3,MobSpawner:spiderTFC,MobSpawner:skeletonTFC
rule4=0,100,air,Steamcraft:pipe-0,Steamcraft:pipe-0,Steamcraft:pipe-0
rule5=0,100,terrafirmacraft:Vine-2
rule6=0,100,Railcraft:frame-0
rule7=0,100,Steamcraft:valvePipe-2
rule8=0,100,terrafirmacraft:Vine-1
rule9=0,100,Steamcraft:steamTank-0,Steamcraft:steamTank-0,Steamcraft:steamTank-0,air
rule10=0,100,terrafirmacraft:Vine-4
rule11=0,100,air,minecraft:anvil-0
rule12=0,100,Steamcraft:valvePipe-1
rule13=0,100,terrafirmacraft:Vine-8,terrafirmacraft:Vine-8,terrafirmacraft:Vine-8,air
rule14=0,100,air
rule15=0,100,terrafirmacraft:Vine-6,terrafirmacraft:Vine-6,terrafirmacraft:Vine-6,air
rule16=0,100,terrafirmacraft:FreshWaterStationary-0
rule17=0,100,terrafirmacraft:Vine-9
rule18=0,100,air,Steamcraft:hammer-3
rule19=0,100,terrafirmacraft:planks-2,terrafirmacraft:planks-2,terrafirmacraft:planks-2,air
rule20=0,100,IInventory;BiblioCraft:BiblioSeats;BiblioCraft:item.seatBack#1#5#1-5
rule21=0,100,terrafirmacraft:Vine-5
rule22=0,100,minecraft:stained_glass-8,minecraft:stained_glass-8,minecraft:stained_glass-8,air
rule23=0,100,terrafirmacraft:Vine-0
rule24=0,100,air,Steamcraft:heater-5
rule25=0,100,air,ChestGenHook:dungeonChest:5-3,MobSpawner:skeletonTFC,MobSpawner:caveSpiderTFC
rule26=0,100,air
rule27=0,100,BiblioCraft:Bibliotheca-5,BiblioCraft:Bibliotheca-5,BiblioCraft:Bibliotheca-5,BiblioCraft:Bibliotheca-5,air
rule28=0,100,air,BiblioCraft:BiblioDesk-5
rule29=0,100,IInventory;BiblioCraft:BiblioSeats;BiblioCraft:item.seatBack5#1#5#1-5
rule30=0,100,air,ChestGenHook:dungeonChest:5-3,MobSpawner:skeletonTFC,MobSpawner:spiderTFC,MobSpawner:skeletonTFC,MobSpawner:spiderTFC,
rule31=0,100,ChestGenHook:dungeonChest:5-3,MobSpawner:skeletonTFC,TwilightForest:tile.TFBossSpawner-1,TwilightForest:tile.TFBossSpawner-1
rule32=0,100,air,air,ChestGenHook:dungeonChest:5-3,minecraft:enchanting_table-0,minecraft:enchanting_table-0

layer
2,2,2,2,2,2,1,1,1,1,1,1,1,1,1,1,1,1,1,1,1,1,1,1
2,2,2,2,2,2,2,2,2,2,1,1,1,1,1,1,1,1,1,1,1,1,1,1
2,2,2,2,2,2,2,2,2,2,2,2,2,1,1,1,1,1,1,1,1,1,1,1
2,2,2,2,2,2,2,2,2,2,2,2,2,2,2,1,1,1,1,1,1,1,1,1
2,2,2,2,2,2,2,2,3,2,2,2,2,2,2,2,2,1,1,1,1,1,1,1
2,2,2,2,2,2,2,2,2,2,2,2,2,2,2,2,2,2,1,1,1,1,1,1
2,2,2,2,2,2,2,2,2,2,2,2,2,2,2,2,2,2,2,1,1,1,1,1
2,2,2,2,2,2,2,2,2,2,2,2,2,2,2,2,2,2,2,2,1,1,1,1
1,1,1,1,1,2,2,2,2,2,2,2,2,2,2,2,2,2,2,2,2,1,1,1
1,1,1,1,1,1,1,1,1,2,2,2,2,2,2,2,2,2,2,2,2,2,1,1
1,1,1,1,1,1,1,1,1,1,1,1,2,2,2,2,2,2,2,2,2,2,1,1
1,1,1,1,1,1,1,1,1,1,1,1,1,2,2,2,2,2,2,2,2,2,2,1
1,1,1,1,1,1,1,1,1,1,1,1,1,1,2,2,2,2,2,2,2,2,2,1
1,1,1,1,1,1,1,1,1,1,1,1,1,1,1,2,2,2,2,2,2,2,2,2
endlayer

layer
2,2,2,4,2,2,1,1,1,1,1,1,1,1,1,1,1,1,1,1,1,1,1,1
2,6,0,4,5,0,2,2,2,2,1,1,1,1,1,1,1,1,1,1,1,1,1,1
0,0,0,7,0,0,5,5,0,0,2,2,2,1,1,1,1,1,1,1,1,1,1,1
2,0,9,9,8,0,0,0,0,0,5,5,0,2,2,1,1,1,1,1,1,1,1,1
2,0,9,9,0,0,0,0,0,0,0,0,0,5,6,2,2,1,1,1,1,1,1,1
2,0,0,4,4,4,4,4,0,0,0,0,0,0,0,5,10,2,1,1,1,1,1,1
2,6,0,13,0,0,0,12,0,0,0,0,0,0,0,0,11,10,2,1,1,1,1,1
2,2,2,2,2,13,13,4,13,0,0,0,0,0,0,14,14,0,0,2,1,1,1,1
1,1,1,1,1,2,2,4,2,0,13,13,0,0,0,0,14,0,0,15,2,1,1,1
1,1,1,1,1,1,1,1,1,2,2,2,6,0,0,0,0,14,0,0,5,2,1,1
1,1,1,1,1,1,1,1,1,1,1,1,2,13,0,0,0,0,0,0,0,2,1,1
1,1,16,16,16,16,16,16,16,1,1,1,1,2,13,0,0,0,0,0,0,6,2,1
1,1,16,16,16,16,16,16,16,1,1,1,1,1,2,17,0,0,0,0,0,0,2,1
1,1,0,0,0,0,0,0,0,1,1,1,1,1,1,2,6,2,2,2,2,2,2,2
endlayer

layer
2,2,2,2,2,2,1,1,1,1,1,1,1,1,1,1,1,1,1,1,1,1,1,1
2,6,0,5,5,0,2,2,2,2,1,1,1,1,1,1,1,1,1,1,1,1,1,1
0,0,0,0,0,0,5,5,0,0,2,2,2,1,1,1,1,1,1,1,1,1,1,1
2,0,9,9,8,0,0,0,0,0,5,5,0,2,2,1,1,1,1,1,1,1,1,1
2,0,9,9,0,0,0,0,0,0,0,0,0,5,6,2,2,1,1,1,1,1,1,1
2,0,0,0,0,0,0,14,14,14,14,14,0,14,0,4,4,2,1,1,1,1,1,1
2,6,0,13,0,0,0,0,0,0,14,0,0,0,14,0,18,10,2,1,1,1,1,1
2,2,2,2,2,13,13,0,13,0,0,0,0,0,0,0,0,0,0,2,1,1,1,1
1,1,1,1,1,2,2,2,2,0,13,13,0,0,0,0,0,0,0,5,2,1,1,1
1,1,1,1,1,1,1,1,1,2,2,2,6,0,0,0,14,0,0,0,5,2,1,1
1,1,1,1,1,1,1,1,1,1,1,1,2,13,0,0,0,0,0,0,0,2,1,1
1,1,16,16,16,16,16,16,16,1,1,1,1,2,13,0,0,0,14,0,0,6,2,1
1,1,0,0,0,0,0,0,0,1,1,1,1,1,2,17,0,0,0,0,0,0,2,1
1,1,0,0,0,0,0,0,0,1,1,1,1,1,1,2,6,0,14,2,2,2,2,2
endlayer

layer
2,2,2,2,2,2,1,1,1,1,1,1,1,1,1,1,1,1,1,1,1,1,1,1
2,6,0,5,5,0,2,2,2,2,1,1,1,1,1,1,1,1,1,1,1,1,1,1
0,0,0,0,0,0,5,5,0,0,2,2,2,1,1,1,1,1,1,1,1,1,1,1
2,0,9,9,8,0,0,0,0,0,5,5,0,2,2,1,1,1,1,1,1,1,1,1
2,0,9,9,0,0,0,0,0,0,0,0,0,5,6,2,2,1,1,1,1,1,1,1
2,0,0,0,0,0,0,0,0,0,0,0,0,0,0,4,10,2,1,1,1,1,1,1
2,6,0,13,0,0,0,0,0,0,0,0,0,0,0,0,0,10,2,1,1,1,1,1
2,2,2,2,2,13,13,0,13,0,0,0,0,0,0,0,0,0,0,2,1,1,1,1
1,1,1,1,1,2,2,2,2,0,13,13,0,0,0,0,0,0,0,5,2,1,1,1
1,1,1,1,1,1,1,1,1,2,2,2,6,0,0,0,0,0,0,0,5,2,1,1
1,1,1,1,1,1,1,1,1,1,1,1,2,13,0,0,0,0,0,0,0,2,1,1
1,1,0,0,0,0,0,0,0,1,1,1,1,2,13,0,0,0,0,0,0,6,2,1
1,1,0,0,0,0,0,0,0,1,1,1,1,1,2,17,0,0,0,0,0,0,2,1
1,1,0,0,0,0,0,0,0,1,1,1,1,1,1,2,6,0,0,0,2,2,2,2
endlayer

layer
2,2,2,2,2,2,17,13,0,13,0,0,0,0,0,0,0,0,0,0,0,0,0,0
2,6,0,5,0,0,2,2,2,2,0,13,13,0,0,0,0,0,0,0,0,0,0,0
2,0,0,0,0,0,0,0,0,0,2,2,2,13,13,0,0,0,0,0,0,0,0,0
2,0,0,7,0,0,0,0,0,0,0,0,0,2,2,8,13,0,0,0,0,0,0,0
2,0,0,0,0,0,0,0,0,0,0,0,0,5,6,2,2,0,0,0,0,0,0,0
2,0,0,0,0,0,0,0,0,0,0,0,0,0,0,4,0,2,0,0,0,0,0,0
2,6,0,0,0,0,0,0,0,0,0,0,0,0,0,0,0,0,2,13,0,0,0,0
2,2,2,2,2,13,0,0,0,0,0,0,0,0,0,0,0,0,0,2,0,0,0,0
0,5,5,0,0,2,2,2,2,0,0,13,0,0,0,0,0,0,0,0,2,0,0,0
0,0,0,0,0,5,5,0,0,2,2,2,6,0,0,0,0,0,0,0,5,2,8,0
0,0,0,0,0,0,0,0,0,0,5,5,2,0,0,0,0,0,0,0,0,2,0,0
0,0,0,0,0,0,0,0,0,0,0,0,0,2,0,0,0,0,0,0,0,6,2,8
0,0,0,0,0,0,0,0,0,0,0,0,0,10,2,0,0,0,0,0,0,0,2,17
0,0,0,0,0,0,0,0,0,0,0,0,0,0,0,2,6,0,0,0,0,2,2,2
endlayer

layer
0,2,2,2,2,2,17,13,0,13,0,0,0,0,0,0,0,0,0,0,0,0,0,0
2,6,19,19,19,19,2,2,2,2,0,13,13,0,0,0,0,0,0,0,0,0,0,0
2,19,19,19,19,19,19,19,19,19,2,2,2,13,13,0,0,0,0,0,0,0,0,0
2,19,19,4,19,19,19,19,19,19,19,19,19,2,2,8,13,0,0,0,0,0,0,0
2,19,19,19,19,19,19,19,19,19,19,19,19,19,6,2,2,0,0,0,0,0,0,0
2,19,19,19,19,19,19,19,19,19,19,19,19,19,19,4,19,2,0,0,0,0,0,0
2,6,19,19,19,19,19,19,19,19,19,19,19,19,19,19,19,19,2,13,0,0,0,0
2,2,2,2,2,19,19,19,19,0,19,19,19,19,19,19,19,19,19,2,0,0,0,0
0,5,5,0,0,2,2,2,2,19,19,19,19,19,19,19,19,19,19,19,2,0,0,0
0,0,0,0,0,5,5,0,0,2,2,2,6,19,19,19,19,19,19,19,19,2,8,0
0,0,0,0,0,0,0,0,0,0,5,5,2,19,19,19,19,19,19,19,19,2,0,0
0,0,0,0,0,0,0,0,0,0,0,0,0,2,19,19,19,19,19,19,19,6,2,8
0,0,0,0,0,0,0,0,0,0,0,0,0,10,2,19,19,19,19,19,19,19,2,17
0,0,0,0,0,0,0,0,0,0,0,0,0,0,0,2,6,19,19,19,19,19,19,2
endlayer

layer
2,2,2,2,2,2,17,13,0,13,0,0,0,0,0,0,0,0,0,0,0,0,0,0
2,6,0,0,0,15,2,2,2,2,0,13,13,0,0,0,0,0,0,0,0,0,0,0
2,4,0,0,0,0,20,20,20,0,2,2,2,13,13,0,0,0,0,0,0,0,0,0
5,4,4,4,0,0,14,14,0,0,14,14,0,2,2,17,13,0,0,14,0,14,0,0
2,8,0,0,0,0,14,14,14,0,14,0,0,0,6,2,2,0,14,14,0,0,0,0
2,0,0,0,0,0,14,0,14,0,0,14,0,0,0,4,0,2,0,0,0,14,0,0
2,6,0,0,0,0,0,0,0,0,0,0,0,0,0,0,0,0,2,17,0,0,14,0
2,2,2,2,2,13,20,20,20,0,0,0,0,0,0,14,0,0,0,2,0,0,0,0
0,5,5,0,0,2,2,2,2,0,0,0,0,0,0,14,0,0,13,0,2,0,0,0
0,0,0,0,0,5,5,0,0,2,2,2,6,0,0,0,14,0,0,0,0,2,8,0
0,0,0,0,0,0,0,0,0,0,5,5,2,13,0,0,0,0,5,5,0,2,0,0
0,0,0,0,0,0,0,0,0,0,0,0,0,2,13,0,0,14,0,0,0,6,2,8
0,0,0,0,0,0,0,0,0,0,0,0,0,10,2,21,0,0,0,0,0,0,2,17
0,0,0,0,0,0,0,0,0,0,0,0,0,0,0,2,6,0,0,0,0,0,0,2
endlayer

layer
2,22,22,22,22,2,8,0,0,0,0,0,0,0,0,0,0,0,0,0,0,0,0,0
2,6,0,0,0,5,22,22,22,22,0,0,0,0,0,0,0,0,0,0,0,0,0,0
2,4,0,0,0,0,0,0,0,0,22,22,22,0,13,0,0,0,0,0,0,0,0,0
5,0,0,0,0,14,14,0,0,0,0,0,0,22,22,17,0,0,0,0,0,0,0,0
2,8,0,0,0,0,0,14,14,0,0,0,0,0,6,22,22,0,0,14,0,14,0,0
2,0,0,0,0,0,0,0,14,14,0,14,0,0,0,4,0,22,0,0,0,0,0,0
2,6,0,0,0,0,0,0,0,0,0,0,14,0,0,0,0,0,22,0,0,0,0,0
2,22,22,22,22,13,0,0,0,0,0,0,14,0,14,0,0,0,0,22,0,0,0,0
0,5,5,0,0,2,22,22,22,0,0,0,0,0,0,14,0,0,13,0,22,0,0,0
0,0,0,0,0,0,0,0,0,22,22,22,6,0,10,0,14,0,0,0,0,22,0,0
0,0,0,0,0,0,0,0,0,0,5,5,22,13,0,0,14,0,5,5,0,22,0,0
0,0,0,0,0,0,0,0,0,0,0,0,0,2,13,0,0,14,0,0,0,6,22,8
0,0,0,0,0,0,0,0,0,0,0,0,0,0,2,21,0,0,0,0,0,0,0,0
0,0,0,0,0,0,0,0,0,0,0,0,0,0,0,22,6,0,14,0,0,0,8,0
endlayer

layer
2,22,22,22,22,2,0,13,0,0,0,0,0,0,0,0,0,0,0,0,0,0,0,0
2,6,0,0,0,5,22,22,22,22,0,0,0,0,0,0,0,0,0,0,0,0,0,0
2,4,0,0,0,0,0,0,0,0,22,22,22,0,13,0,0,0,0,0,0,0,0,0
5,0,0,0,0,0,0,0,0,0,0,0,0,22,22,17,13,0,0,0,14,0,0,0
2,8,0,0,0,0,0,0,0,0,0,0,0,0,6,22,22,0,0,0,14,14,0,0
2,0,0,0,0,0,0,0,0,0,0,0,0,0,0,4,0,22,0,0,14,0,0,0
2,6,0,0,0,0,0,0,0,0,0,0,0,0,0,0,0,0,22,0,0,0,14,0
2,22,22,22,22,13,0,0,0,0,0,0,0,0,0,0,0,0,0,22,0,0,0,0
0,5,5,0,0,2,22,22,22,0,0,0,0,0,0,0,0,0,13,0,22,0,0,0
0,0,0,0,0,0,0,0,0,22,22,22,6,0,10,0,0,0,14,0,0,22,0,0
0,0,0,0,0,0,0,0,0,5,5,5,22,13,0,0,0,0,5,5,0,22,13,0
0,0,0,0,0,0,0,0,0,0,0,0,0,2,13,0,0,0,0,0,0,6,22,8
0,0,0,0,0,0,0,0,0,0,0,0,0,0,2,21,0,0,0,0,0,0,0,0
0,0,0,0,0,0,0,0,0,0,0,0,0,0,0,22,6,0,0,0,0,0,8,0
endlayer

layer
2,22,22,22,22,2,8,13,0,0,0,0,0,0,0,0,0,0,0,0,0,0,0,0
2,6,0,0,23,5,22,22,22,22,8,0,0,0,0,0,0,0,0,0,0,0,0,0
2,4,4,4,4,4,4,4,4,4,22,22,22,0,13,0,0,0,0,0,0,0,0,0
5,0,0,0,0,0,0,0,0,4,4,4,4,22,22,17,13,0,0,0,0,0,0,0
2,8,0,0,0,0,0,0,0,0,0,0,4,4,6,22,13,0,0,0,0,0,0,0
2,0,0,0,0,0,0,0,0,0,0,0,0,4,4,4,0,22,0,0,0,0,0,0
2,6,0,0,0,23,0,0,0,0,0,0,0,0,0,24,0,23,22,17,0,0,0,0
2,22,22,22,22,13,0,0,0,0,0,0,0,0,0,0,0,0,0,22,0,0,0,0
0,5,5,0,0,2,22,22,22,0,0,0,0,0,0,0,0,0,23,0,22,0,0,0
0,0,0,0,0,0,0,5,15,22,22,22,6,0,10,0,0,0,0,0,0,22,0,0
0,0,0,0,0,0,0,0,0,5,5,5,0,0,0,0,0,0,5,5,0,22,13,0
0,0,0,0,0,0,0,0,0,0,0,0,0,0,0,0,0,0,0,0,0,6,22,8
0,0,0,0,0,0,0,0,0,0,0,0,0,0,2,10,0,0,0,0,0,0,0,0
0,0,0,0,0,0,0,0,0,0,0,0,0,0,0,22,6,0,0,0,0,0,8,0
endlayer

layer
2,2,2,2,2,2,17,13,0,0,0,0,0,0,0,0,0,0,0,0,0,0,0,0
2,6,19,19,19,19,2,2,2,2,8,0,0,0,0,0,0,0,0,0,0,0,0,0
2,4,19,19,19,19,19,19,19,19,2,2,2,0,13,0,0,0,0,0,0,0,0,0
0,19,19,19,0,0,19,19,19,19,19,19,19,2,2,17,13,14,14,0,0,0,0,0
2,19,19,0,0,0,0,19,19,19,19,19,19,19,6,2,13,0,14,0,0,0,0,0
2,19,19,0,0,0,0,0,19,19,19,19,19,19,19,4,19,2,14,14,0,0,0,0
2,6,19,19,19,19,19,19,19,19,19,19,19,19,19,19,19,19,2,17,0,14,0,14
2,2,2,2,2,19,19,19,19,19,19,19,19,19,19,19,19,19,19,2,0,0,0,0
0,5,5,0,0,2,2,2,2,19,19,19,19,19,19,19,19,19,19,19,2,0,0,0
0,0,0,0,0,0,0,5,15,2,2,2,6,0,10,19,19,19,19,19,19,2,0,0
0,0,0,0,0,0,0,0,0,5,5,5,0,0,0,0,0,0,5,5,0,2,13,0
0,0,0,0,0,0,0,0,0,0,0,0,0,0,0,10,0,0,0,0,0,6,2,8
0,0,0,0,0,0,0,0,0,0,0,0,0,5,0,10,0,0,0,0,0,0,0,0
0,0,0,0,0,0,0,0,0,0,0,0,0,0,0,0,6,0,0,0,0,0,8,0
endlayer

layer
2,2,2,2,2,2,17,13,0,0,0,0,0,0,0,0,0,0,0,0,0,0,0,0
2,6,4,0,0,0,2,2,2,2,8,0,0,0,0,0,0,0,0,0,0,0,0,0
2,4,4,0,0,0,0,0,0,0,2,2,2,0,13,0,0,0,0,0,0,0,0,0
2,0,0,0,0,0,0,0,0,0,0,0,0,2,2,17,13,0,0,0,0,0,0,0
0,14,14,0,0,0,0,0,0,0,0,0,0,0,6,0,0,0,0,0,0,0,0,0
0,0,0,0,0,0,0,0,0,0,0,0,0,0,0,4,0,0,0,0,0,0,0,0
2,6,0,0,0,0,0,0,0,0,0,0,0,0,0,0,0,0,0,17,0,0,0,0
2,2,2,2,2,0,0,0,0,0,0,0,0,0,0,0,0,0,0,0,8,0,0,0
0,5,5,0,0,2,2,2,2,0,0,0,0,0,15,0,0,0,0,0,0,8,0,0
0,0,0,0,0,5,0,5,15,2,2,2,6,0,0,0,0,0,0,0,0,0,0,0
0,0,0,0,0,0,0,0,0,5,0,0,0,0,0,0,0,0,0,0,0,0,0,0
0,0,0,0,0,0,0,0,0,0,0,0,0,0,0,10,0,0,0,0,0,6,2,8
0,0,0,0,0,0,0,0,0,0,0,0,0,5,0,10,0,0,0,0,0,0,0,0
0,0,0,0,0,0,0,0,0,0,0,0,0,0,0,0,6,0,0,0,0,0,8,0
endlayer

layer
2,22,22,22,22,2,17,13,0,0,0,0,0,0,0,0,0,0,0,0,0,0,0,0
2,6,4,0,0,0,22,22,22,22,8,0,0,0,0,0,0,0,0,0,0,0,0,0
2,0,0,0,0,0,0,0,0,0,0,0,0,0,0,0,0,0,0,0,0,0,0,0
0,0,0,0,0,0,0,0,0,0,0,0,0,0,0,13,13,0,0,0,0,0,0,0
0,0,0,0,0,14,0,0,0,0,0,0,0,0,6,22,22,0,0,0,0,0,0,0
0,0,0,0,0,0,0,0,0,0,0,0,0,0,0,4,0,0,0,0,0,0,0,0
2,6,0,0,0,0,0,0,0,0,0,0,0,0,0,0,14,0,0,17,0,0,0,0
2,22,22,22,22,0,0,0,0,0,0,0,0,0,0,0,14,0,14,0,8,0,0,0
0,5,5,0,15,2,22,22,22,0,0,0,0,0,15,0,0,0,0,0,0,8,0,0
0,0,0,0,0,5,0,5,0,22,22,22,6,0,0,0,0,0,0,0,0,0,0,0
0,0,0,0,0,0,0,0,0,0,0,0,0,0,0,0,14,0,0,0,0,0,0,0
0,0,0,0,0,0,0,0,0,0,0,0,0,0,0,10,14,0,0,0,0,6,22,8
0,0,0,0,0,0,0,0,0,0,0,0,0,5,0,10,0,0,0,0,0,0,0,0
0,0,0,0,0,0,0,0,0,0,0,0,0,0,14,0,6,0,0,0,0,0,8,0
endlayer

layer
2,22,22,22,22,2,17,13,13,0,0,0,0,0,0,0,0,0,0,0,0,0,0,0
2,6,4,0,0,0,22,22,22,22,8,0,0,14,14,0,0,0,0,0,0,0,0,0
2,0,0,0,0,0,0,0,0,0,0,0,14,0,0,0,0,0,0,0,0,0,0,0
0,0,0,0,0,0,0,0,0,0,0,0,0,0,0,13,13,0,0,0,0,0,0,0
0,0,14,0,0,0,0,0,0,0,0,0,0,0,6,22,22,0,0,0,0,0,0,0
0,0,0,0,0,0,0,0,0,0,0,0,0,0,0,4,0,22,0,0,0,0,0,0
2,6,0,0,0,0,0,0,0,0,0,0,0,0,0,0,0,0,0,17,0,0,0,0
2,22,22,22,22,0,0,0,0,0,0,0,0,0,0,0,0,0,0,0,8,0,0,0
0,5,5,5,15,2,22,22,0,0,0,0,0,0,15,0,0,0,0,0,0,8,0,0
0,0,0,0,0,5,0,5,0,0,22,22,6,0,0,0,0,0,0,0,0,0,0,0
0,0,0,0,0,0,0,0,0,0,0,0,0,0,0,0,0,0,0,0,0,0,0,0
0,0,0,0,0,0,0,0,0,0,0,0,0,0,0,10,0,0,0,0,0,6,22,8
0,0,0,0,0,0,0,0,0,0,0,0,0,15,0,10,0,0,0,0,0,0,0,0
0,0,0,0,0,0,0,0,0,0,0,0,0,0,0,0,6,0,0,0,0,0,8,0
endlayer

layer
2,22,22,22,22,2,17,13,13,0,0,0,0,0,0,0,0,0,0,0,0,0,0,0
2,6,4,0,0,0,22,22,22,22,8,0,0,0,14,0,0,0,0,0,0,0,0,0
2,0,0,0,0,0,0,0,0,0,0,0,0,0,0,0,0,0,0,0,0,0,0,0
0,0,0,0,0,0,0,0,0,0,0,0,0,0,0,13,13,0,0,0,0,0,0,0
0,0,0,0,0,0,0,0,14,0,0,0,0,0,6,22,22,0,0,0,0,0,0,0
2,0,0,0,0,0,0,0,0,0,0,0,0,0,0,4,0,22,0,0,0,0,0,0
2,6,0,0,0,0,0,0,0,14,0,0,0,0,0,24,0,0,2,17,0,0,0,0
2,22,22,22,22,0,0,0,0,0,0,0,0,0,0,0,0,0,0,2,8,0,0,0
0,5,5,5,15,2,22,0,0,14,0,0,0,0,15,0,0,0,0,0,0,8,0,0
0,0,0,0,0,5,0,5,0,0,22,22,6,0,0,0,0,0,0,0,0,0,8,0
0,0,0,0,0,0,0,0,0,0,0,0,0,0,0,0,0,0,0,0,0,22,0,0
0,0,0,0,0,0,0,0,0,0,0,0,0,0,0,10,0,0,0,0,0,6,22,8
0,0,0,0,0,0,0,0,0,0,0,0,0,15,0,10,0,0,0,0,0,0,0,0
0,0,0,0,0,0,0,0,0,0,0,0,0,0,0,0,6,0,0,0,0,0,8,0
endlayer

layer
2,2,2,2,2,2,17,13,13,0,0,0,0,0,0,0,0,0,0,0,0,0,0,0
2,6,4,19,19,19,2,2,2,2,8,13,0,0,0,0,0,0,0,0,0,0,0,0
2,19,19,19,19,19,19,0,0,0,0,0,14,0,0,0,0,0,0,0,0,0,0,0
2,19,19,19,19,19,0,0,0,14,0,0,0,0,0,13,13,0,0,0,0,0,0,0
2,19,19,19,19,19,0,0,0,0,19,19,0,0,6,2,2,0,0,0,0,0,0,0
2,19,19,19,19,19,0,0,0,0,19,19,0,19,19,4,19,2,0,0,0,0,0,0
2,6,19,19,19,19,0,0,0,0,19,19,19,19,19,19,19,19,2,17,0,0,0,0
2,2,2,2,2,19,0,0,0,0,19,19,19,19,19,19,19,19,19,2,8,0,0,0
0,5,5,5,15,2,0,0,0,0,19,19,19,19,15,19,19,19,19,19,2,8,0,0
0,0,0,0,0,5,0,5,0,0,0,2,6,0,0,0,19,19,19,19,19,2,8,0
0,0,0,0,0,0,0,0,0,0,0,0,0,0,0,0,19,19,19,19,19,2,0,0
0,0,0,0,0,0,0,0,0,0,0,0,0,0,0,10,19,19,19,19,19,6,2,8
0,0,0,0,0,0,0,0,0,0,0,0,0,15,0,10,19,19,19,19,19,19,0,0
0,0,0,0,0,0,0,0,0,0,0,0,0,0,5,0,10,19,19,19,19,19,8,0
endlayer

layer
2,2,2,2,2,2,17,13,13,13,0,0,0,0,0,0,0,0,0,0,0,0,0,0
2,6,4,0,0,0,2,2,2,2,8,13,0,0,0,0,0,0,0,0,0,0,0,0
2,0,0,0,0,0,0,0,0,0,0,14,14,0,0,0,0,0,0,0,0,0,0,0
2,0,0,0,0,0,0,0,0,0,0,0,0,0,0,13,13,0,0,0,0,0,0,0
2,14,0,0,0,0,0,0,0,14,0,0,0,0,6,2,2,0,0,0,0,0,0,0
2,0,14,0,0,0,0,0,0,14,0,0,0,0,0,4,0,2,0,0,0,0,0,0
2,6,0,0,0,0,0,0,0,0,0,0,0,0,0,0,0,0,2,13,0,0,0,0
2,2,2,2,2,0,0,0,0,0,0,0,0,0,0,0,0,0,0,2,8,0,0,0
0,5,5,5,15,2,0,0,0,0,0,0,0,0,0,0,0,0,0,0,2,0,0,0
0,0,0,0,0,5,0,5,0,0,2,2,6,0,0,0,0,0,0,0,0,2,8,0
0,0,0,0,0,0,0,0,0,0,0,0,0,0,0,14,0,0,0,0,0,2,0,0
0,0,0,0,0,0,0,0,0,0,0,0,0,0,0,0,0,0,0,0,0,6,2,0
0,0,0,0,0,0,0,0,0,0,0,0,0,15,0,0,0,0,5,5,0,0,0,0
0,0,0,0,0,0,0,0,0,0,0,0,0,0,5,2,6,0,0,0,0,0,0,0
endlayer

layer
0,0,14,0,0,2,8,13,13,13,0,0,0,0,0,0,0,0,0,0,0,0,0,0
2,6,4,0,0,0,0,22,22,22,8,13,13,0,14,14,0,0,0,0,0,0,0,0
2,0,0,0,0,0,0,0,0,0,0,0,0,0,0,0,0,0,0,0,0,0,0,0
2,0,0,0,0,0,0,0,0,0,0,0,0,0,14,0,0,0,0,0,0,0,0,0
2,0,0,0,0,0,0,0,0,0,0,0,0,0,6,22,22,0,0,0,0,0,0,0
2,0,0,0,0,0,0,0,0,0,0,0,0,0,0,4,0,22,0,0,0,0,0,0
2,6,0,0,0,0,0,0,0,0,0,0,0,0,0,0,0,0,2,13,0,0,0,0
0,0,0,0,0,0,0,0,0,0,0,0,0,0,0,14,0,0,0,2,8,0,0,0
0,0,0,0,15,2,22,0,0,0,0,0,0,0,0,14,0,0,0,0,22,0,0,0
0,0,0,0,0,5,0,5,0,0,22,22,6,0,0,0,14,0,0,0,0,22,8,0
0,0,0,0,0,0,0,0,0,0,0,0,22,0,0,0,0,0,0,0,0,22,0,0
0,0,0,0,0,0,0,0,0,0,0,0,0,0,0,0,0,0,0,0,0,6,22,0
0,0,0,0,0,0,0,0,0,0,0,0,0,15,0,0,0,0,5,5,0,0,0,0
0,0,0,0,0,0,0,0,0,0,0,0,0,0,5,22,6,0,0,0,0,0,0,0
endlayer

layer
0,0,0,0,0,2,8,13,13,13,0,0,0,0,0,0,0,0,0,0,0,0,0,0
2,6,4,0,0,0,0,22,22,22,8,13,13,0,0,0,0,0,0,0,0,0,0,0
2,0,0,0,0,0,0,0,0,0,0,0,0,0,0,0,0,0,0,0,0,0,0,0
2,0,0,0,0,0,0,0,0,0,0,0,0,0,0,0,0,0,0,0,0,0,0,0
2,0,0,0,0,0,0,0,0,0,0,0,0,0,6,22,22,0,0,0,0,0,0,0
2,0,0,0,0,0,0,0,0,0,0,0,0,0,0,4,0,22,0,0,0,0,0,0
2,6,0,0,0,0,0,0,0,0,0,0,0,0,0,0,0,0,2,13,0,0,0,0
0,0,0,0,0,0,0,0,0,0,0,0,0,0,0,0,0,0,0,2,8,0,0,0
0,0,0,0,15,2,22,0,0,0,0,0,0,0,0,0,0,0,0,0,22,0,0,0
0,0,0,0,0,5,0,5,0,0,22,22,6,0,0,0,0,0,0,0,0,22,8,0
0,0,0,0,0,0,0,0,0,0,0,0,22,0,0,0,0,0,0,0,0,22,0,0
0,0,0,0,0,0,0,0,14,0,0,0,0,2,0,0,0,0,0,0,0,6,22,0
0,0,0,0,0,0,0,0,0,0,0,0,0,15,2,0,0,0,5,5,0,0,0,0
0,0,0,0,0,0,0,0,0,0,0,0,0,0,5,22,6,0,0,0,0,0,0,0
endlayer

layer
0,0,0,0,0,2,8,13,13,13,0,0,0,0,0,0,0,0,0,0,0,0,0,0
2,6,4,0,0,0,0,22,22,22,8,13,13,0,0,0,0,0,0,0,0,0,0,0
2,0,0,0,0,0,0,0,0,0,0,0,0,0,0,0,0,0,0,0,0,0,0,0
2,14,0,0,0,0,0,0,0,0,0,0,0,0,0,0,0,0,0,0,0,0,0,0
2,14,0,0,0,0,0,0,0,0,0,0,0,0,6,22,22,0,0,0,0,0,0,0
2,0,0,0,0,0,0,0,0,0,0,0,0,0,0,4,0,22,0,0,0,0,0,0
2,6,0,0,0,0,0,0,0,0,0,0,0,0,0,0,0,0,2,13,0,0,0,0
0,0,0,0,0,0,0,0,0,0,0,0,0,0,0,0,0,0,0,2,8,0,0,0
0,0,0,0,15,2,22,0,0,0,0,0,0,0,0,0,0,0,0,0,22,0,0,0
0,0,0,0,0,5,0,5,0,0,22,22,6,0,0,0,0,0,0,0,0,22,8,0
0,0,0,0,0,0,0,0,0,0,5,0,22,0,0,0,0,0,0,0,0,22,0,0
0,0,0,0,0,0,0,0,14,0,0,0,0,2,0,0,0,0,0,0,0,6,22,0
0,0,0,0,0,0,0,0,0,0,0,0,0,15,2,0,0,0,5,5,0,0,0,8
0,0,0,0,0,0,0,0,0,0,0,0,0,0,5,22,6,0,0,14,0,0,0,0
endlayer

layer
0,2,2,2,2,2,0,13,13,13,0,0,0,0,0,0,0,0,0,0,0,0,0,0
2,6,4,19,19,19,2,2,2,2,8,13,13,0,0,0,0,0,0,0,0,0,0,0
2,2,19,19,19,19,19,19,19,19,2,2,2,17,0,0,0,0,0,0,0,0,0,0
2,2,19,19,19,19,19,19,19,19,19,19,19,2,2,0,0,0,0,0,0,0,0,0
2,2,19,19,19,19,19,19,19,19,19,19,19,19,6,2,2,0,0,0,0,0,0,0
2,2,19,19,19,19,19,19,19,19,19,19,19,19,19,4,19,2,0,0,0,0,0,0
2,6,19,19,19,19,19,19,19,19,19,19,19,19,19,19,19,19,2,13,0,0,0,0
0,0,0,19,19,19,19,19,19,19,19,19,19,19,19,19,19,19,19,2,8,0,0,0
0,0,0,5,15,2,2,0,0,0,19,19,19,19,19,19,25,19,19,19,2,0,0,0
0,0,0,0,0,5,5,5,14,0,2,2,6,19,19,19,19,19,19,19,19,2,8,0
0,0,0,0,0,0,0,0,0,0,5,0,2,19,19,19,19,19,19,19,0,2,0,0
0,0,0,0,0,0,0,0,14,0,0,0,0,2,19,19,19,19,19,19,19,6,2,0
0,0,0,0,0,0,0,0,0,0,0,0,0,15,2,19,19,0,5,5,0,0,0,8
0,0,0,0,0,0,0,0,0,0,0,0,0,0,5,2,6,0,0,0,0,0,0,0
endlayer

layer
2,2,2,2,2,2,0,0,13,13,0,0,0,0,0,0,0,0,0,0,0,0,0,0
2,6,4,0,0,0,2,2,2,2,8,13,13,0,0,0,0,0,0,0,0,0,0,0
0,0,0,0,0,0,0,0,0,0,2,2,2,17,0,0,0,0,0,0,0,0,0,0
0,0,0,0,0,0,0,0,0,0,0,0,0,2,2,0,0,0,0,0,0,0,0,0
0,0,0,0,0,0,0,0,0,0,0,0,0,0,6,0,0,0,0,0,0,0,0,0
0,0,0,0,0,0,0,0,0,0,0,0,0,0,0,4,0,0,0,0,0,0,0,0
2,6,0,0,0,0,0,0,0,0,0,0,0,0,0,0,0,10,2,13,0,0,0,0
0,0,0,0,0,13,0,0,0,0,0,0,0,0,0,0,0,0,5,2,8,0,0,0
0,0,0,5,15,2,2,0,0,0,0,0,0,0,8,0,14,0,0,5,0,0,0,0
0,0,0,0,0,5,5,5,0,0,2,2,6,0,0,0,0,0,14,0,0,0,0,0
0,0,0,0,0,0,0,0,0,0,5,0,2,8,0,0,0,0,0,14,0,0,0,0
0,0,0,0,0,0,0,0,0,0,0,0,0,0,0,0,0,0,0,0,0,6,0,0
0,0,0,0,0,0,0,0,0,0,0,0,0,10,2,0,0,0,0,0,0,0,0,8
0,0,0,0,0,0,0,0,0,0,0,0,0,0,0,0,6,0,0,0,0,0,0,0
endlayer

layer
2,0,0,0,0,2,8,0,0,0,0,0,0,0,0,0,0,0,0,0,0,0,0,0
2,6,14,0,0,0,22,22,22,22,0,13,13,0,0,0,0,0,0,0,0,0,0,0
2,0,0,0,0,0,0,0,0,0,22,22,22,17,0,0,0,0,0,0,0,0,0,0
2,0,0,0,0,0,0,0,0,0,0,0,0,22,22,0,0,0,0,0,0,0,0,0
2,0,0,0,0,0,0,0,0,0,0,0,0,0,6,0,0,0,0,0,0,0,0,0
2,0,0,0,0,0,0,0,0,0,0,0,0,0,0,4,0,0,0,0,0,0,0,0
2,6,0,0,0,0,0,0,0,0,0,0,0,0,0,0,0,10,2,13,0,0,0,0
0,22,0,0,0,0,0,0,0,0,0,0,0,0,0,0,0,0,5,2,8,0,0,0
0,0,0,5,15,2,22,0,0,0,0,0,0,0,8,0,0,0,0,5,0,0,0,0
0,0,0,0,0,5,5,5,0,0,22,22,6,0,0,0,0,0,0,0,0,0,0,0
0,0,0,0,0,0,0,0,0,0,5,0,22,8,0,0,14,0,0,0,0,0,8,0
0,0,0,0,0,0,0,0,0,0,0,0,0,0,0,0,0,0,0,0,0,6,0,0
0,0,0,0,0,0,0,0,0,0,0,0,0,15,2,0,0,0,0,0,0,0,0,8
0,0,0,0,0,0,0,0,0,0,0,0,0,0,0,0,6,0,0,0,0,0,0,0
endlayer

layer
2,22,0,0,0,2,8,0,0,0,0,0,0,0,0,0,0,0,0,0,0,0,0,0
2,6,14,0,0,0,22,22,22,22,0,13,13,0,0,0,0,0,0,0,0,0,0,0
2,0,0,0,0,0,0,0,0,0,22,22,22,17,0,0,0,0,0,0,0,0,0,0
2,0,0,0,0,0,0,0,0,0,0,0,0,22,22,0,13,0,0,0,0,0,0,0
2,0,0,0,0,0,0,0,0,0,0,0,0,0,6,0,0,0,0,0,0,0,0,0
2,0,0,0,0,0,0,0,0,0,0,0,0,0,0,4,0,0,0,0,0,0,0,0
2,6,0,0,0,0,0,0,0,0,0,0,0,0,0,24,0,10,2,13,0,0,0,0
2,22,0,0,0,0,0,0,0,0,0,0,0,0,0,0,0,0,5,2,8,0,0,0
0,0,0,5,15,2,22,0,0,0,0,0,0,0,8,0,0,0,0,5,0,0,0,0
0,0,0,0,0,5,5,5,0,0,22,22,6,0,0,0,0,0,0,0,0,0,0,0
0,0,0,0,0,0,0,0,0,0,5,0,22,8,0,0,14,14,0,0,0,0,8,0
0,0,0,0,0,0,0,0,0,0,0,0,0,14,0,0,0,0,14,0,0,6,0,0
0,0,0,0,0,0,0,0,0,0,0,0,0,15,2,0,0,14,0,0,0,0,0,8
0,0,0,0,0,0,0,0,0,0,0,14,14,0,0,0,6,0,0,0,0,0,0,0
endlayer

layer
2,22,22,0,22,2,8,0,0,13,0,0,0,0,0,0,0,0,0,0,0,0,0,0
2,6,14,0,0,0,22,22,22,22,0,13,13,0,0,0,0,0,0,0,0,0,0,0
2,0,0,0,0,0,0,0,0,0,22,22,22,17,0,0,0,0,0,0,0,0,0,0
2,0,0,0,0,0,0,0,0,0,0,0,0,22,22,0,13,0,0,0,0,0,0,0
2,0,0,0,0,0,0,0,0,0,0,0,0,0,6,0,0,0,0,0,0,0,0,0
2,0,0,0,0,0,0,0,0,0,0,0,0,0,0,8,0,0,0,0,0,0,0,0
2,6,0,0,0,0,0,0,0,0,0,0,0,0,0,8,0,10,2,13,0,0,0,14
2,22,22,22,22,0,0,0,0,0,0,0,0,0,0,0,0,0,5,2,8,0,0,0
0,0,0,5,15,2,22,22,22,0,0,0,0,0,8,0,0,0,0,5,0,0,0,0
0,0,0,0,0,5,5,5,0,22,22,22,6,0,0,0,0,0,0,14,0,0,0,0
0,0,0,0,0,0,0,0,0,0,5,0,22,8,14,0,0,0,0,0,0,0,8,0
0,0,0,0,0,0,0,0,0,0,0,0,0,14,0,14,0,0,0,0,0,6,0,0
0,0,0,0,0,0,0,0,0,0,0,0,0,15,2,0,0,0,0,0,0,0,0,8
0,0,0,0,0,0,0,0,0,0,0,0,0,0,5,0,6,0,0,0,0,0,0,0
endlayer

layer
2,2,2,2,2,2,8,0,0,13,0,0,0,0,0,0,0,0,0,0,0,0,0,0
2,6,19,19,19,19,2,2,2,2,0,13,13,0,0,0,0,0,0,0,0,0,0,0
2,19,19,19,19,19,19,19,19,19,2,2,2,17,0,0,0,0,0,0,0,0,0,0
2,19,19,19,19,19,19,19,19,19,19,19,19,2,2,0,13,0,0,0,0,0,0,0
2,19,19,19,19,19,19,19,19,19,19,19,19,19,6,0,0,0,0,0,0,0,0,0
2,19,19,19,19,19,19,19,19,19,19,19,19,19,19,8,0,0,0,0,0,0,0,0
2,6,19,19,19,19,19,19,19,19,19,19,19,19,19,8,0,0,2,13,0,0,0,0
2,2,2,2,2,19,19,19,19,19,19,19,19,19,19,0,0,0,0,2,8,0,0,0
0,0,0,5,15,2,2,2,2,19,19,19,19,19,8,0,14,0,0,5,0,0,0,0
0,0,0,0,0,0,5,5,0,2,2,2,6,19,0,0,0,0,0,0,0,0,0,0
0,0,0,0,0,0,0,0,0,0,5,0,2,8,0,0,0,14,0,0,0,0,8,0
0,0,0,0,0,0,0,0,0,0,0,0,0,2,0,14,0,0,0,0,0,6,0,0
0,0,0,0,0,0,0,0,0,0,0,0,0,15,2,0,0,0,0,0,0,0,0,8
0,0,0,0,0,0,0,0,0,14,0,0,0,0,5,0,6,0,0,0,0,0,0,0
endlayer

layer
2,2,2,2,2,2,8,0,0,13,0,0,0,0,0,0,0,0,0,0,0,0,0,0
2,6,0,0,0,5,2,2,2,2,0,0,13,0,0,0,0,0,0,0,0,0,0,0
5,0,0,0,0,26,0,0,0,0,2,2,2,17,0,0,0,0,0,0,0,0,0,0
0,8,0,0,14,0,0,0,0,0,0,0,0,2,2,0,13,0,0,0,0,0,0,0
2,8,0,26,14,14,14,0,14,0,0,0,0,0,6,0,0,0,0,0,0,0,0,0
2,8,0,0,0,0,26,0,0,0,0,0,0,0,0,0,0,0,0,0,0,0,0,0
2,6,0,0,26,0,0,0,0,0,0,0,0,0,0,0,0,0,2,13,0,0,0,0
2,2,2,2,2,13,0,0,0,0,0,0,0,0,0,0,0,0,0,2,8,0,0,0
0,0,0,5,15,2,2,2,2,0,0,0,0,0,0,0,0,0,0,5,0,13,0,0
0,0,0,0,0,0,5,5,5,2,2,2,6,0,0,0,0,0,0,0,0,0,0,0
14,14,0,0,0,0,0,0,0,0,5,0,2,0,0,0,0,0,0,0,0,0,8,0
0,0,0,0,0,0,0,0,0,0,0,0,0,2,0,0,0,0,0,0,0,6,0,0
0,0,0,0,0,0,0,0,0,0,0,14,0,15,2,0,0,0,0,0,0,0,0,8
0,0,0,0,0,0,0,0,0,0,0,0,0,0,5,0,6,0,0,0,0,0,0,0
endlayer

layer
2,22,22,22,22,2,8,0,0,13,0,0,0,0,0,0,0,0,0,0,0,0,0,0
2,6,14,0,0,5,22,22,22,22,0,0,0,0,0,0,0,0,0,0,0,0,0,0
5,0,0,0,0,0,0,0,0,0,22,22,22,13,0,0,0,0,0,0,0,0,0,0
0,8,0,0,0,0,0,0,0,0,0,0,0,22,22,0,13,0,0,0,0,0,0,0
2,8,0,0,0,0,0,0,0,0,0,0,0,0,6,0,0,0,0,0,0,0,0,0
2,8,0,0,0,0,0,0,0,0,0,0,0,0,0,0,0,0,0,0,0,0,0,0
2,6,0,0,0,0,0,0,0,0,0,0,0,0,0,0,0,0,2,13,0,0,0,0
2,22,22,22,22,13,0,0,0,0,0,0,0,0,0,0,0,0,0,2,0,0,0,0
5,0,0,0,15,2,22,22,22,0,0,0,0,0,0,0,0,0,0,14,22,13,0,0
0,0,0,0,0,0,5,5,5,22,22,22,6,0,0,0,0,0,0,0,0,0,0,0
0,0,0,0,0,0,0,0,0,0,0,0,22,0,0,0,0,14,14,0,0,22,8,0
0,0,0,0,0,0,0,0,0,0,0,0,0,2,0,0,0,0,0,0,0,6,0,0
0,0,0,0,0,0,0,14,0,0,0,0,0,15,2,0,0,0,0,0,0,0,0,8
0,0,0,0,0,0,0,0,0,0,0,0,0,0,5,0,6,0,0,0,0,0,0,0
endlayer

layer
2,22,22,22,22,2,8,0,0,13,0,0,0,0,0,0,0,0,14,0,0,0,0,0
2,6,14,0,0,5,22,22,22,22,0,0,0,0,0,0,0,0,0,0,0,0,0,0
2,0,0,0,0,0,0,0,0,0,22,22,22,13,0,0,0,0,0,0,0,0,0,0
2,8,0,0,0,0,0,0,0,0,0,0,0,22,22,0,13,0,0,0,0,0,0,0
2,8,0,0,0,0,0,0,14,0,0,0,0,0,6,22,0,0,0,0,0,0,0,0
2,8,0,0,0,0,0,0,0,14,0,0,0,0,0,0,0,0,0,0,0,0,0,0
2,6,0,0,0,0,0,0,0,0,0,0,0,0,0,0,0,0,2,13,0,0,0,0
2,22,22,22,22,0,0,0,0,0,0,0,0,0,14,0,0,0,0,2,0,0,0,0
5,0,0,0,15,2,22,22,22,0,0,0,0,0,0,0,0,0,0,0,22,13,0,0
0,0,0,0,0,0,5,5,5,22,22,22,6,0,0,0,0,0,0,0,0,22,0,0
0,0,0,0,0,0,0,0,0,0,0,0,22,0,0,0,0,0,0,0,0,22,8,0
0,0,0,0,0,0,0,0,0,0,0,0,10,2,0,0,0,0,0,0,0,6,0,0
0,0,0,0,0,0,0,0,0,0,0,0,0,15,2,0,0,0,0,0,0,0,0,8
0,0,0,0,0,0,0,0,0,0,0,0,0,0,5,0,6,0,0,0,0,0,0,0
endlayer

layer
2,22,22,22,22,2,0,0,0,13,0,0,0,0,0,0,0,0,0,0,0,0,0,0
2,6,0,0,0,5,22,22,22,22,0,0,0,0,0,0,0,0,0,0,0,0,0,0
2,0,0,0,0,0,0,0,0,0,22,22,22,13,0,0,0,0,0,0,0,0,0,0
2,8,0,0,0,0,0,0,0,0,0,0,0,22,22,0,13,0,0,0,0,0,0,0
2,0,0,0,0,0,0,0,0,0,0,0,0,0,6,22,0,0,0,0,0,0,0,0
2,0,0,0,0,0,0,0,0,0,0,0,0,0,0,0,0,0,0,0,0,0,0,0
2,6,0,0,0,0,0,0,0,0,0,0,0,0,0,0,0,0,2,13,0,0,0,0
2,22,22,22,22,0,0,0,0,0,0,0,0,0,0,0,0,0,0,2,0,0,0,0
5,0,0,0,5,2,22,22,22,0,0,0,0,0,0,0,0,0,0,0,22,13,0,0
0,0,0,0,0,0,5,5,5,22,22,22,6,0,0,0,0,0,0,0,0,22,0,0
0,0,0,0,0,0,0,0,0,0,0,0,22,0,0,0,0,0,0,0,0,22,8,0
0,0,0,0,0,0,0,0,0,0,0,0,10,2,0,0,0,0,0,0,0,6,0,0
0,0,0,0,0,0,0,0,0,0,0,0,0,15,2,0,0,0,0,0,0,0,0,8
0,0,0,0,0,0,0,0,0,0,0,0,0,0,5,0,6,0,0,0,0,0,0,0
endlayer

layer
2,2,2,2,2,2,0,0,0,13,0,0,0,0,0,0,0,0,0,0,0,0,0,0
2,6,19,19,19,19,2,2,2,2,0,0,0,0,0,0,0,0,0,0,0,0,0,0
2,19,19,19,19,19,19,19,19,19,2,2,2,13,0,0,0,0,0,0,0,0,0,0
2,19,19,19,19,19,19,19,19,19,19,19,19,2,2,0,13,0,0,0,0,0,0,0
2,19,19,19,19,19,19,19,19,19,19,19,19,19,6,2,2,0,0,0,0,0,0,0
2,19,19,19,19,19,19,19,19,19,19,19,19,19,19,19,19,2,0,0,0,0,0,0
2,6,19,19,19,19,19,19,19,19,19,19,19,19,19,19,19,19,2,13,0,0,0,0
2,2,2,2,2,19,19,19,19,19,19,19,19,19,19,19,19,19,19,2,0,0,0,0
5,5,0,0,5,2,2,2,2,19,19,19,19,19,19,19,19,19,19,19,2,13,0,0
0,0,0,0,0,0,5,5,5,2,2,2,6,19,19,19,19,19,19,19,19,2,0,0
0,0,0,0,0,0,0,0,0,0,0,0,2,19,19,19,19,19,19,19,19,2,8,0
0,0,0,0,0,0,0,0,0,0,0,0,10,2,19,19,19,19,19,19,19,6,2,0
0,0,0,0,0,0,0,0,0,0,0,0,0,15,2,19,19,19,19,19,19,19,2,8
0,0,0,0,0,0,0,0,0,0,0,0,0,0,5,0,6,19,19,19,19,19,19,2
endlayer

layer
2,22,22,22,22,2,0,0,0,0,0,0,0,0,0,0,0,0,0,0,0,0,0,0
2,6,14,0,0,0,22,22,22,22,0,13,0,0,0,0,0,0,0,0,0,0,0,0
2,27,0,0,0,0,0,0,0,0,22,22,22,0,0,0,0,0,0,0,0,0,0,0
2,27,0,0,30,0,0,0,0,14,14,29,28,22,22,0,0,0,0,0,0,0,0,0
2,27,0,14,0,0,14,14,14,14,14,14,0,0,6,22,22,0,0,0,0,0,0,0
2,27,0,0,0,14,14,0,14,0,14,14,0,0,0,0,0,22,0,0,0,0,0,0
2,6,0,0,0,0,0,0,0,0,14,14,0,0,0,0,0,0,2,0,0,0,0,0
2,22,22,22,22,0,0,0,0,0,0,0,0,0,31,0,0,0,0,2,0,0,0,0
5,5,0,0,0,2,22,22,22,0,0,0,0,0,14,14,0,14,0,0,22,0,0,0
0,0,0,0,0,0,0,0,0,22,22,22,6,0,0,14,14,14,0,14,0,22,0,0
0,0,0,0,0,0,0,0,0,0,0,0,22,0,0,0,0,0,0,32,0,22,0,0
0,0,0,0,0,0,0,0,0,0,0,0,10,2,0,0,0,0,0,0,14,6,22,0
0,0,0,0,0,0,0,0,0,0,0,0,0,15,2,0,0,27,27,27,27,0,22,0
0,0,0,0,0,0,0,0,0,0,0,0,0,0,5,0,6,2,2,2,2,2,2,22
endlayer

layer
2,22,22,22,22,2,0,0,0,0,0,0,0,0,0,0,0,0,0,0,0,0,0,0
2,6,0,0,0,0,22,22,22,22,13,13,0,0,0,0,0,0,0,0,0,0,0,0
2,27,0,0,0,0,0,0,0,0,22,22,22,0,0,0,0,0,0,0,0,0,0,0
2,27,0,0,0,0,0,0,0,0,0,14,0,22,22,0,0,0,0,0,0,0,0,0
2,27,0,0,0,0,0,0,0,0,0,0,0,0,6,22,22,0,0,0,0,0,0,0
2,27,0,0,0,0,0,0,0,0,0,0,0,14,0,0,0,22,0,0,0,0,0,0
2,6,0,0,0,0,0,0,0,0,0,14,14,0,0,0,0,0,2,0,0,0,0,0
2,22,22,22,22,0,0,0,0,0,14,0,0,14,0,14,0,0,0,2,0,0,0,0
5,5,0,0,0,2,22,22,22,0,0,0,0,0,0,0,0,0,0,0,22,0,0,0
0,0,0,0,0,0,0,0,0,22,22,22,6,0,14,0,14,0,0,0,0,22,0,0
0,0,0,0,0,0,0,0,0,0,0,0,22,0,0,0,0,0,0,14,0,22,0,0
0,0,0,0,0,0,0,0,0,0,0,0,10,2,0,0,0,0,0,0,0,6,22,0
0,0,0,0,0,0,0,0,0,0,0,0,0,15,2,0,0,27,27,27,27,0,22,0
0,0,0,0,0,0,0,0,0,0,0,0,0,0,5,22,6,2,2,2,2,2,2,22
endlayer

layer
2,22,22,22,22,2,0,0,0,0,0,0,0,0,0,0,0,0,0,0,0,0,0,0
2,6,0,0,0,0,22,22,22,22,13,13,13,0,0,0,0,0,0,0,0,0,0,0
2,27,0,0,0,0,0,0,0,0,22,22,22,0,0,0,0,0,0,0,0,0,0,0
2,27,0,0,0,0,0,0,0,0,0,0,0,22,22,0,0,0,0,0,0,0,0,0
2,27,14,14,14,0,0,0,0,0,0,0,0,0,6,22,22,0,0,0,0,0,0,0
2,27,14,0,0,14,0,14,0,14,0,14,0,0,0,0,0,22,0,0,0,0,0,0
2,6,0,0,0,0,0,0,14,0,0,14,0,0,0,0,0,0,2,0,0,0,0,0
2,22,22,22,22,0,0,0,0,0,0,0,0,14,0,0,0,0,0,2,0,0,0,0
5,5,0,0,0,2,22,22,22,0,0,0,0,0,0,0,0,0,0,0,22,0,0,0
0,0,0,0,0,0,0,0,0,22,22,22,6,0,0,14,0,0,0,0,0,22,0,0
0,0,0,0,0,0,0,0,0,0,0,0,22,0,0,0,0,0,14,0,0,22,0,0
0,0,0,0,0,0,0,0,0,0,0,0,0,2,0,0,0,0,0,14,0,6,22,0
0,0,0,0,0,0,0,0,0,0,0,0,0,15,2,0,0,0,0,0,0,0,22,0
0,0,0,0,0,0,0,0,0,0,0,0,0,0,5,22,6,2,2,2,2,2,2,22
endlayer

layer
2,22,22,22,22,2,0,0,0,0,0,0,0,0,0,0,0,0,0,0,0,0,0,0
2,6,0,0,0,0,22,22,22,22,13,13,13,0,0,0,0,0,0,0,0,0,0,0
2,0,0,0,0,0,0,0,0,0,22,22,22,0,0,0,0,0,0,0,0,0,0,0
2,0,0,0,0,0,0,0,0,0,0,0,0,22,22,0,0,0,0,0,0,0,0,0
2,0,0,0,0,0,0,0,0,0,0,0,0,0,6,22,22,0,0,0,0,0,0,0
2,0,0,0,0,0,0,0,0,0,0,0,0,0,0,0,0,22,0,0,0,0,0,0
2,6,0,0,0,0,0,0,0,0,0,0,0,0,0,0,0,0,2,0,0,0,0,0
2,22,22,22,22,0,0,0,0,0,0,0,14,0,0,0,0,0,0,2,0,0,0,0
5,5,0,0,0,2,22,22,22,0,0,0,0,0,0,0,0,0,0,0,22,0,0,0
0,0,0,0,0,0,0,0,0,22,22,22,6,0,0,0,0,0,0,0,0,22,0,0
0,0,0,0,0,0,0,0,0,0,0,0,22,0,0,0,0,0,0,0,0,22,0,0
0,0,0,0,0,0,0,0,0,0,0,14,0,2,0,0,0,0,0,0,0,6,22,0
0,0,0,0,0,0,0,0,0,0,0,0,0,15,2,0,0,0,0,0,0,0,22,0
0,0,0,0,0,0,0,0,0,0,0,0,0,0,5,22,6,2,2,2,2,2,2,22
endlayer

layer
2,22,22,22,22,2,0,0,0,0,0,0,0,0,0,0,0,0,0,0,0,0,0,0
2,6,14,0,0,0,22,22,22,22,13,13,13,0,0,0,0,0,0,0,0,0,0,0
2,0,0,0,0,0,0,0,0,0,22,22,22,0,0,0,0,0,0,0,0,0,0,0
2,0,0,0,0,0,0,0,0,0,0,0,0,22,22,0,0,0,0,0,0,0,0,0
2,0,0,0,0,0,0,0,0,0,0,0,0,0,6,22,22,0,0,0,0,0,0,0
2,0,0,0,0,0,0,0,0,0,0,0,0,0,0,0,0,22,0,0,0,0,0,0
2,6,0,0,0,0,0,0,0,0,0,0,0,0,0,0,0,0,2,0,0,0,0,0
2,22,22,22,22,0,0,0,0,0,0,0,0,0,0,0,0,0,0,2,0,0,0,0
5,5,0,0,0,2,22,22,22,0,0,0,0,0,0,0,0,0,0,0,22,0,0,0
0,0,0,0,0,0,0,0,0,22,22,22,6,0,0,0,0,0,0,0,0,22,0,0
0,0,0,0,0,0,0,0,0,0,0,0,22,0,0,0,0,0,0,0,0,22,0,0
0,0,0,0,0,0,0,0,0,0,0,0,0,2,0,0,0,0,0,0,0,6,22,0
0,0,0,0,0,0,0,0,0,0,0,0,0,15,2,0,0,0,0,0,0,0,22,0
0,0,0,0,0,0,0,0,0,0,0,0,0,0,5,22,6,2,2,2,2,2,2,22
endlayer

layer
2,2,2,2,2,2,0,0,0,0,0,0,0,0,0,0,0,0,0,0,0,0,0,0
2,2,0,2,2,2,2,2,2,2,13,13,13,0,0,0,0,0,0,0,0,0,0,0
2,2,2,0,0,2,2,2,2,2,2,2,2,0,0,0,0,0,0,0,0,0,0,0
2,2,2,2,0,0,0,2,2,2,2,2,2,2,2,0,0,0,0,0,0,0,0,0
2,2,2,2,2,0,0,0,2,2,2,2,2,2,2,2,2,0,0,0,0,0,0,0
2,2,2,2,2,2,2,0,0,0,2,2,2,2,2,2,2,2,0,0,0,0,0,0
2,2,2,2,2,2,2,2,0,0,0,2,2,2,2,2,2,2,2,0,0,0,0,0
2,2,2,2,2,2,2,2,2,2,0,0,0,0,0,0,0,2,2,2,0,0,0,0
5,5,0,0,0,2,2,2,2,2,0,0,0,0,0,0,0,2,2,2,2,0,0,0
0,0,0,0,0,0,0,0,0,2,2,2,0,0,0,0,0,0,2,2,2,2,0,0
0,0,0,0,0,0,0,0,0,0,0,0,2,0,2,2,0,0,2,2,2,2,0,0
0,0,0,0,0,0,0,0,0,0,0,0,0,2,2,2,2,2,2,2,2,2,2,0
0,0,0,0,0,0,0,0,0,0,0,0,0,0,2,2,2,2,2,2,2,2,2,0
0,0,0,0,0,0,0,0,0,0,0,0,14,0,0,2,2,2,2,2,2,2,2,2
endlayer

layer
0,0,0,0,0,0,0,0,0,0,0,0,0,0,0,0,0,0,0,0,0,0,0,0
0,0,0,0,0,0,0,0,0,0,0,0,0,0,0,0,0,0,0,0,0,0,0,0
0,0,0,0,0,0,0,0,0,0,0,0,0,0,0,0,0,0,0,0,0,0,0,0
0,0,0,0,0,0,0,0,0,0,0,0,0,0,0,0,0,0,0,0,0,0,0,0
0,0,0,0,0,0,0,0,0,0,0,0,0,0,0,0,0,0,0,0,0,0,0,0
0,0,0,0,0,0,0,0,0,0,0,0,0,0,0,0,0,0,0,0,0,0,0,0
0,0,0,0,0,0,0,0,0,0,0,0,0,0,0,0,0,0,0,0,0,0,0,0
0,0,0,0,0,0,0,0,0,0,0,0,0,0,0,0,0,0,0,0,0,0,0,0
0,0,0,0,0,0,0,0,0,0,0,0,0,0,0,0,0,0,0,0,0,0,0,0
0,0,0,0,0,0,0,0,0,0,0,0,0,0,0,0,0,0,0,0,0,0,0,0
0,0,0,0,0,0,0,0,0,0,0,0,0,0,0,0,0,0,0,0,0,0,0,0
0,0,0,0,0,0,0,0,0,0,0,14,0,0,0,0,0,0,0,0,0,0,0,0
0,0,0,0,0,0,0,0,0,0,14,0,0,0,0,0,0,0,0,0,0,0,0,0
0,0,0,0,0,0,0,0,0,0,0,0,0,0,0,0,0,0,0,0,0,0,0,0
endlayer

layer
0,0,14,0,0,0,0,0,0,0,0,0,0,0,0,0,0,0,0,0,0,0,0,0
0,0,0,0,0,0,0,0,0,0,0,0,0,0,0,0,0,0,0,0,0,0,0,0
0,0,14,0,0,0,0,0,0,0,0,0,0,0,0,0,0,0,0,0,0,0,0,0
0,0,0,0,0,14,0,0,0,0,0,0,0,0,0,0,0,0,0,0,0,0,0,0
0,0,0,0,0,0,0,0,0,0,0,0,0,0,0,0,0,0,0,0,0,0,0,0
0,0,0,0,0,0,0,14,0,0,0,0,0,0,0,0,0,0,0,0,0,0,0,0
0,0,0,0,0,0,0,0,0,14,0,14,0,0,0,0,0,0,0,0,0,0,0,0
0,0,0,0,0,0,0,0,0,0,14,0,14,0,0,0,0,0,0,0,0,0,0,0
0,0,0,0,0,0,0,0,0,0,0,0,0,0,14,14,0,0,0,0,0,0,0,0
0,0,0,0,0,0,0,0,0,0,0,0,0,0,0,0,0,0,0,0,0,0,0,0
0,0,0,0,0,0,0,0,0,0,0,0,0,0,0,0,0,0,0,0,0,0,0,0
0,0,0,0,0,0,0,0,0,0,0,0,0,0,0,0,0,0,0,0,0,0,0,0
0,0,0,0,0,0,0,0,0,0,0,0,0,0,0,0,0,0,0,0,0,0,0,0
0,0,0,0,0,0,0,0,0,0,0,0,0,0,0,0,0,0,0,0,0,0,0,0
endlayer

layer
0,0,0,0,0,0,0,0,0,0,0,0,0,0,0,0,0,0,0,0,0,0,0,0
0,0,0,0,0,0,0,0,0,0,0,0,0,0,0,0,0,0,0,0,0,0,0,0
0,0,0,0,0,0,0,0,0,0,0,0,0,0,0,0,0,0,0,0,0,0,0,0
0,0,0,0,0,0,0,0,0,0,0,0,0,0,0,0,0,0,0,0,0,0,0,0
0,0,0,0,0,0,0,0,0,0,0,0,0,0,0,0,0,0,0,0,0,0,0,0
0,0,0,0,0,0,0,0,0,0,0,0,0,0,0,0,0,0,0,0,0,0,0,0
0,0,0,0,0,0,0,0,0,0,0,0,0,0,0,0,0,0,0,0,0,0,0,0
0,0,0,0,0,0,0,0,0,0,0,0,0,0,0,14,0,0,0,0,0,0,0,0
0,0,0,0,0,0,0,0,0,0,0,0,0,0,0,0,0,0,0,0,0,0,0,0
0,0,0,0,0,0,0,0,0,0,0,0,0,0,0,0,0,0,0,0,0,0,0,0
0,0,0,0,0,0,0,0,0,0,0,0,0,0,0,0,0,0,0,0,0,0,0,0
0,0,0,0,0,0,0,0,0,0,0,0,0,0,0,0,0,0,0,0,0,0,0,0
0,0,0,0,0,0,0,0,0,0,0,0,0,0,0,0,0,0,0,0,0,0,0,0
0,0,0,0,0,0,0,0,0,0,0,0,0,0,0,0,0,0,0,0,0,0,0,0
endlayer

