
# Created by Ruins mod version 13.8 Ingame Parser
# authoring Player: OneWolfe

weight=5
embed_into_distance=4
acceptable_target_blocks=
unacceptable_target_blocks=flowing_water,water,flowing_lava,lava
dimensions=39,14,24
allowable_overhang=8
max_leveling=6
leveling_buffer=0
preserve_water=0
preserve_lava=0
preserve_plants=1

rule1=0,100,preserveBlock
rule2=0,100,terrafirmacraft:StoneMMBrick-1,terrafirmacraft:StoneMMBrick-1,terrafirmacraft:StoneMMBrick-1,terrafirmacraft:StoneMMBrick-1
rule3=0,100,air,air,ChestGenHook:dungeonChest:5-3,MobSpawner:spiderTFC,MobSpawner:skeletonTFC
rule4=0,100,air,Steamcraft:pipe-0,Steamcraft:pipe-0
rule5=0,100,Railcraft:frame-0
rule6=0,100,air,Steamcraft:valvePipe-2,Steamcraft:valvePipe-2
rule7=0,100,air,Steamcraft:steamTank-0
rule8=0,100,air
rule9=0,100,Steamcraft:valvePipe-1
rule10=0,100,preserveBlock,terrafirmacraft:FreshWaterStationary-0
rule11=0,100,terrafirmacraft:Vine-2
rule12=0,100,terrafirmacraft:Vine-8
rule13=0,100,terrafirmacraft:Vine-1
rule14=0,100,terrafirmacraft:Vine-4
rule15=0,100,terrafirmacraft:Vine-9
rule16=0,100,air,terrafirmacraft:planks-2,terrafirmacraft:planks-2
rule17=0,100,air,minecraft:stained_glass-8,minecraft:stained_glass-8
rule18=0,100,air,terrafirmacraft:Vine-0
rule19=0,100,air,air,ChestGenHook:dungeonChest:5-3,MobSpawner:skeletonTFC,MobSpawner:caveSpiderTFC
rule20=0,100,air,Steamcraft:valvePipe-5
rule21=0,100,air,air,ChestGenHook:dungeonChest:5-3,MobSpawner:skeletonTFC,TwilightForest:tile.TFBossSpawner-1
rule22=0,100,terrafirmacraft:Vine-6
rule23=0,100,air,Steamcraft:horn-2

layer
2,2,2,2,2,2,1,1,1,1,1,1,1,1,1,1,1,1,1,1,1,1,1,1
2,2,2,2,2,2,2,2,2,2,1,1,1,1,1,1,1,1,1,1,1,1,1,1
2,2,2,2,2,2,2,2,2,2,2,2,2,1,1,1,1,1,1,1,1,1,1,1
2,2,2,2,2,2,2,2,2,2,2,2,2,2,2,1,1,1,1,1,1,1,1,1
2,2,2,2,2,2,2,2,3,2,2,2,2,2,2,2,2,1,1,1,1,1,1,1
2,2,2,2,2,2,2,2,2,2,2,2,2,2,2,2,2,2,1,1,1,1,1,1
2,2,2,2,2,2,2,2,2,2,2,2,2,2,2,2,2,2,2,1,1,1,1,1
2,2,2,2,2,2,2,2,2,2,2,2,2,2,2,2,2,2,2,2,1,1,1,1
1,1,1,1,1,2,2,2,2,2,2,2,2,2,2,2,2,2,2,2,2,1,1,1
1,1,1,1,1,1,1,1,1,2,2,2,2,2,2,2,2,2,2,2,2,2,1,1
1,1,1,1,1,1,1,1,1,1,1,1,2,2,2,2,2,2,2,2,2,2,1,1
1,1,1,1,1,1,1,1,1,1,1,1,1,2,2,2,2,2,2,2,2,2,2,1
1,1,1,1,1,1,1,1,1,1,1,1,1,1,2,2,2,2,2,2,2,2,2,1
1,1,1,1,1,1,1,1,1,1,1,1,1,1,1,2,2,2,2,2,2,2,2,2
endlayer

layer
2,2,2,4,2,2,1,1,1,1,1,1,1,1,1,1,1,1,1,1,1,1,1,1
2,5,0,4,0,0,2,2,2,2,1,1,1,1,1,1,1,1,1,1,1,1,1,1
0,0,0,6,0,0,0,0,0,0,2,2,2,1,1,1,1,1,1,1,1,1,1,1
2,0,7,7,0,0,0,0,0,0,0,0,0,2,2,1,1,1,1,1,1,1,1,1
2,0,7,7,0,0,0,0,0,8,8,8,0,0,5,2,2,1,1,1,1,1,1,1
2,0,0,4,4,4,4,4,0,0,8,0,0,0,0,0,0,2,1,1,1,1,1,1
2,5,0,0,0,0,0,9,0,0,0,0,0,0,0,0,0,0,2,1,1,1,1,1
2,2,2,2,2,0,0,4,0,0,0,0,0,0,0,0,8,0,0,2,1,1,1,1
1,1,1,1,1,2,2,4,2,0,0,0,0,0,0,0,0,0,0,0,2,1,1,1
1,1,1,1,1,1,1,1,1,2,2,2,5,0,0,0,0,0,0,0,0,2,1,1
1,1,1,1,1,1,1,1,1,1,1,1,2,0,0,0,0,0,0,0,0,2,1,1
1,1,10,10,10,10,10,10,10,1,1,1,1,2,0,0,0,0,0,0,0,5,2,1
1,1,10,10,10,10,10,10,10,1,1,1,1,1,2,0,0,0,0,0,0,0,2,1
1,1,0,0,0,0,0,0,0,1,1,1,1,1,1,2,5,2,2,2,2,2,2,2
endlayer

layer
2,2,2,2,2,2,1,1,1,1,1,1,1,1,1,1,1,1,1,1,1,1,1,1
2,5,0,0,0,0,2,2,2,2,1,1,1,1,1,1,1,1,1,1,1,1,1,1
0,0,0,0,0,0,11,0,0,0,2,2,2,1,1,1,1,1,1,1,1,1,1,1
2,0,7,7,0,0,0,0,0,0,0,11,0,2,2,1,1,1,1,1,1,1,1,1
2,0,7,7,0,8,0,0,8,0,0,0,0,0,5,2,2,1,1,1,1,1,1,1
2,0,0,0,0,0,0,0,8,0,0,0,0,0,0,0,0,2,1,1,1,1,1,1
2,5,0,0,0,0,0,0,0,0,0,0,0,8,0,0,0,0,2,1,1,1,1,1
2,2,2,2,2,0,12,0,0,0,0,0,0,0,8,0,0,0,0,2,1,1,1,1
1,1,1,1,1,2,2,2,2,0,0,0,0,0,0,0,0,0,0,0,2,1,1,1
1,1,1,1,1,1,1,1,1,2,2,2,5,0,0,0,0,8,0,0,11,2,1,1
1,1,1,1,1,1,1,1,1,1,1,1,2,0,0,0,0,8,0,0,0,2,1,1
1,1,10,10,10,10,10,10,10,1,1,1,1,2,0,0,0,8,8,0,0,5,2,1
1,1,0,0,0,0,0,0,0,1,1,1,1,1,2,0,0,0,0,0,0,0,2,1
1,1,0,0,0,0,0,0,0,1,1,1,1,1,1,2,5,0,0,2,2,2,2,2
endlayer

layer
2,2,2,2,2,2,1,1,1,1,1,1,1,1,1,1,1,1,1,1,1,1,1,1
2,5,0,11,11,0,2,2,2,2,1,1,1,1,1,1,1,1,1,1,1,1,1,1
0,0,0,0,0,0,11,11,0,0,2,2,2,1,1,1,1,1,1,1,1,1,1,1
2,0,7,7,13,0,0,0,0,0,11,11,0,2,2,1,1,1,1,1,1,1,1,1
2,0,7,7,0,0,0,0,0,0,0,0,0,0,5,2,2,1,1,1,1,1,1,1
2,0,0,0,0,0,0,0,0,0,0,0,0,0,0,11,14,2,1,1,1,1,1,1
2,5,0,12,0,0,0,0,0,0,0,0,0,0,0,0,0,14,2,1,1,1,1,1
2,2,2,2,2,0,12,0,12,0,0,0,0,0,0,0,0,0,0,2,1,1,1,1
1,1,1,1,1,2,2,2,2,0,12,0,0,0,0,0,0,0,0,11,2,1,1,1
1,1,1,1,1,1,1,1,1,2,2,2,5,0,0,0,0,0,0,0,11,2,1,1
1,1,1,1,1,1,1,1,1,1,1,1,2,12,0,0,0,0,0,0,0,2,1,1
1,1,0,0,0,0,0,0,0,1,1,1,1,2,0,0,0,0,0,0,0,5,2,1
1,1,0,0,0,0,0,0,0,1,1,1,1,1,2,15,0,0,0,0,0,0,2,1
1,1,0,0,0,0,0,0,0,1,1,1,1,1,1,2,5,0,0,0,2,2,2,2
endlayer

layer
2,2,2,2,2,2,12,12,0,12,0,0,0,0,8,0,0,0,0,0,0,0,0,0
2,5,0,11,0,0,2,2,2,2,0,0,12,0,0,0,0,8,0,0,0,0,0,0
2,0,0,0,0,0,0,0,0,0,2,2,2,0,12,0,0,0,0,0,0,0,8,0
2,0,0,6,0,0,0,0,0,0,0,0,0,2,2,0,12,0,0,0,0,0,0,0
2,0,0,0,0,0,0,0,0,0,0,0,0,11,5,2,2,0,0,0,0,0,0,0
2,0,0,0,0,0,0,0,0,0,0,0,0,0,0,0,0,2,0,0,0,0,0,0
2,5,0,0,0,0,0,0,0,0,0,0,0,0,0,0,0,0,2,0,0,0,0,0
2,2,2,2,2,12,0,0,0,0,0,0,0,0,0,0,0,0,0,2,0,0,0,0
0,0,11,0,0,2,2,2,2,0,0,12,0,0,0,0,0,0,0,0,2,0,0,0
0,0,0,0,0,11,11,0,0,2,2,2,5,0,0,0,0,0,0,0,11,2,13,0
0,0,0,0,0,0,0,0,0,0,11,0,2,0,0,0,0,0,0,0,0,2,0,0
0,0,0,0,0,0,0,0,0,0,0,0,0,2,0,0,0,0,0,0,0,5,2,0
0,0,0,0,0,0,0,8,0,0,0,0,0,0,2,0,0,0,0,0,0,0,2,12
0,0,0,8,0,0,0,0,0,0,0,0,0,0,0,2,5,0,0,0,0,2,2,2
endlayer

layer
0,2,2,2,2,2,12,12,0,12,0,0,0,0,0,0,8,0,0,0,0,0,0,0
2,5,16,16,16,16,2,2,2,2,0,0,12,0,0,0,0,0,0,0,0,0,0,0
2,16,16,16,16,16,16,16,16,16,2,2,2,0,12,0,0,0,0,0,0,0,0,0
2,16,16,4,16,16,16,16,16,16,16,16,16,2,2,0,12,0,0,0,0,0,0,0
2,16,16,16,16,16,16,16,16,16,16,16,16,16,5,2,2,0,0,0,0,0,0,0
2,16,16,16,16,16,16,16,16,16,16,16,16,16,16,16,16,2,0,0,0,0,0,0
2,5,16,16,16,16,16,16,16,16,16,16,16,16,16,16,16,16,13,0,0,0,8,0
2,2,2,2,2,16,16,16,16,16,16,16,16,16,16,16,16,16,16,12,0,0,0,8
0,0,11,0,0,2,2,2,2,16,16,16,16,16,16,16,16,16,16,16,0,0,0,0
0,0,0,0,0,11,11,0,0,2,2,2,5,16,16,16,16,16,16,16,16,2,13,0
0,0,8,0,0,0,0,0,0,0,11,0,2,16,16,16,16,16,16,16,16,2,0,0
0,0,0,0,0,8,0,0,0,0,0,0,0,2,16,16,16,16,16,16,16,5,2,0
0,0,0,0,0,0,0,0,0,8,0,0,0,0,2,16,16,16,16,16,16,16,2,12
0,0,0,0,0,0,0,0,0,0,0,0,0,0,0,2,5,16,16,16,16,16,16,2
endlayer

layer
2,2,2,2,2,2,12,12,0,12,0,0,0,0,0,0,0,0,0,0,0,0,0,0
2,5,0,0,0,14,2,2,2,2,0,12,12,0,0,0,0,0,0,0,0,0,0,0
2,4,0,0,0,0,0,0,0,0,2,2,2,12,12,0,0,0,0,0,0,0,0,0
0,4,4,4,0,0,0,0,0,0,0,0,0,2,2,0,12,0,0,0,8,0,0,0
2,13,8,0,8,0,8,0,8,0,0,0,0,0,5,2,2,0,0,0,0,0,0,0
2,0,0,0,8,0,0,8,0,8,0,8,8,0,0,0,0,0,0,0,0,0,0,0
2,5,0,0,0,0,0,0,0,0,0,0,0,0,0,8,0,0,0,0,0,0,0,0
2,2,2,2,2,0,0,0,0,0,0,0,0,0,0,0,0,0,0,0,0,0,0,0
0,11,11,0,0,2,2,2,2,0,0,0,0,0,0,0,8,8,0,0,0,0,0,0
0,0,0,0,0,11,11,0,0,2,2,2,5,0,0,8,0,8,0,0,0,2,13,0
0,0,0,0,0,0,0,0,0,0,11,0,2,12,0,0,0,0,0,0,0,2,0,0
0,0,0,0,0,0,0,0,0,0,0,0,0,2,0,0,0,0,0,0,0,5,2,0
0,0,0,0,0,0,0,0,0,0,0,0,0,14,2,13,0,0,0,0,0,0,2,15
0,0,0,0,0,0,0,0,0,0,0,0,0,0,0,2,5,0,0,0,0,0,0,2
endlayer

layer
2,17,17,17,17,2,13,0,0,0,0,0,0,0,0,0,0,0,0,0,0,0,0,0
2,5,0,0,0,11,17,17,17,17,0,0,0,0,0,0,0,0,0,0,0,0,0,0
2,4,0,0,0,0,0,0,0,0,17,17,17,0,0,0,0,0,0,0,0,0,0,0
11,0,0,0,0,0,0,0,0,0,0,0,0,17,17,0,0,0,0,0,0,0,0,0
2,13,0,0,0,0,0,0,0,0,0,0,0,0,5,17,17,0,0,0,0,0,0,0
2,0,0,0,0,0,0,0,0,0,0,0,0,0,0,0,0,0,0,0,0,0,0,0
2,5,0,0,0,0,0,0,0,0,0,0,0,0,0,0,0,0,0,0,0,0,0,0
2,17,17,17,17,0,0,0,0,0,0,0,0,0,0,0,0,0,0,0,0,0,0,0
0,0,0,0,0,2,17,17,17,0,0,0,0,0,0,0,0,0,0,0,0,0,0,0
0,0,0,0,0,0,0,0,0,17,17,17,5,0,0,0,0,0,0,0,0,17,0,0
0,0,0,0,0,0,0,0,0,0,0,0,17,12,0,0,0,0,0,0,0,17,0,0
0,0,0,0,0,0,0,0,0,0,0,0,0,2,12,0,0,0,0,0,0,5,17,0
0,0,0,0,0,0,0,0,0,0,0,0,0,0,2,13,0,0,0,0,0,0,0,0
0,0,0,0,0,0,0,0,0,0,0,0,0,0,0,17,5,0,0,0,0,0,0,0
endlayer

layer
2,17,17,17,17,2,0,0,0,0,0,0,0,0,0,0,0,0,0,0,0,0,0,0
2,5,0,0,0,11,17,17,17,17,0,0,0,0,0,0,0,0,0,0,0,0,0,0
2,4,0,0,0,0,0,0,0,0,17,17,17,0,0,0,0,0,0,0,0,0,0,0
11,0,0,0,0,0,0,0,0,0,0,0,0,17,17,0,0,0,0,0,0,0,0,0
2,13,0,0,0,0,0,0,0,0,0,0,0,0,5,17,17,0,0,0,0,0,0,0
2,0,0,0,0,0,0,0,0,0,0,0,0,0,0,0,0,0,0,0,8,0,0,0
2,5,0,0,0,0,0,0,0,0,0,0,0,0,0,0,0,0,0,0,0,0,0,0
2,17,17,17,17,12,0,0,0,0,0,0,0,0,0,0,0,0,0,0,0,0,0,0
0,0,0,0,0,2,17,17,17,0,0,0,0,0,0,0,8,0,0,0,0,0,0,0
0,0,0,0,0,0,0,0,0,17,17,17,5,0,0,0,0,0,0,0,0,17,0,0
0,0,0,0,0,0,0,0,0,0,0,0,17,12,0,0,0,0,0,0,0,17,0,0
0,0,0,0,0,0,0,0,0,0,0,0,0,2,12,0,0,8,0,0,0,5,17,0
0,0,0,0,0,0,0,0,0,0,0,0,0,0,2,13,0,0,8,0,0,0,0,0
0,0,0,0,0,0,0,0,0,0,0,0,0,0,0,17,5,0,8,0,0,0,0,0
endlayer

layer
2,17,17,17,17,2,0,0,0,0,0,0,0,0,0,0,0,0,0,0,0,0,0,0
2,5,0,0,18,11,17,17,17,17,0,0,0,0,0,0,0,0,0,0,0,0,0,0
2,4,0,0,0,0,0,0,0,0,17,17,17,0,0,0,0,0,0,0,0,0,0,0
11,0,0,0,0,0,0,0,0,0,0,0,0,17,17,13,0,0,0,0,0,0,0,0
2,13,0,0,0,0,0,0,0,0,0,0,0,0,5,17,0,0,0,0,0,0,0,0
2,0,0,0,0,0,0,0,0,0,0,0,0,0,0,0,0,0,0,0,8,0,0,0
2,5,0,0,0,18,0,0,0,0,0,0,0,0,0,0,0,13,0,0,0,0,0,0
2,17,17,17,17,12,0,0,0,0,0,0,0,0,0,0,0,0,0,0,0,0,0,0
0,0,0,0,0,2,17,17,17,0,0,0,0,0,0,0,0,0,0,0,0,0,0,0
0,0,0,0,0,0,0,0,0,17,17,17,5,0,0,0,0,0,0,0,0,17,0,0
0,0,0,0,0,0,0,0,0,0,0,0,0,0,0,0,0,0,0,11,0,17,0,0
0,0,0,0,0,0,0,0,0,0,0,0,0,0,0,0,0,0,0,0,0,5,17,0
0,0,0,0,0,0,0,0,0,0,0,0,0,0,2,0,0,0,0,0,0,0,0,0
0,0,0,0,0,0,0,0,0,0,0,0,0,0,0,17,5,0,0,0,0,0,0,0
endlayer

layer
2,2,2,2,2,2,0,0,0,0,0,0,0,0,0,0,0,0,0,0,0,0,0,0
2,5,16,16,16,16,2,2,2,2,0,0,0,0,0,0,0,0,0,0,0,0,0,0
2,4,16,16,16,16,16,16,16,16,2,2,2,0,12,0,0,0,0,0,0,0,0,0
0,16,16,16,16,16,16,16,16,16,16,16,16,2,2,13,0,0,0,0,0,0,0,0
2,16,16,16,16,16,16,16,16,16,16,16,16,16,5,0,12,0,0,0,0,0,0,0
2,16,16,16,16,16,16,16,16,16,16,16,16,16,16,16,16,13,0,0,0,0,0,0
2,5,16,16,16,16,16,16,16,16,16,16,16,16,16,16,16,13,0,0,0,0,0,0
2,2,2,2,2,16,16,16,16,16,16,16,16,16,16,16,16,0,0,0,0,0,0,0
0,0,0,0,0,2,2,2,2,16,16,16,16,16,16,16,16,16,12,0,0,0,0,0
0,0,0,0,0,0,0,0,0,2,2,2,5,0,14,16,16,16,16,16,16,2,0,0
0,0,0,0,0,0,0,0,0,0,11,11,0,0,0,0,0,0,11,11,0,2,0,0
0,0,0,0,0,0,0,0,0,0,0,0,0,0,0,0,0,0,0,0,0,5,2,0
0,0,0,0,0,0,0,0,0,0,0,0,0,0,0,0,0,0,0,0,0,0,0,0
0,0,0,0,0,0,8,0,8,0,0,0,0,0,0,0,5,0,0,0,0,0,0,0
endlayer

layer
2,2,2,2,2,2,0,0,0,0,0,0,0,0,0,0,0,0,0,0,0,0,0,0
2,5,4,0,0,0,2,2,2,2,0,0,0,0,0,0,0,0,0,0,0,8,0,0
2,4,4,0,0,0,0,0,0,0,2,2,2,0,12,0,0,0,0,0,0,0,0,0
2,0,0,0,0,0,0,0,0,0,0,0,0,2,2,13,0,0,0,0,0,0,0,0
2,0,0,0,0,0,0,0,0,0,0,0,0,0,5,0,0,0,0,0,0,0,0,0
2,0,0,0,0,0,0,0,0,0,0,0,0,0,0,0,0,0,0,0,0,0,0,0
2,5,0,0,0,0,0,0,0,0,0,0,0,0,0,0,0,0,0,0,0,0,0,0
2,2,2,2,2,0,0,0,0,0,0,0,0,0,0,0,0,0,0,0,0,0,8,0
0,0,0,0,0,2,2,2,2,0,0,0,0,0,0,0,0,0,0,0,0,0,0,0
0,0,0,0,0,0,0,0,0,2,2,2,5,0,0,0,0,0,0,0,0,0,0,0
0,0,0,0,0,0,0,0,0,0,0,0,0,0,0,0,0,0,0,0,0,0,0,0
0,0,0,0,0,0,0,0,0,0,0,0,0,8,0,0,0,0,0,8,0,5,2,0
0,0,0,0,0,0,0,0,0,0,0,0,0,0,8,0,0,8,0,0,0,0,0,0
0,0,0,0,0,0,0,0,0,0,0,0,0,0,0,0,5,0,0,0,0,0,0,0
endlayer

layer
2,17,17,17,17,2,0,0,0,0,0,0,0,0,8,0,0,0,8,0,0,0,0,0
2,5,4,0,0,0,17,17,17,17,0,0,0,0,0,0,0,0,0,0,0,0,0,0
2,0,0,0,0,0,0,0,0,0,17,17,17,0,0,0,0,0,0,0,0,0,0,0
2,0,0,0,0,0,0,0,0,0,0,0,0,17,17,0,0,0,0,0,0,0,0,0
2,0,0,0,0,0,0,0,0,0,0,0,0,0,5,17,17,0,0,0,0,0,8,0
2,0,0,0,0,0,0,0,0,0,0,0,0,0,0,0,0,0,0,0,0,0,0,0
2,5,0,0,0,0,0,0,0,0,0,0,0,0,0,0,0,0,0,0,0,0,0,0
2,17,17,17,17,0,0,0,0,0,0,0,0,0,0,0,0,0,8,0,0,0,0,0
0,0,0,0,0,2,17,17,17,0,0,0,0,0,0,0,0,0,0,0,0,0,0,0
0,0,0,0,0,0,0,0,0,17,17,17,5,0,0,0,0,0,0,0,0,0,0,0
0,0,0,0,0,0,0,0,0,0,0,0,0,0,0,0,0,0,0,0,0,0,0,0
0,8,0,0,0,0,0,0,0,0,0,0,0,0,0,0,0,0,0,0,0,5,17,0
0,0,0,0,0,0,0,0,0,0,0,0,0,0,0,0,0,0,0,0,0,0,0,0
0,0,0,0,0,8,0,0,0,0,0,0,0,0,0,0,5,0,0,0,0,0,0,0
endlayer

layer
2,17,17,17,17,2,0,0,0,0,0,0,0,0,0,0,0,0,0,0,0,0,0,0
2,5,4,0,0,0,17,17,17,17,0,0,0,0,0,0,0,0,0,0,0,0,0,0
0,0,0,0,0,0,0,0,0,0,17,17,17,0,0,0,0,0,0,0,0,0,0,0
0,0,0,0,0,0,0,0,0,0,0,0,0,17,17,0,0,0,0,0,0,0,0,0
2,0,0,0,0,0,0,0,0,0,0,0,0,0,5,17,17,0,0,0,0,0,0,0
2,0,0,0,0,0,0,0,0,0,0,0,0,0,0,0,0,17,0,0,0,0,8,0
2,5,0,0,0,0,0,0,0,0,0,0,0,0,0,0,0,0,0,0,0,0,0,0
2,17,17,17,17,0,0,0,0,0,0,0,0,0,0,0,0,0,0,0,0,0,0,0
0,0,0,0,0,2,17,17,17,0,0,0,0,0,0,0,0,0,0,0,0,0,0,0
0,0,0,0,0,0,0,0,0,17,17,17,5,0,0,0,0,0,0,0,0,0,0,0
0,0,0,0,0,0,0,0,0,0,0,0,0,0,0,0,0,0,0,0,0,0,0,0
0,0,0,0,0,0,0,0,0,0,0,0,0,0,0,0,0,0,0,0,0,5,17,0
0,0,0,0,0,0,0,0,0,0,0,0,0,0,0,0,0,0,0,0,0,0,0,0
0,0,0,0,0,0,0,0,0,0,0,0,0,0,0,0,5,0,0,0,0,0,0,0
endlayer

layer
2,17,17,17,17,2,0,0,0,0,0,0,0,0,0,0,8,0,0,0,0,0,0,0
2,5,4,0,0,0,17,17,17,17,0,0,0,0,0,0,0,0,0,0,0,0,0,0
0,0,0,0,0,0,0,0,0,0,17,17,17,0,0,0,0,0,0,8,0,0,0,0
0,0,0,0,0,0,0,0,0,0,0,0,0,17,17,12,0,0,0,0,0,0,0,0
0,0,0,0,0,0,0,0,0,0,0,0,0,0,5,17,17,0,0,0,0,0,0,0
0,0,0,0,0,0,0,0,0,0,0,0,0,0,0,0,0,17,0,0,0,0,0,0
2,5,0,0,0,0,0,0,0,0,0,0,0,0,0,0,0,0,2,13,0,0,0,0
2,17,17,17,17,0,0,0,0,0,0,0,0,0,0,0,0,0,0,2,0,0,0,0
0,0,0,0,0,2,17,17,17,0,0,0,0,0,0,0,0,0,0,0,0,0,0,0
0,0,0,0,0,0,0,0,0,17,17,17,5,0,0,0,0,0,0,0,0,0,0,0
0,0,0,0,0,0,0,0,0,0,0,0,0,0,0,0,0,0,0,0,0,17,0,0
0,0,0,0,0,0,0,0,0,0,0,0,0,0,0,0,0,0,0,0,0,5,17,13
0,0,0,0,0,0,0,0,0,0,0,0,0,0,0,0,0,0,0,0,0,0,0,0
0,0,0,0,0,0,0,0,0,0,0,0,0,0,0,0,5,0,0,0,0,0,0,0
endlayer

layer
2,2,2,2,2,2,12,0,0,0,0,0,0,0,0,0,0,0,0,0,0,0,0,0
2,5,4,16,16,16,2,2,2,2,0,0,0,0,0,0,0,0,0,0,0,0,0,0
0,0,0,0,0,16,16,16,16,16,2,2,2,0,0,0,0,0,0,0,0,0,0,0
0,0,0,0,0,16,16,16,16,16,16,16,16,2,2,12,12,0,0,0,0,0,0,0
0,0,0,0,16,16,16,16,16,16,16,16,16,16,5,2,2,0,0,0,0,0,0,0
0,0,0,0,16,16,16,16,16,16,16,16,16,16,16,16,16,2,0,0,0,0,0,0
2,5,0,16,0,16,16,16,16,16,16,16,16,16,16,16,16,16,2,13,0,0,0,0
2,2,2,2,2,16,16,16,16,16,16,16,16,16,16,16,16,16,16,2,0,0,0,0
0,0,0,0,0,2,2,2,2,16,16,16,16,16,11,16,16,16,16,16,2,13,0,0
0,0,0,0,0,0,0,11,11,2,2,2,5,0,0,0,16,16,16,16,16,2,0,0
0,0,0,0,0,0,0,0,0,0,0,0,0,0,8,0,16,16,16,16,16,2,0,0
0,0,0,0,0,0,0,0,0,0,0,0,0,0,0,14,16,16,16,16,16,5,2,13
0,0,0,0,0,0,0,0,0,0,0,0,0,0,0,14,16,16,16,16,16,16,0,0
0,0,0,0,0,0,0,0,0,0,0,0,0,8,0,0,14,16,16,16,16,16,13,0
endlayer

layer
2,2,2,2,2,2,15,0,0,0,0,0,0,0,0,0,0,0,0,0,0,0,0,0
2,5,4,0,0,0,2,2,2,2,0,0,0,0,0,0,0,0,0,0,0,0,0,0
0,0,0,0,0,0,0,0,0,0,2,2,2,0,0,0,0,0,0,0,0,0,0,0
0,0,0,0,0,0,0,0,0,0,0,0,0,2,2,12,12,0,0,0,0,0,0,0
0,0,0,0,0,0,0,0,0,0,0,0,0,0,5,2,2,0,0,0,0,0,0,0
0,0,0,0,0,0,0,0,0,0,0,0,0,0,0,0,0,2,0,0,0,0,0,0
0,5,0,0,0,0,0,0,0,0,0,0,0,0,0,0,0,0,2,0,0,0,8,0
2,2,2,2,2,0,0,0,0,0,0,0,0,0,0,0,0,0,0,2,0,0,0,0
0,11,0,0,0,2,2,2,2,0,0,0,0,0,0,0,0,0,0,0,2,0,0,0
0,0,0,0,0,0,0,0,11,2,2,2,5,0,0,0,0,0,0,0,0,2,0,0
0,0,0,0,0,0,0,0,0,0,0,0,0,0,0,0,0,0,0,0,0,2,0,0
0,0,0,0,0,0,0,0,0,0,0,0,0,0,0,0,0,0,0,0,0,5,2,0
0,0,0,0,0,0,0,0,0,0,0,0,0,0,0,0,0,0,0,0,0,0,0,0
0,0,0,0,0,0,0,0,0,0,0,0,0,0,0,2,5,0,0,0,0,0,0,0
endlayer

layer
0,0,0,0,0,2,13,0,0,0,0,0,0,0,0,0,0,0,0,0,0,0,0,0
0,5,4,0,0,0,0,17,17,17,0,0,0,0,0,0,0,0,0,0,0,0,0,0
0,0,0,0,0,0,0,0,0,0,17,17,17,0,0,0,0,0,0,0,0,0,0,0
0,0,0,0,0,0,0,0,0,0,0,0,0,17,17,0,0,0,0,0,0,0,0,0
0,0,0,0,0,0,0,0,0,0,0,0,0,0,5,17,17,0,0,0,0,0,0,0
0,0,0,0,0,0,0,0,0,0,0,0,0,0,0,0,0,17,0,0,0,0,0,0
0,5,0,0,0,0,0,0,0,0,0,0,0,0,0,0,0,0,2,0,0,0,0,0
0,0,0,0,0,0,0,0,0,0,0,0,0,0,0,0,0,0,0,2,0,0,0,0
0,0,0,0,0,2,17,17,17,0,0,0,0,0,0,0,0,0,0,0,17,0,0,0
0,0,0,0,0,0,0,0,0,17,17,17,5,0,0,0,0,0,0,0,0,17,0,0
0,0,0,0,0,0,0,0,0,0,0,0,17,0,0,0,0,0,0,0,0,17,0,0
0,0,0,0,0,0,0,0,0,0,0,0,0,0,0,0,0,0,0,0,0,5,17,0
0,0,0,0,0,0,0,0,0,0,0,0,0,0,0,0,0,0,0,0,0,0,0,0
0,0,0,0,0,0,0,0,0,0,0,0,0,0,0,17,5,0,0,0,0,0,0,0
endlayer

layer
0,0,0,0,0,2,13,0,0,0,0,0,0,0,0,0,0,0,0,0,0,0,0,0
0,5,4,0,0,0,0,17,17,17,0,0,0,0,0,0,0,0,0,0,0,0,0,0
0,0,0,0,0,0,0,0,0,0,17,17,17,0,0,0,0,0,0,0,0,0,0,0
0,0,0,0,0,0,0,0,0,0,0,0,0,17,17,0,0,0,0,0,0,0,0,0
0,0,0,0,0,0,0,0,0,0,0,0,0,0,5,17,17,0,0,0,0,0,0,0
0,0,0,0,0,0,0,0,0,0,0,0,0,0,0,0,0,17,0,0,0,0,0,0
0,5,0,0,0,0,0,0,0,0,0,0,0,0,0,0,0,0,2,0,0,0,0,0
0,0,0,0,0,0,0,0,0,0,0,0,0,0,0,0,0,0,0,2,0,0,0,0
0,0,0,0,0,2,17,17,17,0,0,0,0,0,0,0,0,0,0,0,17,0,0,0
0,0,0,0,0,0,0,0,0,17,17,17,5,0,0,0,0,0,0,0,0,17,0,0
0,0,0,0,0,0,0,0,0,0,0,0,17,0,0,0,0,0,0,0,0,17,0,0
0,0,0,0,0,0,0,0,0,0,0,0,0,2,0,0,0,0,0,0,0,5,17,0
0,0,0,0,0,0,0,0,0,0,0,0,0,11,2,0,0,0,0,0,0,0,0,0
0,0,0,0,0,0,0,0,0,0,0,0,8,0,0,17,5,0,0,0,0,0,0,0
endlayer

layer
0,0,0,0,0,2,13,0,0,0,0,0,0,0,0,0,0,0,0,0,0,0,0,0
0,5,4,0,0,0,0,17,17,17,0,0,0,0,0,0,0,0,0,0,0,0,0,0
0,0,0,0,0,0,0,0,0,0,17,17,17,0,0,0,0,0,0,0,0,0,0,0
0,0,0,0,0,0,0,0,0,0,0,0,0,17,17,0,0,0,0,0,0,0,0,0
0,0,0,0,0,0,0,0,0,0,0,0,0,0,5,17,17,0,0,0,0,0,0,0
0,0,0,0,0,0,0,0,0,0,0,0,0,0,0,0,0,17,0,0,0,0,0,0
0,5,0,0,0,0,0,0,0,0,0,0,0,0,0,0,0,0,2,0,0,0,0,0
0,0,0,0,0,0,0,0,0,0,0,0,0,0,0,0,0,0,0,2,0,0,0,0
0,0,0,0,0,2,17,17,17,0,0,0,0,0,0,0,0,0,0,0,17,0,0,0
0,0,0,0,0,0,0,0,0,17,17,17,5,0,0,0,0,0,0,0,0,17,13,0
0,0,0,8,0,0,0,0,0,0,0,0,17,0,0,0,0,0,0,0,0,17,0,0
0,0,0,0,0,0,0,0,0,0,0,0,0,2,0,0,0,0,0,0,0,5,17,0
0,0,0,0,0,0,0,0,0,0,0,0,0,11,2,0,0,0,0,0,0,0,0,0
0,0,0,0,0,0,0,0,0,0,0,0,0,0,0,17,5,0,0,0,0,0,0,0
endlayer

layer
0,2,2,2,2,2,0,12,12,0,0,0,0,0,0,0,0,0,0,0,0,0,0,0
0,5,4,0,0,16,2,2,2,2,0,0,0,0,0,0,0,0,0,0,0,0,0,0
0,0,0,0,0,16,16,16,16,16,2,2,2,0,0,0,0,0,0,0,0,0,0,0
0,0,0,0,0,16,16,16,16,16,16,16,16,2,2,0,0,0,0,0,0,0,0,0
0,0,0,0,0,16,16,16,16,16,16,16,16,16,5,2,2,0,0,0,0,0,0,0
0,0,0,0,0,16,16,16,16,16,16,16,16,16,16,16,16,2,0,0,0,0,0,0
0,5,0,0,0,16,16,16,16,16,16,16,16,16,16,16,16,16,2,0,0,0,8,0
0,0,0,0,0,16,16,16,16,16,16,16,16,16,16,16,16,16,16,2,13,0,0,0
0,0,0,0,14,2,2,2,2,16,16,16,16,16,16,16,19,16,16,16,2,0,0,0
0,0,0,0,0,0,0,0,0,2,2,2,5,16,16,16,16,16,16,16,16,2,13,0
0,0,0,0,0,0,0,0,0,0,0,0,2,16,16,16,16,16,16,16,0,2,0,0
0,0,0,0,0,0,0,0,0,0,0,0,0,2,16,16,16,16,16,16,16,5,2,0
0,0,0,0,0,0,0,0,0,0,0,0,0,14,2,16,16,0,11,11,0,0,0,0
0,0,0,0,0,0,0,0,0,0,0,0,0,0,0,2,5,0,0,0,0,0,0,0
endlayer

layer
2,2,2,2,2,2,0,0,12,12,0,0,0,0,0,0,0,0,0,0,0,0,0,0
11,5,4,0,0,0,2,2,2,2,0,0,0,0,0,0,0,0,0,0,0,0,0,0
0,0,0,0,0,0,0,0,0,0,2,2,2,0,0,0,0,0,0,0,0,0,0,0
0,0,0,0,0,0,0,0,0,0,0,0,0,2,2,0,0,0,0,0,0,0,0,0
0,0,0,0,0,0,0,0,0,0,0,0,0,0,5,0,0,0,0,0,0,0,0,0
0,0,0,0,0,0,0,0,0,0,0,0,0,0,0,0,0,0,0,0,0,0,0,0
0,5,0,0,0,0,0,0,0,0,0,0,0,0,0,0,0,0,2,0,0,0,0,0
0,0,0,0,0,0,0,0,0,0,0,0,0,0,0,0,0,0,0,2,13,0,0,0
0,0,0,0,14,2,2,2,2,0,0,0,0,0,0,0,0,0,0,0,0,0,0,0
0,0,8,8,0,0,0,0,0,2,2,2,5,0,0,8,0,0,0,0,0,0,0,0
0,0,0,0,0,0,0,0,0,0,0,0,2,0,8,8,0,0,0,0,0,0,0,0
0,0,0,0,0,0,0,0,0,0,0,0,0,0,0,0,0,0,0,0,0,5,0,0
0,0,0,0,0,0,0,0,0,0,0,0,0,0,0,0,0,0,0,0,0,0,0,0
0,0,0,0,0,0,0,0,0,0,0,0,0,0,0,0,5,0,0,0,0,0,0,0
endlayer

layer
2,0,0,0,0,2,0,0,0,0,0,0,0,0,0,0,0,0,0,0,0,0,0,0
2,5,4,0,0,0,17,17,17,17,0,0,0,0,0,0,0,0,0,0,0,0,0,0
0,0,0,0,0,0,0,0,0,0,17,17,17,0,0,0,0,0,0,0,0,0,0,0
0,0,0,0,0,0,0,0,0,0,0,0,0,17,17,0,0,0,0,0,0,0,0,0
0,0,0,0,0,0,0,0,0,0,0,0,0,0,5,0,0,0,0,0,0,0,0,0
0,0,0,0,0,0,0,0,0,0,0,0,0,0,0,0,0,0,0,0,0,0,8,0
0,5,0,0,0,0,0,0,0,0,0,0,0,0,0,0,0,0,2,0,0,0,0,0
0,17,0,0,0,0,0,0,0,0,0,0,0,0,0,0,0,0,0,2,13,0,0,0
0,0,0,0,14,2,17,17,17,0,0,0,0,0,0,0,0,0,0,0,0,0,0,8
0,0,0,0,0,0,0,0,0,17,17,17,5,0,0,0,0,0,0,0,0,0,0,0
0,0,0,0,0,0,0,0,0,0,0,0,17,0,0,0,0,8,0,0,0,0,0,0
0,0,0,0,0,0,0,0,0,0,0,0,0,0,0,0,0,0,0,0,0,5,0,0
0,0,0,0,0,0,0,0,0,0,0,0,0,0,0,0,0,0,0,0,0,0,0,0
0,0,0,0,0,0,0,0,0,0,0,0,0,0,0,0,5,0,0,0,0,0,0,0
endlayer

layer
2,17,0,0,0,2,0,0,0,0,0,0,0,0,0,0,0,0,0,0,0,0,0,0
2,5,4,0,0,0,17,17,17,17,0,0,0,0,0,0,0,0,0,0,0,0,0,0
0,0,0,0,0,0,0,0,0,0,17,17,17,0,0,0,0,0,0,0,0,0,0,0
0,0,0,0,0,0,0,0,0,0,0,0,0,17,17,0,0,0,0,0,0,0,0,0
0,0,0,0,0,0,0,0,0,0,0,0,0,0,5,0,0,0,0,0,0,0,0,0
0,0,0,0,0,0,0,0,0,0,0,0,0,0,0,0,0,0,0,0,0,0,0,0
0,5,0,0,0,0,0,0,0,0,0,0,0,0,0,0,0,14,2,0,0,0,0,0
0,17,0,0,0,0,0,0,0,0,0,0,0,0,0,0,0,0,0,2,13,0,0,0
0,0,0,0,14,2,17,17,17,0,0,0,0,0,0,0,0,0,0,0,0,0,0,0
0,0,0,0,0,0,0,0,0,17,17,17,5,0,0,0,0,0,0,0,0,0,0,0
0,0,0,0,0,0,0,0,0,0,11,0,17,0,0,0,0,0,0,0,0,0,0,0
0,0,0,8,0,0,0,0,0,0,0,0,0,0,0,0,0,0,0,0,0,5,0,0
0,0,8,0,0,0,0,8,0,0,0,0,0,0,0,0,0,0,0,0,0,0,0,0
0,0,0,0,0,0,0,0,0,0,0,0,0,0,0,0,5,0,0,0,0,0,0,0
endlayer

layer
2,17,17,0,17,2,13,0,0,0,0,0,0,0,0,0,0,0,0,0,0,0,0,0
2,5,4,0,0,0,17,17,17,17,0,12,0,0,0,0,0,0,0,0,0,0,0,0
2,0,0,0,0,0,0,0,0,0,17,17,17,0,0,0,0,0,0,0,0,0,0,0
0,0,0,0,0,0,0,0,0,0,0,0,0,17,17,0,0,0,0,0,0,0,0,0
2,0,0,0,0,0,0,0,0,0,0,0,0,0,5,0,0,0,0,0,0,0,0,0
2,0,0,0,0,0,0,0,0,0,0,0,0,0,0,0,0,0,0,0,0,0,0,0
2,5,0,0,0,0,0,0,0,0,0,0,0,0,0,0,0,14,2,0,0,0,0,0
2,17,17,17,17,0,0,0,0,0,0,0,0,0,0,0,0,0,11,2,13,0,0,0
0,0,0,0,14,2,17,17,17,0,0,0,0,0,0,8,0,0,0,0,0,0,0,0
0,0,0,0,0,11,0,11,0,17,17,17,5,0,0,0,0,0,0,0,0,0,0,0
0,8,0,0,0,0,0,0,0,0,11,0,17,0,0,0,0,0,0,0,0,0,0,0
0,0,0,0,0,0,0,0,0,0,0,0,0,0,0,0,0,0,0,0,0,5,0,0
0,0,0,0,0,0,0,0,0,0,0,0,0,0,0,0,0,0,0,0,0,0,0,0
0,0,0,0,0,0,0,0,0,0,0,0,0,0,0,0,5,0,0,0,0,0,0,0
endlayer

layer
2,2,2,2,2,2,13,0,0,0,0,0,0,0,0,0,0,0,0,0,0,0,0,0
2,5,4,16,16,16,2,2,2,2,0,12,12,0,0,0,0,0,0,0,0,0,0,0
0,16,16,16,16,16,16,16,16,16,2,2,2,0,0,0,0,0,0,0,0,0,0,0
0,16,16,16,16,16,16,16,16,16,16,16,16,2,2,0,0,0,0,0,0,0,0,0
2,16,16,16,16,16,16,16,16,16,16,16,16,16,5,0,0,0,0,0,0,0,0,0
2,16,16,16,16,16,16,16,16,16,16,16,16,16,16,13,0,0,0,0,0,0,0,0
2,5,16,16,16,16,16,16,16,16,16,16,16,16,16,13,0,0,2,0,0,0,0,0
2,2,2,2,2,16,16,16,16,16,16,16,16,16,16,0,0,0,0,2,13,0,0,0
0,0,0,0,11,2,2,2,2,16,16,16,16,16,13,0,0,0,0,0,0,0,0,0
0,0,0,0,0,0,0,11,0,2,2,2,5,16,0,0,0,0,0,0,0,0,0,0
0,0,0,0,0,0,0,0,0,0,11,0,2,13,0,0,0,0,0,0,0,0,0,0
0,0,0,0,0,0,0,0,0,0,0,0,0,0,0,0,0,0,0,0,0,5,0,0
0,0,8,0,0,0,0,0,0,0,0,0,0,0,0,0,0,0,0,8,0,0,0,0
0,0,0,0,0,0,0,0,8,0,0,0,0,0,0,0,5,0,0,0,0,0,0,0
endlayer

layer
2,2,2,2,2,2,13,0,0,0,0,0,0,0,0,0,0,0,0,0,0,0,0,0
2,5,4,0,0,0,2,2,2,2,0,0,12,0,0,0,0,0,0,0,0,0,0,0
11,0,0,0,0,0,0,0,0,0,2,2,2,0,0,0,0,0,0,0,0,0,0,0
0,0,8,0,0,0,0,0,0,0,0,0,0,2,2,0,0,0,0,0,0,0,0,0
2,13,0,0,0,0,0,0,0,0,0,0,0,0,5,0,0,0,0,0,0,8,0,0
2,0,0,0,0,0,0,0,0,0,0,0,0,0,0,0,0,0,0,0,0,0,0,0
2,5,0,0,0,0,0,0,0,0,0,0,0,0,0,0,0,0,2,0,0,0,0,0
2,2,2,2,2,0,0,0,0,0,0,0,0,0,0,0,0,0,0,2,13,0,0,0
0,0,0,11,14,2,2,2,2,0,0,0,0,0,0,0,0,0,0,11,0,0,0,0
0,0,0,0,0,0,0,11,0,2,2,2,5,0,0,0,0,0,0,0,0,0,0,0
0,0,0,0,0,0,0,0,0,0,11,0,2,0,0,0,8,0,0,0,0,0,0,0
0,0,0,0,0,0,0,0,0,0,0,0,0,0,0,0,0,0,0,0,0,5,0,0
0,0,0,0,0,0,0,0,0,0,0,0,0,0,0,0,0,0,0,0,0,0,0,0
0,0,0,0,0,0,0,0,0,0,0,0,0,0,0,0,5,0,0,0,0,0,0,0
endlayer

layer
2,17,17,17,17,2,13,0,0,0,0,0,0,0,0,0,0,0,0,0,0,0,0,0
2,5,20,0,0,0,17,17,17,17,0,0,0,0,0,0,0,0,0,0,0,0,0,0
11,0,0,0,0,0,0,0,0,0,17,17,17,0,0,0,0,0,0,0,0,0,0,0
0,0,0,0,0,0,0,0,0,0,0,0,0,17,17,0,0,0,0,0,0,0,0,0
2,13,0,0,0,8,0,0,0,0,0,0,0,0,5,0,0,0,0,0,0,0,0,0
2,0,0,0,0,0,0,0,0,0,0,0,0,0,0,0,0,0,0,0,0,0,0,0
2,5,0,0,0,0,0,8,0,0,0,0,0,0,0,8,0,0,2,0,0,0,0,0
2,17,17,17,17,12,0,0,0,0,0,0,0,0,0,0,0,0,8,2,0,0,0,0
0,0,0,0,14,2,17,17,17,0,0,0,0,0,0,0,0,0,0,0,17,0,0,0
0,0,0,0,0,0,0,0,0,17,17,17,5,0,0,0,0,0,0,0,0,0,0,0
0,0,0,0,0,0,0,0,0,0,0,0,17,0,0,0,0,0,8,0,0,17,0,0
0,0,0,0,0,0,0,0,0,0,0,0,0,0,0,0,0,0,0,0,0,5,0,0
0,0,0,0,0,0,8,0,0,0,0,0,0,0,0,0,0,0,0,0,0,0,0,0
0,0,0,0,0,0,0,0,0,0,0,0,0,0,0,0,5,0,0,0,0,0,0,0
endlayer

layer
2,17,17,17,17,2,0,0,0,0,0,0,0,0,8,0,0,0,0,0,0,0,0,0
2,5,4,0,0,0,17,17,17,17,0,0,0,0,0,0,0,0,0,0,0,0,0,0
2,0,0,0,0,0,0,0,0,0,17,17,17,0,0,0,0,0,0,0,0,0,0,0
2,13,0,0,0,0,0,0,0,0,0,0,0,17,17,0,0,0,0,0,0,0,0,0
2,13,0,0,0,0,0,0,0,0,0,0,0,0,5,17,0,0,0,0,0,0,8,0
2,13,0,0,0,0,0,0,0,0,0,0,0,0,0,0,0,0,0,0,0,0,0,0
2,5,0,0,0,0,0,0,0,0,0,0,0,0,0,0,0,0,2,12,0,0,0,0
2,17,17,17,17,0,0,0,0,0,0,0,0,0,0,0,0,0,0,2,0,0,0,0
0,0,0,0,14,2,17,17,17,0,0,0,0,0,0,0,0,0,0,0,17,0,0,0
0,0,0,0,0,0,0,0,0,17,17,17,5,0,0,0,0,0,0,0,0,17,0,0
0,0,8,0,0,0,0,0,0,0,0,0,17,0,0,0,0,0,0,0,0,17,0,0
0,0,0,0,0,0,0,0,0,0,0,0,0,0,0,0,0,0,0,0,0,5,0,0
0,0,0,0,0,0,0,0,0,0,0,0,0,0,0,0,0,0,0,0,0,0,0,0
0,0,0,0,0,0,0,0,0,0,0,0,0,0,0,0,5,0,0,0,0,0,0,0
endlayer

layer
2,17,17,17,17,2,0,0,0,0,0,0,0,0,0,0,0,0,0,0,0,0,0,0
2,5,4,0,0,11,17,17,17,17,0,0,0,0,0,0,0,0,0,0,0,0,0,0
2,0,0,0,0,0,0,0,0,0,17,17,17,12,0,0,0,0,0,0,0,0,0,0
2,13,0,0,0,0,0,0,0,0,0,0,0,17,17,0,0,0,0,0,0,0,0,0
2,0,0,0,0,0,0,0,0,0,0,0,0,0,5,17,0,0,0,0,0,0,0,0
2,0,0,0,0,0,0,0,0,0,0,0,0,0,0,0,0,0,0,0,0,0,0,0
2,5,0,0,0,0,0,0,0,0,0,0,0,0,0,0,0,0,2,12,0,0,0,0
2,17,17,17,17,0,0,0,0,0,0,0,0,0,0,0,0,0,0,2,0,0,0,0
0,0,0,0,0,2,17,17,17,0,0,0,0,0,0,0,0,0,0,0,17,12,0,0
0,0,0,0,0,0,0,0,0,17,17,17,5,0,0,0,0,0,0,0,0,17,0,0
0,0,0,0,0,0,0,0,0,0,0,0,17,0,0,0,0,0,0,0,0,17,13,0
0,0,0,0,0,0,0,0,0,0,0,0,0,0,0,0,0,0,0,0,0,5,0,0
0,0,0,0,0,0,0,0,0,0,0,0,0,0,0,0,0,0,0,0,0,0,0,13
0,0,0,0,0,0,0,0,0,0,0,0,0,0,0,0,5,0,0,0,0,0,0,0
endlayer

layer
2,2,2,2,2,2,0,0,0,12,0,0,0,0,0,0,0,0,0,0,0,0,0,0
2,5,4,16,16,16,2,2,2,2,0,0,0,0,0,0,0,0,0,0,0,0,0,0
2,16,16,16,16,16,16,16,16,16,2,2,2,12,0,0,0,0,0,0,0,0,0,0
2,16,16,16,16,16,16,16,16,16,16,16,16,2,2,0,12,0,0,0,0,0,0,0
2,16,16,16,16,16,16,16,16,16,16,16,16,16,5,2,2,0,0,0,0,0,0,0
2,16,16,16,16,16,16,16,16,16,16,16,16,16,16,16,16,2,0,0,0,0,0,0
2,5,16,16,16,16,16,16,16,16,16,16,16,16,16,16,16,16,2,12,0,0,0,0
2,2,2,2,2,16,16,16,16,16,16,16,16,16,16,16,16,16,16,2,0,0,0,0
0,0,0,0,11,2,2,2,2,16,16,16,16,16,16,16,16,16,16,16,2,12,0,0
0,0,0,0,0,0,11,11,0,2,2,2,5,16,16,16,16,16,16,16,16,2,0,0
0,0,0,0,0,0,0,0,0,0,0,0,2,16,16,16,16,16,16,16,16,2,13,0
0,0,0,0,0,0,0,0,0,0,0,0,0,0,16,16,16,16,16,16,16,5,2,0
0,0,0,0,0,0,0,0,0,0,0,0,0,0,0,16,16,16,16,16,16,16,2,13
0,0,0,0,0,0,0,0,0,0,0,0,0,0,0,0,5,16,16,16,16,16,16,2
endlayer

layer
2,17,17,17,17,2,0,0,0,0,0,0,0,0,0,0,0,0,0,0,0,0,0,0
2,5,4,0,0,0,17,17,17,17,0,0,0,0,0,0,0,0,0,0,0,0,0,0
2,0,0,0,0,0,0,0,0,0,17,17,17,0,0,0,0,0,0,0,0,0,0,0
2,0,0,0,0,0,0,0,0,0,0,0,0,17,17,0,0,0,0,0,0,0,0,0
2,0,0,0,0,21,0,0,0,0,0,0,0,0,5,17,17,0,0,0,0,0,0,0
2,0,0,0,0,0,0,0,0,0,0,0,0,0,0,0,0,17,0,0,0,0,0,0
2,5,0,0,0,0,0,0,0,0,0,0,0,0,0,0,0,0,2,0,0,0,0,0
2,17,17,17,17,0,0,0,0,0,0,0,0,0,0,0,0,0,0,2,0,0,0,0
0,0,0,0,0,2,17,17,17,0,0,0,0,0,0,0,0,0,0,0,17,0,0,0
0,0,0,0,0,0,0,0,0,17,17,17,5,0,0,0,0,0,0,0,0,17,0,0
8,0,0,0,0,0,0,0,0,0,0,0,17,0,0,0,0,0,0,0,0,17,0,0
0,0,0,0,0,0,0,0,0,0,0,0,0,2,0,0,0,0,0,0,0,5,17,0
0,0,0,0,0,0,0,0,0,0,0,0,0,11,2,0,0,0,0,0,0,0,17,0
0,0,0,0,0,0,0,0,0,0,0,0,0,0,0,0,5,2,2,2,2,2,2,17
endlayer

layer
2,17,17,17,17,2,0,0,0,0,0,0,0,0,0,0,0,0,0,0,0,0,0,0
2,5,4,0,0,0,17,17,17,17,0,0,0,0,0,0,0,0,0,0,0,0,0,0
2,0,0,0,0,0,0,0,0,0,17,17,17,0,0,0,0,0,0,0,0,0,0,0
2,0,0,0,0,0,0,0,0,0,0,0,0,17,17,0,0,0,0,0,0,0,0,0
2,0,0,0,0,0,0,8,8,0,0,0,0,0,5,17,17,0,0,0,0,0,0,0
2,0,0,0,0,0,0,0,8,0,0,0,0,0,0,0,0,17,0,0,0,0,0,0
2,5,0,0,0,0,0,0,0,0,0,0,0,0,0,0,0,0,2,0,0,0,0,0
2,17,17,17,17,0,0,0,0,0,0,0,0,0,0,0,0,0,0,2,0,0,0,0
0,0,0,0,0,2,17,17,17,0,0,0,8,0,0,0,0,0,0,0,17,0,0,0
0,0,0,0,0,0,0,0,0,17,17,17,5,0,0,8,0,0,0,0,0,17,0,0
0,0,0,0,0,0,0,0,0,0,0,0,17,0,0,0,0,8,0,0,0,17,0,0
0,0,0,0,0,0,0,0,0,0,0,0,0,2,0,0,0,0,0,0,0,5,17,0
0,0,0,0,0,0,0,0,0,0,0,0,0,22,2,0,0,0,0,0,0,0,17,0
0,0,0,0,0,0,0,0,0,0,0,8,0,0,0,17,5,2,2,2,2,2,2,17
endlayer

layer
2,17,17,17,17,2,0,0,0,0,0,0,0,0,0,0,0,0,0,0,0,0,0,0
2,5,4,0,0,0,17,17,17,17,0,0,0,0,0,0,0,0,0,0,0,0,0,0
2,0,0,0,0,0,0,0,0,0,17,17,17,0,0,0,0,0,0,0,0,0,0,0
2,0,0,0,0,0,0,0,0,0,0,0,0,17,17,0,0,0,0,0,0,0,0,0
2,0,0,0,0,0,0,0,0,0,0,0,0,0,5,17,17,0,0,0,0,0,0,0
2,0,0,0,0,0,0,0,0,0,0,0,0,0,0,0,0,17,0,0,0,0,0,0
2,5,0,0,0,0,0,0,0,0,0,0,0,0,0,0,0,0,2,0,0,0,0,0
2,17,17,17,17,0,0,0,0,0,0,0,0,0,0,0,0,0,0,2,0,0,0,0
0,0,0,0,0,2,17,17,17,0,0,0,0,0,0,0,0,0,0,0,17,0,0,0
0,0,0,0,0,0,0,0,0,17,17,17,5,0,0,0,0,0,0,0,0,17,0,0
0,0,0,0,0,0,0,0,0,0,0,0,17,0,0,0,0,0,0,0,0,17,0,0
0,0,0,0,0,0,0,0,0,0,0,0,0,2,0,0,0,0,0,0,0,5,17,0
0,0,0,0,0,0,0,0,0,0,0,0,0,0,2,0,0,0,0,0,0,0,17,0
0,0,0,0,0,0,0,0,0,0,0,0,0,0,0,17,5,2,2,2,2,2,2,17
endlayer

layer
2,17,17,17,17,2,0,0,0,0,0,0,0,0,0,0,0,0,0,0,0,0,0,0
2,5,4,0,0,0,17,17,17,17,0,0,0,0,0,0,0,0,0,0,0,0,0,0
2,0,0,0,0,0,0,0,0,0,17,17,17,0,0,0,0,0,0,0,0,0,0,0
2,0,0,0,0,0,0,0,0,0,0,0,0,17,17,0,0,0,0,0,0,0,0,0
2,0,0,0,0,0,0,0,0,0,0,0,0,0,5,17,17,0,0,0,0,0,0,0
2,0,0,0,0,0,0,0,0,0,0,0,0,0,0,0,0,17,0,0,0,0,0,0
2,5,0,0,0,0,0,0,0,0,0,0,0,0,0,0,0,0,2,0,0,0,0,0
2,17,17,17,17,0,0,0,0,0,0,0,0,0,0,0,0,0,0,2,0,0,0,0
0,0,0,0,0,2,17,17,17,0,0,0,0,0,0,0,0,0,0,0,17,0,0,0
0,0,0,0,0,0,0,0,0,17,17,17,5,0,0,0,0,0,0,0,0,17,0,0
0,0,0,0,0,0,0,0,0,0,0,0,17,0,0,0,0,0,0,0,0,17,0,0
0,0,0,0,0,0,0,0,0,0,0,0,0,2,0,0,0,0,0,0,0,5,17,0
0,0,0,0,0,0,0,0,0,0,0,0,0,0,2,0,0,0,0,0,0,0,17,0
0,0,0,0,0,0,0,0,0,0,0,0,0,0,0,17,5,2,2,2,2,2,2,17
endlayer

layer
2,17,17,17,17,2,0,0,0,0,0,0,0,0,0,0,0,0,0,0,0,0,0,0
2,5,4,0,0,0,17,17,17,17,0,0,0,0,0,0,0,0,0,0,0,0,0,0
2,0,0,0,0,0,0,0,0,0,17,17,17,0,0,0,0,0,0,0,0,0,0,0
2,0,0,0,0,0,0,0,0,0,0,0,0,17,17,0,0,0,0,0,0,0,0,0
2,0,0,0,0,0,0,0,0,0,0,0,0,0,5,17,17,0,0,0,0,0,0,0
2,0,0,0,0,0,0,0,0,0,0,0,0,0,0,0,0,17,0,0,0,0,0,0
2,5,0,0,0,0,0,0,0,0,0,0,0,0,0,0,0,0,2,0,0,0,0,0
2,17,17,17,17,0,0,0,0,0,0,0,0,0,0,0,0,0,0,2,0,0,0,0
0,11,0,0,0,2,17,17,17,0,0,0,0,0,0,0,0,0,0,0,17,0,0,0
0,0,0,0,0,0,0,0,0,17,17,17,5,0,0,0,0,0,0,0,0,17,0,0
0,0,0,0,0,0,0,0,0,0,0,0,17,0,0,0,0,0,0,0,0,17,0,0
0,0,0,0,0,0,0,0,0,0,0,0,0,2,0,0,0,0,0,0,0,5,17,0
0,0,0,0,0,0,0,0,0,0,0,0,0,11,2,0,0,0,0,0,0,0,17,0
0,0,0,0,0,0,0,0,0,0,0,0,0,0,0,17,5,2,2,2,2,2,2,17
endlayer

layer
2,2,2,2,2,2,0,0,0,0,0,0,0,0,0,0,0,0,0,0,0,0,0,0
2,2,4,2,2,2,2,2,2,2,0,12,0,0,0,0,0,0,0,0,0,0,0,0
2,2,2,2,2,2,2,2,2,2,2,2,2,0,0,0,0,0,0,0,0,0,0,0
2,2,2,2,2,2,2,2,2,2,2,2,2,2,2,0,0,0,0,0,0,0,0,0
2,2,2,2,2,2,2,2,2,2,2,2,2,2,2,2,2,0,0,0,0,0,0,0
2,2,2,2,2,2,2,2,2,2,2,2,2,2,2,2,2,2,0,0,0,0,0,0
2,2,2,2,2,2,2,2,2,2,2,2,2,2,2,2,2,2,2,0,0,0,0,0
2,2,2,2,2,2,2,2,2,2,2,2,2,2,2,2,2,2,2,2,0,0,0,0
11,11,0,0,0,2,2,2,2,2,2,2,2,2,2,2,2,2,2,2,2,0,0,0
0,0,0,0,0,0,0,0,0,2,2,2,2,2,2,2,2,2,2,2,2,2,0,0
0,0,0,0,0,0,0,0,0,0,0,0,2,2,2,2,2,2,2,2,2,2,0,0
0,0,0,0,0,0,0,0,0,0,0,0,0,2,2,2,2,2,2,2,2,2,2,0
0,0,0,0,0,0,0,0,0,0,0,0,0,0,2,2,2,2,2,2,2,2,2,0
0,0,0,0,0,0,0,0,0,0,0,0,0,0,0,2,2,2,2,2,2,2,2,2
endlayer

layer
0,0,0,0,0,0,0,0,0,0,0,0,0,0,0,0,0,0,0,0,0,0,0,0
0,0,4,23,0,0,0,0,0,0,0,0,0,0,0,0,0,0,0,0,0,0,0,0
0,0,0,0,0,0,0,0,0,0,0,0,0,0,0,0,0,0,0,0,0,0,0,0
0,0,0,0,0,0,0,0,0,0,0,0,0,0,0,0,0,0,0,0,0,0,0,0
0,0,0,0,0,0,0,0,0,0,0,0,0,0,0,0,0,0,0,0,0,0,0,0
0,0,0,0,0,0,0,0,0,0,0,0,0,0,0,0,0,0,0,0,0,0,0,0
0,0,0,0,0,0,0,0,0,0,0,0,0,0,0,0,0,0,0,0,0,0,0,0
0,0,0,0,0,0,0,0,0,0,0,0,0,0,0,0,0,0,0,0,0,0,0,0
0,0,0,0,0,0,0,0,0,0,0,0,0,0,0,0,0,0,0,0,0,0,0,0
0,0,0,0,0,0,0,0,0,0,0,0,0,0,0,0,0,0,0,0,0,0,0,0
0,0,0,0,0,0,0,0,0,0,0,0,0,0,0,0,0,0,0,0,0,0,0,0
0,0,0,0,0,0,0,0,0,0,0,0,0,0,0,0,0,0,0,0,0,0,0,0
0,0,0,0,0,0,0,0,0,0,0,0,0,0,0,0,0,0,0,0,0,0,0,0
0,0,0,0,0,0,0,0,0,0,0,0,0,0,0,0,0,0,0,0,0,0,0,0
endlayer

layer
0,0,0,0,0,0,0,0,0,0,0,0,0,0,0,0,0,0,0,0,0,0,0,0
0,0,7,0,0,0,0,0,0,0,0,0,0,0,0,0,0,0,0,0,0,0,0,0
0,0,0,0,0,0,0,0,0,0,0,0,0,0,0,0,0,0,0,0,0,0,0,0
0,0,0,0,0,0,0,0,0,0,0,0,0,0,0,0,0,0,0,0,0,0,0,0
0,0,0,0,0,0,0,0,0,0,0,0,0,0,0,0,0,0,0,0,0,0,0,0
0,0,0,0,0,0,0,0,0,0,0,0,0,0,0,0,0,0,0,0,0,0,0,0
0,0,0,0,0,0,0,0,0,0,0,0,0,0,0,0,0,0,0,0,0,0,0,0
0,0,0,0,0,0,0,0,0,0,0,0,0,0,0,0,0,0,0,0,0,0,0,0
0,0,0,0,0,0,0,0,0,0,0,0,0,0,0,0,0,0,0,0,0,0,0,0
0,0,0,0,0,0,0,0,0,0,0,0,0,0,0,0,0,0,0,0,0,0,0,0
0,0,0,0,0,0,0,0,0,0,0,0,0,0,0,0,0,0,0,0,0,0,0,0
0,0,0,0,0,0,0,0,0,0,0,0,0,0,0,0,0,0,0,0,0,0,0,0
0,0,0,0,0,0,0,0,0,0,0,0,0,0,0,0,0,0,0,0,0,0,0,0
0,0,0,0,0,0,0,0,0,0,0,0,0,0,0,0,0,0,0,0,0,0,0,0
endlayer

